{"op":"mcm","clk":"AAwAAgAE","pt":1675435140398,"mc":[{"id":"1.209492553","rc":[{"atb":[[3.25,0]],"atl":[[3.25,11.26]],"trd":[[3.25,30]],"ltp":3.25,"tv":280.28,"id":51644292}],"tv":711.17}]}
{"op":"mcm","clk":"AAwAFwAE","pt":1675435140424,"mc":[{"id":"1.209492553","rc":[{"bdatb":[[0,3.15,6.53],[1,3.1,1.61],[2,3.05,13.66],[3,3,1.94],[4,2.98,4.28],[5,2.92,4.17],[6,2.84,6.42],[7,2.8,5.31],[8,2.76,4.91],[9,2.74,1.14]],"bdatl":[[0,3.25,11.26],[1,3.4,1.3],[2,3.45,3.56],[3,3.55,1.63],[4,3.65,8.11],[5,3.7,5.09],[6,3.75,6.25],[7,3.8,7.04],[8,3.85,1.8],[9,3.95,3.07]],"id":51644292},{"bdatb":[[2,6.6,1.55],[3,6.4,3.86],[4,6.2,1.93],[5,6,1.53],[6,5.9,1.63],[7,5.8,1],[8,5.6,2.64],[9,5.4,1.82]],"bdatl":[[4,13.5,1.05],[5,14,8.82],[6,18,1.23],[7,29,1.05],[8,34,6.06],[9,44,4.79]],"id":43513345},{"bdatb":[[3,5.5,7.11],[4,5.4,3.34],[5,5,1.46],[6,4.9,1.19],[7,4.7,2.29],[8,4.5,1.5],[9,4.4,1]],"bdatl":[[6,8.4,2.88],[7,8.6,1.29],[8,9.2,2.48],[9,9.4,1.07]],"id":36614067},{"bdatb":[[4,10.5,1.91],[5,9.8,1.37],[6,8.4,1.5],[7,7.6,1.96],[8,6.8,3.8],[9,6,12.61]],"bdatl":[[9,140,1.92]],"id":45930908},{"bdatb":[[5,5,3.65],[6,4.9,7.17],[7,4.7,1.21],[8,4.6,1.87],[9,4.5,1.65]],"bdatl":[[4,8,1.87],[5,8.2,1.94],[6,9.2,1.82],[9,11.5,1.28]],"id":50567711},{"bdatb":[[3,4.3,3.34],[4,4.2,11.63],[5,4.1,1.65],[6,4,13.68],[7,3.95,1.53],[8,3.9,35.72],[9,3.8,56.55]],"bdatl":[[4,6,1.6],[5,6.4,4.4],[6,7,2.64],[7,7.6,1.1],[8,7.8,1.42],[9,8.4,2.41]],"id":48921383}]}]}
{"op":"mcm","clk":"ABQAFwAK","pt":1675435140490,"mc":[{"id":"1.209492553","rc":[{"atb":[[2.5,50]],"atl":[[3.25,0]],"trd":[[3.25,52.52]],"tv":302.8,"id":51644292},{"atb":[[5.6,51.74]],"atl":[[9,5.29]],"id":43513345},{"atb":[[4.4,50]],"atl":[[7.2,6.26]],"id":36614067},{"atb":[[10.5,50],[16,0.28]],"atl":[[19.5,1.48]],"id":45930908},{"atb":[[4.1,50]],"atl":[[6.2,2.89]],"id":50567711},{"atb":[[3.5,50]],"atl":[[5.2,5.7]],"id":48921383}],"tv":733.69}]}
{"op":"mcm","clk":"ABYAJAAS","pt":1675435140530,"mc":[{"id":"1.209492553","rc":[{"bdatb":[[6,2.88,6.21],[7,2.84,4.13],[8,2.8,5.31],[9,2.78,3.9]],"bdatl":[[0,3.4,1.3],[1,3.45,3.56],[2,3.55,1.63],[3,3.65,8.11],[4,3.7,5.09],[5,3.75,6.75],[6,3.8,6.56],[7,3.85,1.8],[8,3.95,3.07],[9,4,1]],"id":51644292},{"bdatb":[[2,6.6,1.54],[3,6.4,1.02],[4,6.2,1.54],[5,6,3.47],[7,5.6,51.95],[8,5.4,2.84],[9,5.3,1.16]],"bdatl":[[0,9,5.29],[4,13.5,1.18],[5,14,8.69],[7,29,1.06]],"id":43513345},{"bdatb":[[3,5.5,6.35],[4,5.2,1.58],[5,5.1,2.41],[6,4.8,1.19],[7,4.7,1.43],[8,4.6,1.33],[9,4.5,2.04]],"bdatl":[[0,7.2,6.26]],"id":36614067},{"bdatb":[[0,15.5,2.37],[4,10.5,50.17],[5,9.8,1.03],[6,9.2,2.16],[7,7.8,1.61],[8,7.6,1.64],[9,7.4,1.47]],"bdatl":[[0,19.5,1.48],[1,20,3.42],[2,21,1.5],[3,22,1.13],[4,23,1.55],[5,25,4.71],[6,27,4.93],[7,29,7.63],[8,40,2.56],[9,44,4.69]],"id":45930908},{"bdatb":[[5,4.9,6.67],[6,4.7,1.94],[7,4.6,3.96],[8,4.4,1.31],[9,4.3,1.48]],"bdatl":[[0,6.2,2.89],[1,6.4,4.01],[2,6.6,5.59],[3,7,1.71],[4,7.2,3.14],[5,8,2.1],[6,8.2,1.71],[7,9.2,1.82],[8,9.4,11.9],[9,9.6,17.44]],"id":50567711},{"bdatb":[[3,4.3,3.33],[4,4.2,6.48],[5,4.1,2.08],[6,4,16.4],[7,3.9,34.78],[8,3.8,57.76],[9,3.7,98.29]],"bdatl":[[0,5.2,5.7],[9,8.4,2.43]],"id":48921383}]}]}
{"op":"mcm","clk":"ACUAJAAa","pt":1675435140591,"mc":[{"id":"1.209492553","rc":[{"atb":[[3.2,0]],"atl":[[3.45,4.61]],"trd":[[3.2,0.88]],"ltp":3.2,"tv":303.68,"id":51644292},{"atl":[[9.6,0]],"id":43513345},{"atb":[[6.2,4.8]],"id":36614067}],"tv":734.57}]}
{"op":"mcm","clk":"ACYAOQAb","pt":1675435140635,"mc":[{"id":"1.209492553","rc":[{"bdatb":[[0,3.15,6.09]],"bdatl":[[1,3.45,4.61],[6,3.8,8.38],[7,3.95,3.9],[8,4.2,1],[9,4.4,37.72]],"id":51644292},{"bdatb":[[5,6,3.67],[7,5.6,52.34],[8,5.4,2.87],[9,5.2,2.84]],"bdatl":[[1,9.8,2.27],[2,11.5,2.35],[3,13.5,1.18],[4,14,8.73],[5,18,1.28],[6,29,1.03],[7,34,6.06],[8,44,4.79],[9,140,1.86]],"id":43513345},{"bdatb":[[0,6.2,4.8],[5,5.1,2.64],[6,4.8,1.69],[8,4.5,2.59],[9,4.4,52.62]],"bdatl":[[8,9.2,2.33]],"id":36614067},{"bdatb":[[6,9.2,2.28],[7,8,1.11],[8,7.6,1.96]],"id":45930908},{"bdatb":[[7,4.6,4.75],[9,4.2,1.4]],"bdatl":[[6,8.2,1.78],[7,9.2,1.77],[8,9.4,12.01]],"id":50567711},{"bdatb":[[6,4,16.7],[7,3.9,35.1],[8,3.8,58.06],[9,3.7,97.31]],"bdatl":[[5,6.4,4.48],[6,6.8,1.04],[7,7,2.13],[8,7.8,1.94]],"id":48921383}]}]}
{"op":"mcm","clk":"ADAAOQAg","pt":1675435140655,"mc":[{"id":"1.209492553","rc":[{"atb":[[3.05,3.9],[3.2,2.88]],"id":51644292},{"atl":[[6.2,3.98]],"id":50567711}]}]}
{"op":"mcm","clk":"ADEAOQAg","pt":1675435140690,"mc":[{"id":"1.209492553","rc":[{"bdatb":[[0,3.2,2.88],[1,3.15,6.09],[2,3.1,1.61],[3,3.05,3.9],[4,3,1.94],[5,2.98,4.28],[6,2.92,4.17],[7,2.88,8.56],[8,2.84,1.75],[9,2.8,5.31]],"id":51644292},{"bdatb":[[5,6,4.07],[7,5.6,52.5],[8,5.4,2.27]],"bdatl":[[3,13,1.55],[4,14,8.86],[5,18,1.06],[6,34,6.68],[7,44,4.89],[8,140,1.82],[9,150,3]],"id":43513345},{"bdatb":[[5,5.1,3.12],[6,4.8,1.18],[9,4.4,52.7]],"bdatl":[[8,8.8,1.17],[9,9.2,1.89]],"id":36614067},{"bdatb":[[6,9.2,2.55],[7,7.8,1.12],[8,7.6,1.64]],"id":45930908},{"bdatl":[[0,6.2,3.98],[5,7.8,1.28],[6,8,1.43],[7,8.2,1.99],[8,9.2,1.51],[9,9.4,11.9]],"id":50567711},{"bdatb":[[6,4,17.31],[7,3.9,35.59],[8,3.8,56.93],[9,3.7,97.71]],"bdatl":[[5,6.4,5.93],[6,7,1.95],[7,7.8,1.84],[8,8.4,2.43],[9,9.2,3.45]],"id":48921383}]}]}
{"op":"mcm","clk":"AD4ATgAt","pt":1675435140770,"mc":[{"id":"1.209492553","rc":[{"atb":[[3.15,2.37]],"atl":[[3.45,3.56]],"id":51644292},{"atb":[[7.4,1.36]],"id":43513345},{"atl":[[19.5,2.51]],"id":45930908}]}]}
{"op":"mcm","clk":"AD8AXAAu","pt":1675435140823,"mc":[{"id":"1.209492553","rc":[{"bdatb":[[1,3.15,2.37],[9,2.8,5.3]],"bdatl":[[1,3.45,3.56],[9,4.3,2.05]],"id":51644292},{"bdatb":[[1,7.4,1.8],[2,7.2,3.23],[3,6.6,1.54],[4,6.4,1.02],[5,6.2,1.54],[6,6,3.47],[7,5.9,1.63],[8,5.7,1.01],[9,5.6,51.92]],"bdatl":[[4,14,8.22],[5,18,1.43],[6,34,6.72],[7,44,4.9],[8,140,1.74]],"id":43513345},{"bdatb":[[5,5.1,2.41],[6,4.9,1.17],[7,4.7,1.68],[8,4.6,1.08],[9,4.5,4.45]],"bdatl":[[9,9.4,1.99]],"id":36614067},{"bdatb":[[6,9.2,2.16],[7,7.8,1.57]],"bdatl":[[0,19.5,2.51]],"id":45930908},{"bdatb":[[7,4.6,3.96],[9,4.3,1.66]],"bdatl":[[7,8.6,1.49],[8,9.2,1.47],[9,9.4,12.01]],"id":50567711},{"bdatb":[[6,4,16.4],[7,3.9,35.96],[8,3.8,56.81],[9,3.7,98.41]],"bdatl":[[5,6.4,4.1],[6,6.8,1.04],[7,7,2.49],[8,7.8,1.9],[9,8.4,1.9]],"id":48921383}]}]}
{"op":"mcm","clk":"AE0AYgA0","pt":1675435140871,"mc":[{"id":"1.209492553","rc":[{"atb":[[3,11.94],[3.1,2.66],[3.2,4.25]],"id":51644292},{"atb":[[1.02,1.99]],"id":43513345},{"atb":[[1.02,1.99]],"id":45930908},{"atl":[[11.5,0]],"id":50567711}]}]}
{"op":"mcm","clk":"AE4AcQA2","pt":1675435140921,"mc":[{"id":"1.209492553","rc":[{"bdatb":[[0,3.2,4.25],[2,3.1,2.66],[4,3,11.94]],"id":51644292},{"bdatl":[[3,13,1.89],[5,18,1.31],[6,34,6.62],[7,44,4.93],[8,140,1.89]],"id":43513345},{"bdatl":[[8,8.8,1.66]],"id":36614067},{"bdatl":[[5,7.8,1.84],[7,8.6,1.43],[8,9.2,1.45],[9,9.4,11.9]],"id":50567711},{"bdatl":[[5,6.4,4.79],[6,6.8,1.52],[7,7,1.4],[8,7.8,1.94],[9,8.4,2.45]],"id":48921383}]}]}
{"op":"mcm","clk":"AFgAdwA8","pt":1675435140970,"mc":[{"id":"1.209492553","rc":[{"atb":[[5.7,1.64]],"id":43513345},{"atb":[[11,1.58]],"id":45930908},{"atl":[[12,0.5]],"id":50567711}]}]}
{"op":"mcm","clk":"AFoAgQEAPQ==","pt":1675435141028,"mc":[{"id":"1.209492553","rc":[{"bdatb":[[8,5.7,2.65]],"id":43513345},{"bdatb":[[4,11,1.75],[5,10.5,50],[6,9.8,1.03],[7,9.2,2.16],[8,7.8,1.57],[9,7.6,1.64]],"id":45930908}]}]}
{"op":"mcm","clk":"AGkAjwEARQ==","pt":1675435141100,"mc":[{"id":"1.209492553","rc":[{"atb":[[3.2,6.25]],"id":51644292},{"atl":[[9,2.41]],"id":43513345},{"atb":[[6.2,3.8]],"id":36614067},{"atb":[[16,0.17]],"atl":[[20,1.42],[19.5,1.24]],"id":45930908},{"atl":[[6.2,1.1],[6.4,0]],"id":50567711}]}]}
{"op":"mcm","clk":"AGkAlAEASA==","pt":1675435141159,"mc":[{"id":"1.209492553","rc":[{"bdatb":[[0,3.2,6.25],[7,2.88,2.37],[8,2.8,9.75],[9,2.76,4.55]],"bdatl":[[5,3.75,6.25],[6,3.8,8.35],[7,3.95,3.58],[8,4,1],[9,4.3,2.86]],"id":51644292},{"bdatb":[[6,6,1.82],[8,5.7,1.64],[9,5.6,53.5]],"bdatl":[[0,9,2.41],[3,13,2.38],[4,14,7.95],[5,18,1.04],[6,34,6.88],[7,44,4.83]],"id":43513345},{"bdatb":[[0,6.2,3.8],[5,4.9,2.49],[6,4.7,2.28],[7,4.5,1.67],[8,4.4,50.23],[9,4.3,12.79]],"bdatl":[[8,8.8,2.39],[9,9.4,1.78]],"id":36614067},{"bdatb":[[0,15.5,2.26],[7,9.2,1.08],[8,8.4,1.18],[9,7.6,1.94]],"bdatl":[[0,19.5,1.24],[1,20,1.42]],"id":45930908},{"bdatb":[[8,4.4,1.13],[9,4.1,51.93]],"bdatl":[[0,6.2,1.1],[1,6.6,5.59],[2,7,1.71],[3,7.2,3.14],[4,7.8,2.66],[5,8,1.43],[6,9.2,1.92],[7,9.4,11.9],[8,9.6,17.44],[9,12,1.88]],"id":50567711},{"bdatb":[[6,4,13.93],[7,3.9,34.48],[8,3.85,2.57],[9,3.8,56.82]],"bdatl":[[5,6.4,5.18],[6,7,2.65],[7,7.8,2.09],[8,8,1.03],[9,8.4,1.21]],"id":48921383}]}]}
{"op":"mcm","clk":"AHAAlgEASQ==","pt":1675435141180,"mc":[{"id":"1.209492553","rc":[{"atl":[[9.8,5.15]],"id":43513345},{"atb":[[15.5,2.21]],"atl":[[20,2.68]],"id":45930908},{"atl":[[6.4,2.88]],"id":50567711}]}]}
{"op":"mcm","clk":"AHIAnQEASQ==","pt":1675435141200,"mc":[{"id":"1.209492553","rc":[{"bdatb":[[8,2.84,5.24],[9,2.8,4.44]],"id":51644292},{"bdatb":[[8,5.8,1.7],[9,5.7,1.64]],"bdatl":[[1,9.8,5.15]],"id":43513345},{"bdatb":[[5,5,2.45],[6,4.8,1.04],[7,4.7,1.22],[8,4.5,1.89],[9,4.4,50.4]],"id":36614067},{"bdatb":[[0,15.5,2.38],[8,8.8,1.12],[9,7.6,2.02]],"bdatl":[[1,20,2.68]],"id":45930908},{"bdatl":[[1,6.4,2.88],[2,6.6,5.59],[3,7,1.71],[4,7.2,3.14],[5,7.8,2.66],[6,8,1.43],[7,9.2,1.92],[8,9.4,11.9],[9,9.6,17.44]],"id":50567711},{"bdatb":[[7,3.95,2.5],[8,3.9,34.48],[9,3.8,57.86]],"id":48921383}]}]}
