{"op":"mcm","clk":"AJVaAIExAPJP","pt":1659347568016,"mc":[{"id":"1.201590187","rc":[{"bdatb":[[7,10,13.13],[8,9.8,10.78]],"id":45323444},{"bdatb":[[8,1.94,4.77],[9,1.93,2.73]],"id":9570503},{"bdatb":[[4,5.7,3.9],[5,5.5,6.04],[6,5.4,3.07],[7,5.3,6.67],[8,5.2,3.46],[9,5.1,1.44]],"id":12989514},{"bdatl":[[0,34,1]],"id":44621159},{"bdatb":[[8,5.5,27.04],[9,5.4,14.98]],"id":44836671},{"bdatb":[[8,6.4,6.3],[9,6.2,11.96]],"id":43885158},{"bdatb":[[8,11.5,2.29],[9,10,5.25]],"id":46969227}]}]}
{"op":"mcm","clk":"AJtaAIcxAPlP","pt":1659347568157,"mc":[{"id":"1.201590187","rc":[{"atb":[[2.04,12.12]],"id":9570503}]}]}
{"op":"mcm","clk":"AJ1aAIcxAPxP","pt":1659347568207,"mc":[{"id":"1.201590187","rc":[{"bdatb":[[0,2.04,12.12]],"id":9570503},{"bdatl":[[9,15.5,3.2]],"id":12989514}]}]}
{"op":"mcm","clk":"AKNaAIoxAP5P","pt":1659347568262,"mc":[{"id":"1.201590187","rc":[{"atb":[[2.04,8.01]],"id":9570503}]}]}
{"op":"mcm","clk":"AKZaAIwxAINQ","pt":1659347568312,"mc":[{"id":"1.201590187","rc":[{"bdatb":[[0,2.04,8.01]],"id":9570503},{"bdatl":[[9,15.5,3.16]],"id":12989514}]}]}
{"op":"mcm","clk":"ALRaAJcxAJBQ","pt":1659347568550,"mc":[{"id":"1.201590187","rc":[{"atb":[[13.5,5.43],[13,2.19]],"bdatb":[[1,13,2.19]],"id":45323444},{"bdatl":[[9,2.48,6.27]],"id":9570503},{"bdatl":[[9,15.5,2.14]],"id":12989514}],"con":true}]}
{"op":"mcm","clk":"ALVaAJcxAJJQ","pt":1659347568600,"mc":[{"id":"1.201590187","rc":[{"bdatb":[[0,13.5,5.43]],"id":45323444},{"bdatl":[[7,2.44,159.13],[8,2.46,12.74],[9,2.48,3.24]],"id":9570503},{"bdatl":[[9,15,3.25]],"id":12989514}]}]}
{"op":"mcm","clk":"ANNaAKsxAKpQ","pt":1659347568971,"mc":[{"id":"1.201590187","rc":[{"atl":[[2.18,6.18]],"id":9570503}]}]}
{"op":"mcm","clk":"ANVaALAxAKxQ","pt":1659347569021,"mc":[{"id":"1.201590187","rc":[{"bdatl":[[1,2.18,6.18]],"id":9570503}]}]}
{"op":"mcm","clk":"AOBaALoxALdQ","pt":1659347569259,"mc":[{"id":"1.201590187","rc":[{"atb":[[13.5,1.18]],"id":45323444}]}]}
{"op":"mcm","clk":"AOFaALwxALtQ","pt":1659347569309,"mc":[{"id":"1.201590187","rc":[{"bdatb":[[0,13.5,1.18]],"id":45323444},{"bdatl":[[7,2.44,153.83],[8,2.46,5.25],[9,2.48,6.27]],"id":9570503},{"bdatl":[[9,15.5,2.14]],"id":12989514}]}]}
{"op":"mcm","clk":"AOhaAL0xAL1Q","pt":1659347569368,"mc":[{"id":"1.201590187","rc":[{"atb":[[12.5,1.33]],"id":45323444},{"atl":[[9.4,0]],"id":12989514},{"atl":[[7.4,7.34]],"id":44836671},{"atl":[[32,0.09]],"id":46969227}]}]}
{"op":"mcm","clk":"AOlaAL4xAMJQ","pt":1659347569419,"mc":[{"id":"1.201590187","rc":[{"bdatb":[[2,12.5,1.33]],"id":45323444},{"bdatb":[[5,5.5,3.68],[6,5.4,2.41],[7,5.3,9.8]],"bdatl":[[3,9.6,11.09],[4,10,17.36],[5,10.5,12.47],[6,11,33.84],[7,13.5,1.01],[8,15.5,2.14],[9,17,1.01]],"id":12989514},{"bdatb":[[8,11.5,1.22],[9,11,32.79]],"id":44621159},{"bdatl":[[0,7.4,7.34]],"id":44836671},{"bdatb":[[9,10,2.49]],"bdatl":[[2,34,8.21],[3,40,5.01],[4,80,1.66],[5,310,1],[6,990,2.15],[7,0,0]],"id":46969227}]}]}
{"op":"mcm","clk":"AO9aAMIxAMNQ","pt":1659347569474,"mc":[{"id":"1.201590187","rc":[{"atb":[[14,2.1],[13,6.61]],"id":45323444},{"atl":[[8.8,3.67]],"id":12989514},{"atb":[[8,3.86]],"id":43885158}]}]}
{"op":"mcm","clk":"APFaAMYxAMdQ","pt":1659347569524,"mc":[{"id":"1.201590187","rc":[{"bdatb":[[0,14,2.1],[1,13.5,1.18],[2,13,6.61],[3,12.5,1.33],[4,12,2.87],[5,11.5,5.54],[6,11,1.39],[7,10.5,1.69],[8,10,13.13],[9,9.8,10.78]],"id":45323444},{"bdatl":[[5,2.38,1.03],[6,2.4,82.43],[7,2.44,152.92],[8,2.46,5.88],[9,2.48,5.99]],"id":9570503},{"bdatl":[[2,8.8,3.67],[3,9,11.3],[4,9.6,11.09],[5,10,17.36],[6,10.5,12.47],[7,11,33.84],[8,13,1.4],[9,14.5,1.03]],"id":12989514},{"bdatl":[[9,13.5,2.76]],"id":44836671},{"bdatb":[[0,8,3.86]],"id":43885158}]}]}
{"op":"mcm","clk":"APVaAMcxAMlQ","pt":1659347569574,"mc":[{"id":"1.201590187","rc":[{"atl":[[2.16,8]],"id":9570503},{"atb":[[8,5.01]],"atl":[[9.2,3.84]],"id":43885158}]}]}
{"op":"mcm","clk":"APZaAMgxAMpQ","pt":1659347569624,"mc":[{"id":"1.201590187","rc":[{"bdatb":[[8,10,13.26],[9,9.8,10.64]],"id":45323444},{"bdatb":[[7,1.95,11.41],[8,1.93,2.73],[9,1.92,6.33]],"bdatl":[[1,2.16,8],[2,2.18,6.18],[3,2.2,4],[4,2.22,4],[5,2.3,8.58],[6,2.38,1.03],[7,2.4,82.43],[8,2.44,156.69],[9,2.46,2.14]],"id":9570503},{"bdatb":[[6,5.4,4.37],[7,5.3,7.81]],"bdatl":[[9,14.5,1.67]],"id":12989514},{"bdatb":[[7,13.5,1.75],[8,12.5,1.27],[9,11,34]],"id":44621159},{"bdatb":[[0,8,5.01]],"bdatl":[[0,9.2,3.84]],"id":43885158},{"bdatb":[[7,12.5,2.61],[8,11.5,1.51]],"id":46969227}]}]}
{"op":"mcm","clk":"AKFbAOMxAOZQ","pt":1659347570155,"mc":[{"id":"1.201590187","rc":[{"atb":[[13,2.19]],"id":45323444},{"atb":[[7.8,1.26]],"id":43885158}]}]}
{"op":"mcm","clk":"AKFbAOUxAOpQ","pt":1659347570205,"mc":[{"id":"1.201590187","rc":[{"bdatb":[[2,13,2.19]],"id":45323444},{"bdatb":[[1,7.8,1.26]],"id":43885158}]}]}
{"op":"mcm","clk":"AKZbAOgxAOtQ","pt":1659347570256,"mc":[{"id":"1.201590187","rc":[{"atl":[[23,0],[22,2.72]],"id":45323444},{"atb":[[24,5.84],[20,0]],"id":44621159}]}]}
{"op":"mcm","clk":"AKlbAOgxAO5Q","pt":1659347570306,"mc":[{"id":"1.201590187","rc":[{"bdatl":[[2,22,2.72]],"id":45323444},{"bdatb":[[8,5.2,4.88],[9,5.1,3.39]],"id":12989514},{"bdatb":[[1,24,5.84],[4,18.5,1.37],[5,15.5,4.95],[6,13.5,1.75],[7,12.5,1.27],[8,11,34],[9,10.5,2.6]],"id":44621159}]}]}
{"op":"mcm","clk":"AK1bAO0xAPBQ","pt":1659347570363,"mc":[{"id":"1.201590187","rc":[{"atb":[[14,6.18]],"id":45323444},{"atb":[[2.02,26.85]],"id":9570503}]}]}
{"op":"mcm","clk":"ALFbAO4xAPdQ","pt":1659347570413,"mc":[{"id":"1.201590187","rc":[{"bdatb":[[0,14,6.18]],"id":45323444},{"bdatb":[[1,2.02,26.85]],"bdatl":[[9,2.46,4.01]],"id":9570503},{"bdatl":[[9,14,1.69]],"id":12989514}]}]}
{"op":"mcm","clk":"ALVbAPQxAPdQ","pt":1659347570467,"mc":[{"id":"1.201590187","rc":[{"atb":[[2.02,30.75]],"id":9570503}]}]}
{"op":"mcm","clk":"ALhbAPYxAPxQ","pt":1659347570517,"mc":[{"id":"1.201590187","rc":[{"bdatb":[[1,2.02,30.75]],"id":9570503}]}]}
{"op":"mcm","clk":"AL9bAPoxAP9Q","pt":1659347570567,"mc":[{"id":"1.201590187","rc":[{"atb":[[14,6.35]],"bdatb":[[0,14,6.35]],"id":45323444},{"atl":[[1000,0.41]],"bdatl":[[5,1000,0.41]],"id":44621159}]}]}
{"op":"mcm","clk":"ANBbAIUyAI1R","pt":1659347570755,"mc":[{"id":"1.201590187","rc":[{"atl":[[1000,0]],"id":44621159}]}]}
{"op":"mcm","clk":"ANJbAIUyAJJR","pt":1659347570805,"mc":[{"id":"1.201590187","rc":[{"bdatl":[[5,0,0]],"id":44621159}]}]}
{"op":"mcm","clk":"ANVbAIoyAJNR","pt":1659347570856,"mc":[{"id":"1.201590187","rc":[{"atb":[[22,0]],"atl":[[38,1]],"id":44621159}]}]}
{"op":"mcm","clk":"ANlbAIoyAJpR","pt":1659347570906,"mc":[{"id":"1.201590187","rc":[{"bdatb":[[2,21,5],[3,18.5,1.37],[4,15.5,4.95],[5,13.5,1.75],[6,12.5,1.27],[7,11,34],[8,10.5,2.6],[9,10,103.41]],"bdatl":[[1,38,1],[2,40,3.27],[3,95,2.64],[4,170,2],[5,990,2.07]],"id":44621159},{"bdatb":[[9,10,4.06]],"id":46969227}]}]}
{"op":"mcm","clk":"AOFbAJEyAJxR","pt":1659347570957,"mc":[{"id":"1.201590187","rc":[{"atb":[[21,6.8]],"id":44621159}]}]}
{"op":"mcm","clk":"AOVbAJQyAKJR","pt":1659347571007,"mc":[{"id":"1.201590187","rc":[{"bdatb":[[2,21,6.8]],"id":44621159}]}]}
{"op":"mcm","clk":"APBbAJsyAKpR","pt":1659347571159,"mc":[{"id":"1.201590187","rc":[{"atb":[[14,2.27]],"id":45323444}]}]}
{"op":"mcm","clk":"APNbAKAyAK9R","pt":1659347571209,"mc":[{"id":"1.201590187","rc":[{"bdatb":[[0,14,2.27]],"id":45323444},{"bdatl":[[9,2.46,3.11]],"id":9570503},{"bdatl":[[9,14,1.1]],"id":12989514}]}]}
{"op":"mcm","clk":"AP9bAKcyALJR","pt":1659347571363,"mc":[{"id":"1.201590187","rc":[{"atb":[[14.5,3.96]],"atl":[[16.5,0]],"id":45323444}]}]}
{"op":"mcm","clk":"AINcAKgyALlR","pt":1659347571413,"mc":[{"id":"1.201590187","rc":[{"bdatb":[[0,14.5,3.96],[1,14,2.27],[2,13.5,1.18],[3,13,2.19],[4,12.5,1.33],[5,12,2.87],[6,11.5,5.54],[7,11,1.39],[8,10.5,1.69],[9,10,13.26]],"bdatl":[[0,19.5,1.41]],"id":45323444},{"bdatb":[[3,1.98,36.93],[4,1.97,2.53],[5,1.96,2.62],[6,1.95,14.11],[7,1.94,3.34],[8,1.92,9.07],[9,1.91,107.36]],"bdatl":[[6,2.36,1.04],[8,2.42,4.64],[9,2.44,156.13]],"id":9570503},{"bdatb":[[2,6.2,10.3],[3,6,6.68],[4,5.7,5.95],[5,5.5,3.69],[7,5.3,5.59],[8,5.2,7.14]],"bdatl":[[8,12.5,1.44],[9,13.5,1.76]],"id":12989514},{"bdatb":[[4,15.5,4.19],[5,13.5,2.02],[6,12.5,1.89],[9,10,102.23]],"id":44621159},{"bdatb":[[3,6,29.74],[4,5.9,9],[5,5.8,30.83],[6,5.7,44.86],[7,5.6,46.64],[8,5.5,28.69],[9,5.4,14.24]],"id":44836671},{"bdatb":[[4,7.2,3.71],[5,7,5],[6,6.6,47.75],[7,6.4,7.03],[8,6.2,12.81],[9,6,14.48]],"id":43885158},{"bdatb":[[7,12.5,2.2],[8,11.5,2.06]],"id":46969227}]}]}
{"op":"mcm","clk":"AJJcAK8yAMJR","pt":1659347571578,"mc":[{"id":"1.201590187","rc":[{"atb":[[14.5,4.13]],"atl":[[19.5,1.54]],"id":45323444},{"atb":[[3.9,61.72]],"id":12989514}]}]}
{"op":"mcm","clk":"AJRcALIyAMZR","pt":1659347571628,"mc":[{"id":"1.201590187","rc":[{"bdatb":[[0,14.5,4.13]],"bdatl":[[0,19.5,1.54]],"id":45323444},{"bdatb":[[6,1.95,15.41],[7,1.94,2.04]],"id":9570503},{"bdatb":[[7,5.3,6.07],[8,5.2,6.65]],"id":12989514},{"bdatb":[[5,13.5,2.21],[6,12.5,1.7],[9,10,102.49]],"id":44621159},{"bdatb":[[7,12.5,2.4],[8,11.5,1.85]],"id":46969227}]}]}
{"op":"mcm","clk":"AJhcALUyAMhR","pt":1659347571681,"mc":[{"id":"1.201590187","rc":[{"atb":[[9.4,54.1]],"id":45323444},{"atb":[[1.79,51.72]],"id":9570503},{"atb":[[6.6,64.72]],"bdatb":[[6,6.6,64.99]],"id":43885158}]}]}
{"op":"mcm","clk":"ALtcAMoyAOVR","pt":1659347572160,"mc":[{"id":"1.201590187","rc":[{"atb":[[14.5,0.17]],"id":45323444}]}]}
{"op":"mcm","clk":"AL5cAMsyAOhR","pt":1659347572210,"mc":[{"id":"1.201590187","rc":[{"bdatb":[[0,14,2.44],[1,13.5,1.18],[2,13,2.19],[3,12.5,1.33],[4,12,2.87],[5,11.5,5.54],[6,11,1.39],[7,10.5,1.69],[8,10,13.26],[9,9.8,10.64]],"id":45323444},{"bdatl":[[8,2.44,156.69],[9,2.46,4.01]],"id":9570503},{"bdatl":[[8,13,1.4],[9,14,1.28]],"id":12989514}]}]}
{"op":"mcm","clk":"AMVcAM4yAOtR","pt":1659347572276,"mc":[{"id":"1.201590187","rc":[{"atb":[[10.5,0]],"id":45323444}]}]}
{"op":"mcm","clk":"AMpcANAyAOxR","pt":1659347572326,"mc":[{"id":"1.201590187","rc":[{"bdatb":[[7,10,13.35],[8,9.8,10.64],[9,9.6,21]],"id":45323444}]}]}
{"op":"mcm","clk":"AMtcANEyAO9R","pt":1659347572377,"mc":[{"id":"1.201590187","rc":[{"atb":[[14,6.18],[1.02,1.6]],"bdatb":[[0,14,6.35]],"id":45323444},{"bdatl":[[9,14,1.69]],"id":12989514}]}]}
{"op":"mcm","clk":"APpcAO4yAI5S","pt":1659347573057,"mc":[{"id":"1.201590187","rc":[{"atb":[[14,2.1]],"id":45323444}]}]}
{"op":"mcm","clk":"AP1cAPIyAJNS","pt":1659347573107,"mc":[{"id":"1.201590187","rc":[{"bdatb":[[0,14,2.27]],"id":45323444},{"bdatl":[[9,2.46,3.14]],"id":9570503},{"bdatl":[[9,14,1.11]],"id":12989514}]}]}
{"op":"mcm","clk":"AINdAPIyAJNS","pt":1659347573159,"mc":[{"id":"1.201590187","rc":[{"atb":[[14.5,4.13]],"id":45323444}]}]}
{"op":"mcm","clk":"AIZdAPIyAJtS","pt":1659347573209,"mc":[{"id":"1.201590187","rc":[{"bdatb":[[0,14.5,4.13],[1,14,2.1],[2,13.5,1.18],[3,13,2.19],[4,12.5,1.33],[5,12,2.87],[6,11.5,5.54],[7,11,1.39],[8,10,13.35],[9,9.8,10.64]],"id":45323444},{"bdatl":[[8,2.42,4.64],[9,2.44,156.13]],"id":9570503},{"bdatl":[[8,12.5,1.44],[9,13.5,1.76]],"id":12989514}]}]}
{"op":"mcm","clk":"ALZdAIwzAL1S","pt":1659347573847,"mc":[{"id":"1.201590187","rc":[{"atb":[[14.5,0.17]],"id":45323444}]}]}
{"op":"mcm","clk":"ALtdAI0zAMFS","pt":1659347573897,"mc":[{"id":"1.201590187","rc":[{"bdatb":[[0,14,2.27],[1,13.5,1.18],[2,13,2.19],[3,12.5,1.33],[4,12,2.87],[5,11.5,5.54],[6,11,1.39],[7,10,13.35],[8,9.8,10.64],[9,9.6,21]],"id":45323444},{"bdatl":[[8,2.44,156.69],[9,2.46,3.14]],"id":9570503},{"bdatl":[[8,13,1.4],[9,14,1.11]],"id":12989514}]}]}
{"op":"mcm","clk":"AMRdAJEzAMZS","pt":1659347573962,"mc":[{"id":"1.201590187","rc":[{"atb":[[14,6.18]],"id":45323444}]}]}
{"op":"mcm","clk":"AMhdAJczAMdS","pt":1659347574012,"mc":[{"id":"1.201590187","rc":[{"bdatb":[[0,14,6.35]],"id":45323444},{"bdatl":[[9,2.46,4.01]],"id":9570503},{"bdatl":[[9,14,1.69]],"id":12989514}]}]}
{"op":"mcm","clk":"ANJdAJgzAMhS","pt":1659347574071,"mc":[{"id":"1.201590187","rc":[{"atb":[[24,1.49],[22,4.76]],"id":44621159}]}]}
{"op":"mcm","clk":"ANJdAJ0zAMlS","pt":1659347574121,"mc":[{"id":"1.201590187","rc":[{"bdatb":[[1,24,1.49],[2,22,4.76],[3,21,6.8],[4,18.5,1.37],[5,15.5,4.19],[6,13.5,2.21],[7,12.5,1.7],[8,11,34],[9,10.5,2.6]],"id":44621159}]}]}
{"op":"mcm","clk":"AIleALszAO1S","pt":1659347574756,"mc":[{"id":"1.201590187","rc":[{"atb":[[2.02,26.85]],"atl":[[2.14,63.08],[2.3,5.17]],"id":9570503},{"atb":[[6.4,17.76]],"atl":[[8.4,4.09],[9,9.01]],"id":12989514},{"atb":[[6.8,17.72]],"atl":[[7.6,156.73]],"id":44836671},{"atb":[[7.6,6.9]],"atl":[[9.4,2.35]],"id":43885158}]}]}
{"op":"mcm","clk":"AI1eALszAO1S","pt":1659347574806,"mc":[{"id":"1.201590187","rc":[{"bdatb":[[1,2.02,26.85]],"bdatl":[[0,2.14,63.93],[5,2.3,5.17]],"id":9570503},{"bdatb":[[1,6.4,17.76],[6,5.4,3.27],[7,5.3,7.18],[8,5.2,5.14]],"bdatl":[[1,8.4,4.09],[3,9,9.01]],"id":12989514},{"bdatb":[[8,11,32.13],[9,10.5,2.7]],"id":44621159},{"bdatb":[[0,6.8,18.07]],"bdatl":[[1,7.6,156.73]],"id":44836671},{"bdatb":[[2,7.6,6.9]],"bdatl":[[1,9.4,2.35]],"id":43885158},{"bdatb":[[9,10,2.6]],"id":46969227}]}]}
{"op":"mcm","clk":"AJNeAL8zAPNS","pt":1659347574865,"mc":[{"id":"1.201590187","rc":[{"atb":[[14,2.1]],"id":45323444}]}]}
{"op":"mcm","clk":"AJdeAL8zAPRS","pt":1659347574915,"mc":[{"id":"1.201590187","rc":[{"bdatb":[[0,14,2.27]],"id":45323444},{"bdatl":[[9,2.46,3.14]],"id":9570503},{"bdatl":[[9,14,1.11]],"id":12989514}]}]}
{"op":"mcm","clk":"AJ9eAMUzAPhS","pt":1659347574965,"mc":[{"id":"1.201590187","rc":[{"atb":[[2.02,22.7]],"atl":[[2.14,59.19],[2.3,1.72]],"id":9570503},{"atb":[[6.4,15.48]],"atl":[[8.4,1.76],[9,6.82]],"id":12989514},{"atb":[[6.8,15.36]],"atl":[[7.6,154.34]],"id":44836671},{"atb":[[7.6,4.53]],"atl":[[9.4,0]],"id":43885158}]}]}
{"op":"mcm","clk":"AKJeAMkzAPpS","pt":1659347575015,"mc":[{"id":"1.201590187","rc":[{"bdatb":[[8,9.8,9],[9,9.6,22.68]],"id":45323444},{"bdatb":[[1,2.02,22.7]],"bdatl":[[0,2.14,60.04],[5,2.3,1.72]],"id":9570503},{"bdatb":[[1,6.4,15.48],[8,5.2,3.54]],"bdatl":[[1,8.4,1.76],[3,9,6.82]],"id":12989514},{"bdatb":[[8,11,31.87],[9,10.5,1.13]],"id":44621159},{"bdatb":[[0,6.8,15.71]],"bdatl":[[1,7.6,154.34]],"id":44836671},{"bdatb":[[2,7.6,4.53]],"bdatl":[[1,9.6,14.54],[2,11,3.46],[3,11.5,2.64],[4,12,1.4],[5,12.5,18],[6,14,1],[7,14.5,1],[8,15,12],[9,15.5,1]],"id":43885158},{"bdatb":[[8,11,1.9],[9,10,2.29]],"id":46969227}]}]}
{"op":"mcm","clk":"ANNeAO8zAJhT","pt":1659347575642,"mc":[{"id":"1.201590187","rc":[{"atb":[[14,6.18]],"id":45323444}]}]}
{"op":"mcm","clk":"ANZeAO8zAJlT","pt":1659347575692,"mc":[{"id":"1.201590187","rc":[{"bdatb":[[0,14,6.35]],"id":45323444},{"bdatl":[[9,2.46,4.01]],"id":9570503},{"bdatl":[[9,14,1.69]],"id":12989514}]}]}
{"op":"mcm","clk":"ANxeAPUzAJtT","pt":1659347575749,"mc":[{"id":"1.201590187","rc":[{"atb":[[7.6,7.85]],"id":43885158}]}]}
{"op":"mcm","clk":"AN5eAPUzAJ5T","pt":1659347575800,"mc":[{"id":"1.201590187","rc":[{"bdatb":[[2,7.6,7.85]],"id":43885158}]}]}
{"op":"mcm","clk":"AO1eAII0AKhT","pt":1659347575959,"mc":[{"id":"1.201590187","rc":[{"atb":[[2.04,1.21]],"id":9570503},{"atb":[[8,3.86]],"atl":[[9.2,2.69]],"id":43885158}]}]}
{"op":"mcm","clk":"AO9eAII0AKlT","pt":1659347576009,"mc":[{"id":"1.201590187","marketDefinition":{"bspMarket":true,"turnInPlayEnabled":true,"persistenceEnabled":true,"marketBaseRate":5,"eventId":"31628781","eventTypeId":"7","numberOfWinners":1,"bettingType":"ODDS","marketType":"WIN","marketTime":"2022-08-01T10:00:00.000Z","suspendTime":"2022-08-01T10:00:00.000Z","bspReconciled":false,"complete":true,"inPlay":false,"crossMatching":true,"runnersVoidable":false,"numberOfActiveRunners":7,"betDelay":0,"status":"OPEN","runners":[{"adjustmentFactor":4.027,"status":"ACTIVE","sortPriority":1,"id":44621159},{"adjustmentFactor":7.322,"status":"ACTIVE","sortPriority":2,"id":45323444},{"adjustmentFactor":50.251,"status":"ACTIVE","sortPriority":3,"id":9570503},{"adjustmentFactor":12.203,"status":"ACTIVE","sortPriority":4,"id":44836671},{"adjustmentFactor":10.326,"status":"ACTIVE","sortPriority":5,"id":43885158},{"adjustmentFactor":4.027,"status":"ACTIVE","sortPriority":6,"id":46969227},{"adjustmentFactor":11.844,"status":"ACTIVE","sortPriority":7,"id":12989514}],"regulators":["MR_INT"],"venue":"DAX","countryCode":"FR","discountAllowed":true,"timezone":"Europe/London","openDate":"2022-08-01T10:00:00.000Z","version":4679024403,"raceType":"Flat","priceLadderDefinition":{"type":"CLASSIC"}},"rc":[{"bdatb":[[7,10,12.29],[8,9.8,9.94],[9,9.6,22.82]],"id":45323444},{"bdatb":[[0,2.04,1.21],[6,1.95,12.69],[7,1.93,4.79],[8,1.92,9.08]],"bdatl":[[8,2.44,152.92]],"id":9570503},{"bdatb":[[4,5.7,4.33],[5,5.6,1.65],[6,5.5,3.69],[7,5.4,3.27],[8,5.3,7.18],[9,5.2,3.54]],"bdatl":[[8,14,2.36],[9,15,1.19]],"id":12989514},{"bdatb":[[6,13.5,1.82],[7,12.5,2.13]],"id":44621159},{"bdatb":[[8,5.5,27.01],[9,5.4,14.98]],"bdatl":[[9,13.5,1.74]],"id":44836671},{"bdatb":[[0,8,3.86]],"bdatl":[[0,9.2,2.69]],"id":43885158},{"bdatb":[[7,12.5,1.98],[8,11,2.38]],"id":46969227}]}]}
{"op":"mcm","clk":"APVeAIY0AKxT","pt":1659347576060,"mc":[{"id":"1.201590187","rc":[{"atl":[[23,1.82],[22,0.82]],"id":45323444}]}]}
{"op":"mcm","clk":"APheAIY0AK9T","pt":1659347576114,"mc":[{"id":"1.201590187","rc":[{"bdatl":[[2,23,2.64]],"id":45323444},{"bdatb":[[9,5.2,3.46]],"id":12989514}]}]}
{"op":"mcm","clk":"AP9eAIs0ALNT","pt":1659347576164,"mc":[{"id":"1.201590187","rc":[{"atl":[[34,5.09],[32,3.32]],"id":46969227}]}]}
{"op":"mcm","clk":"AIFfAI00ALVT","pt":1659347576214,"mc":[{"id":"1.201590187","rc":[{"bdatl":[[2,32,3.32],[3,34,5.09],[4,40,5.01],[5,80,1.66],[6,310,1],[7,990,2.15]],"id":46969227}]}]}
{"op":"mcm","clk":"AI9fAJI0ALdT","pt":1659347576357,"mc":[{"id":"1.201590187","rc":[{"atb":[[14,2.1]],"id":45323444}]}]}
{"op":"mcm","clk":"AJFfAJI0ALtT","pt":1659347576407,"mc":[{"id":"1.201590187","rc":[{"bdatb":[[0,14,2.27]],"id":45323444},{"bdatl":[[9,15.5,1.12]],"id":12989514}]}]}
{"op":"mcm","clk":"AJZfAJk0ALxT","pt":1659347576461,"mc":[{"id":"1.201590187","rc":[{"atb":[[14.5,4.13]],"id":45323444}]}]}
{"op":"mcm","clk":"AJlfAJk0AL9T","pt":1659347576511,"mc":[{"id":"1.201590187","rc":[{"bdatb":[[0,14.5,4.13],[1,14,2.1],[2,13.5,1.18],[3,13,2.19],[4,12.5,1.33],[5,12,2.87],[6,11.5,5.54],[7,11,1.39],[8,10,12.29],[9,9.8,9.94]],"id":45323444},{"bdatl":[[8,2.44,156.97],[9,2.46,7.81]],"id":9570503},{"bdatl":[[8,13.5,2.43],[9,14.5,1.22]],"id":12989514}]}]}
{"op":"mcm","clk":"AKxfAKY0AMtT","pt":1659347576771,"mc":[{"id":"1.201590187","rc":[{"atb":[[2.02,17.99],[2,13.38]],"id":9570503}]}]}
{"op":"mcm","clk":"AK5fAKk0AM9T","pt":1659347576821,"mc":[{"id":"1.201590187","rc":[{"bdatb":[[1,2.02,17.99],[2,2,13.38]],"id":9570503},{"bdatl":[[9,15.5,1.94]],"id":12989514}]}]}
{"op":"mcm","clk":"ALNfAKs0ANFT","pt":1659347576871,"mc":[{"id":"1.201590187","rc":[{"atl":[[11,0.01]],"id":43885158}]}]}
{"op":"mcm","clk":"ALdfAKw0ANNT","pt":1659347576921,"mc":[{"id":"1.201590187","rc":[{"bdatl":[[2,11.5,2.65],[3,12,1.4],[4,12.5,18],[5,14,1],[6,14.5,1],[7,15,12],[8,15.5,1],[9,16.5,8.94]],"id":43885158}]}]}
{"op":"mcm","clk":"AL1fAK80ANVT","pt":1659347576980,"mc":[{"id":"1.201590187","rc":[{"atl":[[10.5,3.45]],"id":43885158}]}]}
{"op":"mcm","clk":"AMZfALA0ANlT","pt":1659347577030,"mc":[{"id":"1.201590187","marketDefinition":{"bspMarket":true,"turnInPlayEnabled":true,"persistenceEnabled":true,"marketBaseRate":5,"eventId":"31628781","eventTypeId":"7","numberOfWinners":1,"bettingType":"ODDS","marketType":"WIN","marketTime":"2022-08-01T10:00:00.000Z","suspendTime":"2022-08-01T10:00:00.000Z","bspReconciled":false,"complete":true,"inPlay":false,"crossMatching":true,"runnersVoidable":false,"numberOfActiveRunners":7,"betDelay":0,"status":"OPEN","runners":[{"adjustmentFactor":4.027,"status":"ACTIVE","sortPriority":1,"id":44621159},{"adjustmentFactor":7.322,"status":"ACTIVE","sortPriority":2,"id":45323444},{"adjustmentFactor":50.251,"status":"ACTIVE","sortPriority":3,"id":9570503},{"adjustmentFactor":12.203,"status":"ACTIVE","sortPriority":4,"id":44836671},{"adjustmentFactor":10.326,"status":"ACTIVE","sortPriority":5,"id":43885158},{"adjustmentFactor":4.027,"status":"ACTIVE","sortPriority":6,"id":46969227},{"adjustmentFactor":11.844,"status":"ACTIVE","sortPriority":7,"id":12989514}],"regulators":["MR_INT"],"venue":"DAX","countryCode":"FR","discountAllowed":true,"timezone":"Europe/London","openDate":"2022-08-01T10:00:00.000Z","version":4679024405,"raceType":"Flat","priceLadderDefinition":{"type":"CLASSIC"}},"rc":[{"bdatl":[[2,10.5,3.45],[3,11.5,2.65],[4,12,1.4],[5,12.5,18],[6,14,1],[7,14.5,1],[8,15,12],[9,15.5,1]],"id":43885158}]}]}
{"op":"mcm","clk":"AMhfALI0ANlT","pt":1659347577086,"mc":[{"id":"1.201590187","rc":[{"atb":[[2.02,22.02]],"atl":[[2.14,62.89]],"id":9570503},{"atb":[[6.6,6.84]],"atl":[[8.4,4.02]],"id":12989514},{"atb":[[6.8,17.69]],"atl":[[7.6,156.76]],"id":44836671},{"atb":[[7.6,10.09]],"atl":[[9.4,2.18]],"id":43885158}]}]}
{"op":"mcm","clk":"AMpfALI0AN5T","pt":1659347577136,"mc":[{"id":"1.201590187","rc":[{"bdatb":[[8,10,13.22],[9,9.8,10.15]],"id":45323444},{"bdatb":[[1,2.02,22.02],[7,1.94,4.77]],"bdatl":[[0,2.14,63.74],[7,2.4,83.27],[8,2.42,5.91],[9,2.44,152.09]],"id":9570503},{"bdatb":[[0,6.6,6.84],[4,5.7,5.26],[5,5.5,4.4],[6,5.4,3.27],[7,5.3,7.18],[8,5.2,3.46],[9,5.1,1.64]],"bdatl":[[1,8.4,4.02],[9,14.5,1.13]],"id":12989514},{"bdatb":[[7,12.5,2.12],[9,10.5,2.94]],"id":44621159},{"bdatb":[[0,6.8,18.04],[8,5.5,27.97],[9,5.4,14.73]],"bdatl":[[1,7.6,156.76]],"id":44836671},{"bdatb":[[2,7.6,10.09]],"bdatl":[[1,9.4,2.18],[2,9.6,14.54],[3,10.5,3.45],[4,11.5,2.65],[5,12,1.4],[6,12.5,18],[7,14,1],[8,14.5,1],[9,15,12]],"id":43885158},{"bdatb":[[8,11.5,1.76],[9,10,2.85]],"id":46969227}]}]}
{"op":"mcm","clk":"ANNfALY0AN9T","pt":1659347577190,"mc":[{"id":"1.201590187","rc":[{"atb":[[14.5,0.17]],"atl":[[20,2]],"id":45323444},{"atb":[[2.02,25.96]],"atl":[[2.14,66.54]],"id":9570503},{"atb":[[6.6,9.24]],"atl":[[8.4,6.36]],"id":12989514},{"atb":[[6.8,19.93]],"atl":[[7.6,158.98]],"id":44836671},{"atb":[[7.6,12.32]],"atl":[[9.4,4.46]],"id":43885158}]}]}
{"op":"mcm","clk":"ANNfALc0AOFT","pt":1659347577241,"mc":[{"id":"1.201590187","rc":[{"bdatb":[[0,14,2.27],[1,13.5,1.18],[2,13,2.19],[3,12.5,1.33],[4,12,2.87],[5,11.5,5.54],[6,11,1.39],[7,10,13.22],[8,9.8,10.78],[9,9.6,21]],"bdatl":[[1,20,2]],"id":45323444},{"bdatb":[[1,2.02,25.96]],"bdatl":[[0,2.14,67.39],[8,2.44,156.14],[9,2.46,2.87]],"id":9570503},{"bdatb":[[0,6.6,9.24],[6,5.4,2.91],[7,5.2,3.46],[8,5.1,8.21],[9,5,2.86]],"bdatl":[[1,8.4,6.36],[8,14,2.36],[9,15.5,1.12]],"id":12989514},{"bdatb":[[8,11,32.98],[9,10,105.8]],"id":44621159},{"bdatb":[[0,6.8,20.28]],"bdatl":[[1,7.6,158.98]],"id":44836671},{"bdatb":[[2,7.6,12.32]],"bdatl":[[1,9.4,4.46]],"id":43885158},{"bdatb":[[8,11.5,2.3],[9,10,3.53]],"id":46969227}]}]}
{"op":"mcm","clk":"AN9fALs0AOdT","pt":1659347577351,"mc":[{"id":"1.201590187","rc":[{"atb":[[14.5,0],[14,6.18]],"atl":[[26,5.04],[19.5,1.41]],"id":45323444},{"atb":[[8.2,6.32]],"id":43885158}]}]}
{"op":"mcm","clk":"AORfALw0AOdT","pt":1659347577401,"mc":[{"id":"1.201590187","rc":[{"bdatb":[[0,14,6.18]],"bdatl":[[0,19.5,1.41],[4,26,5.04]],"id":45323444},{"bdatl":[[7,2.38,20.75],[8,2.4,74.91],[9,2.44,155.39]],"id":9570503},{"bdatb":[[4,5.7,4.81],[5,5.6,1.16],[6,5.5,3.69],[7,5.4,2.44],[8,5.2,3.46],[9,5.1,8.21]],"bdatl":[[8,13.5,3.99],[9,15,1.11]],"id":12989514},{"bdatb":[[9,10,105.81]],"id":44621159},{"bdatb":[[8,5.5,27.51],[9,5.4,15.2]],"bdatl":[[8,13,42.09],[9,13.5,1.55]],"id":44836671},{"bdatb":[[0,8.2,6.32],[1,8,3.86],[2,7.8,1.26],[3,7.6,12.32],[4,7.4,10.26],[5,7.2,3.71],[6,7,5],[7,6.6,64.99],[8,6.4,7.03],[9,6.2,12.81]],"id":43885158},{"bdatb":[[8,11.5,2.31]],"id":46969227}]}]}
{"op":"mcm","clk":"AOlfAL80AOpT","pt":1659347577462,"mc":[{"id":"1.201590187","rc":[{"atb":[[14,6.35]],"atl":[[25,5.61]],"id":45323444},{"atb":[[8,4.16]],"id":43885158}]}]}
{"op":"mcm","clk":"AOxfAL80AOtT","pt":1659347577512,"mc":[{"id":"1.201590187","rc":[{"bdatb":[[0,14,6.35]],"bdatl":[[3,25,5.61]],"id":45323444},{"bdatb":[[1,8,4.16]],"id":43885158}]}]}
{"op":"mcm","clk":"APJfAME0AO1T","pt":1659347577563,"mc":[{"id":"1.201590187","rc":[{"atl":[[19.5,1.54]],"id":45323444}]}]}
{"op":"mcm","clk":"APVfAMU0APBT","pt":1659347577613,"mc":[{"id":"1.201590187","rc":[{"bdatl":[[0,19.5,1.54]],"id":45323444},{"bdatb":[[4,5.7,5.26],[5,5.5,4.4],[6,5.4,2.91],[7,5.2,3.46],[8,5.1,8.21],[9,5,2.86]],"id":12989514},{"bdatb":[[9,10,105.8]],"id":44621159},{"bdatb":[[8,5.5,27.97],[9,5.4,14.73]],"id":44836671},{"bdatb":[[8,11.5,2.3]],"id":46969227}]}]}
{"op":"mcm","clk":"APhfAMY0APFT","pt":1659347577663,"mc":[{"id":"1.201590187","rc":[{"atl":[[1000,0]],"id":45323444}]}]}
{"op":"mcm","clk":"AP1fAMk0APRT","pt":1659347577759,"mc":[{"id":"1.201590187","rc":[{"atl":[[24,0.48]],"id":45323444},{"atb":[[2,21]],"id":9570503}]}]}
{"op":"mcm","clk":"AIJgAMk0APZT","pt":1659347577809,"mc":[{"id":"1.201590187","rc":[{"bdatl":[[3,25,6.09]],"id":45323444},{"bdatb":[[2,2,21]],"id":9570503},{"bdatb":[[8,5.1,10.48],[9,4.9,7.6]],"id":12989514}]}]}
{"op":"mcm","clk":"AJVgANc0AINU","pt":1659347578169,"mc":[{"id":"1.201590187","rc":[{"atb":[[14,2.27],[1.01,48.08]],"atl":[[23,0],[22,2.72]],"id":45323444},{"atb":[[8.2,0]],"id":43885158}]}]}
{"op":"mcm","clk":"AJdgANc0AIVU","pt":1659347578220,"mc":[{"id":"1.201590187","rc":[{"bdatb":[[0,14,2.27]],"bdatl":[[2,22,2.72]],"id":45323444},{"bdatl":[[6,2.38,1.03],[7,2.4,83.65],[8,2.44,156.75],[9,2.46,1.86]],"id":9570503},{"bdatb":[[7,5.2,11.5],[8,5.1,2.27],[9,4.9,7.61]],"bdatl":[[8,14,2.42],[9,15.5,1.05]],"id":12989514},{"bdatl":[[8,13,41.9],[9,13.5,1.74]],"id":44836671},{"bdatb":[[0,8,4.16],[1,7.8,1.26],[2,7.6,12.32],[3,7.4,10.26],[4,7.2,3.71],[5,7,5],[6,6.6,64.99],[7,6.4,7.03],[8,6.2,12.81],[9,6,14.48]],"id":43885158}]}]}
{"op":"mcm","clk":"AJxgANw0AIZU","pt":1659347578276,"mc":[{"id":"1.201590187","rc":[{"atb":[[1.01,47.24]],"id":45323444}]}]}
{"op":"mcm","clk":"AKFgAOA0AIlU","pt":1659347578340,"mc":[{"id":"1.201590187","rc":[{"atb":[[14.5,3.96]],"id":45323444}]}]}
{"op":"mcm","clk":"AKNgAOA0AIpU","pt":1659347578390,"mc":[{"id":"1.201590187","rc":[{"bdatb":[[0,14.5,3.96],[1,14,2.27],[2,13.5,1.18],[3,13,2.19],[4,12.5,1.33],[5,12,2.87],[6,11.5,5.54],[7,11,1.39],[8,10,13.22],[9,9.8,10.78]],"id":45323444},{"bdatl":[[6,2.36,1.04],[7,2.4,84.27],[8,2.42,10.01],[9,2.44,153.2]],"id":9570503},{"bdatl":[[8,13.5,2.61],[9,14.5,1.51]],"id":12989514}]}]}
{"op":"mcm","clk":"AKVgAOU0AIxU","pt":1659347578441,"mc":[{"id":"1.201590187","rc":[{"atb":[[14.5,4.13],[1.01,45.55]],"atl":[[19.5,1.41]],"id":45323444},{"atl":[[8.8,0]],"id":12989514}]}]}
{"op":"mcm","clk":"AKhgAOY0AI5U","pt":1659347578492,"mc":[{"id":"1.201590187","rc":[{"bdatb":[[0,14.5,4.13]],"bdatl":[[0,19.5,1.41]],"id":45323444},{"bdatl":[[8,2.42,11.03],[9,2.44,152.19]],"id":9570503},{"bdatb":[[4,5.7,4.81],[5,5.6,1.16],[6,5.5,3.69],[7,5.4,2.44],[8,5.2,11.5],[9,5.1,2.27]],"bdatl":[[2,9,6.82],[3,9.6,11.09],[4,10,17.36],[5,10.5,12.47],[6,11,33.84],[7,13.5,2.61],[8,14.5,1.51],[9,17.5,2.17]],"id":12989514},{"bdatb":[[9,10,105.81]],"id":44621159},{"bdatb":[[8,5.5,27.51],[9,5.4,15.2]],"id":44836671},{"bdatb":[[8,11.5,2.31]],"id":46969227}]}]}
{"op":"mcm","clk":"ALBgAOw0AJNU","pt":1659347578556,"mc":[{"id":"1.201590187","rc":[{"atb":[[14.5,5.83]],"id":45323444},{"atl":[[9.4,3.67]],"id":12989514}]}]}
{"op":"mcm","clk":"ALNgAOw0AJhU","pt":1659347578606,"mc":[{"id":"1.201590187","rc":[{"bdatb":[[0,14.5,5.83]],"id":45323444},{"bdatl":[[8,2.42,11.12],[9,2.44,152.42]],"id":9570503},{"bdatl":[[3,9.4,3.67],[4,9.6,11.09],[5,10,17.36],[6,10.5,12.47],[7,11,33.84],[8,13.5,2.61],[9,14.5,1.51]],"id":12989514}]}]}
{"op":"mcm","clk":"AMFgAPg0AKZU","pt":1659347578752,"mc":[{"id":"1.201590187","rc":[{"atb":[[2,23.35]],"id":9570503}]}]}
{"op":"mcm","clk":"AMNgAPw0AKhU","pt":1659347578802,"mc":[{"id":"1.201590187","rc":[{"bdatb":[[2,2,23.35]],"id":9570503}]}]}
{"op":"mcm","clk":"AMlgAP40AK9U","pt":1659347578864,"mc":[{"id":"1.201590187","rc":[{"atl":[[20,0]],"id":45323444}]}]}
{"op":"mcm","clk":"AM1gAP80ALBU","pt":1659347578914,"mc":[{"id":"1.201590187","rc":[{"bdatl":[[1,22,2.72],[2,25,6.09],[3,26,5.04],[4,27,3.85],[5,29,8.93],[6,50,8],[7,55,9],[8,60,10],[9,65,11]],"id":45323444},{"bdatb":[[7,1.94,1.43],[8,1.92,3.38],[9,1.91,116.48]],"id":9570503},{"bdatb":[[5,5.5,1.18],[6,5.4,3.76],[7,5.3,2.33],[8,5.2,3.96]],"id":12989514},{"bdatb":[[7,12,2.2],[8,11,31.6],[9,10.5,1.45]],"id":44621159},{"bdatb":[[9,5.4,14]],"id":44836671},{"bdatb":[[7,6.4,6.02],[8,6.2,11.05],[9,6,16.9]],"id":43885158},{"bdatb":[[8,10.5,2.48],[9,10,2]],"id":46969227}]}]}
{"op":"mcm","clk":"AN1gAIw1ALtU","pt":1659347579172,"mc":[{"id":"1.201590187","rc":[{"atb":[[14.5,1.86]],"atl":[[21,1.15]],"id":45323444}]}]}
{"op":"mcm","clk":"AOFgAI01AMBU","pt":1659347579222,"mc":[{"id":"1.201590187","rc":[{"bdatb":[[0,14.5,1.86]],"bdatl":[[1,21,1.15],[2,22,2.72],[3,25,6.09],[4,26,5.04],[5,27,3.85],[6,29,8.93],[7,50,8],[8,55,9],[9,60,10]],"id":45323444},{"bdatb":[[8,1.93,3.36],[9,1.92,9.08]],"bdatl":[[8,2.42,4.08],[9,2.44,158.49]],"id":9570503},{"bdatb":[[5,5.6,1.16],[6,5.5,3.21],[7,5.3,2.82],[8,5.2,8.61]],"bdatl":[[8,13.5,2.15],[9,14.5,1.13]],"id":12989514},{"bdatb":[[7,12.5,2.12],[8,11,31.62],[9,10.5,1.43]],"id":44621159},{"bdatb":[[8,6.2,13.86],[9,6,14]],"id":43885158},{"bdatb":[[8,11,2.37],[9,10,2.02]],"id":46969227}]}]}
{"op":"mcm","clk":"AO5gAJE1AMdU","pt":1659347579381,"mc":[{"id":"1.201590187","rc":[{"atb":[[14,6.35]],"id":45323444}]}]}
{"op":"mcm","clk":"APFgAJE1AMtU","pt":1659347579431,"mc":[{"id":"1.201590187","rc":[{"bdatb":[[1,14,6.35]],"id":45323444},{"bdatl":[[9,2.44,159.08]],"id":9570503}]}]}
{"op":"mcm","clk":"APVgAJM1AMxU","pt":1659347579481,"mc":[{"id":"1.201590187","rc":[{"atb":[[23,4.55]],"id":44621159}]}]}
{"op":"mcm","clk":"APdgAJM1ANBU","pt":1659347579532,"mc":[{"id":"1.201590187","rc":[{"bdatb":[[2,23,4.55],[3,22,4.76],[4,21,6.8],[5,18.5,1.37],[6,15.5,4.19],[7,13.5,1.82],[8,12.5,2.12],[9,11,31.62]],"id":44621159}]}]}
{"op":"mcm","clk":"APtgAJY1ANVU","pt":1659347579582,"mc":[{"id":"1.201590187","rc":[{"atb":[[22,0]],"bdatb":[[3,21,6.8],[4,18.5,1.37],[5,15.5,4.19],[6,13.5,1.82],[7,12.5,2.12],[8,11,31.62],[9,10.5,1.43]],"id":44621159}]}]}
{"op":"mcm","clk":"AIhhAJ01ANtU","pt":1659347579783,"mc":[{"id":"1.201590187","rc":[{"atb":[[13,4.31]],"id":45323444},{"atb":[[7.6,9]],"id":43885158}]}]}
{"op":"mcm","clk":"AIthAJ01AOFU","pt":1659347579833,"mc":[{"id":"1.201590187","rc":[{"bdatb":[[3,13,4.31]],"id":45323444},{"bdatb":[[2,7.6,9]],"id":43885158}]}]}
{"op":"mcm","clk":"AJ1hAKM1AOxU","pt":1659347580057,"mc":[{"id":"1.201590187","rc":[{"atb":[[14,2.27],[13,3.31]],"id":45323444}]}]}
{"op":"mcm","clk":"AKBhAKM1APBU","pt":1659347580107,"mc":[{"id":"1.201590187","rc":[{"bdatb":[[1,14,2.27],[3,13,3.31]],"id":45323444},{"bdatl":[[9,2.44,158.49]],"id":9570503}]}]}
{"op":"mcm","clk":"AKVhAKU1APFU","pt":1659347580160,"mc":[{"id":"1.201590187","rc":[{"atb":[[13,2.31]],"id":45323444}]}]}
{"op":"mcm","clk":"AKlhAKU1APRU","pt":1659347580210,"mc":[{"id":"1.201590187","rc":[{"bdatb":[[3,13,2.31]],"id":45323444}]}]}
{"op":"mcm","clk":"AK5hAKs1APVU","pt":1659347580276,"mc":[{"id":"1.201590187","rc":[{"atb":[[14.5,5.83]],"id":45323444}]}]}
{"op":"mcm","clk":"ALFhAKw1APpU","pt":1659347580326,"mc":[{"id":"1.201590187","rc":[{"bdatb":[[0,14.5,5.83]],"id":45323444},{"bdatl":[[8,2.42,11.12],[9,2.44,152.42]],"id":9570503},{"bdatl":[[8,13.5,2.61],[9,14.5,1.51]],"id":12989514}]}]}
{"op":"mcm","clk":"AMhhALo1AItV","pt":1659347580689,"mc":[{"id":"1.201590187","rc":[{"atb":[[8.2,16.95],[6.4,22.59]],"id":45323444},{"atb":[[1.55,149.09],[1.41,297.56]],"atl":[[2.98,12.2],[3.4,17.2]],"id":9570503},{"atb":[[3.5,48.8],[4.3,24.85]],"id":12989514},{"atb":[[13.5,6.56],[10,115.56]],"id":44621159},{"atb":[[3.6,46.92]],"atl":[[11.5,12.2]],"id":44836671},{"atb":[[5.2,45.33],[4,40.67]],"atl":[[14,13.2]],"id":43885158},{"atb":[[11.5,7.81],[9,15.25]],"id":46969227}]}]}
{"op":"mcm","clk":"AMthALo1AJFV","pt":1659347580739,"mc":[{"id":"1.201590187","rc":[{"bdatb":[[6,13.5,8.38]],"id":44621159},{"bdatl":[[7,11.5,12.2],[8,12,1.41],[9,13,41.9]],"id":44836671},{"bdatl":[[7,14,13.2]],"id":43885158},{"bdatb":[[8,11.5,8.6],[9,11,1.58]],"id":46969227}]}]}
{"op":"mcm","clk":"ANNhAL41AJJV","pt":1659347580798,"mc":[{"id":"1.201590187","rc":[{"atb":[[3.05,20.2],[2.66,45.18],[2.22,20.2]],"id":45323444},{"atb":[[3.05,20.2],[2.66,45.18]],"atl":[[12,12.33]],"id":12989514},{"atb":[[3.05,20.2],[2.22,20.2]],"id":44621159},{"atb":[[3.05,20.2],[4.4,24.12],[2.66,45.18]],"atl":[[13,59.08]],"id":44836671},{"atb":[[3.05,20.2],[2.66,45.18]],"atl":[[16.5,26.14]],"id":43885158},{"atb":[[3.05,20.2],[2.66,45.18],[2.22,20.2]],"id":46969227}]}]}
{"op":"mcm","clk":"ANhhAMA1AJVV","pt":1659347580848,"mc":[{"id":"1.201590187","rc":[{"bdatl":[[8,12,12.53],[9,13.5,2.28]],"id":12989514},{"bdatl":[[9,13,59.1]],"id":44836671}]}]}
{"op":"mcm","clk":"AOVhAMQ1AJxV","pt":1659347580965,"mc":[{"id":"1.201590187","rc":[{"atb":[[15,1],[6,10.1],[4.1,10.1]],"atl":[[20,1],[19.5,0.41]],"id":45323444},{"atb":[[2.22,20.2]],"atl":[[14,17.2]],"id":12989514},{"atb":[[26,1],[2.66,45.18],[4.1,10.1],[10,120.66]],"atl":[[38,2],[34,0]],"id":44621159},{"atb":[[2.22,20.2]],"id":44836671},{"atb":[[4.1,10.1],[2.22,20.2]],"id":43885158},{"atb":[[6,10.1],[4.1,10.1],[10,7.1]],"id":46969227}]}]}
{"op":"mcm","clk":"AOVhAMQ1AKBV","pt":1659347581016,"mc":[{"id":"1.201590187","rc":[{"bdatb":[[0,15,1],[1,14.5,5.83],[2,14,2.27],[3,13.5,1.18],[4,13,2.31],[5,12.5,1.33],[6,12,2.87],[7,11.5,5.54],[8,11,1.23],[9,10,12.46]],"bdatl":[[0,20,1.41]],"id":45323444},{"bdatb":[[6,1.94,4.13],[7,1.93,8.67],[8,1.92,13.9],[9,1.91,107.36]],"bdatl":[[6,2.34,1.05],[7,2.38,9.89],[8,2.4,74.46],[9,2.42,11.46]],"id":9570503},{"bdatb":[[4,5.6,4.41],[5,5.5,4.98],[6,5.3,2.73],[7,5.2,8.7],[8,5.1,2.27],[9,5,4.14]],"bdatl":[[8,12,12.54],[9,12.5,1]],"id":12989514},{"bdatb":[[0,26,1],[1,25,2.41],[2,24,1.49],[3,23,4.55],[4,21,6.8],[5,18.5,1.37],[6,15.5,4.19],[7,13.5,7.14],[8,13,1.29],[9,12.5,2.13]],"bdatl":[[0,38,2],[1,40,3.27],[2,95,2.64],[3,170,2],[4,990,2.07],[5,0,0]],"id":44621159},{"bdatb":[[6,5.7,44.55],[7,5.6,46.8],[8,5.5,23.16],[9,5.4,18.08]],"bdatl":[[9,13,59.3]],"id":44836671},{"bdatb":[[7,6.4,2.97],[8,6.2,17]],"id":43885158},{"bdatb":[[7,11.5,10.21],[8,11,2.13],[9,10,7.17]],"id":46969227}]}]}
{"op":"mcm","clk":"AO1hAMg1AKJV","pt":1659347581070,"mc":[{"id":"1.201590187","rc":[{"atb":[[15,1.16],[14.5,1.86],[13.5,0.18]],"atl":[[21,1.28]],"id":45323444},{"atb":[[24,0.49]],"id":44621159}]}]}
{"op":"mcm","clk":"AO1hAM01AKZV","pt":1659347581121,"mc":[{"id":"1.201590187","rc":[{"bdatb":[[0,15,1.16],[1,14.5,1.86],[3,13,2.49],[4,12.5,1.33],[5,12,2.87],[6,11.5,5.54],[7,11,1.23],[8,10,12.46],[9,9.8,11.72]],"bdatl":[[1,21,1.28]],"id":45323444},{"bdatl":[[9,2.42,4.59]],"id":9570503},{"bdatb":[[5,5.5,5.38],[6,5.3,2.33],[7,5.2,9.23],[9,5,3.59]],"bdatl":[[9,12.5,1.19]],"id":12989514},{"bdatb":[[2,23,5.04],[3,21,6.8],[4,18.5,1.37],[5,15.5,4.19],[6,13.5,7.14],[7,13,1.29],[8,12.5,2.13],[9,11,31.87]],"id":44621159},{"bdatb":[[9,10,7.39]],"id":46969227}]}]}
{"op":"mcm","clk":"APNhAM01AKdV","pt":1659347581177,"mc":[{"id":"1.201590187","rc":[{"atb":[[12.5,1.14]],"id":45323444},{"atb":[[6,10.1]],"id":44621159}]}]}
{"op":"mcm","clk":"APNhANI1AK1V","pt":1659347581227,"mc":[{"id":"1.201590187","rc":[{"bdatb":[[4,12.5,1.14]],"id":45323444}]}]}
{"op":"mcm","clk":"APhhANM1AK9V","pt":1659347581277,"mc":[{"id":"1.201590187","rc":[{"atb":[[14,6.35]],"id":45323444}]}]}
{"op":"mcm","clk":"APthANc1ALJV","pt":1659347581328,"mc":[{"id":"1.201590187","rc":[{"bdatb":[[2,14,6.35]],"id":45323444}]}]}
{"op":"mcm","clk":"AItiAOI1AMFV","pt":1659347581582,"mc":[{"id":"1.201590187","rc":[{"atl":[[30,4.62],[32,0.09]],"id":46969227}]}]}
{"op":"mcm","clk":"AJFiAOM1AMpV","pt":1659347581632,"mc":[{"id":"1.201590187","rc":[{"bdatl":[[1,30,4.62],[2,34,5.18],[3,40,5.01],[4,80,1.66],[5,310,1],[6,990,2.15],[7,0,0]],"id":46969227}]}]}
{"op":"mcm","clk":"AJpiAOs1AM5V","pt":1659347581785,"mc":[{"id":"1.201590187","rc":[{"atb":[[13,0.19]],"id":45323444}]}]}
{"op":"mcm","clk":"AJtiAOs1ANJV","pt":1659347581835,"mc":[{"id":"1.201590187","rc":[{"bdatb":[[3,12.5,1.51],[4,12,2.87],[5,11.5,5.54],[6,11,1.23],[7,10,12.46],[8,9.8,11.72],[9,9.6,21]],"id":45323444}]}]}
{"op":"mcm","clk":"AKxiAPM1AN1V","pt":1659347581960,"mc":[{"id":"1.201590187","rc":[{"atb":[[14,2.27]],"id":45323444},{"atb":[[25,0.11]],"id":44621159},{"atl":[[30,3.52]],"id":46969227}]}]}
{"op":"mcm","clk":"ALFiAPM1AN9V","pt":1659347582010,"mc":[{"id":"1.201590187","rc":[{"bdatb":[[2,14,2.27]],"id":45323444},{"bdatl":[[9,2.42,3.03]],"id":9570503},{"bdatb":[[1,23,5.15],[2,21,6.8],[3,18.5,1.37],[4,15.5,4.19],[5,13.5,7.14],[6,13,1.29],[7,12.5,2.13],[8,11,31.87],[9,10.5,1.18]],"id":44621159},{"bdatl":[[1,30,3.52]],"id":46969227}]}]}
{"op":"mcm","clk":"ALRiAPY1AOBV","pt":1659347582060,"mc":[{"id":"1.201590187","rc":[{"atb":[[15,5.01]],"id":45323444}]}]}
{"op":"mcm","clk":"ALZiAPc1AONV","pt":1659347582110,"mc":[{"id":"1.201590187","rc":[{"bdatb":[[0,15,5.01]],"id":45323444},{"bdatl":[[7,2.38,12.95],[8,2.4,74.48],[9,2.42,1.05]],"id":9570503},{"bdatl":[[9,12.5,1.88]],"id":12989514}]}]}
{"op":"mcm","clk":"ALxiAPk1AORV","pt":1659347582164,"mc":[{"id":"1.201590187","rc":[{"atb":[[24,2.91]],"id":44621159}]}]}
{"op":"mcm","clk":"AL9iAPk1AOpV","pt":1659347582214,"mc":[{"id":"1.201590187","rc":[{"bdatl":[[8,2.4,75.54],[9,2.42,7.38]],"id":9570503},{"bdatb":[[1,24,3.02],[2,23,4.55],[3,21,6.8],[4,18.5,1.37],[5,15.5,4.19],[6,13.5,7.14],[7,13,1.29],[8,12.5,2.13],[9,11,31.87]],"id":44621159}]}]}
{"op":"mcm","clk":"AMxiAP81APBV","pt":1659347582376,"mc":[{"id":"1.201590187","rc":[{"atb":[[8.2,1.15]],"atl":[[9.2,3.84]],"id":43885158},{"atl":[[27,1.25]],"id":46969227}]}]}
{"op":"mcm","clk":"ANBiAII2APVV","pt":1659347582426,"mc":[{"id":"1.201590187","rc":[{"bdatb":[[7,10,13.52],[8,9.8,10.64]],"id":45323444},{"bdatb":[[6,1.94,14.44],[7,1.93,2.96],[8,1.92,9.22]],"bdatl":[[7,2.36,2.95],[8,2.38,13.98],[9,2.4,75.54]],"id":9570503},{"bdatb":[[4,5.7,1.4],[5,5.6,4.59],[6,5.5,3.74],[7,5.3,4.32],[8,5.2,7.19],[9,5.1,2.27]],"bdatl":[[7,11,34.06],[8,12,12.33]],"id":12989514},{"bdatb":[[6,13.5,8.62],[7,12.5,1.86],[8,11,31.87],[9,10.5,2.19]],"id":44621159},{"bdatb":[[8,5.5,24.13],[9,5.4,18.76]],"bdatl":[[8,12,1.62],[9,13,59.63]],"id":44836671},{"bdatb":[[0,8.2,1.15],[1,8,4.16],[2,7.8,1.26],[3,7.6,9],[4,7.4,10.26],[5,7.2,3.71],[6,7,5],[7,6.6,64.99],[8,6.4,6.1],[9,6.2,13.78]],"bdatl":[[0,9.2,3.84]],"id":43885158},{"bdatb":[[7,11.5,10.84],[8,11,1.46]],"bdatl":[[0,27,1.25],[1,28,7.64],[2,30,3.52],[3,34,5.18],[4,40,5.01],[5,80,1.66],[6,310,1],[7,990,2.15]],"id":46969227}]}]}
{"op":"mcm","clk":"ANRiAII2APZV","pt":1659347582476,"mc":[{"id":"1.201590187","rc":[{"atb":[[14,0.17]],"id":45323444},{"atl":[[7.8,4.19]],"id":12989514}]}]}
{"op":"mcm","clk":"ANtiAIY2APdV","pt":1659347582526,"mc":[{"id":"1.201590187","rc":[{"bdatb":[[2,12.5,1.68],[3,12,2.87],[4,11.5,5.54],[5,11,1.23],[6,10,13.26],[7,9.8,9],[8,9.6,21],[9,9.4,54.1]],"id":45323444},{"bdatb":[[7,1.93,2.43],[8,1.91,107.36],[9,1.89,1.38]],"id":9570503},{"bdatl":[[0,7.8,4.19]],"id":12989514},{"bdatb":[[7,11,33.92],[8,10.5,2.19],[9,10,121.54]],"id":44621159},{"bdatb":[[9,5.4,18.57]],"id":44836671},{"bdatb":[[9,6.2,10.76]],"id":43885158},{"bdatb":[[7,11.5,10.62],[8,10,9.26],[9,9.6,2.26]],"id":46969227}]}]}
{"op":"mcm","clk":"AN5iAIc2APhV","pt":1659347582576,"mc":[{"id":"1.201590187","rc":[{"atb":[[2.04,7.94]],"id":9570503},{"atl":[[8.2,2.52]],"id":12989514},{"atl":[[30,2.87],[28,11.16]],"id":46969227}]}]}
{"op":"mcm","clk":"AOViAIk2APxV","pt":1659347582626,"mc":[{"id":"1.201590187","rc":[{"bdatb":[[8,9.6,21.11],[9,9.4,54.27]],"id":45323444},{"bdatb":[[0,2.04,7.94],[8,1.91,107.9],[9,1.89,10.39]],"id":9570503},{"bdatl":[[1,8.2,2.52],[2,8.4,6.36],[3,9,6.82],[4,9.4,3.67],[5,9.6,11.09],[6,10,17.36],[7,10.5,12.47],[8,11,34.06],[9,12,13.5]],"id":12989514},{"bdatb":[[7,11.5,2.16],[8,11,31.69],[9,10.5,2.19]],"id":44621159},{"bdatl":[[8,12,2.2],[9,13,59.64]],"id":44836671},{"bdatb":[[8,10,9.25]],"bdatl":[[1,28,11.16],[2,30,2.87]],"id":46969227}]}]}
{"op":"mcm","clk":"APFiAJA2AIJW","pt":1659347582875,"mc":[{"id":"1.201590187","rc":[{"atb":[[15,1.16]],"id":45323444},{"atb":[[24,0.49]],"id":44621159}]}]}
{"op":"mcm","clk":"APRiAJE2AIZW","pt":1659347582925,"mc":[{"id":"1.201590187","rc":[{"bdatb":[[0,15,1.16]],"id":45323444},{"bdatl":[[8,2.38,6.96],[9,2.4,77.51]],"id":9570503},{"bdatb":[[1,23,5.15],[2,21,6.8],[3,18.5,1.37],[4,15.5,4.19],[5,13.5,8.62],[6,11.5,2.16],[7,11,31.69],[8,10.5,2.19],[9,10,123.61]],"id":44621159}]}]}
{"op":"mcm","clk":"AP9iAJc2AI5W","pt":1659347583086,"mc":[{"id":"1.201590187","rc":[{"atb":[[14.5,5.83]],"id":45323444}]}]}
{"op":"mcm","clk":"AIFjAJg2AJVW","pt":1659347583137,"mc":[{"id":"1.201590187","rc":[{"bdatb":[[1,14.5,5.83]],"id":45323444}]}]}
{"op":"mcm","clk":"AIRjAJo2AJVW","pt":1659347583191,"mc":[{"id":"1.201590187","rc":[{"atb":[[20,3.01]],"id":46969227}]}]}
{"op":"mcm","clk":"AIdjAJs2AJtW","pt":1659347583241,"mc":[{"id":"1.201590187","rc":[{"bdatb":[[1,20,3.01]],"id":46969227}]}]}
{"op":"mcm","clk":"AI5jAJ02AJtW","pt":1659347583300,"mc":[{"id":"1.201590187","rc":[{"atb":[[25,2.41]],"id":44621159},{"atb":[[1.02,1.63]],"id":46969227}]}]}
{"op":"mcm","clk":"AJBjAJ82AJ9W","pt":1659347583350,"mc":[{"id":"1.201590187","rc":[{"bdatl":[[9,2.4,78.39]],"id":9570503},{"bdatb":[[1,25,2.41],[2,23,5.04],[3,21,6.8],[4,18.5,1.37],[5,15.5,4.19],[6,13.5,8.62],[7,11.5,2.16],[8,11,31.69],[9,10.5,2.19]],"id":44621159}]}]}
{"op":"mcm","clk":"ALRjALc2AMNW","pt":1659347583986,"mc":[{"id":"1.201590187","rc":[{"atb":[[14.5,1.86]],"id":45323444},{"atb":[[25,0.11]],"id":44621159}]}]}
{"op":"mcm","clk":"ALdjALk2AMhW","pt":1659347584036,"mc":[{"id":"1.201590187","rc":[{"bdatb":[[1,14.5,1.86]],"id":45323444},{"bdatl":[[9,2.4,77.51]],"id":9570503},{"bdatb":[[1,23,5.15],[2,21,6.8],[3,18.5,1.37],[4,15.5,4.19],[5,13.5,8.62],[6,11.5,2.16],[7,11,31.69],[8,10.5,2.19],[9,10,123.61]],"id":44621159}]}]}
{"op":"mcm","clk":"AL5jALw2ANBW","pt":1659347584187,"mc":[{"id":"1.201590187","rc":[{"atb":[[24,2.91]],"id":44621159}]}]}
{"op":"mcm","clk":"AMBjAL02ANVW","pt":1659347584237,"mc":[{"id":"1.201590187","rc":[{"bdatl":[[9,2.4,78.39]],"id":9570503},{"bdatb":[[1,24,3.02],[2,23,4.55],[3,21,6.8],[4,18.5,1.37],[5,15.5,4.19],[6,13.5,8.62],[7,11.5,2.16],[8,11,31.69],[9,10.5,2.19]],"id":44621159}]}]}
{"op":"mcm","clk":"AMRjAL42ANhW","pt":1659347584291,"mc":[{"id":"1.201590187","rc":[{"atl":[[9.2,4.54],[9,2.17]],"id":12989514}]}]}
{"op":"mcm","clk":"AMdjAL82ANtW","pt":1659347584341,"mc":[{"id":"1.201590187","rc":[{"bdatl":[[3,9,2.17],[4,9.2,4.54],[5,9.4,3.67],[6,9.6,11.09],[7,10,17.36],[8,10.5,12.47],[9,11,34.06]],"id":12989514}]}]}
{"op":"mcm","clk":"AOdjAM42APdW","pt":1659347584772,"mc":[{"id":"1.201590187","rc":[{"atb":[[12.5,6.7],[12,7.33]],"id":45323444},{"atb":[[24,7.26]],"id":44621159}]}]}
{"op":"mcm","clk":"AOljAM82APhW","pt":1659347584822,"mc":[{"id":"1.201590187","rc":[{"bdatb":[[2,12.5,7.24],[3,12,7.33]],"id":45323444},{"bdatb":[[1,24,7.37]],"id":44621159}]}]}
{"op":"mcm","clk":"AO9jANA2APxW","pt":1659347584884,"mc":[{"id":"1.201590187","rc":[{"atb":[[24,4.84],[23,0]],"id":44621159}]}]}
{"op":"mcm","clk":"APZjANQ2AP1W","pt":1659347584935,"mc":[{"id":"1.201590187","rc":[{"bdatb":[[1,24,4.95],[2,21,6.8],[3,18.5,1.37],[4,15.5,4.19],[5,13.5,8.62],[6,11.5,2.16],[7,11,31.69],[8,10.5,2.19],[9,10,123.61]],"id":44621159}]}]}
{"op":"mcm","clk":"APpjANU2AP9W","pt":1659347584985,"mc":[{"id":"1.201590187","rc":[{"atb":[[25,2.41]],"bdatb":[[1,25,2.41],[2,24,4.84],[3,21,6.8],[4,18.5,1.37],[5,15.5,4.19],[6,13.5,8.62],[7,11.5,2.16],[8,11,31.69],[9,10.5,2.19]],"id":44621159}]}]}
{"op":"mcm","clk":"AI1kAOI2AIxX","pt":1659347585287,"mc":[{"id":"1.201590187","rc":[{"atb":[[1.02,0]],"id":45323444}]}]}
{"op":"mcm","clk":"AJJkAOY2AJJX","pt":1659347585397,"mc":[{"id":"1.201590187","rc":[{"atb":[[13,1.79]],"id":45323444}]}]}
{"op":"mcm","clk":"AJVkAOc2AJRX","pt":1659347585447,"mc":[{"id":"1.201590187","rc":[{"bdatb":[[2,13,2.14],[3,12.5,6.7],[4,12,7.33],[5,11.5,5.54],[6,11,1.23],[7,10,13.26],[8,9.8,9],[9,9.6,21.11]],"id":45323444}]}]}
{"op":"mcm","clk":"AKhkAPQ2AKFX","pt":1659347585667,"mc":[{"id":"1.201590187","rc":[{"atb":[[8.8,34.48]],"id":46969227}]}]}
{"op":"mcm","clk":"ALBkAPc2AK5X","pt":1659347585778,"mc":[{"id":"1.201590187","rc":[{"atb":[[13,5.92],[12,2.87]],"id":45323444},{"atb":[[2.02,28.24]],"id":9570503}]}]}
{"op":"mcm","clk":"ALBkAPc2ALNX","pt":1659347585828,"mc":[{"id":"1.201590187","rc":[{"bdatb":[[2,13,6.27],[4,12,2.87]],"id":45323444},{"bdatb":[[1,2.02,28.24]],"id":9570503}]}]}
{"op":"mcm","clk":"AL9kAP42AL5X","pt":1659347585989,"mc":[{"id":"1.201590187","rc":[{"atb":[[21,5]],"id":44621159}]}]}
{"op":"mcm","clk":"AMFkAIE3AMFX","pt":1659347586040,"mc":[{"id":"1.201590187","rc":[{"bdatb":[[3,21,5]],"id":44621159}]}]}
{"op":"mcm","clk":"AMRkAII3AMNX","pt":1659347586090,"mc":[{"id":"1.201590187","rc":[{"atb":[[14.5,0.17]],"bdatb":[[1,13,6.44],[2,12.5,6.7],[3,12,2.87],[4,11.5,5.54],[5,11,1.23],[6,10,13.26],[7,9.8,9],[8,9.6,21.11],[9,9.4,54.27]],"id":45323444},{"atb":[[24,6.64]],"bdatb":[[2,24,6.64]],"id":44621159},{"bdatl":[[8,2.38,4.39],[9,2.4,72.42]],"id":9570503}]}]}
{"op":"mcm","clk":"AOdkAJY3AN5X","pt":1659347586602,"mc":[{"id":"1.201590187","rc":[{"atb":[[5.6,63.72]],"id":44836671}]}]}
{"op":"mcm","clk":"AOtkAJg3AN9X","pt":1659347586652,"mc":[{"id":"1.201590187","rc":[{"bdatb":[[7,5.6,64.04]],"id":44836671}]}]}
{"op":"mcm","clk":"APtkAJ03AOtX","pt":1659347586783,"mc":[{"id":"1.201590187","rc":[{"atb":[[13.5,4.43],[13,1.79]],"id":45323444}]}]}
{"op":"mcm","clk":"APtkAKA3AO9X","pt":1659347586833,"mc":[{"id":"1.201590187","rc":[{"bdatb":[[1,13.5,4.77],[2,13,1.79],[3,12.5,6.7],[4,12,2.87],[5,11.5,5.54],[6,11,1.23],[7,10,13.26],[8,9.8,9],[9,9.6,21.11]],"id":45323444}]}]}
{"op":"mcm","clk":"AIBlAKA3APJX","pt":1659347586883,"mc":[{"id":"1.201590187","rc":[{"atb":[[8.8,48.84]],"id":46969227}]}]}
{"op":"mcm","clk":"AKZlALA3AIhY","pt":1659347587389,"mc":[{"id":"1.201590187","rc":[{"atb":[[12,0]],"id":45323444}]}]}
{"op":"mcm","clk":"AKZlALI3AItY","pt":1659347587439,"mc":[{"id":"1.201590187","rc":[{"bdatb":[[4,11.5,5.54],[5,11,1.23],[6,10,13.26],[7,9.8,9],[8,9.6,21.11],[9,9.4,54.27]],"id":45323444}]}]}
{"op":"mcm","clk":"AK5lALM3AItY","pt":1659347587494,"mc":[{"id":"1.201590187","rc":[{"atb":[[13.5,0.18],[11.5,8.41]],"id":45323444},{"atb":[[5.4,36.73],[5.8,10]],"id":44836671}]}]}
{"op":"mcm","clk":"ALJlALc3AJFY","pt":1659347587544,"mc":[{"id":"1.201590187","rc":[{"bdatb":[[1,13,2.31],[2,12.5,6.7],[3,11.5,8.41],[4,11,1.23],[5,10,13.26],[6,9.8,9],[7,9.6,21.11],[8,9.4,54.27],[9,9.2,13.96]],"id":45323444},{"bdatb":[[5,5.8,10],[9,5.4,41.3]],"id":44836671}]}]}
{"op":"mcm","clk":"ALdlALg3AJJY","pt":1659347587605,"mc":[{"id":"1.201590187","rc":[{"atb":[[13,6.22]],"id":45323444}]}]}
{"op":"mcm","clk":"ALtlALs3AJVY","pt":1659347587656,"mc":[{"id":"1.201590187","rc":[{"bdatb":[[1,13,6.74]],"id":45323444}]}]}
{"op":"mcm","clk":"AMRlAL83AJlY","pt":1659347587802,"mc":[{"id":"1.201590187","rc":[{"atb":[[12.5,1.14]],"id":45323444}]}]}
{"op":"mcm","clk":"AMVlAMA3AJ9Y","pt":1659347587852,"mc":[{"id":"1.201590187","rc":[{"bdatb":[[2,12.5,1.14]],"id":45323444}]}]}
{"op":"mcm","clk":"ANtlANE3ALNY","pt":1659347588181,"mc":[{"id":"1.201590187","rc":[{"atb":[[13,4.61]],"id":45323444}]}]}
{"op":"mcm","clk":"ANtlANY3ALVY","pt":1659347588231,"mc":[{"id":"1.201590187","rc":[{"bdatb":[[1,13,5.13]],"id":45323444}]}]}
{"op":"mcm","clk":"AN5lANc3ALZY","pt":1659347588281,"mc":[{"id":"1.201590187","rc":[{"atb":[[13,0.19],[1.02,1.6]],"id":45323444}]}]}
{"op":"mcm","clk":"AOJlANk3ALlY","pt":1659347588332,"mc":[{"id":"1.201590187","rc":[{"bdatb":[[1,12.5,1.85],[2,11.5,8.41],[3,11,1.23],[4,10,13.26],[5,9.8,9],[6,9.6,21.11],[7,9.4,54.27],[8,9.2,13.96],[9,9,13.1]],"id":45323444}]}]}
{"op":"mcm","clk":"AOllAOA3AL9Y","pt":1659347588482,"mc":[{"id":"1.201590187","rc":[{"atb":[[13.5,4.43]],"id":45323444}]}]}
{"op":"mcm","clk":"AOxlAOI3AMFY","pt":1659347588532,"mc":[{"id":"1.201590187","rc":[{"bdatb":[[1,13.5,4.77],[2,12.5,1.33],[3,11.5,8.41],[4,11,1.23],[5,10,13.26],[6,9.8,9],[7,9.6,21.11],[8,9.4,54.27],[9,9.2,13.96]],"id":45323444}]}]}
{"op":"mcm","clk":"APxlAO43ANBY","pt":1659347588796,"mc":[{"id":"1.201590187","rc":[{"atb":[[8.2,0]],"atl":[[9.2,2.69]],"id":43885158},{"atl":[[27,0.1]],"id":46969227}]}]}
{"op":"mcm","clk":"AP9lAPA3ANZY","pt":1659347588846,"mc":[{"id":"1.201590187","rc":[{"bdatb":[[5,10,12.46],[6,9.8,9.81],[7,9.6,21],[8,9.4,54.1],[9,9.2,14.25]],"id":45323444},{"bdatb":[[6,1.94,4.13],[7,1.93,8.67],[8,1.92,4.15],[9,1.91,107.36]],"bdatl":[[7,2.38,7.32],[8,2.4,72.42],[9,2.42,4.56]],"id":9570503},{"bdatb":[[4,5.6,4.41],[5,5.5,5.38],[6,5.3,2.33],[7,5.2,9.23],[8,5.1,2.27],[9,5,3.59]],"bdatl":[[9,11,33.84]],"id":12989514},{"bdatb":[[6,13.5,7.14],[7,13,1.29],[8,11.5,2.44],[9,11,31.69]],"id":44621159},{"bdatb":[[8,5.5,23.16],[9,5.4,40.81]],"bdatl":[[8,12,1.41],[9,12.5,1.32]],"id":44836671},{"bdatb":[[0,8,4.16],[1,7.8,1.26],[2,7.6,9],[3,7.4,10.26],[4,7.2,3.71],[5,7,5],[6,6.6,64.99],[7,6.4,2.97],[8,6.2,13.98],[9,6,17.44]],"bdatl":[[0,9.2,2.69]],"id":43885158},{"bdatb":[[7,11.5,10.21],[8,10,9.69],[9,9.6,1.29]],"bdatl":[[0,28,11.26],[1,30,2.87],[2,34,5.18],[3,40,5.01],[4,80,1.66],[5,310,1],[6,990,2.15],[7,0,0]],"id":46969227}]}]}
{"op":"mcm","clk":"AINmAPI3ANZY","pt":1659347588899,"mc":[{"id":"1.201590187","rc":[{"atb":[[6.8,5.07]],"id":12989514}]}]}
{"op":"mcm","clk":"AIdmAPM3AN5Y","pt":1659347588949,"mc":[{"id":"1.201590187","rc":[{"bdatl":[[6,2.32,1.06],[7,2.34,6.39],[8,2.36,1.04],[9,2.38,2.58]],"id":9570503},{"bdatb":[[0,6.8,5.07],[1,6.6,9.24],[2,6.4,15.48],[3,6.2,10.3],[4,6,6.68],[5,5.6,4.41],[6,5.5,5.38],[7,5.3,2.33],[8,5.2,9.23],[9,5.1,2.27]],"id":12989514},{"bdatl":[[8,12,2.76],[9,13,59.39]],"id":44836671},{"bdatl":[[9,15,12.16]],"id":43885158}]}]}
{"op":"mcm","clk":"AI1mAPg3AOFY","pt":1659347589009,"mc":[{"id":"1.201590187","rc":[{"atb":[[6.4,8.14]],"id":12989514},{"atl":[[29,3.57],[28,7.64]],"id":46969227}]}]}
{"op":"mcm","clk":"AJZmAPo3AOZY","pt":1659347589059,"mc":[{"id":"1.201590187","rc":[{"bdatb":[[2,6.4,8.14]],"id":12989514},{"bdatl":[[0,28,7.74],[1,29,3.57],[2,30,2.87],[3,34,5.18],[4,40,5.01],[5,80,1.66],[6,310,1],[7,990,2.15]],"id":46969227}]}]}
{"op":"mcm","clk":"AJ9mAPw3AOdY","pt":1659347589109,"mc":[{"id":"1.201590187","rc":[{"atb":[[4.9,3.02],[6.8,5.43]],"bdatb":[[0,6.8,5.43]],"id":12989514}]}]}
{"op":"mcm","clk":"AKVmAP83AO9Y","pt":1659347589169,"mc":[{"id":"1.201590187","rc":[{"atb":[[13.5,0.18]],"id":45323444}]}]}
{"op":"mcm","clk":"AKZmAII4APVY","pt":1659347589220,"mc":[{"id":"1.201590187","rc":[{"bdatb":[[1,12.5,1.85],[2,11.5,8.41],[3,11,1.23],[4,10,12.46],[5,9.8,9.81],[6,9.6,21],[7,9.4,54.1],[8,9.2,14.25],[9,9,13.1]],"id":45323444},{"bdatl":[[9,2.38,2.02]],"id":9570503}]}]}
{"op":"mcm","clk":"ALFmAIU4APlY","pt":1659347589383,"mc":[{"id":"1.201590187","rc":[{"atb":[[12,4.77]],"id":45323444}]}]}
{"op":"mcm","clk":"ALRmAIY4AIBZ","pt":1659347589433,"mc":[{"id":"1.201590187","rc":[{"bdatb":[[2,12,4.77],[3,11.5,8.41],[4,11,1.23],[5,10,12.46],[6,9.8,9.81],[7,9.6,21],[8,9.4,54.1],[9,9.2,14.25]],"id":45323444}]}]}
{"op":"mcm","clk":"ANpmAJA4AKNZ","pt":1659347589877,"mc":[{"id":"1.201590187","rc":[{"atl":[[10.5,0]],"id":43885158}]}]}
{"op":"mcm","clk":"ANpmAJA4AKhZ","pt":1659347589927,"mc":[{"id":"1.201590187","rc":[{"bdatl":[[3,11.5,2.65],[4,12,1.4],[5,12.5,18],[6,14,13.2],[7,14.5,1],[8,15,12.16],[9,15.5,1]],"id":43885158}]}]}
{"op":"mcm","clk":"AOJmAJM4AK9Z","pt":1659347589985,"mc":[{"id":"1.201590187","rc":[{"atl":[[9.4,7.91]],"id":43885158}]}]}
{"op":"mcm","clk":"AOJmAJQ4ALBZ","pt":1659347590035,"mc":[{"id":"1.201590187","rc":[{"bdatb":[[7,5.3,8.44],[8,5.2,2.99]],"id":12989514},{"bdatl":[[1,9.4,7.91]],"id":43885158},{"bdatb":[[9,9.6,2.26]],"id":46969227}]}]}
{"op":"mcm","clk":"AOhmAJU4ALJZ","pt":1659347590085,"mc":[{"id":"1.201590187","rc":[{"atb":[[12,0]],"id":45323444}]}]}
{"op":"mcm","clk":"AOpmAJk4ALVZ","pt":1659347590135,"mc":[{"id":"1.201590187","rc":[{"bdatb":[[2,11.5,8.41],[3,11,1.23],[4,10,12.46],[5,9.8,9.81],[6,9.6,21],[7,9.4,54.1],[8,9.2,14.25],[9,9,13.1]],"id":45323444}]}]}
{"op":"mcm","clk":"AO1mAJo4ALpZ","pt":1659347590187,"mc":[{"id":"1.201590187","rc":[{"atb":[[1.02,0]],"id":45323444}]}]}
{"op":"mcm","clk":"APdmAJ44AMBZ","pt":1659347590294,"mc":[{"id":"1.201590187","rc":[{"atb":[[13,4.61],[12.5,2.74]],"id":45323444}]}]}
{"op":"mcm","clk":"AP1mAKI4AMRZ","pt":1659347590344,"mc":[{"id":"1.201590187","rc":[{"bdatb":[[1,13,5.13],[2,12.5,2.74],[3,11.5,8.41],[4,11,1.23],[5,10,12.46],[6,9.8,9.81],[7,9.6,21],[8,9.4,54.1],[9,9.2,14.25]],"id":45323444}]}]}
{"op":"mcm","clk":"ALFnALk4AIRa","pt":1659347591082,"mc":[{"id":"1.201590187","rc":[{"atb":[[13,0.19]],"id":45323444}]}]}
{"op":"mcm","clk":"ALFnALk4AIRa","pt":1659347591132,"mc":[{"id":"1.201590187","rc":[{"bdatb":[[1,12.5,3.45],[2,11.5,8.41],[3,11,1.23],[4,10,12.46],[5,9.8,9.81],[6,9.6,21],[7,9.4,54.1],[8,9.2,14.25],[9,9,13.1]],"id":45323444}]}]}
{"op":"mcm","clk":"ALtnAMI4AIxa","pt":1659347591293,"mc":[{"id":"1.201590187","rc":[{"atb":[[12,4.77]],"id":45323444}]}]}
{"op":"mcm","clk":"AL5nAMU4AJFa","pt":1659347591344,"mc":[{"id":"1.201590187","rc":[{"bdatb":[[2,12,4.77],[3,11.5,8.41],[4,11,1.23],[5,10,12.46],[6,9.8,9.81],[7,9.6,21],[8,9.4,54.1],[9,9.2,14.25]],"id":45323444}]}]}
{"op":"mcm","clk":"AOtnAOQ4AL5a","pt":1659347592110,"mc":[{"id":"1.201590187","rc":[{"atb":[[12,0]],"id":45323444}]}]}
{"op":"mcm","clk":"AO5nAOU4AMJa","pt":1659347592160,"mc":[{"id":"1.201590187","rc":[{"bdatb":[[2,11.5,8.41],[3,11,1.23],[4,10,12.46],[5,9.8,9.81],[6,9.6,21],[7,9.4,54.1],[8,9.2,14.25],[9,9,13.1]],"id":45323444}]}]}
{"op":"mcm","clk":"APJnAOY4AMVa","pt":1659347592210,"mc":[{"id":"1.201590187","rc":[{"atb":[[13,4.61]],"bdatb":[[1,13,5.13],[2,12.5,2.74],[3,11.5,8.41],[4,11,1.23],[5,10,12.46],[6,9.8,9.81],[7,9.6,21],[8,9.4,54.1],[9,9.2,14.25]],"id":45323444}]}]}
{"op":"mcm","clk":"AKRoAPI4AO5a","pt":1659347592884,"mc":[{"id":"1.201590187","rc":[{"atb":[[13,0.19]],"id":45323444}]}]}
{"op":"mcm","clk":"AKloAPQ4APJa","pt":1659347592934,"mc":[{"id":"1.201590187","rc":[{"bdatb":[[1,12.5,3.45],[2,11.5,8.41],[3,11,1.23],[4,10,12.46],[5,9.8,9.81],[6,9.6,21],[7,9.4,54.1],[8,9.2,14.25],[9,9,13.1]],"id":45323444}]}]}
{"op":"mcm","clk":"ALRoAPc4APda","pt":1659347593099,"mc":[{"id":"1.201590187","rc":[{"atb":[[12,4.77]],"id":45323444}]}]}
{"op":"mcm","clk":"ALloAPc4APpa","pt":1659347593149,"mc":[{"id":"1.201590187","rc":[{"bdatb":[[2,12,4.77],[3,11.5,8.41],[4,11,1.23],[5,10,12.46],[6,9.8,9.81],[7,9.6,21],[8,9.4,54.1],[9,9.2,14.25]],"id":45323444}]}]}
{"op":"mcm","clk":"ALxoAPc4APta","pt":1659347593202,"mc":[{"id":"1.201590187","rc":[{"atb":[[12.5,1.14]],"id":45323444}]}]}
{"op":"mcm","clk":"AL5oAPo4AP1a","pt":1659347593252,"mc":[{"id":"1.201590187","rc":[{"bdatb":[[1,12.5,1.85]],"id":45323444}]}]}
{"op":"mcm","clk":"AMJoAPs4AP9a","pt":1659347593302,"mc":[{"id":"1.201590187","rc":[{"atb":[[1.02,1.6]],"id":45323444}]}]}
{"op":"mcm","clk":"AMloAIE5AIhb","pt":1659347593508,"mc":[{"id":"1.201590187","rc":[{"atb":[[6.6,14.05],[6.4,1.52]],"id":12989514}]}]}
{"op":"mcm","clk":"AMtoAIQ5AIxb","pt":1659347593558,"mc":[{"id":"1.201590187","rc":[{"bdatb":[[1,6.6,14.05],[2,6.4,1.52]],"id":12989514}]}]}
{"op":"mcm","clk":"AOxoAI45AKJb","pt":1659347593983,"mc":[{"id":"1.201590187","rc":[{"atb":[[12,0]],"id":45323444}]}]}
{"op":"mcm","clk":"AO1oAJA5AKVb","pt":1659347594033,"mc":[{"id":"1.201590187","rc":[{"bdatb":[[2,11.5,8.41],[3,11,1.23],[4,10,12.46],[5,9.8,9.81],[6,9.6,21],[7,9.4,54.1],[8,9.2,14.25],[9,9,13.1]],"id":45323444}]}]}
{"op":"mcm","clk":"APRoAJM5AK1b","pt":1659347594198,"mc":[{"id":"1.201590187","rc":[{"atb":[[13,4.61]],"atl":[[50,25.2],[46,12.2]],"id":45323444}]}]}
{"op":"mcm","clk":"APRoAJg5AK5b","pt":1659347594248,"mc":[{"id":"1.201590187","rc":[{"bdatb":[[1,13,5.13],[2,12.5,1.14],[3,11.5,8.41],[4,11,1.23],[5,10,12.46],[6,9.8,9.81],[7,9.6,21],[8,9.4,54.1],[9,9.2,14.25]],"bdatl":[[7,46,12.2],[8,50,25.2],[9,55,9]],"id":45323444}]}]}
{"op":"mcm","clk":"AJxpAK85ANNb","pt":1659347595011,"mc":[{"id":"1.201590187","rc":[{"atb":[[13,0.19]],"id":45323444}]}]}
{"op":"mcm","clk":"AJ9pALA5ANpb","pt":1659347595061,"mc":[{"id":"1.201590187","rc":[{"bdatb":[[1,12.5,1.85],[2,11.5,8.41],[3,11,1.23],[4,10,12.46],[5,9.8,9.81],[6,9.6,21],[7,9.4,54.1],[8,9.2,14.25],[9,9,13.1]],"id":45323444}]}]}
{"op":"mcm","clk":"AKlpALc5AOJb","pt":1659347595178,"mc":[{"id":"1.201590187","rc":[{"atb":[[12,4.77]],"id":45323444},{"atb":[[8.2,1.15]],"atl":[[9.2,3.84]],"id":43885158},{"atl":[[27,1.25]],"id":46969227}]}]}
{"op":"mcm","clk":"AK1pALg5AOdb","pt":1659347595228,"mc":[{"id":"1.201590187","rc":[{"bdatb":[[2,12,4.77],[3,11.5,8.41],[4,11,1.23],[5,10,13.26],[6,9.8,9],[7,9.6,21.11],[8,9.4,54.27],[9,9.2,13.96]],"id":45323444},{"bdatb":[[6,1.94,14.44],[7,1.93,2.43],[8,1.91,107.9],[9,1.89,10.39]],"bdatl":[[5,2.3,2.79],[6,2.32,3.01],[7,2.34,3.41]],"id":9570503},{"bdatb":[[5,5.7,1.4],[6,5.6,4.59],[7,5.5,3.74],[8,5.3,10.44],[9,5.1,3.23]],"bdatl":[[9,11,34.06]],"id":12989514},{"bdatb":[[6,13.5,8.62],[7,11.5,2.16],[8,11,31.69],[9,10.5,4.99]],"id":44621159},{"bdatb":[[8,5.5,24.13],[9,5.4,41.3]],"bdatl":[[7,11.5,13.02],[8,12,1.98]],"id":44836671},{"bdatb":[[0,8.2,1.15],[1,8,4.16],[2,7.8,1.26],[3,7.6,9],[4,7.4,10.26],[5,7.2,3.71],[6,7,5],[7,6.6,64.99],[8,6.4,6.1],[9,6.2,10.76]],"bdatl":[[0,9.2,3.84]],"id":43885158},{"bdatb":[[7,11.5,10.62],[8,10,9.25]],"bdatl":[[0,27,1.25],[1,28,7.64],[2,29,3.57],[3,30,2.87],[4,34,5.18],[5,40,5.01],[6,80,1.66],[7,310,1],[8,990,2.15]],"id":46969227}]}]}
{"op":"mcm","clk":"ALJpALs5AOpb","pt":1659347595288,"mc":[{"id":"1.201590187","rc":[{"atb":[[6.4,0.38]],"id":12989514},{"atl":[[29,0],[28,11.21],[34,5]],"id":46969227}]}]}
{"op":"mcm","clk":"ALJpAL05AOtb","pt":1659347595338,"mc":[{"id":"1.201590187","rc":[{"bdatb":[[2,6.2,10.68],[3,6,6.68],[4,5.7,1.4],[5,5.6,4.59],[6,5.5,3.74],[7,5.3,10.44],[8,5.1,3.23],[9,5,3.59]],"id":12989514},{"bdatl":[[1,28,11.21],[2,30,2.87],[3,34,5.09],[4,40,5.01],[5,80,1.66],[6,310,1],[7,990,2.15],[8,0,0]],"id":46969227}]}]}
{"op":"mcm","clk":"ALRpAL45AO1b","pt":1659347595394,"mc":[{"id":"1.201590187","rc":[{"atb":[[15,0.16],[13,1.19]],"id":45323444}]}]}
{"op":"mcm","clk":"ALhpAL85AO9b","pt":1659347595445,"mc":[{"id":"1.201590187","rc":[{"bdatb":[[0,13,1.87],[1,12.5,1.14]],"id":45323444},{"bdatl":[[5,2.3,2.77],[6,2.34,1.05],[7,2.36,1.93],[8,2.4,77.99],[9,2.42,4.86]],"id":9570503},{"bdatl":[[7,11.5,12.41],[8,12,1.62],[9,13,59.48]],"id":44836671}]}]}
{"op":"mcm","clk":"AMhpAMY5AIBc","pt":1659347595760,"mc":[{"id":"1.201590187","rc":[{"atb":[[15,0],[14.5,0]],"atl":[[19.5,0.54]],"bdatb":[[0,13,1.54]],"id":45323444},{"atb":[[6.6,10.05]],"bdatl":[[9,11,33.84]],"id":12989514},{"atb":[[8,1.76]],"bdatl":[[8,15,12]],"id":43885158},{"bdatl":[[5,2.3,1.72],[7,2.36,1],[8,2.38,1.94],[9,2.4,75.95]],"id":9570503},{"bdatl":[[7,11.5,12.2],[8,12,1.41],[9,13,59.83]],"id":44836671}],"con":true}]}
{"op":"mcm","clk":"AMtpAMY5AIJc","pt":1659347595810,"mc":[{"id":"1.201590187","rc":[{"atb":[[12.5,3.46],[11.5,14.44]],"bdatb":[[1,12.5,3.46],[3,11.5,14.44]],"bdatl":[[0,20,1.54]],"id":45323444},{"atb":[[6.8,9.23]],"bdatb":[[0,6.8,9.23],[1,6.6,10.05],[4,5.7,1.84],[5,5.6,4.14],[7,5.3,10.43],[8,5.2,1.45],[9,5.1,2.27]],"id":12989514},{"bdatb":[[6,1.94,15.75],[7,1.93,1.12]],"id":9570503},{"bdatb":[[6,13.5,8.81],[7,11.5,1.97]],"id":44621159},{"bdatb":[[8,5.5,24.59],[9,5.4,40.83]],"id":44836671},{"bdatb":[[1,8,1.76],[8,6.4,6.49],[9,6.2,10.35]],"id":43885158},{"bdatb":[[7,11.5,10.61]],"id":46969227}]}]}
{"op":"mcm","clk":"ANFpAMc5AIlc","pt":1659347595905,"mc":[{"id":"1.201590187","rc":[{"atb":[[12,0]],"bdatb":[[2,11.5,14.44],[3,11,1.23],[4,10,13.26],[5,9.8,9],[6,9.6,21.11],[7,9.4,54.27],[8,9.2,13.96],[9,9,13.1]],"id":45323444}]}]}
{"op":"mcm","clk":"AN1pAMw5AJNc","pt":1659347596106,"mc":[{"id":"1.201590187","rc":[{"atb":[[13,5.61]],"id":45323444}]}]}
{"op":"mcm","clk":"AN9pAM85AJhc","pt":1659347596156,"mc":[{"id":"1.201590187","rc":[{"bdatb":[[0,13,5.96]],"id":45323444},{"bdatl":[[9,2.4,77.29]],"id":9570503}]}]}
{"op":"mcm","clk":"AOFpANI5AJhc","pt":1659347596211,"mc":[{"id":"1.201590187","rc":[{"bdatb":[[1,12.5,1.14]],"id":45323444}]}]}
{"op":"mcm","clk":"AOZpANI5AJ1c","pt":1659347596261,"mc":[{"id":"1.201590187","rc":[{"atb":[[12.5,1.14]],"id":45323444}]}]}
{"op":"mcm","clk":"AJhqAPA5AM1c","pt":1659347597098,"mc":[{"id":"1.201590187","rc":[{"atb":[[7.6,6.76]],"id":43885158}]}]}
{"op":"mcm","clk":"AJxqAPE5ANNc","pt":1659347597148,"mc":[{"id":"1.201590187","rc":[{"bdatb":[[3,7.6,6.76]],"id":43885158}]}]}
{"op":"mcm","clk":"AKRqAPQ5ANVc","pt":1659347597199,"mc":[{"id":"1.201590187","rc":[{"atb":[[7.6,4.53]],"id":43885158}]}]}
{"op":"mcm","clk":"AKdqAPU5ANlc","pt":1659347597249,"mc":[{"id":"1.201590187","rc":[{"bdatb":[[3,7.6,4.53]],"id":43885158}]}]}
{"op":"mcm","clk":"ALNqAP85AONc","pt":1659347597510,"mc":[{"id":"1.201590187","rc":[{"atb":[[13,1.19]],"id":45323444}]}]}
{"op":"mcm","clk":"ALdqAIE6AOhc","pt":1659347597560,"mc":[{"id":"1.201590187","rc":[{"bdatb":[[0,13,1.54]],"id":45323444},{"bdatl":[[9,2.4,75.95]],"id":9570503}]}]}
{"op":"mcm","clk":"ALtqAIM6AOlc","pt":1659347597620,"mc":[{"id":"1.201590187","rc":[{"atb":[[1.01,48.08]],"id":45323444}]}]}
{"op":"mcm","clk":"AMRqAIM6APJc","pt":1659347597689,"mc":[{"id":"1.201590187","rc":[{"atb":[[12,4.77]],"id":45323444}]}]}
{"op":"mcm","clk":"AMVqAIM6APRc","pt":1659347597740,"mc":[{"id":"1.201590187","rc":[{"bdatb":[[2,12,4.77],[3,11.5,14.44],[4,11,1.23],[5,10,13.26],[6,9.8,9],[7,9.6,21.11],[8,9.4,54.27],[9,9.2,13.96]],"id":45323444}]}]}
{"op":"mcm","clk":"AMxqAIU6APdc","pt":1659347597790,"mc":[{"id":"1.201590187","rc":[{"atb":[[11.5,8.41],[10.5,6.03],[1.01,46.81]],"id":45323444}]}]}
{"op":"mcm","clk":"AM1qAIU6APpc","pt":1659347597840,"mc":[{"id":"1.201590187","rc":[{"bdatb":[[3,11.5,8.41],[5,10.5,6.2],[6,10,13.09],[7,9.8,9],[8,9.6,21.11],[9,9.4,54.27]],"id":45323444}]}]}
{"op":"mcm","clk":"ANVqAIc6APtc","pt":1659347597890,"mc":[{"id":"1.201590187","rc":[{"atb":[[24,4.84]],"atl":[[55,0]],"id":44621159}]}]}
{"op":"mcm","clk":"ANVqAIg6AIJd","pt":1659347597940,"mc":[{"id":"1.201590187","rc":[{"bdatb":[[2,24,4.84]],"bdatl":[[2,95,2]],"id":44621159}]}]}
{"op":"mcm","clk":"AN9qAIs6AIZd","pt":1659347597995,"mc":[{"id":"1.201590187","rc":[{"atb":[[1.01,45.55]],"id":45323444},{"atb":[[25,4.21]],"atl":[[60,0.64]],"id":44621159}]}]}
{"op":"mcm","clk":"AN9qAI86AIld","pt":1659347598045,"mc":[{"id":"1.201590187","rc":[{"bdatb":[[1,25,4.21]],"bdatl":[[2,95,2.64]],"id":44621159}]}]}
{"op":"mcm","clk":"AONqAI86AIxd","pt":1659347598095,"mc":[{"id":"1.201590187","rc":[{"atb":[[13.5,1.45]],"id":45323444}]}]}
{"op":"mcm","clk":"AOVqAJE6AI5d","pt":1659347598145,"mc":[{"id":"1.201590187","rc":[{"bdatb":[[0,13.5,1.62],[1,13,1.19],[2,12.5,1.14],[3,12,4.77],[4,11.5,8.41],[5,11,1.23],[6,10.5,6.2],[7,10,13.09],[8,9.8,9],[9,9.6,21.11]],"id":45323444},{"bdatl":[[7,2.36,2.95],[8,2.38,5.25],[9,2.4,72.08]],"id":9570503},{"bdatl":[[9,13,60.37]],"id":44836671}]}]}
{"op":"mcm","clk":"APhqAJY6AJxd","pt":1659347598418,"mc":[{"id":"1.201590187","rc":[{"atb":[[12,0]],"id":45323444}]}]}
{"op":"mcm","clk":"APpqAJg6AJxd","pt":1659347598468,"mc":[{"id":"1.201590187","rc":[{"bdatb":[[3,11.5,8.41],[4,11,1.23],[5,10.5,6.2],[6,10,13.09],[7,9.8,9],[8,9.6,21.11],[9,9.4,54.27]],"id":45323444}]}]}
{"op":"mcm","clk":"AP1qAJk6AKBd","pt":1659347598518,"mc":[{"id":"1.201590187","rc":[{"atb":[[12.5,5.74]],"bdatb":[[2,12.5,5.74]],"id":45323444}]}]}
{"op":"mcm","clk":"AJtrALg6ANNd","pt":1659347599191,"mc":[{"id":"1.201590187","rc":[{"atb":[[12.5,1.14]],"id":45323444},{"atb":[[25,1.91]],"id":44621159}]}]}
{"op":"mcm","clk":"AJtrALo6ANpd","pt":1659347599241,"mc":[{"id":"1.201590187","rc":[{"bdatb":[[2,12.5,1.14]],"id":45323444},{"bdatb":[[1,25,1.91]],"id":44621159}]}]}
{"op":"mcm","clk":"AJ9rAL46AOFd","pt":1659347599304,"mc":[{"id":"1.201590187","rc":[{"atb":[[2.02,24.3]],"atl":[[2.14,62.89]],"id":9570503},{"atb":[[6.6,7.65]],"atl":[[8.4,4.02]],"id":12989514},{"atb":[[6.8,17.69]],"atl":[[7.6,156.76]],"id":44836671},{"atb":[[7.4,12.57]],"atl":[[9.4,5.63]],"id":43885158}]}]}
{"op":"mcm","clk":"AJ9rAL46AOJd","pt":1659347599354,"mc":[{"id":"1.201590187","rc":[{"bdatb":[[1,2.02,24.3]],"bdatl":[[0,2.14,63.74]],"id":9570503},{"bdatb":[[1,6.6,7.65],[7,5.3,6.38],[8,5.2,5.57]],"bdatl":[[2,8.4,4.02]],"id":12989514},{"bdatb":[[9,10.5,3.13]],"id":44621159},{"bdatb":[[0,6.8,18.04]],"bdatl":[[1,7.6,156.76]],"id":44836671},{"bdatb":[[4,7.4,12.57]],"bdatl":[[1,9.4,5.63]],"id":43885158}]}]}
{"op":"mcm","clk":"AKRrAME6AONd","pt":1659347599404,"mc":[{"id":"1.201590187","rc":[{"atb":[[13,5.61]],"id":45323444}]}]}
{"op":"mcm","clk":"AKRrAMQ6AOhd","pt":1659347599455,"mc":[{"id":"1.201590187","rc":[{"bdatb":[[1,13,5.61]],"id":45323444}]}]}
{"op":"mcm","clk":"AKhrAMU6AOxd","pt":1659347599511,"mc":[{"id":"1.201590187","rc":[{"atb":[[2.02,24.21]],"atl":[[2.14,62.77]],"id":9570503},{"atb":[[6.6,5.18],[6.8,11.61]],"atl":[[8.4,4]],"id":12989514},{"atb":[[26,3.18]],"id":44621159},{"atb":[[6.8,17.62]],"atl":[[7.6,156.65]],"id":44836671},{"atb":[[7.4,12.66]],"atl":[[9.4,5.77]],"id":43885158}]}]}
{"op":"mcm","clk":"AK5rAMY6APJd","pt":1659347599561,"mc":[{"id":"1.201590187","rc":[{"bdatb":[[1,2.02,24.21]],"bdatl":[[0,2.14,63.62]],"id":9570503},{"bdatb":[[0,6.8,11.61],[1,6.6,5.18],[7,5.3,6.64],[8,5.2,5.31]],"bdatl":[[2,8.4,4]],"id":12989514},{"bdatb":[[0,26,3.18],[9,10.5,3.11]],"id":44621159},{"bdatb":[[0,6.8,17.97]],"bdatl":[[1,7.6,156.65]],"id":44836671},{"bdatb":[[4,7.4,12.66]],"bdatl":[[1,9.4,5.77]],"id":43885158}]}]}
{"op":"mcm","clk":"ANprANc6AKBe","pt":1659347600191,"mc":[{"id":"1.201590187","rc":[{"atb":[[13,1.19]],"id":45323444},{"atb":[[26,1]],"id":44621159}]}]}
{"op":"mcm","clk":"ANprANg6AKVe","pt":1659347600241,"mc":[{"id":"1.201590187","rc":[{"bdatb":[[1,13,1.19]],"id":45323444},{"bdatb":[[0,26,1]],"id":44621159}]}]}
{"op":"mcm","clk":"AOdrANw6AK5e","pt":1659347600402,"mc":[{"id":"1.201590187","rc":[{"atb":[[13.5,5.7]],"id":45323444}]}]}
{"op":"mcm","clk":"AOlrAN46ALZe","pt":1659347600452,"mc":[{"id":"1.201590187","rc":[{"bdatb":[[0,13.5,5.87]],"id":45323444},{"bdatl":[[8,2.38,5.91],[9,2.4,72.47]],"id":9570503}]}]}
{"op":"mcm","clk":"APRrAOI6ALte","pt":1659347600605,"mc":[{"id":"1.201590187","rc":[{"atb":[[25,4.21]],"id":44621159}]}]}
{"op":"mcm","clk":"APZrAOQ6AMFe","pt":1659347600655,"mc":[{"id":"1.201590187","rc":[{"bdatb":[[1,25,4.21]],"id":44621159}]}]}
{"op":"mcm","clk":"AKhsAPo6AOxe","pt":1659347601396,"mc":[{"id":"1.201590187","rc":[{"atb":[[13.5,1.45]],"id":45323444},{"atb":[[25,1.91]],"id":44621159}]}]}
{"op":"mcm","clk":"AKhsAPs6APRe","pt":1659347601446,"mc":[{"id":"1.201590187","rc":[{"bdatb":[[0,13.5,1.62]],"id":45323444},{"bdatl":[[8,2.38,5.25],[9,2.4,72.08]],"id":9570503},{"bdatb":[[1,25,1.91]],"id":44621159}]}]}
{"op":"mcm","clk":"AK5sAPs6AP1e","pt":1659347601599,"mc":[{"id":"1.201590187","rc":[{"atb":[[12,4.77]],"id":45323444},{"atb":[[2.02,28.32]],"atl":[[2.14,66.35]],"id":9570503},{"atb":[[6.8,13.94]],"atl":[[8.4,6.24]],"id":12989514},{"atb":[[6.8,19.91]],"atl":[[7.6,159.04]],"id":44836671},{"atl":[[9.4,8]],"id":43885158}]}]}
{"op":"mcm","clk":"ALJsAPs6AINf","pt":1659347601649,"mc":[{"id":"1.201590187","rc":[{"bdatb":[[3,12,4.77],[4,11.5,8.41],[5,11,1.23],[6,10.5,6.2],[7,10,13.09],[8,9.8,9],[9,9.6,21.11]],"id":45323444},{"bdatb":[[1,2.02,28.32]],"bdatl":[[0,2.14,67.2]],"id":9570503},{"bdatb":[[0,6.8,13.94],[7,5.3,10.59],[8,5.2,1.28]],"bdatl":[[2,8.4,6.24]],"id":12989514},{"bdatb":[[9,10.5,4.9]],"id":44621159},{"bdatb":[[0,6.8,20.26]],"bdatl":[[1,7.6,159.04]],"id":44836671},{"bdatl":[[1,9.4,8]],"id":43885158}]}]}
{"op":"mcm","clk":"ALlsAPw6AIRf","pt":1659347601712,"mc":[{"id":"1.201590187","rc":[{"atb":[[8.2,0]],"atl":[[9.2,2.69]],"id":43885158},{"atl":[[27,0.1]],"id":46969227}]}]}
{"op":"mcm","clk":"AMBsAP46AIhf","pt":1659347601762,"mc":[{"id":"1.201590187","rc":[{"bdatb":[[7,10,12.29],[8,9.8,9.81],[9,9.6,21]],"id":45323444},{"bdatb":[[6,1.94,5.44],[7,1.93,7.36],[8,1.92,4.15],[9,1.91,107.36]],"bdatl":[[6,2.34,1.02],[7,2.38,4.91],[8,2.4,74.7],[9,2.44,153.76]],"id":9570503},{"bdatb":[[4,5.6,4.41],[5,5.5,5.38],[6,5.3,8.6],[7,5.2,3.32],[8,5.1,2.27],[9,5,3]],"id":12989514},{"bdatb":[[6,13.5,7.33],[7,13,1.09],[8,11.5,2.44],[9,11,31.69]],"id":44621159},{"bdatb":[[8,5.5,23.16],[9,5.4,40.81]],"bdatl":[[9,13,60.19]],"id":44836671},{"bdatb":[[0,8,1.76],[1,7.8,1.26],[2,7.6,4.53],[3,7.4,12.66],[4,7.2,3.71],[5,7,5],[6,6.6,64.99],[7,6.4,3.37],[8,6.2,13.57],[9,6,17.44]],"bdatl":[[0,9.2,2.69]],"id":43885158},{"bdatb":[[7,11.5,10.42],[8,10,9.46]],"bdatl":[[0,28,11.31],[1,30,2.87],[2,34,5.09],[3,40,5.01],[4,80,1.66],[5,310,1],[6,990,2.15],[7,0,0]],"id":46969227}]}]}
{"op":"mcm","clk":"AMJsAP46AItf","pt":1659347601812,"mc":[{"id":"1.201590187","rc":[{"atb":[[12,9.37],[10.5,0]],"bdatb":[[3,12,9.37],[6,10,12.46],[7,9.8,9.81],[8,9.6,21],[9,9.4,54.1]],"id":45323444},{"atb":[[26,3.18]],"bdatb":[[0,26,3.18]],"id":44621159},{"bdatl":[[9,2.44,158.43]],"id":9570503}]}]}
{"op":"mcm","clk":"AMZsAIA7AJBf","pt":1659347601903,"mc":[{"id":"1.201590187","rc":[{"atl":[[29,3.57],[28,7.64]],"id":46969227}]}]}
{"op":"mcm","clk":"AMpsAIM7AJdf","pt":1659347601953,"mc":[{"id":"1.201590187","rc":[{"bdatl":[[0,28,7.74],[1,29,3.57],[2,30,2.87],[3,34,5.09],[4,40,5.01],[5,80,1.66],[6,310,1],[7,990,2.15]],"id":46969227}]}]}
{"op":"mcm","clk":"AM5sAIc7AJhf","pt":1659347602016,"mc":[{"id":"1.201590187","rc":[{"atl":[[7,7]],"id":12989514}]}]}
{"op":"mcm","clk":"ANJsAI07AJtf","pt":1659347602067,"mc":[{"id":"1.201590187","rc":[{"bdatb":[[2,12.5,1.28],[3,12,9.45],[4,11.5,12.43],[6,10,10],[7,9.8,9.54],[9,9.4,57.01]],"id":45323444},{"bdatb":[[2,2,28.63],[3,1.99,7.14],[4,1.98,39.86],[5,1.97,11.9],[6,1.96,2.62],[7,1.92,2.77],[8,1.91,107.36],[9,1.9,1.63]],"id":9570503},{"bdatl":[[0,7,7],[1,7.8,4.19],[2,8.2,2.52],[3,8.4,6.24],[4,9,2.17],[5,9.2,4.54],[6,9.4,3.67],[7,9.6,11.09],[8,10,17.36],[9,10.5,12.47]],"id":12989514},{"bdatb":[[4,18.5,1.47],[5,16.5,1.39],[6,15.5,4.57],[7,15,1.23],[8,13.5,6.56],[9,11.5,2.8]],"id":44621159},{"bdatb":[[3,6,30.19],[4,5.9,12.74],[5,5.8,11],[6,5.7,47.78],[7,5.6,63.72],[8,5.5,23],[9,5.4,36.73]],"id":44836671},{"bdatb":[[4,7.2,3.96],[5,7,9.11],[6,6.8,2.71],[7,6.6,64.72],[8,6.4,2],[9,6.2,10.86]],"id":43885158},{"bdatb":[[7,14,1.73],[8,13,1.85],[9,11.5,7.81]],"id":46969227}]}]}
{"op":"mcm","clk":"ANhsAI87AJxf","pt":1659347602117,"mc":[{"id":"1.201590187","rc":[{"atl":[[7,1.15]],"trd":[[7,17.7]],"ltp":7,"tv":91.86,"id":12989514}],"tv":1386.09}]}
{"op":"mcm","clk":"ANtsAJE7AKBf","pt":1659347602167,"mc":[{"id":"1.201590187","rc":[{"bdatb":[[4,11.5,8.87],[6,10,11.67],[7,9.8,10.63],[9,9.4,54.1]],"id":45323444},{"bdatb":[[2,2,27.38],[3,1.98,36.93],[4,1.97,2.53],[5,1.96,2.62],[6,1.94,1.29],[7,1.93,7.36],[8,1.92,8.34],[9,1.91,107.36]],"id":9570503},{"bdatl":[[0,7,1.15]],"id":12989514},{"bdatb":[[5,15.5,4.56],[6,13.5,6.75],[7,13,1.09],[8,12.5,1.28],[9,11.5,1.18]],"id":44621159},{"bdatb":[[4,5.9,9.91],[5,5.8,10],[6,5.7,44.55],[9,5.4,39.82]],"id":44836671},{"bdatb":[[5,7,5.89],[6,6.6,64.72],[7,6.4,2.39],[8,6.2,14.87],[9,6,16.26]],"id":43885158},{"bdatb":[[7,11.5,10.31],[8,10,9.7],[9,9.6,1.93]],"id":46969227}]}]}
{"op":"mcm","clk":"ANxsAJM7AKBf","pt":1659347602219,"mc":[{"id":"1.201590187","rc":[{"atl":[[7,0]],"trd":[[7,19.99]],"tv":94.15,"id":12989514}],"tv":1388.38}]}
{"op":"mcm","clk":"AN9sAJU7AKlf","pt":1659347602269,"mc":[{"id":"1.201590187","rc":[{"bdatb":[[2,12.5,1.14],[3,12,9.37],[4,11.5,8.41],[6,10,12.46],[7,9.8,9.81]],"id":45323444},{"bdatb":[[2,2,23.35],[6,1.94,5.44],[8,1.92,4.15]],"id":9570503},{"bdatl":[[0,7.8,4.19],[1,8.2,2.52],[2,8.4,6.24],[3,9,2.17],[4,9.2,4.54],[5,9.4,3.67],[6,9.6,11.09],[7,10,17.36],[8,10.5,12.47],[9,11,33.84]],"id":12989514},{"bdatb":[[4,18.5,1.37],[5,15.5,4.19],[6,13.5,7.33],[8,11.5,2.44],[9,11,31.69]],"id":44621159},{"bdatb":[[3,6,29.74],[4,5.9,9],[7,5.6,64.04],[8,5.5,23.16],[9,5.4,40.81]],"id":44836671},{"bdatb":[[4,7.2,3.71],[5,7,5],[6,6.6,64.99],[7,6.4,3.37],[8,6.2,13.57],[9,6,17.44]],"id":43885158},{"bdatb":[[7,11.5,10.42],[8,10,9.46],[9,9.6,2.26]],"id":46969227}]}]}
{"op":"mcm","clk":"AOlsAJo7AK5f","pt":1659347602425,"mc":[{"id":"1.201590187","rc":[{"atb":[[6.8,10.14]],"id":12989514},{"atl":[[30,0.07]],"id":46969227}]}]}
{"op":"mcm","clk":"AOtsAJ07ALFf","pt":1659347602475,"mc":[{"id":"1.201590187","rc":[{"bdatb":[[0,6.8,10.14]],"id":12989514},{"bdatl":[[2,34,5.16],[3,40,5.01],[4,80,1.66],[5,310,1],[6,990,2.15],[7,0,0]],"id":46969227}]}]}
{"op":"mcm","clk":"APFsAJ47ALZf","pt":1659347602525,"mc":[{"id":"1.201590187","rc":[{"atb":[[6.6,8.08]],"bdatb":[[1,6.6,8.08]],"id":12989514},{"atl":[[38,1.87]],"trd":[[38,0.26]],"bdatl":[[0,38,1.87]],"ltp":38,"tv":2.34,"id":44621159},{"bdatb":[[9,9.6,1.74]],"id":46969227}],"tv":1388.64}]}
{"op":"mcm","clk":"APdsAKM7AL5f","pt":1659347602596,"mc":[{"id":"1.201590187","rc":[{"atb":[[12,4.6]],"id":45323444},{"atb":[[26,1]],"id":44621159}]}]}
{"op":"mcm","clk":"APpsAKM7AMFf","pt":1659347602646,"mc":[{"id":"1.201590187","rc":[{"bdatb":[[3,12,4.6]],"id":45323444},{"bdatl":[[9,2.44,153.76]],"id":9570503},{"bdatb":[[0,26,1]],"id":44621159}]}]}
{"op":"mcm","clk":"AIBtAKU7AMJf","pt":1659347602696,"mc":[{"id":"1.201590187","rc":[{"atb":[[13,5.61]],"id":45323444},{"atb":[[8,8.25]],"id":43885158}]}]}
{"op":"mcm","clk":"AIBtAKc7AMdf","pt":1659347602746,"mc":[{"id":"1.201590187","rc":[{"bdatb":[[1,13,5.61]],"id":45323444},{"bdatl":[[7,2.38,8.21],[8,2.4,73.13],[9,2.42,16.54]],"id":9570503},{"bdatl":[[9,13,60.35]],"id":44836671},{"bdatb":[[0,8,8.25]],"id":43885158}]}]}
{"op":"mcm","clk":"AIRtAKs7AMpf","pt":1659347602815,"mc":[{"id":"1.201590187","rc":[{"atl":[[42,0.12]],"id":44621159}]}]}
{"op":"mcm","clk":"AIRtAKs7AM9f","pt":1659347602865,"mc":[{"id":"1.201590187","rc":[{"bdatl":[[2,95,2.76]],"id":44621159}]}]}
{"op":"mcm","clk":"AIltAKs7ANVf","pt":1659347602915,"mc":[{"id":"1.201590187","rc":[{"atb":[[25,4.21]],"id":44621159}]}]}
{"op":"mcm","clk":"AIltAK47ANVf","pt":1659347602965,"mc":[{"id":"1.201590187","rc":[{"bdatb":[[1,25,4.21]],"id":44621159}]}]}
{"op":"mcm","clk":"ALBtALk7AP5f","pt":1659347603634,"mc":[{"id":"1.201590187","rc":[{"atb":[[13,1.19]],"id":45323444},{"atb":[[25,1.91]],"id":44621159},{"atb":[[8,1.76]],"id":43885158}]}]}
{"op":"mcm","clk":"ALptALo7AIRg","pt":1659347603684,"mc":[{"id":"1.201590187","rc":[{"bdatb":[[1,13,1.19]],"id":45323444},{"bdatl":[[7,2.38,4.91],[8,2.4,74.7],[9,2.44,153.76]],"id":9570503},{"bdatb":[[1,25,1.91]],"id":44621159},{"bdatl":[[9,13,60.19]],"id":44836671},{"bdatb":[[0,8,1.76]],"id":43885158}]}]}
{"op":"mcm","clk":"AL1tALs7AIdg","pt":1659347603734,"mc":[{"id":"1.201590187","rc":[{"atb":[[8,4.04]],"bdatb":[[0,8,4.04]],"id":43885158},{"bdatl":[[7,2.38,8.21],[8,2.4,73.13],[9,2.42,2.61]],"id":9570503},{"bdatl":[[9,13,60.35]],"id":44836671}]}]}
{"op":"mcm","clk":"AMFtAL47AI9g","pt":1659347603830,"mc":[{"id":"1.201590187","rc":[{"atb":[[13.5,5.7]],"id":45323444},{"atb":[[6.8,7.81]],"id":12989514},{"atb":[[7.8,7.93],[8,3.74]],"id":43885158}]}]}
{"op":"mcm","clk":"AMRtAL87AJVg","pt":1659347603880,"mc":[{"id":"1.201590187","rc":[{"bdatb":[[0,13.5,5.87]],"id":45323444},{"bdatl":[[7,2.38,9.92],[8,2.4,73.06],[9,2.42,9.58]],"id":9570503},{"bdatb":[[0,6.8,7.81]],"id":12989514},{"bdatb":[[0,8,3.74],[1,7.8,7.93]],"id":43885158}]}]}
{"op":"mcm","clk":"AMltAL87AJdg","pt":1659347603935,"mc":[{"id":"1.201590187","rc":[{"atb":[[6.8,5.43]],"id":12989514},{"atb":[[26,3.18]],"id":44621159}]}]}
{"op":"mcm","clk":"AM9tAL87AJtg","pt":1659347603985,"mc":[{"id":"1.201590187","rc":[{"bdatl":[[7,2.38,11.57],[8,2.4,74.34],[9,2.44,169.47]],"id":9570503},{"bdatb":[[0,6.8,5.43]],"id":12989514},{"bdatb":[[0,26,3.18]],"id":44621159}]}]}
{"op":"mcm","clk":"AO5tAMk7AMlg","pt":1659347604615,"mc":[{"id":"1.201590187","rc":[{"atb":[[13.5,1.45]],"id":45323444},{"atb":[[26,1]],"id":44621159},{"atb":[[7.8,1.26]],"id":43885158}]}]}
{"op":"mcm","clk":"AO9tAMo7AM5g","pt":1659347604665,"mc":[{"id":"1.201590187","rc":[{"bdatb":[[0,13.5,1.62]],"id":45323444},{"bdatl":[[7,2.38,8.21],[8,2.4,73.13],[9,2.42,1.62]],"id":9570503},{"bdatb":[[0,26,1]],"id":44621159},{"bdatb":[[1,7.8,1.26]],"id":43885158}]}]}
{"op":"mcm","clk":"APptAMw7ANZg","pt":1659347604821,"mc":[{"id":"1.201590187","rc":[{"atb":[[12.5,5.74]],"id":45323444}]}]}
{"op":"mcm","clk":"APttAMw7AN1g","pt":1659347604871,"mc":[{"id":"1.201590187","rc":[{"bdatb":[[2,12.5,5.74]],"id":45323444}]}]}
{"op":"mcm","clk":"AIJuAM87AOlg","pt":1659347605030,"mc":[{"id":"1.201590187","rc":[{"atb":[[25,4.21]],"id":44621159}]}]}
{"op":"mcm","clk":"AINuANM7AOxg","pt":1659347605081,"mc":[{"id":"1.201590187","rc":[{"bdatb":[[1,25,4.21]],"id":44621159}]}]}
{"op":"mcm","clk":"AKNuAOc7AJ9h","pt":1659347605819,"mc":[{"id":"1.201590187","rc":[{"atb":[[12.5,1.14]],"id":45323444},{"atb":[[25,1.91]],"id":44621159}]}]}
{"op":"mcm","clk":"AKNuAOg7AKVh","pt":1659347605870,"mc":[{"id":"1.201590187","rc":[{"bdatb":[[2,12.5,1.14]],"id":45323444},{"bdatb":[[1,25,1.91]],"id":44621159}]}]}
{"op":"mcm","clk":"AKpuAO47AK1h","pt":1659347606029,"mc":[{"id":"1.201590187","rc":[{"atb":[[13,5.61]],"id":45323444},{"atb":[[6.6,10.4]],"id":12989514},{"atb":[[8,1.46]],"id":43885158}]}]}
{"op":"mcm","clk":"AK1uAO87ALBh","pt":1659347606079,"mc":[{"id":"1.201590187","rc":[{"bdatb":[[1,13,5.61]],"id":45323444},{"bdatl":[[7,2.38,3.91],[8,2.4,75.54],[9,2.44,153.92]],"id":9570503},{"bdatb":[[1,6.6,10.4]],"id":12989514},{"bdatl":[[9,13,60]],"id":44836671},{"bdatb":[[0,8,1.46]],"id":43885158}]}]}
{"op":"mcm","clk":"AK5uAPA7ALRh","pt":1659347606129,"mc":[{"id":"1.201590187","rc":[{"atb":[[6.6,12.68]],"id":12989514}]}]}
{"op":"mcm","clk":"ALBuAPI7ALdh","pt":1659347606179,"mc":[{"id":"1.201590187","rc":[{"bdatb":[[1,6.6,12.68]],"id":12989514}]}]}
{"op":"mcm","clk":"ALFuAPI7ALlh","pt":1659347606230,"mc":[{"id":"1.201590187","rc":[{"atb":[[26,3.18]],"id":44621159}]}]}
{"op":"mcm","clk":"ALRuAPQ7ALxh","pt":1659347606280,"mc":[{"id":"1.201590187","rc":[{"bdatl":[[9,2.44,158.39]],"id":9570503},{"bdatb":[[0,26,3.18]],"id":44621159}]}]}
{"op":"mcm","clk":"AMduAPw7ANFh","pt":1659347606707,"mc":[{"id":"1.201590187","rc":[{"atb":[[9.4,36.86]],"id":45323444},{"atb":[[1.79,34.48]],"id":9570503},{"atb":[[3.9,44.48]],"id":12989514},{"atb":[[11,34.48]],"id":44621159},{"atb":[[5.6,46.48]],"id":44836671},{"atb":[[6.6,47.48]],"id":43885158},{"atb":[[8.8,31.6]],"id":46969227}]}]}
{"op":"mcm","clk":"AMduAPw7ANVh","pt":1659347606758,"mc":[{"id":"1.201590187","rc":[{"bdatb":[[9,9.4,36.86]],"id":45323444},{"bdatb":[[9,11,34.56]],"id":44621159},{"bdatb":[[7,5.6,46.8]],"id":44836671},{"bdatb":[[6,6.6,47.75]],"id":43885158}]}]}
{"op":"mcm","clk":"AMpuAP07ANdh","pt":1659347606811,"mc":[{"id":"1.201590187","rc":[{"atb":[[9.4,45.48]],"id":45323444}]}]}
{"op":"mcm","clk":"AMxuAP47ANxh","pt":1659347606861,"mc":[{"id":"1.201590187","rc":[{"bdatb":[[9,9.4,45.48]],"id":45323444}]}]}
{"op":"mcm","clk":"ANluAIM8AONh","pt":1659347607021,"mc":[{"id":"1.201590187","rc":[{"atb":[[13,1.19]],"id":45323444},{"atb":[[26,1]],"id":44621159},{"atb":[[8.8,48.84]],"id":46969227}]}]}
{"op":"mcm","clk":"ANluAIY8AONh","pt":1659347607071,"mc":[{"id":"1.201590187","rc":[{"bdatb":[[1,13,1.19]],"id":45323444},{"bdatl":[[9,2.44,153.92]],"id":9570503},{"bdatb":[[0,26,1]],"id":44621159}]}]}
{"op":"mcm","clk":"AOJuAIo8AOhh","pt":1659347607211,"mc":[{"id":"1.201590187","rc":[{"atb":[[13.5,5.7]],"id":45323444},{"atb":[[7.8,7.93]],"id":43885158}]}]}
{"op":"mcm","clk":"AONuAIo8AO1h","pt":1659347607261,"mc":[{"id":"1.201590187","rc":[{"bdatb":[[0,13.5,5.87]],"id":45323444},{"bdatl":[[8,2.4,77.4],[9,2.42,4.51]],"id":9570503},{"bdatb":[[1,7.8,7.93]],"id":43885158}]}]}
{"op":"mcm","clk":"AO9uAI48APNh","pt":1659347607417,"mc":[{"id":"1.201590187","rc":[{"atb":[[6.8,0.36]],"id":12989514},{"atb":[[25,4.21]],"id":44621159}]}]}
{"op":"mcm","clk":"APJuAI48APdh","pt":1659347607467,"mc":[{"id":"1.201590187","rc":[{"bdatl":[[7,2.4,71.46],[8,2.42,3.81],[9,2.44,175.27]],"id":9570503},{"bdatb":[[0,6.6,13.04],[1,6.2,10.68],[2,6,6.68],[3,5.6,4.41],[4,5.5,5.38],[5,5.3,8.6],[6,5.2,3.32],[7,5.1,2.27],[8,5,3],[9,4.9,6.55]],"id":12989514},{"bdatb":[[1,25,4.21]],"id":44621159},{"bdatl":[[9,13,59.29]],"id":44836671}]}]}
{"op":"mcm","clk":"APRuAJE8APlh","pt":1659347607521,"mc":[{"id":"1.201590187","rc":[{"atb":[[6.4,5.45]],"id":12989514}]}]}
{"op":"mcm","clk":"APVuAJI8AP1h","pt":1659347607571,"mc":[{"id":"1.201590187","rc":[{"bdatb":[[1,6.4,5.45],[2,6.2,10.3],[3,6,6.68],[4,5.6,4.41],[5,5.5,5.38],[6,5.3,8.6],[7,5.2,3.32],[8,5.1,2.27],[9,5,3]],"id":12989514}]}]}
{"op":"mcm","clk":"AJJvAJk8AJRi","pt":1659347607900,"mc":[{"id":"1.201590187","rc":[{"atb":[[6.8,11.36]],"id":12989514}]}]}
{"op":"mcm","clk":"AJJvAJs8AJZi","pt":1659347607950,"mc":[{"id":"1.201590187","rc":[{"bdatl":[[7,2.38,3.91],[8,2.4,77.4],[9,2.42,19.64]],"id":9570503},{"bdatb":[[0,6.8,11.36],[1,6.6,12.68],[2,6.4,5.45],[3,6.2,10.3],[4,6,6.68],[5,5.6,4.41],[6,5.5,5.38],[7,5.3,8.6],[8,5.2,3.32],[9,5.1,2.27]],"id":12989514},{"bdatl":[[9,13,60]],"id":44836671}]}]}
{"op":"mcm","clk":"AKRvAJ88AJ1i","pt":1659347608105,"mc":[{"id":"1.201590187","rc":[{"atb":[[7,1.15]],"id":12989514},{"atb":[[8,2.61]],"atl":[[9.2,3.84]],"id":43885158},{"atl":[[27,1.25]],"id":46969227}]}]}
{"op":"mcm","clk":"AKRvAJ88AKJi","pt":1659347608155,"mc":[{"id":"1.201590187","rc":[{"bdatb":[[6,10,13.26],[7,9.8,9],[8,9.6,21.11],[9,9.4,45.65]],"id":45323444},{"bdatb":[[6,1.94,15.75],[7,1.93,1.12],[8,1.91,107.9],[9,1.89,10.39]],"bdatl":[[6,2.32,1.03],[7,2.36,2.4],[8,2.38,5.39],[9,2.4,73.57]],"id":9570503},{"bdatb":[[0,7,1.15],[1,6.8,11.36],[2,6.6,12.68],[3,6.4,5.45],[4,6.2,10.3],[5,6,6.68],[6,5.7,1.84],[7,5.6,4.14],[8,5.5,3.74],[9,5.3,10.59]],"id":12989514},{"bdatb":[[6,13.5,8.81],[7,11.5,1.97],[8,11,34.56],[9,10.5,4.9]],"id":44621159},{"bdatb":[[8,5.5,24.59],[9,5.4,40.83]],"bdatl":[[8,12,1.61],[9,13,60.17]],"id":44836671},{"bdatb":[[0,8,2.61],[7,6.4,6.49],[8,6.2,10.35]],"bdatl":[[0,9.2,3.84],[9,15.5,1.15]],"id":43885158},{"bdatb":[[7,11.5,10.61],[8,10,9.25]],"bdatl":[[0,27,1.25],[1,28,7.64],[2,29,3.57],[3,34,5.16],[4,40,5.01],[5,80,1.66],[6,310,1],[7,990,2.15]],"id":46969227}]}]}
{"op":"mcm","clk":"AKpvAKA8AKZi","pt":1659347608213,"mc":[{"id":"1.201590187","rc":[{"atb":[[13.5,1.45]],"id":45323444},{"atb":[[7,1.5]],"id":12989514},{"atb":[[25,1.91]],"id":44621159},{"atb":[[7.8,10.31]],"id":43885158},{"atl":[[28,11.21]],"id":46969227}]}]}
{"op":"mcm","clk":"AKpvAKM8AKli","pt":1659347608263,"mc":[{"id":"1.201590187","rc":[{"bdatb":[[0,13.5,1.62]],"id":45323444},{"bdatl":[[7,2.36,3.44],[8,2.38,4.36],[9,2.4,71.87]],"id":9570503},{"bdatb":[[0,7,1.5]],"id":12989514},{"bdatb":[[1,25,1.91]],"id":44621159},{"bdatl":[[9,13,60.18]],"id":44836671},{"bdatb":[[1,7.8,10.31]],"id":43885158},{"bdatl":[[1,28,11.21]],"id":46969227}]}]}
{"op":"mcm","clk":"ALBvAKY8AKti","pt":1659347608317,"mc":[{"id":"1.201590187","rc":[{"atb":[[12.5,5.74]],"id":45323444},{"atl":[[29,0]],"id":46969227}]}]}
{"op":"mcm","clk":"ALBvAKk8ALFi","pt":1659347608367,"mc":[{"id":"1.201590187","rc":[{"bdatb":[[2,12.5,5.74]],"id":45323444},{"bdatl":[[2,34,5.16],[3,40,5.01],[4,80,1.66],[5,310,1],[6,990,2.15],[7,0,0]],"id":46969227}]}]}
{"op":"mcm","clk":"ALZvAKo8ALVi","pt":1659347608428,"mc":[{"id":"1.201590187","rc":[{"atb":[[26,3.18]],"atl":[[60,0]],"id":44621159}]}]}
{"op":"mcm","clk":"ALlvAKs8ALZi","pt":1659347608478,"mc":[{"id":"1.201590187","rc":[{"bdatb":[[0,26,3.18]],"bdatl":[[2,95,2.12]],"id":44621159}]}]}
{"op":"mcm","clk":"ALpvAKw8ALhi","pt":1659347608528,"mc":[{"id":"1.201590187","rc":[{"atl":[[55,0.64]],"id":44621159}]}]}
{"op":"mcm","clk":"AMBvAK08AL5i","pt":1659347608578,"mc":[{"id":"1.201590187","rc":[{"bdatl":[[2,95,2.76]],"id":44621159}]}]}
{"op":"mcm","clk":"ANJvALc8ANpi","pt":1659347608935,"mc":[{"id":"1.201590187","rc":[{"atb":[[11.5,5.54]],"id":45323444},{"atb":[[6.6,4.97]],"id":12989514}]}]}
{"op":"mcm","clk":"ANdvALo8ANxi","pt":1659347608986,"mc":[{"id":"1.201590187","rc":[{"bdatb":[[4,11.5,5.54]],"id":45323444},{"bdatb":[[2,6.6,4.97]],"id":12989514}]}]}
{"op":"mcm","clk":"ANlvALo8AOFi","pt":1659347609039,"mc":[{"id":"1.201590187","rc":[{"atb":[[13,4.06]],"id":45323444},{"atb":[[7,4.06]],"id":12989514},{"atb":[[8,5.41]],"id":43885158},{"atl":[[27,3.55]],"id":46969227}]}]}
{"op":"mcm","clk":"ANpvALw8AORi","pt":1659347609090,"mc":[{"id":"1.201590187","rc":[{"bdatb":[[1,13,4.06],[8,9.6,21.27],[9,9.4,47.4]],"id":45323444},{"bdatb":[[8,1.91,108.73],[9,1.9,9.5]],"bdatl":[[7,2.36,8.28],[8,2.38,2.73],[9,2.4,77.62]],"id":9570503},{"bdatb":[[0,7,4.06],[7,5.6,4.42],[8,5.5,3.45]],"id":12989514},{"bdatb":[[7,11.5,1.96]],"id":44621159},{"bdatl":[[9,12.5,1.13]],"id":44836671},{"bdatb":[[0,8,5.41]],"id":43885158},{"bdatl":[[0,27,3.55]],"id":46969227}]}]}
{"op":"mcm","clk":"AN1vAL48AOdi","pt":1659347609140,"mc":[{"id":"1.201590187","rc":[{"atb":[[12.5,1.14]],"bdatb":[[2,12.5,1.14]],"id":45323444},{"atb":[[7.8,3.65]],"bdatb":[[1,7.8,3.65]],"id":43885158}]}]}
{"op":"mcm","clk":"AOFvAME8AOxi","pt":1659347609199,"mc":[{"id":"1.201590187","rc":[{"atb":[[6.8,4.91]],"id":44836671}]}]}
{"op":"mcm","clk":"AOJvAMI8AO5i","pt":1659347609249,"mc":[{"id":"1.201590187","rc":[{"bdatl":[[9,2.4,74.51]],"id":9570503},{"bdatb":[[0,6.8,5.26]],"id":44836671}]}]}
{"op":"mcm","clk":"AOZvAMU8APJi","pt":1659347609304,"mc":[{"id":"1.201590187","rc":[{"atb":[[13,8.49]],"id":45323444},{"atb":[[7,15.35]],"id":44836671}]}]}
{"op":"mcm","clk":"AOZvAMc8APdi","pt":1659347609354,"mc":[{"id":"1.201590187","rc":[{"bdatb":[[1,13,8.49]],"id":45323444},{"bdatl":[[7,2.34,8.35],[8,2.36,2.75],[9,2.38,6.24]],"id":9570503},{"bdatb":[[0,7,15.35],[1,6.8,4.91],[2,6.6,5.83],[3,6.2,26.16],[4,6,29.74],[5,5.9,9],[6,5.8,10],[7,5.7,44.55],[8,5.6,46.8],[9,5.5,24.59]],"id":44836671}]}]}
{"op":"mcm","clk":"APVvAM08AIZj","pt":1659347609599,"mc":[{"id":"1.201590187","rc":[{"atb":[[25,1.8]],"id":44621159}]}]}
{"op":"mcm","clk":"APVvAM48AIlj","pt":1659347609650,"mc":[{"id":"1.201590187","rc":[{"bdatb":[[1,25,1.8]],"id":44621159}]}]}
{"op":"mcm","clk":"AI9wANk8AKJj","pt":1659347610015,"mc":[{"id":"1.201590187","rc":[{"atb":[[13,4.06]],"id":45323444},{"atb":[[26,1]],"id":44621159}]}]}
{"op":"mcm","clk":"AJBwANo8AKdj","pt":1659347610065,"mc":[{"id":"1.201590187","rc":[{"bdatb":[[1,13,4.06]],"id":45323444},{"bdatb":[[0,26,1]],"id":44621159}]}]}
{"op":"mcm","clk":"AJpwANw8AKxj","pt":1659347610221,"mc":[{"id":"1.201590187","rc":[{"atb":[[13.5,5.7]],"id":45323444}]}]}
{"op":"mcm","clk":"AJtwAN08ALJj","pt":1659347610271,"mc":[{"id":"1.201590187","rc":[{"bdatb":[[0,13.5,5.87]],"id":45323444},{"bdatl":[[7,2.34,11.13],[8,2.38,16.73],[9,2.4,72.57]],"id":9570503}]}]}
{"op":"mcm","clk":"AKZwAN48ALtj","pt":1659347610428,"mc":[{"id":"1.201590187","rc":[{"atb":[[7.8,1.26]],"id":43885158}]}]}
{"op":"mcm","clk":"AKdwAN88AL9j","pt":1659347610478,"mc":[{"id":"1.201590187","rc":[{"bdatl":[[8,2.38,10.39],[9,2.4,77.72]],"id":9570503},{"bdatb":[[1,7.8,1.26]],"id":43885158}]}]}
{"op":"mcm","clk":"AM5wAO88AN1j","pt":1659347611005,"mc":[{"id":"1.201590187","rc":[{"atl":[[38,2.87]],"id":44621159}]}]}
{"op":"mcm","clk":"AM5wAPA8AONj","pt":1659347611055,"mc":[{"id":"1.201590187","rc":[{"bdatl":[[0,38,2.87]],"id":44621159},{"bdatb":[[9,9.6,5.36]],"id":46969227}]}]}
{"op":"mcm","clk":"ANJwAPI8AORj","pt":1659347611110,"mc":[{"id":"1.201590187","rc":[{"atb":[[14,1.17],[13,3.06]],"id":45323444},{"atl":[[38,1.87]],"id":44621159}]}]}
{"op":"mcm","clk":"ANJwAPM8AOZj","pt":1659347611160,"mc":[{"id":"1.201590187","rc":[{"bdatb":[[0,14,1.17],[1,13.5,5.7],[2,13,3.06],[3,12.5,1.14],[4,12,4.6],[5,11.5,5.54],[6,11,1.23],[7,10,13.26],[8,9.8,9],[9,9.6,21.27]],"id":45323444},{"bdatl":[[6,2.32,7.06],[7,2.34,5.14]],"id":9570503},{"bdatl":[[0,38,1.87]],"id":44621159},{"bdatl":[[8,12,2.76],[9,13,59.85]],"id":44836671},{"bdatl":[[9,15.5,2.05]],"id":43885158},{"bdatb":[[9,9.6,1.74]],"id":46969227}]}]}
{"op":"mcm","clk":"AN1wAPc8AOxj","pt":1659347611402,"mc":[{"id":"1.201590187","rc":[{"atb":[[13.5,4.43]],"id":45323444}]}]}
{"op":"mcm","clk":"AN1wAPg8AO9j","pt":1659347611452,"mc":[{"id":"1.201590187","rc":[{"bdatb":[[1,13.5,4.43]],"id":45323444}]}]}
{"op":"mcm","clk":"AOhwAPo8APdj","pt":1659347611613,"mc":[{"id":"1.201590187","rc":[{"atb":[[1.79,0]],"id":9570503},{"atb":[[6.6,13]],"id":43885158}]}]}
{"op":"mcm","clk":"AOhwAPs8APhj","pt":1659347611663,"mc":[{"id":"1.201590187","rc":[{"bdatb":[[6,6.6,13.27]],"id":43885158}]}]}
{"op":"mcm","clk":"APBwAP48APtj","pt":1659347611716,"mc":[{"id":"1.201590187","rc":[{"atb":[[3.9,61.72]],"id":12989514}]}]}
{"op":"mcm","clk":"APVwAII9AP9j","pt":1659347611817,"mc":[{"id":"1.201590187","rc":[{"atb":[[1.75,17.24]],"id":9570503},{"atb":[[5.6,63.72]],"id":44836671},{"atb":[[6,31.24]],"id":43885158}]}]}
{"op":"mcm","clk":"APVwAIU9AIJk","pt":1659347611867,"mc":[{"id":"1.201590187","rc":[{"bdatb":[[8,5.6,64.04]],"id":44836671},{"bdatb":[[9,6,34.68]],"id":43885158}]}]}
{"op":"mcm","clk":"APpwAIc9AINk","pt":1659347611919,"mc":[{"id":"1.201590187","rc":[{"atb":[[9.4,62.72]],"id":45323444}]}]}
{"op":"mcm","clk":"AP1wAIo9AItk","pt":1659347612019,"mc":[{"id":"1.201590187","rc":[{"atb":[[13.5,0.18]],"id":45323444}]}]}
{"op":"mcm","clk":"AIBxAIw9AJFk","pt":1659347612069,"mc":[{"id":"1.201590187","rc":[{"bdatb":[[1,13,3.24],[2,12.5,1.14],[3,12,4.6],[4,11.5,5.54],[5,11,1.23],[6,10,13.26],[7,9.8,9],[8,9.6,21.27],[9,9.4,64.64]],"id":45323444},{"bdatl":[[7,2.34,1.04],[8,2.36,4.07],[9,2.38,6.24]],"id":9570503},{"bdatl":[[9,13,59.3]],"id":44836671}]}]}
{"op":"mcm","clk":"AI1xAJE9AJhk","pt":1659347612224,"mc":[{"id":"1.201590187","rc":[{"atb":[[14,5.25]],"id":45323444}]}]}
{"op":"mcm","clk":"AI9xAJU9AJ1k","pt":1659347612274,"mc":[{"id":"1.201590187","rc":[{"bdatb":[[0,14,5.25]],"id":45323444},{"bdatl":[[6,2.32,11.21],[7,2.34,1.03],[8,2.36,6.29],[9,2.38,4.15]],"id":9570503},{"bdatl":[[9,13,60.04]],"id":44836671}]}]}
{"op":"mcm","clk":"AJtxAJs9AKNk","pt":1659347612430,"mc":[{"id":"1.201590187","rc":[{"atb":[[13,0.19]],"id":45323444}]}]}
{"op":"mcm","clk":"AJ1xAJ49AKdk","pt":1659347612480,"mc":[{"id":"1.201590187","rc":[{"bdatb":[[1,12.5,1.51],[2,12,4.6],[3,11.5,5.54],[4,11,1.23],[5,10,13.26],[6,9.8,9],[7,9.6,21.27],[8,9.4,64.64],[9,9.2,12]],"id":45323444}]}]}
{"op":"mcm","clk":"AKBxAKM9AKhk","pt":1659347612534,"mc":[{"id":"1.201590187","rc":[{"atb":[[12,7.48]],"id":45323444},{"atb":[[2.02,26.04]],"id":9570503}]}]}
{"op":"mcm","clk":"AKNxAKQ9AK1k","pt":1659347612585,"mc":[{"id":"1.201590187","rc":[{"bdatb":[[2,12,7.48]],"id":45323444},{"bdatb":[[1,2.02,26.04]],"id":9570503}]}]}
{"op":"mcm","clk":"AKpxAKc9AK1k","pt":1659347612635,"mc":[{"id":"1.201590187","rc":[{"atb":[[1.17,1.68]],"id":44621159},{"atb":[[7.6,6.78]],"id":43885158}]}]}
{"op":"mcm","clk":"AK5xAKc9ALFk","pt":1659347612685,"mc":[{"id":"1.201590187","rc":[{"bdatb":[[2,7.6,6.78]],"id":43885158}]}]}
{"op":"mcm","clk":"ALpxALE9ALZk","pt":1659347612803,"mc":[{"id":"1.201590187","rc":[{"atb":[[1.17,0.1]],"id":44621159}]}]}
{"op":"mcm","clk":"AMZxALg9AMJk","pt":1659347613008,"mc":[{"id":"1.201590187","rc":[{"atb":[[14,1.17]],"id":45323444},{"atb":[[1.17,0]],"id":44621159}]}]}
{"op":"mcm","clk":"AMZxALo9AMhk","pt":1659347613059,"mc":[{"id":"1.201590187","rc":[{"bdatb":[[0,14,1.17]],"id":45323444},{"bdatl":[[6,2.32,7.06],[7,2.34,1.04],[8,2.36,1.05],[9,2.38,3]],"id":9570503},{"bdatl":[[9,13,59.3]],"id":44836671}]}]}
{"op":"mcm","clk":"AMlxAL49AMlk","pt":1659347613119,"mc":[{"id":"1.201590187","rc":[{"atb":[[13.5,4.43]],"id":45323444},{"atb":[[26,1.1]],"id":44621159}]}]}
{"op":"mcm","clk":"AMtxAL89AM9k","pt":1659347613169,"mc":[{"id":"1.201590187","rc":[{"bdatb":[[1,13.5,4.43],[2,12.5,1.33],[3,12,7.48],[4,11.5,5.54],[5,11,1.23],[6,10,13.26],[7,9.8,9],[8,9.6,21.27],[9,9.4,64.64]],"id":45323444},{"bdatl":[[7,2.34,5.14],[8,2.38,10.39],[9,2.4,77.72]],"id":9570503},{"bdatb":[[0,26,1.1]],"id":44621159},{"bdatl":[[9,13,60.04]],"id":44836671}]}]}
{"op":"mcm","clk":"APVxAMs9APBk","pt":1659347613838,"mc":[{"id":"1.201590187","rc":[{"atb":[[13.5,0.18]],"id":45323444}]}]}
{"op":"mcm","clk":"APdxAMs9APNk","pt":1659347613888,"mc":[{"id":"1.201590187","rc":[{"bdatb":[[1,12.5,1.51],[2,12,7.48],[3,11.5,5.54],[4,11,1.23],[5,10,13.26],[6,9.8,9],[7,9.6,21.27],[8,9.4,64.64],[9,9.2,12]],"id":45323444},{"bdatl":[[7,2.34,1.04],[8,2.36,1.05],[9,2.38,3]],"id":9570503},{"bdatl":[[9,13,59.3]],"id":44836671}]}]}
{"op":"mcm","clk":"AIFyAM49APlk","pt":1659347614047,"mc":[{"id":"1.201590187","rc":[{"atb":[[12.5,5.74]],"id":45323444}]}]}
{"op":"mcm","clk":"AIRyANA9AP1k","pt":1659347614097,"mc":[{"id":"1.201590187","rc":[{"bdatb":[[1,12.5,6.11]],"id":45323444}]}]}
{"op":"mcm","clk":"AJFyANI9AIJl","pt":1659347614211,"mc":[{"id":"1.201590187","rc":[{"atb":[[26,3.28]],"id":44621159}]}]}
{"op":"mcm","clk":"AJJyANM9AIdl","pt":1659347614261,"mc":[{"id":"1.201590187","rc":[{"bdatb":[[0,26,3.28]],"id":44621159}]}]}
{"op":"mcm","clk":"AJdyANU9AIll","pt":1659347614320,"mc":[{"id":"1.201590187","rc":[{"atl":[[29,3.57],[28,7.64]],"id":46969227}]}]}
{"op":"mcm","clk":"AJtyANc9AIxl","pt":1659347614371,"mc":[{"id":"1.201590187","rc":[{"bdatl":[[1,28,7.64],[2,29,3.57],[3,34,5.16],[4,40,5.01],[5,80,1.66],[6,310,1],[7,990,2.15]],"id":46969227}]}]}
{"op":"mcm","clk":"AKNyANg9AI5l","pt":1659347614430,"mc":[{"id":"1.201590187","rc":[{"atb":[[13,1.34]],"id":45323444}]}]}
{"op":"mcm","clk":"AKNyANg9AJJl","pt":1659347614480,"mc":[{"id":"1.201590187","rc":[{"bdatb":[[1,13,1.52],[2,12.5,5.74],[3,12,7.48],[4,11.5,5.54],[5,11,1.23],[6,10,13.26],[7,9.8,9],[8,9.6,21.27],[9,9.4,64.64]],"id":45323444},{"bdatl":[[8,2.36,4.07],[9,2.38,3.28]],"id":9570503}]}]}
{"op":"mcm","clk":"AKhyANk9AJdl","pt":1659347614531,"mc":[{"id":"1.201590187","rc":[{"atl":[[9.2,0],[9,6.82]],"id":12989514},{"atb":[[24,0.49],[23,4.55]],"id":44621159},{"atb":[[8,4.26]],"atl":[[9.2,2.69]],"id":43885158}]}]}
{"op":"mcm","clk":"AKhyANs9AJpl","pt":1659347614581,"mc":[{"id":"1.201590187","rc":[{"bdatb":[[8,9.6,21],[9,9.4,64.91]],"id":45323444},{"bdatb":[[6,1.94,12.76],[7,1.93,3.01],[8,1.92,1.12],[9,1.91,107.36]],"bdatl":[[9,2.38,2.38]],"id":9570503},{"bdatb":[[7,5.6,3.57],[8,5.5,4.32],[9,5.3,8.6]],"bdatl":[[3,9,6.82],[4,9.4,3.67],[5,9.6,11.09],[6,10,17.36],[7,10.5,12.47],[8,11,33.84],[9,12,13.68]],"id":12989514},{"bdatb":[[2,23,5.04],[6,13.5,8.38],[7,11.5,2.42],[9,10.5,4.35]],"id":44621159},{"bdatb":[[0,8,4.26]],"bdatl":[[0,9.2,2.69]],"id":43885158},{"bdatb":[[7,11.5,10.42],[8,10,9.46]],"id":46969227}]}]}
{"op":"mcm","clk":"ALxyAOI9AK5l","pt":1659347614936,"mc":[{"id":"1.201590187","rc":[{"atb":[[12.5,1.14]],"id":45323444},{"atb":[[26,1.1]],"id":44621159}]}]}
{"op":"mcm","clk":"AMByAOQ9ALRl","pt":1659347614986,"mc":[{"id":"1.201590187","rc":[{"bdatb":[[2,12.5,1.14]],"id":45323444},{"bdatb":[[0,26,1.1]],"id":44621159}]}]}
{"op":"mcm","clk":"AMtyAOc9ALtl","pt":1659347615146,"mc":[{"id":"1.201590187","rc":[{"atb":[[13,5.76]],"id":45323444}]}]}
{"op":"mcm","clk":"AM5yAOk9AMBl","pt":1659347615196,"mc":[{"id":"1.201590187","rc":[{"bdatb":[[1,13,5.94]],"id":45323444}]}]}
{"op":"mcm","clk":"ANdyAO09AMZl","pt":1659347615345,"mc":[{"id":"1.201590187","rc":[{"atb":[[25,4.1]],"id":44621159}]}]}
{"op":"mcm","clk":"ANdyAPA9AMpl","pt":1659347615395,"mc":[{"id":"1.201590187","rc":[{"bdatb":[[1,25,4.1]],"id":44621159}]}]}
{"op":"mcm","clk":"APZyAPw9AOZl","pt":1659347615825,"mc":[{"id":"1.201590187","rc":[{"atb":[[2.02,28.41]],"id":9570503}]}]}
{"op":"mcm","clk":"APdyAP09AOtl","pt":1659347615876,"mc":[{"id":"1.201590187","rc":[{"bdatb":[[1,2.02,28.41]],"id":9570503}]}]}
{"op":"mcm","clk":"AIVzAP89APJl","pt":1659347616033,"mc":[{"id":"1.201590187","rc":[{"atb":[[13,1.34]],"id":45323444},{"atb":[[25,1.8]],"id":44621159}]}]}
{"op":"mcm","clk":"AIVzAIA+APhl","pt":1659347616084,"mc":[{"id":"1.201590187","rc":[{"bdatb":[[1,13,1.52]],"id":45323444},{"bdatb":[[1,25,1.8]],"id":44621159}]}]}
{"op":"mcm","clk":"ALNzAJQ+AKFm","pt":1659347616746,"mc":[{"id":"1.201590187","rc":[{"atb":[[13,5.76]],"id":45323444}]}]}
{"op":"mcm","clk":"ALtzAJQ+AKNm","pt":1659347616796,"mc":[{"id":"1.201590187","rc":[{"bdatb":[[1,13,5.94]],"id":45323444}]}]}
{"op":"mcm","clk":"AL5zAJQ+AKRm","pt":1659347616847,"mc":[{"id":"1.201590187","rc":[{"atb":[[11.5,11.31]],"id":45323444},{"atb":[[2.02,30.79]],"id":9570503},{"atb":[[7,15.18]],"trd":[[7,21.13]],"tv":203.46,"id":44836671}],"tv":1388.97}]}
{"op":"mcm","clk":"AL9zAJU+AKhm","pt":1659347616897,"mc":[{"id":"1.201590187","rc":[{"bdatb":[[4,11.5,11.31]],"id":45323444},{"bdatb":[[1,2.02,30.79]],"id":9570503},{"bdatb":[[0,7,15.18]],"id":44836671}]}]}
{"op":"mcm","clk":"AMVzAJU+AKhm","pt":1659347616950,"mc":[{"id":"1.201590187","rc":[{"atb":[[1.75,34.48]],"id":9570503},{"atb":[[26,3.28]],"id":44621159},{"atb":[[6,48.48]],"id":43885158}]}]}
{"op":"mcm","clk":"AMZzAJY+AKxm","pt":1659347617000,"mc":[{"id":"1.201590187","rc":[{"bdatb":[[0,26,3.28]],"id":44621159},{"bdatb":[[9,6,51.92]],"id":43885158}]}]}
{"op":"mcm","clk":"AOpzAJw+AMNm","pt":1659347617438,"mc":[{"id":"1.201590187","rc":[{"atb":[[25,0]],"id":44621159}]}]}
{"op":"mcm","clk":"AO5zAJ8+AMhm","pt":1659347617489,"mc":[{"id":"1.201590187","rc":[{"bdatb":[[1,23,5.04],[2,21,5],[3,18.5,1.37],[4,15.5,4.19],[5,13.5,8.38],[6,11.5,2.42],[7,11,34.56],[8,10.5,4.35],[9,10,121.24]],"id":44621159}]}]}
{"op":"mcm","clk":"APJzAKA+AMpm","pt":1659347617539,"mc":[{"id":"1.201590187","rc":[{"atb":[[24,2.29]],"id":44621159}]}]}
{"op":"mcm","clk":"APdzAKI+AM1m","pt":1659347617589,"mc":[{"id":"1.201590187","rc":[{"bdatb":[[1,24,2.29],[2,23,4.55],[3,21,5],[4,18.5,1.37],[5,15.5,4.19],[6,13.5,8.38],[7,11.5,2.42],[8,11,34.56],[9,10.5,4.35]],"id":44621159}]}]}
{"op":"mcm","clk":"APlzAKM+AM5m","pt":1659347617644,"mc":[{"id":"1.201590187","rc":[{"atb":[[13,1.34]],"atl":[[24,0]],"id":45323444},{"atb":[[26,1.1]],"id":44621159}]}]}
{"op":"mcm","clk":"AP1zAKc+ANNm","pt":1659347617694,"mc":[{"id":"1.201590187","rc":[{"bdatb":[[1,13,1.52]],"bdatl":[[3,25,5.61]],"id":45323444},{"bdatl":[[9,2.4,73.78]],"id":9570503},{"bdatb":[[0,26,1.1]],"id":44621159}]}]}
{"op":"mcm","clk":"AIB0AKc+ANdm","pt":1659347617748,"mc":[{"id":"1.201590187","rc":[{"atl":[[1000,0.48]],"id":45323444}]}]}
{"op":"mcm","clk":"AIt0AK0+AN1m","pt":1659347617848,"mc":[{"id":"1.201590187","rc":[{"atb":[[13.5,4.43]],"id":45323444}]}]}
{"op":"mcm","clk":"AIt0AK8+AOBm","pt":1659347617898,"mc":[{"id":"1.201590187","rc":[{"bdatb":[[1,13.5,4.43],[2,13,1.34],[3,12.5,1.14],[4,12,7.48],[5,11.5,11.31],[6,11,1.23],[7,10,13.26],[8,9.8,9],[9,9.6,21]],"id":45323444},{"bdatl":[[7,2.34,5.14],[8,2.38,2.38],[9,2.4,75.54]],"id":9570503},{"bdatl":[[9,13,60.04]],"id":44836671}]}]}
{"op":"mcm","clk":"AJN0ALA+AOJm","pt":1659347617950,"mc":[{"id":"1.201590187","rc":[{"atl":[[1000,2]],"id":44621159}]}]}
{"op":"mcm","clk":"AJN0ALA+AOdm","pt":1659347618000,"mc":[{"id":"1.201590187","rc":[{"bdatl":[[5,1000,2]],"id":44621159}]}]}
{"op":"mcm","clk":"AJl0ALY+AO5m","pt":1659347618055,"mc":[{"id":"1.201590187","rc":[{"atl":[[2.12,0]],"bdatl":[[0,2.14,66.35]],"id":9570503},{"atb":[[24,4.71]],"bdatb":[[1,24,4.71],[6,13.5,8.39]],"id":44621159},{"bdatb":[[7,10,13.27]],"id":45323444},{"bdatb":[[6,5.7,1.85]],"id":12989514},{"bdatb":[[8,5.6,63.72],[9,5.5,24.92]],"id":44836671},{"bdatb":[[6,6.6,13],[7,6.4,6.77]],"id":43885158},{"bdatb":[[7,11.5,10.43]],"id":46969227}]}]}
{"op":"mcm","clk":"ALp0AMg+AI1n","pt":1659347618631,"mc":[{"id":"1.201590187","rc":[{"atl":[[670,0.82]],"id":45323444},{"atl":[[670,0.82]],"id":9570503},{"atl":[[670,0.82]],"id":12989514},{"atl":[[670,0.82]],"id":44621159},{"atl":[[670,0.82]],"id":44836671},{"atl":[[670,0.82]],"id":43885158},{"atl":[[670,0.82]],"id":46969227}]}]}
{"op":"mcm","clk":"ALx0AMk+AJBn","pt":1659347618683,"mc":[{"id":"1.201590187","rc":[{"bdatl":[[4,900,1.06],[5,990,1.83],[6,1000,2]],"id":44621159},{"bdatl":[[7,900,1.06],[8,990,1.91]],"id":46969227}]}]}
{"op":"mcm","clk":"AL90AMs+AJVn","pt":1659347618745,"mc":[{"id":"1.201590187","rc":[{"atl":[[2.16,9.18]],"id":9570503}]}]}
{"op":"mcm","clk":"AMR0AM4+AJln","pt":1659347618795,"mc":[{"id":"1.201590187","rc":[{"bdatl":[[1,2.16,9.18]],"id":9570503}]}]}
{"op":"mcm","clk":"AMh0AM8+AJ9n","pt":1659347618845,"mc":[{"id":"1.201590187","rc":[{"atb":[[13.5,0.18]],"id":45323444},{"atb":[[6.4,0.38]],"id":12989514},{"atb":[[24,2.29]],"id":44621159}]}]}
{"op":"mcm","clk":"AMt0ANE+AKFn","pt":1659347618895,"mc":[{"id":"1.201590187","rc":[{"bdatb":[[1,13,1.52],[2,12.5,1.14],[3,12,7.48],[4,11.5,11.31],[5,11,1.23],[6,10,13.27],[7,9.8,9],[8,9.6,21],[9,9.4,64.91]],"id":45323444},{"bdatl":[[7,2.34,1.04],[8,2.36,4.07],[9,2.4,73.78]],"id":9570503},{"bdatb":[[3,6.2,10.68],[4,6,6.68],[5,5.7,1.85],[6,5.6,3.57],[7,5.5,4.32],[8,5.3,8.6],[9,5.2,3.32]],"id":12989514},{"bdatb":[[1,24,2.29]],"id":44621159},{"bdatl":[[9,13,59.3]],"id":44836671}]}]}
{"op":"mcm","clk":"AM50ANQ+AKNn","pt":1659347618948,"mc":[{"id":"1.201590187","rc":[{"atb":[[7,9.13]],"id":12989514}]}]}
{"op":"mcm","clk":"ANN0ANY+AKpn","pt":1659347618998,"mc":[{"id":"1.201590187","rc":[{"bdatl":[[8,2.36,4.16],[9,2.38,2.29]],"id":9570503},{"bdatb":[[0,7,9.13]],"id":12989514}]}]}
{"op":"mcm","clk":"ANV0ANc+AKtn","pt":1659347619051,"mc":[{"id":"1.201590187","rc":[{"atb":[[12.5,5.74]],"id":45323444}]}]}
{"op":"mcm","clk":"ANd0ANg+ALVn","pt":1659347619101,"mc":[{"id":"1.201590187","rc":[{"bdatb":[[2,12.5,5.74]],"id":45323444}]}]}
{"op":"mcm","clk":"AON0ANs+AL1n","pt":1659347619221,"mc":[{"id":"1.201590187","rc":[{"atb":[[25,2.3]],"id":44621159}]}]}
{"op":"mcm","clk":"AON0ANw+AMNn","pt":1659347619271,"mc":[{"id":"1.201590187","rc":[{"bdatl":[[8,2.36,6.47],[9,2.4,75.55]],"id":9570503},{"bdatb":[[1,25,2.3],[2,24,2.29],[3,23,4.55],[4,21,5],[5,18.5,1.37],[6,15.5,4.19],[7,13.5,8.39],[8,11.5,2.42],[9,11,34.56]],"id":44621159}]}]}
{"op":"mcm","clk":"AJR1API+AP5n","pt":1659347620067,"mc":[{"id":"1.201590187","rc":[{"atb":[[12.5,1.14]],"id":45323444},{"atb":[[25,0]],"id":44621159}]}]}
{"op":"mcm","clk":"AJh1API+AIVo","pt":1659347620117,"mc":[{"id":"1.201590187","rc":[{"bdatb":[[2,12.5,1.14]],"id":45323444},{"bdatl":[[8,2.36,4.16],[9,2.38,2.29]],"id":9570503},{"bdatb":[[1,24,2.29],[2,23,4.55],[3,21,5],[4,18.5,1.37],[5,15.5,4.19],[6,13.5,8.39],[7,11.5,2.42],[8,11,34.56],[9,10.5,4.35]],"id":44621159}]}]}
{"op":"mcm","clk":"AJ91APo+AJFo","pt":1659347620261,"mc":[{"id":"1.201590187","rc":[{"atb":[[13,5.76]],"id":45323444}]}]}
{"op":"mcm","clk":"AKN1APs+AJVo","pt":1659347620311,"mc":[{"id":"1.201590187","rc":[{"bdatb":[[1,13,5.94]],"id":45323444}]}]}
{"op":"mcm","clk":"AK51AP0+AKFo","pt":1659347620431,"mc":[{"id":"1.201590187","rc":[{"atb":[[24,4.71]],"id":44621159}]}]}
{"op":"mcm","clk":"AK91AP8+AKVo","pt":1659347620481,"mc":[{"id":"1.201590187","rc":[{"bdatb":[[1,24,4.71]],"id":44621159}]}]}
{"op":"mcm","clk":"AMZ1AIs/ALlo","pt":1659347620848,"mc":[{"id":"1.201590187","rc":[{"atl":[[9.4,4.55]],"id":43885158}]}]}
{"op":"mcm","clk":"AMt1AI8/AL5o","pt":1659347620898,"mc":[{"id":"1.201590187","rc":[{"bdatb":[[8,5.3,3.14],[9,5.2,8.88]],"id":12989514},{"bdatb":[[9,10.5,1.26]],"id":44621159},{"bdatl":[[1,9.4,4.55]],"id":43885158},{"bdatb":[[9,9.6,1.38]],"id":46969227}]}]}
{"op":"mcm","clk":"AM51AI8/AMJo","pt":1659347620948,"mc":[{"id":"1.201590187","rc":[{"atb":[[8.2,1.15]],"atl":[[10.5,3.45],[9.2,3.84]],"id":43885158}]}]}
{"op":"mcm","clk":"ANB1AJE/AMdo","pt":1659347620998,"mc":[{"id":"1.201590187","rc":[{"bdatb":[[8,9.6,21.27],[9,9.4,64.64]],"id":45323444},{"bdatb":[[6,1.94,15.75],[7,1.93,1.12],[8,1.91,108.73],[9,1.9,9.5]],"bdatl":[[5,2.3,5.82],[6,2.32,3],[9,2.38,6.25]],"id":9570503},{"bdatb":[[6,5.6,4.42],[7,5.5,3.45],[8,5.3,4.48],[9,5.2,7.51]],"bdatl":[[9,12,13.71]],"id":12989514},{"bdatb":[[6,13.5,8.82],[7,11.5,1.96],[9,10.5,2.27]],"id":44621159},{"bdatl":[[7,11.5,13.02],[8,12,1.98]],"id":44836671},{"bdatb":[[0,8.2,1.15],[1,8,4.26],[2,7.8,1.26],[3,7.6,6.78],[4,7.4,12.66],[5,7.2,3.71],[6,7,5],[7,6.6,13],[8,6.4,6.77],[9,6.2,10.35]],"bdatl":[[0,9.2,3.84],[3,10.5,3.45],[4,11.5,2.65],[5,12,1.4],[6,12.5,18],[7,14,13.2],[8,14.5,1],[9,15,12]],"id":43885158},{"bdatb":[[7,11.5,10.62],[8,10,9.25],[9,9.6,1.74]],"id":46969227}]}]}
{"op":"mcm","clk":"ANt1AJM/ANNo","pt":1659347621159,"mc":[{"id":"1.201590187","rc":[{"atb":[[13,4.61]],"id":45323444},{"atb":[[8,4.56]],"id":43885158}]}]}
{"op":"mcm","clk":"AN51AJQ/ANVo","pt":1659347621209,"mc":[{"id":"1.201590187","rc":[{"bdatb":[[1,13,4.79]],"id":45323444},{"bdatl":[[9,2.38,7.26]],"id":9570503},{"bdatb":[[1,8,4.56]],"id":43885158}]}]}
{"op":"mcm","clk":"AON1AJU/ANZo","pt":1659347621259,"mc":[{"id":"1.201590187","rc":[{"atb":[[13,0.19]],"bdatb":[[1,12.5,1.51],[2,12,7.48],[3,11.5,11.31],[4,11,1.23],[5,10,13.27],[6,9.8,9],[7,9.6,21.27],[8,9.4,64.64],[9,9.2,12]],"id":45323444},{"atb":[[24,2.29]],"bdatb":[[1,24,2.29]],"id":44621159},{"bdatl":[[8,2.36,1.05],[9,2.38,3.08]],"id":9570503}]}]}
{"op":"mcm","clk":"AOp1AJs/AN1o","pt":1659347621327,"mc":[{"id":"1.201590187","rc":[{"atb":[[13.5,4.43]],"id":45323444}]}]}
{"op":"mcm","clk":"AOt1AJs/AN1o","pt":1659347621377,"mc":[{"id":"1.201590187","rc":[{"bdatb":[[1,13.5,4.43],[2,12.5,1.33],[3,12,7.48],[4,11.5,11.31],[5,11,1.23],[6,10,13.27],[7,9.8,9],[8,9.6,21.27],[9,9.4,64.64]],"id":45323444},{"bdatl":[[7,2.34,5.23],[8,2.36,7.32],[9,2.38,4.15]],"id":9570503},{"bdatl":[[9,13,60.05]],"id":44836671}]}]}
{"op":"mcm","clk":"APF1AKA/AOFo","pt":1659347621427,"mc":[{"id":"1.201590187","rc":[{"atb":[[25,2.3]],"id":44621159}]}]}
{"op":"mcm","clk":"APF1AKI/AOJo","pt":1659347621477,"mc":[{"id":"1.201590187","rc":[{"bdatl":[[7,2.34,12.61],[8,2.36,4.18],[9,2.38,3.41]],"id":9570503},{"bdatb":[[1,25,2.3],[2,24,2.29],[3,23,4.55],[4,21,5],[5,18.5,1.37],[6,15.5,4.19],[7,13.5,8.82],[8,11.5,1.96],[9,11,34.56]],"id":44621159}]}]}
{"op":"mcm","clk":"AIB2AKU/AO5o","pt":1659347621643,"mc":[{"id":"1.201590187","rc":[{"atb":[[2.02,26.85]],"atl":[[2.14,62.77]],"id":9570503},{"atb":[[6.6,2.69]],"atl":[[8.4,4]],"id":12989514},{"atb":[[6.8,2.64]],"atl":[[7.6,156.73]],"id":44836671},{"atb":[[7.4,10.26]],"atl":[[9.4,2.23]],"id":43885158}]}]}
{"op":"mcm","clk":"AIB2AKY/APBo","pt":1659347621694,"mc":[{"id":"1.201590187","rc":[{"bdatb":[[1,2.02,26.85]],"bdatl":[[0,2.14,62.77]],"id":9570503},{"bdatb":[[2,6.6,2.69],[8,5.3,3.15],[9,5.2,8.88]],"bdatl":[[2,8.4,4]],"id":12989514},{"bdatb":[[1,6.8,2.64]],"bdatl":[[1,7.6,156.73]],"id":44836671},{"bdatb":[[4,7.4,10.26]],"bdatl":[[1,9.4,2.23]],"id":43885158},{"bdatb":[[9,9.4,1.77]],"id":46969227}]}]}
{"op":"mcm","clk":"AI92AKs/APpo","pt":1659347621840,"mc":[{"id":"1.201590187","rc":[{"atl":[[8,6]],"id":12989514}]}]}
{"op":"mcm","clk":"AI92AK0/AP5o","pt":1659347621890,"mc":[{"id":"1.201590187","rc":[{"bdatb":[[7,9.8,9.27],[8,9.6,22.98],[9,9.4,62.72]],"id":45323444},{"bdatb":[[8,1.92,1.36],[9,1.91,117.31]],"id":9570503},{"bdatl":[[1,8,6],[2,8.2,2.52],[3,8.4,4],[4,9,6.82],[5,9.4,3.67],[6,9.6,11.09],[7,10,17.36],[8,10.5,12.47],[9,11,33.84]],"id":12989514},{"bdatb":[[8,12,1.96],[9,11,36.87]],"id":44621159},{"bdatb":[[8,10.5,2.05],[9,10,7.41]],"id":46969227}]}]}
{"op":"mcm","clk":"AJ92ALE/AIZp","pt":1659347622145,"mc":[{"id":"1.201590187","rc":[{"atl":[[95,0]],"id":44621159},{"atb":[[8,1.76]],"id":43885158}]}]}
{"op":"mcm","clk":"AKF2ALM/AIlp","pt":1659347622195,"mc":[{"id":"1.201590187","rc":[{"bdatl":[[7,2.34,3.04],[9,2.38,12.83]],"id":9570503},{"bdatl":[[2,170,2.76],[3,900,1.06],[4,990,1.83],[5,1000,2],[6,0,0]],"id":44621159},{"bdatl":[[9,13,59.66]],"id":44836671},{"bdatb":[[1,8,1.76]],"id":43885158}]}]}
{"op":"mcm","clk":"AKV2ALQ/AItp","pt":1659347622245,"mc":[{"id":"1.201590187","rc":[{"atb":[[13.5,0.18]],"id":45323444},{"atb":[[25,0]],"atl":[[80,2.2]],"id":44621159}]}]}
{"op":"mcm","clk":"AKZ2ALU/AIxp","pt":1659347622295,"mc":[{"id":"1.201590187","rc":[{"bdatb":[[1,12.5,1.51],[2,12,7.48],[3,11.5,11.31],[4,11,1.23],[5,10,13.27],[6,9.8,9.27],[7,9.6,22.98],[8,9.4,62.72],[9,9.2,13.82]],"id":45323444},{"bdatl":[[7,2.34,1.04],[8,2.36,1.05],[9,2.4,76.47]],"id":9570503},{"bdatb":[[1,24,2.29],[2,23,4.55],[3,21,5],[4,18.5,1.37],[5,15.5,4.19],[6,13.5,8.82],[7,12,1.96],[8,11,36.87],[9,10.5,1.97]],"bdatl":[[2,80,2.96],[3,170,2],[4,900,1.06],[5,990,1.83],[6,1000,2]],"id":44621159},{"bdatl":[[9,13,59.3]],"id":44836671}]}]}
{"op":"mcm","clk":"AK12ALY/AI5p","pt":1659347622361,"mc":[{"id":"1.201590187","rc":[{"atb":[[12.5,5.74]],"id":45323444}]}]}
{"op":"mcm","clk":"ALN2ALg/AJFp","pt":1659347622411,"mc":[{"id":"1.201590187","rc":[{"bdatb":[[1,12.5,6.11]],"id":45323444}]}]}
{"op":"mcm","clk":"AL12ALo/AJtp","pt":1659347622531,"mc":[{"id":"1.201590187","rc":[{"atb":[[24,4.71]],"id":44621159}]}]}
{"op":"mcm","clk":"AL12ALo/AJtp","pt":1659347622581,"mc":[{"id":"1.201590187","rc":[{"bdatb":[[1,24,4.71]],"id":44621159}]}]}
{"op":"mcm","clk":"AOd2ANU/AMRp","pt":1659347623241,"mc":[{"id":"1.201590187","rc":[{"atb":[[12.5,1.14]],"id":45323444},{"atb":[[24,2.29]],"id":44621159}]}]}
{"op":"mcm","clk":"AOh2ANY/AMhp","pt":1659347623291,"mc":[{"id":"1.201590187","rc":[{"bdatb":[[1,12.5,1.51]],"id":45323444},{"bdatb":[[1,24,2.29]],"id":44621159}]}]}
{"op":"mcm","clk":"APV2ANs/AM5p","pt":1659347623449,"mc":[{"id":"1.201590187","rc":[{"atb":[[13,4.61]],"id":45323444}]}]}
{"op":"mcm","clk":"APl2AN0/AM9p","pt":1659347623500,"mc":[{"id":"1.201590187","rc":[{"bdatb":[[1,13,4.79],[2,12.5,1.14],[3,12,7.48],[4,11.5,11.31],[5,11,1.23],[6,10,13.27],[7,9.8,9.27],[8,9.6,22.98],[9,9.4,62.72]],"id":45323444},{"bdatl":[[8,2.36,1.99],[9,2.38,2.15]],"id":9570503}]}]}
{"op":"mcm","clk":"AIJ3AN8/ANZp","pt":1659347623663,"mc":[{"id":"1.201590187","rc":[{"atb":[[25,2.3]],"id":44621159}]}]}
{"op":"mcm","clk":"AIV3AOA/ANlp","pt":1659347623713,"mc":[{"id":"1.201590187","rc":[{"bdatl":[[9,2.38,4.15]],"id":9570503},{"bdatb":[[1,25,2.3],[2,24,2.29],[3,23,4.55],[4,21,5],[5,18.5,1.37],[6,15.5,4.19],[7,13.5,8.82],[8,12,1.96],[9,11,36.87]],"id":44621159}]}]}
{"op":"mcm","clk":"AIp3AOM/AOBp","pt":1659347623871,"mc":[{"id":"1.201590187","rc":[{"atb":[[7.6,4.53]],"id":43885158}]}]}
{"op":"mcm","clk":"AI53AOM/AONp","pt":1659347623921,"mc":[{"id":"1.201590187","rc":[{"bdatb":[[3,7.6,4.53]],"id":43885158}]}]}
{"op":"mcm","clk":"AJJ3AOQ/AOpp","pt":1659347623971,"mc":[{"id":"1.201590187","rc":[{"atb":[[2.02,26.8]],"atl":[[2.14,63.01]],"bdatb":[[1,2.02,26.8]],"bdatl":[[0,2.14,63.01]],"id":9570503},{"atb":[[6.6,0.37],[7,11.36]],"bdatb":[[0,7,11.36],[2,6.2,11.05],[3,6,6.68],[4,5.7,1.85],[5,5.6,4.42],[6,5.5,3.45],[7,5.3,3.14],[8,5.2,8.88],[9,5,3.53]],"id":12989514},{"atb":[[6.6,8.3],[6.8,0.36]],"atl":[[7.6,156.65]],"bdatb":[[1,6.6,8.66],[2,6.2,26.16],[3,6,29.74],[4,5.9,9],[5,5.8,10],[6,5.7,44.55],[7,5.6,63.72],[8,5.5,24.92],[9,5.4,40.83]],"bdatl":[[1,7.6,156.65]],"id":44836671},{"atb":[[7.4,12.55]],"atl":[[9.4,2.3]],"bdatb":[[4,7.4,12.55]],"bdatl":[[1,9.4,2.3]],"id":43885158}]}]}
{"op":"mcm","clk":"AJp3AOg/AOxp","pt":1659347624035,"mc":[{"id":"1.201590187","rc":[{"atl":[[7.8,4.52]],"id":12989514}]}]}
{"op":"mcm","clk":"AJp3AOo/AO5p","pt":1659347624085,"mc":[{"id":"1.201590187","rc":[{"bdatb":[[6,10,13.53],[7,9.8,9]],"id":45323444},{"bdatb":[[7,1.93,2.45],[8,1.91,117.33],[9,1.9,1.37]],"id":9570503},{"bdatl":[[0,7.8,4.52]],"id":12989514},{"bdatb":[[8,12,1.94],[9,11,37.1]],"id":44621159},{"bdatb":[[9,5.4,41.31]],"id":44836671},{"bdatb":[[9,6.2,10.76]],"id":43885158},{"bdatb":[[7,11.5,10.84],[8,10.5,1.81]],"id":46969227}]}]}
{"op":"mcm","clk":"AKV3API/AP5p","pt":1659347624321,"mc":[{"id":"1.201590187","rc":[{"atb":[[5.5,13]],"bdatb":[[8,5.5,14.92]],"id":44836671}]}]}
{"op":"mcm","clk":"AK53API/AIJq","pt":1659347624371,"mc":[{"id":"1.201590187","rc":[{"atb":[[13,0.19]],"bdatb":[[1,12.5,1.51],[2,12,7.48],[3,11.5,11.31],[4,11,1.23],[5,10,13.53],[6,9.8,9],[7,9.6,22.98],[8,9.4,62.72],[9,9.2,13.82]],"id":45323444},{"atb":[[25,0]],"bdatb":[[1,24,2.29],[2,23,4.55],[3,21,5],[4,18.5,1.37],[5,15.5,4.19],[6,13.5,8.82],[7,12,1.94],[8,11,37.1],[9,10.5,1.97]],"id":44621159},{"bdatl":[[8,2.36,1.05],[9,2.4,76.47]],"id":9570503}]}]}
{"op":"mcm","clk":"ALp3APc/AIxq","pt":1659347624546,"mc":[{"id":"1.201590187","rc":[{"atb":[[12.5,5.74]],"id":45323444}]}]}
{"op":"mcm","clk":"ALx3APg/AJJq","pt":1659347624596,"mc":[{"id":"1.201590187","rc":[{"bdatb":[[1,12.5,6.11]],"id":45323444}]}]}
{"op":"mcm","clk":"AMV3AP0/AJtq","pt":1659347624755,"mc":[{"id":"1.201590187","rc":[{"atb":[[24,4.71]],"id":44621159}]}]}
{"op":"mcm","clk":"AMl3AP8/AKFq","pt":1659347624805,"mc":[{"id":"1.201590187","rc":[{"bdatb":[[1,24,4.71]],"id":44621159}]}]}
{"op":"mcm","clk":"AM13AIJAAKFq","pt":1659347624859,"mc":[{"id":"1.201590187","rc":[{"atb":[[6.6,16.86]],"id":44836671}]}]}
{"op":"mcm","clk":"ANF3AINAAKhq","pt":1659347624909,"mc":[{"id":"1.201590187","rc":[{"bdatb":[[1,6.6,17.22]],"id":44836671}]}]}
{"op":"mcm","clk":"APp3AJZAAM5q","pt":1659347625448,"mc":[{"id":"1.201590187","rc":[{"atb":[[12.5,1.14]],"id":45323444},{"atb":[[24,2.29]],"id":44621159}]}]}
{"op":"mcm","clk":"APt3AJtAANVq","pt":1659347625506,"mc":[{"id":"1.201590187","rc":[{"bdatb":[[1,12.5,1.51]],"id":45323444},{"bdatb":[[1,24,2.29]],"id":44621159}]}]}
{"op":"mcm","clk":"AIl4AJ5AAONq","pt":1659347625660,"mc":[{"id":"1.201590187","rc":[{"atb":[[13,4.61]],"id":45323444}]}]}
{"op":"mcm","clk":"AIl4AJ9AAOZq","pt":1659347625710,"mc":[{"id":"1.201590187","rc":[{"bdatb":[[1,13,4.79],[2,12.5,1.14],[3,12,7.48],[4,11.5,11.31],[5,11,1.23],[6,10,13.53],[7,9.8,9],[8,9.6,22.98],[9,9.4,62.72]],"id":45323444},{"bdatl":[[8,2.36,1.99],[9,2.38,2.15]],"id":9570503}]}]}
{"op":"mcm","clk":"AJF4AKBAAOxq","pt":1659347625761,"mc":[{"id":"1.201590187","rc":[{"atb":[[25,2.3]],"id":44621159}]}]}
{"op":"mcm","clk":"AJF4AKJAAO9q","pt":1659347625818,"mc":[{"id":"1.201590187","rc":[{"bdatl":[[9,2.38,4.15]],"id":9570503},{"bdatb":[[1,25,2.3],[2,24,2.29],[3,23,4.55],[4,21,5],[5,18.5,1.37],[6,15.5,4.19],[7,13.5,8.82],[8,12,1.94],[9,11,37.1]],"id":44621159}]}]}
{"op":"mcm","clk":"AKN4AKtAAINr","pt":1659347626077,"mc":[{"id":"1.201590187","rc":[{"atb":[[2.02,30.83]],"atl":[[2.14,66.59]],"id":9570503},{"atb":[[7,13.81]],"id":12989514},{"atb":[[6.6,19.31]],"atl":[[7.6,158.97]],"id":44836671},{"atb":[[7.4,14.78]],"atl":[[9.4,4.65]],"id":43885158}]}]}
{"op":"mcm","clk":"AKR4AK1AAIhr","pt":1659347626127,"mc":[{"id":"1.201590187","rc":[{"bdatb":[[1,2.02,30.83],[9,1.9,1.63]],"bdatl":[[0,2.14,66.59]],"id":9570503},{"bdatb":[[0,7,13.81],[7,5.3,4.64],[8,5.2,7.35],[9,5,5.06]],"id":12989514},{"bdatb":[[1,6.6,19.67]],"bdatl":[[1,7.6,158.97]],"id":44836671},{"bdatb":[[4,7.4,14.78]],"bdatl":[[1,9.4,4.65]],"id":43885158},{"bdatb":[[9,10,9.57]],"id":46969227}]}]}
{"op":"mcm","clk":"AK94ALBAAJFr","pt":1659347626288,"mc":[{"id":"1.201590187","rc":[{"atb":[[1.02,0]],"id":45323444}]}]}
{"op":"mcm","clk":"ALZ4ALJAAJhr","pt":1659347626417,"mc":[{"id":"1.201590187","rc":[{"atb":[[13.5,1.78]],"id":45323444},{"atl":[[38,0.87]],"id":44621159}]}]}
{"op":"mcm","clk":"ALx4ALNAAJ1r","pt":1659347626467,"mc":[{"id":"1.201590187","rc":[{"atb":[[14,0.17],[13.5,2.78]],"bdatb":[[0,13.5,2.95],[1,13,4.61],[2,12.5,1.14],[3,12,7.48],[4,11.5,11.31],[5,11,1.23],[6,10,13.53],[7,9.8,9],[8,9.6,22.98],[9,9.4,62.72]],"id":45323444},{"atl":[[38,1.87]],"bdatl":[[0,38,1.87],[1,40,3.27],[2,80,2.96],[3,170,2],[4,900,1.06],[5,990,1.83],[6,1000,2]],"id":44621159},{"bdatb":[[7,1.93,2.45],[8,1.91,117.33],[9,1.9,1.63]],"bdatl":[[5,2.3,2.76],[6,2.32,3.04],[7,2.34,6.01],[9,2.38,2.76],[8,2.36,4.18]],"id":9570503},{"bdatb":[[5,5.6,4.42],[6,5.5,3.45]],"id":12989514},{"bdatb":[[9,5.4,41.31]],"bdatl":[[7,11.5,12.41],[8,12,2],[9,13,60.2]],"id":44836671},{"bdatb":[[7,11.5,10.84],[8,10.5,1.81]],"id":46969227}]}]}
{"op":"mcm","clk":"AL14ALRAAJ5r","pt":1659347626538,"mc":[{"id":"1.201590187","rc":[{"atb":[[13,0.19]],"id":45323444}]}]}
{"op":"mcm","clk":"AMF4ALRAAKRr","pt":1659347626589,"mc":[{"id":"1.201590187","rc":[{"bdatb":[[1,12.5,1.33],[2,12,7.48],[3,11.5,11.31],[4,11,1.23],[5,10,13.53],[6,9.8,9],[7,9.6,22.98],[8,9.4,62.72],[9,9.2,14.68]],"id":45323444}]}]}
{"op":"mcm","clk":"AMd4ALRAAKdr","pt":1659347626656,"mc":[{"id":"1.201590187","rc":[{"atb":[[9.4,45.48]],"id":45323444},{"atb":[[3.9,44.48]],"id":12989514},{"atb":[[11,17.24]],"id":44621159},{"atb":[[5.6,46.48]],"id":44836671},{"atb":[[8.8,31.6]],"id":46969227}]}]}
{"op":"mcm","clk":"AMd4ALRAAKpr","pt":1659347626706,"mc":[{"id":"1.201590187","rc":[{"bdatb":[[8,9.4,45.48]],"id":45323444},{"bdatb":[[9,11,19.86]],"id":44621159},{"bdatb":[[7,5.6,46.48]],"id":44836671}]}]}
{"op":"mcm","clk":"AM94ALZAAK1r","pt":1659347626762,"mc":[{"id":"1.201590187","rc":[{"atb":[[12.5,5.74]],"id":45323444}]}]}
{"op":"mcm","clk":"AM94ALdAALFr","pt":1659347626812,"mc":[{"id":"1.201590187","rc":[{"bdatb":[[1,12.5,5.93]],"id":45323444}]}]}
{"op":"mcm","clk":"AOd4AMFAAM1r","pt":1659347627177,"mc":[{"id":"1.201590187","rc":[{"atb":[[13.5,1.18]],"id":45323444},{"atb":[[8.8,48.84]],"id":46969227}]}]}
{"op":"mcm","clk":"AOp4AMFAANBr","pt":1659347627227,"mc":[{"id":"1.201590187","rc":[{"bdatb":[[0,13.5,1.35]],"id":45323444},{"bdatl":[[7,2.34,3.8],[8,2.36,1.05],[9,2.38,1.14]],"id":9570503},{"bdatl":[[9,13,59.8]],"id":44836671}]}]}
{"op":"mcm","clk":"APB4AMJAANNr","pt":1659347627277,"mc":[{"id":"1.201590187","rc":[{"atb":[[13,1.79]],"id":45323444}]}]}
{"op":"mcm","clk":"APV4AMJAANdr","pt":1659347627328,"mc":[{"id":"1.201590187","rc":[{"bdatb":[[1,13,1.79],[2,12.5,5.74],[3,12,7.48],[4,11.5,11.31],[5,11,1.23],[6,10,13.53],[7,9.8,9],[8,9.6,22.98],[9,9.4,45.48]],"id":45323444},{"bdatl":[[8,2.36,2.2],[9,2.38,4.15]],"id":9570503}]}]}
{"op":"mcm","clk":"APp4AMNAAN1r","pt":1659347627476,"mc":[{"id":"1.201590187","rc":[{"atb":[[13.5,2.33],[12.5,1.14]],"id":45323444},{"atl":[[7.6,1.15]],"id":12989514},{"atb":[[25,0]],"id":44621159}]}]}
{"op":"mcm","clk":"APx4AMZAAOBr","pt":1659347627526,"mc":[{"id":"1.201590187","rc":[{"bdatb":[[0,13.5,2.5],[2,12.5,1.14],[6,10,14.36],[8,9.6,22.07]],"id":45323444},{"bdatb":[[5,1.96,7.07],[6,1.94,11.24],[7,1.93,2.47],[8,1.92,4.53],[9,1.91,112.75]],"bdatl":[[7,2.34,6.01],[8,2.36,2.17],[9,2.38,1.99]],"id":9570503},{"bdatl":[[0,7.6,1.15],[1,7.8,4.52],[2,8,6],[3,8.2,2.52],[4,8.4,4],[5,9,6.82],[6,9.4,3.67],[7,9.6,11.09],[8,10,17.36],[9,10.5,12.47]],"id":12989514},{"bdatb":[[1,24,2.29],[2,23,4.55],[3,21,5],[4,18.5,1.37],[5,15.5,4.19],[6,13.5,8.8],[7,12.5,1.07],[8,11.5,1.13],[9,11,20.38]],"id":44621159},{"bdatb":[[7,5.6,48.04],[8,5.5,13.33],[9,5.4,41.32]],"bdatl":[[9,13,60.2]],"id":44836671},{"bdatb":[[7,6.6,14.32],[8,6.4,5.41],[9,6.2,12.17]],"id":43885158},{"bdatb":[[7,11.5,10.81],[8,10.5,1.77]],"id":46969227}]}]}
{"op":"mcm","clk":"AId5AMhAAOlr","pt":1659347627685,"mc":[{"id":"1.201590187","rc":[{"atb":[[14,4.25]],"id":45323444},{"atl":[[7.8,12.52],[7.6,1.49]],"id":12989514},{"atb":[[8.2,0]],"atl":[[9.2,2.69]],"id":43885158}]}]}
{"op":"mcm","clk":"AIt5AMtAAO1r","pt":1659347627735,"mc":[{"id":"1.201590187","rc":[{"bdatb":[[0,14,4.25],[1,13.5,2.33],[2,13,1.79],[3,12.5,1.14],[4,12,7.48],[5,11.5,11.31],[6,11,1.23],[7,10.5,1.08],[8,10,14.3],[9,9.8,9]],"id":45323444},{"bdatb":[[5,1.96,8],[6,1.94,7.31],[7,1.93,3.01],[8,1.92,12.38],[9,1.91,108.98]],"bdatl":[[5,2.3,1.72],[6,2.32,6.07],[7,2.34,4.22],[8,2.36,1.98],[9,2.38,12.51]],"id":9570503},{"bdatb":[[5,5.6,3.57],[6,5.5,4.32],[7,5.3,3.14],[8,5.2,8.88]],"bdatl":[[0,7.6,1.49],[1,7.8,12.52]],"id":12989514},{"bdatb":[[6,13.5,8.36],[7,12.5,2.35],[8,11.5,3.6],[9,11,19.18]],"id":44621159},{"bdatb":[[7,5.6,48.36],[8,5.5,13.14],[9,5.4,40.29]],"bdatl":[[7,11.5,12.2],[8,12,2.59],[9,13,59.27]],"id":44836671},{"bdatb":[[0,8,1.76],[1,7.8,1.26],[2,7.6,4.53],[3,7.4,14.78],[4,7.2,3.71],[5,7,5],[6,6.6,14.6],[7,6.4,5.13],[8,6.2,13.83],[9,6,55.4]],"bdatl":[[0,9.2,2.69]],"id":43885158},{"bdatb":[[7,11.5,10.38],[8,11,2.16],[9,10.5,1.34]],"id":46969227}]}]}
{"op":"mcm","clk":"AJd5AMxAAPRr","pt":1659347627850,"mc":[{"id":"1.201590187","rc":[{"atb":[[24,4.71]],"id":44621159}]}]}
{"op":"mcm","clk":"AJh5AM5AAPxr","pt":1659347627900,"mc":[{"id":"1.201590187","rc":[{"bdatb":[[1,24,4.71]],"id":44621159}]}]}
{"op":"mcm","clk":"ALN5ANhAAJRs","pt":1659347628272,"mc":[{"id":"1.201590187","rc":[{"atl":[[7.8,14.76]],"id":12989514}]}]}
{"op":"mcm","clk":"ALN5ANlAAJhs","pt":1659347628322,"mc":[{"id":"1.201590187","rc":[{"bdatl":[[1,7.8,14.76]],"id":12989514}]}]}
{"op":"mcm","clk":"ALt5ANxAAJxs","pt":1659347628380,"mc":[{"id":"1.201590187","rc":[{"atl":[[7.8,17.08]],"id":12989514}]}]}
{"op":"mcm","clk":"ALt5AN1AAJ5s","pt":1659347628430,"mc":[{"id":"1.201590187","rc":[{"bdatl":[[1,7.8,17.08]],"id":12989514}]}]}
{"op":"mcm","clk":"AMp5AOpAAKZs","pt":1659347628678,"mc":[{"id":"1.201590187","rc":[{"atb":[[14,0.17]],"id":45323444},{"atb":[[24,2.29]],"id":44621159}]}]}
{"op":"mcm","clk":"AMt5AOpAAKds","pt":1659347628729,"mc":[{"id":"1.201590187","rc":[{"bdatb":[[0,13.5,2.5],[1,13,1.79],[2,12.5,1.14],[3,12,7.48],[4,11.5,11.31],[5,11,1.23],[6,10.5,1.08],[7,10,14.3],[8,9.8,9],[9,9.6,22.47]],"id":45323444},{"bdatl":[[6,2.32,1.03],[7,2.34,5],[8,2.36,4.18],[9,2.38,1.96]],"id":9570503},{"bdatb":[[1,24,2.29]],"id":44621159},{"bdatl":[[8,12,1.61],[9,13,60.2]],"id":44836671}]}]}
{"op":"mcm","clk":"ANB5AO5AAKps","pt":1659347628779,"mc":[{"id":"1.201590187","rc":[{"atl":[[8.2,0]],"id":12989514}]}]}
{"op":"mcm","clk":"ANN5AO5AAKps","pt":1659347628829,"mc":[{"id":"1.201590187","rc":[{"bdatl":[[3,8.4,4],[4,9,6.82],[5,9.4,3.67],[6,9.6,11.09],[7,10,17.36],[8,10.5,12.47],[9,11,33.84]],"id":12989514}]}]}
{"op":"mcm","clk":"ANl5APBAAK5s","pt":1659347628880,"mc":[{"id":"1.201590187","rc":[{"atb":[[13.5,6.58],[11.5,5.54]],"id":45323444},{"atb":[[7.4,6.83],[8,8.25]],"id":43885158}]}]}
{"op":"mcm","clk":"ANl5APNAALBs","pt":1659347628930,"mc":[{"id":"1.201590187","rc":[{"bdatb":[[0,13.5,6.75],[4,11.5,5.54]],"id":45323444},{"bdatl":[[7,2.34,11.21],[8,2.36,15.85],[9,2.38,4.15]],"id":9570503},{"bdatl":[[9,12.5,1.13]],"id":44836671},{"bdatb":[[0,8,8.25],[3,7.4,6.83]],"id":43885158}]}]}
{"op":"mcm","clk":"AN95APRAALRs","pt":1659347628980,"mc":[{"id":"1.201590187","rc":[{"atl":[[7.6,8.49]],"bdatl":[[0,7.6,8.49]],"id":12989514},{"bdatb":[[6,10.5,2.36],[7,10,13.98],[9,9.6,21.41]],"id":45323444},{"bdatb":[[6,1.95,7.28],[7,1.94,2.99],[8,1.93,12.31],[9,1.92,1.61]],"id":9570503},{"bdatb":[[6,14,1.77],[7,13.5,6.99],[8,13,1.83],[9,11.5,3.56]],"id":44621159},{"bdatb":[[8,5.5,16.64],[9,5.4,41.7]],"id":44836671},{"bdatb":[[7,6.4,8.84],[8,6.2,11.65],[9,6,53.7]],"id":43885158},{"bdatb":[[7,12,2.51],[8,11.5,9.88],[9,10.5,1.33]],"id":46969227}]}]}
{"op":"mcm","clk":"AOR5APRAALZs","pt":1659347629052,"mc":[{"id":"1.201590187","rc":[{"atb":[[25,2.3]],"id":44621159}]}]}
{"op":"mcm","clk":"AOV5APRAALhs","pt":1659347629102,"mc":[{"id":"1.201590187","rc":[{"bdatl":[[7,2.34,27.2],[8,2.38,4.15],[9,2.4,77.82]],"id":9570503},{"bdatb":[[1,25,2.3],[2,24,2.29],[3,23,4.55],[4,21,5],[5,18.5,1.37],[6,15.5,4.19],[7,14,1.77],[8,13.5,6.99],[9,13,1.83]],"id":44621159}]}]}
{"op":"mcm","clk":"AP15AP5AAOFs","pt":1659347629571,"mc":[{"id":"1.201590187","rc":[{"atb":[[6.8,0.36]],"id":12989514}]}]}
{"op":"mcm","clk":"AP95AIBBAOZs","pt":1659347629622,"mc":[{"id":"1.201590187","rc":[{"bdatb":[[1,6.4,1.11],[2,6.2,10.3]],"id":12989514}]}]}
{"op":"mcm","clk":"AIN6AIJBAOls","pt":1659347629679,"mc":[{"id":"1.201590187","rc":[{"atb":[[1.01,48.08]],"id":45323444},{"atb":[[6.6,11.37]],"id":12989514}]}]}
{"op":"mcm","clk":"AId6AIRBAOxs","pt":1659347629729,"mc":[{"id":"1.201590187","rc":[{"bdatb":[[1,6.6,11.73],[2,6.2,10.68]],"id":12989514}]}]}
{"op":"mcm","clk":"AJR6AIZBAPds","pt":1659347629886,"mc":[{"id":"1.201590187","rc":[{"atb":[[13.5,2.33],[1.01,46.81]],"bdatb":[[0,13.5,2.5]],"id":45323444},{"atb":[[25,0]],"bdatb":[[1,24,2.29],[2,23,4.55],[3,21,5],[4,18.5,1.37],[5,15.5,4.19],[6,14,1.77],[7,13.5,6.99],[8,13,1.83],[9,11.5,3.56]],"id":44621159},{"atb":[[8,1.76]],"bdatb":[[0,8,1.76]],"id":43885158},{"bdatl":[[7,2.34,5],[8,2.36,4.18],[9,2.38,1.96]],"id":9570503},{"bdatl":[[9,13,60.2]],"id":44836671}]}]}
{"op":"mcm","clk":"AKR6AIlBAIJt","pt":1659347630057,"mc":[{"id":"1.201590187","rc":[{"atb":[[14,4.25],[1.01,45.55]],"id":45323444},{"atl":[[2.3,0]],"id":9570503},{"atb":[[7.8,7.93],[8,1.46]],"id":43885158}]}]}
{"op":"mcm","clk":"AKZ6AIxBAIJt","pt":1659347630107,"mc":[{"id":"1.201590187","rc":[{"bdatb":[[0,14,4.25],[1,13.5,2.33],[2,13,1.79],[3,12.5,1.14],[4,12,7.48],[5,11.5,5.54],[6,11,1.23],[7,10.5,2.36],[8,10,13.98],[9,9.8,9]],"id":45323444},{"bdatl":[[5,2.32,5.03],[6,2.34,7.24],[7,2.36,13.08],[8,2.38,5.9],[9,2.4,75.65]],"id":9570503},{"bdatl":[[8,12,2.39],[9,13,59.46]],"id":44836671},{"bdatb":[[0,8,1.46],[1,7.8,7.93]],"id":43885158}]}]}
{"op":"mcm","clk":"AK96AI5BAIht","pt":1659347630172,"mc":[{"id":"1.201590187","rc":[{"atb":[[14,5.52],[13,0.19]],"id":45323444},{"atl":[[2.1,1.72]],"id":9570503}]}]}
{"op":"mcm","clk":"AK96AI9BAIht","pt":1659347630222,"mc":[{"id":"1.201590187","rc":[{"bdatb":[[0,14,5.52],[2,12.5,1.33],[3,12,7.48],[4,11.5,5.85],[5,11,1.23],[6,10.5,2.01],[7,10,13.98],[8,9.8,9],[9,9.6,21.41]],"id":45323444},{"bdatl":[[0,2.1,1.72],[1,2.14,66.59],[2,2.16,9.18],[3,2.18,6.18],[4,2.2,4],[5,2.22,4],[6,2.32,5.03],[7,2.34,7.24],[8,2.36,16.79],[9,2.38,2.23]],"id":9570503},{"bdatb":[[3,6,7.28],[4,5.7,1.22],[9,5,5.78]],"id":12989514},{"bdatb":[[5,15.5,4.41],[6,14,1.51]],"id":44621159},{"bdatb":[[4,5.9,9.61],[7,5.6,47.71]],"id":44836671},{"bdatb":[[5,7,5.52],[6,6.6,14.05]],"id":43885158},{"bdatb":[[7,12,2.48]],"id":46969227}]}]}
{"op":"mcm","clk":"ALd6AJFBAI5t","pt":1659347630273,"mc":[{"id":"1.201590187","rc":[{"atb":[[12.5,2.74]],"id":45323444},{"atb":[[24,4.71]],"id":44621159}]}]}
{"op":"mcm","clk":"ALd6AJJBAJBt","pt":1659347630323,"mc":[{"id":"1.201590187","rc":[{"bdatb":[[2,12.5,2.93]],"id":45323444},{"bdatb":[[1,24,4.71]],"id":44621159}]}]}
{"op":"mcm","clk":"ANp6AKlBAMFt","pt":1659347630890,"mc":[{"id":"1.201590187","rc":[{"atl":[[670,0.9]],"id":45323444},{"atl":[[670,0.9]],"id":9570503},{"atb":[[6.6,13.78]],"atl":[[670,0.9]],"id":12989514},{"atl":[[670,0.9]],"id":44621159},{"atl":[[670,0.9]],"id":44836671},{"atl":[[670,0.9]],"id":43885158},{"atl":[[670,0.9]],"id":46969227}]}]}
{"op":"mcm","clk":"AN56AKlBAMJt","pt":1659347630940,"mc":[{"id":"1.201590187","rc":[{"bdatb":[[1,6.6,14.14]],"id":12989514},{"bdatl":[[4,900,1.14]],"id":44621159},{"bdatl":[[7,900,1.14]],"id":46969227}]}]}
{"op":"mcm","clk":"AN96AKpBAMZt","pt":1659347630990,"mc":[{"id":"1.201590187","rc":[{"atb":[[14,1.44]],"id":45323444},{"atb":[[4.9,58.02]],"id":12989514},{"atb":[[24,2.29]],"id":44621159}]}]}
{"op":"mcm","clk":"AOF6AK1BAMht","pt":1659347631040,"mc":[{"id":"1.201590187","rc":[{"bdatb":[[0,14,1.44]],"id":45323444},{"bdatl":[[7,2.34,3.61],[8,2.36,3.6],[9,2.38,9.65]],"id":9570503},{"bdatb":[[1,24,2.29]],"id":44621159}]}]}
{"op":"mcm","clk":"AOh6AK1BAMxt","pt":1659347631091,"mc":[{"id":"1.201590187","rc":[{"atb":[[13,4.61]],"id":45323444}]}]}
{"op":"mcm","clk":"AOh6AK1BANBt","pt":1659347631141,"mc":[{"id":"1.201590187","rc":[{"bdatb":[[2,13,4.61],[3,12.5,2.74],[4,12,7.48],[5,11.5,5.85],[6,11,1.23],[7,10.5,2.01],[8,10,13.98],[9,9.8,9]],"id":45323444}]}]}
{"op":"mcm","clk":"APV6AK5BANxt","pt":1659347631265,"mc":[{"id":"1.201590187","rc":[{"atb":[[6.8,1.71]],"atl":[[7.4,8]],"id":12989514},{"atb":[[25,2.3]],"id":44621159}]}]}
{"op":"mcm","clk":"APV6ALJBANxt","pt":1659347631315,"mc":[{"id":"1.201590187","rc":[{"bdatb":[[4,12,7.78],[5,11.5,5.54],[6,11,3.15],[7,10.5,2.82],[8,10,11.41],[9,9.8,9.26]],"id":45323444},{"bdatb":[[4,1.97,7.88],[5,1.96,12.82],[6,1.95,12.19],[7,1.93,2.53],[8,1.91,112.19],[9,1.9,14.43]],"bdatl":[[8,2.36,13.32],[9,2.38,7]],"id":9570503},{"bdatb":[[1,6.8,1.71],[2,6.6,13.78],[3,6.2,10.68],[4,6,7.28],[5,5.7,1.22],[6,5.6,3.57],[7,5.5,4.32],[8,5.3,3.14],[9,5.2,8.88]],"bdatl":[[0,7.4,8],[1,7.6,8.49],[2,7.8,17.08],[3,8,6],[4,8.4,4],[5,9,6.82],[6,9.4,3.67],[7,9.6,11.09],[8,10,17.36],[9,10.5,12.47]],"id":12989514},{"bdatb":[[1,25,2.3],[2,24,2.29],[3,23,4.55],[4,21,5],[5,18.5,1.37],[6,15.5,4.4],[7,14.5,1.44],[8,14,2.11],[9,13.5,6.56]],"id":44621159},{"bdatb":[[3,6,30.34],[4,5.9,9],[6,5.7,45.76],[7,5.6,50.05],[8,5.5,17.88],[9,5.4,37.06]],"id":44836671},{"bdatb":[[6,6.6,20.68],[7,6.4,2.48],[8,6.2,12.19],[9,6,56.17]],"id":43885158},{"bdatb":[[7,12.5,2.38],[8,12,1.98],[9,11.5,8.08]],"id":46969227}]}]}
{"op":"mcm","clk":"AP96ALNBAOBt","pt":1659347631366,"mc":[{"id":"1.201590187","rc":[{"atl":[[7.4,8.34]],"id":12989514}]}]}
{"op":"mcm","clk":"AP96ALVBAONt","pt":1659347631416,"mc":[{"id":"1.201590187","rc":[{"bdatb":[[7,1.93,3.83],[8,1.91,110.87]],"id":9570503},{"bdatl":[[0,7.4,8.34]],"id":12989514},{"bdatb":[[9,5.4,37.53]],"id":44836671}]}]}
{"op":"mcm","clk":"AJh7AL5BAIlu","pt":1659347631880,"mc":[{"id":"1.201590187","rc":[{"atb":[[3.9,61.72],[6.6,15.97],[6,2]],"id":12989514}]}]}
{"op":"mcm","clk":"AJl7AMFBAI5u","pt":1659347631930,"mc":[{"id":"1.201590187","rc":[{"bdatb":[[2,6.6,15.97],[4,6,2.6]],"id":12989514}]}]}
{"op":"mcm","clk":"AKB7AMJBAJBu","pt":1659347631988,"mc":[{"id":"1.201590187","rc":[{"atb":[[11,31.6]],"id":44621159},{"atb":[[5.6,63.72]],"id":44836671}]}]}
{"op":"mcm","clk":"AKV7AMNBAJdu","pt":1659347632038,"mc":[{"id":"1.201590187","rc":[{"bdatb":[[7,5.6,67.29]],"id":44836671}]}]}
{"op":"mcm","clk":"AKt7AMRBAJdu","pt":1659347632088,"mc":[{"id":"1.201590187","rc":[{"atb":[[13,0.19]],"id":45323444},{"atb":[[25,0]],"id":44621159}]}]}
{"op":"mcm","clk":"AKt7AMRBAJhu","pt":1659347632138,"mc":[{"id":"1.201590187","rc":[{"bdatb":[[2,12.5,2.93],[3,12,7.78],[4,11.5,5.54],[5,11,3.15],[6,10.5,2.82],[7,10,11.41],[8,9.8,9.26],[9,9.6,23.58]],"id":45323444},{"bdatl":[[8,2.36,3.6],[9,2.38,9.65]],"id":9570503},{"bdatb":[[1,24,2.29],[2,23,4.55],[3,21,5],[4,18.5,1.37],[5,15.5,4.4],[6,14.5,1.44],[7,14,2.11],[8,13.5,6.56],[9,12,3.42]],"id":44621159}]}]}
{"op":"mcm","clk":"ALF7AMVBAJpu","pt":1659347632193,"mc":[{"id":"1.201590187","rc":[{"atb":[[14,5.52]],"id":45323444}]}]}
{"op":"mcm","clk":"ALR7AMdBAJ1u","pt":1659347632243,"mc":[{"id":"1.201590187","rc":[{"bdatb":[[0,14,5.52]],"id":45323444},{"bdatl":[[7,2.34,7.24],[8,2.36,16.79],[9,2.38,2.23]],"id":9570503}]}]}
{"op":"mcm","clk":"ALp7AMhBAKJu","pt":1659347632303,"mc":[{"id":"1.201590187","rc":[{"atb":[[24,4.71]],"id":44621159}]}]}
{"op":"mcm","clk":"AMF7AMlBAKhu","pt":1659347632359,"mc":[{"id":"1.201590187","rc":[{"bdatb":[[1,24,4.71]],"id":44621159}]}]}
{"op":"mcm","clk":"ANp7ANBBAMNu","pt":1659347632779,"mc":[{"id":"1.201590187","rc":[{"atb":[[7,11.36]],"id":12989514}]}]}
{"op":"mcm","clk":"ANp7ANFBAMVu","pt":1659347632829,"mc":[{"id":"1.201590187","rc":[{"bdatb":[[0,7,11.36]],"id":12989514}]}]}
{"op":"mcm","clk":"AOB7ANNBAMhu","pt":1659347632879,"mc":[{"id":"1.201590187","rc":[{"atb":[[7,4.06]],"id":12989514}]}]}
{"op":"mcm","clk":"AOB7ANNBAMpu","pt":1659347632929,"mc":[{"id":"1.201590187","rc":[{"bdatl":[[7,2.34,7.15],[8,2.38,4.89],[9,2.4,83.18]],"id":9570503},{"bdatb":[[0,7,4.06]],"id":12989514}]}]}
{"op":"mcm","clk":"AOd7ANRBANBu","pt":1659347632988,"mc":[{"id":"1.201590187","rc":[{"atb":[[14,1.44]],"id":45323444},{"atb":[[7,3.71]],"id":12989514},{"atb":[[24,2.29]],"id":44621159}]}]}
{"op":"mcm","clk":"AOd7ANZBANJu","pt":1659347633038,"mc":[{"id":"1.201590187","rc":[{"bdatb":[[0,14,1.44]],"id":45323444},{"bdatl":[[7,2.34,3.61],[8,2.36,2.47],[9,2.38,1.11]],"id":9570503},{"bdatb":[[0,7,3.71]],"id":12989514},{"bdatb":[[1,24,2.29]],"id":44621159}]}]}
{"op":"mcm","clk":"APZ7ANlBANlu","pt":1659347633183,"mc":[{"id":"1.201590187","rc":[{"atb":[[13,4.61]],"id":45323444}]}]}
{"op":"mcm","clk":"APl7ANtBAN1u","pt":1659347633257,"mc":[{"id":"1.201590187","rc":[{"bdatb":[[2,13,4.61],[3,12.5,2.74],[4,12,7.78],[5,11.5,5.54],[6,11,3.15],[7,10.5,2.82],[8,10,11.41],[9,9.8,9.26]],"id":45323444}]}]}
{"op":"mcm","clk":"AIt8AN9BAOBu","pt":1659347633389,"mc":[{"id":"1.201590187","rc":[{"atb":[[12,4.6]],"id":45323444},{"atb":[[25,2.3]],"id":44621159},{"atl":[[10.5,0]],"id":43885158}]}]}
{"op":"mcm","clk":"AI18AONBAONu","pt":1659347633439,"mc":[{"id":"1.201590187","rc":[{"bdatb":[[4,12,4.91]],"id":45323444},{"bdatl":[[9,2.38,4.89]],"id":9570503},{"bdatb":[[1,25,2.3],[2,24,2.29],[3,23,4.55],[4,21,5],[5,18.5,1.37],[6,15.5,4.4],[7,14.5,1.44],[8,14,2.11],[9,13.5,6.56]],"id":44621159},{"bdatl":[[3,11.5,2.65],[4,12,1.4],[5,12.5,18],[6,14,13.2],[7,14.5,1],[8,15,12],[9,15.5,2.05]],"id":43885158}]}]}
{"op":"mcm","clk":"AJJ8AORBAOhu","pt":1659347633493,"mc":[{"id":"1.201590187","rc":[{"atb":[[12.5,5.62]],"id":45323444}]}]}
{"op":"mcm","clk":"AJd8AOVBAOpu","pt":1659347633543,"mc":[{"id":"1.201590187","rc":[{"bdatb":[[3,12.5,5.62]],"id":45323444}]}]}
{"op":"mcm","clk":"ALl8APVBAIxv","pt":1659347634075,"mc":[{"id":"1.201590187","rc":[{"atb":[[13,0.19]],"id":45323444},{"atb":[[25,0]],"id":44621159},{"atb":[[8,2.61]],"atl":[[9.2,3.84]],"id":43885158}]}]}
{"op":"mcm","clk":"AMB8APdBAJNv","pt":1659347634182,"mc":[{"id":"1.201590187","rc":[{"atb":[[7,2.56]],"atl":[[7.6,7.34]],"id":12989514}]}]}
{"op":"mcm","clk":"AMR8APhBAJRv","pt":1659347634273,"mc":[{"id":"1.201590187","rc":[{"atb":[[14,5.52]],"id":45323444}]}]}
{"op":"mcm","clk":"AMx8APtBAKJv","pt":1659347634382,"mc":[{"id":"1.201590187","rc":[{"bdatb":[[2,12.5,5.81],[3,12,4.91],[4,11.5,5.54],[5,11,4.11],[6,10.5,1.81],[7,10,11.67],[8,9.8,9.81],[9,9.6,22.75]],"id":45323444},{"bdatb":[[5,1.96,15.26],[6,1.95,9.74],[8,1.91,116.41],[9,1.9,8.86]],"bdatl":[[6,2.32,8.68],[7,2.36,2.48],[8,2.38,1.11],[9,2.4,75.17]],"id":9570503},{"bdatb":[[6,5.6,4.42],[7,5.5,3.45],[8,5.3,4.64],[9,5.2,7.35]],"id":12989514},{"bdatb":[[1,24,2.29],[2,23,4.55],[3,21,5],[4,18.5,1.37],[5,15.5,4.4],[6,14.5,1.84],[7,14,1.7],[8,13.5,6.56],[9,12,3.42]],"id":44621159},{"bdatb":[[7,5.6,68.14],[8,5.5,17.02]],"bdatl":[[8,12,2.76]],"id":44836671},{"bdatb":[[0,8,2.61]],"bdatl":[[0,9.2,3.84]],"id":43885158},{"bdatb":[[7,12.5,2.76],[8,12,1.58]],"id":46969227}]}]}
{"op":"mcm","clk":"AMx8APtBAKZv","pt":1659347634432,"mc":[{"id":"1.201590187","rc":[{"bdatb":[[0,14,5.52]],"id":45323444},{"bdatl":[[6,2.32,7.72],[7,2.34,1.26],[8,2.36,3.28],[9,2.4,87.94]],"id":9570503},{"bdatb":[[0,7,2.56]],"bdatl":[[1,7.6,7.34]],"id":12989514},{"bdatl":[[9,13,59.23]],"id":44836671}]}]}
{"op":"mcm","clk":"ANJ8APxBAKdv","pt":1659347634485,"mc":[{"id":"1.201590187","rc":[{"atb":[[24,4.71]],"id":44621159}]}]}
{"op":"mcm","clk":"ANN8AP1BAKlv","pt":1659347634535,"mc":[{"id":"1.201590187","rc":[{"bdatb":[[1,24,4.71]],"id":44621159}]}]}
{"op":"mcm","clk":"ANd8AP9BAKxv","pt":1659347634587,"mc":[{"id":"1.201590187","rc":[{"atl":[[29,0],[28,11.34]],"id":46969227}]}]}
{"op":"mcm","clk":"ANh8AIFCALRv","pt":1659347634637,"mc":[{"id":"1.201590187","rc":[{"bdatl":[[1,28,11.34],[2,34,5.16],[3,40,5.01],[4,80,1.66],[5,310,1],[6,900,1.14],[7,990,1.91],[8,0,0]],"id":46969227}]}]}
{"op":"mcm","clk":"AOt8AIJCAMFv","pt":1659347634889,"mc":[{"id":"1.201590187","rc":[{"atb":[[6.8,5.36]],"id":44836671}]}]}
{"op":"mcm","clk":"AO18AINCAMNv","pt":1659347634939,"mc":[{"id":"1.201590187","rc":[{"bdatb":[[1,6.8,5.36],[2,6.6,19.31],[3,6.2,26.16],[4,6,30.34],[5,5.9,9],[6,5.8,10],[7,5.7,45.76],[8,5.6,68.14],[9,5.5,17.02]],"id":44836671}]}]}
{"op":"mcm","clk":"APB8AIVCAMZv","pt":1659347634993,"mc":[{"id":"1.201590187","rc":[{"atb":[[6.6,18.31]],"id":12989514}]}]}
{"op":"mcm","clk":"APJ8AIdCAMdv","pt":1659347635043,"mc":[{"id":"1.201590187","rc":[{"bdatb":[[2,6.6,18.31]],"id":12989514}]}]}
{"op":"mcm","clk":"APx8AIhCAMtv","pt":1659347635093,"mc":[{"id":"1.201590187","rc":[{"atb":[[6.6,20.59]],"bdatb":[[2,6.6,20.59]],"id":12989514}]}]}
{"op":"mcm","clk":"AIR9AIlCAMxv","pt":1659347635160,"mc":[{"id":"1.201590187","rc":[{"atb":[[14,1.44]],"id":45323444},{"atb":[[24,2.29]],"id":44621159},{"atb":[[7.8,1.26]],"id":43885158}]}]}
{"op":"mcm","clk":"AIR9AIpCANFv","pt":1659347635211,"mc":[{"id":"1.201590187","rc":[{"bdatb":[[0,14,1.44]],"id":45323444},{"bdatl":[[7,2.36,1.25],[8,2.38,3.26],[9,2.4,71.82]],"id":9570503},{"bdatb":[[1,24,2.29]],"id":44621159},{"bdatb":[[1,7.8,1.26]],"id":43885158}]}]}
{"op":"mcm","clk":"AIx9AIxCANRv","pt":1659347635273,"mc":[{"id":"1.201590187","rc":[{"atb":[[13,4.61]],"id":45323444},{"atb":[[7,0]],"id":12989514},{"atb":[[6.6,15.64]],"id":44836671}]}]}
{"op":"mcm","clk":"AIx9AI1CANVv","pt":1659347635323,"mc":[{"id":"1.201590187","rc":[{"bdatb":[[2,13,4.61],[3,12.5,5.62],[4,12,4.91],[5,11.5,5.54],[6,11,4.11],[7,10.5,1.81],[8,10,11.67],[9,9.8,9.81]],"id":45323444},{"bdatl":[[6,2.34,4.97],[7,2.38,3.88],[8,2.4,74.66],[9,2.44,161.51]],"id":9570503},{"bdatb":[[0,6.8,1.71],[1,6.6,20.59],[2,6.2,10.68],[3,6,2.6],[4,5.7,1.22],[5,5.6,4.42],[6,5.5,3.45],[7,5.3,4.64],[8,5.2,7.35],[9,5,5.78]],"id":12989514},{"bdatb":[[2,6.6,15.64]],"bdatl":[[8,12,1.41],[9,13,60.03]],"id":44836671},{"bdatl":[[9,15.5,1]],"id":43885158}]}]}
{"op":"mcm","clk":"AJN9AI1CANdv","pt":1659347635373,"mc":[{"id":"1.201590187","rc":[{"atl":[[9.4,0]],"id":12989514},{"atb":[[25,2.3]],"id":44621159},{"atb":[[8,4.61]],"id":43885158}]}]}
{"op":"mcm","clk":"AJN9AI1CANhv","pt":1659347635423,"mc":[{"id":"1.201590187","rc":[{"bdatl":[[7,2.38,7.14],[8,2.4,74.87],[9,2.42,4.08]],"id":9570503},{"bdatl":[[6,9.6,11.09],[7,10,17.36],[8,10.5,12.47],[9,11,33.84]],"id":12989514},{"bdatb":[[1,25,2.3],[2,24,2.29],[3,23,4.55],[4,21,5],[5,18.5,1.37],[6,15.5,4.4],[7,14.5,1.84],[8,14,1.7],[9,13.5,6.56]],"id":44621159},{"bdatb":[[0,8,4.61]],"id":43885158}]}]}
{"op":"mcm","clk":"AJp9AI1CANtv","pt":1659347635481,"mc":[{"id":"1.201590187","rc":[{"atl":[[7.6,11.01]],"id":12989514}]}]}
{"op":"mcm","clk":"AJp9AI1CAN5v","pt":1659347635531,"mc":[{"id":"1.201590187","rc":[{"bdatl":[[1,7.6,11.01]],"id":12989514}]}]}
{"op":"mcm","clk":"AJ59AI5CAONv","pt":1659347635582,"mc":[{"id":"1.201590187","rc":[{"atb":[[6.6,15.99]],"id":12989514}]}]}
{"op":"mcm","clk":"AJ59AI9CAOVv","pt":1659347635632,"mc":[{"id":"1.201590187","rc":[{"bdatb":[[1,6.6,15.99]],"id":12989514}]}]}
{"op":"mcm","clk":"AL99AJxCAP5v","pt":1659347636087,"mc":[{"id":"1.201590187","rc":[{"atb":[[13,0.19]],"id":45323444},{"atb":[[6.2,19]],"id":12989514},{"atb":[[25,0]],"id":44621159}]}]}
{"op":"mcm","clk":"AMF9AKBCAIJw","pt":1659347636138,"mc":[{"id":"1.201590187","rc":[{"bdatb":[[2,12.5,5.81],[3,12,4.91],[4,11.5,5.54],[5,11,4.11],[6,10.5,1.81],[7,10,11.67],[8,9.8,9.81],[9,9.6,22.75]],"id":45323444},{"bdatb":[[2,6.2,19.38]],"id":12989514},{"bdatb":[[1,24,2.29],[2,23,4.55],[3,21,5],[4,18.5,1.37],[5,15.5,4.4],[6,14.5,1.84],[7,14,1.7],[8,13.5,6.56],[9,12,3.42]],"id":44621159}]}]}
{"op":"mcm","clk":"AMt9AKZCAIhw","pt":1659347636292,"mc":[{"id":"1.201590187","rc":[{"atb":[[14,5.52]],"id":45323444}]}]}
{"op":"mcm","clk":"AM59AKdCAItw","pt":1659347636342,"mc":[{"id":"1.201590187","rc":[{"bdatb":[[0,14,5.52]],"id":45323444},{"bdatl":[[8,2.4,78.98],[9,2.42,8.88]],"id":9570503}]}]}
{"op":"mcm","clk":"ANp9AKtCAJJw","pt":1659347636497,"mc":[{"id":"1.201590187","rc":[{"atb":[[24,4.71]],"id":44621159}]}]}
{"op":"mcm","clk":"ANx9AK1CAJRw","pt":1659347636547,"mc":[{"id":"1.201590187","rc":[{"bdatb":[[1,24,4.71]],"id":44621159}]}]}
{"op":"mcm","clk":"APZ9ALZCAKZw","pt":1659347636877,"mc":[{"id":"1.201590187","rc":[{"atl":[[10.5,3.28]],"id":43885158}]}]}
{"op":"mcm","clk":"APZ9ALZCAKZw","pt":1659347636928,"mc":[{"id":"1.201590187","rc":[{"bdatl":[[3,10.5,3.28],[4,11.5,2.65],[5,12,1.4],[6,12.5,18],[7,14,13.2],[8,14.5,1],[9,15,12]],"id":43885158}]}]}
{"op":"mcm","clk":"AId+ALpCALVw","pt":1659347637186,"mc":[{"id":"1.201590187","rc":[{"atl":[[2.14,81.59]],"id":9570503}]}]}
{"op":"mcm","clk":"AId+ALpCALdw","pt":1659347637236,"mc":[{"id":"1.201590187","rc":[{"bdatl":[[1,2.14,81.59]],"id":9570503},{"bdatb":[[9,5,12.2]],"id":12989514}]}]}
{"op":"mcm","clk":"AIx+ALtCALtw","pt":1659347637286,"mc":[{"id":"1.201590187","rc":[{"atb":[[14,1.44]],"id":45323444},{"atb":[[6.8,0.36],[6.4,4.88]],"id":12989514},{"atb":[[24,2.29]],"id":44621159}]}]}
{"op":"mcm","clk":"AI1+ALtCAL5w","pt":1659347637344,"mc":[{"id":"1.201590187","rc":[{"bdatb":[[0,14,1.44]],"id":45323444},{"bdatl":[[6,2.34,1.05],[7,2.38,11],[8,2.4,74.87],[9,2.42,4.08]],"id":9570503},{"bdatb":[[0,6.6,16.35],[1,6.4,4.88],[2,6.2,19]],"id":12989514},{"bdatb":[[1,24,2.29]],"id":44621159},{"bdatl":[[9,13,59.3]],"id":44836671}]}]}
{"op":"mcm","clk":"AJh+ALxCAMhw","pt":1659347637488,"mc":[{"id":"1.201590187","rc":[{"atb":[[13,4.61]],"id":45323444}]}]}
{"op":"mcm","clk":"AJl+AL5CAMtw","pt":1659347637538,"mc":[{"id":"1.201590187","rc":[{"bdatb":[[2,13,4.61],[3,12.5,5.62],[4,12,4.91],[5,11.5,5.54],[6,11,4.11],[7,10.5,1.81],[8,10,11.67],[9,9.8,9.81]],"id":45323444}]}]}
{"op":"mcm","clk":"AKR+AL9CANNw","pt":1659347637688,"mc":[{"id":"1.201590187","rc":[{"atb":[[25,2.3]],"id":44621159}]}]}
{"op":"mcm","clk":"AKV+AMBCANNw","pt":1659347637738,"mc":[{"id":"1.201590187","rc":[{"bdatb":[[1,25,2.3],[2,24,2.29],[3,23,4.55],[4,21,5],[5,18.5,1.37],[6,15.5,4.4],[7,14.5,1.84],[8,14,1.7],[9,13.5,6.56]],"id":44621159}]}]}
{"op":"mcm","clk":"AL1+AMdCAOlw","pt":1659347638085,"mc":[{"id":"1.201590187","rc":[{"atb":[[7,13.18]],"trd":[[7,25.13]],"tv":207.46,"id":44836671}],"tv":1392.97}]}
{"op":"mcm","clk":"AL1+AMhCAOlw","pt":1659347638135,"mc":[{"id":"1.201590187","rc":[{"bdatb":[[0,7,13.18]],"id":44836671}]}]}
{"op":"mcm","clk":"ANR+AMxCAPpw","pt":1659347638384,"mc":[{"id":"1.201590187","rc":[{"atb":[[13,0.19]],"id":45323444},{"atl":[[7.2,6],[8,0]],"id":12989514},{"atb":[[25,0]],"id":44621159}]}]}
{"op":"mcm","clk":"ANR+AMxCAP5w","pt":1659347638434,"mc":[{"id":"1.201590187","rc":[{"bdatb":[[2,12.5,6.1],[3,12,4.6],[4,11.5,8.29],[5,11,1.94],[6,10.5,1.06],[7,10,14.15],[8,9.8,9.93],[9,9.6,21]],"id":45323444},{"bdatb":[[3,1.98,52.36],[4,1.97,4.95],[5,1.96,6.64],[6,1.95,5.7],[7,1.93,8.65],[8,1.92,4.15],[9,1.91,120.93]],"id":9570503},{"bdatl":[[0,7.2,6],[1,7.4,8.34],[2,7.6,11.01],[3,7.8,17.08]],"id":12989514},{"bdatb":[[1,24,2.29],[2,23,4.55],[3,21,5],[4,18.5,1.57],[5,15.5,5.91],[6,14,1.65],[7,13.5,6.56],[8,12.5,3.31],[9,11.5,1.83]],"id":44621159},{"bdatb":[[6,5.8,14.64],[7,5.7,45.38],[8,5.6,65.12],[9,5.5,15.58]],"id":44836671},{"bdatb":[[4,7.2,4.21],[5,7,5],[6,6.8,3.96],[7,6.6,16.6],[8,6.4,2.48],[9,6.2,17.66]],"id":43885158},{"bdatb":[[7,13.5,2.22],[8,12.5,1],[9,11.5,9.01]],"id":46969227}]}]}
{"op":"mcm","clk":"ANl+AM5CAP9w","pt":1659347638489,"mc":[{"id":"1.201590187","rc":[{"atb":[[14,5.52]],"id":45323444}]}]}
{"op":"mcm","clk":"ANp+AM5CAIZx","pt":1659347638540,"mc":[{"id":"1.201590187","rc":[{"bdatb":[[0,14,5.52]],"id":45323444},{"bdatl":[[8,2.4,78.98],[9,2.42,8.88]],"id":9570503}]}]}
{"op":"mcm","clk":"AOB+ANRCAIpx","pt":1659347638603,"mc":[{"id":"1.201590187","rc":[{"atl":[[7.2,6.35]],"id":12989514},{"atb":[[24,4.71]],"id":44621159}]}]}
{"op":"mcm","clk":"AON+ANRCAI9x","pt":1659347638653,"mc":[{"id":"1.201590187","rc":[{"bdatb":[[5,11,2.17],[6,10,14.97],[7,9.8,10.18],[8,9.6,21],[9,9.4,53.01]],"id":45323444},{"bdatb":[[5,1.96,7.92],[6,1.95,4.41],[9,1.91,122.25]],"id":9570503},{"bdatl":[[0,7.2,6.35]],"id":12989514},{"bdatb":[[1,24,4.71],[6,14.5,1.04],[7,13.5,7.17],[9,11.5,1.82]],"id":44621159},{"bdatb":[[8,5.6,65.57],[9,5.5,15.13]],"id":44836671},{"bdatb":[[9,6.2,18.07]],"id":43885158},{"bdatb":[[8,12.5,1.2],[9,11.5,8.8]],"id":46969227}]}]}
{"op":"mcm","clk":"AIt/AOtCAKtx","pt":1659347639267,"mc":[{"id":"1.201590187","rc":[{"atb":[[14,1.44]],"id":45323444},{"atb":[[24,2.29]],"id":44621159}]}]}
{"op":"mcm","clk":"AIt/AO5CAK9x","pt":1659347639317,"mc":[{"id":"1.201590187","rc":[{"bdatb":[[0,14,1.44]],"id":45323444},{"bdatl":[[8,2.4,74.87],[9,2.42,4.08]],"id":9570503},{"bdatb":[[1,24,2.29]],"id":44621159}]}]}
{"op":"mcm","clk":"AJR/APRCALpx","pt":1659347639482,"mc":[{"id":"1.201590187","rc":[{"atb":[[13,4.61]],"id":45323444}]}]}
{"op":"mcm","clk":"AJR/APVCALxx","pt":1659347639532,"mc":[{"id":"1.201590187","rc":[{"bdatb":[[2,13,4.61],[3,12.5,5.91],[4,12,4.6],[5,11.5,8.29],[6,11,2.17],[7,10,14.97],[8,9.8,10.18],[9,9.6,21]],"id":45323444}]}]}
{"op":"mcm","clk":"AJ1/APlCAMNx","pt":1659347639690,"mc":[{"id":"1.201590187","rc":[{"atb":[[25,2.3]],"id":44621159}]}]}
{"op":"mcm","clk":"AJ1/APpCAMVx","pt":1659347639740,"mc":[{"id":"1.201590187","rc":[{"bdatb":[[1,25,2.3],[2,24,2.29],[3,23,4.55],[4,21,5],[5,18.5,1.57],[6,15.5,5.91],[7,14.5,1.04],[8,13.5,7.17],[9,12.5,3.31]],"id":44621159}]}]}
{"op":"mcm","clk":"AKp/AP5CANpx","pt":1659347639987,"mc":[{"id":"1.201590187","rc":[{"atl":[[9.6,0]],"id":43885158}]}]}
{"op":"mcm","clk":"AKp/AIFDANpx","pt":1659347640038,"mc":[{"id":"1.201590187","rc":[{"bdatb":[[7,10,13.29],[8,9.8,9]],"id":45323444},{"bdatb":[[9,1.91,107.36]],"id":9570503},{"bdatb":[[8,5,6.89],[9,4.9,58.04]],"id":12989514},{"bdatb":[[9,12.5,1.97]],"id":44621159},{"bdatl":[[2,10.5,3.28],[3,11.5,2.65],[4,12,1.4],[5,12.5,18],[6,14,13.2],[7,14.5,1],[8,15,12],[9,15.5,1]],"id":43885158}]}]}
{"op":"mcm","clk":"AMZ/AI9DAPZx","pt":1659347640466,"mc":[{"id":"1.201590187","rc":[{"atb":[[13,0.19]],"id":45323444},{"atb":[[25,0]],"id":44621159},{"atl":[[10.5,0]],"id":43885158}]}]}
{"op":"mcm","clk":"AMd/AJJDAP5x","pt":1659347640517,"mc":[{"id":"1.201590187","rc":[{"bdatb":[[2,12.5,6.1],[3,12,4.6],[4,11.5,8.29],[5,11,2.17],[6,10,13.29],[7,9.8,9],[8,9.6,21],[9,9.4,45.48]],"id":45323444},{"bdatb":[[8,4.9,58.04],[9,4.8,9.18]],"id":12989514},{"bdatb":[[1,24,2.29],[2,23,4.55],[3,21,5],[4,18.5,1.57],[5,15.5,5.91],[6,14.5,1.04],[7,13.5,7.17],[8,12.5,1.97],[9,11,31.6]],"id":44621159},{"bdatl":[[2,11.5,2.65],[3,12,1.4],[4,12.5,18],[5,14,13.2],[6,14.5,1],[7,15,12],[8,15.5,1],[9,16.5,26.29]],"id":43885158}]}]}
{"op":"mcm","clk":"AM1/AJNDAIFy","pt":1659347640582,"mc":[{"id":"1.201590187","rc":[{"atb":[[8,3.46]],"atl":[[12,4.68],[9.2,2.69]],"id":43885158}]}]}
{"op":"mcm","clk":"AM1/AJRDAIRy","pt":1659347640633,"mc":[{"id":"1.201590187","rc":[{"bdatb":[[4,11.5,7.37],[5,11,3.13],[6,10,12.23]],"id":45323444},{"bdatb":[[3,1.98,49.43],[4,1.97,5.47],[5,1.96,10.36],[7,1.93,7.31],[8,1.91,107.36],[9,1.86,1.4]],"bdatl":[[7,2.38,10.6],[8,2.4,71.82],[9,2.42,3.69]],"id":9570503},{"bdatb":[[5,5.6,3.57],[6,5.5,4.32],[7,5.3,2.65]],"id":12989514},{"bdatb":[[5,15.5,5.54],[6,14.5,1.44],[8,12.5,1.12]],"id":44621159},{"bdatb":[[6,5.8,13.64],[7,5.7,45.56],[8,5.6,66.42]],"id":44836671},{"bdatb":[[0,8,3.46]],"bdatl":[[0,9.2,2.69],[3,12,4.68]],"id":43885158},{"bdatb":[[7,13.5,1.8],[8,12.5,1.66]],"id":46969227}]}]}
{"op":"mcm","clk":"ANR/AJVDAIhy","pt":1659347640691,"mc":[{"id":"1.201590187","rc":[{"atb":[[14,5.52]],"id":45323444}]}]}
{"op":"mcm","clk":"ANR/AJVDAIly","pt":1659347640741,"mc":[{"id":"1.201590187","rc":[{"bdatb":[[0,14,5.52]],"id":45323444},{"bdatl":[[8,2.4,75.54],[9,2.42,12.68]],"id":9570503}]}]}
{"op":"mcm","clk":"ANp/AJZDAIxy","pt":1659347640792,"mc":[{"id":"1.201590187","rc":[{"atb":[[14,6.52]],"atl":[[20,2]],"id":45323444},{"atb":[[25,1]],"atl":[[38,2.87]],"id":44621159}]}]}
{"op":"mcm","clk":"ANp/AJdDAI1y","pt":1659347640842,"mc":[{"id":"1.201590187","rc":[{"bdatb":[[0,14,6.52]],"bdatl":[[0,20,2.54]],"id":45323444},{"bdatb":[[4,1.97,13.18],[5,1.96,5.08],[6,1.95,1.93],[9,1.86,14.74]],"id":9570503},{"bdatb":[[5,5.6,7.14],[6,5.4,3.3],[7,4.9,59.85],[8,4.8,7.33],[9,4.7,8.16]],"id":12989514},{"bdatb":[[1,25,1],[2,24,2.29],[3,23,4.55],[4,21,5],[5,18.5,1.57],[6,15.5,5.54],[7,15,1.4],[8,13.5,7.17],[9,13,1.09]],"bdatl":[[0,38,2.87]],"id":44621159},{"bdatb":[[7,5.7,48.23],[8,5.6,64.58],[9,5.5,16.25]],"id":44836671},{"bdatb":[[6,6.8,6.19],[7,6.6,14.3],[8,6.4,5.61],[9,6.2,14.84]],"id":43885158},{"bdatb":[[8,13,1.61],[9,11.5,9.74]],"id":46969227}]}]}
{"op":"mcm","clk":"AOF/AJdDAJBy","pt":1659347640892,"mc":[{"id":"1.201590187","rc":[{"atb":[[24,4.71]],"id":44621159}]}]}
{"op":"mcm","clk":"AOR/AJpDAJRy","pt":1659347640942,"mc":[{"id":"1.201590187","rc":[{"bdatb":[[2,24,4.71]],"id":44621159}]}]}
{"op":"mcm","clk":"APJ/AKBDAJ9y","pt":1659347641110,"mc":[{"id":"1.201590187","rc":[{"atb":[[7.6,7.71]],"id":43885158}]}]}
{"op":"mcm","clk":"APZ/AKFDAKRy","pt":1659347641160,"mc":[{"id":"1.201590187","rc":[{"bdatb":[[2,7.6,7.71]],"id":43885158}]}]}
{"op":"mcm","clk":"APl/AKZDAKVy","pt":1659347641210,"mc":[{"id":"1.201590187","rc":[{"atb":[[9.2,1.31]],"atl":[[9.2,0]],"trd":[[9.2,33.14]],"ltp":9.2,"tv":146.9,"id":43885158}],"tv":1398.35}]}
{"op":"mcm","clk":"APp/AKdDAKpy","pt":1659347641260,"mc":[{"id":"1.201590187","rc":[{"bdatb":[[2,12.5,5.81],[3,12,4.91],[4,11.5,5.54],[5,11,4.87],[6,10,10],[9,9.4,45.49]],"bdatl":[[7,46,12.26],[8,50,25.39]],"id":45323444},{"bdatb":[[3,1.98,42.26],[4,1.97,19.34],[5,1.96,2.62],[6,1.91,107.42],[7,1.9,1.02],[8,1.88,4.57],[9,1.86,10.63]],"bdatl":[[6,2.26,1.08],[7,2.28,4.21],[8,2.38,11.63],[9,2.4,75.54]],"id":9570503},{"bdatb":[[3,6,2],[4,5.6,7.76],[5,5,2.13],[6,4.9,62.05],[7,4.8,3.55],[8,4.7,11.24],[9,4.6,17.31]],"bdatl":[[7,10,18.57]],"id":12989514},{"bdatb":[[5,18.5,1.37],[6,15.5,4.84],[7,15,2.21],[8,13.5,6.56],[9,11,32.57]],"id":44621159},{"bdatb":[[6,5.8,10],[7,5.7,51.57],[8,5.6,63.72],[9,5.5,13]],"bdatl":[[7,11,1.1],[8,11.5,12.2],[9,12,1.41]],"id":44836671},{"bdatb":[[0,9.2,1.31],[1,8,3.46],[2,7.8,1.26],[3,7.6,7.71],[4,7.4,6.83],[5,7.2,4.21],[6,7,5],[7,6.8,6.19],[8,6.6,14.3],[9,6.4,5.61]],"bdatl":[[0,9.4,4.65],[1,11.5,2.65],[2,12,4.68],[3,12.5,18],[4,14,13.2],[5,14.5,1],[6,15,12],[7,15.5,1],[8,16.5,26.29],[9,17,24.25]],"id":43885158},{"bdatb":[[7,13,3.32],[8,11.5,7.81],[9,10,7.79]],"id":46969227}]}]}
{"op":"mcm","clk":"AP1/AKhDAKty","pt":1659347641310,"mc":[{"id":"1.201590187","rc":[{"atb":[[9.2,0]],"trd":[[9.2,35.76]],"tv":149.52,"id":43885158}],"tv":1400.97}]}
{"op":"mcm","clk":"AICAAQCrQwCucg==","pt":1659347641360,"mc":[{"id":"1.201590187","rc":[{"bdatl":[[7,46,12.2],[8,50,25.2]],"id":45323444},{"bdatl":[[6,2.34,1.05],[7,2.38,10.6],[8,2.4,75.54],[9,2.42,12.68]],"id":9570503},{"bdatl":[[7,10,17.36]],"id":12989514},{"bdatl":[[7,11.5,12.2],[8,12,1.41],[9,13,59.3]],"id":44836671},{"bdatb":[[0,8,3.46],[1,7.8,1.26],[2,7.6,7.71],[3,7.4,6.83],[4,7.2,4.21],[5,7,5],[6,6.8,6.19],[7,6.6,14.3],[8,6.4,5.61],[9,6.2,14.84]],"id":43885158}]}]}
{"op":"mcm","clk":"AIGAAQCsQwCwcg==","pt":1659347641410,"mc":[{"id":"1.201590187","rc":[{"atl":[[9.4,4.92],[9.2,2]],"id":43885158}]}]}
{"op":"mcm","clk":"AISAAQCuQwC0cg==","pt":1659347641460,"mc":[{"id":"1.201590187","rc":[{"bdatb":[[2,12.5,6.1],[3,12,4.6],[4,11.5,6.82],[5,11,3.71],[6,10,11.85],[9,9.4,45.48]],"id":45323444},{"bdatb":[[3,1.98,46.23],[4,1.97,16.4],[5,1.96,5.08],[6,1.95,1.93],[7,1.93,5.33],[8,1.91,107.36],[9,1.86,16.35]],"id":9570503},{"bdatb":[[3,6,2.6],[4,5.7,1.22],[5,5.6,7.14],[6,5.4,2.6],[7,4.9,60.63],[8,4.8,6.53],[9,4.7,8.97]],"id":12989514},{"bdatb":[[5,18.5,1.57],[6,15.5,5.13],[7,15,1.82],[8,13.5,7.17],[9,11,32.4]],"id":44621159},{"bdatb":[[6,5.8,12.55],[7,5.7,49.34],[8,5.6,64.58],[9,5.5,15.56]],"id":44836671},{"bdatl":[[0,9.2,2],[1,9.4,4.92],[2,11.5,2.65],[3,12,4.68],[4,12.5,18],[5,14,13.2],[6,14.5,1],[7,15,12],[8,15.5,1],[9,16.5,26.29]],"id":43885158},{"bdatb":[[7,13.5,1.32],[8,13,2.1],[9,11.5,9.41]],"id":46969227}]}]}
{"op":"mcm","clk":"AIaAAQCwQwC3cg==","pt":1659347641510,"mc":[{"id":"1.201590187","rc":[{"atb":[[15.5,1.76]],"atl":[[23,1.76]],"id":45323444},{"atb":[[1.94,1.76]],"id":9570503},{"atb":[[5.9,1.76]],"atl":[[8,1.76]],"id":12989514},{"atb":[[27,1.76]],"id":44621159},{"atl":[[8.2,2.07]],"id":44836671},{"atl":[[13,1.76]],"id":43885158},{"atb":[[17.5,1.76]],"atl":[[29,1.76]],"id":46969227}]}]}
{"op":"mcm","clk":"AIiAAQCzQwC6cg==","pt":1659347641560,"mc":[{"id":"1.201590187","rc":[{"bdatb":[[0,15.5,1.76],[1,14,6.52],[2,13.5,2.33],[3,12.5,6.1],[4,12,4.6],[5,11.5,6.82],[6,11,3.71],[7,10,11.85],[8,9.8,9],[9,9.6,21]],"bdatl":[[3,23,1.76],[4,25,5.61],[5,26,5.04],[6,27,3.85],[7,29,8.93],[8,46,12.2],[9,50,25.2]],"id":45323444},{"bdatb":[[7,1.94,1.76],[8,1.93,5.33],[9,1.91,107.36]],"bdatl":[[6,2.3,1.06],[7,2.32,10.73],[8,2.38,4.29],[9,2.4,75.63]],"id":9570503},{"bdatb":[[4,5.9,1.76],[5,5.7,1.22],[6,5.6,7.14],[7,5.4,2.6],[8,4.9,60.63],[9,4.8,6.53]],"bdatl":[[4,8,1.76],[5,8.4,4],[6,9,6.82],[7,9.6,11.09],[8,10,17.36],[9,10.5,12.47]],"id":12989514},{"bdatb":[[0,27,1.76],[1,26,1.1],[2,25,1],[3,24,4.71],[4,23,4.55],[5,21,5],[6,18.5,1.57],[7,15.5,5.13],[8,15,1.82],[9,13.5,7.17]],"id":44621159},{"bdatl":[[4,8.2,2.07],[5,8.4,3],[6,9.2,8],[7,9.8,33.55],[8,11.5,12.41],[9,12,2.56]],"id":44836671},{"bdatl":[[5,13,1.76],[6,14,13.2],[7,14.5,1.17],[8,15,12],[9,15.5,1.89]],"id":43885158},{"bdatb":[[6,17.5,1.76],[7,16,1.43],[8,13.5,1.32],[9,13,2.1]],"bdatl":[[2,29,1.76],[3,34,5.16],[4,40,5.01],[5,80,1.66],[6,310,1],[7,900,1.14],[8,990,1.91]],"id":46969227}]}]}
{"op":"mcm","clk":"AI2AAQC3QwC/cg==","pt":1659347641611,"mc":[{"id":"1.201590187","rc":[{"atb":[[14,2.44]],"bdatb":[[1,14,2.44],[6,11,3.19],[7,10,10]],"id":45323444},{"atb":[[24,2.29]],"bdatb":[[3,24,2.29],[8,15,1.44],[9,13.5,6.56]],"id":44621159},{"atl":[[9.4,2.3]],"bdatl":[[1,9.4,2.3]],"id":43885158},{"bdatb":[[4,1.97,13.49],[5,1.96,2.62],[6,1.94,1.76],[7,1.91,107.42],[8,1.9,2.95],[9,1.88,4.57]],"id":9570503},{"bdatb":[[6,5.6,5.26],[7,5,2.86],[8,4.9,61.31],[9,4.8,4.32]],"id":12989514},{"bdatb":[[7,5.7,48.34],[8,5.6,63.72],[9,5.5,13]],"id":44836671},{"bdatb":[[9,13,1.66]],"id":46969227}]}]}
{"op":"mcm","clk":"AJaAAQC6QwDCcg==","pt":1659347641683,"mc":[{"id":"1.201590187","rc":[{"atb":[[14.5,3.96]],"id":45323444},{"atl":[[9.4,0]],"id":43885158}]}]}
{"op":"mcm","clk":"AJaAAQC9QwDHcg==","pt":1659347641733,"mc":[{"id":"1.201590187","rc":[{"bdatb":[[1,14.5,3.96],[2,14,2.44],[3,13.5,2.33],[4,12.5,6.1],[5,12,4.6],[6,11.5,6.82],[7,11,1.23],[8,10,10],[9,9.8,9]],"id":45323444},{"bdatb":[[4,1.97,2.53],[8,1.9,14.32],[9,1.88,1.65]],"bdatl":[[8,2.36,4.32],[9,2.38,4.24]],"id":9570503},{"bdatb":[[6,5.6,1.4],[7,5,6.08],[8,4.9,59.14],[9,4.8,7.67]],"id":12989514},{"bdatb":[[8,13.5,6.56],[9,11.5,2.38]],"id":44621159},{"bdatb":[[7,5.7,44.55]],"id":44836671},{"bdatl":[[1,11.5,2.65],[2,12,4.68],[3,12.5,18],[4,13,1.76],[5,14,13.2],[6,14.5,1.17],[7,15,12],[8,15.5,1.89],[9,16.5,26.82]],"id":43885158},{"bdatb":[[9,11.5,7.81]],"id":46969227}]}]}
{"op":"mcm","clk":"AKWAAQDCQwDQcg==","pt":1659347641900,"mc":[{"id":"1.201590187","rc":[{"atl":[[1000,0]],"id":45323444},{"atb":[[25,3.3]],"id":44621159},{"atl":[[1000,0]],"id":43885158}]}]}
{"op":"mcm","clk":"AKWAAQDDQwDTcg==","pt":1659347641950,"mc":[{"id":"1.201590187","rc":[{"bdatb":[[2,25,3.3]],"id":44621159}]}]}
{"op":"mcm","clk":"AKmAAQDFQwDXcg==","pt":1659347642000,"mc":[{"id":"1.201590187","rc":[{"atl":[[24,0.48]],"id":45323444},{"atb":[[6.4,9.88]],"id":12989514},{"atl":[[11.5,3.07]],"id":43885158}]}]}
{"op":"mcm","clk":"AKmAAQDIQwDXcg==","pt":1659347642050,"mc":[{"id":"1.201590187","rc":[{"bdatl":[[4,25,6.09]],"id":45323444},{"bdatb":[[9,1.88,4.3]],"id":9570503},{"bdatb":[[1,6.4,9.88],[7,5,7.08],[8,4.9,58.12]],"id":12989514},{"bdatl":[[1,11.5,3.08]],"id":43885158}]}]}
{"op":"mcm","clk":"ALCAAQDJQwDccg==","pt":1659347642119,"mc":[{"id":"1.201590187","rc":[{"atl":[[20,1]],"id":45323444},{"atl":[[38,1.87]],"id":44621159},{"atl":[[12,3.28]],"id":43885158}]}]}
{"op":"mcm","clk":"ALGAAQDVQwDhcg==","pt":1659347642169,"mc":[{"id":"1.201590187","rc":[{"bdatl":[[0,20,1.54]],"id":45323444},{"bdatb":[[8,1.9,6.34],[9,1.89,8.03]],"id":9570503},{"bdatb":[[9,4.8,3.51]],"id":12989514},{"bdatb":[[9,11.5,1.06]],"bdatl":[[0,38,1.87]],"id":44621159},{"bdatb":[[6,6.8,3.96],[7,6.6,16.6],[8,6.4,2.48],[9,6.2,18.07]],"bdatl":[[2,12,3.28]],"id":43885158}]}]}
{"op":"mcm","clk":"ALaAAQDbQwDmcg==","pt":1659347642220,"mc":[{"id":"1.201590187","rc":[{"atb":[[13.5,1.33],[12.5,4.01]],"id":45323444},{"atb":[[26,0.1]],"id":44621159},{"atl":[[990,1.4]],"id":43885158}]}]}
{"op":"mcm","clk":"AL2AAQDcQwDpcg==","pt":1659347642278,"mc":[{"id":"1.201590187","rc":[{"atb":[[1.02,1.6]],"bdatb":[[3,13.5,1.33],[4,12.5,4.49]],"id":45323444},{"bdatb":[[1,25,3.4],[2,24,2.29],[3,23,4.55],[4,21,5],[5,18.5,1.57],[6,15.5,5.13],[7,13.5,6.56],[8,11.5,1.06],[9,11,33.72]],"id":44621159}]}]}
{"op":"mcm","clk":"AMGAAQDfQwDucg==","pt":1659347642377,"mc":[{"id":"1.201590187","rc":[{"atb":[[27,0]],"id":44621159}]}]}
{"op":"mcm","clk":"AMGAAQDfQwDwcg==","pt":1659347642427,"mc":[{"id":"1.201590187","rc":[{"bdatl":[[6,2.32,1.06],[7,2.34,10.64],[8,2.38,4.29],[9,2.4,84.22]],"id":9570503},{"bdatb":[[0,25,3.4],[1,24,2.29],[2,23,4.55],[3,21,5],[4,18.5,1.57],[5,15.5,5.13],[6,13.5,6.56],[7,11.5,1.06],[8,11,33.72],[9,10,121.02]],"id":44621159},{"bdatl":[[9,12,1.41]],"id":44836671},{"bdatl":[[8,15.5,1.01],[9,16.5,26.99]],"id":43885158}]}]}
{"op":"mcm","clk":"AMuAAQDqQwD8cg==","pt":1659347642686,"mc":[{"id":"1.201590187","rc":[{"atb":[[14.5,0],[14,1.17]],"atl":[[19.5,0.13]],"id":45323444},{"atb":[[26,0],[25,1]],"id":44621159}]}]}
{"op":"mcm","clk":"AM+AAQDvQwCBcw==","pt":1659347642737,"mc":[{"id":"1.201590187","rc":[{"bdatb":[[1,14,1.17],[2,13.5,1.33],[3,12.5,4.49],[4,12,4.6],[5,11.5,6.82],[6,11,1.23],[7,10,10],[8,9.8,9],[9,9.6,21]],"bdatl":[[0,20,1.13]],"id":45323444},{"bdatb":[[8,1.9,2.12],[9,1.89,12.27]],"bdatl":[[7,2.34,9.64],[8,2.4,76.67],[9,2.42,2.55]],"id":9570503},{"bdatb":[[5,5.6,2.64],[6,5,6.2],[7,4.9,58.92],[8,4.8,2.97],[9,4.7,8.27]],"id":12989514},{"bdatb":[[0,25,1],[5,15.5,5.15],[7,11,34.41],[8,10,121.13],[9,9.8,3.97]],"id":44621159},{"bdatl":[[8,11.5,12.2],[9,12,1.62]],"id":44836671},{"bdatb":[[6,6.8,2.78],[7,6.6,17.07],[8,6.4,2.77],[9,6.2,18.57]],"bdatl":[[6,14.5,1],[7,15,12.16],[8,15.5,1],[9,16.5,27]],"id":43885158}]}]}
{"op":"mcm","clk":"ANCAAQDxQwCCcw==","pt":1659347642792,"mc":[{"id":"1.201590187","rc":[{"atb":[[13,1.95]],"id":45323444},{"atb":[[1.93,1.76]],"id":9570503},{"atb":[[5.8,1.76]],"atl":[[8.2,1.76]],"id":12989514},{"atb":[[22,1.76]],"id":44621159},{"atl":[[8.6,1.76]],"id":44836671},{"atb":[[17,1.76]],"atl":[[36,1.76]],"id":46969227}]}]}
{"op":"mcm","clk":"ANOAAQDyQwCGcw==","pt":1659347642842,"mc":[{"id":"1.201590187","rc":[{"bdatb":[[3,13,1.95],[4,12.5,4.3],[5,12,4.6],[6,11.5,6.82],[7,11,1.23],[8,10,10],[9,9.8,9]],"id":45323444},{"bdatb":[[7,1.93,1.76],[8,1.91,107.42],[9,1.9,2.12]],"id":9570503},{"bdatb":[[5,5.8,1.76],[6,5.6,2.64],[7,5,6.2],[8,4.9,58.92],[9,4.8,2.97]],"bdatl":[[5,8.2,1.76],[6,8.4,4],[7,9,6.82],[8,9.6,11.09],[9,10,17.36]],"id":12989514},{"bdatb":[[3,22,1.76],[4,21,5],[5,18.5,1.57],[6,15.5,5.15],[7,13.5,6.56],[8,11,34.41],[9,10,121.13]],"id":44621159},{"bdatl":[[6,8.6,1.76],[7,9.2,8],[8,9.8,33.55],[9,11.5,12.2]],"id":44836671},{"bdatb":[[7,17,1.76],[8,16,1.43],[9,13.5,1.32]],"bdatl":[[4,36,1.76],[5,40,5.01],[6,80,1.66],[7,310,1],[8,900,1.14],[9,990,1.91]],"id":46969227}]}]}
{"op":"mcm","clk":"ANiAAQDzQwCKcw==","pt":1659347642902,"mc":[{"id":"1.201590187","rc":[{"atl":[[19.5,0]],"id":45323444},{"atl":[[11.5,2.64]],"id":43885158}]}]}
{"op":"mcm","clk":"ANiAAQD1QwCNcw==","pt":1659347642952,"mc":[{"id":"1.201590187","rc":[{"bdatl":[[0,20,1]],"id":45323444},{"bdatb":[[9,1.89,14.39]],"id":9570503},{"bdatb":[[7,5,5.69],[8,4.9,58.42],[9,4.8,4.01]],"id":12989514},{"bdatb":[[8,11,34.19],[9,10,121.4]],"id":44621159},{"bdatb":[[6,6.8,2.41],[8,6.4,3.16],[9,6.2,18.44]],"bdatl":[[1,11.5,2.65]],"id":43885158},{"bdatb":[[9,13.5,1.33]],"id":46969227}]}]}
{"op":"mcm","clk":"AN2AAQD4QwCOcw==","pt":1659347643004,"mc":[{"id":"1.201590187","rc":[{"atl":[[12,3.71]],"id":43885158}]}]}
{"op":"mcm","clk":"AN2AAQD6QwCTcw==","pt":1659347643054,"mc":[{"id":"1.201590187","rc":[{"bdatl":[[2,12,3.71]],"id":43885158}]}]}
{"op":"mcm","clk":"AOKAAQD+QwCUcw==","pt":1659347643118,"mc":[{"id":"1.201590187","rc":[{"atb":[[13,4.62],[12,7.26]],"atl":[[20,1.13]],"id":45323444}]}]}
{"op":"mcm","clk":"AOeAAQCBRACXcw==","pt":1659347643168,"mc":[{"id":"1.201590187","rc":[{"bdatb":[[3,13,4.62],[5,12,7.26]],"bdatl":[[0,20,1.13]],"id":45323444},{"bdatb":[[9,1.9,2.15]],"id":9570503},{"bdatb":[[7,5,6.08],[8,4.9,58.15],[9,4.8,3.87]],"id":12989514},{"bdatb":[[8,11,34.36],[9,10,121.21]],"id":44621159},{"bdatb":[[6,6.8,2.79],[8,6.4,2.76],[9,6.2,18.57]],"id":43885158}]}]}
{"op":"mcm","clk":"AOqAAQCCRACacw==","pt":1659347643218,"mc":[{"id":"1.201590187","rc":[{"atl":[[16.5,3.92]],"id":45323444},{"atb":[[6.8,0]],"atl":[[6.8,5.98]],"trd":[[6.8,1.84]],"ltp":6.8,"tv":94.87,"id":12989514},{"atb":[[7.2,5.99]],"id":44836671},{"atb":[[8.8,4.9],[7.6,4.53]],"id":43885158}],"tv":1401.69}]}
{"op":"mcm","clk":"AO2AAQCFRACecw==","pt":1659347643269,"mc":[{"id":"1.201590187","rc":[{"bdatb":[[1,14,1.43],[4,12.5,5.2],[6,11.5,5.54],[8,10,10.01],[9,9.8,11.26]],"bdatl":[[0,16.5,3.92],[1,20,1.13],[2,21,1.28],[3,22,2.72],[4,23,1.76],[5,25,6.09],[6,26,5.04],[7,27,3.85],[8,29,8.93],[9,46,12.2]],"id":45323444},{"bdatb":[[0,2.06,8.93],[1,2.04,7.94],[2,2.02,30.83],[3,2,23.35],[4,1.98,36.99],[5,1.97,13.76],[6,1.96,2.62],[7,1.94,5.98],[8,1.93,1.76],[9,1.92,2.86]],"bdatl":[[6,2.26,11.06],[7,2.28,1.03],[8,2.3,6.84],[9,2.4,79.17]],"id":9570503},{"bdatb":[[0,6.6,15.99],[1,6.4,10.45],[3,6,4.46],[6,5.3,5.74],[7,5.2,1.06],[8,5.1,2.03],[9,4.9,58.02]],"bdatl":[[0,6.8,5.98],[1,7.2,6.35],[2,7.4,8.34],[3,7.6,11.01],[4,7.8,17.08],[5,8,1.76],[6,8.2,1.76],[7,8.4,4],[8,9,6.82],[9,9.6,12.78]],"id":12989514},{"bdatb":[[0,25,1.13],[3,22,2.44],[5,18.5,1.37],[6,15.5,4.2],[7,15,1.48],[8,13.5,6.56],[9,12.5,1.07]],"id":44621159},{"bdatb":[[0,7.2,5.99],[1,7,13.18],[2,6.8,5.89],[3,6.6,15.64],[4,6.4,2.68],[5,6.2,25.79],[6,6,29.74],[7,5.9,9],[8,5.8,10.02],[9,5.7,48.43]],"bdatl":[[9,11,1.47]],"id":44836671},{"bdatb":[[0,8.8,4.9],[1,8,3.89],[2,7.8,6.01],[3,7.6,4.53],[4,7.4,8.68],[5,7.2,5.14],[6,7,5],[7,6.6,16.29],[8,6.4,2.14],[9,6.2,19.81]],"bdatl":[[7,15,13.08],[9,16.5,26.82]],"id":43885158},{"bdatb":[[0,21,3.42],[5,18,5.82],[9,13,1.71]],"bdatl":[[8,900,1.16]],"id":46969227}]}]}
{"op":"mcm","clk":"APKAAQCHRACfcw==","pt":1659347643319,"mc":[{"id":"1.201590187","rc":[{"atl":[[20,1]],"bdatl":[[1,20,1]],"id":45323444},{"atb":[[7,130]],"bdatb":[[6,7,130],[7,6.6,16.03],[8,6.4,2.26],[9,6.2,19.95]],"id":43885158}]}]}
{"op":"mcm","clk":"APqAAQCLRACkcw==","pt":1659347643380,"mc":[{"id":"1.201590187","rc":[{"atb":[[15.5,0]],"id":45323444},{"atl":[[6.8,0]],"trd":[[6.8,13.79]],"tv":106.82,"id":12989514},{"atb":[[25,3.3]],"id":44621159},{"atb":[[7,13.53],[7.2,0.01]],"trd":[[7.2,20.26]],"ltp":7.2,"tv":219.42,"id":44836671},{"atl":[[9.2,0]],"trd":[[9.2,39.76]],"tv":153.52,"id":43885158}],"tv":1429.6}]}
{"op":"mcm","clk":"APqAAQCMRACmcw==","pt":1659347643438,"mc":[{"id":"1.201590187","rc":[{"bdatb":[[0,14,1.17],[1,13.5,1.33],[2,13,4.62],[3,12.5,4.01],[4,12,7.26],[5,11.5,5.54],[6,11,1.23],[7,10,10.36],[8,9.8,9],[9,9.6,21]],"id":45323444},{"bdatb":[[0,2.04,7.94],[1,2.02,30.83],[2,2,23.35],[3,1.98,36.93],[4,1.97,2.53],[5,1.96,2.62],[6,1.94,17.45],[7,1.93,1.76],[8,1.92,7.97],[9,1.91,111.86]],"bdatl":[[6,2.32,7.06],[7,2.34,11.41],[8,2.4,71.43],[9,2.42,11.44]],"id":9570503},{"bdatb":[[1,6.4,9.88],[3,6,2],[6,5.3,5.71],[7,5.2,4.6]],"bdatl":[[0,7.2,6.35],[1,7.4,8.34],[2,7.6,11.01],[3,7.8,17.08],[4,8,1.76],[5,8.2,1.76],[6,8.4,4],[7,9,6.82],[8,9.6,11.09],[9,10,17.36]],"id":12989514},{"bdatb":[[0,25,3.3],[3,22,1.76],[7,13.5,6.79],[8,13,2.06],[9,12.5,1.22]],"id":44621159},{"bdatb":[[0,7,13.54],[1,6.8,5.36],[2,6.6,15.64],[3,6.2,26.16],[4,6,29.74],[5,5.9,9],[6,5.8,10.02],[7,5.7,45.16],[8,5.6,63.72],[9,5.5,13]],"bdatl":[[9,11.5,12.2]],"id":44836671},{"bdatb":[[1,8,3.46],[2,7.8,1.73],[4,7.4,12.52],[5,7.2,4.9],[6,7,131.48],[7,6.6,13],[8,6.4,5.13],[9,6.2,14.33]],"bdatl":[[0,11.5,2.65],[1,12,3.71],[2,12.5,18],[3,13,1.76],[4,14,13.2],[5,14.5,1],[6,15,12],[7,15.5,1],[8,16.5,26.14],[9,17,24.25]],"id":43885158},{"bdatb":[[0,21,3.25],[5,18,5],[9,11.5,10.42]],"bdatl":[[8,900,1.14]],"id":46969227}]}]}
{"op":"mcm","clk":"AIGBAQCORACpcw==","pt":1659347643488,"mc":[{"id":"1.201590187","rc":[{"atl":[[7.8,0.34],[7.6,154.97],[7.4,0.34],[8,0.32]],"id":44836671}]}]}
{"op":"mcm","clk":"AIGBAQCPRACpcw==","pt":1659347643538,"mc":[{"id":"1.201590187","rc":[{"bdatb":[[7,10,10.25],[9,9.6,21.12]],"id":45323444},{"bdatb":[[6,1.94,3.06],[8,1.92,14.53],[9,1.91,115.37]],"id":9570503},{"bdatb":[[6,5.2,5.8],[7,5.1,6.71],[8,4.9,58.02],[9,4.8,5.01]],"id":12989514},{"bdatb":[[7,13.5,6.8],[8,12.5,2.14],[9,12,1.28]],"id":44621159},{"bdatl":[[0,7.6,155.31],[1,8.2,2.73],[2,8.4,3],[3,8.6,1.76],[4,9.2,8],[5,9.8,33.55],[6,11.5,12.2],[7,12,2.76],[8,13,60.49],[9,13.5,2.2]],"id":44836671},{"bdatb":[[2,7.8,1.59],[3,7.6,4.68],[4,7.4,6.83],[5,7.2,9.55],[6,7,132.71]],"id":43885158},{"bdatb":[[9,11.5,8.1]],"id":46969227}]}]}
{"op":"mcm","clk":"AIqBAQCSRACucw==","pt":1659347643596,"mc":[{"id":"1.201590187","rc":[{"atl":[[12.5,10],[12,7.42]],"id":43885158}]}]}
{"op":"mcm","clk":"AIqBAQCSRACucw==","pt":1659347643647,"mc":[{"id":"1.201590187","rc":[{"bdatb":[[9,4.8,9.36]],"id":12989514},{"bdatl":[[1,12,7.42],[2,12.5,10]],"id":43885158}]}]}
{"op":"mcm","clk":"AJKBAQCVRAC0cw==","pt":1659347643697,"mc":[{"id":"1.201590187","rc":[{"atb":[[2.02,26.08]],"id":9570503}]}]}
{"op":"mcm","clk":"AJKBAQCXRAC0cw==","pt":1659347643747,"mc":[{"id":"1.201590187","rc":[{"bdatb":[[1,2.02,26.08]],"id":9570503}]}]}
{"op":"mcm","clk":"AJmBAQCaRAC3cw==","pt":1659347643800,"mc":[{"id":"1.201590187","rc":[{"atl":[[11.5,2.88]],"id":43885158},{"atl":[[29,0]],"id":46969227}]}]}
{"op":"mcm","clk":"AJmBAQCbRAC5cw==","pt":1659347643850,"mc":[{"id":"1.201590187","rc":[{"bdatb":[[8,1.92,15.97],[9,1.91,113.93]],"id":9570503},{"bdatb":[[6,5.2,6.33],[7,5.1,6.17]],"id":12989514},{"bdatb":[[8,12.5,2.36],[9,12,1.05]],"id":44621159},{"bdatl":[[0,11.5,2.89]],"id":43885158},{"bdatl":[[2,34,5.16],[3,36,1.76],[4,40,5.01],[5,80,1.66],[6,310,1],[7,900,1.14],[8,990,1.91],[9,0,0]],"id":46969227}]}]}
{"op":"mcm","clk":"AKGBAQCdRAC9cw==","pt":1659347643900,"mc":[{"id":"1.201590187","rc":[{"atb":[[8,5.64]],"id":43885158}]}]}
{"op":"mcm","clk":"AKKBAQCfRADAcw==","pt":1659347643950,"mc":[{"id":"1.201590187","rc":[{"bdatl":[[9,2.42,16.27]],"id":9570503},{"bdatb":[[1,8,5.64]],"id":43885158}]}]}
{"op":"mcm","clk":"AKiBAQCkRADDcw==","pt":1659347644003,"mc":[{"id":"1.201590187","rc":[{"atb":[[10.5,1.76]],"atl":[[19.5,1.76]],"id":45323444},{"atb":[[5.7,1.76]],"atl":[[8.6,1.76]],"id":12989514},{"atb":[[20,1.76]],"id":44621159},{"atl":[[7.8,2.1]],"id":44836671},{"atb":[[9,1.76],[8,7.82]],"atl":[[13.5,1.76]],"id":43885158},{"atb":[[16.5,1.76]],"atl":[[38,1.76]],"id":46969227}]}]}
{"op":"mcm","clk":"AKuBAQClRADJcw==","pt":1659347644054,"mc":[{"id":"1.201590187","rc":[{"bdatb":[[7,10.5,1.76],[8,10,10.25],[9,9.8,9]],"bdatl":[[1,19.5,1.76],[2,20,1],[3,21,1.28],[4,22,2.72],[5,23,1.76],[6,25,6.09],[7,26,5.04],[8,27,3.85],[9,29,8.93]],"id":45323444},{"bdatl":[[6,2.3,6.9],[7,2.34,18.42],[9,2.42,9.71]],"id":9570503},{"bdatb":[[6,5.7,1.78],[7,5.2,6.31],[8,5.1,6.17],[9,4.9,59.32]],"bdatl":[[7,8.6,1.76],[8,9,6.82],[9,9.6,11.09]],"id":12989514},{"bdatb":[[5,20,1.76],[6,18.5,1.37],[7,15.5,4.2],[8,13.5,6.8],[9,12.5,2.36]],"id":44621159},{"bdatl":[[1,7.8,2.1],[2,8.2,2.39],[3,8.4,3],[4,8.6,1.76],[5,9.2,8],[6,9.8,33.55],[7,11.5,13.58],[8,12,1.44],[9,13,60.49]],"id":44836671},{"bdatb":[[0,9,1.76],[1,8.8,4.9],[2,8,7.82],[3,7.8,1.59],[4,7.6,4.68],[5,7.4,6.83],[6,7.2,9.55],[7,7,132.71],[8,6.6,13.96],[9,6.4,7.69]],"bdatl":[[4,13.5,1.76],[5,14,13.2],[6,14.5,1],[7,15,12],[8,15.5,1],[9,16.5,26.14]],"id":43885158},{"bdatb":[[8,16.5,1.76],[9,16,1.43]],"bdatl":[[4,38,1.76],[5,40,5.01],[6,80,1.66],[7,310,1],[8,900,1.14],[9,990,1.91]],"id":46969227}]}]}
{"op":"mcm","clk":"ALKBAQCmRADMcw==","pt":1659347644116,"mc":[{"id":"1.201590187","rc":[{"atb":[[13,1.95]],"id":45323444},{"atb":[[6.2,10.3]],"id":12989514},{"atb":[[25,1]],"id":44621159}]}]}
{"op":"mcm","clk":"ALKBAQCmRADScw==","pt":1659347644166,"mc":[{"id":"1.201590187","rc":[{"bdatb":[[2,13,1.95]],"id":45323444},{"bdatl":[[7,2.34,7.89],[8,2.36,10.44],[9,2.4,71.43]],"id":9570503},{"bdatb":[[2,6.2,10.3]],"id":12989514},{"bdatb":[[0,25,1]],"id":44621159},{"bdatl":[[9,13,59.77]],"id":44836671}]}]}
{"op":"mcm","clk":"ALmBAQCrRADScw==","pt":1659347644216,"mc":[{"id":"1.201590187","rc":[{"atb":[[14,1]],"id":45323444},{"atb":[[24,4.71]],"id":44621159}]}]}
{"op":"mcm","clk":"ALmBAQCrRADXcw==","pt":1659347644266,"mc":[{"id":"1.201590187","rc":[{"bdatb":[[0,14,1]],"id":45323444},{"bdatl":[[6,2.3,6.09],[7,2.34,7.68],[8,2.36,10.76],[9,2.4,72.11]],"id":9570503},{"bdatb":[[1,24,4.71]],"id":44621159},{"bdatl":[[7,11.5,13.42],[8,12,1.57],[9,13,59.8]],"id":44836671}]}]}
{"op":"mcm","clk":"AOKBAQC4RAD6cw==","pt":1659347644882,"mc":[{"id":"1.201590187","rc":[{"atl":[[7.8,9.08],[7,8]],"id":12989514},{"atb":[[24,2.29]],"id":44621159},{"atl":[[12.5,13.48]],"id":43885158}]}]}
{"op":"mcm","clk":"AOOBAQC4RAD/cw==","pt":1659347644932,"mc":[{"id":"1.201590187","rc":[{"bdatb":[[7,10.5,1.77],[8,10,10.35]],"id":45323444},{"bdatb":[[4,1.97,2.59],[6,1.95,1.23],[7,1.94,17.57],[8,1.93,1.76],[9,1.92,11.89]],"id":9570503},{"bdatl":[[0,7,8],[1,7.2,6.35],[2,7.4,8.34],[3,7.6,11.01],[4,7.8,9.08],[5,8,1.76],[6,8.2,1.76],[7,8.4,4],[8,8.6,1.76],[9,9,6.82]],"id":12989514},{"bdatb":[[1,24,2.29],[7,15.5,4.35],[8,13.5,8.82],[9,12.5,1.83]],"id":44621159},{"bdatb":[[4,6,29.76],[6,5.8,10.61],[7,5.7,44.55],[9,5.5,18.37]],"id":44836671},{"bdatb":[[2,8,8.13],[3,7.8,1.41],[4,7.6,4.53],[5,7.4,13.91],[6,7.2,4.91],[7,7,130],[8,6.6,18.21],[9,6.4,5.13]],"bdatl":[[2,12.5,13.48]],"id":43885158}]}]}
{"op":"mcm","clk":"AOuBAQC7RACEdA==","pt":1659347644991,"mc":[{"id":"1.201590187","rc":[{"atl":[[7,8.36]],"id":12989514}]}]}
{"op":"mcm","clk":"AOuBAQC7RACGdA==","pt":1659347645041,"mc":[{"id":"1.201590187","rc":[{"bdatb":[[9,1.92,13.2]],"id":9570503},{"bdatl":[[0,7,8.36]],"id":12989514},{"bdatb":[[9,12.5,2.03]],"id":44621159},{"bdatb":[[5,7.4,14.25],[6,7.2,4.56]],"id":43885158}]}]}
{"op":"mcm","clk":"APGBAQC9RACJdA==","pt":1659347645094,"mc":[{"id":"1.201590187","rc":[{"atb":[[25,3.3]],"id":44621159},{"atl":[[26,5]],"id":46969227}]}]}
{"op":"mcm","clk":"APGBAQC+RACMdA==","pt":1659347645144,"mc":[{"id":"1.201590187","rc":[{"bdatb":[[6,11,1.24],[7,10.5,1.99],[8,10,10.11]],"id":45323444},{"bdatb":[[5,1.96,3.84],[6,1.94,17.57],[7,1.93,14.89],[8,1.92,3.2],[9,1.91,107.36]],"bdatl":[[7,2.34,18.53],[8,2.4,72.11],[9,2.44,161.72]],"id":9570503},{"bdatb":[[5,5.8,1.78],[6,5.7,1.76],[9,4.9,65.04]],"id":12989514},{"bdatb":[[0,25,3.3],[7,15.5,4.42],[8,13.5,8.75],[9,13,1.95]],"id":44621159},{"bdatb":[[5,5.9,9.59],[6,5.8,10],[8,5.6,68.99],[9,5.5,17.61]],"bdatl":[[9,13,60.34]],"id":44836671},{"bdatb":[[2,8,8.27],[3,7.8,1.26],[8,6.6,18.96],[9,6.4,6.02]],"id":43885158},{"bdatl":[[0,26,5],[1,27,3.55],[2,28,11.34],[3,34,5.16],[4,36,1.76],[5,38,1.76],[6,40,5.01],[7,80,1.66],[8,310,1],[9,900,1.14]],"id":46969227}]}]}
{"op":"mcm","clk":"APiBAQDERACOdA==","pt":1659347645199,"mc":[{"id":"1.201590187","rc":[{"atl":[[26,5.1]],"id":46969227}]}]}
{"op":"mcm","clk":"APiBAQDFRACRdA==","pt":1659347645250,"mc":[{"id":"1.201590187","rc":[{"bdatb":[[9,6.4,6.43]],"id":43885158},{"bdatl":[[0,26,5.1]],"id":46969227}]}]}
{"op":"mcm","clk":"AIWCAQDIRACXdA==","pt":1659347645401,"mc":[{"id":"1.201590187","rc":[{"atb":[[5.6,1.76]],"atl":[[8.8,1.76]],"id":12989514},{"atb":[[19.5,1.76]],"id":44621159},{"atl":[[8,2.08]],"id":44836671},{"atl":[[14.5,2.76],[11,2.01]],"id":43885158},{"atl":[[29,1.76]],"id":46969227}]}]}
{"op":"mcm","clk":"AIWCAQDJRACddA==","pt":1659347645451,"mc":[{"id":"1.201590187","rc":[{"bdatb":[[6,11,1.46],[7,10.5,1.87],[8,10,10]],"id":45323444},{"bdatb":[[4,1.97,3.81],[5,1.96,12.61],[6,1.94,18.81],[7,1.93,3.5]],"id":9570503},{"bdatb":[[5,5.8,2.2],[7,5.6,1.96],[8,5.4,3.42],[9,5.2,6.36]],"bdatl":[[9,8.8,1.76]],"id":12989514},{"bdatb":[[6,19.5,1.76],[7,18.5,1.37],[8,15.5,4.4],[9,14.5,1.28]],"id":44621159},{"bdatb":[[4,6,30.34],[5,5.9,9],[7,5.7,47.79],[8,5.6,69.62],[9,5.5,13.61]],"bdatl":[[2,8,2.08],[3,8.2,2.07],[4,8.4,3],[5,8.6,1.76],[6,9.2,8],[7,9.8,33.55],[8,11.5,13.42],[9,12,1.57]],"id":44836671},{"bdatl":[[0,11,2.01],[1,11.5,2.88],[2,12,7.42],[3,12.5,13.48],[4,13,1.76],[5,13.5,1.76],[6,14,13.2],[7,14.5,2.76],[8,15,12],[9,15.5,1]],"id":43885158},{"bdatl":[[3,29,1.76],[4,34,5.16],[5,36,1.76],[6,38,1.76],[7,40,5.01],[8,80,1.66],[9,310,1]],"id":46969227}]}]}
{"op":"mcm","clk":"AIiCAQDJRACedA==","pt":1659347645501,"mc":[{"id":"1.201590187","rc":[{"atl":[[11,2.25]],"id":43885158}]}]}
{"op":"mcm","clk":"AIiCAQDJRACgdA==","pt":1659347645551,"mc":[{"id":"1.201590187","rc":[{"bdatb":[[5,1.96,13.96],[7,1.93,2.13]],"id":9570503},{"bdatb":[[8,5.4,3.91]],"id":12989514},{"bdatb":[[9,14.5,1.46]],"id":44621159},{"bdatb":[[7,5.7,48.25],[9,5.5,13.13]],"id":44836671},{"bdatl":[[0,11,2.25]],"id":43885158}]}]}
{"op":"mcm","clk":"AJWCAQDMRACrdA==","pt":1659347645724,"mc":[{"id":"1.201590187","rc":[{"atb":[[1.17,1.68]],"id":44621159}]}]}
{"op":"mcm","clk":"AKGCAQDQRAC3dA==","pt":1659347645907,"mc":[{"id":"1.201590187","rc":[{"atb":[[1.17,0.1],[25,1]],"id":44621159},{"atl":[[11,3.4]],"id":43885158}]}]}
{"op":"mcm","clk":"AKOCAQDSRAC5dA==","pt":1659347645958,"mc":[{"id":"1.201590187","rc":[{"bdatb":[[5,1.96,20.41],[6,1.94,12.66],[7,1.93,4.95],[8,1.91,107.36],[9,1.89,3.07]],"bdatl":[[7,2.34,7.68],[8,2.36,10.76],[9,2.4,72.11]],"id":9570503},{"bdatb":[[8,5.4,6.25],[9,5.2,5.24]],"id":12989514},{"bdatb":[[0,25,1],[9,14.5,2.33]],"id":44621159},{"bdatb":[[7,5.7,50.47],[8,5.6,67.49],[9,5.5,14.12]],"id":44836671},{"bdatl":[[0,11,3.4]],"id":43885158}]}]}
{"op":"mcm","clk":"AKmCAQDTRAC/dA==","pt":1659347646018,"mc":[{"id":"1.201590187","rc":[{"atl":[[21,0.13]],"id":45323444},{"atb":[[24,4.71]],"id":44621159}]}]}
{"op":"mcm","clk":"AKyCAQDVRADDdA==","pt":1659347646068,"mc":[{"id":"1.201590187","rc":[{"bdatl":[[3,22,2.85],[4,23,1.76],[5,25,6.09],[6,26,5.04],[7,27,3.85],[8,29,8.93],[9,46,12.2]],"id":45323444},{"bdatb":[[1,24,4.71]],"id":44621159},{"bdatb":[[9,6.4,4.74]],"id":43885158}]}]}
{"op":"mcm","clk":"ALSCAQDXRADFdA==","pt":1659347646118,"mc":[{"id":"1.201590187","rc":[{"atb":[[2.02,22.02]],"atl":[[2.14,77.77]],"id":9570503},{"atb":[[6.6,13.72]],"atl":[[7.8,6.76]],"id":12989514},{"atb":[[1.17,0]],"id":44621159},{"atb":[[6.6,13.17]],"atl":[[7.6,152.65]],"id":44836671},{"atb":[[7.4,4.55],[8,5.64]],"id":43885158}]}]}
{"op":"mcm","clk":"ALSCAQDXRADFdA==","pt":1659347646168,"mc":[{"id":"1.201590187","rc":[{"bdatb":[[1,2.02,22.02]],"bdatl":[[1,2.14,77.77]],"id":9570503},{"bdatb":[[0,6.6,13.72]],"bdatl":[[4,7.8,6.76]],"id":12989514},{"bdatb":[[2,6.6,13.17]],"bdatl":[[0,7.6,152.99]],"id":44836671},{"bdatb":[[2,8,6.09],[5,7.4,11.97]],"id":43885158}]}]}
{"op":"mcm","clk":"AL2CAQDYRADMdA==","pt":1659347646218,"mc":[{"id":"1.201590187","rc":[{"atb":[[26,0.1]],"id":44621159}]}]}
{"op":"mcm","clk":"AL2CAQDZRADMdA==","pt":1659347646268,"mc":[{"id":"1.201590187","rc":[{"bdatb":[[0,25,1.1]],"id":44621159}]}]}
{"op":"mcm","clk":"ANWCAQDpRADrdA==","pt":1659347646712,"mc":[{"id":"1.201590187","rc":[{"atl":[[21,1.89]],"id":45323444},{"atb":[[5.5,1.76]],"id":12989514},{"atb":[[19,1.76]],"id":44621159},{"atb":[[6.4,2.13]],"atl":[[8.8,1.76]],"id":44836671},{"atb":[[8.4,1.76],[9,7.51]],"atl":[[15.5,2.76]],"id":43885158},{"atl":[[30,1.83]],"id":46969227}]}]}
{"op":"mcm","clk":"ANWCAQDpRADsdA==","pt":1659347646771,"mc":[{"id":"1.201590187","rc":[{"bdatl":[[3,21,1.89],[4,22,2.72],[5,23,1.76],[6,25,6.09],[7,26,5.04],[8,27,3.85],[9,29,8.93]],"id":45323444},{"bdatl":[[7,2.32,7.73],[8,2.34,10.86],[9,2.36,4.34]],"id":9570503},{"bdatb":[[8,5.5,1.76],[9,5.4,6.25]],"id":12989514},{"bdatb":[[7,19,1.76],[8,18.5,1.37],[9,15.5,4.4]],"id":44621159},{"bdatb":[[3,6.4,2.13],[4,6.2,25.79],[5,6,30.34],[6,5.9,9],[7,5.8,10],[8,5.7,50.47],[9,5.6,67.49]],"bdatl":[[6,8.8,1.76],[7,9.2,8],[8,9.8,33.55],[9,11.5,13.42]],"id":44836671},{"bdatb":[[0,9,7.51],[2,8.4,1.76],[3,8,6.09],[4,7.8,1.26],[5,7.6,4.53],[6,7.4,11.97],[7,7.2,4.56],[8,7,130],[9,6.6,18.96]],"bdatl":[[9,15.5,2.76]],"id":43885158},{"bdatl":[[4,30,1.83],[5,34,5.09],[6,36,1.76],[7,38,1.76],[8,40,5.01],[9,80,1.66]],"id":46969227}]}]}
{"op":"mcm","clk":"AOKCAQDvRADydA==","pt":1659347646921,"mc":[{"id":"1.201590187","rc":[{"atb":[[9,7.78]],"id":43885158}]}]}
{"op":"mcm","clk":"AOKCAQDwRAD3dA==","pt":1659347646971,"mc":[{"id":"1.201590187","rc":[{"bdatl":[[9,2.36,4.61]],"id":9570503},{"bdatb":[[0,9,7.78]],"id":43885158}]}]}
{"op":"mcm","clk":"AOmCAQDxRAD3dA==","pt":1659347647021,"mc":[{"id":"1.201590187","rc":[{"atb":[[7.2,17.25]],"id":44836671},{"atl":[[10.5,1.15]],"id":43885158}]}]}
{"op":"mcm","clk":"AOmCAQDyRAD4dA==","pt":1659347647071,"mc":[{"id":"1.201590187","rc":[{"bdatb":[[5,11.5,5.75],[6,11,1.33],[7,10.5,1.76],[8,10,10.84]],"id":45323444},{"bdatb":[[3,1.99,1.26],[4,1.98,41.76],[5,1.97,2.53],[6,1.96,21.69],[7,1.94,6.43],[8,1.93,4.95],[9,1.91,107.36]],"bdatl":[[6,2.28,6.14],[7,2.3,7.8],[8,2.32,10.95],[9,2.34,4.65]],"id":9570503},{"bdatb":[[4,5.9,2.19],[5,5.8,1.95],[7,5.6,1.76],[8,5.5,3.3],[9,5.4,6.92]],"id":12989514},{"bdatb":[[7,19,1.9],[9,15.5,4.8]],"id":44621159},{"bdatb":[[0,7.2,17.25],[1,7,13.53],[2,6.8,5.36],[3,6.6,13.17],[4,6.4,2.13],[5,6.2,26.37],[6,6,29.74],[7,5.9,10.43],[8,5.8,10],[9,5.7,51.11]],"id":44836671},{"bdatl":[[0,10.5,1.15],[1,11,3.4],[2,11.5,2.88],[3,12,7.42],[4,12.5,13.48],[5,13,1.76],[6,13.5,1.76],[7,14,13.2],[8,14.5,2.76],[9,15,12]],"id":43885158}]}]}
{"op":"mcm","clk":"AO6CAQD1RAD9dA==","pt":1659347647124,"mc":[{"id":"1.201590187","rc":[{"atb":[[9.4,54.1],[13.5,0.18]],"id":45323444},{"atb":[[11,34.48]],"id":44621159}]}]}
{"op":"mcm","clk":"APGCAQD2RACBdQ==","pt":1659347647174,"mc":[{"id":"1.201590187","rc":[{"bdatb":[[1,13,2.13],[2,12.5,4.01],[3,12,7.26],[4,11.5,5.75],[5,11,1.33],[6,10.5,1.76],[7,10,10.84],[8,9.8,9],[9,9.6,24.89]],"id":45323444},{"bdatl":[[7,2.3,1.06],[9,2.34,11.28]],"id":9570503}]}]}
{"op":"mcm","clk":"APiCAQD5RACFdQ==","pt":1659347647238,"mc":[{"id":"1.201590187","rc":[{"atl":[[7.4,0]],"id":44836671},{"atl":[[10.5,1.4]],"id":43885158}]}]}
{"op":"mcm","clk":"AP6CAQD6RACJdQ==","pt":1659347647288,"mc":[{"id":"1.201590187","rc":[{"bdatb":[[4,11.5,5.54],[5,11,1.56],[7,10,11.11]],"id":45323444},{"bdatb":[[3,1.98,44.35],[4,1.97,2.53],[5,1.96,21.69],[6,1.94,5.08],[7,1.93,4.95],[8,1.91,107.36],[9,1.89,10.84]],"id":9570503},{"bdatb":[[4,5.9,1.76],[5,5.8,2.39],[8,5.5,3.78]],"id":12989514},{"bdatb":[[7,19,1.76],[9,15.5,5.11]],"id":44621159},{"bdatb":[[7,5.9,10.88]],"bdatl":[[0,7.6,152.65]],"id":44836671},{"bdatl":[[0,10.5,1.4]],"id":43885158}]}]}
{"op":"mcm","clk":"AI6DAQCBRQCWdQ==","pt":1659347647503,"mc":[{"id":"1.201590187","rc":[{"atb":[[24,2.29]],"id":44621159},{"atl":[[11,1.4]],"id":43885158}]}]}
{"op":"mcm","clk":"AI6DAQCDRQCWdQ==","pt":1659347647553,"mc":[{"id":"1.201590187","rc":[{"bdatb":[[9,9.6,22.6]],"id":45323444},{"bdatb":[[5,1.96,10.47],[6,1.94,16.42],[7,1.93,4.16],[8,1.91,108.15],[9,1.88,18.3]],"id":9570503},{"bdatb":[[9,5.4,2.85]],"id":12989514},{"bdatb":[[1,24,2.29]],"id":44621159},{"bdatb":[[9,5.7,47.25]],"id":44836671},{"bdatl":[[1,11,1.4]],"id":43885158}]}]}
{"op":"mcm","clk":"AJqDAQCFRQCadQ==","pt":1659347647697,"mc":[{"id":"1.201590187","rc":[{"atb":[[25,3.3]],"id":44621159}]}]}
{"op":"mcm","clk":"AJ2DAQCFRQCddQ==","pt":1659347647748,"mc":[{"id":"1.201590187","rc":[{"bdatl":[[9,2.34,12.05]],"id":9570503},{"bdatb":[[0,25,3.4]],"id":44621159}]}]}
{"op":"mcm","clk":"AKODAQCHRQCgdQ==","pt":1659347647814,"mc":[{"id":"1.201590187","rc":[{"atb":[[9.4,45.48]],"id":45323444},{"atb":[[3.9,44.48]],"id":12989514},{"atb":[[5.6,46.48]],"atl":[[7.8,0.34]],"id":44836671},{"atb":[[8.8,34.48]],"id":46969227}]}]}
{"op":"mcm","clk":"AKODAQCHRQCidQ==","pt":1659347647865,"mc":[{"id":"1.201590187","rc":[{"bdatl":[[1,8,2.42],[2,8.2,2.07],[3,8.4,3],[4,8.6,1.76],[5,8.8,1.76],[6,9.2,8],[7,9.8,33.55],[8,11.5,13.42],[9,12,1.6]],"id":44836671}]}]}
{"op":"mcm","clk":"ALSDAQCKRQCxdQ==","pt":1659347648116,"mc":[{"id":"1.201590187","rc":[{"atb":[[13.5,1.94]],"atl":[[19,1.76]],"id":45323444},{"atb":[[2.02,24.75]],"id":9570503},{"atb":[[5.3,1.76]],"atl":[[9.2,1.76]],"id":12989514},{"atb":[[6.6,4.61]],"atl":[[9,1.76]],"id":44836671}]}]}
{"op":"mcm","clk":"ALaDAQCLRQCzdQ==","pt":1659347648166,"mc":[{"id":"1.201590187","rc":[{"bdatb":[[1,13.5,1.94],[2,13,1.95],[3,12.5,4.01],[4,12,7.26],[5,11.5,5.54],[6,11,1.56],[7,10.5,1.76],[8,10,11.11],[9,9.8,9]],"bdatl":[[1,19,1.76],[2,19.5,1.76],[3,20,1],[4,21,1.89],[5,22,2.72],[6,23,1.76],[7,25,6.09],[8,26,5.04],[9,27,3.85]],"id":45323444},{"bdatb":[[1,2.02,24.75],[9,1.89,3.36]],"bdatl":[[7,2.3,11.41],[9,2.34,1.87]],"id":9570503},{"bdatb":[[3,6.6,4.61]],"bdatl":[[6,9,1.76],[7,9.2,8],[8,9.8,33.55],[9,11.5,13.42]],"id":44836671},{"bdatb":[[9,6.8,4.93]],"id":43885158}]}]}
{"op":"mcm","clk":"AMaDAQCRRQC/dQ==","pt":1659347648388,"mc":[{"id":"1.201590187","rc":[{"atb":[[6.6,9.61]],"id":44836671}]}]}
{"op":"mcm","clk":"AMaDAQCRRQDCdQ==","pt":1659347648438,"mc":[{"id":"1.201590187","rc":[{"bdatb":[[3,6.6,9.61]],"id":44836671}]}]}
{"op":"mcm","clk":"AMiDAQCURQDFdQ==","pt":1659347648495,"mc":[{"id":"1.201590187","rc":[{"atb":[[2.02,24.5]],"atl":[[2.14,77.96]],"id":9570503},{"atb":[[6.6,11.37],[6.4,12.19]],"atl":[[7.8,4.52],[7.4,10.76]],"id":12989514},{"atb":[[25,1]],"id":44621159},{"atb":[[6.6,7.16],[7,15.83]],"atl":[[7.6,150.34],[8,4.48]],"id":44836671},{"atb":[[7.4,2.32],[9,2.03],[8,3.86]],"id":43885158}]}]}
{"op":"mcm","clk":"AMyDAQCVRQDKdQ==","pt":1659347648545,"mc":[{"id":"1.201590187","rc":[{"bdatb":[[1,2.02,24.5]],"bdatl":[[1,2.14,77.96],[7,2.3,1.87],[8,2.32,9.46],[9,2.34,9.04]],"id":9570503},{"bdatb":[[0,6.6,11.37],[1,6.4,12.19]],"bdatl":[[2,7.4,10.76],[4,7.8,4.52]],"id":12989514},{"bdatb":[[0,25,1.1]],"id":44621159},{"bdatb":[[1,7,15.83],[3,6.6,7.16]],"bdatl":[[0,7.6,150.34],[1,8,4.82]],"id":44836671},{"bdatb":[[0,9,2.03],[3,8,4.31],[6,7.4,9.74]],"id":43885158}]}]}
{"op":"mcm","clk":"AM6DAQCZRQDLdQ==","pt":1659347648600,"mc":[{"id":"1.201590187","rc":[{"atb":[[24,4.71]],"id":44621159},{"atl":[[8,7.48]],"id":44836671},{"atb":[[9,1.76]],"id":43885158}]}]}
{"op":"mcm","clk":"ANWDAQCdRQDRdQ==","pt":1659347648650,"mc":[{"id":"1.201590187","rc":[{"bdatl":[[7,2.32,11.32],[8,2.34,8],[9,2.36,2.83]],"id":9570503},{"bdatb":[[1,24,4.71]],"id":44621159},{"bdatl":[[1,8,7.82]],"id":44836671},{"bdatb":[[0,9,1.76]],"id":43885158}]}]}
{"op":"mcm","clk":"AOyDAQCkRQDkdQ==","pt":1659347648923,"mc":[{"id":"1.201590187","rc":[{"atb":[[13.5,0.18]],"id":45323444}]}]}
{"op":"mcm","clk":"AO2DAQCmRQDndQ==","pt":1659347648973,"mc":[{"id":"1.201590187","rc":[{"bdatb":[[1,13,2.13],[2,12.5,4.01],[3,12,7.26],[4,11.5,5.54],[5,11,1.56],[6,10.5,1.76],[7,10,11.11],[8,9.8,9],[9,9.6,22.6]],"id":45323444},{"bdatl":[[7,2.32,5.88],[8,2.34,6.08],[9,2.36,7.26]],"id":9570503}]}]}
{"op":"mcm","clk":"AIiEAQCuRQD6dQ==","pt":1659347649288,"mc":[{"id":"1.201590187","rc":[{"atb":[[24,2.29]],"id":44621159}]}]}
{"op":"mcm","clk":"AJCEAQCxRQCEdg==","pt":1659347649338,"mc":[{"id":"1.201590187","rc":[{"bdatb":[[1,24,2.29]],"id":44621159}]}]}
{"op":"mcm","clk":"AJaEAQCzRQCFdg==","pt":1659347649396,"mc":[{"id":"1.201590187","rc":[{"atl":[[7.6,7.34]],"id":12989514},{"atb":[[25,3.3]],"id":44621159}]}]}
{"op":"mcm","clk":"AJmEAQC0RQCKdg==","pt":1659347649446,"mc":[{"id":"1.201590187","rc":[{"bdatl":[[7,2.32,12.01],[8,2.34,7.32],[9,2.38,6.23]],"id":9570503},{"bdatl":[[3,7.6,7.34]],"id":12989514},{"bdatb":[[0,25,3.4]],"id":44621159}]}]}
{"op":"mcm","clk":"AJyEAQC1RQCMdg==","pt":1659347649502,"mc":[{"id":"1.201590187","rc":[{"atb":[[13.5,1.94]],"atl":[[18.5,1.76]],"id":45323444},{"atl":[[9.4,1.76]],"id":44836671}]}]}
{"op":"mcm","clk":"AKOEAQC3RQCRdg==","pt":1659347649552,"mc":[{"id":"1.201590187","rc":[{"bdatb":[[1,13.5,1.94],[2,13,1.95],[3,12.5,4.01],[4,12,7.26],[5,11.5,5.54],[6,11,1.56],[7,10.5,1.76],[8,10,11.11],[9,9.8,9]],"bdatl":[[1,18.5,1.76],[2,19,1.76],[3,19.5,1.76],[4,20,1],[5,21,1.89],[6,22,2.72],[7,23,1.76],[8,25,6.09],[9,26,5.04]],"id":45323444},{"bdatb":[[9,1.89,17.27]],"bdatl":[[7,2.32,19.39],[8,2.36,2.83],[9,2.38,3.42]],"id":9570503},{"bdatl":[[8,9.4,1.76],[9,9.8,33.55]],"id":44836671},{"bdatb":[[9,6.8,5.82]],"id":43885158}]}]}
{"op":"mcm","clk":"AL2EAQDFRQCwdg==","pt":1659347649978,"mc":[{"id":"1.201590187","rc":[{"atb":[[13.5,0.18]],"id":45323444}]}]}
{"op":"mcm","clk":"AMOEAQDHRQCydg==","pt":1659347650029,"mc":[{"id":"1.201590187","rc":[{"bdatb":[[1,13,2.13],[2,12.5,4.01],[3,12,7.26],[4,11.5,5.54],[5,11,1.56],[6,10.5,1.76],[7,10,11.11],[8,9.8,9],[9,9.6,22.6]],"id":45323444},{"bdatl":[[7,2.32,12.01],[8,2.34,7.32],[9,2.38,6.23]],"id":9570503}]}]}
{"op":"mcm","clk":"AMaEAQDKRQCzdg==","pt":1659347650083,"mc":[{"id":"1.201590187","rc":[{"atb":[[25,1]],"id":44621159}]}]}
{"op":"mcm","clk":"AM2EAQDLRQC3dg==","pt":1659347650134,"mc":[{"id":"1.201590187","rc":[{"bdatl":[[7,2.32,5.88],[8,2.34,6.08],[9,2.36,7.26]],"id":9570503},{"bdatb":[[0,25,1.1]],"id":44621159}]}]}
{"op":"mcm","clk":"ANaEAQDLRQC5dg==","pt":1659347650184,"mc":[{"id":"1.201590187","rc":[{"atb":[[6.2,13.94],[6.4,7.69]],"id":12989514}]}]}
{"op":"mcm","clk":"ANaEAQDMRQC6dg==","pt":1659347650235,"mc":[{"id":"1.201590187","rc":[{"bdatb":[[1,6.4,7.69],[2,6.2,13.94]],"id":12989514}]}]}
{"op":"mcm","clk":"ANuEAQDORQC7dg==","pt":1659347650285,"mc":[{"id":"1.201590187","rc":[{"atb":[[24,4.71]],"id":44621159}]}]}
{"op":"mcm","clk":"AOCEAQDORQDAdg==","pt":1659347650342,"mc":[{"id":"1.201590187","rc":[{"bdatb":[[1,24,4.71]],"id":44621159}]}]}
{"op":"mcm","clk":"AO2EAQDTRQDHdg==","pt":1659347650498,"mc":[{"id":"1.201590187","rc":[{"atb":[[2.02,28.61]],"atl":[[2.14,81.86]],"id":9570503},{"atb":[[6.4,10.17]],"atl":[[7.4,12.97]],"id":12989514},{"atb":[[7,18.28]],"atl":[[8,9.74]],"id":44836671},{"atb":[[8,6.23]],"id":43885158}]}]}
{"op":"mcm","clk":"APOEAQDVRQDJdg==","pt":1659347650548,"mc":[{"id":"1.201590187","rc":[{"bdatb":[[1,2.02,28.61]],"bdatl":[[1,2.14,81.86]],"id":9570503},{"bdatb":[[1,6.4,10.17]],"bdatl":[[2,7.4,12.97]],"id":12989514},{"bdatb":[[1,7,18.28]],"bdatl":[[1,8,10.08]],"id":44836671},{"bdatb":[[3,8,6.68]],"id":43885158}]}]}
{"op":"mcm","clk":"AIaFAQDhRQDbdg==","pt":1659347650814,"mc":[{"id":"1.201590187","rc":[{"atb":[[13.5,1.94]],"id":45323444},{"atl":[[9.6,1.76]],"id":44836671}]}]}
{"op":"mcm","clk":"AImFAQDiRQDedg==","pt":1659347650864,"mc":[{"id":"1.201590187","rc":[{"bdatb":[[1,13.5,1.94],[2,13,1.95],[3,12.5,4.01],[4,12,7.26],[5,11.5,5.54],[6,11,1.56],[7,10.5,1.76],[8,10,11.11],[9,9.8,9]],"id":45323444},{"bdatl":[[7,2.32,11.32],[8,2.34,8],[9,2.36,2.83]],"id":9570503},{"bdatl":[[9,9.6,1.76]],"id":44836671}]}]}
{"op":"mcm","clk":"AJeFAQDpRQDldg==","pt":1659347651026,"mc":[{"id":"1.201590187","rc":[{"atb":[[24,2.29]],"id":44621159}]}]}
{"op":"mcm","clk":"AJuFAQDtRQDodg==","pt":1659347651076,"mc":[{"id":"1.201590187","rc":[{"bdatb":[[1,24,2.29]],"id":44621159}]}]}
{"op":"mcm","clk":"AJ6FAQDuRQDsdg==","pt":1659347651126,"mc":[{"id":"1.201590187","rc":[{"atb":[[7.4,2]],"id":44836671}]}]}
{"op":"mcm","clk":"AJ+FAQDwRQDydg==","pt":1659347651176,"mc":[{"id":"1.201590187","rc":[{"atb":[[25,3.3]],"id":44621159},{"atb":[[7.4,0]],"trd":[[7.4,55.23]],"bdatb":[[0,7.4,2],[1,7.2,17.25],[2,7,18.28],[3,6.8,5.36],[4,6.6,7.16],[5,6.4,2.13],[6,6.2,26.37],[7,6,29.74],[8,5.9,10.88],[9,5.8,10]],"ltp":7.4,"tv":223.42,"id":44836671},{"bdatl":[[6,2.26,6.19]],"id":9570503}],"tv":1433.6}]}
{"op":"mcm","clk":"AKOFAQDxRQD1dg==","pt":1659347651226,"mc":[{"id":"1.201590187","rc":[{"bdatl":[[6,2.28,6.14],[7,2.32,19.39],[8,2.36,2.83],[9,2.38,3.42]],"id":9570503},{"bdatb":[[0,25,3.4]],"id":44621159},{"bdatb":[[0,7.2,17.25],[1,7,18.28],[2,6.8,5.36],[3,6.6,7.16],[4,6.4,2.13],[5,6.2,26.37],[6,6,29.74],[7,5.9,10.88],[8,5.8,10],[9,5.7,47.25]],"id":44836671}]}]}
{"op":"mcm","clk":"AK6FAQDzRQD5dg==","pt":1659347651294,"mc":[{"id":"1.201590187","rc":[{"atb":[[6.4,1.76],[7.2,17.6]],"id":44836671}]}]}
{"op":"mcm","clk":"AK+FAQDzRQD9dg==","pt":1659347651344,"mc":[{"id":"1.201590187","rc":[{"bdatb":[[0,7.2,17.6],[4,6.4,1.76]],"id":44836671}]}]}
{"op":"mcm","clk":"ALyFAQD3RQCJdw==","pt":1659347651586,"mc":[{"id":"1.201590187","rc":[{"atb":[[13.5,0.18]],"id":45323444}]}]}
{"op":"mcm","clk":"AMGFAQD4RQCNdw==","pt":1659347651636,"mc":[{"id":"1.201590187","rc":[{"bdatb":[[1,13,2.13],[2,12.5,4.01],[3,12,7.26],[4,11.5,5.54],[5,11,1.56],[6,10.5,1.76],[7,10,11.11],[8,9.8,9],[9,9.6,22.6]],"id":45323444},{"bdatl":[[7,2.32,12.01],[8,2.34,7.32],[9,2.38,6.23]],"id":9570503}]}]}
{"op":"mcm","clk":"AMyFAQD9RQCYdw==","pt":1659347651803,"mc":[{"id":"1.201590187","rc":[{"atl":[[13.5,9.76]],"id":43885158}]}]}
{"op":"mcm","clk":"AM6FAQD+RQCadw==","pt":1659347651854,"mc":[{"id":"1.201590187","rc":[{"bdatl":[[6,13.5,9.76]],"id":43885158}]}]}
{"op":"mcm","clk":"ANmFAQCARgCjdw==","pt":1659347652003,"mc":[{"id":"1.201590187","rc":[{"atb":[[25,1]],"id":44621159}]}]}
{"op":"mcm","clk":"AN6FAQCDRgCldw==","pt":1659347652053,"mc":[{"id":"1.201590187","rc":[{"bdatl":[[7,2.32,5.88],[8,2.34,6.08],[9,2.36,7.26]],"id":9570503},{"bdatb":[[0,25,1.1]],"id":44621159}]}]}
{"op":"mcm","clk":"AOaFAQCFRgCodw==","pt":1659347652120,"mc":[{"id":"1.201590187","rc":[{"atb":[[1.75,51.72]],"id":9570503},{"atb":[[24,4.71]],"id":44621159},{"atb":[[1.8,2.88],[5.6,63.72]],"id":44836671}]}]}
{"op":"mcm","clk":"AOeFAQCGRgCsdw==","pt":1659347652171,"mc":[{"id":"1.201590187","rc":[{"bdatb":[[1,24,4.71]],"id":44621159}]}]}
{"op":"mcm","clk":"AO2FAQCHRgCwdw==","pt":1659347652223,"mc":[{"id":"1.201590187","rc":[{"atb":[[9.4,62.72]],"id":45323444},{"atb":[[3.9,61.72]],"id":12989514},{"atb":[[6,65.72]],"id":43885158}]}]}
{"op":"mcm","clk":"APaFAQCMRgC2dw==","pt":1659347652322,"mc":[{"id":"1.201590187","rc":[{"atb":[[13.5,1.94]],"id":45323444},{"atl":[[2.1,0.88]],"trd":[[2.1,50.96]],"ltp":2.1,"tv":886.68,"id":9570503}],"tv":1435.28}]}
{"op":"mcm","clk":"APeFAQCORgC3dw==","pt":1659347652372,"mc":[{"id":"1.201590187","rc":[{"bdatb":[[1,13.5,1.94],[2,13,1.95],[3,12.5,4.01],[4,12,7.26],[5,11.5,5.54],[6,11,1.4],[7,10.5,1.76],[8,10,11.28],[9,9.8,9]],"id":45323444},{"bdatl":[[0,2.14,82.74],[1,2.16,9.18],[2,2.18,6.18],[3,2.2,4],[4,2.22,4],[5,2.28,6.14],[6,2.32,11.32],[7,2.34,8],[8,2.36,2.83],[9,2.38,1.09]],"id":9570503},{"bdatb":[[5,5.8,2.08],[8,5.5,4.1]],"id":12989514},{"bdatb":[[9,15.5,5.12]],"id":44621159},{"bdatb":[[5,6.2,26.09],[7,5.9,11.18]],"id":44836671},{"bdatb":[[3,8,6.46],[6,7.4,9.98]],"id":43885158}]}]}
{"op":"mcm","clk":"AP2FAQCPRgC4dw==","pt":1659347652427,"mc":[{"id":"1.201590187","rc":[{"atb":[[8.8,48.84]],"id":46969227}]}]}
{"op":"mcm","clk":"AIaGAQCQRgC9dw==","pt":1659347652494,"mc":[{"id":"1.201590187","rc":[{"atb":[[1.8,0.01]],"id":44836671}]}]}
{"op":"mcm","clk":"AJaGAQCYRgDadw==","pt":1659347652973,"mc":[{"id":"1.201590187","rc":[{"bdatl":[[3,12,6.99]],"id":43885158}]}]}
{"op":"mcm","clk":"AK2GAQCbRgDgdw==","pt":1659347653023,"mc":[{"id":"1.201590187","rc":[{"atb":[[1.8,0]],"atl":[[7.6,150.33]],"trd":[[7.6,2.94]],"ltp":7.6,"tv":223.44,"id":44836671},{"atl":[[1000,0.43],[12,6.99]],"id":43885158}],"con":true,"tv":1435.3}]}
{"op":"mcm","clk":"AK2GAQCbRgDgdw==","pt":1659347653073,"mc":[{"id":"1.201590187","rc":[{"bdatl":[[0,7.6,150.33]],"id":44836671}]}]}
{"op":"mcm","clk":"ALSGAQCcRgDkdw==","pt":1659347653123,"mc":[{"id":"1.201590187","rc":[{"atb":[[13.5,0.18]],"id":45323444}]}]}
{"op":"mcm","clk":"ALSGAQCdRgDldw==","pt":1659347653173,"mc":[{"id":"1.201590187","rc":[{"bdatb":[[1,13,2.13],[2,12.5,4.01],[3,12,7.26],[4,11.5,5.54],[5,11,1.4],[6,10.5,1.76],[7,10,11.28],[8,9.8,9],[9,9.6,22.6]],"id":45323444},{"bdatl":[[6,2.32,5.88],[7,2.34,6.08],[8,2.36,7.26],[9,2.38,3.9]],"id":9570503}]}]}
{"op":"mcm","clk":"AMuGAQCjRgDxdw==","pt":1659347653432,"mc":[{"id":"1.201590187","rc":[{"atb":[[1.71,0],[1.78,33.55]],"id":9570503},{"atb":[[4.9,73.82],[4.6,0]],"id":12989514},{"atb":[[24,2.29]],"id":44621159},{"atb":[[5.4,14]],"id":44836671},{"atl":[[19,0],[18,1],[17,18]],"id":43885158}]}]}
{"op":"mcm","clk":"AM2GAQCjRgD0dw==","pt":1659347653482,"mc":[{"id":"1.201590187","rc":[{"bdatb":[[1,24,2.29]],"id":44621159}]}]}
{"op":"mcm","clk":"ANGGAQCkRgD5dw==","pt":1659347653533,"mc":[{"id":"1.201590187","rc":[{"atb":[[13.5,1.33]],"id":45323444},{"atb":[[4.9,25.64]],"id":44836671}]}]}
{"op":"mcm","clk":"ANSGAQClRgD8dw==","pt":1659347653583,"mc":[{"id":"1.201590187","rc":[{"bdatb":[[1,13.5,1.33],[2,13,1.95],[3,12.5,4.01],[4,12,7.26],[5,11.5,5.54],[6,11,1.4],[7,10.5,1.76],[8,10,11.28],[9,9.8,9]],"id":45323444},{"bdatl":[[6,2.32,7.75],[7,2.34,10.86],[8,2.38,4.58],[9,2.4,73.74]],"id":9570503}]}]}
{"op":"mcm","clk":"ANmGAQClRgD9dw==","pt":1659347653633,"mc":[{"id":"1.201590187","rc":[{"atb":[[25,3.3]],"id":44621159}]}]}
{"op":"mcm","clk":"ANuGAQClRgCBeA==","pt":1659347653684,"mc":[{"id":"1.201590187","rc":[{"bdatl":[[6,2.32,18.7],[7,2.38,6.92],[8,2.4,71.43],[9,2.44,156.72]],"id":9570503},{"bdatb":[[0,25,3.4]],"id":44621159}]}]}
{"op":"mcm","clk":"AOOGAQClRgCEeA==","pt":1659347653735,"mc":[{"id":"1.201590187","rc":[{"atb":[[13.5,3.09]],"bdatb":[[1,13.5,3.09],[8,10,10.08]],"id":45323444},{"atb":[[1.95,1.76]],"bdatb":[[3,1.98,38.26],[6,1.95,1.76],[7,1.94,18.81],[8,1.93,5.62],[9,1.92,3.2]],"bdatl":[[6,2.32,19.39],[7,2.36,3.93],[8,2.38,2.33],[9,2.4,71.96]],"id":9570503},{"atl":[[10.5,0.25]],"bdatl":[[0,11,1.65],[1,11.5,2.88],[2,12,6.99],[3,12.5,13.48],[4,13,1.76],[5,13.5,9.76],[6,14,13.2],[7,14.5,2.76],[8,15,12],[9,15.5,2.76]],"id":43885158},{"bdatb":[[8,5.5,1.9]],"id":12989514},{"bdatb":[[9,15.5,4.34]],"id":44621159},{"bdatb":[[7,5.9,9.13]],"id":44836671}]}]}
{"op":"mcm","clk":"AOuGAQCmRgCLeA==","pt":1659347653893,"mc":[{"id":"1.201590187","rc":[{"atb":[[2.02,25.87]],"id":9570503}]}]}
{"op":"mcm","clk":"APGGAQCoRgCNeA==","pt":1659347653943,"mc":[{"id":"1.201590187","rc":[{"bdatb":[[1,2.02,25.87]],"id":9570503}]}]}
{"op":"mcm","clk":"AI6HAQC5RgCgeA==","pt":1659347654408,"mc":[{"id":"1.201590187","rc":[{"atb":[[13.5,1.33]],"id":45323444},{"atb":[[25,1]],"id":44621159}]}]}
{"op":"mcm","clk":"AJKHAQC6RgCieA==","pt":1659347654459,"mc":[{"id":"1.201590187","rc":[{"bdatb":[[1,13.5,1.33]],"id":45323444},{"bdatl":[[6,2.32,7.75],[7,2.34,10.86],[8,2.38,4.58],[9,2.4,73.74]],"id":9570503},{"bdatb":[[0,25,1.1]],"id":44621159}]}]}
{"op":"mcm","clk":"AJyHAQC/RgCneA==","pt":1659347654625,"mc":[{"id":"1.201590187","rc":[{"atb":[[24,4.71]],"id":44621159}]}]}
{"op":"mcm","clk":"AJ2HAQDARgCpeA==","pt":1659347654675,"mc":[{"id":"1.201590187","rc":[{"bdatb":[[1,24,4.71]],"id":44621159}]}]}
{"op":"mcm","clk":"ALaHAQDJRgDAeA==","pt":1659347655091,"mc":[{"id":"1.201590187","rc":[{"atl":[[2.16,13.18]],"id":9570503},{"atb":[[8.2,1.76]],"id":43885158}]}]}
{"op":"mcm","clk":"ALqHAQDKRgDCeA==","pt":1659347655141,"mc":[{"id":"1.201590187","rc":[{"bdatl":[[1,2.16,13.18]],"id":9570503},{"bdatb":[[3,8.2,1.76],[4,8,6.46],[5,7.8,1.26],[6,7.6,4.53],[7,7.4,9.98],[8,7.2,4.56],[9,7,130]],"id":43885158}]}]}
{"op":"mcm","clk":"AMmHAQDURgDTeA==","pt":1659347655393,"mc":[{"id":"1.201590187","rc":[{"atl":[[20,0]],"id":45323444},{"atl":[[38,2.87]],"id":44621159}]}]}
{"op":"mcm","clk":"AM2HAQDURgDVeA==","pt":1659347655446,"mc":[{"id":"1.201590187","rc":[{"bdatl":[[4,21,1.89],[5,22,2.72],[6,23,1.76],[7,25,6.09],[8,26,5.04],[9,27,3.85]],"id":45323444},{"bdatl":[[0,38,2.87]],"id":44621159}]}]}
{"op":"mcm","clk":"ANGHAQDVRgDXeA==","pt":1659347655504,"mc":[{"id":"1.201590187","rc":[{"atb":[[14,0]],"id":45323444},{"atl":[[38,1.87]],"id":44621159}]}]}
{"op":"mcm","clk":"ANKHAQDWRgDbeA==","pt":1659347655556,"mc":[{"id":"1.201590187","rc":[{"bdatb":[[0,13.5,1.33],[1,13,1.95],[2,12.5,4.01],[3,12,7.26],[4,11.5,5.54],[5,11,1.4],[6,10.5,1.76],[7,10,10.08],[8,9.8,9],[9,9.6,22.6]],"id":45323444},{"bdatl":[[5,2.3,6.9],[6,2.32,5.06],[7,2.34,6.72],[8,2.36,6.62],[9,2.38,3.9]],"id":9570503},{"bdatl":[[0,38,1.87]],"id":44621159}]}]}
{"op":"mcm","clk":"AOWHAQDcRgDueA==","pt":1659347655830,"mc":[{"id":"1.201590187","rc":[{"atb":[[24,2.29]],"id":44621159}]}]}
{"op":"mcm","clk":"AOaHAQDcRgDweA==","pt":1659347655880,"mc":[{"id":"1.201590187","rc":[{"bdatb":[[1,24,2.29]],"id":44621159}]}]}
{"op":"mcm","clk":"AO2HAQDfRgD1eA==","pt":1659347655930,"mc":[{"id":"1.201590187","rc":[{"atb":[[1.08,1]],"id":43885158}]}]}
{"op":"mcm","clk":"APWHAQDhRgD6eA==","pt":1659347656028,"mc":[{"id":"1.201590187","rc":[{"atb":[[25,3.3]],"id":44621159},{"atb":[[1.08,0.11]],"id":43885158}]}]}
{"op":"mcm","clk":"APeHAQDhRgD9eA==","pt":1659347656078,"mc":[{"id":"1.201590187","rc":[{"bdatl":[[6,2.32,11.84],[7,2.34,6.67],[8,2.38,6.23],[9,2.4,71.96]],"id":9570503},{"bdatb":[[0,25,3.4]],"id":44621159}]}]}
{"op":"mcm","clk":"AP2HAQDjRgD/eA==","pt":1659347656128,"mc":[{"id":"1.201590187","rc":[{"atb":[[2.02,28.23],[2,23.58]],"id":9570503},{"atb":[[6.8,7.36]],"id":44836671},{"atb":[[1.08,0]],"id":43885158}]}]}
{"op":"mcm","clk":"AP6HAQDlRgCBeQ==","pt":1659347656178,"mc":[{"id":"1.201590187","rc":[{"bdatb":[[1,2.02,28.23],[2,2,23.58]],"id":9570503},{"bdatb":[[2,6.8,7.36]],"id":44836671}]}]}
{"op":"mcm","clk":"AP+HAQDmRgCDeQ==","pt":1659347656228,"mc":[{"id":"1.201590187","rc":[{"atb":[[9.2,0.11]],"bdatb":[[0,9,1.87]],"id":43885158},{"bdatl":[[5,2.3,7.34],[6,2.32,11.4],[7,2.34,7.1],[9,2.4,71.54]],"id":9570503}]}]}
{"op":"mcm","clk":"AI2IAQDnRgCKeQ==","pt":1659347656344,"mc":[{"id":"1.201590187","rc":[{"atb":[[8.8,5.17]],"id":43885158}]}]}
{"op":"mcm","clk":"AI+IAQDqRgCReQ==","pt":1659347656394,"mc":[{"id":"1.201590187","rc":[{"atb":[[1.99,1.76]],"bdatl":[[7,2.34,8.12],[8,2.38,5.33],[9,2.4,71.43]],"id":9570503},{"atb":[[7.8,0.96]],"bdatb":[[1,8.8,5.17]],"id":43885158}]}]}
{"op":"mcm","clk":"AJGIAQDrRgCReQ==","pt":1659347656444,"mc":[{"id":"1.201590187","rc":[{"bdatb":[[3,1.99,1.76],[4,1.98,38.26],[5,1.97,2.53],[6,1.96,10.47],[7,1.95,1.76],[8,1.94,18.81],[9,1.93,5.62]],"id":9570503},{"bdatb":[[5,7.6,5.49],[6,7.4,9.98],[7,7.2,4.56],[8,7,130],[9,6.8,5.82]],"id":43885158}]}]}
{"op":"mcm","clk":"AKSIAQDzRgCjeQ==","pt":1659347656804,"mc":[{"id":"1.201590187","rc":[{"atb":[[2.1,19.12]],"atl":[[2.1,0]],"trd":[[2.1,52.73]],"tv":888.45,"id":9570503}],"tv":1437.07}]}
{"op":"mcm","clk":"AKaIAQD1RgCneQ==","pt":1659347656854,"mc":[{"id":"1.201590187","rc":[{"bdatb":[[5,11,1.23],[7,10,10.26]],"bdatl":[[8,26,5.08]],"id":45323444},{"bdatb":[[0,2.1,19.12],[1,2.04,7.94],[2,2.02,28.23],[3,2,23.58],[4,1.99,1.76],[5,1.98,38.26],[6,1.97,2.53],[7,1.96,10.47],[8,1.95,1.76],[9,1.94,18.81]],"bdatl":[[0,2.14,81.86]],"id":9570503},{"bdatb":[[5,5.8,1.76],[8,5.5,2.24]],"bdatl":[[9,8.8,2.06]],"id":12989514},{"bdatb":[[9,15.5,4.36]],"id":44621159},{"bdatb":[[5,6.2,25.79],[7,5.9,9.44]],"id":44836671},{"bdatb":[[4,8,6.23],[6,7.4,10.23]],"bdatl":[[6,14,14.48],[8,15,13.48]],"id":43885158}]}]}
{"op":"mcm","clk":"AKmIAQD2RgCseQ==","pt":1659347656906,"mc":[{"id":"1.201590187","rc":[{"atl":[[25,4.17]],"id":45323444},{"atb":[[2.1,0]],"trd":[[2.1,90.97]],"tv":926.69,"id":9570503},{"atb":[[7.6,0]],"id":43885158}],"tv":1475.31}]}
{"op":"mcm","clk":"AK6IAQD2RgCteQ==","pt":1659347656956,"mc":[{"id":"1.201590187","rc":[{"bdatl":[[7,25,4.65],[8,26,5.04]],"id":45323444},{"bdatb":[[0,2.04,7.94],[1,2.02,28.23],[2,2,23.58],[3,1.99,1.76],[4,1.98,38.26],[5,1.97,2.53],[6,1.96,10.47],[7,1.95,1.76],[8,1.94,18.81],[9,1.93,5.62]],"id":9570503},{"bdatl":[[9,8.8,1.76]],"id":12989514},{"bdatb":[[5,7.4,11.19],[6,7.2,4.56],[7,7,130],[8,6.8,5.82],[9,6.6,17.3]],"bdatl":[[6,14,13.2],[8,15,12]],"id":43885158}]}]}
{"op":"mcm","clk":"ALCIAQD2RgCyeQ==","pt":1659347657006,"mc":[{"id":"1.201590187","rc":[{"atl":[[24,1.92]],"id":45323444},{"atl":[[2.16,5.18],[2.2,0],[2.18,1.18],[2.28,8]],"id":9570503},{"atb":[[8.6,4.53]],"id":43885158}]}]}
{"op":"mcm","clk":"ALaIAQD2RgC0eQ==","pt":1659347657056,"mc":[{"id":"1.201590187","rc":[{"bdatl":[[7,24,1.92],[8,25,4.17],[9,26,5.04]],"id":45323444},{"bdatl":[[1,2.16,5.18],[2,2.18,1.18],[3,2.22,4],[4,2.28,8.44],[5,2.3,6.9],[8,2.36,2.49],[9,2.38,2.86]],"id":9570503},{"bdatb":[[2,8.6,4.53],[3,8.4,1.76],[4,8.2,1.76],[5,8,6.23],[6,7.4,11.19],[7,7.2,4.56],[8,7,130],[9,6.8,5.82]],"id":43885158}]}]}
{"op":"mcm","clk":"AL6IAQD5RgC8eQ==","pt":1659347657210,"mc":[{"id":"1.201590187","rc":[{"atb":[[2,11.07]],"atl":[[2.16,4],[2.14,77.96]],"id":9570503}]}]}
{"op":"mcm","clk":"AMSIAQD5RgDDeQ==","pt":1659347657260,"mc":[{"id":"1.201590187","rc":[{"bdatb":[[2,2,11.07]],"bdatl":[[0,2.14,77.96],[1,2.16,4]],"id":9570503}]}]}
{"op":"mcm","clk":"AMWIAQD7RgDFeQ==","pt":1659347657315,"mc":[{"id":"1.201590187","rc":[{"atb":[[25,1]],"id":44621159},{"atb":[[8.6,6.88]],"id":43885158}]}]}
{"op":"mcm","clk":"AMuIAQD9RgDJeQ==","pt":1659347657365,"mc":[{"id":"1.201590187","rc":[{"bdatl":[[6,2.32,4.62],[7,2.34,6.72],[8,2.36,10.55]],"id":9570503},{"bdatb":[[0,25,1.1]],"id":44621159},{"bdatb":[[2,8.6,6.88]],"id":43885158}]}]}
{"op":"mcm","clk":"ANGIAQD9RgDNeQ==","pt":1659347657514,"mc":[{"id":"1.201590187","rc":[{"atb":[[9,7.51]],"id":43885158}]}]}
{"op":"mcm","clk":"ANeIAQCARwDPeQ==","pt":1659347657564,"mc":[{"id":"1.201590187","rc":[{"bdatl":[[5,2.3,7.36],[6,2.32,10.95],[7,2.34,10.64],[8,2.36,2.88],[9,2.4,79.13]],"id":9570503},{"bdatb":[[0,9,7.62]],"id":43885158}]}]}
{"op":"mcm","clk":"ANmIAQCBRwDReQ==","pt":1659347657619,"mc":[{"id":"1.201590187","rc":[{"atb":[[24,4.71]],"id":44621159}]}]}
{"op":"mcm","clk":"AN2IAQCFRwDVeQ==","pt":1659347657669,"mc":[{"id":"1.201590187","rc":[{"bdatb":[[1,24,4.71]],"id":44621159}]}]}
{"op":"mcm","clk":"AN6IAQCFRwDWeQ==","pt":1659347657719,"mc":[{"id":"1.201590187","rc":[{"atb":[[7.8,2.73]],"id":43885158}]}]}
{"op":"mcm","clk":"AOWIAQCFRwDWeQ==","pt":1659347657769,"mc":[{"id":"1.201590187","rc":[{"bdatb":[[6,7.8,2.73],[7,7.4,10.23],[8,7.2,4.56],[9,7,130]],"id":43885158}]}]}
{"op":"mcm","clk":"AIeJAQCbRwDmeQ==","pt":1659347658301,"mc":[{"id":"1.201590187","rc":[{"atb":[[2.02,25.87]],"id":9570503}]}]}
{"op":"mcm","clk":"AIyJAQCbRwDneQ==","pt":1659347658352,"mc":[{"id":"1.201590187","rc":[{"bdatb":[[1,2.02,25.87]],"id":9570503}]}]}
{"op":"mcm","clk":"AJ6JAQCiRwD0eQ==","pt":1659347658624,"mc":[{"id":"1.201590187","rc":[{"atl":[[14.5,13.87]],"id":43885158}]}]}
{"op":"mcm","clk":"AJ6JAQCiRwD2eQ==","pt":1659347658674,"mc":[{"id":"1.201590187","rc":[{"bdatl":[[7,14.5,13.87]],"id":43885158}]}]}
{"op":"mcm","clk":"ALqJAQCsRwCGeg==","pt":1659347659031,"mc":[{"id":"1.201590187","rc":[{"atb":[[24,2.29]],"id":44621159}]}]}
{"op":"mcm","clk":"AL6JAQCuRwCIeg==","pt":1659347659081,"mc":[{"id":"1.201590187","rc":[{"bdatb":[[1,24,2.29]],"id":44621159}]}]}
{"op":"mcm","clk":"AMyJAQC2RwCPeg==","pt":1659347659235,"mc":[{"id":"1.201590187","rc":[{"atb":[[25,3.3]],"id":44621159}]}]}
