{"op":"mcm","clk":"AAAAAAAA","pt":1659347400891,"mc":[{"id":"1.201590187","marketDefinition":{"bspMarket":true,"turnInPlayEnabled":true,"persistenceEnabled":true,"marketBaseRate":5,"eventId":"31628781","eventTypeId":"7","numberOfWinners":1,"bettingType":"ODDS","marketType":"WIN","marketTime":"2022-08-01T10:00:00.000Z","suspendTime":"2022-08-01T10:00:00.000Z","bspReconciled":false,"complete":true,"inPlay":false,"crossMatching":true,"runnersVoidable":false,"numberOfActiveRunners":7,"betDelay":0,"status":"OPEN","runners":[{"adjustmentFactor":3.355,"status":"ACTIVE","sortPriority":1,"id":44621159},{"adjustmentFactor":2.163,"status":"ACTIVE","sortPriority":2,"id":45323444},{"adjustmentFactor":63.661,"status":"ACTIVE","sortPriority":3,"id":9570503},{"adjustmentFactor":13.991,"status":"ACTIVE","sortPriority":4,"id":44836671},{"adjustmentFactor":7.118,"status":"ACTIVE","sortPriority":5,"id":43885158},{"adjustmentFactor":1.044,"status":"ACTIVE","sortPriority":6,"id":46969227},{"adjustmentFactor":8.669,"status":"ACTIVE","sortPriority":7,"id":12989514}],"regulators":["MR_INT"],"venue":"DAX","countryCode":"FR","discountAllowed":true,"timezone":"Europe/London","openDate":"2022-08-01T10:00:00.000Z","version":4676920473,"raceType":"Flat","priceLadderDefinition":{"type":"CLASSIC"}},"rc":[{"atb":[[12.5,1.76],[11.5,7.04],[10.5,4.47],[10,10],[11,1.23],[9.2,12],[9.6,21],[8.2,5.56],[9.4,11],[8.8,14],[9.8,9],[9,13],[7.2,11.61],[1.03,322],[7,41.67],[7.8,14.71],[7.4,23.44],[1.01,45.55],[2.62,52.47],[5.6,5.74]],"atl":[[26,7.17],[1000,0.48],[24,1.9],[16,2],[55,9],[32,6.46],[50,8],[60,10],[80,14],[75,20.2],[70,12],[65,11],[29,5.36],[27,3.85],[960,0.01],[900,0.22],[890,0.02]],"trd":[[14.5,1.04],[14,1.16],[13,2.14],[15,6]],"bdatb":[[0,12.5,1.76],[1,11.5,7.04],[2,11,1.23],[3,10.5,4.47],[4,10,10],[5,9.8,9],[6,9.6,21],[7,9.4,11],[8,9.2,12],[9,9,14.46]],"bdatl":[[2,26,7.17],[3,27,3.85],[4,29,5.36],[5,32,6.46],[6,50,8],[7,55,9],[8,60,10],[9,65,11],[1,24,1.9],[0,16,2]],"ltp":13,"tv":10.34,"id":45323444},{"atb":[[1.97,13.5],[1.98,41.93],[1.96,3.89],[1.95,1.28],[1.91,107.36],[1.62,156.52],[1.73,33.55],[1.77,33.55],[1.82,47.85],[1.83,33.55],[1.7,5.4],[1.8,2.87],[1.01,45.55],[1.46,156.52],[1.42,62.85],[1.03,322]],"atl":[[2.12,20.6],[2.1,11.21],[2.4,71.43],[2.14,55.67],[2.38,33.55],[2.3,1.72],[2.18,1.18],[2.44,152.09],[2.5,21],[3.55,7.2],[34,11.5],[17,7.5],[900,0.22],[890,0.02]],"trd":[[1.99,31.59],[2.02,30.22],[2.04,73.98],[1.96,6.76],[2,15.1],[1.97,3.69],[2.06,38.06],[2.14,40.71],[2.12,34.75],[2.08,28.2],[2.1,12.98],[1.91,116.2],[1.9,1],[1.87,1.64],[1.82,114],[1.81,6.72],[1.8,34.62],[1.95,10.5],[2.4,5.85]],"bdatb":[[4,1.91,114.24],[5,1.9,2.45],[8,1.82,62.4],[9,1.81,4.84],[6,1.89,7.52],[7,1.83,33.55],[1,1.97,13.5],[0,1.98,41.93],[2,1.96,3.89],[3,1.95,1.28]],"bdatl":[[9,2.44,152.31],[8,2.4,74.47],[4,2.3,1.72],[5,2.32,1.06],[6,2.36,3.99],[7,2.38,34.52],[1,2.12,20.6],[0,2.1,11.21],[2,2.14,55.67],[3,2.18,1.18]],"ltp":1.99,"tv":606.57,"id":9570503},{"atb":[[7.4,2.9],[7,5.57],[6.8,11.36],[6.6,1.15],[7.2,6.21],[4.6,1.55],[1.04,1.69],[4.8,224.86],[4.1,1.47],[4.5,11.02],[4,208],[4.7,2],[1.01,45.55],[3.75,13],[3.9,10],[3.8,12],[3.7,14],[3.95,9],[3.85,11],[2.7,42.35],[2.94,13.6],[1.03,322]],"atl":[[9,1.46],[9.4,2.06],[11,33.84],[1000,0.47],[9.6,14.09],[10,17.36],[9.2,4.93],[10.5,12.47],[12,0.13],[30,8],[42,14],[40,13],[38,12],[36,11],[34,21.5],[32,9],[18.5,7.2],[900,0.22],[890,0.02]],"trd":[[7.6,6.33],[7.4,3.36],[7,6],[6.2,7.22],[6.4,16.78],[4.3,2]],"bdatb":[[8,5,2.07],[9,4.9,13.17],[7,5.4,6.52],[0,7.4,2.9],[5,6.2,3.8],[6,6,1.41],[1,7.2,6.21],[2,7,5.57],[3,6.8,11.36],[4,6.6,1.15]],"bdatl":[[8,30,9.25],[9,32,9],[0,9,1.46],[1,9.2,4.93],[2,9.4,2.06],[3,9.6,14.09],[4,10,17.36],[5,10.5,12.47],[6,11,33.84],[7,18.5,8.01]],"ltp":7.4,"tv":41.69,"id":12989514},{"atb":[[22,2.59],[15.5,5.99],[24,0.49],[1.04,1.13],[18,4.19],[21,5],[18.5,1.37],[10,102],[9.6,1.68],[9.4,10.05],[8.2,5.56],[7,41.67],[7.8,14.71],[7.4,23.44],[1.01,45.55],[2.62,52.47],[5,6.6],[1.03,322]],"atl":[[34,1.56],[55,0.42],[32,0.56],[990,1.82],[120,7.2],[170,2],[950,0.01],[40,3.27],[900,0.22],[890,0.02]],"trd":[[23,0.88],[22,1.12]],"bdatb":[[8,9.4,12.87],[9,8.6,2.17],[0,22,3.08],[1,21,5],[2,18.5,1.37],[3,18,4.19],[4,15.5,5.99],[5,12.5,1.88],[6,10,102.74],[7,9.6,1.68]],"bdatl":[[1,40,3.27],[2,120,7.62],[3,170,2],[4,990,2.07],[5,0,0],[6,0,0],[0,34,2.12],[7,0,0],[8,0,0],[9,0,0]],"ltp":22,"tv":2,"id":44621159},{"atb":[[6.2,9.3],[6.6,25.79],[6.4,0.37],[5.9,29.41],[5.8,10],[1.02,1.53],[5.7,44.55],[5.1,33.55],[6,30.13],[5.5,23],[1.05,1.45],[1.01,45.55],[5.4,14],[5.6,12],[4.8,18.95],[2.62,52.47],[2.06,24.9],[1.03,322]],"atl":[[7.4,9.09],[7.6,150],[8.2,0.31],[8,0.32],[9.8,33.55],[9.2,8],[13,41.88],[8.4,3],[13.5,1.55],[12,1.41],[12.5,0.02],[15,14.22],[14,3.68],[16,24.51],[14.5,0.1],[17.5,13],[16.5,11],[15.5,17.45],[18,14],[17,12],[28,7.2],[900,0.22],[890,0.02]],"trd":[[7.4,21.05],[6.4,2],[6.8,11.23],[6.6,30],[7,20.06],[7.2,8.3],[7.8,0.97],[7.6,2.92],[8.4,4],[9.2,10.32],[8.2,9.98],[9.4,9.44],[9,4],[10,0.82],[12,5.84],[11,0.16],[12.5,3.83],[14,11.38],[13.5,7.8],[13,0.82],[9.8,4]],"bdatb":[[7,5.5,25.39],[8,5.4,14.86],[9,5.3,1.08],[6,5.6,12],[1,6.2,9.67],[2,6,30.13],[3,5.9,29.41],[4,5.8,10],[5,5.7,44.55],[0,6.6,25.79]],"bdatl":[[5,12,1.41],[6,13,42.09],[7,13.5,1.56],[8,14,4.34],[9,15,14.48],[0,7.4,9.09],[1,7.6,150],[2,8.4,3.63],[3,9.2,8],[4,9.8,33.55]],"ltp":7.4,"tv":168.92,"id":44836671},{"atb":[[7.4,2.63],[7.8,1.26],[8,1.47],[7.2,8.24],[8.2,0.3],[1.02,1.55],[7,5],[1.01,45.55],[5.4,20],[5.9,4],[6.6,13],[5.7,8],[5.2,2],[4.9,27],[6,14],[5.5,2],[6.2,10],[5.8,12],[5.1,29],[4.6,20],[5.3,2],[6.4,2],[5.6,18],[2.62,52.47],[3.6,10.15],[1.03,322]],"atl":[[9.6,14.81],[10.5,1.82],[12,1.83],[11,0.25],[12.5,10],[14,1],[14.5,1],[13.5,8],[11.5,2.64],[15.5,1],[16.5,8.94],[19,13.89],[15,12],[19.5,27],[18.5,1],[18,9.82],[17,24.25],[28,7.2],[900,0.22],[890,0.02]],"trd":[[9.4,76.22],[9.6,2.72],[7.8,0.16],[8.2,1.84],[8.4,5.54],[8.8,0.46],[8.6,2.3],[9.2,18.39],[9,4],[10.5,0.82],[10,4],[15.5,2]],"bdatb":[[2,7.4,2.63],[3,7.2,8.24],[4,7,5],[5,6.6,14.99],[6,6.4,3.63],[7,6.2,11.36],[8,6,14],[9,5.9,4],[1,7.8,1.26],[0,8,1.77]],"bdatl":[[0,9.6,14.81],[1,10.5,1.82],[2,11.5,2.89],[3,12,1.83],[4,12.5,10],[5,13.5,8],[6,14,1],[7,14.5,1],[8,15,12],[9,15.5,1]],"ltp":9.6,"tv":118.45,"id":43885158},{"atb":[[25,1.09],[24,4.09],[26,0.1],[21,5],[7.8,12.86],[1.04,1.69],[19.5,0.68],[23,7],[20,1.4],[1.03,322],[16,1.43],[4.2,29.69],[6.6,12.86],[1.01,45.55],[2.62,52.47],[10,2],[5.6,5.74]],"atl":[[38,3.02],[30,5.07],[40,5.01],[36,1],[42,0.02],[990,1.9],[80,1.64],[950,0.01],[310,1],[900,0.22],[890,0.02]],"trd":[[28,12.24],[27,16.78],[21,6.92],[20,0.14],[22,0.3],[19,3.26],[18.5,2.18]],"bdatb":[[6,12.5,1.05],[7,11,1.66],[9,9,2.94],[0,25,1.19],[1,24,4.09],[2,23,7],[3,21,5],[4,20,1.4],[5,16,2.11],[8,10,2]],"bdatl":[[2,38,3.02],[0,30,5.07],[1,36,1],[3,40,5.01],[4,80,1.66],[5,310,1],[6,990,2.15],[7,0,0],[8,0,0],[9,0,0]],"ltp":27,"tv":41.82,"id":46969227}],"img":true,"tv":989.79}]}
{"op":"mcm","clk":"AAYAAwAD","pt":1659347400942,"mc":[{"id":"1.201590187","rc":[{"atb":[[12,4.77]],"bdatb":[[1,12,4.77],[2,11.5,7.04],[3,11,1.23],[4,10.5,4.47],[5,10,10],[6,9.8,9],[7,9.6,21],[8,9.4,11],[9,9.2,12]],"id":45323444},{"atb":[[7.8,8.62]],"bdatb":[[1,7.8,8.62]],"id":43885158},{"bdatl":[[9,2.44,170.41]],"id":9570503},{"bdatl":[[8,23,2.54],[9,30,8.52]],"id":12989514}]}]}
{"op":"mcm","clk":"ABAACAAN","pt":1659347401149,"mc":[{"id":"1.201590187","rc":[{"atb":[[23,1]],"atl":[[32,1.56]],"id":44621159},{"atb":[[7.4,6.2]],"id":43885158}]}]}
{"op":"mcm","clk":"ABMACwAO","pt":1659347401199,"mc":[{"id":"1.201590187","rc":[{"bdatb":[[5,1.9,9.93],[6,1.83,43.27],[7,1.82,52.62],[8,1.81,4.84],[9,1.8,8.64]],"bdatl":[[6,2.36,4.98],[7,2.38,36.61],[8,2.4,71.65],[9,2.42,3.24]],"id":9570503},{"bdatb":[[8,5.1,6.99],[9,4.9,8.03]],"bdatl":[[7,18.5,8.14],[8,22,1],[9,23,1.93]],"id":12989514},{"bdatb":[[0,23,1.49],[1,22,2.59],[2,21,5],[3,18.5,1.37],[4,18,4.19],[5,15.5,5.99],[6,12.5,1.88],[7,10,102.74],[8,9.6,1.68],[9,9.4,12.87]],"bdatl":[[0,32,1.56],[1,34,1.56],[2,40,3.27],[3,120,7.62],[4,170,2],[5,990,2.07]],"id":44621159},{"bdatb":[[8,5.4,15.93],[9,5.3,1.6]],"bdatl":[[9,15,14.97]],"id":44836671},{"bdatb":[[2,7.4,6.2]],"id":43885158},{"bdatb":[[7,11.5,1.61],[9,9.2,1.93]],"id":46969227}]}]}
{"op":"mcm","clk":"ADsAHwAl","pt":1659347401775,"mc":[{"id":"1.201590187","rc":[{"atb":[[7.8,1.26]],"id":43885158}]}]}
{"op":"mcm","clk":"AEEAIAAq","pt":1659347401825,"mc":[{"id":"1.201590187","rc":[{"bdatl":[[9,2.44,152.94]],"id":9570503},{"bdatl":[[8,27,2.22],[9,30,8.31]],"id":12989514},{"bdatb":[[1,7.8,1.26]],"id":43885158}]}]}
{"op":"mcm","clk":"AEMAJAAr","pt":1659347401885,"mc":[{"id":"1.201590187","rc":[{"atb":[[7.4,13.96]],"id":43885158}]}]}
{"op":"mcm","clk":"AEwAJwAw","pt":1659347401935,"mc":[{"id":"1.201590187","rc":[{"bdatl":[[8,27,2.56],[9,30,8.13]],"id":12989514},{"bdatb":[[2,7.4,13.96]],"id":43885158}]}]}
{"op":"mcm","clk":"AGkAOQBN","pt":1659347402475,"mc":[{"id":"1.201590187","rc":[{"atb":[[24,5.06],[19.5,0]],"id":46969227}]}]}
{"op":"mcm","clk":"AGwAOQBP","pt":1659347402525,"mc":[{"id":"1.201590187","rc":[{"bdatb":[[1,24,5.06],[5,16,1.43]],"id":46969227}]}]}
{"op":"mcm","clk":"AHUAPQBY","pt":1659347402582,"mc":[{"id":"1.201590187","rc":[{"atb":[[22,0]],"id":44621159},{"atb":[[7.4,6.2]],"id":43885158},{"atb":[[22,7]],"id":46969227}]}]}
{"op":"mcm","clk":"AHYAPQBY","pt":1659347402632,"mc":[{"id":"1.201590187","rc":[{"bdatl":[[8,29,2.13],[9,30,8]],"id":12989514},{"bdatb":[[1,21,5],[2,18.5,1.37],[3,18,4.19],[4,15.5,5.99],[5,12.5,1.88],[6,10,102.74],[7,9.6,1.68],[8,9.4,12.87],[9,8.6,2.17]],"id":44621159},{"bdatb":[[2,7.4,6.2]],"id":43885158},{"bdatb":[[3,22,7],[4,21,5],[5,20,1.4],[6,16,1.43],[7,12.5,1.05],[8,11.5,1.61],[9,10,2]],"id":46969227}]}]}
{"op":"mcm","clk":"AHcAQQBg","pt":1659347402682,"mc":[{"id":"1.201590187","rc":[{"atb":[[11.5,5.54]],"id":45323444}]}]}
{"op":"mcm","clk":"AIEBAEIAYQ==","pt":1659347402732,"mc":[{"id":"1.201590187","rc":[{"bdatb":[[2,11.5,5.54]],"id":45323444}]}]}
{"op":"mcm","clk":"AIMBAEQAZg==","pt":1659347402782,"mc":[{"id":"1.201590187","rc":[{"atb":[[12,6.27]],"id":45323444},{"atb":[[7.6,7.58]],"id":43885158}]}]}
{"op":"mcm","clk":"AIoBAEkAZg==","pt":1659347402832,"mc":[{"id":"1.201590187","rc":[{"bdatb":[[1,12,6.27]],"id":45323444},{"bdatl":[[9,2.44,155.31]],"id":9570503},{"bdatl":[[8,26,2.76],[9,30,8.05]],"id":12989514},{"bdatb":[[2,7.6,7.58],[3,7.4,6.2],[4,7.2,8.24],[5,7,5],[6,6.6,14.99],[7,6.4,3.63],[8,6.2,11.36],[9,6,14]],"id":43885158}]}]}
{"op":"mcm","clk":"AJABAE4AdA==","pt":1659347402989,"mc":[{"id":"1.201590187","rc":[{"atb":[[23,3.47]],"id":44621159}]}]}
{"op":"mcm","clk":"AJcBAFAAdg==","pt":1659347403039,"mc":[{"id":"1.201590187","rc":[{"bdatl":[[8,24,2.91],[9,30,8.37]],"id":12989514},{"bdatb":[[0,23,3.96]],"id":44621159}]}]}
{"op":"mcm","clk":"AMkBAGYAowE=","pt":1659347403685,"mc":[{"id":"1.201590187","rc":[{"atb":[[12,1.5]],"id":45323444},{"atb":[[23,1]],"id":44621159},{"atb":[[7.6,0]],"id":43885158}]}]}
{"op":"mcm","clk":"AMwBAGgApgE=","pt":1659347403735,"mc":[{"id":"1.201590187","rc":[{"bdatb":[[1,12,1.5]],"id":45323444},{"bdatl":[[9,2.44,152.94]],"id":9570503},{"bdatl":[[8,29,1.1],[9,30,8]],"id":12989514},{"bdatb":[[0,23,1.49]],"id":44621159},{"bdatb":[[2,7.4,6.2],[3,7.2,8.24],[4,7,5],[5,6.6,14.99],[6,6.4,3.63],[7,6.2,11.36],[8,6,14],[9,5.9,4]],"id":43885158}]}]}
{"op":"mcm","clk":"ANgBAG0AswE=","pt":1659347403892,"mc":[{"id":"1.201590187","rc":[{"atb":[[12.5,6.36]],"id":45323444},{"atb":[[7.8,8.62]],"id":43885158}]}]}
{"op":"mcm","clk":"ANwBAG8AuQE=","pt":1659347403942,"mc":[{"id":"1.201590187","rc":[{"bdatb":[[0,12.5,6.36]],"id":45323444},{"bdatl":[[8,2.4,74.91],[9,2.42,2.08]],"id":9570503},{"bdatl":[[8,20,1.05],[9,22,2.03]],"id":12989514},{"bdatb":[[1,7.8,8.62]],"id":43885158}]}]}
{"op":"mcm","clk":"AOgBAHMAwgE=","pt":1659347404095,"mc":[{"id":"1.201590187","rc":[{"atb":[[24,2.91]],"id":44621159}]}]}
{"op":"mcm","clk":"AOoBAHUAxgE=","pt":1659347404145,"mc":[{"id":"1.201590187","rc":[{"bdatl":[[8,2.4,90.05],[9,2.42,1.49]],"id":9570503},{"bdatl":[[7,18.5,8.13],[8,19.5,2.87],[9,30,8.99]],"id":12989514},{"bdatb":[[0,24,2.91],[1,23,1],[2,21,5],[3,18.5,1.37],[4,18,4.19],[5,15.5,5.99],[6,12.5,1.88],[7,10,102.74],[8,9.6,1.68],[9,9.4,12.87]],"id":44621159},{"bdatl":[[8,14,4.51],[9,15,14.83]],"id":44836671}]}]}
{"op":"mcm","clk":"AP0BAHoA2wE=","pt":1659347404373,"mc":[{"id":"1.201590187","rc":[{"atb":[[1.97,29.63]],"bdatb":[[1,1.97,29.63]],"id":9570503}]}]}
{"op":"mcm","clk":"AIwCAI0BAPIB","pt":1659347404774,"mc":[{"id":"1.201590187","rc":[{"atb":[[12.5,1.76]],"id":45323444},{"atb":[[24,0.49]],"id":44621159},{"atb":[[7.8,1.26]],"id":43885158}]}]}
{"op":"mcm","clk":"AIwCAI0BAPIB","pt":1659347404824,"mc":[{"id":"1.201590187","rc":[{"bdatb":[[0,12.5,1.76]],"id":45323444},{"bdatl":[[8,2.4,71.65],[9,2.44,152.94]],"id":9570503},{"bdatl":[[7,18.5,8.14],[8,29,1.1],[9,30,8]],"id":12989514},{"bdatb":[[0,23,1.49],[1,21,5],[2,18.5,1.37],[3,18,4.19],[4,15.5,5.99],[5,12.5,1.88],[6,10,102.74],[7,9.6,1.68],[8,9.4,12.87],[9,8.6,2.17]],"id":44621159},{"bdatl":[[8,14,4.34],[9,15,14.97]],"id":44836671},{"bdatb":[[1,7.8,1.26]],"id":43885158}]}]}
{"op":"mcm","clk":"AJICAJUBAPgB","pt":1659347404875,"mc":[{"id":"1.201590187","rc":[{"atb":[[4.7,0],[4.8,227.44]],"id":12989514}]}]}
{"op":"mcm","clk":"AJUCAJoBAP0B","pt":1659347404971,"mc":[{"id":"1.201590187","rc":[{"atb":[[12,6.27]],"id":45323444},{"atb":[[7.6,7.58]],"id":43885158}]}]}
{"op":"mcm","clk":"AJ0CAJsBAP4B","pt":1659347405021,"mc":[{"id":"1.201590187","rc":[{"bdatb":[[1,12,6.27]],"id":45323444},{"bdatl":[[9,2.44,155.31]],"id":9570503},{"bdatl":[[8,26,2.76],[9,30,8.05]],"id":12989514},{"bdatb":[[2,7.6,7.58],[3,7.4,6.2],[4,7.2,8.24],[5,7,5],[6,6.6,14.99],[7,6.4,3.63],[8,6.2,11.36],[9,6,14]],"id":43885158}]}]}
{"op":"mcm","clk":"AJ4CAJ8BAIAC","pt":1659347405073,"mc":[{"id":"1.201590187","rc":[{"atb":[[1.97,13.5]],"id":9570503}]}]}
{"op":"mcm","clk":"AKQCAKIBAIkC","pt":1659347405123,"mc":[{"id":"1.201590187","rc":[{"bdatb":[[1,1.97,13.5]],"id":9570503}]}]}
{"op":"mcm","clk":"AKcCAKQBAIwC","pt":1659347405179,"mc":[{"id":"1.201590187","rc":[{"atb":[[22,2.59]],"id":44621159}]}]}
{"op":"mcm","clk":"AK4CAKYBAJIC","pt":1659347405229,"mc":[{"id":"1.201590187","rc":[{"bdatl":[[8,25,2.83],[9,30,8.35]],"id":12989514},{"bdatb":[[1,22,2.59],[2,21,5],[3,18.5,1.37],[4,18,4.19],[5,15.5,5.99],[6,12.5,1.88],[7,10,102.74],[8,9.6,1.68],[9,9.4,12.87]],"id":44621159}]}]}
{"op":"mcm","clk":"AN4CALsBALUC","pt":1659347405955,"mc":[{"id":"1.201590187","rc":[{"atb":[[12,1.5]],"id":45323444},{"atb":[[22,0]],"id":44621159},{"atb":[[7.6,0]],"id":43885158}]}]}
{"op":"mcm","clk":"AOMCALsBALkC","pt":1659347406005,"mc":[{"id":"1.201590187","rc":[{"bdatb":[[1,12,1.5]],"id":45323444},{"bdatl":[[9,2.44,152.94]],"id":9570503},{"bdatl":[[8,29,1.1],[9,30,8]],"id":12989514},{"bdatb":[[1,21,5],[2,18.5,1.37],[3,18,4.19],[4,15.5,5.99],[5,12.5,1.88],[6,10,102.74],[7,9.6,1.68],[8,9.4,12.87],[9,8.6,2.17]],"id":44621159},{"bdatb":[[2,7.4,6.2],[3,7.2,8.24],[4,7,5],[5,6.6,14.99],[6,6.4,3.63],[7,6.2,11.36],[8,6,14],[9,5.9,4]],"id":43885158}]}]}
{"op":"mcm","clk":"APACAMIBAMQC","pt":1659347406171,"mc":[{"id":"1.201590187","rc":[{"atb":[[12.5,6.36]],"id":45323444},{"atb":[[7.8,8.62]],"id":43885158}]}]}
{"op":"mcm","clk":"APACAMIBAMQC","pt":1659347406221,"mc":[{"id":"1.201590187","rc":[{"bdatb":[[0,12.5,6.36]],"id":45323444},{"bdatl":[[8,2.4,74.91],[9,2.42,2.08]],"id":9570503},{"bdatl":[[8,20,1.05],[9,22,2.03]],"id":12989514},{"bdatb":[[1,7.8,8.62]],"id":43885158}]}]}
{"op":"mcm","clk":"APICAMcBAMYC","pt":1659347406272,"mc":[{"id":"1.201590187","rc":[{"atb":[[23,3.47]],"id":44621159}]}]}
{"op":"mcm","clk":"APUCAMgBAMkC","pt":1659347406323,"mc":[{"id":"1.201590187","rc":[{"bdatl":[[9,2.42,15.01]],"id":9570503},{"bdatl":[[8,20,3.28],[9,30,8.47]],"id":12989514},{"bdatb":[[0,23,3.96]],"id":44621159}]}]}
{"op":"mcm","clk":"APgCAMoBAMsC","pt":1659347406373,"mc":[{"id":"1.201590187","rc":[{"atb":[[10.5,1.6]],"id":45323444}]}]}
{"op":"mcm","clk":"AP0CAMwBAM8C","pt":1659347406423,"mc":[{"id":"1.201590187","rc":[{"bdatb":[[4,10.5,1.6]],"id":45323444}]}]}
{"op":"mcm","clk":"AP8CAM0BANIC","pt":1659347406476,"mc":[{"id":"1.201590187","rc":[{"atb":[[12,4.37]],"atl":[[16,1]],"trd":[[16,2]],"ltp":16,"tv":12.34,"id":45323444}],"tv":991.79}]}
{"op":"mcm","clk":"AIQDAM4BANQC","pt":1659347406526,"mc":[{"id":"1.201590187","rc":[{"bdatb":[[1,12,4.37]],"bdatl":[[0,16,1]],"id":45323444},{"bdatb":[[5,1.9,1.51],[6,1.83,52.01],[8,1.81,1.74],[9,1.8,5.99]],"id":9570503},{"bdatb":[[5,6.2,2.58],[6,5.6,1.35],[7,5.4,7.05],[8,5.3,1.05],[9,5.1,6.99]],"id":12989514},{"bdatb":[[5,12.5,1.28],[6,10,102],[7,9.6,2.45],[8,9.4,13.77],[9,8.4,2.23]],"id":44621159},{"bdatb":[[8,5.4,14.53],[9,5.1,33.55]],"id":44836671},{"bdatb":[[6,6.4,2.45],[7,6.2,10]],"id":43885158},{"bdatb":[[8,10,2.24],[9,9.2,3.64]],"id":46969227}]}]}
{"op":"mcm","clk":"AI8DANMBAOAC","pt":1659347406686,"mc":[{"id":"1.201590187","rc":[{"atl":[[26,5.72]],"id":45323444}]}]}
{"op":"mcm","clk":"AJEDANUBAOMC","pt":1659347406737,"mc":[{"id":"1.201590187","rc":[{"bdatl":[[2,26,5.72]],"id":45323444}]}]}
{"op":"mcm","clk":"AJYDANYBAOUC","pt":1659347406796,"mc":[{"id":"1.201590187","rc":[{"atl":[[990,1.45]],"id":45323444}]}]}
{"op":"mcm","clk":"AJkDANkBAOoC","pt":1659347406884,"mc":[{"id":"1.201590187","rc":[{"atl":[[38,2.51]],"id":46969227}]}]}
{"op":"mcm","clk":"AKADANoBAOsC","pt":1659347406935,"mc":[{"id":"1.201590187","rc":[{"bdatl":[[2,38,2.51]],"id":46969227}]}]}
{"op":"mcm","clk":"AKIDAN0BAPAC","pt":1659347406989,"mc":[{"id":"1.201590187","rc":[{"atl":[[34,0.51]],"id":46969227}]}]}
{"op":"mcm","clk":"AKkDAN4BAPIC","pt":1659347407039,"mc":[{"id":"1.201590187","rc":[{"bdatl":[[1,36,1.51]],"id":46969227}]}]}
{"op":"mcm","clk":"AK4DAN4BAPYC","pt":1659347407107,"mc":[{"id":"1.201590187","rc":[{"atb":[[12.5,1.76]],"id":45323444},{"atb":[[23,1]],"id":44621159},{"atb":[[7.8,1.26]],"id":43885158}]}]}
{"op":"mcm","clk":"AK4DAOEBAPgC","pt":1659347407157,"mc":[{"id":"1.201590187","rc":[{"bdatb":[[0,12.5,1.76]],"id":45323444},{"bdatl":[[8,2.4,71.65],[9,2.44,152.94]],"id":9570503},{"bdatl":[[8,29,2.13],[9,30,8]],"id":12989514},{"bdatb":[[0,23,1.49]],"id":44621159},{"bdatb":[[1,7.8,1.26]],"id":43885158}]}]}
{"op":"mcm","clk":"AK8DAOEBAPoC","pt":1659347407207,"mc":[{"id":"1.201590187","rc":[{"atb":[[7.4,2.63]],"bdatb":[[2,7.4,2.63]],"id":43885158},{"bdatl":[[8,29,1.22]],"id":12989514}]}]}
{"op":"mcm","clk":"ALgDAOUBAP8C","pt":1659347407269,"mc":[{"id":"1.201590187","rc":[{"atb":[[12,9.14]],"id":45323444},{"atb":[[7.6,7.58]],"id":43885158}]}]}
{"op":"mcm","clk":"AL4DAOUBAP8C","pt":1659347407319,"mc":[{"id":"1.201590187","rc":[{"bdatb":[[1,12,9.14]],"id":45323444},{"bdatl":[[9,2.44,155.31]],"id":9570503},{"bdatl":[[8,26,2.76],[9,30,8.05]],"id":12989514},{"bdatb":[[2,7.6,7.58],[3,7.4,2.63],[4,7.2,8.24],[5,7,5],[6,6.6,14.99],[7,6.4,2.45],[8,6.2,10],[9,6,14]],"id":43885158}]}]}
{"op":"mcm","clk":"AMIDAOwBAIMD","pt":1659347407370,"mc":[{"id":"1.201590187","rc":[{"atl":[[30,0.07]],"id":46969227}]}]}
{"op":"mcm","clk":"AMMDAOwBAIQD","pt":1659347407420,"mc":[{"id":"1.201590187","rc":[{"bdatb":[[4,1.91,108.46],[5,1.89,7.35],[6,1.83,33.55],[7,1.82,47.85],[8,1.81,18.67],[9,1.8,7.7]],"id":9570503},{"bdatb":[[5,6,2.66],[6,5.4,1.4],[7,5.3,4.95],[8,5.2,2.28],[9,5.1,1.09]],"id":12989514},{"bdatb":[[5,12,1.09],[6,10,102.25],[7,9.6,1.68],[8,9.4,10.86],[9,9,3.53]],"id":44621159},{"bdatb":[[7,5.5,23.38],[8,5.4,14],[9,5.3,2.62]],"id":44836671},{"bdatb":[[6,6.6,13.32],[7,6.4,3.72],[8,6.2,10.46]],"id":43885158},{"bdatl":[[0,36,1.58],[1,38,2.51],[2,40,5.01],[3,80,1.66],[4,310,1],[5,990,2.15],[6,0,0]],"id":46969227}]}]}
{"op":"mcm","clk":"AMcDAO4BAIoD","pt":1659347407470,"mc":[{"id":"1.201590187","rc":[{"atb":[[12.5,2.76]],"atl":[[23,1]],"id":45323444},{"atb":[[24,2.91]],"id":44621159}]}]}
{"op":"mcm","clk":"AMsDAO4BAIoD","pt":1659347407520,"mc":[{"id":"1.201590187","rc":[{"bdatb":[[0,12.5,2.76]],"bdatl":[[1,23,1],[2,24,1.9],[3,26,5.72],[4,27,3.85],[5,29,5.36],[6,32,6.46],[7,50,8],[8,55,9],[9,60,10]],"id":45323444},{"bdatb":[[7,1.82,49.65],[8,1.81,16.85]],"bdatl":[[8,2.4,72.5],[9,2.42,4.32]],"id":9570503},{"bdatb":[[6,5.4,1.39],[8,5.2,3.35],[9,5,3.49]],"bdatl":[[7,18.5,8.13],[8,21,1.03],[9,23,1.53]],"id":12989514},{"bdatb":[[0,24,2.91],[1,23,1],[2,21,5],[3,18.5,1.37],[4,18,4.19],[5,15.5,5.99],[6,12,1.09],[7,10,102.25],[8,9.6,2.02],[9,9.4,10.51]],"id":44621159},{"bdatl":[[8,14,4.51],[9,15,14.83]],"id":44836671},{"bdatb":[[9,9.4,2.41]],"id":46969227}]}]}
{"op":"mcm","clk":"AMwDAPMBAJMD","pt":1659347407570,"mc":[{"id":"1.201590187","rc":[{"atb":[[26,0]],"id":46969227}]}]}
{"op":"mcm","clk":"AM8DAPMBAJMD","pt":1659347407620,"mc":[{"id":"1.201590187","rc":[{"bdatl":[[5,2.34,1.05]],"id":9570503},{"bdatl":[[7,18.5,8.12]],"id":12989514},{"bdatl":[[6,13,41.9],[7,13.5,1.74],[8,14,4.52]],"id":44836671},{"bdatb":[[0,25,1.09]],"id":46969227}]}]}
{"op":"mcm","clk":"ANcDAPYBAJcD","pt":1659347407678,"mc":[{"id":"1.201590187","rc":[{"atb":[[25,2.72]],"id":46969227}]}]}
{"op":"mcm","clk":"ANcDAPcBAJcD","pt":1659347407728,"mc":[{"id":"1.201590187","rc":[{"bdatl":[[8,20,1.04],[9,22,1.52]],"id":12989514},{"bdatb":[[0,25,2.72]],"id":46969227}]}]}
{"op":"mcm","clk":"APIDAIcCAKwD","pt":1659347408185,"mc":[{"id":"1.201590187","rc":[{"atb":[[12,4.37]],"id":45323444},{"atb":[[24,0.49]],"id":44621159},{"atb":[[7.6,0]],"id":43885158}]}]}
{"op":"mcm","clk":"APcDAIoCAK4D","pt":1659347408235,"mc":[{"id":"1.201590187","rc":[{"bdatb":[[1,12,4.37]],"id":45323444},{"bdatl":[[9,2.44,156.37]],"id":9570503},{"bdatl":[[8,27,1.29],[9,30,8.81]],"id":12989514},{"bdatb":[[0,23,1.49],[1,21,5],[2,18.5,1.37],[3,18,4.19],[4,15.5,5.99],[5,12,1.09],[6,10,102.25],[7,9.6,2.02],[8,9.4,10.51],[9,9,3.53]],"id":44621159},{"bdatl":[[8,14,4.35],[9,15,14.97]],"id":44836671},{"bdatb":[[2,7.4,2.63],[3,7.2,8.24],[4,7,5],[5,6.6,13.32],[6,6.4,3.72],[7,6.2,10.46],[8,6,14],[9,5.9,4]],"id":43885158}]}]}
{"op":"mcm","clk":"APgDAIoCALUD","pt":1659347408286,"mc":[{"id":"1.201590187","rc":[{"atb":[[1.01,48.08]],"atl":[[1000,0.89]],"id":45323444}]}]}
{"op":"mcm","clk":"APwDAIsCALwD","pt":1659347408390,"mc":[{"id":"1.201590187","rc":[{"atb":[[12.5,7.36]],"id":45323444},{"atb":[[7.8,8.62]],"id":43885158},{"atl":[[1000,0.41]],"id":46969227}]}]}
{"op":"mcm","clk":"AP8DAIwCAL4D","pt":1659347408440,"mc":[{"id":"1.201590187","rc":[{"bdatb":[[0,12.5,7.36]],"id":45323444},{"bdatl":[[8,2.4,77.01],[9,2.42,12.94]],"id":9570503},{"bdatl":[[8,19.5,1.06],[9,22,2.12]],"id":12989514},{"bdatb":[[1,7.8,8.62]],"id":43885158},{"bdatl":[[6,1000,0.41]],"id":46969227}]}]}
{"op":"mcm","clk":"AIAEAIwCAL8D","pt":1659347408492,"mc":[{"id":"1.201590187","rc":[{"atb":[[12,2.87],[1.01,47.24]],"atl":[[1000,0.48]],"id":45323444}]}]}
{"op":"mcm","clk":"AIUEAI0CAMID","pt":1659347408542,"mc":[{"id":"1.201590187","rc":[{"bdatb":[[1,12,2.87]],"id":45323444}]}]}
{"op":"mcm","clk":"AIcEAI4CAMcD","pt":1659347408596,"mc":[{"id":"1.201590187","rc":[{"atb":[[10,11.5]],"atl":[[22,0.41]],"id":45323444},{"atl":[[1000,0]],"id":46969227}]}]}
{"op":"mcm","clk":"AIwEAJACAMgD","pt":1659347408646,"mc":[{"id":"1.201590187","rc":[{"bdatb":[[5,10,11.5]],"bdatl":[[1,23,1.41]],"id":45323444},{"bdatb":[[6,1.83,35.34],[7,1.82,51],[8,1.81,13.68]],"id":9570503},{"bdatb":[[6,5.5,1.36],[9,5,5.29]],"id":12989514},{"bdatb":[[7,9.6,2.46],[8,9.4,10.05],[9,9,3.52]],"id":44621159},{"bdatb":[[8,10,2.99],[9,9.4,2.61]],"bdatl":[[6,0,0]],"id":46969227}]}]}
{"op":"mcm","clk":"AI4EAJACAM4D","pt":1659347408696,"mc":[{"id":"1.201590187","rc":[{"atb":[[1.01,45.55]],"id":45323444},{"atl":[[36,1.41]],"bdatl":[[0,36,1.99]],"id":46969227},{"bdatb":[[9,1.8,12.57]],"id":9570503},{"bdatb":[[9,9,3.88]],"id":44621159}]}]}
{"op":"mcm","clk":"AJgEAJECANED","pt":1659347408763,"mc":[{"id":"1.201590187","rc":[{"atb":[[13,1.69]],"id":45323444}]}]}
{"op":"mcm","clk":"AJgEAJECANQD","pt":1659347408813,"mc":[{"id":"1.201590187","rc":[{"bdatb":[[0,13,1.69],[1,12.5,7.36],[2,12,2.87],[3,11.5,5.54],[4,11,1.23],[5,10.5,1.6],[6,10,11.5],[7,9.8,9],[8,9.6,21],[9,9.4,11]],"id":45323444},{"bdatl":[[5,2.32,1.06],[6,2.34,5.02],[7,2.36,3.09],[8,2.38,33.75],[9,2.4,76.8]],"id":9570503},{"bdatl":[[7,18.5,8.58],[8,22,2.78],[9,30,8.7]],"id":12989514},{"bdatl":[[6,13,42.09],[7,13.5,2.42],[8,14,3.68],[9,15,14.86]],"id":44836671}]}]}
{"op":"mcm","clk":"AKoEAJ4CAOQD","pt":1659347409080,"mc":[{"id":"1.201590187","rc":[{"atb":[[12.5,2.76]],"id":45323444},{"atb":[[7.8,1.26]],"id":43885158}]}]}
{"op":"mcm","clk":"AKoEAJ4CAOUD","pt":1659347409130,"mc":[{"id":"1.201590187","rc":[{"bdatb":[[1,12.5,2.76]],"id":45323444},{"bdatl":[[9,2.4,72.3]],"id":9570503},{"bdatl":[[8,28,1.39],[9,30,8.38]],"id":12989514},{"bdatb":[[1,7.8,1.26]],"id":43885158}]}]}
{"op":"mcm","clk":"ALAEAKICAOwD","pt":1659347409180,"mc":[{"id":"1.201590187","rc":[{"atl":[[36,2.56],[34,5.51]],"id":46969227}]}]}
{"op":"mcm","clk":"ALAEAKICAOwD","pt":1659347409230,"mc":[{"id":"1.201590187","rc":[{"bdatb":[[6,1.83,38.49],[7,1.82,60.48],[8,1.81,5.77],[9,1.8,7.74]],"id":9570503},{"bdatb":[[6,5.6,1.35],[7,5.4,4.54],[8,5.3,3.62],[9,5,7.13]],"id":12989514},{"bdatb":[[7,9.6,2.45],[8,9.4,10.21],[9,9.2,2.5]],"id":44621159},{"bdatl":[[0,34,5.58],[1,36,2.56],[2,38,2.51],[3,40,5.01],[4,80,1.66],[5,310,1],[6,990,2.15]],"id":46969227}]}]}
{"op":"mcm","clk":"ALIEAKgCAO0D","pt":1659347409282,"mc":[{"id":"1.201590187","rc":[{"atb":[[13,6.12]],"id":45323444},{"atb":[[7.4,10.39]],"id":43885158}]}]}
{"op":"mcm","clk":"ALcEAKoCAPUD","pt":1659347409333,"mc":[{"id":"1.201590187","rc":[{"bdatb":[[0,13,6.12]],"id":45323444},{"bdatl":[[8,2.38,34.63],[9,2.4,71.43]],"id":9570503},{"bdatl":[[7,18.5,8.69],[8,23,1.95],[9,28,1.26]],"id":12989514},{"bdatl":[[9,15,15]],"id":44836671},{"bdatb":[[2,7.4,10.39]],"id":43885158}]}]}
{"op":"mcm","clk":"AMEEAK0CAP0D","pt":1659347409483,"mc":[{"id":"1.201590187","rc":[{"atb":[[22,2.59]],"id":44621159}]}]}
{"op":"mcm","clk":"AMYEAK4CAIAE","pt":1659347409533,"mc":[{"id":"1.201590187","rc":[{"bdatl":[[8,22,2.01],[9,28,1.31]],"id":12989514},{"bdatb":[[1,22,2.59],[2,21,5],[3,18.5,1.37],[4,18,4.19],[5,15.5,5.99],[6,12,1.09],[7,10,102.25],[8,9.6,2.45],[9,9.4,10.21]],"id":44621159}]}]}
{"op":"mcm","clk":"APIEAMgCAKcE","pt":1659347410264,"mc":[{"id":"1.201590187","rc":[{"atb":[[13,1.69]],"id":45323444},{"atb":[[22,0]],"id":44621159},{"atb":[[7.4,2.63]],"id":43885158}]}]}
{"op":"mcm","clk":"APUEAMgCAKwE","pt":1659347410315,"mc":[{"id":"1.201590187","rc":[{"bdatb":[[0,13,1.69]],"id":45323444},{"bdatl":[[8,2.38,33.75],[9,2.4,72.3]],"id":9570503},{"bdatl":[[7,18.5,8.58],[8,28,1.39],[9,30,8.38]],"id":12989514},{"bdatb":[[1,21,5],[2,18.5,1.37],[3,18,4.19],[4,15.5,5.99],[5,12,1.09],[6,10,102.25],[7,9.6,2.45],[8,9.4,10.21],[9,9.2,2.5]],"id":44621159},{"bdatl":[[9,15,14.86]],"id":44836671},{"bdatb":[[2,7.4,2.63]],"id":43885158}]}]}
{"op":"mcm","clk":"AIEFAM8CALQE","pt":1659347410476,"mc":[{"id":"1.201590187","rc":[{"atb":[[12.5,7.36]],"id":45323444},{"atb":[[7.6,7.58]],"id":43885158}]}]}
{"op":"mcm","clk":"AIQFANACALYE","pt":1659347410526,"mc":[{"id":"1.201590187","rc":[{"bdatb":[[1,12.5,7.36]],"id":45323444},{"bdatl":[[8,23,2.06],[9,28,1.27]],"id":12989514},{"bdatb":[[2,7.6,7.58],[3,7.4,2.63],[4,7.2,8.24],[5,7,5],[6,6.6,13.32],[7,6.4,3.72],[8,6.2,10.46],[9,6,14]],"id":43885158}]}]}
{"op":"mcm","clk":"AJAFANgCALwE","pt":1659347410680,"mc":[{"id":"1.201590187","rc":[{"atb":[[23,3.47]],"id":44621159}]}]}
{"op":"mcm","clk":"AJIFANoCAMEE","pt":1659347410730,"mc":[{"id":"1.201590187","rc":[{"bdatl":[[8,21,2.2],[9,25,1.03]],"id":12989514},{"bdatb":[[0,23,3.96]],"id":44621159}]}]}
{"op":"mcm","clk":"ALEFAPECAOEE","pt":1659347411301,"mc":[{"id":"1.201590187","rc":[{"atl":[[25,1.67]],"id":45323444},{"atb":[[24,1.06],[20,6.4]],"id":46969227}]}]}
{"op":"mcm","clk":"ALgFAPECAOQE","pt":1659347411351,"mc":[{"id":"1.201590187","rc":[{"bdatl":[[3,25,1.67],[4,26,5.72],[5,27,3.85],[6,29,5.36],[7,32,6.46],[8,50,8],[9,55,9]],"id":45323444},{"bdatb":[[1,24,1.06],[5,20,6.4]],"id":46969227}]}]}
{"op":"mcm","clk":"ALsFAPICAO0E","pt":1659347411401,"mc":[{"id":"1.201590187","rc":[{"atb":[[12.5,2.76]],"bdatb":[[1,12.5,2.76]],"id":45323444},{"atb":[[23,1]],"bdatb":[[0,23,1.49]],"id":44621159},{"atb":[[7.6,0]],"bdatb":[[2,7.4,2.63],[3,7.2,8.24],[4,7,5],[5,6.6,13.32],[6,6.4,3.72],[7,6.2,10.46],[8,6,14],[9,5.9,4]],"id":43885158},{"atb":[[25,1.09]],"bdatb":[[0,25,1.09]],"id":46969227},{"bdatl":[[8,29,1.21],[9,30,8.13]],"id":12989514}]}]}
{"op":"mcm","clk":"AMUFAPMCAPIE","pt":1659347411467,"mc":[{"id":"1.201590187","rc":[{"atb":[[25,1],[1.02,1.63]],"id":46969227}]}]}
{"op":"mcm","clk":"AMgFAPMCAPIE","pt":1659347411517,"mc":[{"id":"1.201590187","rc":[{"bdatl":[[8,29,1.12],[9,30,8.21]],"id":12989514},{"bdatb":[[0,25,1]],"id":46969227}]}]}
{"op":"mcm","clk":"AMsFAPQCAPUE","pt":1659347411567,"mc":[{"id":"1.201590187","rc":[{"atb":[[13,6.12]],"id":45323444},{"atb":[[7.8,8.62]],"id":43885158}]}]}
{"op":"mcm","clk":"ANAFAPQCAPgE","pt":1659347411617,"mc":[{"id":"1.201590187","rc":[{"bdatb":[[0,13,6.12]],"id":45323444},{"bdatl":[[8,2.38,35.02],[9,2.4,75.54]],"id":9570503},{"bdatl":[[7,18.5,8.74],[8,21,1.26],[9,22,1.33]],"id":12989514},{"bdatl":[[9,15,15.06]],"id":44836671},{"bdatb":[[1,7.8,8.62]],"id":43885158}]}]}
{"op":"mcm","clk":"ANcFAPcCAP4E","pt":1659347411775,"mc":[{"id":"1.201590187","rc":[{"atl":[[2.1,6.21]],"trd":[[2.1,22.98]],"ltp":2.1,"tv":616.57,"id":9570503},{"atb":[[24,2.91]],"id":44621159}],"tv":1001.79}]}
{"op":"mcm","clk":"ANsFAPcCAIMF","pt":1659347411825,"mc":[{"id":"1.201590187","rc":[{"bdatl":[[0,2.1,6.21],[8,2.38,45.66],[9,2.4,78.04]],"id":9570503},{"bdatb":[[6,5.4,5.93],[7,5.3,1.64],[8,5.1,2.07],[9,5,7.12]],"bdatl":[[7,18,1.57],[8,18.5,8.57],[9,19,1.02]],"id":12989514},{"bdatb":[[0,24,2.91],[1,23,1],[2,21,5],[3,18.5,1.37],[4,18,4.19],[5,15.5,5.99],[6,12,1.08],[7,10,102.27],[8,9.6,1.68],[9,9.4,11.02]],"id":44621159},{"bdatb":[[9,5.3,2.06]],"bdatl":[[8,14,4.2],[9,15,16.26]],"id":44836671},{"bdatb":[[6,6.4,3.71],[7,6.2,10.01],[8,6,14.48]],"id":43885158},{"bdatb":[[7,12.5,1.04],[8,10,2.26],[9,9.4,3.39]],"id":46969227}]}]}
{"op":"mcm","clk":"APAFAIMDAJQF","pt":1659347412183,"mc":[{"id":"1.201590187","rc":[{"atb":[[1.02,0]],"id":46969227}]}]}
{"op":"mcm","clk":"APUFAIcDAJ0F","pt":1659347412287,"mc":[{"id":"1.201590187","rc":[{"atb":[[1.98,36.93]],"trd":[[1.98,10]],"ltp":1.98,"tv":626.57,"id":9570503},{"atb":[[24,2.68]],"id":46969227}],"tv":1011.79}]}
{"op":"mcm","clk":"APkFAIoDAJ0F","pt":1659347412337,"mc":[{"id":"1.201590187","rc":[{"bdatb":[[0,1.98,36.93]],"bdatl":[[8,2.38,52.32],[9,2.4,72.94]],"id":9570503},{"bdatl":[[8,18.5,9.62],[9,26,1.04]],"id":12989514},{"bdatl":[[9,15,17.32]],"id":44836671},{"bdatb":[[1,24,2.68]],"id":46969227}]}]}
{"op":"mcm","clk":"APwFAIsDAKAF","pt":1659347412397,"mc":[{"id":"1.201590187","rc":[{"atb":[[1.98,38.19]],"atl":[[2.1,7.41]],"id":9570503}]}]}
{"op":"mcm","clk":"AP8FAI4DAKIF","pt":1659347412447,"mc":[{"id":"1.201590187","rc":[{"bdatb":[[0,1.98,38.19]],"bdatl":[[0,2.1,7.41]],"id":9570503},{"bdatb":[[7,5.3,2.11],[8,5.1,1.57]],"id":12989514},{"bdatb":[[6,12,1.09],[7,10,102.25]],"id":44621159},{"bdatb":[[9,5.3,2.54]],"id":44836671},{"bdatb":[[6,6.4,3.72],[7,6.2,10.39],[8,6,14.07]],"id":43885158},{"bdatb":[[7,12.5,1.05],[8,10,2.24]],"id":46969227}]}]}
{"op":"mcm","clk":"AIAGAI8DAKcF","pt":1659347412498,"mc":[{"id":"1.201590187","rc":[{"atb":[[13,1.69]],"id":45323444},{"atb":[[24,0.49]],"id":44621159},{"atb":[[7.8,1.26]],"id":43885158}]}]}
{"op":"mcm","clk":"AIYGAJIDAKcF","pt":1659347412548,"mc":[{"id":"1.201590187","rc":[{"bdatb":[[0,13,1.69]],"id":45323444},{"bdatl":[[8,2.38,33.75],[9,2.4,72.3]],"id":9570503},{"bdatl":[[7,18.5,8.58],[8,29,1.34],[9,30,8]],"id":12989514},{"bdatb":[[0,23,1.49],[1,21,5],[2,18.5,1.37],[3,18,4.19],[4,15.5,5.99],[5,12,1.09],[6,10,102.25],[7,9.6,1.68],[8,9.4,11.02],[9,9.2,2.5]],"id":44621159},{"bdatl":[[8,14,3.68],[9,15,14.86]],"id":44836671},{"bdatb":[[1,7.8,1.26]],"id":43885158}]}]}
{"op":"mcm","clk":"AI4GAJcDALQF","pt":1659347412700,"mc":[{"id":"1.201590187","rc":[{"atb":[[12.5,7.36]],"id":45323444},{"atb":[[7.4,13.96]],"id":43885158}]}]}
{"op":"mcm","clk":"AJEGAJcDALUF","pt":1659347412751,"mc":[{"id":"1.201590187","rc":[{"bdatb":[[1,12.5,7.36]],"id":45323444},{"bdatl":[[8,26,2.13],[9,30,8.93]],"id":12989514},{"bdatb":[[2,7.4,13.96]],"id":43885158}]}]}
{"op":"mcm","clk":"AJoGAJ4DAMEF","pt":1659347412907,"mc":[{"id":"1.201590187","rc":[{"atb":[[15.5,4.19],[22,2.59]],"id":44621159}]}]}
{"op":"mcm","clk":"AJ8GAJ8DAMEF","pt":1659347412957,"mc":[{"id":"1.201590187","rc":[{"bdatl":[[8,25,2.19],[9,30,8.98]],"id":12989514},{"bdatb":[[1,22,2.59],[2,21,5],[3,18.5,1.37],[4,18,4.19],[5,15.5,4.19],[6,12,1.09],[7,10,102.25],[8,9.6,1.68],[9,9.4,11.02]],"id":44621159}]}]}
{"op":"mcm","clk":"AKYGAKEDAMcF","pt":1659347413007,"mc":[{"id":"1.201590187","rc":[{"atb":[[15,1.8]],"bdatb":[[6,15,1.8],[7,12,1.09],[8,10,102.25],[9,9.6,1.68]],"id":44621159}]}]}
{"op":"mcm","clk":"AKgGAKQDAMsF","pt":1659347413073,"mc":[{"id":"1.201590187","rc":[{"atb":[[12.5,6.74]],"id":45323444}]}]}
{"op":"mcm","clk":"AK8GAKUDAM4F","pt":1659347413123,"mc":[{"id":"1.201590187","rc":[{"bdatb":[[1,12.5,6.74]],"id":45323444}]}]}
{"op":"mcm","clk":"ALMGAKYDANAF","pt":1659347413182,"mc":[{"id":"1.201590187","rc":[{"atb":[[13.5,0.62]],"id":45323444},{"atb":[[7.4,16.94]],"id":43885158}]}]}
{"op":"mcm","clk":"ALUGAKYDANIF","pt":1659347413232,"mc":[{"id":"1.201590187","rc":[{"bdatb":[[0,13,2.31]],"id":45323444},{"bdatl":[[4,2.3,2.79],[5,2.32,2.55],[6,2.34,2.49],[8,2.38,34.63],[9,2.4,71.43]],"id":9570503},{"bdatl":[[7,17.5,1],[8,18.5,7.73],[9,25,2.1]],"id":12989514},{"bdatl":[[6,13,42.55],[7,13.5,1.98],[9,15,15]],"id":44836671},{"bdatb":[[2,7.4,16.94]],"id":43885158}]}]}
{"op":"mcm","clk":"AOAGALIDAPoF","pt":1659347413694,"mc":[{"id":"1.201590187","rc":[{"atb":[[12.5,2.14]],"id":45323444},{"atb":[[22,0]],"id":44621159},{"atb":[[7.4,9.18]],"id":43885158}]}]}
{"op":"mcm","clk":"AOMGALUDAPwF","pt":1659347413744,"mc":[{"id":"1.201590187","rc":[{"bdatb":[[1,12.5,2.14]],"id":45323444},{"bdatl":[[9,26,1.33]],"id":12989514},{"bdatb":[[1,21,5],[2,18.5,1.37],[3,18,4.19],[4,15.5,4.19],[5,15,1.8],[6,12,1.09],[7,10,102.25],[8,9.6,1.68],[9,9.4,11.02]],"id":44621159},{"bdatb":[[2,7.4,9.18]],"id":43885158}]}]}
{"op":"mcm","clk":"AO0GALoDAIoG","pt":1659347413904,"mc":[{"id":"1.201590187","rc":[{"atb":[[13,6.12]],"id":45323444},{"atb":[[7.6,7.58]],"id":43885158}]}]}
{"op":"mcm","clk":"AO8GAL0DAIoG","pt":1659347413954,"mc":[{"id":"1.201590187","rc":[{"bdatb":[[0,13,6.74]],"id":45323444},{"bdatl":[[9,2.4,71.82]],"id":9570503},{"bdatl":[[9,22,2.37]],"id":12989514},{"bdatb":[[2,7.6,7.58],[3,7.4,9.18],[4,7.2,8.24],[5,7,5],[6,6.6,13.32],[7,6.4,3.72],[8,6.2,10.39],[9,6,14.07]],"id":43885158}]}]}
{"op":"mcm","clk":"APgGAMIDAJUG","pt":1659347414110,"mc":[{"id":"1.201590187","rc":[{"atb":[[23,3.47]],"id":44621159}]}]}
{"op":"mcm","clk":"AP8GAMIDAJgG","pt":1659347414160,"mc":[{"id":"1.201590187","rc":[{"bdatl":[[9,21,2.46]],"id":12989514},{"bdatb":[[0,23,3.96]],"id":44621159}]}]}
{"op":"mcm","clk":"AIsHAMkDAJ8G","pt":1659347414270,"mc":[{"id":"1.201590187","rc":[{"atl":[[2,25]],"id":9570503}]}]}
{"op":"mcm","clk":"AJEHAMoDAKMG","pt":1659347414320,"mc":[{"id":"1.201590187","rc":[{"bdatb":[[3,11.5,5.72],[4,11,2.23],[5,10.5,5.11]],"id":45323444},{"bdatl":[[0,2,25],[1,2.1,7.41],[2,2.12,20.6],[3,2.14,55.67],[4,2.18,1.18],[5,2.3,2.79],[6,2.32,2.55],[7,2.34,2.49],[8,2.36,3.09],[9,2.38,34.63]],"id":9570503},{"bdatb":[[0,7.4,3.19],[1,7.2,8.14],[5,6.4,1.41],[6,6.2,4.03],[7,5.4,2.88],[8,5.2,5.4],[9,5.1,1.8]],"id":12989514},{"bdatb":[[2,18.5,1.49],[4,15.5,5.01],[6,12.5,2.56],[7,10,102.16],[9,9.4,10.96]],"id":44621159},{"bdatb":[[1,6.2,10.01],[2,6,32.45],[7,5.5,24.64],[8,5.4,18.58],[9,5.1,33.59]],"id":44836671},{"bdatb":[[1,7.8,1.53],[2,7.6,9.04],[3,7.4,9.57],[6,6.6,14.37],[7,6.4,5.9],[8,6.2,10],[9,6,14]],"id":43885158},{"bdatb":[[6,16,2.35],[7,12.5,2.68],[8,10,2.02],[9,9.2,1.67]],"id":46969227}]}]}
{"op":"mcm","clk":"AJYHAM0DAKYG","pt":1659347414379,"mc":[{"id":"1.201590187","rc":[{"atl":[[2,5.26]],"trd":[[2,54.58]],"ltp":2,"tv":666.05,"id":9570503}],"tv":1051.27}]}
{"op":"mcm","clk":"AJgHAM4DAKYG","pt":1659347414429,"mc":[{"id":"1.201590187","rc":[{"bdatb":[[4,11,1.99],[5,10.5,1.6]],"id":45323444},{"bdatl":[[0,2,5.26]],"id":9570503},{"bdatb":[[1,7.2,7.38],[5,5.6,2.52],[6,5.4,4.26],[7,5.3,3.63],[8,5,7.1],[9,4.9,6.65]],"id":12989514},{"bdatb":[[4,15.5,4.69],[6,10,102.47],[7,9.6,2.71],[8,9.4,10.05],[9,9.2,2.39]],"id":44621159},{"bdatb":[[2,6,31.53],[7,5.5,23],[8,5.4,14],[9,5.3,1.03]],"id":44836671},{"bdatb":[[2,7.6,8.69],[3,7.4,9.18],[6,6.6,13],[7,6.4,2.41],[8,6.2,10.46]],"id":43885158},{"bdatb":[[6,16,2.03],[7,10,3.35],[8,9.4,2.45],[9,9,1.16]],"id":46969227}]}]}
{"op":"mcm","clk":"AKAHAM8DAKsG","pt":1659347414489,"mc":[{"id":"1.201590187","rc":[{"atl":[[2,0]],"trd":[[2,65.1]],"tv":676.57,"id":9570503}],"tv":1061.79}]}
{"op":"mcm","clk":"AKIHANEDAKsG","pt":1659347414539,"mc":[{"id":"1.201590187","rc":[{"bdatb":[[3,11.5,5.54],[4,11,1.23]],"id":45323444},{"bdatl":[[0,2.1,7.41],[1,2.12,20.6],[2,2.14,55.67],[3,2.18,1.18],[4,2.3,2.79],[5,2.32,2.55],[6,2.34,2.49],[7,2.36,3.09],[8,2.38,34.63],[9,2.4,71.82]],"id":9570503},{"bdatb":[[0,7.4,2.9],[1,7.2,6.21],[5,6,2.66],[6,5.4,5.93],[7,5.3,2.11],[8,5.1,1.57],[9,5,7.12]],"id":12989514},{"bdatb":[[2,18.5,1.37],[4,15.5,4.19],[6,12,1.09],[7,10,102.25],[8,9.6,1.68],[9,9.4,11.02]],"id":44621159},{"bdatb":[[1,6.2,9.67],[2,6,30.13],[7,5.5,23.38],[9,5.3,2.54]],"id":44836671},{"bdatb":[[1,7.8,1.26],[2,7.6,7.58],[6,6.6,13.32],[7,6.4,3.72],[8,6.2,10.39],[9,6,14.07]],"id":43885158},{"bdatb":[[6,16,1.43],[7,12.5,1.05],[8,10,2.24],[9,9.4,3.39]],"id":46969227}]}]}
{"op":"mcm","clk":"AMIHANwDAMsG","pt":1659347414907,"mc":[{"id":"1.201590187","rc":[{"atl":[[36,1.41]],"id":46969227}]}]}
{"op":"mcm","clk":"AMQHAOQDAM0G","pt":1659347414958,"mc":[{"id":"1.201590187","rc":[{"bdatl":[[1,36,1.41]],"id":46969227}]}]}
{"op":"mcm","clk":"AMsHAOkDANgG","pt":1659347415097,"mc":[{"id":"1.201590187","rc":[{"atb":[[13,1.69]],"id":45323444},{"atb":[[23,1]],"id":44621159},{"atb":[[6.2,11.69]],"id":44836671},{"atb":[[7.6,0]],"id":43885158}]}]}
{"op":"mcm","clk":"ANEHAOsDANoG","pt":1659347415147,"mc":[{"id":"1.201590187","rc":[{"bdatb":[[0,13,2.31]],"id":45323444},{"bdatl":[[9,2.4,71.43]],"id":9570503},{"bdatl":[[9,26,1.33]],"id":12989514},{"bdatb":[[0,23,1.49]],"id":44621159},{"bdatb":[[1,6.2,12.06]],"id":44836671},{"bdatb":[[2,7.4,9.18],[3,7.2,8.24],[4,7,5],[5,6.6,13.32],[6,6.4,3.72],[7,6.2,10.39],[8,6,14.07],[9,5.9,4]],"id":43885158}]}]}
{"op":"mcm","clk":"ANkHAO4DAOMG","pt":1659347415301,"mc":[{"id":"1.201590187","rc":[{"atb":[[13.5,4.87]],"id":45323444},{"atb":[[7.8,8.62]],"id":43885158}]}]}
{"op":"mcm","clk":"AN4HAO4DAOUG","pt":1659347415351,"mc":[{"id":"1.201590187","rc":[{"bdatb":[[0,13.5,4.87],[1,13,1.69],[2,12.5,2.14],[3,12,2.87],[4,11.5,5.54],[5,11,1.23],[6,10.5,1.6],[7,10,11.5],[8,9.8,9],[9,9.6,21]],"id":45323444},{"bdatl":[[5,2.32,4.06],[6,2.34,4.11],[7,2.36,1.49],[8,2.38,37.7],[9,2.4,84.31]],"id":9570503},{"bdatl":[[7,16.5,1.02],[8,18,1.17],[9,18.5,7.2]],"id":12989514},{"bdatl":[[6,13,43],[7,13.5,1.55],[8,14,4.2],[9,15,15.23]],"id":44836671},{"bdatb":[[1,7.8,8.62]],"id":43885158}]}]}
{"op":"mcm","clk":"AOgHAPYDAPMG","pt":1659347415510,"mc":[{"id":"1.201590187","rc":[{"atb":[[9.4,28.24]],"id":45323444},{"atb":[[1.77,50.78]],"id":9570503},{"atb":[[3.7,31.24]],"id":12989514},{"atb":[[9.4,27.29],[24,2.91]],"id":44621159},{"atb":[[6,47.37]],"id":44836671},{"atb":[[6.6,30.24]],"id":43885158},{"atb":[[9.4,17.24]],"id":46969227}]}]}
{"op":"mcm","clk":"AOkHAPcDAPMG","pt":1659347415560,"mc":[{"id":"1.201590187","rc":[{"bdatl":[[5,2.32,5.06],[6,2.34,3.12],[7,2.36,18.77],[8,2.38,33.71],[9,2.4,72.94]],"id":9570503},{"bdatl":[[7,16,1.02],[8,17.5,2.97],[9,18.5,7.42]],"id":12989514},{"bdatb":[[0,24,2.91],[1,23,1],[2,21,5],[3,18.5,1.37],[4,18,4.19],[5,15.5,4.19],[6,15,1.8],[7,12,1.09],[8,10,102.25],[9,9.6,1.68]],"id":44621159},{"bdatb":[[2,6,47.37]],"bdatl":[[7,13.5,2.09],[8,14,3.93],[9,14.5,2.92]],"id":44836671},{"bdatb":[[5,6.6,30.56]],"id":43885158},{"bdatb":[[9,9.4,20.63]],"id":46969227}]}]}
{"op":"mcm","clk":"APYHAP4DAP4G","pt":1659347415778,"mc":[{"id":"1.201590187","rc":[{"atl":[[22,1.41]],"id":45323444}]}]}
{"op":"mcm","clk":"APkHAIAEAIMH","pt":1659347415828,"mc":[{"id":"1.201590187","rc":[{"bdatl":[[1,22,1.41],[2,23,1],[3,24,1.9],[4,25,1.67],[5,26,5.72],[6,27,3.85],[7,29,5.36],[8,32,6.46],[9,50,8]],"id":45323444},{"bdatb":[[6,1.83,50.51],[7,1.82,49.36],[8,1.81,9.65],[9,1.8,2.87]],"id":9570503},{"bdatb":[[6,5.4,6.26],[7,5.3,1.78],[8,5.2,1.54],[9,5,7.11]],"id":12989514},{"bdatb":[[9,9.6,3.23]],"id":46969227}]}]}
{"op":"mcm","clk":"APsHAIIEAIUH","pt":1659347415881,"mc":[{"id":"1.201590187","rc":[{"atb":[[14,1]],"id":45323444}]}]}
{"op":"mcm","clk":"AP4HAIMEAIYH","pt":1659347415932,"mc":[{"id":"1.201590187","rc":[{"bdatb":[[0,14,1],[1,13.5,4.87],[2,13,1.69],[3,12.5,2.14],[4,12,2.87],[5,11.5,5.54],[6,11,1.23],[7,10.5,1.6],[8,10,11.5],[9,9.8,9]],"id":45323444},{"bdatl":[[4,2.3,7.81],[5,2.34,3.21],[6,2.36,18.94],[7,2.38,33.55],[8,2.4,77.1],[9,2.44,152.77]],"id":9570503},{"bdatl":[[7,15.5,1.03],[8,17.5,3.21],[9,18.5,7.52]],"id":12989514},{"bdatl":[[5,12,1.62],[6,13,42.83],[9,14.5,2.94]],"id":44836671}]}]}
{"op":"mcm","clk":"AJEIAJMEAJUH","pt":1659347416304,"mc":[{"id":"1.201590187","rc":[{"atb":[[13.5,0.62]],"id":45323444},{"atb":[[1.94,2.37]],"atl":[[2.12,18.48]],"id":9570503},{"atb":[[24,0.49]],"id":44621159},{"atb":[[7.8,1.26]],"id":43885158}]}]}
{"op":"mcm","clk":"AJYIAJgEAJcH","pt":1659347416354,"mc":[{"id":"1.201590187","rc":[{"bdatb":[[1,13,2.31],[2,12.5,2.14],[3,12,2.87],[4,11.5,5.54],[5,11,1.23],[6,10.5,1.6],[7,10,11.5],[8,9.8,9],[9,9.6,21]],"id":45323444},{"bdatb":[[4,1.94,2.37],[5,1.91,108.46],[6,1.89,7.35],[7,1.83,50.51],[8,1.82,49.36],[9,1.81,9.65]],"bdatl":[[1,2.12,18.48],[4,2.3,6.89],[5,2.34,4.12],[6,2.38,34.64],[7,2.4,71.43],[8,2.44,156.53],[9,2.46,3.85]],"id":9570503},{"bdatb":[[7,5.2,3.34],[8,5,7.11],[9,4.9,8.03]],"bdatl":[[7,16,1.03],[8,18.5,7.77],[9,26,1.92]],"id":12989514},{"bdatb":[[0,23,1.49],[1,21,5],[2,18.5,1.37],[3,18,4.19],[4,15.5,4.19],[5,15,1.8],[6,12,1.09],[7,10,102.25],[8,9.6,1.68],[9,9.4,30.59]],"id":44621159},{"bdatl":[[6,13,42.82],[7,13.5,1.55],[8,14,4.2],[9,15,14.49]],"id":44836671},{"bdatb":[[1,7.8,1.26]],"id":43885158}]}]}
{"op":"mcm","clk":"AKMIAKAEAJgH","pt":1659347416436,"mc":[{"id":"1.201590187","rc":[{"atb":[[13,0]],"id":45323444}]}]}
{"op":"mcm","clk":"AK8IAKYEALUH","pt":1659347416489,"mc":[{"id":"1.201590187","rc":[{"bdatb":[[1,12.5,2.76],[2,12,2.87],[3,11.5,5.54],[4,11,1.23],[5,10.5,1.6],[6,10,11.5],[7,9.8,9],[8,9.6,21],[9,9.4,28.24]],"id":45323444},{"bdatl":[[6,2.38,33.93],[7,2.4,72.13],[8,2.44,152.47],[9,2.46,4.01]],"id":9570503},{"bdatl":[[8,18.5,7.68],[9,26,1.09]],"id":12989514},{"bdatl":[[9,15,14.38]],"id":44836671}]}]}
{"op":"mcm","clk":"ALcIAK0EALsH","pt":1659347416545,"mc":[{"id":"1.201590187","rc":[{"atb":[[13,4.42]],"id":45323444},{"atb":[[1.94,0]],"atl":[[2.12,20.74]],"id":9570503},{"atb":[[7.6,7.58]],"id":43885158}]}]}
{"op":"mcm","clk":"ALoIAK8EAL0H","pt":1659347416595,"mc":[{"id":"1.201590187","rc":[{"bdatb":[[1,13,5.04],[2,12.5,2.14],[3,12,2.87],[4,11.5,5.54],[5,11,1.23],[6,10.5,1.6],[7,10,11.5],[8,9.8,9],[9,9.6,21]],"id":45323444},{"bdatb":[[4,1.91,108.46],[5,1.89,7.35],[6,1.83,50.51],[7,1.82,49.36],[8,1.81,9.65],[9,1.8,2.87]],"bdatl":[[1,2.12,20.74],[6,2.38,34.64],[7,2.4,71.82],[8,2.42,4.08],[9,2.44,164.92]],"id":9570503},{"bdatb":[[7,5.3,1.84],[8,5.2,1.49],[9,5,7.11]],"bdatl":[[8,18.5,7.77],[9,22,2.37]],"id":12989514},{"bdatl":[[9,15,14.49]],"id":44836671},{"bdatb":[[2,7.6,7.58],[3,7.4,9.18],[4,7.2,8.24],[5,7,5],[6,6.6,30.56],[7,6.4,3.72],[8,6.2,10.39],[9,6,14.07]],"id":43885158}]}]}
{"op":"mcm","clk":"APIIANkEAO4H","pt":1659347417214,"mc":[{"id":"1.201590187","rc":[{"atb":[[23,0],[22,1]],"id":44621159},{"atl":[[36,1]],"id":46969227}]}]}
{"op":"mcm","clk":"APoIANoEAO8H","pt":1659347417264,"mc":[{"id":"1.201590187","rc":[{"bdatl":[[5,2.34,1.01],[6,2.36,3.09],[7,2.38,33.92],[8,2.4,72.13],[9,2.42,4.05]],"id":9570503},{"bdatl":[[7,16.5,1.03],[8,18.5,7.66],[9,22,2.46]],"id":12989514},{"bdatb":[[0,22,1.49]],"id":44621159},{"bdatl":[[6,13,42.81],[7,13.5,1.57],[9,15,14.38]],"id":44836671},{"bdatl":[[1,36,1]],"id":46969227}]}]}
{"op":"mcm","clk":"AP8IAN0EAPYH","pt":1659347417326,"mc":[{"id":"1.201590187","rc":[{"atb":[[22,3.59]],"id":44621159}]}]}
{"op":"mcm","clk":"AIcJAN4EAPgH","pt":1659347417376,"mc":[{"id":"1.201590187","rc":[{"bdatl":[[9,2.42,17.4]],"id":9570503},{"bdatl":[[9,21,2.55]],"id":12989514},{"bdatb":[[0,22,4.08]],"id":44621159}]}]}
{"op":"mcm","clk":"ANYJAIoFAKUI","pt":1659347418117,"mc":[{"id":"1.201590187","rc":[{"atb":[[13,0]],"bdatb":[[1,12.5,2.76],[2,12,2.87],[3,11.5,5.54],[4,11,1.23],[5,10.5,1.6],[6,10,11.5],[7,9.8,9],[8,9.6,21],[9,9.4,28.24]],"id":45323444},{"atb":[[22,1]],"bdatb":[[0,22,1.49]],"id":44621159},{"atb":[[7.6,0]],"bdatb":[[2,7.4,9.18],[3,7.2,8.24],[4,7,5],[5,6.6,30.56],[6,6.4,3.72],[7,6.2,10.39],[8,6,14.07],[9,5.9,4]],"id":43885158},{"bdatl":[[8,2.4,71.43],[9,2.44,152.79]],"id":9570503},{"bdatl":[[9,26,1.07]],"id":12989514}]}]}
{"op":"mcm","clk":"AOEJAI4FALcI","pt":1659347418233,"mc":[{"id":"1.201590187","rc":[{"atb":[[12.5,6.74]],"id":45323444},{"atb":[[7.8,8.62]],"id":43885158}]}]}
{"op":"mcm","clk":"AOYJAJIFALsI","pt":1659347418283,"mc":[{"id":"1.201590187","rc":[{"bdatb":[[1,12.5,7.36]],"id":45323444},{"bdatl":[[9,2.42,4.75]],"id":9570503},{"bdatl":[[9,22,2.45]],"id":12989514},{"bdatb":[[1,7.8,8.62]],"id":43885158}]}]}
{"op":"mcm","clk":"AO8JAJkFAMEI","pt":1659347418389,"mc":[{"id":"1.201590187","rc":[{"atb":[[23,2.47]],"id":44621159}]}]}
{"op":"mcm","clk":"AO8JAJkFAMEI","pt":1659347418439,"mc":[{"id":"1.201590187","rc":[{"bdatl":[[5,2.34,4.12],[6,2.38,33.93],[7,2.4,72.52],[8,2.42,17.02],[9,2.44,158.34]],"id":9570503},{"bdatl":[[7,16,1.03],[8,18.5,7.68],[9,20,2.32]],"id":12989514},{"bdatb":[[0,23,2.96],[1,22,1],[2,21,5],[3,18.5,1.37],[4,18,4.19],[5,15.5,4.19],[6,15,1.8],[7,12,1.09],[8,10,102.25],[9,9.6,1.68]],"id":44621159},{"bdatl":[[6,13,42.82],[7,13.5,1.55]],"id":44836671}]}]}
{"op":"mcm","clk":"AJsKALwFAN8I","pt":1659347418929,"mc":[{"id":"1.201590187","rc":[{"atl":[[2.1,2.91]],"trd":[[2.1,31.98]],"ltp":2.1,"tv":685.57,"id":9570503}],"tv":1070.79}]}
{"op":"mcm","clk":"AJ8KAL4FAOMI","pt":1659347418979,"mc":[{"id":"1.201590187","rc":[{"bdatl":[[0,2.1,2.91]],"id":9570503},{"bdatb":[[7,5.2,3.35],[8,5,7.11],[9,4.9,8.03]],"id":12989514},{"bdatb":[[7,11.5,1.11],[8,10,102.26]],"id":44621159},{"bdatb":[[9,5.2,2.66]],"id":44836671},{"bdatb":[[6,6.4,2.63],[7,6.2,11.13],[8,6,14.48]],"id":43885158},{"bdatb":[[7,11.5,1.35],[8,10,2]],"id":46969227}]}]}
{"op":"mcm","clk":"AKsKAMYFAOkI","pt":1659347419092,"mc":[{"id":"1.201590187","rc":[{"atb":[[12.5,2.14]],"id":45323444},{"atb":[[23,0]],"id":44621159},{"atb":[[7.8,1.26]],"id":43885158}]}]}
{"op":"mcm","clk":"AKsKAMoFAOsI","pt":1659347419149,"mc":[{"id":"1.201590187","rc":[{"bdatb":[[1,12.5,2.76]],"id":45323444},{"bdatl":[[5,2.34,1.01],[6,2.36,3.09],[7,2.38,33.92],[8,2.4,71.43],[9,2.44,152.79]],"id":9570503},{"bdatl":[[7,16.5,1.03],[8,18.5,7.66],[9,26,1.07]],"id":12989514},{"bdatb":[[0,22,1.49],[1,21,5],[2,18.5,1.37],[3,18,4.19],[4,15.5,4.19],[5,15,1.8],[6,11.5,1.11],[7,10,102.26],[8,9.6,1.68],[9,9.4,30.59]],"id":44621159},{"bdatl":[[6,13,42.81],[7,13.5,1.57]],"id":44836671},{"bdatb":[[1,7.8,1.26]],"id":43885158}]}]}
{"op":"mcm","clk":"ALwKANEFAO8I","pt":1659347419299,"mc":[{"id":"1.201590187","rc":[{"atb":[[13,4.42]],"id":45323444},{"atb":[[7.6,7.58]],"id":43885158}]}]}
{"op":"mcm","clk":"AMIKANIFAPII","pt":1659347419349,"mc":[{"id":"1.201590187","rc":[{"bdatb":[[1,13,5.04],[2,12.5,2.14],[3,12,2.87],[4,11.5,5.54],[5,11,1.23],[6,10.5,1.6],[7,10,11.5],[8,9.8,9],[9,9.6,21]],"id":45323444},{"bdatl":[[8,2.4,72.13],[9,2.42,4.05]],"id":9570503},{"bdatl":[[9,22,2.46]],"id":12989514},{"bdatb":[[2,7.6,7.58],[3,7.4,9.18],[4,7.2,8.24],[5,7,5],[6,6.6,30.56],[7,6.4,2.63],[8,6.2,11.13],[9,6,14.48]],"id":43885158}]}]}
{"op":"mcm","clk":"AMoKANcFAPcI","pt":1659347419500,"mc":[{"id":"1.201590187","rc":[{"atb":[[22,3.59]],"id":44621159}]}]}
{"op":"mcm","clk":"AMwKANkFAPoI","pt":1659347419551,"mc":[{"id":"1.201590187","rc":[{"bdatl":[[9,2.42,17.4]],"id":9570503},{"bdatl":[[9,21,2.55]],"id":12989514},{"bdatb":[[0,22,4.08]],"id":44621159}]}]}
{"op":"mcm","clk":"AIMLAOkFAKMJ","pt":1659347420332,"mc":[{"id":"1.201590187","rc":[{"atb":[[13,0]],"id":45323444},{"atb":[[22,1]],"id":44621159},{"atb":[[7.6,0]],"id":43885158},{"atl":[[1000,0.41]],"id":46969227}]}]}
{"op":"mcm","clk":"AIgLAO0FAKUJ","pt":1659347420382,"mc":[{"id":"1.201590187","rc":[{"bdatb":[[1,12.5,2.76],[2,12,2.87],[3,11.5,5.54],[4,11,1.23],[5,10.5,1.6],[6,10,11.5],[7,9.8,9],[8,9.6,21],[9,9.4,28.24]],"id":45323444},{"bdatl":[[8,2.4,71.43],[9,2.44,152.79]],"id":9570503},{"bdatl":[[9,26,1.07]],"id":12989514},{"bdatb":[[0,22,1.49]],"id":44621159},{"bdatb":[[2,7.4,9.18],[3,7.2,8.24],[4,7,5],[5,6.6,30.56],[6,6.4,2.63],[7,6.2,11.13],[8,6,14.48],[9,5.9,4]],"id":43885158},{"bdatl":[[7,1000,0.41]],"id":46969227}]}]}
{"op":"mcm","clk":"AJELAPEFAKoJ","pt":1659347420522,"mc":[{"id":"1.201590187","rc":[{"atb":[[9.4,45.48],[12.5,6.74]],"id":45323444},{"atb":[[3.7,48.48]],"id":12989514},{"atb":[[9.4,44.53]],"id":44621159},{"atb":[[6,64.61]],"id":44836671},{"atb":[[6.6,47.48],[7.8,8.62]],"id":43885158},{"atl":[[1000,0]],"id":46969227}]}]}
{"op":"mcm","clk":"AJkLAPIFAKwJ","pt":1659347420572,"mc":[{"id":"1.201590187","rc":[{"bdatb":[[1,12.5,7.36],[9,9.4,45.48]],"id":45323444},{"bdatl":[[9,2.42,4.75]],"id":9570503},{"bdatl":[[9,22,2.45]],"id":12989514},{"bdatb":[[9,9.4,47.83]],"id":44621159},{"bdatb":[[2,6,64.61]],"id":44836671},{"bdatb":[[1,7.8,8.62],[5,6.6,47.79]],"id":43885158},{"bdatl":[[7,0,0]],"id":46969227}]}]}
{"op":"mcm","clk":"AKALAPwFALIJ","pt":1659347420622,"mc":[{"id":"1.201590187","rc":[{"atb":[[1.77,68.02]],"id":9570503},{"atb":[[9.4,34.48]],"atl":[[32,1.56]],"id":46969227}]}]}
{"op":"mcm","clk":"AKALAPwFALMJ","pt":1659347420672,"mc":[{"id":"1.201590187","rc":[{"bdatb":[[5,1.9,5.81],[6,1.89,1.52],[7,1.83,52.01],[8,1.82,49.07],[9,1.81,8.41]],"id":9570503},{"bdatb":[[5,6,2.64],[6,5.5,5.64],[7,5.2,3.86]],"id":12989514},{"bdatb":[[6,11.5,1.35],[7,10,102],[8,9.6,4.91],[9,9.4,44.85]],"id":44621159},{"bdatb":[[8,5.4,14.74],[9,5.3,1.32]],"id":44836671},{"bdatb":[[7,6.2,11.6],[8,6,14]],"id":43885158},{"bdatl":[[0,32,1.63],[1,34,5.51],[2,36,1],[3,38,2.51],[4,40,5.01],[5,80,1.66],[6,310,1],[7,990,2.15]],"id":46969227}]}]}
{"op":"mcm","clk":"AKYLAIEGALkJ","pt":1659347420722,"mc":[{"id":"1.201590187","rc":[{"atb":[[23,2.47]],"bdatb":[[0,23,2.96],[1,22,1],[2,21,5],[3,18.5,1.37],[4,18,4.19],[5,15.5,4.19],[6,15,1.8],[7,11.5,1.35],[8,10,102],[9,9.6,4.91]],"id":44621159},{"bdatl":[[5,2.34,4.12],[6,2.38,33.93],[7,2.4,72.52],[8,2.42,17.02],[9,2.44,158.34]],"id":9570503},{"bdatl":[[7,16,1.03],[8,18.5,7.68],[9,20,2.32]],"id":12989514},{"bdatl":[[6,13,42.82],[7,13.5,1.55]],"id":44836671}]}]}
{"op":"mcm","clk":"AK4LAIUGALsJ","pt":1659347420801,"mc":[{"id":"1.201590187","rc":[{"atl":[[24,0.75]],"id":45323444}]}]}
{"op":"mcm","clk":"ALALAIcGAL8J","pt":1659347420852,"mc":[{"id":"1.201590187","rc":[{"bdatl":[[3,25,2.42],[4,26,5.72],[5,27,3.85],[6,29,5.36],[7,32,6.46],[8,50,8],[9,55,9]],"id":45323444},{"bdatb":[[9,4.9,5.51]],"id":12989514}]}]}
{"op":"mcm","clk":"ANcLAJYGANoJ","pt":1659347421421,"mc":[{"id":"1.201590187","rc":[{"atb":[[12.5,2.14]],"id":45323444},{"atb":[[23,0]],"id":44621159},{"atb":[[7.8,1.26]],"id":43885158}]}]}
{"op":"mcm","clk":"ANsLAJgGAN0J","pt":1659347421471,"mc":[{"id":"1.201590187","rc":[{"bdatb":[[1,12.5,2.76]],"id":45323444},{"bdatl":[[5,2.34,1.01],[6,2.36,3.09],[7,2.38,33.92],[8,2.4,71.43],[9,2.44,152.79]],"id":9570503},{"bdatl":[[7,16.5,1.03],[8,18.5,7.66],[9,26,1.07]],"id":12989514},{"bdatb":[[0,22,1.49],[1,21,5],[2,18.5,1.37],[3,18,4.19],[4,15.5,4.19],[5,15,1.8],[6,11.5,1.35],[7,10,102],[8,9.6,4.91],[9,9.4,44.85]],"id":44621159},{"bdatl":[[6,13,42.81],[7,13.5,1.57]],"id":44836671},{"bdatb":[[1,7.8,1.26]],"id":43885158}]}]}
{"op":"mcm","clk":"AN4LAJkGAN4J","pt":1659347421521,"mc":[{"id":"1.201590187","rc":[{"atb":[[13,4.42]],"id":45323444},{"atb":[[7.6,7.58]],"id":43885158}]}]}
{"op":"mcm","clk":"AOELAJoGAOIJ","pt":1659347421571,"mc":[{"id":"1.201590187","rc":[{"bdatb":[[1,13,5.04],[2,12.5,2.14],[3,12,2.87],[4,11.5,5.54],[5,11,1.23],[6,10.5,1.6],[7,10,11.5],[8,9.8,9],[9,9.6,21]],"id":45323444},{"bdatl":[[8,2.4,72.13],[9,2.42,4.05]],"id":9570503},{"bdatl":[[9,22,2.46]],"id":12989514},{"bdatb":[[2,7.6,7.58],[3,7.4,9.18],[4,7.2,8.24],[5,7,5],[6,6.6,47.79],[7,6.4,2.63],[8,6.2,11.6],[9,6,14]],"id":43885158}]}]}
{"op":"mcm","clk":"AOsLAJ4GAOQJ","pt":1659347421715,"mc":[{"id":"1.201590187","rc":[{"atb":[[22,3.59]],"id":44621159}]}]}
{"op":"mcm","clk":"AO4LAJ4GAOUJ","pt":1659347421765,"mc":[{"id":"1.201590187","rc":[{"bdatl":[[9,2.42,17.4]],"id":9570503},{"bdatl":[[9,21,2.55]],"id":12989514},{"bdatb":[[0,22,4.08]],"id":44621159}]}]}
{"op":"mcm","clk":"APcLAKUGAO8J","pt":1659347421933,"mc":[{"id":"1.201590187","rc":[{"atb":[[13.5,0]],"id":45323444},{"atb":[[1.04,0]],"id":44621159}]}]}
{"op":"mcm","clk":"AP4LAKYGAPQJ","pt":1659347421983,"mc":[{"id":"1.201590187","rc":[{"atb":[[13,5.05]],"bdatb":[[1,13,4.42]],"id":45323444},{"atl":[[9.4,3.67]],"bdatl":[[8,18.5,7.21],[9,21,2.78]],"id":12989514},{"atb":[[23,1.13]],"id":44621159},{"atl":[[10.5,3.28]],"id":43885158},{"bdatl":[[5,2.36,1.01],[6,2.38,36.61],[7,2.4,72.5],[8,2.42,17.4],[9,2.44,154.28]],"id":9570503},{"bdatl":[[7,13.5,1.55],[8,14,3.69],[9,15,14.83]],"id":44836671}]}]}
{"op":"mcm","clk":"AIMMAKcGAPcJ","pt":1659347422033,"mc":[{"id":"1.201590187","rc":[{"bdatb":[[1,13,5.05]],"id":45323444},{"bdatl":[[5,2.34,1.01],[6,2.36,3.09],[7,2.38,34.63],[8,2.4,71.82],[9,2.42,17.02]],"id":9570503},{"bdatl":[[2,9.4,3.67],[7,16,1.03],[8,18.5,7.74],[9,21,2.46]],"id":12989514},{"bdatb":[[0,23,1.62],[1,22,3.59],[2,21,5],[3,18.5,1.37],[4,18,4.19],[5,15.5,4.19],[6,15,1.8],[7,11.5,1.35],[8,10,102],[9,9.6,4.91]],"id":44621159},{"bdatl":[[7,13.5,1.57],[8,14,3.68],[9,15,15]],"id":44836671},{"bdatl":[[1,10.5,3.28]],"id":43885158}]}]}
{"op":"mcm","clk":"AJkMALIGAJEK","pt":1659347422411,"mc":[{"id":"1.201590187","rc":[{"atb":[[13,0.62]],"id":45323444},{"atb":[[7.6,0]],"id":43885158}]}]}
{"op":"mcm","clk":"AJ4MALMGAJMK","pt":1659347422461,"mc":[{"id":"1.201590187","rc":[{"bdatb":[[1,12.5,2.76],[2,12,2.87],[3,11.5,5.54],[4,11,1.23],[5,10.5,1.6],[6,10,11.5],[7,9.8,9],[8,9.6,21],[9,9.4,45.48]],"id":45323444},{"bdatl":[[7,2.38,33.79],[8,2.4,72.26],[9,2.44,152.47]],"id":9570503},{"bdatl":[[8,18.5,7.64],[9,25,1.12]],"id":12989514},{"bdatl":[[9,15,14.87]],"id":44836671},{"bdatb":[[2,7.4,9.18],[3,7.2,8.24],[4,7,5],[5,6.6,47.79],[6,6.4,2.63],[7,6.2,11.6],[8,6,14],[9,5.9,4]],"id":43885158}]}]}
{"op":"mcm","clk":"AKUMALgGAJoK","pt":1659347422615,"mc":[{"id":"1.201590187","rc":[{"atb":[[12.5,5.74]],"id":45323444},{"atb":[[7.8,8.62]],"id":43885158}]}]}
{"op":"mcm","clk":"AKsMALkGAJwK","pt":1659347422665,"mc":[{"id":"1.201590187","rc":[{"bdatb":[[1,12.5,6.36]],"id":45323444},{"bdatl":[[8,2.4,72.65],[9,2.42,17.02]],"id":9570503},{"bdatl":[[9,21,2.59]],"id":12989514},{"bdatb":[[1,7.8,8.62]],"id":43885158}]}]}
{"op":"mcm","clk":"AK8MALkGAJ8K","pt":1659347422718,"mc":[{"id":"1.201590187","rc":[{"atl":[[23,0]],"id":45323444}]}]}
{"op":"mcm","clk":"ALEMALoGAKAK","pt":1659347422768,"mc":[{"id":"1.201590187","rc":[{"bdatl":[[2,25,2.42],[3,26,5.72],[4,27,3.85],[5,29,5.36],[6,32,6.46],[7,50,8],[8,55,9],[9,60,10]],"id":45323444},{"bdatb":[[7,1.83,50.51],[8,1.82,49.36],[9,1.81,4.8]],"id":9570503},{"bdatb":[[7,5.1,3.92],[8,5,7.12],[9,4.8,235.62]],"id":12989514}]}]}
{"op":"mcm","clk":"ANMMAMgGAL4K","pt":1659347423320,"mc":[{"id":"1.201590187","rc":[{"atb":[[12.5,1.14]],"id":45323444},{"atb":[[22,1]],"id":44621159},{"atb":[[7.8,1.26]],"id":43885158}]}]}
{"op":"mcm","clk":"ANkMAMwGAMUK","pt":1659347423370,"mc":[{"id":"1.201590187","rc":[{"bdatb":[[1,12.5,1.76]],"id":45323444},{"bdatl":[[8,2.4,72.26],[9,2.44,152.47]],"id":9570503},{"bdatl":[[9,27,1.48]],"id":12989514},{"bdatb":[[1,22,1]],"id":44621159},{"bdatb":[[1,7.8,1.26]],"id":43885158}]}]}
{"op":"mcm","clk":"AOUMANQGANEK","pt":1659347423518,"mc":[{"id":"1.201590187","rc":[{"atb":[[13,5.05]],"id":45323444},{"atb":[[7.6,7.58]],"id":43885158}]}]}
{"op":"mcm","clk":"AOkMANQGANMK","pt":1659347423568,"mc":[{"id":"1.201590187","rc":[{"bdatb":[[1,13,5.05],[2,12.5,1.14],[3,12,2.87],[4,11.5,5.54],[5,11,1.23],[6,10.5,1.6],[7,10,11.5],[8,9.8,9],[9,9.6,21]],"id":45323444},{"bdatl":[[7,2.38,34.63],[8,2.4,71.82],[9,2.42,14.41]],"id":9570503},{"bdatl":[[8,18.5,7.74],[9,21,1.71]],"id":12989514},{"bdatl":[[9,15,15]],"id":44836671},{"bdatb":[[2,7.6,7.58],[3,7.4,9.18],[4,7.2,8.24],[5,7,5],[6,6.6,47.79],[7,6.4,2.63],[8,6.2,11.6],[9,6,14]],"id":43885158}]}]}
{"op":"mcm","clk":"APYMAOAGAN0K","pt":1659347423683,"mc":[{"id":"1.201590187","rc":[{"atb":[[23,3.6]],"id":44621159}]}]}
{"op":"mcm","clk":"APgMAOAGAOQK","pt":1659347423733,"mc":[{"id":"1.201590187","rc":[{"bdatl":[[9,2.42,17.02]],"id":9570503},{"bdatl":[[9,21,2.46]],"id":12989514},{"bdatb":[[0,23,4.09]],"id":44621159}]}]}
{"op":"mcm","clk":"AK8NAIEHAJwL","pt":1659347424424,"mc":[{"id":"1.201590187","rc":[{"atb":[[25,0]],"atl":[[36,0]],"id":46969227}]}]}
{"op":"mcm","clk":"ALENAIMHAJ4L","pt":1659347424474,"mc":[{"id":"1.201590187","rc":[{"bdatl":[[4,2.3,2.79],[5,2.32,4.97],[6,2.38,36.7],[7,2.4,72.5],[8,2.42,17.4],[9,2.44,157.58]],"id":9570503},{"bdatl":[[7,16.5,1.01],[8,18.5,7.21],[9,21,2.98]],"id":12989514},{"bdatl":[[5,12,1.41],[6,13,43.01],[7,13.5,1.55],[8,14,3.69],[9,15,14.83]],"id":44836671},{"bdatb":[[0,24,2.68],[1,23,7],[2,22,7],[3,21,5],[4,20,6.4],[5,16,1.43],[6,11.5,1.35],[7,10,2],[8,9.6,3.23],[9,9.4,34.48]],"bdatl":[[2,38,2.51],[3,40,5.01],[4,80,1.66],[5,310,1],[6,990,2.15],[7,0,0]],"id":46969227}]}]}
{"op":"mcm","clk":"ALINAIQHAKAL","pt":1659347424524,"mc":[{"id":"1.201590187","rc":[{"atb":[[13,0.62]],"id":45323444},{"atb":[[23,1.13]],"id":44621159},{"atb":[[7.6,0]],"id":43885158}]}]}
{"op":"mcm","clk":"ALkNAIUHAKML","pt":1659347424574,"mc":[{"id":"1.201590187","rc":[{"bdatb":[[1,12.5,1.76],[2,12,2.87],[3,11.5,5.54],[4,11,1.23],[5,10.5,1.6],[6,10,11.5],[7,9.8,9],[8,9.6,21],[9,9.4,45.48]],"id":45323444},{"bdatl":[[7,2.4,71.67],[8,2.44,152.92],[9,2.46,4.98]],"id":9570503},{"bdatl":[[9,24,1.02]],"id":12989514},{"bdatb":[[0,23,1.62]],"id":44621159},{"bdatb":[[2,7.4,9.18],[3,7.2,8.24],[4,7,5],[5,6.6,47.79],[6,6.4,2.63],[7,6.2,11.6],[8,6,14],[9,5.9,4]],"id":43885158}]}]}
{"op":"mcm","clk":"AMINAIgHAKgL","pt":1659347424631,"mc":[{"id":"1.201590187","rc":[{"atb":[[23,0.1],[19.5,7]],"atl":[[36,0.49],[34,5.6]],"id":46969227}]}]}
{"op":"mcm","clk":"AMQNAI0HAKkL","pt":1659347424681,"mc":[{"id":"1.201590187","rc":[{"bdatb":[[1,22,7.1],[2,21,5],[3,20,6.4],[4,19.5,7]],"bdatl":[[1,34,5.6],[2,38,3]],"id":46969227}]}]}
{"op":"mcm","clk":"AMUNAI4HAK0L","pt":1659347424732,"mc":[{"id":"1.201590187","rc":[{"atb":[[12.5,5.74]],"id":45323444},{"atb":[[7.8,8.62]],"id":43885158}]}]}
{"op":"mcm","clk":"AMwNAI4HALAL","pt":1659347424782,"mc":[{"id":"1.201590187","rc":[{"bdatb":[[1,12.5,6.36]],"id":45323444},{"bdatl":[[8,2.42,15.62],[9,2.44,154.68]],"id":9570503},{"bdatl":[[9,20,1.2]],"id":12989514},{"bdatb":[[1,7.8,8.62]],"id":43885158}]}]}
{"op":"mcm","clk":"AM4NAJMHALYL","pt":1659347424832,"mc":[{"id":"1.201590187","rc":[{"atl":[[32,2.12]],"bdatl":[[0,32,2.19]],"id":46969227},{"bdatb":[[9,1.81,8.45]],"id":9570503},{"bdatb":[[7,5.2,3.45],[8,5,7.54]],"id":12989514}]}]}
{"op":"mcm","clk":"ANUNAJYHALsL","pt":1659347424904,"mc":[{"id":"1.201590187","rc":[{"atb":[[24,2.91],[19.5,4.19],[18,0]],"id":44621159},{"atb":[[24,1.06]],"id":46969227}]}]}
{"op":"mcm","clk":"ANsNAJkHAMML","pt":1659347424954,"mc":[{"id":"1.201590187","rc":[{"bdatl":[[6,2.36,3.18],[7,2.38,33.79],[8,2.4,72.79],[9,2.42,16.88]],"id":9570503},{"bdatl":[[7,16,1.01],[8,18.5,7.64],[9,21,2.3]],"id":12989514},{"bdatb":[[0,24,2.91],[1,23,1.13],[2,22,1],[3,21,5],[4,19.5,4.19],[5,18.5,1.37],[6,15.5,4.19],[7,15,1.8],[8,11.5,1.35],[9,10,102]],"id":44621159},{"bdatl":[[6,12.5,1.14],[7,13,41.88],[8,13.5,1.57],[9,14,3.68]],"id":44836671},{"bdatb":[[0,24,1.06]],"id":46969227}]}]}
{"op":"mcm","clk":"AN4NAJkHAMQL","pt":1659347425004,"mc":[{"id":"1.201590187","rc":[{"atb":[[23,1.73]],"atl":[[36,0],[32,2.21]],"id":46969227}]}]}
{"op":"mcm","clk":"AOQNAJsHAMUL","pt":1659347425054,"mc":[{"id":"1.201590187","rc":[{"bdatl":[[9,20,2.16]],"id":12989514},{"bdatb":[[1,23,1.73],[2,22,7],[3,21,5],[4,20,6.4],[5,19.5,7],[6,16,1.43],[7,11.5,1.35],[8,10,2],[9,9.6,3.23]],"bdatl":[[0,32,2.28],[2,38,2.51]],"id":46969227}]}]}
{"op":"mcm","clk":"AOUNAJwHAMgL","pt":1659347425104,"mc":[{"id":"1.201590187","rc":[{"atb":[[24,0.97]],"id":46969227}]}]}
{"op":"mcm","clk":"AO0NAJ4HAMgL","pt":1659347425154,"mc":[{"id":"1.201590187","rc":[{"bdatl":[[8,2.4,71.89],[9,2.42,17.77]],"id":9570503},{"bdatl":[[9,20,2.05]],"id":12989514},{"bdatb":[[0,23,2.7],[1,22,7],[2,21,5],[3,20,6.4],[4,19.5,7],[5,16,1.43],[6,11.5,1.35],[7,10,2],[8,9.6,3.23],[9,9.4,34.48]],"id":46969227}]}]}
{"op":"mcm","clk":"APkNAKUHANML","pt":1659347425314,"mc":[{"id":"1.201590187","rc":[{"atl":[[32,2.12]],"id":46969227}]}]}
{"op":"mcm","clk":"AP8NAKUHANQL","pt":1659347425366,"mc":[{"id":"1.201590187","rc":[{"bdatl":[[0,32,2.19]],"id":46969227}]}]}
{"op":"mcm","clk":"AJgOALUHAOYL","pt":1659347425691,"mc":[{"id":"1.201590187","rc":[{"atb":[[12.5,1.14]],"id":45323444},{"atb":[[24,0.49]],"id":44621159},{"atb":[[7.8,1.26]],"id":43885158}]}]}
{"op":"mcm","clk":"AJgOALUHAOoL","pt":1659347425741,"mc":[{"id":"1.201590187","rc":[{"bdatb":[[1,12.5,1.76]],"id":45323444},{"bdatl":[[6,2.38,36.7],[7,2.4,71.67],[8,2.44,152.92],[9,2.46,4.98]],"id":9570503},{"bdatl":[[7,16.5,1.01],[8,18.5,7.21],[9,27,1.05]],"id":12989514},{"bdatb":[[0,23,1.62],[1,22,1],[2,21,5],[3,19.5,4.19],[4,18.5,1.37],[5,15.5,4.19],[6,15,1.8],[7,11.5,1.35],[8,10,102],[9,9.6,4.91]],"id":44621159},{"bdatl":[[6,13,43.01],[7,13.5,1.55],[8,14,3.69],[9,15,14.83]],"id":44836671},{"bdatb":[[1,7.8,1.26]],"id":43885158}]}]}
{"op":"mcm","clk":"AJ0OALwHAOwL","pt":1659347425890,"mc":[{"id":"1.201590187","rc":[{"atb":[[13,5.05]],"id":45323444},{"atb":[[7.6,7.58]],"id":43885158}]}]}
{"op":"mcm","clk":"AKQOALwHAPIL","pt":1659347425940,"mc":[{"id":"1.201590187","rc":[{"bdatb":[[1,13,5.05],[2,12.5,1.14],[3,12,2.87],[4,11.5,5.54],[5,11,1.23],[6,10.5,1.6],[7,10,11.5],[8,9.8,9],[9,9.6,21]],"id":45323444},{"bdatl":[[7,2.4,72.5],[8,2.42,5.7],[9,2.44,162.35]],"id":9570503},{"bdatl":[[9,21,1.18]],"id":12989514},{"bdatb":[[2,7.6,7.58],[3,7.4,9.18],[4,7.2,8.24],[5,7,5],[6,6.6,47.79],[7,6.4,2.63],[8,6.2,11.6],[9,6,14]],"id":43885158}]}]}
{"op":"mcm","clk":"AKsOAMMHAPcL","pt":1659347426099,"mc":[{"id":"1.201590187","rc":[{"atb":[[22,3.59]],"id":44621159}]}]}
{"op":"mcm","clk":"AK0OAMUHAP4L","pt":1659347426149,"mc":[{"id":"1.201590187","rc":[{"bdatl":[[9,2.44,163.7]],"id":9570503},{"bdatb":[[1,22,3.59]],"id":44621159}]}]}
{"op":"mcm","clk":"ALoOAMsHAI4M","pt":1659347426412,"mc":[{"id":"1.201590187","rc":[{"atb":[[7.2,3.71]],"id":43885158}]}]}
{"op":"mcm","clk":"AL0OAM0HAJAM","pt":1659347426462,"mc":[{"id":"1.201590187","rc":[{"bdatb":[[4,7.2,3.71]],"id":43885158}]}]}
{"op":"mcm","clk":"AL8OAM4HAJcM","pt":1659347426512,"mc":[{"id":"1.201590187","rc":[{"atl":[[23,1.15]],"id":45323444},{"atb":[[7.6,12.12]],"id":43885158}]}]}
{"op":"mcm","clk":"AMIOAM4HAJgM","pt":1659347426562,"mc":[{"id":"1.201590187","rc":[{"bdatl":[[2,23,1.15],[3,25,2.42],[4,26,5.72],[5,27,3.85],[6,29,5.36],[7,32,6.46],[8,50,8],[9,55,9]],"id":45323444},{"bdatb":[[7,1.83,52.01],[8,1.82,52.62],[9,1.81,4.84]],"id":9570503},{"bdatb":[[7,5.2,3.86],[8,5.1,1.22],[9,5,5.87]],"id":12989514},{"bdatb":[[2,7.6,12.12]],"id":43885158},{"bdatb":[[9,9.4,34.77]],"id":46969227}]}]}
{"op":"mcm","clk":"ANsOANsHAK0M","pt":1659347426894,"mc":[{"id":"1.201590187","rc":[{"atb":[[13,0.62]],"id":45323444},{"atb":[[22,1]],"id":44621159},{"atb":[[7.6,4.53]],"id":43885158}]}]}
{"op":"mcm","clk":"ANsOANsHALAM","pt":1659347426944,"mc":[{"id":"1.201590187","rc":[{"bdatb":[[1,12.5,1.76],[2,12,2.87],[3,11.5,5.54],[4,11,1.23],[5,10.5,1.6],[6,10,11.5],[7,9.8,9],[8,9.6,21],[9,9.4,45.48]],"id":45323444},{"bdatl":[[7,2.4,71.67],[8,2.44,157.94],[9,2.48,8.95]],"id":9570503},{"bdatl":[[9,23,1.03]],"id":12989514},{"bdatb":[[1,22,1]],"id":44621159},{"bdatb":[[2,7.6,4.53]],"id":43885158}]}]}
{"op":"mcm","clk":"AOMOAOQHALcM","pt":1659347427091,"mc":[{"id":"1.201590187","rc":[{"atb":[[12.5,5.74]],"id":45323444},{"atb":[[7.8,8.62]],"id":43885158}]}]}
{"op":"mcm","clk":"AOYOAOQHALwM","pt":1659347427141,"mc":[{"id":"1.201590187","rc":[{"bdatb":[[1,12.5,6.36]],"id":45323444},{"bdatl":[[8,2.42,6.53],[9,2.44,162.35]],"id":9570503},{"bdatl":[[9,21,1.16]],"id":12989514},{"bdatb":[[1,7.8,8.62]],"id":43885158}]}]}
{"op":"mcm","clk":"AO0OAOoHAMQM","pt":1659347427298,"mc":[{"id":"1.201590187","rc":[{"atb":[[23,3.6]],"id":44621159}]}]}
{"op":"mcm","clk":"APQOAOsHAMgM","pt":1659347427348,"mc":[{"id":"1.201590187","rc":[{"bdatl":[[8,2.42,16.87],[9,2.44,153.44]],"id":9570503},{"bdatl":[[9,21,2.35]],"id":12989514},{"bdatb":[[0,23,4.09]],"id":44621159}]}]}
{"op":"mcm","clk":"AJgPAIAIAOAM","pt":1659347428032,"mc":[{"id":"1.201590187","rc":[{"atb":[[12.5,1.14]],"id":45323444},{"atb":[[23,1.13]],"id":44621159}]}]}
{"op":"mcm","clk":"AJgPAIMIAOUM","pt":1659347428082,"mc":[{"id":"1.201590187","rc":[{"bdatb":[[1,12.5,1.76]],"id":45323444},{"bdatl":[[8,2.42,5.89],[9,2.44,152.72]],"id":9570503},{"bdatl":[[9,21,1.09]],"id":12989514},{"bdatb":[[0,23,1.62]],"id":44621159}]}]}
{"op":"mcm","clk":"AKEPAIYIAOoM","pt":1659347428234,"mc":[{"id":"1.201590187","rc":[{"atb":[[13,5.05]],"id":45323444}]}]}
{"op":"mcm","clk":"AKEPAIkIAO0M","pt":1659347428284,"mc":[{"id":"1.201590187","rc":[{"bdatb":[[1,13,5.05],[2,12.5,1.14],[3,12,2.87],[4,11.5,5.54],[5,11,1.23],[6,10.5,1.6],[7,10,11.5],[8,9.8,9],[9,9.6,21]],"id":45323444},{"bdatl":[[7,2.4,78.25],[8,2.42,10.34],[9,2.44,153.44]],"id":9570503},{"bdatl":[[9,19.5,1.22]],"id":12989514}]}]}
{"op":"mcm","clk":"AKQPAIkIAPMM","pt":1659347428334,"mc":[{"id":"1.201590187","rc":[{"atb":[[1.97,24.96]],"bdatb":[[1,1.97,24.96]],"bdatl":[[6,2.36,3.18],[7,2.38,34.25],[8,2.4,89.35],[9,2.42,1.49]],"id":9570503},{"atb":[[24,2.91]],"bdatb":[[0,24,2.91],[1,23,1.13],[2,22,1],[3,21,5],[4,19.5,4.19],[5,18.5,1.37],[6,15.5,4.19],[7,15,1.8],[8,11.5,1.35],[9,10,102]],"id":44621159},{"bdatl":[[7,16,1.01],[8,18.5,7.69],[9,19,2.09]],"id":12989514},{"bdatl":[[6,12.5,1.14],[7,13,41.88],[8,13.5,1.57],[9,14,3.68]],"id":44836671}]}]}
{"op":"mcm","clk":"ALUPAI4IAPYM","pt":1659347428393,"mc":[{"id":"1.201590187","rc":[{"atb":[[12,0]],"id":45323444},{"atb":[[24,0],[23,3.23]],"id":46969227}]}]}
{"op":"mcm","clk":"ALUPAI4IAPoM","pt":1659347428444,"mc":[{"id":"1.201590187","rc":[{"bdatb":[[3,11.5,5.54],[4,11,1.23],[5,10.5,1.6],[6,10,11.5],[7,9.8,9],[8,9.6,21],[9,9.4,45.48]],"id":45323444},{"bdatl":[[6,2.38,36.7],[7,2.4,90.05],[8,2.42,3.32],[9,2.44,154.29]],"id":9570503},{"bdatl":[[7,18,1],[8,18.5,7.2],[9,19,2.93]],"id":12989514},{"bdatl":[[6,13,42.98],[7,13.5,1.55],[8,14,3.69],[9,15,14.83]],"id":44836671},{"bdatb":[[0,23,3.23]],"id":46969227}]}]}
{"op":"mcm","clk":"ALkPAJAIAPwM","pt":1659347428494,"mc":[{"id":"1.201590187","rc":[{"atb":[[10.5,4.47]],"atl":[[26,6.42]],"id":45323444}]}]}
{"op":"mcm","clk":"ALoPAJEIAIIN","pt":1659347428544,"mc":[{"id":"1.201590187","rc":[{"bdatb":[[5,10.5,4.47]],"bdatl":[[4,26,6.42]],"id":45323444}]}]}
{"op":"mcm","clk":"AL8PAJIIAIUN","pt":1659347428598,"mc":[{"id":"1.201590187","rc":[{"atb":[[1.97,13.5]],"id":9570503}]}]}
{"op":"mcm","clk":"AMAPAJMIAIcN","pt":1659347428649,"mc":[{"id":"1.201590187","rc":[{"bdatb":[[1,1.97,13.5]],"id":9570503}]}]}
{"op":"mcm","clk":"ANAPAJ0IAJsN","pt":1659347429004,"mc":[{"id":"1.201590187","rc":[{"atb":[[13,0.62]],"id":45323444},{"atb":[[24,0.49]],"id":44621159}]}]}
{"op":"mcm","clk":"ANYPAKAIAJwN","pt":1659347429054,"mc":[{"id":"1.201590187","rc":[{"bdatb":[[1,12.5,1.76],[2,11.5,5.54],[3,11,1.23],[4,10.5,4.47],[5,10,11.5],[6,9.8,9],[7,9.6,21],[8,9.4,45.48],[9,9.2,12]],"id":45323444},{"bdatl":[[5,2.32,4.06],[6,2.36,1],[7,2.38,36.61],[8,2.4,71.67],[9,2.42,5.89]],"id":9570503},{"bdatl":[[7,18.5,8.19],[8,21,1.08],[9,27,1.44]],"id":12989514},{"bdatb":[[0,23,1.62],[1,22,1],[2,21,5],[3,19.5,4.19],[4,18.5,1.37],[5,15.5,4.19],[6,15,1.8],[7,11.5,1.35],[8,10,102],[9,9.6,4.91]],"id":44621159},{"bdatl":[[6,13,42.82],[7,13.5,1.71],[8,14,3.68]],"id":44836671}]}]}
{"op":"mcm","clk":"AOAPAKgIAKgN","pt":1659347429316,"mc":[{"id":"1.201590187","rc":[{"atb":[[12.5,5.74]],"id":45323444},{"atb":[[1.99,17.32]],"id":9570503}]}]}
{"op":"mcm","clk":"AOoPAKsIAKoN","pt":1659347429368,"mc":[{"id":"1.201590187","rc":[{"bdatb":[[1,12.5,6.36]],"id":45323444},{"bdatb":[[0,1.99,17.32],[1,1.98,38.19],[2,1.97,13.5],[3,1.96,3.89],[4,1.95,1.28],[5,1.91,108.46],[6,1.9,5.81],[7,1.89,1.52],[8,1.83,52.01],[9,1.82,52.62]],"bdatl":[[9,2.42,6.53]],"id":9570503},{"bdatl":[[7,16,1.01],[8,18.5,7.21],[9,20,1.03]],"id":12989514},{"bdatl":[[5,12,1.62],[6,13,42.81],[7,13.5,1.55],[8,14,3.69]],"id":44836671}]}]}
{"op":"mcm","clk":"APEPAKwIALMN","pt":1659347429418,"mc":[{"id":"1.201590187","rc":[{"atb":[[10,10]],"bdatb":[[5,10,10]],"id":45323444},{"atb":[[22,3.59]],"bdatb":[[1,22,3.59]],"id":44621159}]}]}
{"op":"mcm","clk":"APMPAK0IALMN","pt":1659347429473,"mc":[{"id":"1.201590187","rc":[{"atb":[[11.5,7.04]],"id":45323444},{"atb":[[1.99,18.57]],"id":9570503}]}]}
{"op":"mcm","clk":"APgPALAIALkN","pt":1659347429523,"mc":[{"id":"1.201590187","rc":[{"bdatb":[[2,11.5,7.04]],"id":45323444},{"bdatb":[[0,1.99,18.57]],"id":9570503},{"bdatl":[[9,20,1.15]],"id":12989514}]}]}
{"op":"mcm","clk":"AJ0QAMMIANMN","pt":1659347430100,"mc":[{"id":"1.201590187","rc":[{"atb":[[12.5,1.14]],"id":45323444},{"atb":[[22,1]],"id":44621159}]}]}
{"op":"mcm","clk":"AKEQAMYIANcN","pt":1659347430150,"mc":[{"id":"1.201590187","rc":[{"bdatb":[[1,12.5,1.76]],"id":45323444},{"bdatl":[[9,2.42,5.89]],"id":9570503},{"bdatl":[[9,20,1.12]],"id":12989514},{"bdatb":[[1,22,1]],"id":44621159}]}]}
{"op":"mcm","clk":"AKgQAMwIAN8N","pt":1659347430309,"mc":[{"id":"1.201590187","rc":[{"atb":[[13,5.05]],"id":45323444}]}]}
{"op":"mcm","clk":"ALAQAM0IAOEN","pt":1659347430360,"mc":[{"id":"1.201590187","rc":[{"bdatb":[[1,13,5.05],[2,12.5,1.14],[3,11.5,7.04],[4,11,1.23],[5,10.5,4.47],[6,10,10],[7,9.8,9],[8,9.6,21],[9,9.4,45.48]],"id":45323444},{"bdatl":[[8,2.4,78.25],[9,2.42,11.7]],"id":9570503},{"bdatl":[[9,19,1.2]],"id":12989514}]}]}
{"op":"mcm","clk":"ALkQANQIAOoN","pt":1659347430519,"mc":[{"id":"1.201590187","rc":[{"atb":[[23,3.6]],"id":44621159}]}]}
{"op":"mcm","clk":"AMEQANcIAO0N","pt":1659347430569,"mc":[{"id":"1.201590187","rc":[{"bdatl":[[8,2.4,90.05],[9,2.42,3.32]],"id":9570503},{"bdatb":[[0,23,4.09]],"id":44621159}]}]}
{"op":"mcm","clk":"AMsQANoIAPUN","pt":1659347430681,"mc":[{"id":"1.201590187","rc":[{"atb":[[7.4,0.39]],"trd":[[7.4,8.39]],"tv":46.72,"id":12989514}],"tv":1075.82}]}
{"op":"mcm","clk":"ANEQANoIAPoN","pt":1659347430740,"mc":[{"id":"1.201590187","rc":[{"bdatl":[[5,2.34,4.03],[6,2.38,34.53],[7,2.4,85.33],[8,2.42,11.02],[9,2.44,154.29]],"id":9570503},{"bdatb":[[0,7.2,6.6],[1,7,5.57],[2,6.8,11.36],[3,6.6,1.15],[4,6,2.64],[5,5.5,5.64],[6,5.2,3.86],[7,5.1,1.22],[8,5,5.87],[9,4.9,6.21]],"id":12989514},{"bdatl":[[6,13,42.62],[7,13.5,1.71],[8,14,3.68],[9,15,14.34]],"id":44836671}]}]}
{"op":"mcm","clk":"ANsQAN4IAP4N","pt":1659347430797,"mc":[{"id":"1.201590187","rc":[{"atb":[[7.4,0.06]],"id":12989514}]}]}
{"op":"mcm","clk":"ANsQAN4IAIAO","pt":1659347430848,"mc":[{"id":"1.201590187","rc":[{"bdatl":[[4,2.3,1.91],[5,2.34,4.9],[7,2.4,84.31],[8,2.42,12.02]],"id":9570503},{"bdatb":[[0,7.2,6.27]],"id":12989514},{"bdatl":[[5,12,1.45],[6,13,42.78]],"id":44836671}]}]}
{"op":"mcm","clk":"APMQAPEIAJAO","pt":1659347431218,"mc":[{"id":"1.201590187","rc":[{"atb":[[13,0.62]],"id":45323444},{"atb":[[23,1.13]],"id":44621159}]}]}
{"op":"mcm","clk":"APUQAPIIAJMO","pt":1659347431269,"mc":[{"id":"1.201590187","rc":[{"bdatb":[[1,12.5,1.76],[2,11.5,7.04],[3,11,1.23],[4,10.5,4.47],[5,10,10],[6,9.8,9],[7,9.6,21],[8,9.4,45.48],[9,9.2,12]],"id":45323444},{"bdatl":[[7,2.4,74.71],[8,2.42,5.89],[9,2.44,152.09]],"id":9570503},{"bdatl":[[9,20,1.12]],"id":12989514},{"bdatb":[[0,23,1.62]],"id":44621159}]}]}
{"op":"mcm","clk":"AP0QAPUIAJcO","pt":1659347431411,"mc":[{"id":"1.201590187","rc":[{"atb":[[12,4.77]],"id":45323444}]}]}
{"op":"mcm","clk":"AIERAPcIAJ0O","pt":1659347431461,"mc":[{"id":"1.201590187","rc":[{"bdatb":[[2,12,4.77],[3,11.5,7.04],[4,11,1.23],[5,10.5,4.47],[6,10,10],[7,9.8,9],[8,9.6,21],[9,9.4,45.48]],"id":45323444},{"bdatl":[[9,2.44,152.72]],"id":9570503}]}]}
{"op":"mcm","clk":"AIMRAPcIAJ8O","pt":1659347431511,"mc":[{"id":"1.201590187","rc":[{"atl":[[22,0.41],[21,1]],"id":45323444},{"atl":[[1000,6.47]],"id":12989514},{"atb":[[23,2.13]],"id":44621159}]}]}
{"op":"mcm","clk":"AIsRAPoIAJ8O","pt":1659347431561,"mc":[{"id":"1.201590187","rc":[{"bdatl":[[1,21,1],[2,23,1.56]],"id":45323444},{"bdatb":[[8,1.84,11.41],[9,1.83,40.54]],"bdatl":[[9,2.44,155.69]],"id":9570503},{"bdatb":[[5,5.5,5.46],[6,5.2,4.05],[7,5.1,1.02],[8,5,6.07],[9,4.9,6.01]],"id":12989514},{"bdatb":[[0,23,2.62],[9,9.8,2.14]],"id":44621159},{"bdatb":[[8,9.8,2.14],[9,9.4,35.82]],"id":46969227}]}]}
{"op":"mcm","clk":"AI4RAPoIAKIO","pt":1659347431613,"mc":[{"id":"1.201590187","rc":[{"atb":[[14,0],[13,1.62]],"atl":[[990,0]],"id":45323444},{"atb":[[1.02,6]],"id":12989514},{"atb":[[24,2.91]],"id":44621159}]}]}
{"op":"mcm","clk":"AJIRAPsIAKUO","pt":1659347431663,"mc":[{"id":"1.201590187","rc":[{"bdatb":[[0,13,1.62],[1,12.5,1.14]],"id":45323444},{"bdatl":[[4,2.3,1.72],[5,2.36,1.04],[6,2.38,38.48],[7,2.4,74.29],[9,2.44,156.1]],"id":9570503},{"bdatl":[[7,18,1.35],[8,18.5,7.2],[9,22,2.3]],"id":12989514},{"bdatb":[[0,24,2.91],[1,23,2.13],[2,22,1],[3,21,5],[4,19.5,4.19],[5,18.5,1.37],[6,15.5,4.19],[7,15,1.8],[8,11.5,1.35],[9,10,102]],"id":44621159},{"bdatl":[[5,12,1.41],[6,13,41.93],[7,13.5,1.7],[8,14,4.52],[9,15,14.78]],"id":44836671}]}]}
{"op":"mcm","clk":"AJURAPwIAKcO","pt":1659347431729,"mc":[{"id":"1.201590187","rc":[{"atl":[[26,7.87]],"id":45323444},{"atl":[[1000,2.47]],"id":12989514}]}]}
{"op":"mcm","clk":"AJgRAIAJAKkO","pt":1659347431779,"mc":[{"id":"1.201590187","rc":[{"bdatl":[[4,26,7.87]],"id":45323444}]}]}
{"op":"mcm","clk":"AJoRAIAJAK0O","pt":1659347431829,"mc":[{"id":"1.201590187","rc":[{"atb":[[1.97,1.26],[1.98,57.85]],"id":9570503},{"atb":[[7,8.05],[1.02,4],[7.2,1.97]],"id":12989514},{"atl":[[32,2.56]],"id":44621159}]}]}
{"op":"mcm","clk":"AKARAIEJAK8O","pt":1659347431879,"mc":[{"id":"1.201590187","rc":[{"bdatb":[[1,1.98,57.85],[2,1.97,1.26],[9,1.83,45.29]],"bdatl":[[7,2.4,71.59],[8,2.42,2.68],[9,2.44,157.93]],"id":9570503},{"bdatb":[[0,7.2,2.03],[1,7,8.05],[6,5.3,3.99],[7,5.1,2.84],[8,5,10.61],[9,4.8,228.97]],"id":12989514},{"bdatl":[[0,32,2.56]],"id":44621159},{"bdatl":[[9,15,14.35]],"id":44836671},{"bdatb":[[9,9.4,35.85]],"id":46969227}]}]}
{"op":"mcm","clk":"AKIRAIIJALAO","pt":1659347431929,"mc":[{"id":"1.201590187","rc":[{"atb":[[1.02,2]],"atl":[[1000,0.47]],"id":12989514}]}]}
{"op":"mcm","clk":"AKkRAIYJALMO","pt":1659347431983,"mc":[{"id":"1.201590187","rc":[{"atb":[[1.02,1]],"atl":[[9,3.46]],"id":12989514}]}]}
{"op":"mcm","clk":"AKwRAIYJALsO","pt":1659347432033,"mc":[{"id":"1.201590187","rc":[{"bdatb":[[6,1.9,7.32],[7,1.85,8.18],[8,1.84,3.19],[9,1.83,50.08]],"id":9570503},{"bdatl":[[0,9,3.46]],"id":12989514},{"bdatb":[[9,10,103.51]],"id":44621159},{"bdatb":[[9,5.3,1.87]],"id":44836671},{"bdatb":[[7,10,3.51],[8,9.6,1.54],[9,9.4,34.91]],"id":46969227}]}]}
{"op":"mcm","clk":"ALYRAIkJAL0O","pt":1659347432098,"mc":[{"id":"1.201590187","rc":[{"atb":[[1.02,0],[7.4,1.06]],"id":12989514}]}]}
{"op":"mcm","clk":"ALYRAIoJAMEO","pt":1659347432149,"mc":[{"id":"1.201590187","rc":[{"bdatl":[[5,2.34,1.05],[6,2.36,2.27],[7,2.38,36.22],[8,2.4,74.29],[9,2.44,157.94]],"id":9570503},{"bdatb":[[0,7.4,1.06],[1,7.2,1.97],[2,7,8.05],[3,6.8,11.36],[4,6.6,1.15],[5,6,2.64],[6,5.5,5.46],[7,5.3,3.99],[8,5.1,2.84],[9,5,10.61]],"id":12989514},{"bdatl":[[6,13,42.09],[7,13.5,1.95],[8,14,4.14],[9,15,14.78]],"id":44836671}]}]}
{"op":"mcm","clk":"AL4RAJEJAMcO","pt":1659347432213,"mc":[{"id":"1.201590187","rc":[{"atl":[[22,0]],"id":45323444},{"atb":[[7.4,2.06]],"id":12989514},{"atl":[[34,1.15]],"id":44621159}]}]}
{"op":"mcm","clk":"AL4RAJEJAMcO","pt":1659347432263,"mc":[{"id":"1.201590187","rc":[{"bdatl":[[2,23,1.15]],"id":45323444},{"bdatb":[[9,1.83,47.99]],"bdatl":[[6,2.36,4.98],[7,2.38,33.98],[8,2.4,73.86],[9,2.42,3.44]],"id":9570503},{"bdatb":[[0,7.4,2.06],[6,5.5,3.82],[7,5.4,2.42],[8,5.3,2.52],[9,5.1,3.53]],"id":12989514},{"bdatl":[[1,34,1.15]],"id":44621159},{"bdatl":[[7,13.5,2.42],[8,14,3.75],[9,15,14.71]],"id":44836671},{"bdatb":[[8,9.4,36.47],[9,9,1.48]],"id":46969227}]}]}
{"op":"mcm","clk":"AMYRAJMJAMwO","pt":1659347432314,"mc":[{"id":"1.201590187","rc":[{"atb":[[6.8,15.65]],"id":12989514}]}]}
{"op":"mcm","clk":"AMcRAJMJAMwO","pt":1659347432364,"mc":[{"id":"1.201590187","rc":[{"bdatb":[[3,6.8,15.65]],"id":12989514}]}]}
{"op":"mcm","clk":"AM0RAJUJANQO","pt":1659347432436,"mc":[{"id":"1.201590187","rc":[{"atb":[[12,0]],"id":45323444},{"atb":[[24,0.49]],"id":44621159}]}]}
{"op":"mcm","clk":"AM4RAJYJANQO","pt":1659347432486,"mc":[{"id":"1.201590187","rc":[{"bdatb":[[2,11.5,7.04],[3,11,1.23],[4,10.5,4.47],[5,10,10],[6,9.8,9],[7,9.6,21],[8,9.4,45.48],[9,9.2,12]],"id":45323444},{"bdatl":[[7,18.5,8.16],[8,20,1.07],[9,25,1.03]],"id":12989514},{"bdatb":[[0,23,2.62],[1,22,1],[2,21,5],[3,19.5,4.19],[4,18.5,1.37],[5,15.5,4.19],[6,15,1.8],[7,11.5,1.35],[8,10,103.51],[9,9.6,2.28]],"id":44621159},{"bdatl":[[7,13.5,2.25],[8,14,3.85],[9,15,14.39]],"id":44836671}]}]}
{"op":"mcm","clk":"ANcRAJcJANoO","pt":1659347432604,"mc":[{"id":"1.201590187","rc":[{"atb":[[12.5,5.74]],"id":45323444}]}]}
{"op":"mcm","clk":"ANwRAJoJAN8O","pt":1659347432654,"mc":[{"id":"1.201590187","rc":[{"bdatb":[[1,12.5,5.74]],"id":45323444},{"bdatl":[[8,20,1.15],[9,21,1.14]],"id":12989514}]}]}
{"op":"mcm","clk":"AOQRAJ8JAOsO","pt":1659347432826,"mc":[{"id":"1.201590187","rc":[{"atb":[[7,5.57],[7.2,5.2]],"atl":[[9.2,0.28],[9,8.23]],"id":12989514},{"atb":[[23,4.6],[22,0]],"atl":[[32,1.56]],"id":44621159},{"atb":[[22,0],[19,5]],"id":46969227}]}]}
{"op":"mcm","clk":"AOYRAKEJAO0O","pt":1659347432876,"mc":[{"id":"1.201590187","rc":[{"bdatb":[[7,1.85,11.35],[8,1.83,47.99],[9,1.82,49.95]],"bdatl":[[9,2.42,13.05]],"id":9570503},{"bdatb":[[1,7.2,5.2],[2,7,5.57],[8,5.2,3.3],[9,5,4.31]],"bdatl":[[0,9,8.23],[1,9.4,3.95],[2,9.6,14.09],[3,10,17.36],[4,10.5,12.47],[5,11,33.84],[6,18.5,8.16],[7,20,1.15],[8,21,1.77],[9,30,9.53]],"id":12989514},{"bdatb":[[0,23,5.09],[1,21,5],[2,19.5,4.19],[3,18.5,1.37],[4,15.5,4.19],[5,15,1.8],[6,11.5,1.35],[7,10,104.1],[8,9.6,3.04],[9,9.4,44.53]],"bdatl":[[0,32,1.56]],"id":44621159},{"bdatb":[[1,21,5],[2,20,6.4],[3,19.5,7],[4,19,5],[7,10,4.1],[8,9.6,1.33],[9,9.4,34.51]],"id":46969227}]}]}
{"op":"mcm","clk":"AO0RAKUJAPYO","pt":1659347433022,"mc":[{"id":"1.201590187","rc":[{"atb":[[1.01,48.08]],"id":45323444},{"atb":[[23,3.13],[21,5.1]],"id":46969227}]}]}
{"op":"mcm","clk":"APERAKcJAPkO","pt":1659347433072,"mc":[{"id":"1.201590187","rc":[{"bdatl":[[8,21,1.66],[9,30,9.63]],"id":12989514},{"bdatb":[[0,23,3.13],[1,21,5.1]],"id":46969227}]}]}
{"op":"mcm","clk":"APMRAKgJAPoO","pt":1659347433130,"mc":[{"id":"1.201590187","rc":[{"atb":[[23,1.5]],"id":46969227}]}]}
{"op":"mcm","clk":"APoRAKsJAP8O","pt":1659347433181,"mc":[{"id":"1.201590187","rc":[{"bdatl":[[9,2.42,5.55]],"id":9570503},{"bdatl":[[7,20,1.03],[8,23,2.04],[9,30,9.22]],"id":12989514},{"bdatb":[[0,23,1.5]],"id":46969227}]}]}
{"op":"mcm","clk":"APwRAKsJAIEP","pt":1659347433231,"mc":[{"id":"1.201590187","rc":[{"atb":[[1.01,47.24]],"id":45323444},{"atb":[[22,1.63]],"id":46969227}]}]}
{"op":"mcm","clk":"AP0RAK4JAIEP","pt":1659347433282,"mc":[{"id":"1.201590187","rc":[{"bdatl":[[8,22,1.63],[9,30,9.7]],"id":12989514},{"bdatb":[[1,22,1.63],[2,21,5.1],[3,20,6.4],[4,19.5,7],[5,19,5],[6,16,1.43],[7,11.5,1.35],[8,10,4.1],[9,9.6,1.33]],"id":46969227}]}]}
{"op":"mcm","clk":"AIASAK8JAIcP","pt":1659347433332,"mc":[{"id":"1.201590187","rc":[{"atb":[[6.8,11.36]],"bdatb":[[3,6.8,11.36]],"id":12989514},{"atl":[[55,0]],"bdatl":[[3,120,7.2]],"id":44621159}]}]}
{"op":"mcm","clk":"AIMSAK8JAIgP","pt":1659347433386,"mc":[{"id":"1.201590187","rc":[{"atb":[[1.01,45.55]],"id":45323444},{"atl":[[60,0.42]],"id":44621159}]}]}
{"op":"mcm","clk":"AIoSAK8JAIoP","pt":1659347433436,"mc":[{"id":"1.201590187","rc":[{"bdatl":[[3,120,7.62]],"id":44621159}]}]}
{"op":"mcm","clk":"AIwSALEJAIoP","pt":1659347433493,"mc":[{"id":"1.201590187","rc":[{"atb":[[13.5,1.69],[12.5,1.14]],"id":45323444},{"atb":[[23,2.13]],"id":44621159}]}]}
{"op":"mcm","clk":"AJISALEJAI0P","pt":1659347433543,"mc":[{"id":"1.201590187","rc":[{"bdatb":[[0,13.5,1.69],[1,13,1.62],[2,12.5,1.14],[3,11.5,7.04],[4,11,1.23],[5,10.5,4.47],[6,10,10],[7,9.8,9],[8,9.6,21],[9,9.4,45.48]],"id":45323444},{"bdatl":[[5,2.32,1.06],[6,2.34,4.02],[7,2.36,1.42],[8,2.38,36.74],[9,2.4,76.29]],"id":9570503},{"bdatl":[[6,17,1],[7,18.5,7.68],[8,21,1.07],[9,29,1.08]],"id":12989514},{"bdatb":[[0,23,2.62]],"id":44621159},{"bdatl":[[6,13,42.82],[7,13.5,1.73],[8,14,3.75],[9,15,14.85]],"id":44836671}]}]}
{"op":"mcm","clk":"AJoSALQJAI4P","pt":1659347433603,"mc":[{"id":"1.201590187","rc":[{"atb":[[5.9,9],[5.8,30.83]],"id":44836671}]}]}
{"op":"mcm","clk":"AJoSALQJAJAP","pt":1659347433664,"mc":[{"id":"1.201590187","rc":[{"bdatb":[[3,5.9,9],[4,5.8,30.83]],"id":44836671}]}]}
{"op":"mcm","clk":"AKASALgJAJMP","pt":1659347433714,"mc":[{"id":"1.201590187","rc":[{"atb":[[13,6.05]],"id":45323444},{"atb":[[2.1,1.64]],"atl":[[2.1,0]],"trd":[[2.1,37.8]],"tv":691.39,"id":9570503}],"tv":1081.64}]}
{"op":"mcm","clk":"AKASALsJAJUP","pt":1659347433764,"mc":[{"id":"1.201590187","rc":[{"bdatb":[[1,13,6.05]],"bdatl":[[8,50,8.1]],"id":45323444},{"bdatb":[[0,2.1,1.64],[1,1.99,18.57],[2,1.98,57.85],[3,1.97,1.26],[4,1.96,3.89],[5,1.95,1.28],[6,1.91,108.46],[7,1.9,7.32],[8,1.85,11.35],[9,1.83,47.99]],"bdatl":[[0,2.12,20.74],[1,2.14,55.67],[2,2.18,1.18],[3,2.3,1.72],[4,2.32,1.06],[5,2.34,4.02],[6,2.36,1.42],[7,2.38,36.74],[8,2.4,76.29],[9,2.42,7.5]],"id":9570503},{"bdatb":[[5,6,2.67],[7,5.4,1.29],[8,5.3,1.1],[9,5.2,3.36]],"bdatl":[[5,11,34.06],[6,18,1.35],[7,18.5,7.2],[8,21,1.88],[9,26,1.64]],"id":12989514},{"bdatb":[[6,11.5,1.39],[8,9.6,2.4]],"id":44621159},{"bdatb":[[7,5.5,23],[8,5.4,14],[9,5.3,3.02]],"bdatl":[[4,9.8,33.91],[6,13,42.54]],"id":44836671},{"bdatb":[[6,6.6,47.48],[7,6.4,2.33],[8,6.2,12.24]],"bdatl":[[5,13.5,8.26]],"id":43885158},{"bdatb":[[7,11.5,1.39],[9,9.4,35.21]],"id":46969227}]}]}
{"op":"mcm","clk":"AKkSAL0JAJkP","pt":1659347433819,"mc":[{"id":"1.201590187","rc":[{"atb":[[2.1,0],[1.95,0]],"atl":[[2.14,56.85],[2.12,17.69]],"trd":[[2.1,41.08],[2.12,39.71]],"ltp":2.12,"tv":699.63,"id":9570503},{"atb":[[24,2.91]],"id":44621159}],"tv":1089.88}]}
{"op":"mcm","clk":"AKsSAL8JAJsP","pt":1659347433880,"mc":[{"id":"1.201590187","rc":[{"bdatl":[[8,50,8]],"id":45323444},{"bdatb":[[0,1.99,18.57],[1,1.98,57.85],[2,1.97,1.26],[3,1.96,3.89],[4,1.91,108.46],[5,1.9,7.32],[6,1.85,11.35],[7,1.83,47.99],[8,1.82,49.95],[9,1.81,1.42]],"bdatl":[[0,2.12,17.69],[1,2.14,56.85],[5,2.34,5.02],[6,2.38,37.17],[7,2.4,83.86],[8,2.42,7.09],[9,2.44,152.29]],"id":9570503},{"bdatb":[[7,5.3,2.41],[8,5.2,3.36],[9,5,4.31]],"bdatl":[[5,11,33.84],[6,16.5,1],[7,18,1.14],[8,18.5,7.2],[9,20,1.77]],"id":12989514},{"bdatb":[[0,24,2.91],[1,23,2.13],[2,21,5],[3,19.5,4.19],[4,18.5,1.37],[5,15.5,4.19],[6,15,1.8],[7,11.5,1.39],[8,10,104.1],[9,9.6,1.73]],"id":44621159},{"bdatl":[[4,9.8,33.55],[6,13,43],[7,13.5,1.63],[8,14,3.68],[9,15,15.63]],"id":44836671},{"bdatl":[[5,13.5,8]],"id":43885158},{"bdatb":[[9,9.4,34.53]],"id":46969227}]}]}
{"op":"mcm","clk":"ALISAMAJAKEP","pt":1659347433930,"mc":[{"id":"1.201590187","rc":[{"atb":[[2.08,1.26],[1.98,38.19]],"atl":[[2.12,0]],"trd":[[2.12,75.09]],"tv":735.01,"id":9570503}],"tv":1125.26}]}
{"op":"mcm","clk":"ALMSAMQJAKEP","pt":1659347433995,"mc":[{"id":"1.201590187","rc":[{"bdatl":[[8,50,8.06]],"id":45323444},{"bdatb":[[0,2.08,1.26],[1,1.99,18.57],[2,1.98,38.19],[3,1.97,1.26],[4,1.96,3.89],[5,1.91,108.46],[6,1.9,7.32],[7,1.85,11.35],[8,1.83,47.99],[9,1.82,49.95]],"bdatl":[[0,2.14,56.85],[1,2.18,1.18],[2,2.3,1.72],[3,2.32,1.06],[4,2.34,5.02],[5,2.38,37.17],[6,2.4,83.86],[7,2.42,7.09],[8,2.44,152.29],[9,2.46,4.53]],"id":9570503},{"bdatb":[[5,5.9,2.71],[6,5.4,3.89]],"bdatl":[[6,16.5,1.04],[9,20,1.78]],"id":12989514},{"bdatb":[[7,11,1.44],[8,10,102],[9,9.6,3.86]],"id":44621159},{"bdatb":[[9,5.1,36.67]],"bdatl":[[4,9.8,33.8],[5,12,1.43],[6,13,42.79]],"id":44836671},{"bdatb":[[7,6.4,2],[8,6.2,10.34],[9,6,16.32]],"bdatl":[[6,14,1.19]],"id":43885158},{"bdatb":[[7,11,1.45],[8,10,2],[9,9.6,2.19]],"id":46969227}]}]}
{"op":"mcm","clk":"ALkSAMYJAKcP","pt":1659347434046,"mc":[{"id":"1.201590187","rc":[{"atb":[[2.08,0]],"atl":[[2.14,55.67]],"id":9570503}]}]}
{"op":"mcm","clk":"ALsSAMcJAKkP","pt":1659347434096,"mc":[{"id":"1.201590187","rc":[{"bdatl":[[8,50,8]],"id":45323444},{"bdatb":[[0,1.99,18.57],[1,1.98,38.19],[2,1.97,1.26],[3,1.96,3.89],[4,1.91,108.46],[5,1.9,7.32],[6,1.85,11.35],[7,1.83,47.99],[8,1.82,49.95],[9,1.81,1.42]],"bdatl":[[0,2.14,55.67]],"id":9570503},{"bdatl":[[6,16.5,1],[9,20,1.77]],"id":12989514},{"bdatl":[[4,9.8,33.55],[5,12,1.41],[6,13,43]],"id":44836671},{"bdatl":[[6,14,1]],"id":43885158}]}]}
{"op":"mcm","clk":"AMASAMkJAK0P","pt":1659347434147,"mc":[{"id":"1.201590187","rc":[{"atb":[[2,2]],"atl":[[2.14,58]],"id":9570503}]}]}
{"op":"mcm","clk":"AMESAMsJALAP","pt":1659347434197,"mc":[{"id":"1.201590187","rc":[{"bdatb":[[0,2,2],[1,1.99,18.57],[2,1.98,38.19],[3,1.97,1.26],[4,1.96,3.89],[5,1.91,108.46],[6,1.9,7.32],[7,1.85,11.35],[8,1.83,47.99],[9,1.82,49.95]],"bdatl":[[0,2.14,58]],"id":9570503},{"bdatl":[[6,16.5,1.01],[9,20,1.78]],"id":12989514},{"bdatl":[[5,12,1.62],[6,13,42.8]],"id":44836671}]}]}
{"op":"mcm","clk":"AMYSAMwJALQP","pt":1659347434247,"mc":[{"id":"1.201590187","rc":[{"atb":[[1.99,21.08],[2,12.14]],"bdatb":[[0,2,12.14],[1,1.99,21.08]],"id":9570503},{"bdatl":[[6,16,1.02],[7,18,1.17],[9,19,1.67]],"id":12989514},{"bdatl":[[6,13,42.91],[7,13.5,1.55],[8,14,4.22],[9,15,15.1]],"id":44836671}]}]}
{"op":"mcm","clk":"AMgSANAJALcP","pt":1659347434314,"mc":[{"id":"1.201590187","rc":[{"atb":[[1.99,31.22],[2,13.38]],"atl":[[1000,1.9]],"id":9570503}]}]}
{"op":"mcm","clk":"AMwSANUJAL0P","pt":1659347434365,"mc":[{"id":"1.201590187","rc":[{"bdatb":[[0,2,13.38],[1,1.99,31.22]],"id":9570503},{"bdatl":[[7,18,1.18],[9,19,1.86]],"id":12989514},{"bdatl":[[9,15,15.12]],"id":44836671}]}]}
{"op":"mcm","clk":"AM4SANUJAMEP","pt":1659347434420,"mc":[{"id":"1.201590187","rc":[{"atb":[[2,3.24]],"id":9570503}]}]}
{"op":"mcm","clk":"ANQSANkJAMIP","pt":1659347434470,"mc":[{"id":"1.201590187","rc":[{"bdatb":[[0,2,3.24]],"id":9570503},{"bdatl":[[6,16.5,1.01],[7,18,1.14],[9,19,1.8]],"id":12989514},{"bdatl":[[6,13,42.81],[7,13.5,1.63],[8,14,3.68],[9,15,15.63]],"id":44836671}]}]}
{"op":"mcm","clk":"ANcSANoJAMcP","pt":1659347434523,"mc":[{"id":"1.201590187","rc":[{"atb":[[13,1.62]],"id":45323444},{"atb":[[1.99,28.71]],"atl":[[1000,0]],"id":9570503},{"atl":[[8.8,2]],"id":12989514},{"atb":[[24,0.49]],"id":44621159}]}]}
{"op":"mcm","clk":"ANkSAN4JAMgP","pt":1659347434573,"mc":[{"id":"1.201590187","rc":[{"bdatb":[[1,13,1.62]],"id":45323444},{"bdatb":[[1,1.99,28.71],[5,1.92,1.09],[6,1.91,114.64]],"bdatl":[[4,2.34,4.02],[5,2.36,1.42],[6,2.38,36.74],[7,2.4,76.29],[8,2.42,3.88],[9,2.44,155.68]],"id":9570503},{"bdatl":[[0,8.8,2],[1,9,8.23],[2,9.4,3.95],[3,9.6,14.09],[4,10,17.36],[5,10.5,12.47],[6,11,33.84],[7,17,1.01],[8,18.5,7.68],[9,19.5,1.09]],"id":12989514},{"bdatb":[[0,23,2.62],[1,21,5],[2,19.5,4.19],[3,18.5,1.37],[4,15.5,4.19],[5,15,1.8],[6,11.5,1.39],[7,10,102],[8,9.6,3.86],[9,9.4,44.53]],"id":44621159},{"bdatb":[[9,5.2,3.07]],"bdatl":[[6,13,42.63],[7,13.5,1.73],[8,14,3.75],[9,15,14.85]],"id":44836671},{"bdatb":[[8,6.2,12.58],[9,6,14]],"id":43885158},{"bdatb":[[7,11.5,1.39],[9,9.6,2.18]],"id":46969227}]}]}
{"op":"mcm","clk":"ANoSAN4JAMwP","pt":1659347434623,"mc":[{"id":"1.201590187","rc":[{"atb":[[1.99,31.22]],"atl":[[2.1,1.9]],"id":9570503}]}]}
{"op":"mcm","clk":"AN4SAOAJAM8P","pt":1659347434673,"mc":[{"id":"1.201590187","rc":[{"bdatb":[[9,9.4,45.7]],"id":45323444},{"bdatb":[[1,1.99,31.22]],"bdatl":[[0,2.1,1.9],[1,2.14,58],[2,2.18,1.18],[3,2.3,1.72],[4,2.32,1.06],[5,2.34,4.02],[6,2.36,1.42],[7,2.38,36.74],[8,2.4,76.29],[9,2.42,3.88]],"id":9570503},{"bdatb":[[5,5.9,2.68]],"id":12989514},{"bdatb":[[6,11.5,1.35]],"id":44621159},{"bdatb":[[7,5.5,23.73],[9,5.2,2.31]],"id":44836671},{"bdatb":[[6,6.6,48.08],[8,6.2,11.94]],"id":43885158},{"bdatb":[[7,11.5,1.36]],"id":46969227}]}]}
{"op":"mcm","clk":"AOISAOUJANIP","pt":1659347434730,"mc":[{"id":"1.201590187","rc":[{"atl":[[8.8,2.29]],"id":12989514},{"atb":[[22,2.59]],"id":44621159}]}]}
{"op":"mcm","clk":"AOYSAOYJANUP","pt":1659347434780,"mc":[{"id":"1.201590187","rc":[{"bdatb":[[7,1.86,2.23],[8,1.85,9.11],[9,1.83,47.99]],"id":9570503},{"bdatl":[[0,8.8,2.29]],"id":12989514},{"bdatb":[[1,22,2.59],[2,21,5],[3,19.5,4.19],[4,18.5,1.37],[5,15.5,4.19],[6,15,1.8],[7,11.5,1.35],[8,10,102],[9,9.6,3.85]],"id":44621159}]}]}
{"op":"mcm","clk":"AOoSAOkJANkP","pt":1659347434830,"mc":[{"id":"1.201590187","rc":[{"atb":[[11.5,5.54]],"bdatb":[[3,11.5,5.54]],"id":45323444}]}]}
{"op":"mcm","clk":"APASAO4JAN0P","pt":1659347434901,"mc":[{"id":"1.201590187","rc":[{"atb":[[1.05,1.5]],"id":45323444}]}]}
{"op":"mcm","clk":"AIUTAPgJAOsP","pt":1659347435203,"mc":[{"id":"1.201590187","rc":[{"atl":[[1000,0.89]],"id":45323444}]}]}
{"op":"mcm","clk":"AJoTAIQKAP0P","pt":1659347435418,"mc":[{"id":"1.201590187","rc":[{"atl":[[1000,0.48]],"id":45323444},{"atb":[[22,0]],"id":44621159}]}]}
{"op":"mcm","clk":"AJwTAIYKAIEQ","pt":1659347435468,"mc":[{"id":"1.201590187","rc":[{"bdatb":[[1,21,5],[2,19.5,4.19],[3,18.5,1.37],[4,15.5,4.19],[5,15,1.8],[6,11.5,1.35],[7,10,102],[8,9.6,3.85],[9,9.4,44.53]],"id":44621159}]}]}
{"op":"mcm","clk":"AJ4TAIgKAIcQ","pt":1659347435520,"mc":[{"id":"1.201590187","rc":[{"atl":[[20,0.41]],"id":45323444},{"atb":[[23,4.6]],"id":44621159}]}]}
{"op":"mcm","clk":"AJ8TAIoKAIkQ","pt":1659347435570,"mc":[{"id":"1.201590187","rc":[{"bdatl":[[1,21,1.41]],"id":45323444},{"bdatb":[[7,1.87,2.22],[8,1.86,2.19],[9,1.85,11.35]],"id":9570503},{"bdatb":[[6,5.5,1.49],[7,5.4,3.89],[8,5.2,4.22],[9,5,4.3]],"id":12989514},{"bdatb":[[0,23,5.09],[7,10,102.42],[8,9.6,4.27]],"id":44621159},{"bdatb":[[8,10,2.42],[9,9.6,2.6]],"id":46969227}]}]}
{"op":"mcm","clk":"AMUTAJ4KAKYQ","pt":1659347436231,"mc":[{"id":"1.201590187","rc":[{"atb":[[7.4,2]],"id":12989514},{"atb":[[23,2.13]],"id":44621159},{"atb":[[7.8,1.26]],"id":43885158}]}]}
{"op":"mcm","clk":"AMcTAKAKAKoQ","pt":1659347436281,"mc":[{"id":"1.201590187","rc":[{"bdatl":[[6,2.36,1.24],[7,2.38,36.92],[8,2.4,71.95],[9,2.42,4.31]],"id":9570503},{"bdatb":[[0,7.4,2]],"bdatl":[[9,21,1.04]],"id":12989514},{"bdatb":[[0,23,2.62]],"id":44621159},{"bdatl":[[8,14,3.72],[9,15,14.88]],"id":44836671},{"bdatb":[[1,7.8,1.26]],"id":43885158}]}]}
{"op":"mcm","clk":"AOMTAKwKAMkQ","pt":1659347436711,"mc":[{"id":"1.201590187","rc":[{"atl":[[8.8,0.29]],"id":12989514}]}]}
{"op":"mcm","clk":"AOQTAK8KAM8Q","pt":1659347436784,"mc":[{"id":"1.201590187","rc":[{"bdatb":[[6,1.91,107.6],[7,1.9,7.08],[8,1.86,4.42]],"id":9570503},{"bdatl":[[0,9,8.52],[1,9.4,3.95],[2,9.6,14.09],[3,10,17.36],[4,10.5,12.47],[5,11,33.84],[6,17,1.01],[7,18.5,7.68],[8,21,1.04],[9,30,8.74]],"id":12989514},{"bdatb":[[6,11,1.4],[7,10,102],[8,9.6,4.7]],"id":44621159},{"bdatb":[[7,5.5,23.46],[8,5.4,14.27],[9,5.1,35.9]],"id":44836671},{"bdatb":[[6,6.6,47.86],[7,6.4,2.22],[8,6.2,10],[9,6,16]],"id":43885158},{"bdatb":[[7,11,1.41],[8,10,2],[9,9.6,3.03]],"id":46969227}]}]}
{"op":"mcm","clk":"APATALIKAN0Q","pt":1659347436921,"mc":[{"id":"1.201590187","rc":[{"atl":[[8.8,2.29]],"id":12989514},{"atb":[[23,0]],"id":46969227}]}]}
{"op":"mcm","clk":"APETALQKAOAQ","pt":1659347436971,"mc":[{"id":"1.201590187","rc":[{"bdatb":[[6,1.91,114.64],[7,1.87,2.22],[8,1.86,2.19]],"bdatl":[[4,2.34,1.05],[5,2.36,4.98],[6,2.38,33.8],[7,2.4,74.77],[8,2.44,160.72],[9,2.46,3.39]],"id":9570503},{"bdatl":[[0,8.8,2.29],[1,9,8.23],[2,9.4,3.95],[3,9.6,14.09],[4,10,17.36],[5,10.5,12.47],[6,11,33.84],[7,18.5,8.65],[8,24,1.58],[9,30,8.01]],"id":12989514},{"bdatb":[[6,11.5,1.35],[7,10,102.42],[8,9.6,4.27]],"id":44621159},{"bdatb":[[7,5.5,23.73],[8,5.4,14],[9,5.2,2.31]],"bdatl":[[5,12,1.41],[6,13,42.41],[7,13.5,2.13],[8,14,3.68],[9,15,14.89]],"id":44836671},{"bdatb":[[6,6.6,48.08],[7,6.4,2],[8,6.2,11.94],[9,6,14]],"id":43885158},{"bdatb":[[0,22,1.63],[1,21,5.1],[2,20,6.4],[3,19.5,7],[4,19,5],[5,16,1.43],[6,11.5,1.36],[7,10,2.42],[8,9.6,2.6],[9,9.4,34.48]],"id":46969227}]}]}
{"op":"mcm","clk":"APMTALUKAOQQ","pt":1659347437021,"mc":[{"id":"1.201590187","rc":[{"atb":[[22,3.13]],"id":46969227}]}]}
{"op":"mcm","clk":"APYTALgKAOQQ","pt":1659347437072,"mc":[{"id":"1.201590187","rc":[{"bdatl":[[8,21,1],[9,30,8.74]],"id":12989514},{"bdatb":[[0,22,3.13]],"id":46969227}]}]}
{"op":"mcm","clk":"APgTALgKAOYQ","pt":1659347437128,"mc":[{"id":"1.201590187","rc":[{"atb":[[22,3.24]],"id":46969227}]}]}
{"op":"mcm","clk":"APwTALsKAPAQ","pt":1659347437185,"mc":[{"id":"1.201590187","rc":[{"bdatb":[[0,22,3.24]],"id":46969227}]}]}
{"op":"mcm","clk":"AIQUAL0KAPgQ","pt":1659347437329,"mc":[{"id":"1.201590187","rc":[{"atb":[[7,8.55]],"id":12989514}]}]}
{"op":"mcm","clk":"AIwUAMAKAPsQ","pt":1659347437379,"mc":[{"id":"1.201590187","rc":[{"bdatb":[[2,7,8.55]],"id":12989514}]}]}
{"op":"mcm","clk":"AKQUAMcKAIwR","pt":1659347437695,"mc":[{"id":"1.201590187","rc":[{"atl":[[34,0]],"id":44621159}]}]}
{"op":"mcm","clk":"AKgUAMgKAJMR","pt":1659347437746,"mc":[{"id":"1.201590187","rc":[{"bdatb":[[8,5.1,4.28],[9,4.9,12.4]],"id":12989514},{"bdatl":[[1,40,3.27],[2,120,7.62],[3,170,2],[4,990,2.07],[5,0,0]],"id":44621159}]}]}
{"op":"mcm","clk":"AL8UANQKAK0R","pt":1659347438212,"mc":[{"id":"1.201590187","rc":[{"atl":[[1000,2]],"id":44621159}]}]}
{"op":"mcm","clk":"AMMUANUKALMR","pt":1659347438262,"mc":[{"id":"1.201590187","rc":[{"bdatl":[[5,1000,2]],"id":44621159}]}]}
{"op":"mcm","clk":"AMoUANcKALcR","pt":1659347438332,"mc":[{"id":"1.201590187","rc":[{"atl":[[1000,2.41]],"id":44621159}]}]}
{"op":"mcm","clk":"AMsUANgKALwR","pt":1659347438382,"mc":[{"id":"1.201590187","rc":[{"bdatl":[[5,1000,2.41]],"id":44621159}]}]}
{"op":"mcm","clk":"AMwUANgKAL0R","pt":1659347438432,"mc":[{"id":"1.201590187","rc":[{"atb":[[7,5.57]],"id":12989514}]}]}
{"op":"mcm","clk":"ANAUANkKAMER","pt":1659347438482,"mc":[{"id":"1.201590187","rc":[{"bdatb":[[2,7,5.57]],"id":12989514}]}]}
{"op":"mcm","clk":"ANEUANkKAMMR","pt":1659347438532,"mc":[{"id":"1.201590187","rc":[{"atl":[[1000,2]],"id":44621159}]}]}
{"op":"mcm","clk":"ANYUANsKAMYR","pt":1659347438582,"mc":[{"id":"1.201590187","rc":[{"bdatl":[[5,1000,2]],"id":44621159}]}]}
{"op":"mcm","clk":"ANgUAN0KAMwR","pt":1659347438644,"mc":[{"id":"1.201590187","rc":[{"atl":[[38,0.41]],"id":44621159}]}]}
{"op":"mcm","clk":"ANoUAN4KAM0R","pt":1659347438694,"mc":[{"id":"1.201590187","rc":[{"bdatl":[[1,40,3.68]],"id":44621159}]}]}
{"op":"mcm","clk":"AN4UAOAKANAR","pt":1659347438746,"mc":[{"id":"1.201590187","rc":[{"atb":[[23,1]],"id":44621159}]}]}
{"op":"mcm","clk":"AOAUAOQKANQR","pt":1659347438796,"mc":[{"id":"1.201590187","rc":[{"atb":[[22,1.13]],"bdatb":[[0,23,1.49]],"id":44621159},{"bdatl":[[8,2.44,157.03],[9,2.46,3.66]],"id":9570503},{"bdatl":[[8,25,1.53],[9,30,8.01]],"id":12989514}]}]}
{"op":"mcm","clk":"AOcUAOQKANcR","pt":1659347438846,"mc":[{"id":"1.201590187","rc":[{"bdatl":[[8,2.44,160.72],[9,2.46,3.39]],"id":9570503},{"bdatl":[[8,23,1.6]],"id":12989514},{"bdatb":[[1,22,1.13],[2,21,5],[3,19.5,4.19],[4,18.5,1.37],[5,15.5,4.19],[6,15,1.8],[7,11.5,1.35],[8,10,102.42],[9,9.6,4.27]],"id":44621159}]}]}
{"op":"mcm","clk":"APkUAPAKAOsR","pt":1659347439320,"mc":[{"id":"1.201590187","rc":[{"atb":[[1.99,33.5]],"id":9570503}]}]}
{"op":"mcm","clk":"AP8UAPIKAPAR","pt":1659347439370,"mc":[{"id":"1.201590187","rc":[{"bdatb":[[1,1.99,33.5]],"id":9570503}]}]}
{"op":"mcm","clk":"AIAVAPMKAPIR","pt":1659347439423,"mc":[{"id":"1.201590187","rc":[{"atb":[[15,0]],"id":44621159}]}]}
{"op":"mcm","clk":"AIUVAPQKAPUR","pt":1659347439473,"mc":[{"id":"1.201590187","rc":[{"bdatb":[[6,11.5,1.35],[7,10,102.42],[8,9.6,4.27],[9,9.4,44.53]],"id":44621159}]}]}
{"op":"mcm","clk":"AIcVAPQKAPkR","pt":1659347439530,"mc":[{"id":"1.201590187","rc":[{"atb":[[22,2.93]],"id":44621159}]}]}
{"op":"mcm","clk":"AIwVAPgKAPwR","pt":1659347439580,"mc":[{"id":"1.201590187","rc":[{"bdatb":[[1,22,2.93]],"id":44621159}]}]}
{"op":"mcm","clk":"APAWAPILALMT","pt":1659347443318,"mc":[{"id":"1.201590187","rc":[{"atb":[[21,0.1],[18.5,7]],"id":46969227}]}]}
{"op":"mcm","clk":"APgWAPMLALcT","pt":1659347443368,"mc":[{"id":"1.201590187","rc":[{"bdatb":[[1,20,6.5],[2,19.5,7],[3,19,5],[4,18.5,7]],"id":46969227}]}]}
{"op":"mcm","clk":"APkWAPQLALgT","pt":1659347443418,"mc":[{"id":"1.201590187","rc":[{"atl":[[38,1.56]],"id":44621159}]}]}
{"op":"mcm","clk":"AP8WAPULALoT","pt":1659347443468,"mc":[{"id":"1.201590187","rc":[{"bdatb":[[8,5.1,4.79],[9,5,3.98]],"id":12989514},{"bdatl":[[1,38,1.56],[2,40,3.27],[3,120,7.62],[4,170,2],[5,990,2.07],[6,1000,2]],"id":44621159}]}]}
{"op":"mcm","clk":"AI0XAP4LAMQT","pt":1659347443729,"mc":[{"id":"1.201590187","rc":[{"atl":[[1000,0]],"id":44621159}]}]}
{"op":"mcm","clk":"AJQXAP8LAMYT","pt":1659347443779,"mc":[{"id":"1.201590187","rc":[{"bdatl":[[6,0,0]],"id":44621159}]}]}
{"op":"mcm","clk":"AKMXAIUMANET","pt":1659347444040,"mc":[{"id":"1.201590187","rc":[{"atb":[[22,1.61]],"id":46969227}]}]}
{"op":"mcm","clk":"AKkXAIYMANIT","pt":1659347444090,"mc":[{"id":"1.201590187","rc":[{"bdatl":[[8,2.44,157.25],[9,2.48,3.42]],"id":9570503},{"bdatl":[[8,26,1.5],[9,30,8]],"id":12989514},{"bdatb":[[0,22,1.61]],"id":46969227}]}]}
{"op":"mcm","clk":"AKwXAIgMANcT","pt":1659347444140,"mc":[{"id":"1.201590187","rc":[{"atb":[[21,1.73]],"bdatb":[[1,21,1.73],[2,20,6.4],[3,19.5,7],[4,19,5],[5,18.5,7],[6,16,1.43],[7,11.5,1.36],[8,10,2.42],[9,9.6,2.6]],"id":46969227},{"bdatl":[[9,2.46,3.45]],"id":9570503},{"bdatl":[[8,25,1.53],[9,30,8.01]],"id":12989514}]}]}
{"op":"mcm","clk":"ALcXAIsMANkT","pt":1659347444252,"mc":[{"id":"1.201590187","rc":[{"atb":[[22,1.5]],"id":46969227}]}]}
{"op":"mcm","clk":"ALsXAIwMANwT","pt":1659347444302,"mc":[{"id":"1.201590187","rc":[{"bdatl":[[8,2.44,157.03],[9,2.46,3.66]],"id":9570503},{"bdatl":[[8,25,1.54]],"id":12989514},{"bdatb":[[0,22,1.5]],"id":46969227}]}]}
{"op":"mcm","clk":"AM4XAJQMAO8T","pt":1659347444618,"mc":[{"id":"1.201590187","rc":[{"atb":[[22,2.5]],"atl":[[30,2.07]],"id":46969227}]}]}
{"op":"mcm","clk":"ANIXAJcMAPQT","pt":1659347444668,"mc":[{"id":"1.201590187","rc":[{"bdatb":[[9,9.4,45.9]],"id":45323444},{"bdatb":[[5,1.92,8.33],[6,1.91,107.36],[8,1.86,13.48],[9,1.84,2.49]],"bdatl":[[8,2.44,160.72],[9,2.46,3.39]],"id":9570503},{"bdatb":[[5,6,2.64],[6,5.5,5.31],[7,5.2,3.23],[8,5.1,1.87],[9,5,7.49]],"bdatl":[[8,23,1.46],[9,30,8.14]],"id":12989514},{"bdatb":[[7,10,102.82],[8,9.8,2.14],[9,9.6,1.68]],"id":44621159},{"bdatb":[[9,5.3,2.27]],"id":44836671},{"bdatb":[[0,22,2.5]],"bdatl":[[0,30,2.07],[1,32,2.12],[2,34,5.6],[3,38,2.51],[4,40,5.01],[5,80,1.66],[6,310,1],[7,990,2.15]],"id":46969227}]}]}
{"op":"mcm","clk":"ANMXAJcMAP4T","pt":1659347444722,"mc":[{"id":"1.201590187","rc":[{"atb":[[22,3.5]],"atl":[[32,2.21]],"id":46969227}]}]}
{"op":"mcm","clk":"ANcXAJoMAIEU","pt":1659347444772,"mc":[{"id":"1.201590187","rc":[{"bdatl":[[8,23,1.6],[9,30,8.01]],"id":12989514},{"bdatb":[[0,22,3.5]],"bdatl":[[1,32,2.21]],"id":46969227}]}]}
{"op":"mcm","clk":"AOEXAKEMAJEU","pt":1659347445028,"mc":[{"id":"1.201590187","rc":[{"atb":[[8,8.65]],"id":43885158}]}]}
{"op":"mcm","clk":"AOcXAKIMAJYU","pt":1659347445078,"mc":[{"id":"1.201590187","rc":[{"bdatl":[[5,2.36,5.23],[6,2.38,36.92],[7,2.4,80.21],[8,2.42,3.44],[9,2.44,152.09]],"id":9570503},{"bdatl":[[7,17.5,1.48],[8,18.5,7.85],[9,20,1.18]],"id":12989514},{"bdatl":[[7,13.5,2.17],[9,15,15.68]],"id":44836671},{"bdatb":[[0,8,8.95]],"id":43885158}]}]}
{"op":"mcm","clk":"AO4XAKcMAKUU","pt":1659347445237,"mc":[{"id":"1.201590187","rc":[{"atb":[[23,3.47]],"id":44621159}]}]}
{"op":"mcm","clk":"APIXAKcMAKkU","pt":1659347445287,"mc":[{"id":"1.201590187","rc":[{"bdatl":[[9,2.44,154.52]],"id":9570503},{"bdatl":[[8,18.5,8.34],[9,23,1.32]],"id":12989514},{"bdatb":[[0,23,3.96]],"id":44621159},{"bdatl":[[9,15,16.28]],"id":44836671}]}]}
{"op":"mcm","clk":"AIwYALIMAL0U","pt":1659347445608,"mc":[{"id":"1.201590187","rc":[{"atb":[[13.5,2.69]],"atl":[[20,1.41]],"id":45323444},{"atb":[[24,1.49]],"atl":[[36,1]],"id":44621159}]}]}
{"op":"mcm","clk":"AJIYALUMAMIU","pt":1659347445659,"mc":[{"id":"1.201590187","rc":[{"bdatb":[[0,13.5,2.69]],"bdatl":[[1,20,1.41],[2,21,1],[3,23,1.15],[4,25,2.42],[5,26,7.87],[6,27,3.85],[7,29,5.36],[8,32,6.46],[9,50,8]],"id":45323444},{"bdatb":[[8,1.86,15.94],[9,1.84,8.38]],"bdatl":[[6,2.38,42.59],[7,2.4,78.05],[8,2.42,2.14],[9,2.44,157.93]],"id":9570503},{"bdatb":[[6,5.5,6.14],[7,5.4,2.28],[8,5.1,5.76],[9,5,7.29]],"bdatl":[[7,17,2.26],[8,18.5,8.37],[9,27,1.11]],"id":12989514},{"bdatb":[[0,24,1.49],[1,23,3.47],[2,22,2.93],[3,21,5],[4,19.5,4.19],[5,18.5,1.37],[6,15.5,4.19],[7,11.5,1.35],[8,10,104.82],[9,9.8,1.82]],"bdatl":[[1,36,1],[2,38,1.56],[3,40,3.27],[4,120,7.62],[5,170,2],[6,990,2.07]],"id":44621159},{"bdatl":[[8,14,5.19],[9,15,15.41]],"id":44836671},{"bdatb":[[9,9.8,2.46]],"id":46969227}]}]}
{"op":"mcm","clk":"AKQYAL8MAM0U","pt":1659347446019,"mc":[{"id":"1.201590187","rc":[{"atb":[[23,1]],"id":44621159},{"atb":[[8,1.47]],"id":43885158}]}]}
{"op":"mcm","clk":"AKwYAMAMANYU","pt":1659347446069,"mc":[{"id":"1.201590187","rc":[{"bdatl":[[6,2.38,37.44],[7,2.4,76.35],[8,2.44,158.78],[9,2.46,2.1]],"id":9570503},{"bdatl":[[7,18,1.53],[8,18.5,7.2],[9,21,1.64]],"id":12989514},{"bdatb":[[1,23,1]],"id":44621159},{"bdatl":[[7,13.5,2.13],[8,14,3.72],[9,15,14.96]],"id":44836671},{"bdatb":[[0,8,1.77]],"id":43885158}]}]}
{"op":"mcm","clk":"AK0YAMUMANgU","pt":1659347446126,"mc":[{"id":"1.201590187","rc":[{"atb":[[7.4,0],[7.2,1.41]],"trd":[[7.4,12.39],[7.2,1.1]],"ltp":7.2,"tv":51.82,"id":12989514},{"atb":[[7.8,8.62]],"id":43885158}],"tv":1130.36}]}
{"op":"mcm","clk":"ALMYAMUMANsU","pt":1659347446176,"mc":[{"id":"1.201590187","rc":[{"bdatl":[[4,2.36,1.04],[5,2.38,36.79],[6,2.4,73.11],[7,2.42,9.14],[8,2.44,157.36],[9,2.46,3.33]],"id":9570503},{"bdatb":[[0,7.2,1.41],[1,7,5.57],[2,6.8,11.36],[3,6.6,1.15],[4,6,2.64],[5,5.5,6.14],[6,5.4,2.28],[7,5.1,5.76],[8,5,7.29],[9,4.8,227.98]],"bdatl":[[7,18,2.18],[8,18.5,7.22],[9,19.5,1.08]],"id":12989514},{"bdatl":[[6,13,42.09],[7,13.5,1.85],[8,14,3.94],[9,15,14.59]],"id":44836671},{"bdatb":[[1,7.8,8.62]],"id":43885158}]}]}
{"op":"mcm","clk":"ALkYAMoMAOEU","pt":1659347446329,"mc":[{"id":"1.201590187","rc":[{"atb":[[1.99,31.22]],"id":9570503},{"atb":[[24,3.91]],"id":44621159}]}]}
{"op":"mcm","clk":"AL4YAMoMAOQU","pt":1659347446379,"mc":[{"id":"1.201590187","rc":[{"bdatb":[[1,1.99,31.22]],"bdatl":[[7,2.42,14.46],[8,2.44,152.09]],"id":9570503},{"bdatl":[[7,18,2.21],[8,18.5,7.2],[9,19,1.11]],"id":12989514},{"bdatb":[[0,24,3.91]],"id":44621159}]}]}
{"op":"mcm","clk":"AL8YAMwMAOUU","pt":1659347446432,"mc":[{"id":"1.201590187","rc":[{"atb":[[6.8,13.73]],"id":12989514}]}]}
{"op":"mcm","clk":"AMQYAM4MAOkU","pt":1659347446482,"mc":[{"id":"1.201590187","rc":[{"bdatb":[[2,6.8,13.73]],"id":12989514}]}]}
{"op":"mcm","clk":"AOIYAOEMAPsU","pt":1659347446816,"mc":[{"id":"1.201590187","rc":[{"atb":[[13,0.62]],"atl":[[21,0]],"id":45323444},{"atb":[[7,0.35]],"atl":[[9,6.23]],"id":12989514},{"atb":[[23,0]],"atl":[[32,0.56]],"id":44621159}]}]}
{"op":"mcm","clk":"AOIYAOIMAIEV","pt":1659347446866,"mc":[{"id":"1.201590187","rc":[{"bdatb":[[1,12.5,1.76],[2,11.5,5.54],[3,11,1.23],[4,10.5,4.47],[5,10,10],[6,9.8,9],[7,9.6,21],[8,9.4,45.9],[9,9.2,12]],"bdatl":[[2,23,1.15],[3,25,2.42],[4,26,7.87],[5,27,3.85],[6,29,5.36],[7,32,6.46],[8,50,8],[9,55,9]],"id":45323444},{"bdatb":[[7,1.86,2.23],[8,1.85,13.01],[9,1.83,38.78]],"bdatl":[[6,2.4,72.45],[7,2.44,161.81],[8,2.46,3.28],[9,2.48,5.75]],"id":9570503},{"bdatb":[[1,6.8,14.08],[2,6.6,1.15],[3,6,2.64],[4,5.4,5.22],[5,5.2,3.44],[6,5.1,1.68],[7,5,8.49],[8,4.9,3.07],[9,4.8,227.44]],"bdatl":[[1,9,6.23],[9,20,1.13]],"id":12989514},{"bdatb":[[1,22,2.93],[2,21,5],[3,19.5,4.19],[4,18.5,1.37],[5,15.5,4.19],[6,11.5,1.35],[7,10,104.82],[8,9.6,1.68],[9,9.4,46.43]],"bdatl":[[0,36,1.56],[1,38,1.56],[2,40,3.27],[3,120,7.62],[4,170,2],[5,990,2.07],[6,0,0]],"id":44621159},{"bdatl":[[9,15,14.48]],"id":44836671},{"bdatb":[[8,10,2.18],[9,9.4,37.28]],"id":46969227}]}]}
{"op":"mcm","clk":"AOYYAOMMAIYV","pt":1659347446918,"mc":[{"id":"1.201590187","rc":[{"atb":[[4.9,5.22]],"atl":[[1000,3.35]],"id":12989514}]}]}
{"op":"mcm","clk":"AOsYAOMMAIYV","pt":1659347446969,"mc":[{"id":"1.201590187","rc":[{"bdatb":[[8,4.9,8.29]],"id":12989514}]}]}
{"op":"mcm","clk":"APUYAOoMAI4V","pt":1659347447110,"mc":[{"id":"1.201590187","rc":[{"atb":[[13,0]],"id":45323444},{"atb":[[6.8,11.36]],"id":12989514},{"atb":[[24,1.49],[22,1.8]],"id":44621159}]}]}
{"op":"mcm","clk":"APkYAOsMAJAV","pt":1659347447160,"mc":[{"id":"1.201590187","rc":[{"bdatb":[[1,12.5,1.14]],"id":45323444},{"bdatl":[[7,2.44,161.62],[8,2.5,26.88],[9,2.54,9.79]],"id":9570503},{"bdatb":[[1,6.8,11.71]],"bdatl":[[7,18,2.18],[9,26,1.36]],"id":12989514},{"bdatb":[[0,24,1.49],[1,22,1.8]],"id":44621159}]}]}
{"op":"mcm","clk":"APsYAO8MAJEV","pt":1659347447221,"mc":[{"id":"1.201590187","rc":[{"atb":[[1.04,0.62]],"id":45323444},{"atl":[[1000,1.35]],"id":12989514},{"atb":[[1.04,1.13]],"id":44621159},{"atl":[[32,1.8]],"id":46969227}]}]}
{"op":"mcm","clk":"AIEZAPIMAJkV","pt":1659347447271,"mc":[{"id":"1.201590187","rc":[{"bdatl":[[1,32,1.8]],"id":46969227}]}]}
{"op":"mcm","clk":"AIQZAPIMAJkV","pt":1659347447323,"mc":[{"id":"1.201590187","rc":[{"atb":[[25,2.3]],"id":44621159}]}]}
{"op":"mcm","clk":"AIkZAPIMAKEV","pt":1659347447373,"mc":[{"id":"1.201590187","rc":[{"bdatl":[[4,2.34,1.05],[5,2.36,3.27],[6,2.38,34.58],[7,2.4,72.09],[8,2.42,9.14],[9,2.44,152.09]],"id":9570503},{"bdatl":[[7,16.5,1.01],[8,17.5,1.26],[9,18.5,7.2]],"id":12989514},{"bdatb":[[0,25,2.3],[1,24,1.49],[2,22,1.8],[3,21,5],[4,19.5,4.19],[5,18.5,1.37],[6,15.5,4.19],[7,11.5,1.35],[8,10,104.82],[9,9.6,1.68]],"id":44621159},{"bdatl":[[9,15,14.49]],"id":44836671}]}]}
{"op":"mcm","clk":"AIwZAPcMAKUV","pt":1659347447430,"mc":[{"id":"1.201590187","rc":[{"atb":[[1.05,0]],"id":45323444},{"atb":[[1.99,33.5]],"id":9570503},{"atl":[[1000,3.34]],"id":12989514},{"atb":[[22,2]],"id":46969227}]}]}
{"op":"mcm","clk":"AJIZAPgMAKcV","pt":1659347447480,"mc":[{"id":"1.201590187","rc":[{"bdatb":[[1,1.99,33.5]],"id":9570503},{"bdatb":[[0,22,2]],"id":46969227}]}]}
{"op":"mcm","clk":"AJQZAPgMAKsV","pt":1659347447533,"mc":[{"id":"1.201590187","rc":[{"atb":[[11.5,7.04]],"id":45323444},{"atl":[[8.4,0.88]],"id":12989514},{"atb":[[21,3.23]],"id":46969227}]}]}
{"op":"mcm","clk":"AJoZAPgMAKwV","pt":1659347447583,"mc":[{"id":"1.201590187","rc":[{"bdatb":[[2,11.5,7.04],[6,9.8,9.41],[8,9.4,45.48]],"id":45323444},{"bdatb":[[5,1.94,3.81],[6,1.92,4.48],[7,1.91,107.36],[8,1.86,6.2],[9,1.85,9.01]],"id":9570503},{"bdatl":[[0,8.8,3.17]],"id":12989514},{"bdatb":[[7,11.5,1.3]],"id":44621159},{"bdatb":[[5,5.7,45.25],[7,5.5,23],[8,5.4,14.63],[9,5.3,1.62]],"id":44836671},{"bdatb":[[5,7,5.57],[6,6.6,47.99],[8,6.2,11.39]],"id":43885158},{"bdatb":[[1,21,3.23],[7,11.5,1.33],[9,9.4,37.24]],"id":46969227}]}]}
{"op":"mcm","clk":"AKMZAPwMAMMV","pt":1659347447743,"mc":[{"id":"1.201590187","rc":[{"atb":[[7.2,1.07]],"id":12989514}]}]}
{"op":"mcm","clk":"AKgZAP4MAMcV","pt":1659347447798,"mc":[{"id":"1.201590187","rc":[{"bdatl":[[5,2.36,2.23],[7,2.4,73.11]],"id":9570503},{"bdatb":[[0,7.2,1.07]],"id":12989514},{"bdatl":[[8,14,3.77]],"id":44836671}]}]}
{"op":"mcm","clk":"AKoZAP8MAMkV","pt":1659347447852,"mc":[{"id":"1.201590187","rc":[{"atl":[[1000,0.47]],"id":12989514}]}]}
{"op":"mcm","clk":"AL0ZAIQNANYV","pt":1659347448030,"mc":[{"id":"1.201590187","rc":[{"atb":[[13,4.42]],"id":45323444}]}]}
{"op":"mcm","clk":"AL0ZAIQNANkV","pt":1659347448080,"mc":[{"id":"1.201590187","rc":[{"bdatb":[[1,13,4.42],[2,12.5,1.14],[3,11.5,7.04],[4,11,1.23],[5,10.5,4.47],[6,10,10],[7,9.8,9.41],[8,9.6,21],[9,9.4,45.48]],"id":45323444},{"bdatl":[[9,2.44,155.24]],"id":9570503},{"bdatl":[[9,18.5,7.62]],"id":12989514}]}]}
{"op":"mcm","clk":"AMMZAIkNAN8V","pt":1659347448130,"mc":[{"id":"1.201590187","rc":[{"atb":[[1.02,3]],"atl":[[1000,3.47]],"id":12989514}]}]}
{"op":"mcm","clk":"AMkZAI4NAOMV","pt":1659347448232,"mc":[{"id":"1.201590187","rc":[{"atl":[[1000,6.35]],"id":12989514}]}]}
{"op":"mcm","clk":"ANAZAJINAOkV","pt":1659347448332,"mc":[{"id":"1.201590187","rc":[{"atb":[[1.02,1]],"atl":[[1000,4.35]],"trd":[[7.2,1.12]],"tv":51.84,"id":12989514}],"tv":1130.38}]}
{"op":"mcm","clk":"ANQZAJQNAOoV","pt":1659347448383,"mc":[{"id":"1.201590187","rc":[{"bdatl":[[5,2.36,2.21],[7,2.4,73.13]],"id":9570503},{"bdatl":[[8,14,3.76]],"id":44836671}]}]}
{"op":"mcm","clk":"ANcZAJUNAO8V","pt":1659347448433,"mc":[{"id":"1.201590187","rc":[{"atl":[[1000,2.35]],"id":12989514}]}]}
{"op":"mcm","clk":"AN0ZAJgNAPQV","pt":1659347448523,"mc":[{"id":"1.201590187","rc":[{"atb":[[1.02,0]],"atl":[[1000,1.35]],"id":12989514}]}]}
{"op":"mcm","clk":"AOMZAJwNAP0V","pt":1659347448630,"mc":[{"id":"1.201590187","rc":[{"atb":[[7,1.35]],"atl":[[1000,0.47],[8.6,1]],"id":12989514}]}]}
{"op":"mcm","clk":"AOoZAJ4NAIAW","pt":1659347448680,"mc":[{"id":"1.201590187","rc":[{"bdatb":[[6,1.93,4.46],[8,1.86,10.83],[9,1.85,4.36]],"bdatl":[[6,2.38,36.29],[7,2.4,72.65],[8,2.42,7.94]],"id":9570503},{"bdatb":[[1,7,1.35],[2,6.8,11.36],[3,6.6,1.15],[4,6,2.64],[5,5.4,5.22],[6,5.2,3.44],[7,5.1,1.68],[8,5,8.49],[9,4.9,8.29]],"bdatl":[[0,8.6,1.88],[1,8.8,2.29],[2,9,6.23],[3,9.4,3.95],[4,9.6,14.09],[5,10,17.36],[6,10.5,12.47],[7,11,33.84],[8,16.5,1.01],[9,17.5,1.26]],"id":12989514},{"bdatb":[[7,12,1.27]],"id":44621159},{"bdatb":[[8,5.4,16.22],[9,5.1,33.55]],"bdatl":[[9,15,14.96]],"id":44836671},{"bdatb":[[7,6.4,3.34],[8,6.2,10]],"id":43885158},{"bdatb":[[9,9.8,1.87]],"id":46969227}]}]}
{"op":"mcm","clk":"AOwZAKANAIMW","pt":1659347448731,"mc":[{"id":"1.201590187","rc":[{"atb":[[13.5,1],[13,0]],"id":45323444},{"atl":[[8.4,1.76]],"id":12989514}]}]}
{"op":"mcm","clk":"AO8ZAKENAIoW","pt":1659347448788,"mc":[{"id":"1.201590187","rc":[{"bdatb":[[0,13.5,1],[1,12.5,1.14],[2,11.5,7.04],[3,11,1.23],[4,10.5,4.47],[5,10,10],[6,9.8,9.41],[7,9.6,21],[8,9.4,45.48],[9,9.2,12]],"id":45323444},{"bdatb":[[5,1.94,7.62],[6,1.91,107.99],[7,1.87,3.94],[9,1.83,39.15]],"bdatl":[[6,2.38,36],[7,2.4,71.43],[8,2.44,153.58],[9,2.46,4.32]],"id":9570503},{"bdatl":[[0,8.4,1.76],[1,8.6,1],[2,8.8,2.29],[3,9,6.23],[4,9.4,3.95],[5,9.6,14.09],[6,10,17.36],[7,10.5,12.47],[8,11,33.84],[9,18.5,8.21]],"id":12989514},{"bdatb":[[7,12.5,1.14],[8,10,104.88]],"id":44621159},{"bdatl":[[9,15,14.73]],"id":44836671},{"bdatb":[[6,6.6,49.11],[7,6.4,2.19]],"id":43885158},{"bdatb":[[7,12,1.2],[8,10,2.85],[9,9.8,2.06]],"id":46969227}]}]}
{"op":"mcm","clk":"APQZAKMNAI0W","pt":1659347448851,"mc":[{"id":"1.201590187","rc":[{"atl":[[8.6,1.3]],"id":12989514}]}]}
{"op":"mcm","clk":"APUZAKQNAJAW","pt":1659347448902,"mc":[{"id":"1.201590187","rc":[{"bdatb":[[7,1.87,5.32],[8,1.86,9.81],[9,1.84,1.03]],"id":9570503},{"bdatl":[[1,8.6,1.3]],"id":12989514},{"bdatb":[[8,10.5,1.05],[9,10,103.83]],"id":44621159},{"bdatb":[[8,10,3.11],[9,9.8,1.86]],"id":46969227}]}]}
{"op":"mcm","clk":"APgZAKcNAJMW","pt":1659347448959,"mc":[{"id":"1.201590187","rc":[{"atb":[[13.5,5.25],[1.01,48.08]],"id":45323444},{"atl":[[8.8,0.29]],"id":12989514}]}]}
{"op":"mcm","clk":"APkZAKkNAJYW","pt":1659347449009,"mc":[{"id":"1.201590187","rc":[{"bdatb":[[0,13.5,5.25]],"id":45323444},{"bdatb":[[8,1.86,1.37],[9,1.85,8.49]],"bdatl":[[6,2.38,36.29],[7,2.4,72.65],[8,2.42,11.11],[9,2.44,163.12]],"id":9570503},{"bdatl":[[2,9,6.52],[3,9.4,3.95],[4,9.6,14.09],[5,10,17.36],[6,10.5,12.47],[7,11,33.84],[8,16.5,1.01],[9,17.5,1.7]],"id":12989514},{"bdatl":[[9,15,14.96]],"id":44836671},{"bdatb":[[9,9.4,36.41]],"id":46969227}]}]}
{"op":"mcm","clk":"AIMaALANAJ0W","pt":1659347449167,"mc":[{"id":"1.201590187","rc":[{"atb":[[1.01,47.24]],"atl":[[25,0],[23,2.97]],"id":45323444},{"atl":[[9.2,5.1],[9,0.31]],"id":12989514}]}]}
{"op":"mcm","clk":"AIkaALENAKIW","pt":1659347449217,"mc":[{"id":"1.201590187","rc":[{"bdatl":[[2,23,2.97],[3,26,8.62],[4,27,3.85],[5,29,5.36],[6,32,6.46],[7,50,8],[8,55,9],[9,60,10]],"id":45323444},{"bdatb":[[9,1.85,1.51]],"id":9570503},{"bdatb":[[7,5.1,9.88],[8,5,1.41],[9,4.9,6.97]],"bdatl":[[2,9.2,5.7],[3,9.4,3.67]],"id":12989514},{"bdatb":[[9,10,102.53]],"id":44621159},{"bdatb":[[9,9.4,35.03]],"id":46969227}]}]}
{"op":"mcm","clk":"AI8aALQNAKkW","pt":1659347449323,"mc":[{"id":"1.201590187","rc":[{"atb":[[1.01,45.55]],"atl":[[22,0.82]],"id":45323444}]}]}
{"op":"mcm","clk":"AI8aALQNAKwW","pt":1659347449373,"mc":[{"id":"1.201590187","rc":[{"bdatl":[[2,23,3.79]],"id":45323444},{"bdatb":[[6,5.3,3.37],[7,5.1,9.99],[8,5,3.01],[9,4.9,5.22]],"id":12989514}]}]}
{"op":"mcm","clk":"AJMaALcNALAW","pt":1659347449426,"mc":[{"id":"1.201590187","rc":[{"atb":[[14,1.69]],"atl":[[24,0]],"id":45323444}]}]}
{"op":"mcm","clk":"AJUaALwNALIW","pt":1659347449476,"mc":[{"id":"1.201590187","rc":[{"bdatb":[[0,14,1.69],[1,13.5,5.25],[2,12.5,1.14],[3,11.5,7.04],[4,11,1.23],[5,10.5,4.47],[6,10,10],[7,9.8,9.41],[8,9.6,21],[9,9.4,45.48]],"bdatl":[[3,26,7.87]],"id":45323444},{"bdatl":[[4,2.34,3.28],[5,2.36,2.77],[6,2.38,34.77],[7,2.4,71.43],[9,2.44,167.43]],"id":9570503},{"bdatl":[[8,16,1.04],[9,17.5,1.73]],"id":12989514},{"bdatl":[[6,13,42.41],[7,13.5,1.64],[8,14,4.15],[9,15,14.52]],"id":44836671}]}]}
{"op":"mcm","clk":"AKEaAMINAMAW","pt":1659347449654,"mc":[{"id":"1.201590187","rc":[{"atb":[[13.5,1]],"id":45323444}]}]}
{"op":"mcm","clk":"AKMaAMYNAMkW","pt":1659347449704,"mc":[{"id":"1.201590187","rc":[{"bdatb":[[1,13.5,1]],"id":45323444},{"bdatl":[[8,2.42,8.28],[9,2.44,152.09]],"id":9570503},{"bdatl":[[9,17.5,1.34]],"id":12989514}]}]}
{"op":"mcm","clk":"ALQaAMkNAM8W","pt":1659347449831,"mc":[{"id":"1.201590187","rc":[{"atb":[[12,4.77],[11.5,5.54]],"id":45323444}]}]}
{"op":"mcm","clk":"ALwaAMsNANQW","pt":1659347449881,"mc":[{"id":"1.201590187","rc":[{"bdatb":[[3,12,4.77],[4,11.5,5.54],[5,11,1.23],[6,10.5,4.47],[7,10,10],[8,9.8,9.41],[9,9.6,21]],"id":45323444}]}]}
{"op":"mcm","clk":"AMIaAM4NANgW","pt":1659347449947,"mc":[{"id":"1.201590187","rc":[{"atb":[[1.05,1.5]],"id":45323444}]}]}
{"op":"mcm","clk":"ANsaAN0NAPEW","pt":1659347450358,"mc":[{"id":"1.201590187","rc":[{"atl":[[1000,0.41]],"id":46969227}]}]}
{"op":"mcm","clk":"ANwaAOANAPMW","pt":1659347450408,"mc":[{"id":"1.201590187","rc":[{"bdatl":[[8,1000,0.41]],"id":46969227}]}]}
{"op":"mcm","clk":"AOQaAOYNAPgW","pt":1659347450552,"mc":[{"id":"1.201590187","rc":[{"atl":[[1000,0]],"id":46969227}]}]}
{"op":"mcm","clk":"AOkaAOcNAPkW","pt":1659347450602,"mc":[{"id":"1.201590187","rc":[{"bdatl":[[8,0,0]],"id":46969227}]}]}
{"op":"mcm","clk":"APEaAOoNAPwW","pt":1659347450652,"mc":[{"id":"1.201590187","rc":[{"atb":[[12,0]],"id":45323444},{"atl":[[29,0.41]],"id":46969227}]}]}
{"op":"mcm","clk":"APEaAOoNAPwW","pt":1659347450702,"mc":[{"id":"1.201590187","rc":[{"bdatb":[[3,11.5,5.54],[4,11,1.23],[5,10.5,4.47],[6,10,10.4],[7,9.8,9],[8,9.6,21],[9,9.4,45.48]],"id":45323444},{"bdatb":[[6,5.3,3.39],[7,5.1,9.96]],"id":12989514},{"bdatb":[[4,5.8,31.52],[5,5.7,44.55],[7,5.5,24.44],[8,5.4,14.76]],"id":44836671},{"bdatl":[[0,30,2.48]],"id":46969227}]}]}
{"op":"mcm","clk":"APoaAO8NAIQX","pt":1659347450817,"mc":[{"id":"1.201590187","rc":[{"atb":[[13,4.42]],"id":45323444},{"atl":[[29,1.02],[32,1.24]],"id":46969227}]}]}
{"op":"mcm","clk":"AIEbAPANAIUX","pt":1659347450867,"mc":[{"id":"1.201590187","rc":[{"bdatb":[[2,13,4.42],[3,12.5,1.14],[4,11.5,5.54],[5,11,1.23],[6,10.5,4.47],[7,10,10.4],[8,9.8,9],[9,9.6,21]],"id":45323444},{"bdatb":[[8,1.86,2.01],[9,1.84,7.89]],"bdatl":[[9,2.44,154.89]],"id":9570503},{"bdatb":[[5,5.5,2.49],[6,5.4,2.69],[7,5.3,3.39],[8,5.1,9.96],[9,5,3.01]],"id":12989514},{"bdatb":[[7,5.5,24.96],[8,5.4,14.23]],"id":44836671},{"bdatb":[[9,6,14.3]],"id":43885158},{"bdatl":[[0,29,1.02],[1,30,2.07],[2,32,1.24],[3,34,5.6],[4,38,2.51],[5,40,5.01],[6,80,1.66],[7,310,1],[8,990,2.15]],"id":46969227}]}]}
{"op":"mcm","clk":"AIYbAPENAIkX","pt":1659347450935,"mc":[{"id":"1.201590187","rc":[{"atb":[[22,0]],"id":44621159}]}]}
{"op":"mcm","clk":"AIkbAPINAIsX","pt":1659347450985,"mc":[{"id":"1.201590187","rc":[{"bdatb":[[2,21,5],[3,19.5,4.19],[4,18.5,1.37],[5,15.5,4.19],[6,12.5,1.14],[7,10.5,1.05],[8,10,102.53],[9,9.8,1.32]],"id":44621159}]}]}
{"op":"mcm","clk":"AI4bAPINAJEX","pt":1659347451035,"mc":[{"id":"1.201590187","rc":[{"atb":[[20,1.8]],"bdatb":[[3,20,1.8],[4,19.5,4.19],[5,18.5,1.37],[6,15.5,4.19],[7,12.5,1.14],[8,10.5,1.05],[9,10,102.53]],"id":44621159}]}]}
{"op":"mcm","clk":"AKgbAIAOAKcX","pt":1659347451552,"mc":[{"id":"1.201590187","rc":[{"atb":[[13,0]],"id":45323444}]}]}
{"op":"mcm","clk":"ALAbAIMOAKkX","pt":1659347451602,"mc":[{"id":"1.201590187","rc":[{"bdatb":[[2,12.5,1.14],[3,11.5,5.54],[4,11,1.23],[5,10.5,4.47],[6,10,10.4],[7,9.8,9],[8,9.6,21],[9,9.4,45.48]],"id":45323444},{"bdatl":[[9,2.44,152.09]],"id":9570503}]}]}
{"op":"mcm","clk":"ALUbAIUOAK0X","pt":1659347451671,"mc":[{"id":"1.201590187","rc":[{"atb":[[13.5,5.25]],"id":45323444}]}]}
{"op":"mcm","clk":"ALkbAIcOALQX","pt":1659347451721,"mc":[{"id":"1.201590187","rc":[{"bdatb":[[1,13.5,5.25]],"id":45323444},{"bdatl":[[8,2.42,11.11],[9,2.44,167.43]],"id":9570503},{"bdatl":[[9,17.5,1.73]],"id":12989514}]}]}
{"op":"mcm","clk":"ANIbAJsOANQX","pt":1659347452334,"mc":[{"id":"1.201590187","rc":[{"atb":[[13.5,1]],"id":45323444}]}]}
{"op":"mcm","clk":"AOAbAKEOAN0X","pt":1659347452544,"mc":[{"id":"1.201590187","rc":[{"atb":[[13,4.42]],"id":45323444}]}]}
{"op":"mcm","clk":"AJIcAMMOAPwX","pt":1659347453361,"mc":[{"id":"1.201590187","rc":[{"atb":[[13,0]],"id":45323444}]}]}
{"op":"mcm","clk":"AJ8cAM4OAIMY","pt":1659347453553,"mc":[{"id":"1.201590187","rc":[{"atb":[[14,5.77]],"id":45323444}]}]}
{"op":"mcm","clk":"AKEcANEOAIYY","pt":1659347453643,"mc":[{"id":"1.201590187","rc":[{"bdatb":[[1,13.5,1],[2,13,4.42],[3,12.5,1.14],[4,11.5,5.54],[5,11,1.23],[6,10.5,4.47],[7,10,10.4],[8,9.8,9],[9,9.6,21]],"id":45323444},{"bdatl":[[8,2.42,8.28],[9,2.44,154.89]],"id":9570503},{"bdatl":[[9,17.5,1.34]],"id":12989514}]}]}
{"op":"mcm","clk":"AKQcANMOAI8Y","pt":1659347453694,"mc":[{"id":"1.201590187","rc":[{"bdatb":[[2,12.5,1.14],[3,11.5,5.54],[4,11,1.23],[5,10.5,4.47],[6,10,10.4],[7,9.8,9],[8,9.6,21],[9,9.4,45.48],[0,14,5.77]],"id":45323444},{"bdatl":[[8,2.42,16.67],[9,2.44,161.92]],"id":9570503},{"bdatl":[[9,16.5,1.81]],"id":12989514}]}]}
{"op":"mcm","clk":"AOscAP0OAN4Y","pt":1659347454854,"mc":[{"id":"1.201590187","rc":[{"atb":[[14,1.69]],"atl":[[23,1.82]],"id":45323444},{"atl":[[32,0.09]],"id":46969227}]}]}
{"op":"mcm","clk":"AO4cAP0OAOAY","pt":1659347454904,"mc":[{"id":"1.201590187","rc":[{"bdatb":[[0,14,1.69]],"bdatl":[[2,23,2.64]],"id":45323444},{"bdatl":[[8,2.42,8.28],[9,2.44,152.09]],"id":9570503},{"bdatb":[[8,5.1,6.35],[9,5,1.88]],"bdatl":[[9,17.5,1.34]],"id":12989514},{"bdatl":[[2,34,5.69],[3,38,2.51],[4,40,5.01],[5,80,1.66],[6,310,1],[7,990,2.15],[8,0,0]],"id":46969227}]}]}
{"op":"mcm","clk":"APMcAIEPAOkY","pt":1659347455021,"mc":[{"id":"1.201590187","rc":[{"atb":[[12,4.77]],"id":45323444}]}]}
{"op":"mcm","clk":"APYcAIIPAO0Y","pt":1659347455072,"mc":[{"id":"1.201590187","rc":[{"bdatb":[[3,12,4.77],[4,11.5,5.54],[5,11,1.23],[6,10.5,4.47],[7,10,10.4],[8,9.8,9],[9,9.6,21]],"id":45323444}]}]}
{"op":"mcm","clk":"AIIdAIMPAPkY","pt":1659347455231,"mc":[{"id":"1.201590187","rc":[{"atb":[[5.9,29.41],[5.8,10]],"id":44836671}]}]}
{"op":"mcm","clk":"AIgdAIQPAPsY","pt":1659347455282,"mc":[{"id":"1.201590187","rc":[{"bdatb":[[3,5.9,29.41],[4,5.8,10.69]],"id":44836671}]}]}
{"op":"mcm","clk":"AJIdAIgPAIcZ","pt":1659347455436,"mc":[{"id":"1.201590187","rc":[{"atb":[[1.04,0]],"id":45323444}]}]}
{"op":"mcm","clk":"AJodAIoPAIsZ","pt":1659347455545,"mc":[{"id":"1.201590187","rc":[{"atb":[[14.5,0.62]],"id":45323444}]}]}
{"op":"mcm","clk":"AJ4dAI0PAI8Z","pt":1659347455595,"mc":[{"id":"1.201590187","rc":[{"bdatb":[[0,14,2.31]],"id":45323444},{"bdatl":[[4,2.32,1.06],[5,2.34,2.23],[6,2.36,2.77],[7,2.38,34.77],[8,2.4,71.43],[9,2.42,11.11]],"id":9570503},{"bdatl":[[8,16,1.08],[9,16.5,1.12]],"id":12989514},{"bdatl":[[5,12,1.62],[6,13,42.31],[7,13.5,1.65],[8,14,4.05]],"id":44836671}]}]}
{"op":"mcm","clk":"AKQdAI0PAJYZ","pt":1659347455670,"mc":[{"id":"1.201590187","rc":[{"atb":[[3.7,65.72]],"id":12989514},{"atb":[[9.4,43.1]],"id":46969227}]}]}
{"op":"mcm","clk":"AKgdAI4PAJoZ","pt":1659347455720,"mc":[{"id":"1.201590187","rc":[{"bdatb":[[9,9.4,43.65]],"id":46969227}]}]}
{"op":"mcm","clk":"AKodAI8PAJwZ","pt":1659347455773,"mc":[{"id":"1.201590187","rc":[{"atb":[[9.4,54.1],[12,0]],"bdatb":[[3,11.5,5.54],[4,11,1.23],[5,10.5,4.47],[6,10,10.4],[7,9.8,9],[8,9.6,21],[9,9.4,54.1]],"id":45323444},{"atb":[[9.4,53.15]],"id":44621159},{"atb":[[6,81.85]],"bdatb":[[2,6,81.85]],"id":44836671}]}]}
{"op":"mcm","clk":"ALMdAJMPAKIZ","pt":1659347455860,"mc":[{"id":"1.201590187","rc":[{"atb":[[1.77,85.26]],"id":9570503},{"atb":[[6.6,64.72]],"id":43885158}]}]}
{"op":"mcm","clk":"ALgdAJUPAKIZ","pt":1659347455910,"mc":[{"id":"1.201590187","rc":[{"bdatb":[[6,6.6,66.35]],"id":43885158}]}]}
{"op":"mcm","clk":"ALodAJUPAKcZ","pt":1659347455961,"mc":[{"id":"1.201590187","rc":[{"atb":[[13,4.42]],"bdatb":[[2,13,4.42],[3,12.5,1.14],[4,11.5,5.54],[5,11,1.23],[6,10.5,4.47],[7,10,10.4],[8,9.8,9],[9,9.6,21]],"id":45323444}]}]}
{"op":"mcm","clk":"AOodALUPANYZ","pt":1659347456755,"mc":[{"id":"1.201590187","rc":[{"atb":[[13,0]],"id":45323444}]}]}
{"op":"mcm","clk":"AO8dALYPANoZ","pt":1659347456805,"mc":[{"id":"1.201590187","rc":[{"bdatb":[[2,12.5,1.14],[3,11.5,5.54],[4,11,1.23],[5,10.5,4.47],[6,10,10.4],[7,9.8,9],[8,9.6,21],[9,9.4,54.1]],"id":45323444}]}]}
{"op":"mcm","clk":"APgdALoPAOMZ","pt":1659347456958,"mc":[{"id":"1.201590187","rc":[{"atb":[[14,5.77]],"id":45323444}]}]}
{"op":"mcm","clk":"APkdALwPAOUZ","pt":1659347457023,"mc":[{"id":"1.201590187","rc":[{"bdatb":[[0,14,6.39]],"id":45323444},{"bdatl":[[9,2.42,16.67]],"id":9570503},{"bdatl":[[9,16.5,1.81]],"id":12989514}]}]}
{"op":"mcm","clk":"AJoeANEPAIUa","pt":1659347457638,"mc":[{"id":"1.201590187","rc":[{"atb":[[14,1.69]],"id":45323444}]}]}
{"op":"mcm","clk":"AKAeANEPAIoa","pt":1659347457689,"mc":[{"id":"1.201590187","rc":[{"bdatb":[[0,14,2.31]],"id":45323444},{"bdatl":[[9,2.42,11.11]],"id":9570503},{"bdatl":[[9,16.5,1.12]],"id":12989514}]}]}
{"op":"mcm","clk":"ALUeAN8PAJwa","pt":1659347458054,"mc":[{"id":"1.201590187","rc":[{"atb":[[2.1,2.2]],"atl":[[2.1,0]],"trd":[[2.1,44.88]],"ltp":2.1,"tv":738.81,"id":9570503}],"tv":1134.18}]}
{"op":"mcm","clk":"ALseAN8PAJ8a","pt":1659347458104,"mc":[{"id":"1.201590187","rc":[{"bdatb":[[6,10,10]],"bdatl":[[7,50,8.11]],"id":45323444},{"bdatb":[[0,2.1,2.2],[1,2,3.24],[2,1.99,33.5],[3,1.98,38.19],[4,1.97,1.26],[5,1.96,3.89],[6,1.94,7.62],[7,1.91,107.99],[8,1.87,5.32],[9,1.86,2.01]],"bdatl":[[0,2.14,58],[1,2.18,1.18],[2,2.3,1.72],[3,2.32,1.06],[4,2.34,2.23],[5,2.36,2.77],[6,2.38,34.77],[7,2.4,71.43],[8,2.42,11.11],[9,2.44,152.98]],"id":9570503},{"bdatb":[[4,6,2.67]],"bdatl":[[6,10.5,12.7],[7,11,34.04],[8,16.5,1.88],[9,18.5,7.97]],"id":12989514},{"bdatb":[[7,12.5,1.18]],"id":44621159},{"bdatb":[[4,5.8,10],[7,5.5,25.69]],"bdatl":[[4,9.8,34.04],[5,12,1.41],[6,13,42.24],[7,13.5,1.71],[8,14,3.9]],"id":44836671},{"bdatb":[[5,7,5],[6,6.6,66.96]],"bdatl":[[5,13.5,8.36]],"id":43885158},{"bdatb":[[7,12,1.23]],"bdatl":[[7,990,2.16]],"id":46969227}]}]}
{"op":"mcm","clk":"AMAeAOMPAKca","pt":1659347458180,"mc":[{"id":"1.201590187","rc":[{"atb":[[2.1,0]],"trd":[[2.1,49.28]],"tv":743.21,"id":9570503}],"tv":1138.58}]}
{"op":"mcm","clk":"AMEeAOYPAK0a","pt":1659347458230,"mc":[{"id":"1.201590187","rc":[{"bdatl":[[7,50,8]],"id":45323444},{"bdatb":[[0,2,3.24],[1,1.99,33.5],[2,1.98,38.19],[3,1.97,1.26],[4,1.96,3.89],[5,1.94,7.62],[6,1.91,107.99],[7,1.87,5.32],[8,1.86,2.01],[9,1.84,7.89]],"id":9570503},{"bdatl":[[6,10.5,12.47],[7,11,33.84],[8,16,1.08],[9,16.5,1.12]],"id":12989514},{"bdatl":[[4,9.8,33.55],[5,12,1.62],[6,13,42.31],[7,13.5,1.65],[8,14,4.05]],"id":44836671},{"bdatl":[[5,13.5,8]],"id":43885158},{"bdatl":[[7,990,2.15]],"id":46969227}]}]}
{"op":"mcm","clk":"AMQeAOYPAK8a","pt":1659347458280,"mc":[{"id":"1.201590187","rc":[{"atb":[[1.96,2.62],[1.99,30.99]],"atl":[[2.32,27.48]],"id":9570503}]}]}
{"op":"mcm","clk":"AMoeAOgPALYa","pt":1659347458332,"mc":[{"id":"1.201590187","rc":[{"atb":[[14,5.77]],"id":45323444},{"bdatb":[[1,1.99,30.99],[4,1.96,2.62]],"bdatl":[[3,2.32,28.54]],"id":9570503}]}]}
{"op":"mcm","clk":"AM0eAOwPALYa","pt":1659347458382,"mc":[{"id":"1.201590187","rc":[{"bdatb":[[0,14,6.39]],"id":45323444},{"bdatl":[[8,2.42,16.67],[9,2.44,161.92]],"id":9570503},{"bdatl":[[9,16.5,1.81]],"id":12989514}]}]}
{"op":"mcm","clk":"ANUeAO4PAL4a","pt":1659347458439,"mc":[{"id":"1.201590187","rc":[{"atb":[[1.99,31.22]],"id":9570503},{"atb":[[7.4,2.63]],"id":43885158}]}]}
{"op":"mcm","clk":"ANUeAPEPAL4a","pt":1659347458489,"mc":[{"id":"1.201590187","rc":[{"bdatb":[[1,1.99,31.22]],"id":9570503},{"bdatb":[[3,7.4,2.63]],"id":43885158}]}]}
{"op":"mcm","clk":"APoeAIUQANwa","pt":1659347459065,"mc":[{"id":"1.201590187","rc":[{"atb":[[5,5.22],[4.9,0]],"id":12989514}],"con":true}]}
{"op":"mcm","clk":"APweAIcQAN4a","pt":1659347459115,"mc":[{"id":"1.201590187","rc":[{"bdatb":[[9,5,7.1]],"id":12989514}]}]}
{"op":"mcm","clk":"AIAfAIgQAN8a","pt":1659347459165,"mc":[{"id":"1.201590187","rc":[{"atb":[[14,1.69]],"id":45323444}]}]}
{"op":"mcm","clk":"AIEfAIkQAOMa","pt":1659347459215,"mc":[{"id":"1.201590187","rc":[{"bdatb":[[0,14,2.31]],"id":45323444},{"bdatl":[[8,2.42,11.11],[9,2.44,152.98]],"id":9570503},{"bdatl":[[9,16.5,1.12]],"id":12989514}]}]}
{"op":"mcm","clk":"AIcfAI4QAOwa","pt":1659347459357,"mc":[{"id":"1.201590187","rc":[{"atl":[[25,4.17]],"id":45323444}]}]}
{"op":"mcm","clk":"AIsfAJEQAO4a","pt":1659347459407,"mc":[{"id":"1.201590187","rc":[{"bdatl":[[3,25,4.17],[4,26,7.87],[5,27,3.85],[6,29,5.36],[7,32,6.46],[8,50,8],[9,55,9]],"id":45323444}]}]}
{"op":"mcm","clk":"AJAfAJIQAPQa","pt":1659347459470,"mc":[{"id":"1.201590187","rc":[{"atb":[[1.99,33.5]],"id":9570503}]}]}
{"op":"mcm","clk":"AJUfAJUQAPYa","pt":1659347459521,"mc":[{"id":"1.201590187","rc":[{"bdatb":[[1,1.99,33.5]],"id":9570503}]}]}
{"op":"mcm","clk":"AKAfAJgQAP8a","pt":1659347459641,"mc":[{"id":"1.201590187","rc":[{"atl":[[26,6.42]],"id":45323444}]}]}
{"op":"mcm","clk":"AKAfAJkQAP8a","pt":1659347459691,"mc":[{"id":"1.201590187","rc":[{"bdatl":[[4,26,6.42]],"id":45323444}]}]}
{"op":"mcm","clk":"AKofAJsQAIYb","pt":1659347459741,"mc":[{"id":"1.201590187","rc":[{"atl":[[25,5.62]],"id":45323444}]}]}
{"op":"mcm","clk":"AKofAJsQAIYb","pt":1659347459792,"mc":[{"id":"1.201590187","rc":[{"bdatl":[[3,25,5.62]],"id":45323444}]}]}
{"op":"mcm","clk":"ALwfAKcQAJsb","pt":1659347460048,"mc":[{"id":"1.201590187","rc":[{"atb":[[22,1]],"atl":[[30,1.07]],"id":46969227}]}]}
{"op":"mcm","clk":"AL8fAKkQAJ0b","pt":1659347460098,"mc":[{"id":"1.201590187","rc":[{"bdatl":[[8,2.42,6.42],[9,2.44,157.62]],"id":9570503},{"bdatb":[[7,5.3,3.32],[8,5.1,1.07],[9,5,12.59]],"bdatl":[[9,17.5,1.08]],"id":12989514},{"bdatb":[[0,22,1]],"bdatl":[[1,30,1.07]],"id":46969227}]}]}
{"op":"mcm","clk":"AMQfAKoQAJ8b","pt":1659347460157,"mc":[{"id":"1.201590187","rc":[{"atb":[[2.12,8.77]],"id":9570503},{"atl":[[30,0.07]],"id":46969227}]}]}
{"op":"mcm","clk":"AMYfAKwQAKEb","pt":1659347460207,"mc":[{"id":"1.201590187","rc":[{"bdatl":[[8,50,8.42]],"id":45323444},{"bdatb":[[0,2.12,8.77],[1,2,3.24],[2,1.99,33.5],[3,1.98,38.19],[4,1.97,1.26],[5,1.96,2.62],[6,1.94,7.62],[7,1.91,107.99],[8,1.87,5.32],[9,1.86,2.01]],"id":9570503},{"bdatb":[[6,5.3,2.72],[7,5.2,3.46],[8,5,13.58],[9,4.9,4.09]],"bdatl":[[5,10,17.61],[6,10.5,13.09],[7,11,34.71],[8,18,1.71],[9,18.5,7.2]],"id":12989514},{"bdatl":[[3,9.2,8.84],[4,9.8,34.22],[5,12,1.84],[6,13,41.9],[7,13.5,1.55],[8,14,3.68],[9,15,14.55]],"id":44836671},{"bdatl":[[3,12,2.47],[5,13.5,8.73],[6,14,1.11]],"id":43885158},{"bdatl":[[1,34,5.76],[2,38,2.51],[3,40,5.01],[4,80,1.66],[5,310,1.04],[6,990,2.15],[7,0,0]],"id":46969227}]}]}
{"op":"mcm","clk":"AMwfAK4QAKMb","pt":1659347460263,"mc":[{"id":"1.201590187","rc":[{"atb":[[2.12,0]],"trd":[[2.12,92.63]],"ltp":2.12,"tv":760.75,"id":9570503},{"atb":[[22,0]],"id":46969227}],"tv":1156.12}]}
{"op":"mcm","clk":"AM0fALEQAKUb","pt":1659347460313,"mc":[{"id":"1.201590187","rc":[{"bdatl":[[8,50,8]],"id":45323444},{"bdatb":[[0,2,3.24],[1,1.99,33.5],[2,1.98,38.19],[3,1.97,1.26],[4,1.96,2.62],[5,1.94,7.62],[6,1.91,107.99],[7,1.87,5.32],[8,1.86,2.01],[9,1.84,2.71]],"bdatl":[[5,2.38,36.29],[6,2.4,72.65],[7,2.42,6.42],[8,2.44,157.62],[9,2.48,5.75]],"id":9570503},{"bdatl":[[5,10,17.36],[6,10.5,12.47],[7,11,33.84],[8,16.5,1.05],[9,17.5,1.06]],"id":12989514},{"bdatl":[[3,9.2,8],[4,9.8,33.55],[5,12,1.41],[6,13,42.5],[8,14,3.78],[9,15,14.87]],"id":44836671},{"bdatl":[[3,12,1.83],[5,13.5,8],[6,14,1]],"id":43885158},{"bdatb":[[0,21,3.23],[1,20,6.4],[2,19.5,7],[3,19,5],[4,18.5,7],[5,16,1.43],[6,12,1.23],[7,10,3.11],[8,9.4,43.65],[9,9.2,1.4]],"bdatl":[[5,310,1]],"id":46969227}]}]}
{"op":"mcm","clk":"AM4fALMQAKYb","pt":1659347460364,"mc":[{"id":"1.201590187","rc":[{"atb":[[14,5.77]],"atl":[[32,3.23]],"id":45323444},{"atb":[[1.99,30.99]],"id":9570503},{"atb":[[20,1.4],[18,7]],"atl":[[29,0.41],[32,0.72]],"id":46969227}]}]}
{"op":"mcm","clk":"ANMfALQQAKcb","pt":1659347460414,"mc":[{"id":"1.201590187","rc":[{"bdatb":[[0,14,6.39]],"bdatl":[[7,32,3.23]],"id":45323444},{"bdatb":[[1,1.99,30.99],[5,1.94,7.23],[6,1.92,1.03],[7,1.91,107.36],[8,1.86,5.35],[9,1.85,1.38]],"bdatl":[[7,2.42,16.67],[8,2.44,161.92],[9,2.46,3.39]],"id":9570503},{"bdatb":[[4,6,2.34],[5,5.4,4.24],[6,5.3,1.35]],"bdatl":[[9,17.5,2.47]],"id":12989514},{"bdatb":[[7,12.5,1.12],[8,10,103.42],[9,9.6,2.56]],"id":44621159},{"bdatb":[[7,5.5,25.17],[8,5.4,14.53],[9,5.1,33.78]],"id":44836671},{"bdatb":[[6,6.6,66.84],[7,6.4,2.12],[8,6.2,10.2],[9,6,14]],"id":43885158},{"bdatb":[[1,20,1.4],[5,18,7],[6,16,1.43],[7,12,1.23],[8,10,3.11],[9,9.4,43.65]],"bdatl":[[0,32,1.2],[1,34,5.6]],"id":46969227}]}]}
{"op":"mcm","clk":"ANQfALUQAKgb","pt":1659347460464,"mc":[{"id":"1.201590187","rc":[{"atl":[[1000,0]],"id":45323444},{"atb":[[1.99,33.5]],"id":9570503}]}]}
{"op":"mcm","clk":"ANofALgQAKob","pt":1659347460514,"mc":[{"id":"1.201590187","rc":[{"bdatb":[[1,1.99,33.5]],"id":9570503}]}]}
{"op":"mcm","clk":"AOIfALkQAK0b","pt":1659347460585,"mc":[{"id":"1.201590187","rc":[{"atl":[[24,0.48],[21,1.15]],"id":45323444},{"atb":[[1.99,31.22]],"id":9570503},{"atb":[[20,1.51]],"id":46969227}]}]}
{"op":"mcm","clk":"AOMfALsQALMb","pt":1659347460636,"mc":[{"id":"1.201590187","rc":[{"bdatl":[[2,21,1.15],[3,23,2.64],[4,25,6.1],[5,26,6.42],[6,27,3.85],[7,29,5.36],[8,32,3.23],[9,50,8]],"id":45323444},{"bdatb":[[1,1.99,31.22]],"id":9570503},{"bdatb":[[6,5.3,3.16],[7,5.2,2.59],[8,5.1,3.74],[9,5,12.78]],"id":12989514},{"bdatb":[[1,20,1.51]],"id":46969227}]}]}
{"op":"mcm","clk":"APMfAMAQALsb","pt":1659347460748,"mc":[{"id":"1.201590187","rc":[{"atb":[[9.4,61.77]],"id":44621159},{"atb":[[9.4,51.72]],"id":46969227}]}]}
{"op":"mcm","clk":"APMfAMEQALsb","pt":1659347460798,"mc":[{"id":"1.201590187","rc":[{"bdatb":[[9,9.4,52.27]],"id":46969227}]}]}
{"op":"mcm","clk":"APofAMIQAL8b","pt":1659347460848,"mc":[{"id":"1.201590187","rc":[{"atb":[[9.4,62.72]],"id":45323444}]}]}
{"op":"mcm","clk":"APofAMQQAL8b","pt":1659347460898,"mc":[{"id":"1.201590187","rc":[{"bdatb":[[9,9.4,62.72]],"id":45323444}]}]}
{"op":"mcm","clk":"AIUgAMkQAMgb","pt":1659347461136,"mc":[{"id":"1.201590187","rc":[{"atb":[[14,1.69]],"id":45323444},{"atb":[[25,0]],"id":44621159}]}]}
{"op":"mcm","clk":"AIkgAM0QAMsb","pt":1659347461186,"mc":[{"id":"1.201590187","rc":[{"bdatb":[[0,14,2.31]],"id":45323444},{"bdatl":[[3,2.32,27.48],[4,2.34,1.05],[5,2.36,2.21],[6,2.38,34.11],[7,2.4,74.81],[8,2.44,159.78],[9,2.48,4.15]],"id":9570503},{"bdatl":[[8,17,1.02],[9,18,1.03]],"id":12989514},{"bdatb":[[0,24,1.49],[1,21,5],[2,20,1.8],[3,19.5,4.19],[4,18.5,1.37],[5,15.5,4.19],[6,12.5,1.12],[7,10,103.42],[8,9.6,2.56],[9,9.4,62.53]],"id":44621159},{"bdatl":[[6,13,42.41],[7,13.5,1.64],[8,14,3.68],[9,15,14.77]],"id":44836671}]}]}
{"op":"mcm","clk":"AI8gANEQANMb","pt":1659347461253,"mc":[{"id":"1.201590187","rc":[{"atl":[[34,0.57],[32,0]],"id":44621159}]}]}
{"op":"mcm","clk":"AJEgANIQANYb","pt":1659347461303,"mc":[{"id":"1.201590187","rc":[{"bdatb":[[5,1.94,6.14],[6,1.93,1.09],[7,1.91,108.4],[8,1.87,1.85],[9,1.86,3.5]],"id":9570503},{"bdatb":[[4,5.9,2.38],[6,5.3,3.47],[7,5.2,2.27]],"id":12989514},{"bdatl":[[0,36,1.57]],"id":44621159},{"bdatb":[[7,5.5,23],[8,5.4,16.6],[9,5.1,33.92]],"id":44836671},{"bdatb":[[6,6.6,64.72],[7,6.4,4.31]],"id":43885158}]}]}
{"op":"mcm","clk":"AJggANUQANgb","pt":1659347461358,"mc":[{"id":"1.201590187","rc":[{"atb":[[14.5,1.62],[13.5,0]],"atl":[[20,0.41],[19.5,1]],"bdatb":[[0,14.5,1.62],[1,14,1.69]],"bdatl":[[1,19.5,1],[2,21,1.56]],"id":45323444},{"atb":[[24,0.49]],"atl":[[36,0]],"bdatb":[[0,21,5.49],[1,20,1.8],[2,19.5,4.19],[3,18.5,1.37],[4,15.5,4.19],[5,12.5,1.12],[6,10.5,1.12],[7,10,102.53],[8,9.6,2.97],[9,9.4,64.27]],"bdatl":[[0,38,2.13],[1,40,3.27],[2,120,7.62],[3,170,2],[4,990,2.07],[5,0,0]],"id":44621159},{"atb":[[22,2],[21,1.6]],"atl":[[32,2.72]],"bdatb":[[0,22,2],[1,21,1.6],[2,20,1.51],[3,19.5,7],[4,19,5],[5,18.5,7],[6,18,7],[7,16,1.43],[8,12,1.23],[9,10,3.11]],"bdatl":[[0,32,3.2]],"id":46969227},{"bdatl":[[3,2.32,28.54],[4,2.34,2.23],[5,2.36,1.78],[6,2.38,33.55],[7,2.4,72.4],[8,2.42,1.21],[9,2.44,154.71]],"id":9570503},{"bdatb":[[5,5.4,3.94],[6,5.3,5.99],[7,5.1,3.64],[8,5,12.88],[9,4.8,227.98]],"bdatl":[[8,17,1.06],[9,18.5,7.72]],"id":12989514},{"bdatl":[[6,13,42.51],[7,13.5,1.55],[8,14,3.98],[9,15,14.48]],"id":44836671}]}]}
{"op":"mcm","clk":"AJogANkQANwb","pt":1659347461446,"mc":[{"id":"1.201590187","rc":[{"atb":[[20,3.14]],"id":46969227}]}]}
{"op":"mcm","clk":"AJ4gAN0QAN8b","pt":1659347461496,"mc":[{"id":"1.201590187","rc":[{"bdatb":[[2,20,3.14]],"id":46969227}]}]}
{"op":"mcm","clk":"ALogAO0QAPEb","pt":1659347461876,"mc":[{"id":"1.201590187","rc":[{"atb":[[14,5.77]],"id":45323444}]}]}
{"op":"mcm","clk":"AL0gAPAQAPQb","pt":1659347461926,"mc":[{"id":"1.201590187","rc":[{"bdatb":[[1,14,5.77]],"id":45323444}]}]}
{"op":"mcm","clk":"AL8gAPIQAPkb","pt":1659347461976,"mc":[{"id":"1.201590187","rc":[{"atb":[[22,2.59]],"id":44621159}]}]}
{"op":"mcm","clk":"AMogAPIQAPob","pt":1659347462026,"mc":[{"id":"1.201590187","rc":[{"bdatl":[[6,2.38,34.52],[7,2.4,72.65],[8,2.42,2.64],[9,2.44,160.49]],"id":9570503},{"bdatl":[[8,16.5,1.06],[9,18.5,8.84]],"id":12989514},{"bdatb":[[0,22,3.08],[1,21,5],[2,20,1.8],[3,19.5,4.19],[4,18.5,1.37],[5,15.5,4.19],[6,12.5,1.12],[7,10.5,1.12],[8,10,102.53],[9,9.6,2.97]],"id":44621159}]}]}
{"op":"mcm","clk":"AOIgAIYRAI4c","pt":1659347462353,"mc":[{"id":"1.201590187","rc":[{"atl":[[20,0]],"id":45323444}]}]}
{"op":"mcm","clk":"AOMgAIgRAI8c","pt":1659347462403,"mc":[{"id":"1.201590187","rc":[{"bdatl":[[2,21,1.15]],"id":45323444},{"bdatb":[[6,5.3,4.55],[7,5.2,1.47],[8,5.1,2.25],[9,5,13.37]],"id":12989514},{"bdatb":[[9,9.6,2.11]],"id":44621159}]}]}
{"op":"mcm","clk":"AOggAIoRAJIc","pt":1659347462454,"mc":[{"id":"1.201590187","rc":[{"atb":[[14,4.08]],"id":45323444},{"atb":[[1.99,33.5]],"id":9570503}]}]}
{"op":"mcm","clk":"AOsgAI4RAJIc","pt":1659347462504,"mc":[{"id":"1.201590187","rc":[{"bdatb":[[1,14,4.08]],"id":45323444},{"bdatb":[[1,1.99,33.5]],"id":9570503}]}]}
{"op":"mcm","clk":"APEgAJERAJYc","pt":1659347462554,"mc":[{"id":"1.201590187","rc":[{"atb":[[23,1]],"atl":[[36,1]],"id":44621159}]}]}
{"op":"mcm","clk":"APQgAJIRAJgc","pt":1659347462604,"mc":[{"id":"1.201590187","rc":[{"bdatb":[[8,1.87,5.33],[9,1.86,1.37]],"id":9570503},{"bdatb":[[8,5.1,6.63],[9,5,8.91]],"bdatl":[[8,16,1.07],[9,17.5,1.2]],"id":12989514},{"bdatb":[[0,23,1.49],[1,22,2.59],[2,21,5],[3,20,1.8],[4,19.5,4.19],[5,18.5,1.37],[6,15.5,4.19],[7,12.5,1.12],[8,10.5,1.12],[9,10,102.53]],"bdatl":[[0,36,1.57],[1,38,1.56],[2,40,3.27],[3,120,7.62],[4,170,2],[5,990,2.07]],"id":44621159},{"bdatl":[[8,14,4.15],[9,15,14.51]],"id":44836671}]}]}
{"op":"mcm","clk":"APYgAJURAJoc","pt":1659347462654,"mc":[{"id":"1.201590187","rc":[{"atb":[[14,0]],"id":45323444}]}]}
{"op":"mcm","clk":"APogAJYRAJ0c","pt":1659347462704,"mc":[{"id":"1.201590187","rc":[{"bdatb":[[1,12.5,1.14],[2,11.5,5.54],[3,11,1.23],[4,10.5,4.47],[5,10,10],[6,9.8,9],[7,9.6,21],[8,9.4,62.72],[9,9.2,12]],"id":45323444},{"bdatl":[[9,2.44,152.09]],"id":9570503},{"bdatl":[[9,18.5,7.75]],"id":12989514}]}]}
{"op":"mcm","clk":"AKohAKwRALkc","pt":1659347463086,"mc":[{"id":"1.201590187","rc":[{"atb":[[1.05,0]],"id":45323444},{"atb":[[20,7.14],[18,0]],"id":46969227}]}]}
{"op":"mcm","clk":"AK0hALERALoc","pt":1659347463136,"mc":[{"id":"1.201590187","rc":[{"bdatb":[[2,20,7.14],[6,16,1.43],[7,12,1.23],[8,10,3.11],[9,9.4,52.71]],"id":46969227}]}]}
{"op":"mcm","clk":"ALAhALIRAL0c","pt":1659347463186,"mc":[{"id":"1.201590187","rc":[{"atb":[[11.5,7.04]],"id":45323444}]}]}
{"op":"mcm","clk":"ALUhALURAMAc","pt":1659347463236,"mc":[{"id":"1.201590187","rc":[{"bdatb":[[2,11.5,7.04]],"id":45323444}]}]}
{"op":"mcm","clk":"ALshALsRAMYc","pt":1659347463341,"mc":[{"id":"1.201590187","rc":[{"atb":[[22,0]],"id":44621159}]}]}
{"op":"mcm","clk":"ALwhAL0RAMYc","pt":1659347463391,"mc":[{"id":"1.201590187","rc":[{"bdatb":[[1,21,5],[2,20,1.8],[3,19.5,4.19],[4,18.5,1.37],[5,15.5,4.19],[6,12.5,1.12],[7,10.5,1.12],[8,10,102.53],[9,9.6,2.11]],"id":44621159}]}]}
{"op":"mcm","clk":"AMIhAL4RAMoc","pt":1659347463453,"mc":[{"id":"1.201590187","rc":[{"atb":[[12,4.77]],"id":45323444},{"atb":[[7,0.35]],"id":12989514}]}]}
{"op":"mcm","clk":"AMIhAMARAMsc","pt":1659347463503,"mc":[{"id":"1.201590187","rc":[{"bdatb":[[2,12,4.77],[3,11.5,7.04],[4,11,1.23],[5,10.5,4.47],[6,10,10],[7,9.8,9],[8,9.6,21],[9,9.4,62.72]],"id":45323444},{"bdatl":[[5,2.36,1.04],[6,2.38,34.28],[7,2.4,72.4],[8,2.42,3.84]],"id":9570503},{"bdatb":[[1,6.8,11.71],[2,6.6,1.15],[3,5.9,2.38],[4,5.4,3.94],[5,5.3,4.55],[6,5.2,1.47],[7,5.1,6.63],[8,5,8.91],[9,4.8,228.39]],"id":12989514},{"bdatl":[[8,14,3.86],[9,15,14.6]],"id":44836671}]}]}
{"op":"mcm","clk":"AMghAMARANQc","pt":1659347463558,"mc":[{"id":"1.201590187","rc":[{"atb":[[14.5,1]],"id":45323444},{"atl":[[8.6,0.3]],"id":12989514},{"atb":[[1.04,0],[23,3.47]],"id":44621159}]}]}
{"op":"mcm","clk":"AMkhAMMRANQc","pt":1659347463608,"mc":[{"id":"1.201590187","rc":[{"bdatb":[[0,14.5,1]],"id":45323444},{"bdatb":[[8,1.86,2.1],[9,1.85,1.51]],"bdatl":[[8,2.44,152.21],[9,2.48,5.75]],"id":9570503},{"bdatl":[[1,9.2,6],[2,9.4,3.67],[3,9.6,14.09],[4,10,17.36],[5,10.5,12.47],[6,11,33.84],[7,16,1.07],[8,18.5,7.22],[9,22,1.37]],"id":12989514},{"bdatb":[[0,23,3.96],[7,10,102.83],[8,9.6,3.01],[9,9.4,64.34]],"id":44621159},{"bdatb":[[8,10,2.46],[9,9.4,53.42]],"id":46969227}]}]}
{"op":"mcm","clk":"AMohAMQRANcc","pt":1659347463658,"mc":[{"id":"1.201590187","rc":[{"atb":[[12,5.39]],"id":45323444},{"atb":[[23,4.6]],"id":44621159}]}]}
{"op":"mcm","clk":"ANAhAMYRANgc","pt":1659347463708,"mc":[{"id":"1.201590187","rc":[{"bdatb":[[2,12,5.39]],"id":45323444},{"bdatb":[[0,23,5.09]],"id":44621159}]}]}
{"op":"mcm","clk":"ANUhAMcRAN0c","pt":1659347463758,"mc":[{"id":"1.201590187","rc":[{"atl":[[9,2.45],[9.6,11.09]],"id":12989514}]}]}
{"op":"mcm","clk":"ANYhAMgRAOIc","pt":1659347463808,"mc":[{"id":"1.201590187","rc":[{"bdatb":[[9,1.85,8.42]],"id":9570503},{"bdatl":[[1,9,3.04],[2,9.2,5.1],[3,9.4,3.67],[4,9.6,11.09],[5,10,17.36],[6,10.5,12.47],[7,11,33.84],[8,16,1.07],[9,18.5,7.22]],"id":12989514},{"bdatb":[[7,10,104.11],[8,9.6,2.35],[9,9.4,63.65]],"id":44621159},{"bdatb":[[9,9.6,1.67]],"id":46969227}]}]}
{"op":"mcm","clk":"AOohANURAPcc","pt":1659347464178,"mc":[{"id":"1.201590187","rc":[{"atb":[[2,1.24]],"trd":[[2,69.1]],"ltp":2,"tv":764.75,"id":9570503}],"tv":1160.12}]}
{"op":"mcm","clk":"AOshANgRAPkc","pt":1659347464229,"mc":[{"id":"1.201590187","rc":[{"bdatb":[[0,2,1.24]],"id":9570503},{"bdatl":[[8,16,1.06]],"id":12989514},{"bdatl":[[6,13,42.49]],"id":44836671}]}]}
{"op":"mcm","clk":"APAhANkRAPwc","pt":1659347464279,"mc":[{"id":"1.201590187","rc":[{"atb":[[23,2.13]],"id":44621159}]}]}
{"op":"mcm","clk":"APIhAN0RAP0c","pt":1659347464329,"mc":[{"id":"1.201590187","rc":[{"bdatb":[[0,23,2.62]],"id":44621159}]}]}
{"op":"mcm","clk":"APYhAN4RAIId","pt":1659347464390,"mc":[{"id":"1.201590187","rc":[{"atb":[[21,0.1]],"id":46969227}]}]}
{"op":"mcm","clk":"APkhAOARAIUd","pt":1659347464440,"mc":[{"id":"1.201590187","rc":[{"bdatb":[[1,20,7.24],[2,19.5,7],[3,19,5],[4,18.5,7],[5,16,1.43],[6,12,1.23],[7,10,2.46],[8,9.6,1.67],[9,9.4,51.72]],"id":46969227}]}]}
{"op":"mcm","clk":"APshAOERAIcd","pt":1659347464490,"mc":[{"id":"1.201590187","rc":[{"atb":[[1.98,42.05]],"bdatb":[[2,1.98,42.05]],"bdatl":[[6,2.38,35.26],[7,2.4,71.55],[8,2.44,152.09]],"id":9570503},{"atb":[[24,2.91]],"bdatb":[[0,24,2.91],[1,23,2.13],[2,21,5],[3,20,1.8],[4,19.5,4.19],[5,18.5,1.37],[6,15.5,4.19],[7,12.5,1.12],[8,10,104.11],[9,9.6,2.35]],"id":44621159},{"atb":[[20,8.64]],"bdatb":[[1,20,8.74]],"id":46969227},{"bdatl":[[8,15.5,1.06]],"id":12989514}]}]}
{"op":"mcm","clk":"AKEiAPYRAKod","pt":1659347465163,"mc":[{"id":"1.201590187","rc":[{"atb":[[2.06,9.17]],"id":9570503},{"atb":[[9.4,2]],"id":43885158}]}]}
{"op":"mcm","clk":"AKYiAPgRAK8d","pt":1659347465214,"mc":[{"id":"1.201590187","rc":[{"bdatl":[[9,50,8.48]],"id":45323444},{"bdatb":[[0,2.06,9.17],[1,2,1.24],[2,1.99,33.5],[3,1.98,42.05],[4,1.97,1.26],[5,1.96,2.62],[6,1.94,6.14],[7,1.93,1.09],[8,1.91,108.4],[9,1.86,2.1]],"bdatl":[[2,2.24,3.42],[3,2.26,1.08],[4,2.28,1.92],[5,2.3,1.72],[6,2.32,27.48],[7,2.34,1.84],[8,2.38,33.55],[9,2.4,71.43]],"id":9570503},{"bdatl":[[5,10,18.81],[8,18.5,7.86],[9,22,1.1]],"id":12989514},{"bdatl":[[5,990,2.1]],"id":44621159},{"bdatl":[[3,9.2,9.12],[4,9.8,34.01],[5,12,1.8],[6,13,41.9],[8,14,3.68],[9,15,14.32]],"id":44836671},{"bdatb":[[0,9.4,2],[1,8,1.77],[2,7.8,8.62],[3,7.6,4.53],[4,7.4,2.63],[5,7.2,3.71],[6,7,5],[7,6.6,64.72],[8,6.4,4.31],[9,6.2,10.2]],"bdatl":[[8,15,12.51]],"id":43885158},{"bdatl":[[5,310,1.05],[6,990,2.16]],"id":46969227}]}]}
{"op":"mcm","clk":"AKkiAPgRALAd","pt":1659347465265,"mc":[{"id":"1.201590187","rc":[{"atb":[[12,0.62]],"id":45323444},{"atb":[[24,0.49]],"id":44621159}]}]}
{"op":"mcm","clk":"AK0iAPkRALMd","pt":1659347465315,"mc":[{"id":"1.201590187","rc":[{"bdatb":[[2,11.5,7.66],[3,11,1.23],[4,10.5,4.47],[5,10,10],[6,9.8,9],[7,9.6,21],[8,9.4,62.72],[9,9.2,12]],"bdatl":[[9,50,8.47]],"id":45323444},{"bdatl":[[4,2.3,3.64],[5,2.32,27.48],[6,2.36,1.82],[7,2.38,33.55],[8,2.4,71.43],[9,2.44,153.1]],"id":9570503},{"bdatl":[[5,10,18.55],[6,10.5,12.72],[9,24,1.05]],"id":12989514},{"bdatb":[[0,23,2.62],[1,21,5],[2,20,1.8],[3,19.5,4.19],[4,18.5,1.37],[5,15.5,4.19],[6,12.5,1.12],[7,10,104.11],[8,9.6,2.35],[9,9.4,63.65]],"id":44621159},{"bdatl":[[4,9.8,33.99],[7,13.5,1.56]],"id":44836671}]}]}
{"op":"mcm","clk":"ALIiAPoRALUd","pt":1659347465365,"mc":[{"id":"1.201590187","rc":[{"atl":[[1000,0.41]],"id":45323444},{"atl":[[7.4,4.09]],"trd":[[7.4,31.05]],"tv":178.92,"id":44836671},{"atb":[[9.4,0],[7.4,2.32]],"trd":[[9.4,80.22]],"ltp":9.4,"tv":122.45,"id":43885158}],"tv":1174.12}]}
{"op":"mcm","clk":"ALYiAPsRALgd","pt":1659347465415,"mc":[{"id":"1.201590187","rc":[{"bdatl":[[9,50,8]],"id":45323444},{"bdatl":[[2,2.3,1.72],[3,2.32,28.54],[4,2.34,2.23],[5,2.36,1.04],[6,2.38,34.28],[7,2.4,72.4],[8,2.44,152.21],[9,2.48,5.75]],"id":9570503},{"bdatb":[[4,5.4,2.97],[5,5.2,5.63],[6,5.1,8.12],[7,5,8.91],[8,4.8,228.39],[9,4.6,2.1]],"bdatl":[[5,10,17.36],[6,10.5,12.47],[8,12.5,1.27],[9,18.5,7.5]],"id":12989514},{"bdatb":[[7,10,103.59],[8,9.6,2.22],[9,9.4,61.77]],"bdatl":[[5,990,2.07]],"id":44621159},{"bdatl":[[0,7.4,4.09],[3,9.2,8],[4,9.8,33.55],[5,12,2.66],[6,13,41.92],[7,13.5,1.55],[9,15,14.63]],"id":44836671},{"bdatb":[[0,8,1.77],[1,7.8,8.62],[2,7.6,4.53],[3,7.4,2.32],[4,7.2,3.71],[5,7,5],[6,6.6,64.72],[7,6.4,4.31],[8,6.2,10.2],[9,6,14]],"id":43885158},{"bdatb":[[8,9.6,1.13]],"bdatl":[[5,310,1],[6,990,2.15]],"id":46969227}]}]}
{"op":"mcm","clk":"ALgiAPwRALwd","pt":1659347465466,"mc":[{"id":"1.201590187","rc":[{"atb":[[12.5,5.74]],"id":45323444},{"atl":[[7.4,0]],"trd":[[7.4,39.23]],"tv":187.1,"id":44836671},{"atl":[[12,1.4]],"id":43885158}],"tv":1182.3}]}
{"op":"mcm","clk":"AL8iAP8RAL4d","pt":1659347465516,"mc":[{"id":"1.201590187","rc":[{"bdatb":[[1,12.5,5.74]],"id":45323444},{"bdatb":[[6,1.92,7.3],[7,1.91,107.76],[8,1.86,1.37],[9,1.85,1.38]],"bdatl":[[9,2.48,11.9]],"id":9570503},{"bdatb":[[3,5.8,2.42],[4,5.3,4.02],[5,5.2,4.64]],"id":12989514},{"bdatb":[[6,12,1.17],[7,10,102.31],[8,9.6,3.56]],"id":44621159},{"bdatl":[[0,7.6,150],[1,8.4,3.63],[2,9.2,8],[3,9.8,33.55],[4,12,2.66],[5,13,41.92],[6,13.5,1.55],[7,14,3.68],[8,15,14.63],[9,15.5,17.45]],"id":44836671},{"bdatb":[[7,6.4,3.86],[8,6.2,10.46],[9,6,14.2]],"bdatl":[[3,12,1.4]],"id":43885158},{"bdatb":[[6,11.5,1.29],[7,10,2.25],[8,9.4,51.98],[9,9.2,1.69]],"id":46969227}]}]}
{"op":"mcm","clk":"AMEiAIESAMMd","pt":1659347465566,"mc":[{"id":"1.201590187","rc":[{"atl":[[1000,0]],"id":45323444},{"atb":[[6.6,26.16]],"atl":[[7.6,150.34]],"id":44836671},{"atb":[[8.2,0],[8,1.77]],"atl":[[1000,0.43]],"id":43885158}]}]}
{"op":"mcm","clk":"AMgiAIMSAMYd","pt":1659347465616,"mc":[{"id":"1.201590187","rc":[{"bdatl":[[3,2.32,27.48],[4,2.34,3.28],[7,2.4,72.37],[8,2.44,152.24]],"id":9570503},{"bdatl":[[8,12.5,1.26],[9,18.5,7.51]],"id":12989514},{"bdatb":[[0,6.6,26.16]],"bdatl":[[0,7.6,150.34],[5,13,41.93]],"id":44836671}]}]}
{"op":"mcm","clk":"AMwiAIQSAMgd","pt":1659347465680,"mc":[{"id":"1.201590187","rc":[{"atl":[[19,0.41]],"id":45323444},{"atb":[[22,2.59]],"id":44621159}]}]}
{"op":"mcm","clk":"AM4iAIYSAMod","pt":1659347465730,"mc":[{"id":"1.201590187","rc":[{"bdatl":[[1,19.5,1.41]],"id":45323444},{"bdatb":[[8,1.87,1.37],[9,1.86,1.13]],"id":9570503},{"bdatb":[[4,5.3,5.49],[6,5.1,6.59],[7,5,9.84],[8,4.8,227.98],[9,4.6,1.55]],"id":12989514},{"bdatb":[[1,22,2.59],[2,21,5],[3,20,1.8],[4,19.5,4.19],[5,18.5,1.37],[6,15.5,4.19],[7,12,1.17],[8,10,102.56],[9,9.6,3.97]],"id":44621159},{"bdatb":[[8,9.4,52.39],[9,9.2,1.98]],"id":46969227}]}]}
{"op":"mcm","clk":"AOQiAJMSANwd","pt":1659347465790,"mc":[{"id":"1.201590187","rc":[{"atl":[[7.6,150]],"id":44836671}]}]}
{"op":"mcm","clk":"AOUiAJcSAOEd","pt":1659347465840,"mc":[{"id":"1.201590187","rc":[{"bdatl":[[0,7.6,150]],"id":44836671}]}]}
{"op":"mcm","clk":"AO4iAJsSAOcd","pt":1659347465944,"mc":[{"id":"1.201590187","rc":[{"atl":[[1000,3.31]],"id":43885158}]}]}
{"op":"mcm","clk":"APwiAKQSAPcd","pt":1659347466262,"mc":[{"id":"1.201590187","rc":[{"atb":[[13,4.32]],"id":45323444},{"atl":[[2.26,8]],"id":9570503},{"atl":[[8.8,1.44]],"id":12989514},{"atb":[[6.2,18.68]],"atl":[[9.2,13.2]],"id":44836671},{"atl":[[10.5,6.96]],"id":43885158},{"atb":[[20,12.34]],"atl":[[30,1.22]],"id":46969227}]}]}
{"op":"mcm","clk":"AP0iAKUSAPsd","pt":1659347466313,"mc":[{"id":"1.201590187","rc":[{"bdatb":[[1,13,4.32],[2,12.5,5.74],[3,11.5,7.66],[4,11,1.23],[5,10.5,4.47],[6,10,10],[7,9.8,9],[8,9.6,21],[9,9.4,62.72]],"id":45323444},{"bdatb":[[6,1.92,7.7],[7,1.91,108],[8,1.86,4.19],[9,1.85,3.36]],"bdatl":[[2,2.26,8],[3,2.3,1.72],[4,2.32,27.48],[5,2.34,3.28],[6,2.36,1.04],[7,2.38,34.28],[8,2.4,72.37],[9,2.44,152.24]],"id":9570503},{"bdatb":[[3,5.8,2.76],[4,5.4,5.05],[5,5.2,4.62],[6,5.1,9.28],[7,5,7.1]],"bdatl":[[1,8.8,1.74],[2,9,2.45],[3,9.2,5.1],[4,9.4,3.67],[5,9.6,11.09],[6,10,17.36],[7,10.5,12.47],[8,11,33.84],[9,12.5,1.26]],"id":12989514},{"bdatb":[[7,12,1.23],[8,10,103.51],[9,9.8,1.35]],"id":44621159},{"bdatb":[[1,6.2,19.05],[8,5.4,16.74],[9,5.1,33.78]],"bdatl":[[2,9.2,13.2],[7,14,3.99],[8,15,14.32]],"id":44836671},{"bdatb":[[8,6.2,10.66],[9,6,14]],"bdatl":[[1,10.5,6.96]],"id":43885158},{"bdatb":[[1,20,12.44],[8,9.4,53.04],[9,9.2,1.44]],"bdatl":[[0,30,1.63],[1,32,2.72],[2,34,5.6],[3,38,2.51],[4,40,5.01],[5,80,1.66],[6,310,1],[7,990,2.15]],"id":46969227}]}]}
{"op":"mcm","clk":"AIYjAKcSAIQe","pt":1659347466455,"mc":[{"id":"1.201590187","rc":[{"atb":[[12.5,1.14]],"id":45323444},{"atb":[[1.99,23.36]],"id":9570503},{"atb":[[22,0]],"id":44621159},{"atl":[[1000,0.44]],"id":43885158}]}]}
{"op":"mcm","clk":"AIsjAKcSAIYe","pt":1659347466506,"mc":[{"id":"1.201590187","rc":[{"bdatb":[[2,12.5,1.14]],"id":45323444},{"bdatb":[[2,1.99,23.36]],"id":9570503},{"bdatb":[[1,21,5],[2,20,1.8],[3,19.5,4.19],[4,18.5,1.37],[5,15.5,4.19],[6,12,1.23],[7,10,103.51],[8,9.8,1.35],[9,9.6,1.68]],"id":44621159}]}]}
{"op":"mcm","clk":"AJYjALESAJIe","pt":1659347466686,"mc":[{"id":"1.201590187","rc":[{"atb":[[12,5.39]],"id":45323444}]}]}
{"op":"mcm","clk":"AJcjALESAJUe","pt":1659347466736,"mc":[{"id":"1.201590187","rc":[{"bdatb":[[3,12,5.39],[4,11.5,7.04],[5,11,1.23],[6,10.5,4.47],[7,10,10],[8,9.8,9],[9,9.6,21]],"id":45323444}]}]}
{"op":"mcm","clk":"AKIjALUSAKEe","pt":1659347466850,"mc":[{"id":"1.201590187","rc":[{"atb":[[23,4.6]],"id":44621159},{"atl":[[1000,0.43]],"id":43885158}]}]}
{"op":"mcm","clk":"AKIjALgSAKEe","pt":1659347466900,"mc":[{"id":"1.201590187","rc":[{"bdatb":[[0,23,5.09]],"id":44621159}]}]}
{"op":"mcm","clk":"AKUjALgSAKoe","pt":1659347466950,"mc":[{"id":"1.201590187","rc":[{"atb":[[8,1.76]],"trd":[[8,0.01]],"ltp":8,"tv":122.46,"id":43885158}],"tv":1182.31}]}
{"op":"mcm","clk":"AKgjALsSAKoe","pt":1659347467001,"mc":[{"id":"1.201590187","rc":[{"bdatl":[[8,2.4,72.35],[9,2.44,152.27]],"id":9570503},{"bdatl":[[4,12,2.65]],"id":44836671},{"bdatb":[[0,8,1.76]],"id":43885158}]}]}
{"op":"mcm","clk":"ANQjAMwSANMe","pt":1659347467683,"mc":[{"id":"1.201590187","rc":[{"atb":[[12,0.62]],"id":45323444},{"atb":[[23,2.13]],"id":44621159},{"atb":[[7.8,1.26]],"id":43885158}]}]}
{"op":"mcm","clk":"ANUjAM4SANUe","pt":1659347467734,"mc":[{"id":"1.201590187","rc":[{"bdatb":[[3,11.5,7.66],[4,11,1.23],[5,10.5,4.47],[6,10,10],[7,9.8,9],[8,9.6,21],[9,9.4,62.72]],"id":45323444},{"bdatb":[[0,23,2.62]],"id":44621159},{"bdatb":[[1,7.8,1.26]],"id":43885158}]}]}
{"op":"mcm","clk":"APYjAN0SAPIe","pt":1659347468269,"mc":[{"id":"1.201590187","rc":[{"atl":[[2.36,66.68]],"id":9570503}]}]}
{"op":"mcm","clk":"APgjAN4SAPIe","pt":1659347468319,"mc":[{"id":"1.201590187","rc":[{"bdatl":[[6,2.36,67.72]],"id":9570503}]}]}
{"op":"mcm","clk":"APsjAOASAPoe","pt":1659347468373,"mc":[{"id":"1.201590187","rc":[{"atb":[[8,8.94]],"id":43885158}]}]}
{"op":"mcm","clk":"APwjAOISAPoe","pt":1659347468423,"mc":[{"id":"1.201590187","rc":[{"bdatl":[[8,2.4,72.52],[9,2.44,164.18]],"id":9570503},{"bdatl":[[9,12.5,1.29]],"id":12989514},{"bdatl":[[4,12,2.69],[5,13,41.9],[6,13.5,1.88],[7,14,3.68]],"id":44836671},{"bdatb":[[0,8,8.94]],"id":43885158}]}]}
{"op":"mcm","clk":"AIEkAOMSAIMf","pt":1659347468475,"mc":[{"id":"1.201590187","rc":[{"atb":[[7.4,7.6]],"id":43885158}]}]}
{"op":"mcm","clk":"AIMkAOQSAIUf","pt":1659347468536,"mc":[{"id":"1.201590187","rc":[{"bdatb":[[3,7.4,7.6]],"id":43885158}]}]}
{"op":"mcm","clk":"AIkkAOgSAI4f","pt":1659347468663,"mc":[{"id":"1.201590187","rc":[{"atb":[[6.8,0.36]],"id":12989514}]}]}
{"op":"mcm","clk":"AIwkAOoSAJMf","pt":1659347468713,"mc":[{"id":"1.201590187","rc":[{"bdatl":[[8,2.4,71.72],[9,2.44,152.89]],"id":9570503},{"bdatb":[[1,6.6,1.86],[2,5.8,2.76],[3,5.4,5.05],[4,5.2,4.62],[5,5.1,9.28],[6,5,7.1],[7,4.8,227.98],[8,4.6,1.55],[9,4.5,11.15]],"id":12989514},{"bdatl":[[4,12,2.53],[5,13,42.05],[6,13.5,1.55],[7,14,3.99]],"id":44836671}]}]}
{"op":"mcm","clk":"AJQkAOwSAJYf","pt":1659347468779,"mc":[{"id":"1.201590187","rc":[{"atb":[[6.6,12.15]],"id":12989514}]}]}
{"op":"mcm","clk":"AJYkAO0SAJkf","pt":1659347468829,"mc":[{"id":"1.201590187","rc":[{"bdatb":[[1,6.6,12.86]],"id":12989514}]}]}
{"op":"mcm","clk":"AJokAO4SAJ0f","pt":1659347468885,"mc":[{"id":"1.201590187","rc":[{"atb":[[6.6,17.16]],"id":44836671}]}]}
{"op":"mcm","clk":"AJskAPISAKEf","pt":1659347468942,"mc":[{"id":"1.201590187","rc":[{"bdatb":[[0,6.6,17.16]],"id":44836671}]}]}
{"op":"mcm","clk":"AK0kAPsSALAf","pt":1659347469154,"mc":[{"id":"1.201590187","rc":[{"atb":[[8,1.76]],"id":43885158}]}]}
{"op":"mcm","clk":"AK0kAPwSALIf","pt":1659347469205,"mc":[{"id":"1.201590187","rc":[{"bdatl":[[9,2.44,152.88]],"id":9570503},{"bdatl":[[9,12.5,1.26]],"id":12989514},{"bdatl":[[7,14,3.68],[8,15,14.63]],"id":44836671},{"bdatb":[[0,8,1.76]],"id":43885158}]}]}
{"op":"mcm","clk":"ALkkAIITAL8f","pt":1659347469356,"mc":[{"id":"1.201590187","rc":[{"atb":[[7.8,8.62],[8,1.46]],"id":43885158}]}]}
{"op":"mcm","clk":"ALkkAIMTAMMf","pt":1659347469406,"mc":[{"id":"1.201590187","rc":[{"bdatl":[[7,2.38,34.2],[8,2.4,71.51],[9,2.44,153.17]],"id":9570503},{"bdatl":[[9,12.5,1.06]],"id":12989514},{"bdatl":[[4,12,2.45],[5,13,42.11]],"id":44836671},{"bdatb":[[0,8,1.46],[1,7.8,8.62]],"id":43885158}]}]}
{"op":"mcm","clk":"ALskAIMTAMof","pt":1659347469456,"mc":[{"id":"1.201590187","rc":[{"atb":[[6.6,15.88]],"id":12989514},{"atb":[[7.4,2.32]],"id":43885158}]}]}
{"op":"mcm","clk":"AMEkAIQTAM0f","pt":1659347469506,"mc":[{"id":"1.201590187","rc":[{"bdatb":[[1,6.6,16.59]],"id":12989514},{"bdatb":[[3,7.4,2.32]],"id":43885158}]}]}
{"op":"mcm","clk":"AMQkAIQTANIf","pt":1659347469571,"mc":[{"id":"1.201590187","rc":[{"atb":[[1.02,3]],"atl":[[1000,3.47]],"id":12989514},{"atb":[[22,2.59]],"id":44621159}]}]}
{"op":"mcm","clk":"AMckAIYTANQf","pt":1659347469621,"mc":[{"id":"1.201590187","rc":[{"bdatb":[[1,22,2.59],[2,21,5],[3,20,1.8],[4,19.5,4.19],[5,18.5,1.37],[6,15.5,4.19],[7,12,1.23],[8,10,103.51],[9,9.8,1.35]],"id":44621159}]}]}
{"op":"mcm","clk":"AOAkAJATAO8f","pt":1659347469986,"mc":[{"id":"1.201590187","rc":[{"atb":[[6.6,35.96]],"id":44836671}]}]}
{"op":"mcm","clk":"AOEkAJITAPIf","pt":1659347470036,"mc":[{"id":"1.201590187","rc":[{"bdatb":[[0,6.6,35.96]],"id":44836671}]}]}
{"op":"mcm","clk":"AOYkAJQTAPQf","pt":1659347470086,"mc":[{"id":"1.201590187","rc":[{"atb":[[1.02,1]],"id":12989514}]}]}
{"op":"mcm","clk":"AO0kAJsTAPof","pt":1659347470197,"mc":[{"id":"1.201590187","rc":[{"atb":[[2.06,18.44]],"id":9570503},{"atl":[[1000,1.47]],"id":12989514}]}]}
{"op":"mcm","clk":"APIkAJsTAP0f","pt":1659347470247,"mc":[{"id":"1.201590187","rc":[{"bdatb":[[0,2.06,18.44]],"id":9570503},{"bdatl":[[8,14.5,1.72],[9,15,14.22]],"id":44836671}]}]}
{"op":"mcm","clk":"APkkAKATAP8f","pt":1659347470298,"mc":[{"id":"1.201590187","rc":[{"atb":[[2.06,9.27]],"atl":[[2.26,0]],"id":9570503},{"atb":[[22,0]],"id":44621159},{"atb":[[6.2,11.69]],"atl":[[9.2,8]],"id":44836671},{"atl":[[10.5,3.28]],"id":43885158},{"atb":[[20,8.64]],"id":46969227}]}]}
{"op":"mcm","clk":"AIElAKETAIEg","pt":1659347470348,"mc":[{"id":"1.201590187","rc":[{"atb":[[1.99,20.85]],"atl":[[2.12,10.99]],"bdatb":[[0,2.06,9.27]],"bdatl":[[2,2.3,1.72],[3,2.32,27.48],[4,2.34,3.28],[5,2.36,67.72],[6,2.38,34.2],[7,2.4,71.51],[8,2.44,153.17],[9,2.5,33.64]],"id":9570503},{"atb":[[5,0],[7.2,3.07]],"bdatb":[[9,4.5,11.02]],"id":12989514},{"atb":[[6.4,6.37]],"atl":[[7.4,4.56]],"bdatb":[[1,6.2,12.06]],"bdatl":[[2,9.2,8],[8,15,14.64],[9,15.5,17.45]],"id":44836671},{"atb":[[8,7.46]],"atl":[[9.4,2.7]],"bdatl":[[1,10.5,3.28]],"id":43885158},{"atb":[[22,6.3]],"bdatb":[[1,20,8.74]],"id":46969227},{"bdatb":[[1,21,5],[2,20,1.8],[3,19.5,4.19],[4,18.5,1.37],[5,15.5,4.19],[6,12,1.23],[7,10,103.51],[8,9.8,1.35],[9,9.6,1.68]],"id":44621159}]}]}
{"op":"mcm","clk":"AIElAKQTAIEg","pt":1659347470398,"mc":[{"id":"1.201590187","rc":[{"bdatb":[[8,9.6,22.24],[9,9.4,63.02]],"id":45323444},{"bdatb":[[2,1.99,20.85],[6,1.94,7.62],[7,1.91,107.99],[8,1.88,4.15],[9,1.87,3.33]],"bdatl":[[0,2.12,10.99],[1,2.14,58],[2,2.18,1.18],[3,2.3,1.72],[4,2.32,27.48],[5,2.34,5.07],[6,2.36,67.79],[7,2.38,33.55],[8,2.4,74.58],[9,2.42,1.01]],"id":9570503},{"bdatb":[[0,7.2,3.07],[2,6.2,1.92],[3,5.8,1.28],[4,5.5,2.57],[5,5.4,1.77],[6,5.2,4.62],[7,5.1,9.28],[8,5,4.15],[9,4.9,2.43]],"bdatl":[[9,12.5,1.29]],"id":12989514},{"bdatb":[[6,13.5,1.06],[7,10.5,1.39],[8,10,102.37],[9,9.6,2.66]],"id":44621159},{"bdatb":[[1,6.4,6.37],[2,6.2,11.69],[3,6,81.85],[4,5.9,29.41],[5,5.8,10],[6,5.7,44.55],[7,5.6,14.64],[8,5.5,23.22],[9,5.4,14]],"bdatl":[[0,7.4,4.56],[1,7.6,150],[2,8.4,3.63],[3,9.2,8],[4,9.8,33.55],[5,11,1.32],[6,12,1.8],[7,13,41.9],[8,13.5,1.55],[9,14,3.68]],"id":44836671},{"bdatb":[[0,8,7.46],[6,6.6,66.96],[7,6.4,2.19],[8,6.2,10],[9,6,15.22]],"bdatl":[[0,9.4,2.7],[1,9.6,14.81],[2,10.5,3.28],[3,11.5,2.89],[4,12,1.4],[5,12.5,10],[6,13.5,8],[7,14,1],[8,14.5,1],[9,15,12.79]],"id":43885158},{"bdatb":[[0,22,6.3],[6,13,1.14],[7,10,3],[8,9.4,52.58],[9,9.2,1.04]],"id":46969227}]}]}
{"op":"mcm","clk":"AIslAKYTAIcg","pt":1659347470459,"mc":[{"id":"1.201590187","rc":[{"atb":[[1.99,23.31]],"id":9570503},{"atb":[[7,0],[4.9,5.22]],"atl":[[1000,0.47]],"id":12989514},{"atb":[[23,4.6]],"id":44621159},{"atl":[[7.4,4.91]],"id":44836671},{"atb":[[8,7.76]],"atl":[[9.4,2.97]],"id":43885158}]}]}
{"op":"mcm","clk":"AIslAKsTAIcg","pt":1659347470509,"mc":[{"id":"1.201590187","rc":[{"bdatb":[[2,1.99,23.31]],"bdatl":[[9,2.44,153.09]],"id":9570503},{"bdatb":[[1,6.6,16.24],[4,5.5,3.04],[5,5.4,1.29],[9,4.9,7.65]],"id":12989514},{"bdatb":[[0,23,5.09],[8,10,102.63],[9,9.6,2.39]],"id":44621159},{"bdatl":[[0,7.4,4.91]],"id":44836671},{"bdatb":[[0,8,7.76]],"bdatl":[[0,9.4,2.97]],"id":43885158},{"bdatb":[[7,10,3.25],[8,9.4,52.6],[9,9,1.74]],"id":46969227}]}]}
{"op":"mcm","clk":"AJAlAKsTAIwg","pt":1659347470559,"mc":[{"id":"1.201590187","rc":[{"atl":[[8.4,2.76]],"id":12989514}]}]}
{"op":"mcm","clk":"AJElAK0TAIwg","pt":1659347470609,"mc":[{"id":"1.201590187","rc":[{"bdatb":[[9,9.4,63.52]],"id":45323444},{"bdatb":[[6,1.94,8.25],[7,1.91,107.36],[8,1.9,3.78],[9,1.88,1.37]],"id":9570503},{"bdatl":[[0,8.4,2.76]],"id":12989514},{"bdatb":[[6,13.5,1.15],[7,10.5,1.84],[8,10,102.21],[9,9.6,2.18]],"id":44621159},{"bdatb":[[7,5.6,14.86],[8,5.5,23]],"id":44836671},{"bdatb":[[6,6.6,67.14],[7,6.4,2],[8,6.2,11.16],[9,6,14.02]],"id":43885158},{"bdatb":[[6,13,1.23],[7,10,3.11],[8,9.4,52.8],[9,9,1.88]],"id":46969227}]}]}
{"op":"mcm","clk":"AJIlAK4TAJMg","pt":1659347470664,"mc":[{"id":"1.201590187","rc":[{"atb":[[1.02,0]],"atl":[[8.4,3.06]],"id":12989514}]}]}
{"op":"mcm","clk":"AJolALITAJQg","pt":1659347470714,"mc":[{"id":"1.201590187","rc":[{"bdatb":[[8,1.9,4.11],[9,1.89,1]],"id":9570503},{"bdatl":[[0,8.4,3.06]],"id":12989514},{"bdatb":[[7,11,1.02],[8,10,103.26],[9,9.6,1.92]],"id":44621159},{"bdatb":[[8,6.2,11.18],[9,6,14.4]],"id":43885158},{"bdatb":[[7,10,3.14],[8,9.4,53.03],[9,9,1.61]],"id":46969227}]}]}
{"op":"mcm","clk":"AJslALUTAJkg","pt":1659347470764,"mc":[{"id":"1.201590187","rc":[{"atb":[[6.8,1.36]],"atl":[[8.2,6]],"id":12989514}]}]}
{"op":"mcm","clk":"AKElALcTAJsg","pt":1659347470823,"mc":[{"id":"1.201590187","rc":[{"bdatb":[[7,9.8,10.22],[8,9.6,22.19],[9,9.4,62.72]],"id":45323444},{"bdatb":[[5,1.96,8.7],[6,1.95,2.09],[7,1.91,111.45],[8,1.9,2.16],[9,1.89,4.45]],"bdatl":[[9,2.44,155.88]],"id":9570503},{"bdatb":[[1,6.8,1.36],[2,6.6,15.88],[3,6.2,1.92],[4,5.8,1.28],[5,5.5,3.04],[6,5.4,1.29],[7,5.2,4.62],[8,5.1,9.28],[9,5,4.15]],"bdatl":[[0,8.2,6],[1,8.4,3.06],[2,8.8,1.74],[3,9,2.45],[4,9.2,5.1],[5,9.4,3.67],[6,9.6,11.09],[7,10,17.36],[8,10.5,12.47],[9,11,33.84]],"id":12989514},{"bdatb":[[6,14,1.11],[7,11.5,1.71],[8,10.5,1.12],[9,10,103.89]],"id":44621159},{"bdatb":[[6,5.7,47.35],[7,5.6,12],[9,5.4,14.64]],"id":44836671},{"bdatb":[[6,6.8,2.35],[7,6.6,64.72],[8,6.4,2.54],[9,6.2,10.62]],"id":43885158},{"bdatb":[[6,13.5,1.19],[7,11,1.04],[8,10,4.09],[9,9.6,1.9]],"id":46969227}]}]}
{"op":"mcm","clk":"AKclALkTAJ0g","pt":1659347470886,"mc":[{"id":"1.201590187","rc":[{"atl":[[8.2,6.31],[9.2,4.82]],"id":12989514},{"atl":[[8.2,5.31]],"id":44836671}]}]}
{"op":"mcm","clk":"AKglAL0TAJ4g","pt":1659347470936,"mc":[{"id":"1.201590187","rc":[{"bdatl":[[0,8.2,6.31],[4,9.2,4.82]],"id":12989514},{"bdatl":[[2,8.2,5.63],[3,8.4,3],[4,9.2,8],[5,9.8,33.55],[6,11,1.32],[7,12,1.8],[8,13,41.9],[9,13.5,1.55]],"id":44836671},{"bdatb":[[8,10,4.34],[9,9.6,1.64]],"id":46969227}]}]}
{"op":"mcm","clk":"AL4lAMcTAKsg","pt":1659347471182,"mc":[{"id":"1.201590187","rc":[{"atb":[[23,2.13]],"id":44621159},{"atb":[[7.8,1.26]],"id":43885158}]}]}
{"op":"mcm","clk":"AL8lAMkTALAg","pt":1659347471232,"mc":[{"id":"1.201590187","rc":[{"bdatb":[[0,23,2.62]],"id":44621159},{"bdatb":[[1,7.8,1.26]],"id":43885158}]}]}
{"op":"mcm","clk":"ANElANITAL8g","pt":1659347471444,"mc":[{"id":"1.201590187","rc":[{"atb":[[6.4,9.67]],"id":44836671}]}]}
{"op":"mcm","clk":"ANMlANMTAMEg","pt":1659347471494,"mc":[{"id":"1.201590187","rc":[{"bdatb":[[1,6.4,9.67]],"id":44836671}]}]}
{"op":"mcm","clk":"ANklANYTAMQg","pt":1659347471548,"mc":[{"id":"1.201590187","rc":[{"atb":[[6.2,9.3]],"id":44836671}]}]}
{"op":"mcm","clk":"AN8lANcTAMgg","pt":1659347471598,"mc":[{"id":"1.201590187","rc":[{"bdatb":[[2,6.2,9.3]],"id":44836671}]}]}
{"op":"mcm","clk":"AOglAOETANQg","pt":1659347471754,"mc":[{"id":"1.201590187","rc":[{"atb":[[12,0]],"id":45323444},{"atb":[[23,1]],"id":44621159}]}]}
{"op":"mcm","clk":"AO4lAOITANcg","pt":1659347471804,"mc":[{"id":"1.201590187","rc":[{"bdatb":[[3,11.5,7.04]],"id":45323444},{"bdatb":[[0,23,1.49]],"id":44621159}]}]}
{"op":"mcm","clk":"APMlAOgTANwg","pt":1659347471877,"mc":[{"id":"1.201590187","rc":[{"atb":[[1.04,0.62]],"id":45323444},{"atb":[[1.04,1.13]],"id":44621159}]}]}
{"op":"mcm","clk":"AIEmAO8TAOcg","pt":1659347472086,"mc":[{"id":"1.201590187","rc":[{"atl":[[8.8,0.29]],"id":12989514}]}]}
{"op":"mcm","clk":"AIImAPITAOkg","pt":1659347472136,"mc":[{"id":"1.201590187","rc":[{"bdatl":[[2,9,3.04],[3,9.2,4.82],[4,9.4,3.67],[5,9.6,11.09],[6,10,17.36],[7,10.5,12.47],[8,11,33.84],[9,12.5,1.29]],"id":12989514}]}]}
{"op":"mcm","clk":"AJUmAPgTAPMg","pt":1659347472391,"mc":[{"id":"1.201590187","rc":[{"atl":[[26,5.04],[25,7.05]],"id":45323444},{"atb":[[22,2.59]],"id":44621159}]}]}
{"op":"mcm","clk":"AJkmAPwTAPYg","pt":1659347472441,"mc":[{"id":"1.201590187","rc":[{"bdatl":[[4,25,7.53],[5,26,5.04]],"id":45323444},{"bdatb":[[1,22,2.59],[2,21,5],[3,20,1.8],[4,19.5,4.19],[5,18.5,1.37],[6,15.5,4.19],[7,14,1.11],[8,11.5,1.71],[9,10.5,1.12]],"id":44621159}]}]}
{"op":"mcm","clk":"AMMmAJMUAJch","pt":1659347473140,"mc":[{"id":"1.201590187","rc":[{"atb":[[22,0]],"id":44621159}]}]}
{"op":"mcm","clk":"AMUmAJUUAJsh","pt":1659347473190,"mc":[{"id":"1.201590187","rc":[{"bdatb":[[1,21,5],[2,20,1.8],[3,19.5,4.19],[4,18.5,1.37],[5,15.5,4.19],[6,14,1.11],[7,11.5,1.71],[8,10.5,1.12],[9,10,103.89]],"id":44621159}]}]}
{"op":"mcm","clk":"ANAmAJwUAKMh","pt":1659347473356,"mc":[{"id":"1.201590187","rc":[{"atb":[[23,3.47]],"id":44621159}]}]}
{"op":"mcm","clk":"ANMmAJwUAKQh","pt":1659347473406,"mc":[{"id":"1.201590187","rc":[{"bdatb":[[0,23,3.96]],"id":44621159}]}]}
{"op":"mcm","clk":"ANkmAJ8UAKch","pt":1659347473463,"mc":[{"id":"1.201590187","rc":[{"atb":[[6.8,3.76]],"id":12989514},{"atb":[[7.6,7.37]],"id":43885158}]}]}
{"op":"mcm","clk":"AOEmAKIUAKgh","pt":1659347473513,"mc":[{"id":"1.201590187","rc":[{"bdatl":[[9,2.44,162.56]],"id":9570503},{"bdatb":[[1,6.8,3.76]],"id":12989514},{"bdatb":[[2,7.6,7.37]],"id":43885158}]}]}
{"op":"mcm","clk":"AIYnALEUAMMh","pt":1659347474038,"mc":[{"id":"1.201590187","rc":[{"atb":[[23,1]],"id":44621159}]}]}
{"op":"mcm","clk":"AIonALIUAMQh","pt":1659347474088,"mc":[{"id":"1.201590187","rc":[{"bdatl":[[9,2.44,157.34]],"id":9570503},{"bdatb":[[0,23,1.49]],"id":44621159}]}]}
{"op":"mcm","clk":"AK8nAMIUAN4h","pt":1659347474769,"mc":[{"id":"1.201590187","rc":[{"atb":[[22,2.59]],"id":44621159}]}]}
{"op":"mcm","clk":"ALQnAMQUAOQh","pt":1659347474819,"mc":[{"id":"1.201590187","rc":[{"bdatb":[[1,22,2.59],[2,21,5],[3,20,1.8],[4,19.5,4.19],[5,18.5,1.37],[6,15.5,4.19],[7,14,1.11],[8,11.5,1.71],[9,10.5,1.12]],"id":44621159}]}]}
{"op":"mcm","clk":"ANUnANUUAIQi","pt":1659347475342,"mc":[{"id":"1.201590187","rc":[{"atb":[[13.5,1]],"atl":[[19,1.41]],"id":45323444},{"atb":[[23,2]],"atl":[[36,2]],"id":44621159}]}]}
{"op":"mcm","clk":"ANcnANcUAIgi","pt":1659347475392,"mc":[{"id":"1.201590187","rc":[{"bdatb":[[1,13.5,1],[2,13,4.32],[3,12.5,1.14],[4,11.5,7.04],[5,11,1.23],[6,10.5,4.47],[7,10,10],[8,9.8,10.22],[9,9.6,22.19]],"bdatl":[[1,19,1.41],[2,19.5,1],[3,21,1.15],[4,23,2.64],[5,25,7.53],[6,26,5.04],[7,27,3.85],[8,29,5.36],[9,32,3.23]],"id":45323444},{"bdatb":[[7,1.91,113.6],[8,1.9,4.43],[9,1.89,3.43]],"bdatl":[[7,2.38,36.73],[8,2.4,71.43],[9,2.42,2.45]],"id":9570503},{"bdatb":[[5,5.6,1.49],[6,5.5,1.53],[7,5.4,2.25],[8,5.3,2.61],[9,5.2,4.64]],"id":12989514},{"bdatb":[[0,23,2.49],[8,11.5,1.69],[9,11,1.11]],"bdatl":[[0,36,2.57]],"id":44621159},{"bdatl":[[7,12,1.81]],"id":44836671},{"bdatb":[[8,10.5,1.42],[9,10,3.95]],"id":46969227}]}]}
{"op":"mcm","clk":"APknAOMUAKgi","pt":1659347475888,"mc":[{"id":"1.201590187","rc":[{"atb":[[20,7.14]],"id":46969227}]}]}
{"op":"mcm","clk":"APsnAOUUAKwi","pt":1659347475938,"mc":[{"id":"1.201590187","rc":[{"bdatb":[[1,20,7.24]],"id":46969227}]}]}
{"op":"mcm","clk":"AIAoAOYUAK4i","pt":1659347475988,"mc":[{"id":"1.201590187","rc":[{"atb":[[22,0]],"bdatb":[[1,21,5],[2,20,1.8],[3,19.5,4.19],[4,18.5,1.37],[5,15.5,4.19],[6,14,1.11],[7,11.5,1.69],[8,11,1.11],[9,10,104.88]],"id":44621159}]}]}
{"op":"mcm","clk":"AIMoAOkUALMi","pt":1659347476079,"mc":[{"id":"1.201590187","rc":[{"atb":[[23,4.47]],"id":44621159},{"atb":[[21,1.6]],"id":46969227}]}]}
{"op":"mcm","clk":"AIcoAOsUALci","pt":1659347476129,"mc":[{"id":"1.201590187","rc":[{"bdatb":[[0,23,4.96]],"id":44621159},{"bdatb":[[1,21,1.6],[2,20,7.14],[3,19.5,7],[4,19,5],[5,18.5,7],[6,16,1.43],[7,13.5,1.19],[8,11,1.04],[9,10.5,1.42]],"id":46969227}]}]}
{"op":"mcm","clk":"AKAoAPYUANUi","pt":1659347476554,"mc":[{"id":"1.201590187","rc":[{"atl":[[19.5,0]],"id":45323444},{"atl":[[32,1.72]],"id":46969227}]}]}
{"op":"mcm","clk":"AKQoAPgUANsi","pt":1659347476604,"mc":[{"id":"1.201590187","rc":[{"bdatl":[[2,21,1.15],[3,23,2.64],[4,25,7.53],[5,26,5.04],[6,27,3.85],[7,29,5.36],[8,32,3.23],[9,50,8]],"id":45323444},{"bdatb":[[7,5.4,1.2],[8,5.3,1.07],[9,5.2,3.55]],"id":12989514},{"bdatb":[[8,10.5,1.13],[9,10,103.84]],"id":44621159},{"bdatl":[[1,32,1.72]],"id":46969227}]}]}
{"op":"mcm","clk":"AKcoAPoUANsi","pt":1659347476664,"mc":[{"id":"1.201590187","rc":[{"atb":[[14.5,0]],"id":45323444},{"atb":[[22,4.3]],"atl":[[32,0.72]],"id":46969227}]}]}
{"op":"mcm","clk":"AKsoAP0UAOEi","pt":1659347476714,"mc":[{"id":"1.201590187","rc":[{"bdatb":[[0,13.5,1],[1,13,4.32],[2,12.5,1.14],[3,11.5,7.04],[4,11,1.23],[5,10.5,4.47],[6,10,10],[7,9.8,10.22],[8,9.6,22.19],[9,9.4,62.72]],"id":45323444},{"bdatl":[[5,2.36,66.68],[6,2.38,39.22],[7,2.4,75],[8,2.44,162.56],[9,2.48,5.83]],"id":9570503},{"bdatl":[[9,13.5,1.13]],"id":12989514},{"bdatl":[[6,11.5,1.17],[7,12,1.88]],"id":44836671},{"bdatl":[[9,15,12]],"id":43885158},{"bdatb":[[0,22,4.3]],"bdatl":[[1,34,6.32],[2,38,2.51],[3,40,5.01],[4,80,1.66],[5,310,1],[6,990,2.15],[7,0,0]],"id":46969227}]}]}
{"op":"mcm","clk":"AKwoAP0UAOIi","pt":1659347476765,"mc":[{"id":"1.201590187","rc":[{"atb":[[23,2]],"id":44621159}]}]}
{"op":"mcm","clk":"ALIoAIAVAOYi","pt":1659347476815,"mc":[{"id":"1.201590187","rc":[{"bdatl":[[9,2.48,4.13]],"id":9570503},{"bdatb":[[0,23,2.49]],"id":44621159}]}]}
{"op":"mcm","clk":"ALwoAIQVAPQi","pt":1659347476976,"mc":[{"id":"1.201590187","rc":[{"atb":[[24,2.91]],"id":44621159}]}]}
{"op":"mcm","clk":"AMQoAIcVAPci","pt":1659347477026,"mc":[{"id":"1.201590187","rc":[{"bdatl":[[6,2.38,42.82],[7,2.4,71.43],[9,2.46,5.87]],"id":9570503},{"bdatb":[[0,24,2.91],[1,23,2],[2,21,5],[3,20,1.8],[4,19.5,4.19],[5,18.5,1.37],[6,15.5,4.19],[7,14,1.11],[8,11.5,1.69],[9,10.5,1.13]],"id":44621159}]}]}
{"op":"mcm","clk":"ANgoAI4VAIoj","pt":1659347477296,"mc":[{"id":"1.201590187","rc":[{"atl":[[8,7]],"id":12989514},{"atb":[[5.9,9],[5.8,30.83]],"atl":[[8,7.32]],"id":44836671}]}]}
{"op":"mcm","clk":"ANkoAJAVAI4j","pt":1659347477346,"mc":[{"id":"1.201590187","rc":[{"bdatb":[[6,10,11.95],[7,9.8,9.39],[8,9.6,21],[9,9.4,63.21]],"id":45323444},{"bdatb":[[4,1.97,7.31],[5,1.96,4.7],[6,1.93,1.79],[7,1.92,4.4],[8,1.91,111.77],[9,1.9,3.41]],"id":9570503},{"bdatl":[[0,8,7],[1,8.2,6.31],[2,8.4,3.06],[3,9,3.04],[4,9.2,4.82],[5,9.4,3.67],[6,9.6,11.09],[7,10,17.36],[8,10.5,12.47],[9,11,33.84]],"id":12989514},{"bdatb":[[7,15,1.07],[8,12,1.65],[9,10.5,1.82]],"id":44621159},{"bdatb":[[4,5.9,9],[5,5.8,33.59],[6,5.7,44.55],[8,5.5,23.63],[9,5.4,14.71]],"bdatl":[[2,8,7.32],[3,8.2,5.31],[4,8.4,3],[5,9.2,8],[6,9.8,33.55],[7,11.5,1.17],[8,12,1.88],[9,13,41.9]],"id":44836671},{"bdatb":[[5,7,6.7],[6,6.6,65.32],[7,6.4,3.14],[8,6.2,12.1],[9,6,15.08]],"id":43885158},{"bdatb":[[7,14,1.14],[8,11.5,1],[9,10.5,1.39]],"id":46969227}]}]}
{"op":"mcm","clk":"AN8oAJEVAJMj","pt":1659347477406,"mc":[{"id":"1.201590187","rc":[{"atl":[[19,1]],"id":45323444},{"atb":[[2.06,10.54]],"atl":[[2.32,0]],"id":9570503},{"atl":[[38,1.15]],"id":44621159}]}]}
{"op":"mcm","clk":"AOQoAJMVAJgj","pt":1659347477456,"mc":[{"id":"1.201590187","rc":[{"bdatl":[[1,19,1]],"id":45323444},{"bdatb":[[0,2.06,10.54],[8,1.91,111.07],[9,1.88,7.18]],"bdatl":[[4,2.36,66.68],[5,2.38,42.82],[6,2.4,71.43],[7,2.44,162.56],[8,2.46,5.87],[9,2.48,3.06]],"id":9570503},{"bdatb":[[6,5.5,1.29],[7,5.3,2.54],[8,5.2,2.05],[9,5.1,3.53]],"id":12989514},{"bdatb":[[8,12,1.54],[9,10.5,1.99]],"bdatl":[[1,38,1.15]],"id":44621159},{"bdatl":[[8,12,2.1]],"id":44836671},{"bdatb":[[8,6.2,11.89],[9,6,14.22]],"id":43885158},{"bdatb":[[9,10,5.05]],"id":46969227}]}]}
{"op":"mcm","clk":"AOsoAJUVAJoj","pt":1659347477511,"mc":[{"id":"1.201590187","rc":[{"atl":[[9,2.17],[8,7.32]],"id":12989514}]}]}
{"op":"mcm","clk":"APAoAJYVAJsj","pt":1659347477561,"mc":[{"id":"1.201590187","rc":[{"bdatl":[[0,8,7.32],[3,9,2.76]],"id":12989514},{"bdatb":[[9,10.5,2.24]],"id":44621159}]}]}
{"op":"mcm","clk":"AP4oAJ8VAK0j","pt":1659347477776,"mc":[{"id":"1.201590187","rc":[{"atb":[[24,0.49]],"id":44621159},{"atl":[[30,0.07]],"id":46969227}]}]}
{"op":"mcm","clk":"AIEpAKAVALAj","pt":1659347477826,"mc":[{"id":"1.201590187","rc":[{"bdatb":[[6,10,11.4],[7,9.8,9.56],[8,9.6,21.4],[9,9.4,62.72]],"id":45323444},{"bdatb":[[5,1.96,3.69],[6,1.95,1.02],[7,1.92,1.8],[8,1.91,111.79],[9,1.9,3.73]],"bdatl":[[5,2.38,39.22],[6,2.4,75],[8,2.48,4.13],[9,2.5,22.68]],"id":9570503},{"bdatb":[[4,5.7,1.96],[5,5.5,2.13],[6,5.2,4.63],[7,5.1,3.53],[8,5,10.69],[9,4.9,8.66]],"id":12989514},{"bdatb":[[0,23,2.49],[1,21,5],[2,20,1.8],[3,19.5,4.19],[4,18.5,1.37],[5,15.5,4.19],[6,14.5,1.07],[7,11.5,1.58],[8,10.5,2.24],[9,10,102.06]],"id":44621159},{"bdatb":[[5,5.8,33.25],[6,5.7,44.89],[8,5.5,23],[9,5.4,14.64]],"id":44836671},{"bdatb":[[7,6.4,2.54],[8,6.2,12.51]],"id":43885158},{"bdatl":[[0,32,1.2],[1,34,5.6]],"id":46969227}]}]}
{"op":"mcm","clk":"AIspAKYVALsj","pt":1659347477987,"mc":[{"id":"1.201590187","rc":[{"atb":[[23,1]],"atl":[[36,1]],"id":44621159}]}]}
{"op":"mcm","clk":"AIwpAKgVAL0j","pt":1659347478037,"mc":[{"id":"1.201590187","rc":[{"bdatl":[[7,2.44,157.34],[8,2.48,5.14],[9,2.5,26.78]],"id":9570503},{"bdatb":[[6,5.2,3.93],[7,5.1,4.25],[8,5,8.37],[9,4.9,11.03]],"id":12989514},{"bdatb":[[0,23,1.49]],"bdatl":[[0,36,1.57]],"id":44621159},{"bdatb":[[9,10,4.99]],"id":46969227}]}]}
{"op":"mcm","clk":"AKkpALQVANUj","pt":1659347478498,"mc":[{"id":"1.201590187","rc":[{"atb":[[22,2.59]],"id":44621159},{"atb":[[20,5.51]],"id":46969227}]}]}
{"op":"mcm","clk":"AK0pALUVANcj","pt":1659347478548,"mc":[{"id":"1.201590187","rc":[{"bdatl":[[8,2.46,5.18],[9,2.48,5.83]],"id":9570503},{"bdatb":[[1,22,2.59],[2,21,5],[3,20,1.8],[4,19.5,4.19],[5,18.5,1.37],[6,15.5,4.19],[7,14.5,1.07],[8,11.5,1.58],[9,10.5,2.24]],"id":44621159},{"bdatb":[[2,20,5.51]],"id":46969227}]}]}
{"op":"mcm","clk":"ALIpALYVAOAj","pt":1659347478598,"mc":[{"id":"1.201590187","rc":[{"atb":[[23,1.63]],"bdatb":[[0,23,1.63],[1,22,4.3],[2,21,1.6],[3,20,5.51],[4,19.5,7],[5,19,5],[6,18.5,7],[7,16,1.43],[8,14,1.14],[9,11.5,1]],"id":46969227},{"bdatl":[[4,2.36,71.71],[5,2.38,37.83],[6,2.4,71.43],[7,2.44,158.38],[8,2.46,4.15]],"id":9570503},{"bdatl":[[7,11,1.08],[8,12,2.24]],"id":44836671}]}]}
{"op":"mcm","clk":"ALopALgVAOMj","pt":1659347478673,"mc":[{"id":"1.201590187","rc":[{"atb":[[22,4.4],[21,8.6]],"id":46969227}]}]}
{"op":"mcm","clk":"ALspALoVAOQj","pt":1659347478723,"mc":[{"id":"1.201590187","rc":[{"bdatb":[[1,22,4.4],[2,21,8.6]],"id":46969227}]}]}
{"op":"mcm","clk":"AMMpALwVAOgj","pt":1659347478781,"mc":[{"id":"1.201590187","rc":[{"atb":[[18.5,0]],"id":46969227}]}]}
{"op":"mcm","clk":"AMQpAL4VAOgj","pt":1659347478846,"mc":[{"id":"1.201590187","rc":[{"bdatb":[[6,16,1.43],[7,14,1.14],[8,11.5,1],[9,10,4.99]],"id":46969227}]}]}
{"op":"mcm","clk":"AN4pAMsVAP8j","pt":1659347479296,"mc":[{"id":"1.201590187","rc":[{"atb":[[22,0]],"id":44621159},{"atl":[[32,1.72]],"id":46969227}]}]}
{"op":"mcm","clk":"AOIpAM0VAIIk","pt":1659347479346,"mc":[{"id":"1.201590187","rc":[{"bdatl":[[7,2.44,157.34],[8,2.46,1.03],[9,2.48,4.12]],"id":9570503},{"bdatb":[[6,5.2,4.63],[7,5.1,3.53]],"id":12989514},{"bdatb":[[1,21,5],[2,20,1.8],[3,19.5,4.19],[4,18.5,1.37],[5,15.5,4.19],[6,14.5,1.07],[7,11.5,1.58],[8,10.5,2.24],[9,10,103.05]],"id":44621159},{"bdatl":[[0,32,2.2]],"id":46969227}]}]}
{"op":"mcm","clk":"AOgpAM4VAIMk","pt":1659347479406,"mc":[{"id":"1.201590187","rc":[{"atb":[[23,2.63]],"id":46969227}]}]}
{"op":"mcm","clk":"AOkpAM4VAIck","pt":1659347479456,"mc":[{"id":"1.201590187","rc":[{"bdatl":[[8,2.46,5.18],[9,2.48,5.16]],"id":9570503},{"bdatb":[[0,23,2.63]],"id":46969227}]}]}
{"op":"mcm","clk":"AO4pAM8VAIwk","pt":1659347479507,"mc":[{"id":"1.201590187","rc":[{"atb":[[23,3.47]],"id":44621159}]}]}
{"op":"mcm","clk":"APIpANEVAI8k","pt":1659347479558,"mc":[{"id":"1.201590187","rc":[{"bdatl":[[7,2.44,162.56],[8,2.46,5.2],[9,2.5,24.7]],"id":9570503},{"bdatb":[[0,23,3.96]],"id":44621159}]}]}
{"op":"mcm","clk":"AIUqANcVAKEk","pt":1659347479863,"mc":[{"id":"1.201590187","rc":[{"atb":[[10.5,1.6]],"id":45323444},{"atl":[[60,0],[55,0.64]],"id":44621159}]}]}
{"op":"mcm","clk":"AIsqANkVAKQk","pt":1659347479913,"mc":[{"id":"1.201590187","rc":[{"bdatb":[[5,10.5,1.6]],"id":45323444},{"bdatl":[[3,120,7.84]],"id":44621159}]}]}
{"op":"mcm","clk":"AJIqANkVAKgk","pt":1659347479996,"mc":[{"id":"1.201590187","rc":[{"atb":[[12,2.87]],"id":45323444}]}]}
{"op":"mcm","clk":"AJQqANoVAK8k","pt":1659347480046,"mc":[{"id":"1.201590187","rc":[{"bdatb":[[3,12,2.87],[4,11.5,7.04],[5,11,1.23],[6,10.5,1.6],[7,10,11.4],[8,9.8,9.56],[9,9.6,21.4]],"id":45323444}]}]}
{"op":"mcm","clk":"AKIqAN8VAMIk","pt":1659347480286,"mc":[{"id":"1.201590187","rc":[{"atb":[[23,1]],"id":44621159}]}]}
{"op":"mcm","clk":"AKoqAOEVAMYk","pt":1659347480336,"mc":[{"id":"1.201590187","rc":[{"bdatl":[[7,2.44,157.34],[8,2.46,5.18],[9,2.48,5.16]],"id":9570503},{"bdatb":[[0,23,1.49]],"id":44621159}]}]}
{"op":"mcm","clk":"AK8qAOIVAMgk","pt":1659347480389,"mc":[{"id":"1.201590187","rc":[{"atl":[[29,0]],"id":46969227}]}]}
{"op":"mcm","clk":"ALAqAOQVAMgk","pt":1659347480440,"mc":[{"id":"1.201590187","rc":[{"bdatb":[[7,10,10.21],[8,9.8,10.77]],"id":45323444},{"bdatb":[[4,1.97,1.26],[6,1.95,7.13]],"id":9570503},{"bdatb":[[3,6,2.67],[4,5.7,1.28],[6,5.2,4.25],[7,5.1,3.92]],"id":12989514},{"bdatb":[[6,14.5,1.1],[9,10,102.06]],"id":44621159},{"bdatb":[[5,5.8,31.19],[6,5.7,46.98]],"id":44836671},{"bdatb":[[5,7,5],[6,6.8,2.35],[7,6.6,64.72],[8,6.4,2.54],[9,6.2,12.51]],"id":43885158},{"bdatl":[[0,32,1.79]],"id":46969227}]}]}
{"op":"mcm","clk":"AL8qAOsVANEk","pt":1659347480611,"mc":[{"id":"1.201590187","rc":[{"atl":[[30,0.16]],"id":46969227}]}]}
{"op":"mcm","clk":"AMcqAOsVANck","pt":1659347480661,"mc":[{"id":"1.201590187","rc":[{"bdatb":[[7,10,10.48],[8,9.8,10.5]],"id":45323444},{"bdatb":[[5,1.96,5.07],[6,1.95,5.74]],"id":9570503},{"bdatb":[[6,5.2,4.63],[7,5.1,3.53]],"id":12989514},{"bdatb":[[6,14.5,1.09],[9,10,102.13]],"id":44621159},{"bdatb":[[5,5.8,31.66],[6,5.7,46.51]],"id":44836671},{"bdatl":[[0,32,1.88]],"id":46969227}]}]}
{"op":"mcm","clk":"AMkqAO0VANgk","pt":1659347480711,"mc":[{"id":"1.201590187","rc":[{"atl":[[25,5.61]],"bdatl":[[4,25,6.09]],"id":45323444}]}]}
{"op":"mcm","clk":"ANwqAO8VAOAk","pt":1659347480785,"mc":[{"id":"1.201590187","rc":[{"atl":[[990,1.45]],"id":45323444}]}]}
{"op":"mcm","clk":"AOoqAPcVAO4k","pt":1659347480962,"mc":[{"id":"1.201590187","rc":[{"atb":[[13.5,5.25]],"id":45323444}]}]}
{"op":"mcm","clk":"AO0qAPoVAPIk","pt":1659347481012,"mc":[{"id":"1.201590187","rc":[{"bdatb":[[0,13.5,5.25]],"id":45323444},{"bdatl":[[7,2.42,5.29],[8,2.44,157.32],[9,2.46,5.2]],"id":9570503},{"bdatl":[[8,12,2.27]],"id":44836671}]}]}
{"op":"mcm","clk":"APAqAPsVAPMk","pt":1659347481084,"mc":[{"id":"1.201590187","rc":[{"atb":[[22,2.59]],"id":44621159}]}]}
{"op":"mcm","clk":"APcqAP4VAP4k","pt":1659347481134,"mc":[{"id":"1.201590187","rc":[{"bdatl":[[7,2.42,10.56],[8,2.44,152.09],[9,2.46,5.87]],"id":9570503},{"bdatb":[[1,22,2.59],[2,21,5],[3,20,1.8],[4,19.5,4.19],[5,18.5,1.37],[6,15.5,4.19],[7,14.5,1.09],[8,11.5,1.58],[9,10.5,2.24]],"id":44621159}]}]}
{"op":"mcm","clk":"AIQrAIgWAJEl","pt":1659347481486,"mc":[{"id":"1.201590187","rc":[{"atb":[[7.6,4.53]],"id":43885158}]}]}
{"op":"mcm","clk":"AIwrAIsWAJMl","pt":1659347481538,"mc":[{"id":"1.201590187","rc":[{"bdatb":[[2,7.6,4.53]],"id":43885158}]}]}
{"op":"mcm","clk":"AJUrAJEWAJcl","pt":1659347481688,"mc":[{"id":"1.201590187","rc":[{"atl":[[7.8,4.19]],"id":12989514}]}]}
{"op":"mcm","clk":"AJsrAJMWAJkl","pt":1659347481738,"mc":[{"id":"1.201590187","rc":[{"bdatb":[[7,10,12.33],[8,9.8,9],[9,9.6,21.48]],"id":45323444},{"bdatb":[[3,1.98,44.48],[4,1.97,6.95],[5,1.96,2.62],[6,1.93,1.79],[7,1.92,4.4],[8,1.91,109.87],[9,1.9,1.21]],"id":9570503},{"bdatl":[[0,7.8,4.19],[1,8,7.32],[2,8.2,6.31],[3,8.4,3.06],[4,9,2.76],[5,9.2,4.82],[6,9.4,3.67],[7,9.6,11.09],[8,10,17.36],[9,10.5,12.47]],"id":12989514},{"bdatb":[[6,15.5,4.5],[7,13,1.31],[8,11,1.09],[9,10.5,2.17]],"id":44621159},{"bdatb":[[4,5.9,9.81],[5,5.8,32.76],[6,5.7,44.55],[8,5.5,23.63],[9,5.4,14.71]],"id":44836671},{"bdatb":[[5,7,7.29],[6,6.6,64.72],[7,6.4,3.14],[8,6.2,11.89],[9,6,14.22]],"id":43885158},{"bdatb":[[7,14.5,1.1],[8,11.5,1.38],[9,10,4.62]],"id":46969227}]}]}
{"op":"mcm","clk":"AKUrAJYWAJ4l","pt":1659347481812,"mc":[{"id":"1.201590187","rc":[{"atb":[[13.5,1]],"id":45323444},{"atb":[[22,0]],"id":44621159}]}]}
{"op":"mcm","clk":"AKwrAJgWAKIl","pt":1659347481871,"mc":[{"id":"1.201590187","rc":[{"atl":[[7.8,11.52],[8.8,0]],"id":12989514},{"atl":[[7.8,8]],"bdatl":[[8,12,2.24]],"id":44836671},{"bdatb":[[0,13.5,1]],"id":45323444},{"bdatl":[[7,2.44,157.34],[8,2.46,5.18],[9,2.48,5.16]],"id":9570503},{"bdatb":[[1,21,5],[2,20,1.8],[3,19.5,4.19],[4,18.5,1.37],[5,15.5,4.5],[6,13,1.31],[7,11,1.09],[8,10.5,2.17],[9,10,105.21]],"id":44621159}]}]}
{"op":"mcm","clk":"AKwrAJoWAKIl","pt":1659347481921,"mc":[{"id":"1.201590187","rc":[{"bdatb":[[8,1.91,111.07],[9,1.88,12.83]],"id":9570503},{"bdatl":[[0,7.8,11.52],[4,9,2.47]],"id":12989514},{"bdatb":[[7,11.5,1.08],[8,11,2.07],[9,10.5,1.71]],"id":44621159},{"bdatl":[[2,7.8,8],[3,8,7.32],[4,8.2,5.31],[5,8.4,3],[6,9.2,8],[7,9.8,33.55],[8,11,1.08],[9,12,2.24]],"id":44836671},{"bdatb":[[9,6,17.41]],"id":43885158},{"bdatb":[[8,11.5,1.58],[9,10.5,2.29]],"id":46969227}]}]}
{"op":"mcm","clk":"ALQrAJsWAKQl","pt":1659347481971,"mc":[{"id":"1.201590187","rc":[{"atb":[[23,3.47]],"id":44621159}]}]}
{"op":"mcm","clk":"ALQrAJ0WAKkl","pt":1659347482021,"mc":[{"id":"1.201590187","rc":[{"bdatl":[[7,2.44,162.56],[8,2.46,5.2],[9,2.5,24.7]],"id":9570503},{"bdatb":[[0,23,3.96]],"id":44621159}]}]}
{"op":"mcm","clk":"AOgrALAWANIl","pt":1659347482703,"mc":[{"id":"1.201590187","rc":[{"atb":[[23,1]],"id":44621159}]}]}
{"op":"mcm","clk":"AOsrALIWANgl","pt":1659347482753,"mc":[{"id":"1.201590187","rc":[{"bdatl":[[7,2.44,157.34],[8,2.46,5.18],[9,2.48,5.16]],"id":9570503},{"bdatb":[[0,23,1.49]],"id":44621159}]}]}
{"op":"mcm","clk":"APcrALQWAN4l","pt":1659347482892,"mc":[{"id":"1.201590187","rc":[{"atb":[[13.5,5.25]],"id":45323444}]}]}
{"op":"mcm","clk":"APkrALYWAOAl","pt":1659347482942,"mc":[{"id":"1.201590187","rc":[{"bdatb":[[0,13.5,5.25]],"id":45323444},{"bdatl":[[7,2.42,5.29],[8,2.44,157.32],[9,2.46,5.2]],"id":9570503},{"bdatl":[[9,12,2.27]],"id":44836671}]}]}
{"op":"mcm","clk":"AIUsAL4WAOol","pt":1659347483068,"mc":[{"id":"1.201590187","rc":[{"atb":[[24,2.91]],"id":44621159}]}]}
{"op":"mcm","clk":"AIUsAMIWAOsl","pt":1659347483120,"mc":[{"id":"1.201590187","rc":[{"bdatl":[[4,2.36,76.03],[5,2.38,33.55],[6,2.4,82.08],[7,2.44,158.01],[8,2.46,3.14],[9,2.5,21.86]],"id":9570503},{"bdatb":[[0,24,2.91],[1,23,1],[2,21,5],[3,20,1.8],[4,19.5,4.19],[5,18.5,1.37],[6,15.5,4.5],[7,13,1.31],[8,11.5,1.08],[9,11,2.07]],"id":44621159},{"bdatl":[[8,11,1.97],[9,12,1.41]],"id":44836671}]}]}
{"op":"mcm","clk":"AJssAMsWAPYl","pt":1659347483390,"mc":[{"id":"1.201590187","rc":[{"atb":[[6.8,1.36]],"id":12989514},{"atl":[[1000,0.41]],"id":46969227}]}]}
{"op":"mcm","clk":"AJ0sAMwWAPol","pt":1659347483440,"mc":[{"id":"1.201590187","rc":[{"bdatl":[[6,2.4,75.28],[7,2.44,164.7]],"id":9570503},{"bdatb":[[1,6.8,1.36]],"id":12989514},{"bdatl":[[7,1000,0.41]],"id":46969227}]}]}
{"op":"mcm","clk":"AKIsAM0WAPsl","pt":1659347483491,"mc":[{"id":"1.201590187","rc":[{"atl":[[38,0]],"id":44621159}]}]}
{"op":"mcm","clk":"AKUsAM8WAIAm","pt":1659347483541,"mc":[{"id":"1.201590187","rc":[{"bdatb":[[9,1.88,10.87]],"id":9570503},{"bdatb":[[6,5.2,3.93],[7,5,12.69],[8,4.9,11.03],[9,4.8,227.44]],"id":12989514},{"bdatl":[[1,40,3.27],[2,120,7.84],[3,170,2],[4,990,2.07],[5,0,0]],"id":44621159},{"bdatb":[[9,10.5,1.94]],"id":46969227}]}]}
{"op":"mcm","clk":"AKwsANIWAIMm","pt":1659347483603,"mc":[{"id":"1.201590187","rc":[{"atl":[[1000,0]],"id":46969227}]}]}
{"op":"mcm","clk":"AK0sANQWAIYm","pt":1659347483654,"mc":[{"id":"1.201590187","rc":[{"bdatl":[[7,0,0]],"id":46969227}]}]}
{"op":"mcm","clk":"ALUsANgWAIgm","pt":1659347483713,"mc":[{"id":"1.201590187","rc":[{"atl":[[30,0.57]],"id":46969227}]}]}
{"op":"mcm","clk":"ALYsANoWAIsm","pt":1659347483763,"mc":[{"id":"1.201590187","rc":[{"bdatb":[[3,1.98,50.13],[4,1.97,1.26]],"id":9570503},{"bdatb":[[4,5.7,1.27],[7,5.1,3.27],[8,5,9.37],[9,4.9,11.03]],"id":12989514},{"bdatb":[[6,15.5,5.23],[7,12,1.51],[8,11,2.19],[9,10.5,1.71]],"id":44621159},{"bdatb":[[4,5.9,11.71],[5,5.8,30.83],[7,5.6,12.2],[8,5.5,23.42]],"id":44836671},{"bdatb":[[6,6.6,64.89],[7,6.4,2.96]],"id":43885158},{"bdatl":[[0,32,2.29]],"id":46969227}]}]}
{"op":"mcm","clk":"AL0sAN0WAI4m","pt":1659347483813,"mc":[{"id":"1.201590187","rc":[{"atb":[[9.4,28.24]],"id":45323444},{"atb":[[1.77,50.78]],"id":9570503},{"atb":[[3.7,31.24]],"id":12989514},{"atb":[[9.4,27.29]],"id":44621159},{"atb":[[6,47.37]],"id":44836671},{"atb":[[6.6,30.24]],"id":43885158},{"atb":[[9.4,17.24]],"id":46969227}]}]}
{"op":"mcm","clk":"AL4sAN0WAJEm","pt":1659347483863,"mc":[{"id":"1.201590187","rc":[{"bdatb":[[3,6,47.37]],"id":44836671},{"bdatb":[[6,6.6,30.41]],"id":43885158}]}]}
{"op":"mcm","clk":"AMMsAOEWAJIm","pt":1659347483913,"mc":[{"id":"1.201590187","rc":[{"atb":[[24,0.49]],"id":44621159}]}]}
{"op":"mcm","clk":"AMQsAOEWAJQm","pt":1659347483963,"mc":[{"id":"1.201590187","rc":[{"bdatl":[[4,2.36,71.71],[5,2.38,37.83],[6,2.4,71.43],[7,2.42,3.82],[8,2.44,153.55],[9,2.46,10.38]],"id":9570503},{"bdatb":[[0,23,1.49],[1,21,5],[2,20,1.8],[3,19.5,4.19],[4,18.5,1.37],[5,15.5,5.23],[6,12,1.51],[7,11,2.19],[8,10.5,1.71],[9,10,106.19]],"id":44621159},{"bdatl":[[8,11,1.08],[9,12,2.27]],"id":44836671}]}]}
{"op":"mcm","clk":"AMksAOMWAJUm","pt":1659347484014,"mc":[{"id":"1.201590187","rc":[{"atb":[[22,2.59]],"id":44621159}]}]}
{"op":"mcm","clk":"AMwsAOQWAJcm","pt":1659347484064,"mc":[{"id":"1.201590187","rc":[{"bdatl":[[9,2.46,11.06]],"id":9570503},{"bdatb":[[1,22,2.59],[2,21,5],[3,20,1.8],[4,19.5,4.19],[5,18.5,1.37],[6,15.5,5.23],[7,12,1.51],[8,11,2.19],[9,10.5,1.71]],"id":44621159}]}]}
{"op":"mcm","clk":"ANosAOwWAKYm","pt":1659347484309,"mc":[{"id":"1.201590187","rc":[{"atb":[[13,0],[1.01,48.08]],"id":45323444},{"atb":[[7.2,1.07]],"id":12989514}]}]}
{"op":"mcm","clk":"AN0sAOwWAKkm","pt":1659347484359,"mc":[{"id":"1.201590187","rc":[{"bdatb":[[1,12.5,1.14],[2,12,2.87],[3,11.5,7.04],[4,11,1.23],[5,10.5,1.6],[6,10,12.33],[7,9.8,9],[8,9.6,21.48],[9,9.4,29.13]],"id":45323444},{"bdatl":[[4,2.36,69.93],[5,2.38,33.55],[6,2.4,73.18],[7,2.42,2.08],[8,2.44,159.45]],"id":9570503},{"bdatb":[[0,7.2,1.07]],"id":12989514},{"bdatl":[[8,12,2.11],[9,13,43]],"id":44836671}]}]}
{"op":"mcm","clk":"AOIsAOwWAKsm","pt":1659347484410,"mc":[{"id":"1.201590187","rc":[{"atb":[[14,2.7]],"id":45323444},{"atb":[[6.8,5.77]],"id":12989514},{"atl":[[95,2]],"id":44621159}]}]}
{"op":"mcm","clk":"AOcsAO8WAK0m","pt":1659347484460,"mc":[{"id":"1.201590187","rc":[{"bdatb":[[0,14,2.7],[1,13.5,5.25],[2,12.5,1.14],[3,12,2.87],[4,11.5,7.04],[5,11,1.23],[6,10.5,1.6],[7,10,12.33],[8,9.8,9],[9,9.6,21.48]],"id":45323444},{"bdatl":[[4,2.34,3.28],[5,2.36,66.68],[6,2.38,33.55],[7,2.4,82.77],[8,2.42,4.97],[9,2.44,152.09]],"id":9570503},{"bdatb":[[1,6.8,5.77]],"id":12989514},{"bdatl":[[2,95,2.64],[3,120,7.2],[4,170,2],[5,990,2.07]],"id":44621159},{"bdatl":[[8,12,3.28],[9,13,41.9]],"id":44836671},{"bdatl":[[9,15,12.51]],"id":43885158}]}]}
{"op":"mcm","clk":"AOosAPAWALMm","pt":1659347484510,"mc":[{"id":"1.201590187","rc":[{"atb":[[1.01,47.24]],"id":45323444}]}]}
{"op":"mcm","clk":"APosAPoWALsm","pt":1659347484700,"mc":[{"id":"1.201590187","rc":[{"atb":[[1.01,45.55]],"id":45323444},{"atb":[[22,0]],"id":44621159}]}]}
{"op":"mcm","clk":"AP8sAPwWALsm","pt":1659347484750,"mc":[{"id":"1.201590187","rc":[{"bdatl":[[8,2.42,1.21],[9,2.44,155.82]],"id":9570503},{"bdatb":[[1,21,5],[2,20,1.8],[3,19.5,4.19],[4,18.5,1.37],[5,15.5,5.23],[6,12,1.51],[7,11,2.19],[8,10.5,1.71],[9,10,106.19]],"id":44621159}]}]}
{"op":"mcm","clk":"AIUtAP4WAL0m","pt":1659347484800,"mc":[{"id":"1.201590187","rc":[{"atb":[[14,4.39]],"id":45323444}]}]}
{"op":"mcm","clk":"AIUtAIEXAL0m","pt":1659347484850,"mc":[{"id":"1.201590187","rc":[{"bdatb":[[0,14,4.39]],"id":45323444},{"bdatl":[[8,2.42,4.97],[9,2.44,152.09]],"id":9570503}]}]}
{"op":"mcm","clk":"AI0tAIIXAMMm","pt":1659347484900,"mc":[{"id":"1.201590187","rc":[{"atb":[[23,3.47]],"id":44621159}]}]}
{"op":"mcm","clk":"AI4tAIUXAMMm","pt":1659347484950,"mc":[{"id":"1.201590187","rc":[{"bdatl":[[7,2.4,87.78],[8,2.42,5.59],[9,2.44,152.52]],"id":9570503},{"bdatb":[[0,23,3.96]],"id":44621159}]}]}
{"op":"mcm","clk":"ALEtAKEXAOQm","pt":1659347485602,"mc":[{"id":"1.201590187","rc":[{"atb":[[13.5,1]],"id":45323444},{"atb":[[23,1]],"id":44621159}]}]}
{"op":"mcm","clk":"ALUtAKQXAOcm","pt":1659347485652,"mc":[{"id":"1.201590187","rc":[{"bdatb":[[1,13.5,1]],"id":45323444},{"bdatl":[[7,2.4,82.77],[8,2.42,4.97],[9,2.44,152.09]],"id":9570503},{"bdatb":[[0,23,1.49]],"id":44621159}]}]}
{"op":"mcm","clk":"AMQtAKoXAO0m","pt":1659347485783,"mc":[{"id":"1.201590187","rc":[{"atb":[[14.5,3.96]],"id":45323444}]}]}
{"op":"mcm","clk":"AMctAKsXAPIm","pt":1659347485833,"mc":[{"id":"1.201590187","rc":[{"bdatb":[[0,14.5,3.96],[1,14,4.39],[2,13.5,1],[3,12.5,1.14],[4,12,2.87],[5,11.5,7.04],[6,11,1.23],[7,10.5,1.6],[8,10,12.33],[9,9.8,9]],"id":45323444},{"bdatl":[[6,2.38,44.98],[7,2.4,71.43],[9,2.44,156.43]],"id":9570503},{"bdatl":[[8,11.5,1.1],[9,12,2.23]],"id":44836671},{"bdatl":[[8,14.5,1.53],[9,15,12]],"id":43885158}]}]}
{"op":"mcm","clk":"AMwtAKwXAPUm","pt":1659347485884,"mc":[{"id":"1.201590187","rc":[{"atb":[[3.7,48.48]],"id":12989514},{"atb":[[6,64.61]],"id":44836671}]}]}
{"op":"mcm","clk":"AM4tAK0XAPom","pt":1659347485934,"mc":[{"id":"1.201590187","rc":[{"bdatb":[[3,6,64.61]],"id":44836671}]}]}
{"op":"mcm","clk":"ANYtAK4XAPsm","pt":1659347485985,"mc":[{"id":"1.201590187","rc":[{"atb":[[9.4,45.48]],"id":45323444},{"atb":[[1.77,68.02]],"id":9570503},{"atb":[[9.4,44.53],[24,2.91]],"id":44621159},{"atb":[[9.4,34.48]],"id":46969227}]}]}
{"op":"mcm","clk":"ANctALAXAP8m","pt":1659347486035,"mc":[{"id":"1.201590187","rc":[{"bdatl":[[6,2.38,50.03],[7,2.4,75.84],[8,2.42,1.89],[9,2.44,155.25]],"id":9570503},{"bdatb":[[0,24,2.91],[1,23,1],[2,21,5],[3,20,1.8],[4,19.5,4.19],[5,18.5,1.37],[6,15.5,5.23],[7,12,1.51],[8,11,2.19],[9,10.5,1.71]],"id":44621159},{"bdatl":[[8,11.5,1.95],[9,12,1.41]],"id":44836671}]}]}
{"op":"mcm","clk":"ANotALEXAIQn","pt":1659347486087,"mc":[{"id":"1.201590187","rc":[{"atb":[[6.6,47.48]],"id":43885158}]}]}
{"op":"mcm","clk":"AN0tALMXAIYn","pt":1659347486146,"mc":[{"id":"1.201590187","rc":[{"bdatb":[[6,6.6,47.65]],"id":43885158}]}]}
{"op":"mcm","clk":"AOotALYXAI8n","pt":1659347486294,"mc":[{"id":"1.201590187","rc":[{"atb":[[6.8,4.77]],"atl":[[8.4,2.06]],"id":12989514}]}]}
{"op":"mcm","clk":"AOwtALgXAJAn","pt":1659347486344,"mc":[{"id":"1.201590187","rc":[{"bdatl":[[6,2.38,47.17],[7,2.4,78.67]],"id":9570503},{"bdatb":[[1,6.8,4.77]],"bdatl":[[3,8.4,2.06]],"id":12989514}]}]}
{"op":"mcm","clk":"AP8tAMAXAJIn","pt":1659347486564,"mc":[{"id":"1.201590187","rc":[{"atb":[[6.8,9.99],[4.9,0]],"bdatb":[[1,6.8,9.99],[9,4.9,5.8]],"id":12989514},{"bdatl":[[6,2.38,54.48],[7,2.4,73.34],[8,2.42,3.19],[9,2.44,152.97]],"id":9570503}],"con":true}]}
{"op":"mcm","clk":"AIguAMUXAKQn","pt":1659347486714,"mc":[{"id":"1.201590187","rc":[{"atb":[[14.5,0]],"id":45323444},{"atb":[[24,0.49]],"id":44621159}]}]}
{"op":"mcm","clk":"AI0uAMUXAKUn","pt":1659347486764,"mc":[{"id":"1.201590187","rc":[{"bdatb":[[0,14,4.39],[1,13.5,1],[2,12.5,1.14],[3,12,2.87],[4,11.5,7.04],[5,11,1.23],[6,10.5,1.6],[7,10,12.33],[8,9.8,9],[9,9.6,21.48]],"id":45323444},{"bdatl":[[6,2.38,33.55],[7,2.4,82.77],[8,2.42,10.56],[9,2.44,152.52]],"id":9570503},{"bdatb":[[0,23,1.49],[1,21,5],[2,20,1.8],[3,19.5,4.19],[4,18.5,1.37],[5,15.5,5.23],[6,12,1.51],[7,11,2.19],[8,10.5,1.71],[9,10,106.19]],"id":44621159},{"bdatl":[[8,12,3.28],[9,13,41.9]],"id":44836671},{"bdatl":[[8,14.5,1],[9,15,12.51]],"id":43885158}]}]}
{"op":"mcm","clk":"AJsuAMsXALIn","pt":1659347486908,"mc":[{"id":"1.201590187","rc":[{"atb":[[22,2.59]],"id":44621159}]}]}
{"op":"mcm","clk":"AJ4uAMwXALIn","pt":1659347486958,"mc":[{"id":"1.201590187","rc":[{"bdatl":[[8,2.42,10.99],[9,2.44,152.34]],"id":9570503},{"bdatb":[[1,22,2.59],[2,21,5],[3,20,1.8],[4,19.5,4.19],[5,18.5,1.37],[6,15.5,5.23],[7,12,1.51],[8,11,2.19],[9,10.5,1.71]],"id":44621159}]}]}
{"op":"mcm","clk":"AMQuAOEXANYn","pt":1659347487496,"mc":[{"id":"1.201590187","rc":[{"atb":[[7.6,8.11]],"id":43885158}]}]}
{"op":"mcm","clk":"AMguAOUXANon","pt":1659347487546,"mc":[{"id":"1.201590187","rc":[{"bdatb":[[2,7.6,8.11]],"id":43885158}]}]}
{"op":"mcm","clk":"APIuAJIYAIYo","pt":1659347488119,"mc":[{"id":"1.201590187","rc":[{"atb":[[22,0]],"id":44621159}]}]}
{"op":"mcm","clk":"APguAJQYAIso","pt":1659347488169,"mc":[{"id":"1.201590187","rc":[{"bdatl":[[8,2.42,10.56],[9,2.44,152.52]],"id":9570503},{"bdatb":[[1,21,5],[2,20,1.8],[3,19.5,4.19],[4,18.5,1.37],[5,15.5,5.23],[6,12,1.51],[7,11,2.19],[8,10.5,1.71],[9,10,106.19]],"id":44621159}]}]}
{"op":"mcm","clk":"AIMvAJkYAJMo","pt":1659347488281,"mc":[{"id":"1.201590187","rc":[{"atb":[[23,3.47]],"id":44621159}]}]}
{"op":"mcm","clk":"AIYvAJ0YAJoo","pt":1659347488331,"mc":[{"id":"1.201590187","rc":[{"bdatl":[[7,2.4,93.41],[8,2.44,156.81],[9,2.46,1.23]],"id":9570503},{"bdatb":[[0,23,3.96]],"id":44621159}]}]}
{"op":"mcm","clk":"ALsvAMAYAMQo","pt":1659347488909,"mc":[{"id":"1.201590187","rc":[{"atb":[[12,0]],"id":45323444}]}]}
{"op":"mcm","clk":"AMIvAMEYAMco","pt":1659347488960,"mc":[{"id":"1.201590187","rc":[{"bdatb":[[3,11.5,7.04],[4,11,1.23],[5,10.5,1.6],[6,10,12.33],[7,9.8,9],[8,9.6,21.48],[9,9.4,46.37]],"id":45323444}]}]}
{"op":"mcm","clk":"AMkvAMIYAMoo","pt":1659347489012,"mc":[{"id":"1.201590187","rc":[{"atb":[[11,4.1]],"id":45323444},{"atb":[[23,1]],"id":44621159}]}]}
{"op":"mcm","clk":"ANEvAMgYAM4o","pt":1659347489063,"mc":[{"id":"1.201590187","rc":[{"bdatb":[[4,11,4.1]],"id":45323444},{"bdatl":[[7,2.4,82.77],[8,2.42,10.56],[9,2.44,152.52]],"id":9570503},{"bdatb":[[0,23,1.49]],"id":44621159}]}]}
{"op":"mcm","clk":"AN0vAM0YANwo","pt":1659347489215,"mc":[{"id":"1.201590187","rc":[{"atb":[[24,2.91]],"atl":[[38,1.15]],"id":44621159}]}]}
{"op":"mcm","clk":"AN0vANAYANwo","pt":1659347489265,"mc":[{"id":"1.201590187","rc":[{"bdatb":[[9,1.88,12.83]],"bdatl":[[7,2.4,93.85],[8,2.44,156.38],[9,2.46,1.23]],"id":9570503},{"bdatb":[[6,5.2,4.63],[7,5.1,3.53],[8,5,8.37]],"id":12989514},{"bdatb":[[0,24,2.91],[1,23,1],[2,21,5],[3,20,1.8],[4,19.5,4.19],[5,18.5,1.37],[6,15.5,5.23],[7,12,1.51],[8,11,2.19],[9,10.5,1.71]],"bdatl":[[1,38,1.15],[2,40,3.27],[3,95,2.64],[4,120,7.2],[5,170,2],[6,990,2.07]],"id":44621159},{"bdatb":[[9,10.5,2.29]],"id":46969227}]}]}
{"op":"mcm","clk":"AJowAPIYAI8p","pt":1659347489913,"mc":[{"id":"1.201590187","rc":[{"atb":[[11,1.23]],"id":45323444},{"atb":[[24,0.49]],"id":44621159}]}]}
{"op":"mcm","clk":"AJ8wAPIYAJEp","pt":1659347489964,"mc":[{"id":"1.201590187","rc":[{"bdatb":[[4,11,1.23]],"id":45323444},{"bdatl":[[7,2.4,82.77],[8,2.42,10.56],[9,2.44,152.52]],"id":9570503},{"bdatb":[[0,23,1.49],[1,21,5],[2,20,1.8],[3,19.5,4.19],[4,18.5,1.37],[5,15.5,5.23],[6,12,1.51],[7,11,2.19],[8,10.5,1.71],[9,10,106.19]],"id":44621159}]}]}
{"op":"mcm","clk":"AKAwAPUYAJcp","pt":1659347490014,"mc":[{"id":"1.201590187","rc":[{"atb":[[10.5,4.47]],"id":45323444}]}]}
{"op":"mcm","clk":"AKcwAPgYAJgp","pt":1659347490065,"mc":[{"id":"1.201590187","rc":[{"bdatb":[[5,10.5,4.47]],"id":45323444}]}]}
{"op":"mcm","clk":"AKwwAPwYAJ0p","pt":1659347490137,"mc":[{"id":"1.201590187","rc":[{"atb":[[22,2.59]],"id":44621159}]}]}
{"op":"mcm","clk":"ALQwAP0YAKYp","pt":1659347490187,"mc":[{"id":"1.201590187","rc":[{"bdatl":[[8,2.42,10.99],[9,2.44,152.34]],"id":9570503},{"bdatb":[[1,22,2.59],[2,21,5],[3,20,1.8],[4,19.5,4.19],[5,18.5,1.37],[6,15.5,5.23],[7,12,1.51],[8,11,2.19],[9,10.5,1.71]],"id":44621159}]}]}
{"op":"mcm","clk":"AMkwAIcZALcp","pt":1659347490444,"mc":[{"id":"1.201590187","rc":[{"atl":[[2.12,25.99]],"id":9570503}]}]}
{"op":"mcm","clk":"AMowAIkZAL8p","pt":1659347490494,"mc":[{"id":"1.201590187","rc":[{"bdatb":[[6,10,12.79],[7,9.8,9.86],[8,9.6,21],[9,9.4,47.47]],"id":45323444},{"bdatl":[[0,2.12,25.99]],"id":9570503},{"bdatb":[[4,5.7,2.08],[5,5.6,1.26],[6,5.3,3.79],[7,5.1,4.31],[9,4.9,10.43]],"id":12989514},{"bdatb":[[7,13,1.45],[8,11.5,1.74],[9,10.5,2.08]],"id":44621159},{"bdatb":[[9,5.4,16.88]],"id":44836671},{"bdatb":[[7,6.4,4.79],[8,6.2,10.22],[9,6,17.19]],"id":43885158},{"bdatb":[[8,12,1.54],[9,11,1.83]],"id":46969227}]}]}
{"op":"mcm","clk":"APwwAKIZAOYp","pt":1659347491020,"mc":[{"id":"1.201590187","rc":[{"atb":[[14.5,1]],"id":45323444},{"atb":[[23,2]],"id":44621159}]}]}
{"op":"mcm","clk":"AP0wAKMZAOop","pt":1659347491071,"mc":[{"id":"1.201590187","rc":[{"bdatb":[[0,14.5,1],[1,14,4.39],[2,13.5,1],[3,12.5,1.14],[4,11.5,7.04],[5,11,1.23],[6,10.5,4.47],[7,10,12.79],[8,9.8,9.86],[9,9.6,21]],"id":45323444},{"bdatl":[[6,2.38,36.42],[7,2.4,89.5],[8,2.42,1.74],[9,2.44,156.13]],"id":9570503},{"bdatb":[[0,23,2.49]],"id":44621159},{"bdatl":[[8,11.5,1.1],[9,12,2.23]],"id":44836671},{"bdatl":[[8,14.5,1.53],[9,15,12]],"id":43885158}]}]}
{"op":"mcm","clk":"AIUxAKcZAO0p","pt":1659347491124,"mc":[{"id":"1.201590187","rc":[{"atb":[[13.5,0]],"atl":[[19,0],[18.5,1]],"id":45323444},{"atb":[[23,1]],"id":44621159}]}]}
{"op":"mcm","clk":"AIoxAKgZAPMp","pt":1659347491174,"mc":[{"id":"1.201590187","rc":[{"bdatb":[[2,12.5,1.14],[3,11.5,7.04],[4,11,1.23],[5,10.5,4.47],[6,10,12.79],[7,9.8,9.86],[8,9.6,21],[9,9.4,47.47]],"bdatl":[[1,18.5,1]],"id":45323444},{"bdatb":[[6,1.93,6.17],[7,1.92,3.43],[8,1.91,107.36]],"bdatl":[[7,2.4,79.92],[8,2.42,11.24]],"id":9570503},{"bdatb":[[5,5.6,1.18],[6,5.3,3.88],[7,5.1,4.21],[9,4.9,10.53]],"id":12989514},{"bdatb":[[0,23,1.49],[7,13,1.39],[8,11.5,1.78],[9,10.5,2.03]],"id":44621159},{"bdatb":[[8,5.5,24.96],[9,5.4,15.22]],"id":44836671},{"bdatb":[[6,6.6,48],[7,6.4,4.35],[8,6.2,10.3]],"id":43885158},{"bdatb":[[8,12.5,1.45],[9,11,1.87]],"id":46969227}]}]}
{"op":"mcm","clk":"AJcxAKwZAPwp","pt":1659347491311,"mc":[{"id":"1.201590187","rc":[{"atl":[[7.8,15.94]],"id":12989514},{"atb":[[22,0]],"id":44621159}]}]}
{"op":"mcm","clk":"AJcxAK8ZAP4p","pt":1659347491361,"mc":[{"id":"1.201590187","rc":[{"bdatl":[[8,2.42,10.56],[9,2.44,152.77]],"id":9570503},{"bdatl":[[0,7.8,15.94]],"id":12989514},{"bdatb":[[1,21,5],[2,20,1.8],[3,19.5,4.19],[4,18.5,1.37],[5,15.5,5.23],[6,13,1.39],[7,11.5,1.78],[8,10.5,2.03],[9,10,106.77]],"id":44621159}]}]}
{"op":"mcm","clk":"AKExALAZAIQq","pt":1659347491417,"mc":[{"id":"1.201590187","rc":[{"atl":[[9.4,0]],"id":12989514},{"atb":[[23,3.47]],"id":44621159}]}]}
{"op":"mcm","clk":"AKQxALIZAIQq","pt":1659347491468,"mc":[{"id":"1.201590187","rc":[{"bdatl":[[7,2.4,90.56],[8,2.44,156.81],[9,2.46,1.5]],"id":9570503},{"bdatl":[[6,9.6,11.09],[7,10,17.36],[8,10.5,12.47],[9,11,33.84]],"id":12989514},{"bdatb":[[0,23,3.96]],"id":44621159}]}]}
{"op":"mcm","clk":"AKkxALIZAIkq","pt":1659347491518,"mc":[{"id":"1.201590187","rc":[{"atl":[[24,0]],"id":45323444},{"atl":[[7.6,7]],"id":12989514},{"atl":[[7.6,158]],"id":44836671}]}]}
{"op":"mcm","clk":"AK0xALUZAIkq","pt":1659347491569,"mc":[{"id":"1.201590187","rc":[{"bdatb":[[5,10.5,6.33],[6,10,11.69],[7,9.8,10.72],[9,9.4,45.68]],"bdatl":[[4,25,5.61]],"id":45323444},{"bdatb":[[2,1.99,31.35],[3,1.98,42.05],[5,1.96,3.19],[6,1.95,1.2],[7,1.94,4.36],[8,1.93,3.41],[9,1.91,108.32]],"id":9570503},{"bdatl":[[0,7.6,7],[1,7.8,15.94],[2,8,7.32],[3,8.2,6.31],[4,8.4,2.06],[5,9,2.47],[6,9.2,4.82],[7,9.6,11.09],[8,10,17.36],[9,10.5,12.47]],"id":12989514},{"bdatb":[[5,15.5,5.16],[6,13.5,1.34],[7,12,1.56],[8,10.5,2.2],[9,10,111.35]],"id":44621159},{"bdatb":[[3,6,67.27],[4,5.9,9],[6,5.7,44.74],[7,5.6,13.93],[8,5.5,24.2],[9,5.4,14]],"bdatl":[[1,7.6,158]],"id":44836671},{"bdatb":[[4,7.2,5.93],[5,7,5],[6,6.6,50.27],[7,6.4,2.29],[8,6.2,12.72],[9,6,14.38]],"id":43885158},{"bdatb":[[7,15.5,1.03],[8,13,1.39],[9,11.5,1.62]],"id":46969227}]}]}
{"op":"mcm","clk":"ALQxALYZAJEq","pt":1659347491619,"mc":[{"id":"1.201590187","rc":[{"atl":[[1000,0.48]],"id":45323444},{"atl":[[7.6,7.33],[8.6,0]],"id":12989514}]}]}
{"op":"mcm","clk":"ALgxALgZAJEq","pt":1659347491670,"mc":[{"id":"1.201590187","rc":[{"bdatb":[[7,9.8,10.91],[9,9.4,45.52]],"id":45323444},{"bdatl":[[0,7.6,7.33],[5,9,2.17]],"id":12989514},{"bdatb":[[7,12,1.71],[8,10.5,2.03]],"id":44621159},{"bdatb":[[8,6.2,13.03],[9,6,14.1]],"id":43885158},{"bdatb":[[9,11.5,1.78]],"id":46969227}]}]}
{"op":"mcm","clk":"AO8xAM8ZALwq","pt":1659347492226,"mc":[{"id":"1.201590187","rc":[{"atb":[[23,1]],"id":44621159}]}]}
{"op":"mcm","clk":"APUxAM8ZAL8q","pt":1659347492276,"mc":[{"id":"1.201590187","rc":[{"bdatl":[[7,2.4,79.92],[8,2.42,10.56],[9,2.44,152.77]],"id":9570503},{"bdatb":[[0,23,1.49]],"id":44621159}]}]}
{"op":"mcm","clk":"APkxANEZAMQq","pt":1659347492333,"mc":[{"id":"1.201590187","rc":[{"atl":[[29,5]],"id":46969227}]}]}
{"op":"mcm","clk":"AP4xANQZAM8q","pt":1659347492383,"mc":[{"id":"1.201590187","rc":[{"bdatb":[[5,10.5,7.94],[6,10,11.88],[7,9.8,9],[8,9.6,21.04],[9,9.4,45.5]],"id":45323444},{"bdatb":[[5,1.96,4.38],[6,1.95,7.71],[7,1.91,118.33],[8,1.89,1.68],[9,1.88,21.54]],"id":9570503},{"bdatb":[[3,6.2,2.58],[4,5.8,2.05],[5,5.7,1.15],[6,5.4,3.8],[7,5.2,4.13],[8,5.1,8.21],[9,5,8.73]],"id":12989514},{"bdatb":[[5,15.5,5.13],[6,14.5,1.28],[7,12.5,1.64],[8,11,5.74],[9,10.5,2.53]],"id":44621159},{"bdatb":[[5,5.8,31.43],[6,5.7,46.03],[7,5.6,13.18],[8,5.5,23],[9,5.4,17.81]],"id":44836671},{"bdatb":[[6,6.8,2.72],[7,6.6,47.48],[8,6.4,5.22],[9,6.2,10.1]],"id":43885158},{"bdatl":[[0,29,5],[1,32,2.29],[2,34,5.6],[3,38,2.51],[4,40,5.01],[5,80,1.66],[6,310,1],[7,990,2.15]],"id":46969227}]}]}
{"op":"mcm","clk":"AIIyANgZANAq","pt":1659347492433,"mc":[{"id":"1.201590187","rc":[{"atb":[[24,2.91]],"id":44621159}]}]}
{"op":"mcm","clk":"AIkyANkZANYq","pt":1659347492483,"mc":[{"id":"1.201590187","rc":[{"bdatl":[[7,2.4,91.25],[8,2.42,3.19],[9,2.44,152.97]],"id":9570503},{"bdatb":[[0,24,2.91],[1,23,1],[2,21,5],[3,20,1.8],[4,19.5,4.19],[5,18.5,1.37],[6,15.5,5.13],[7,14.5,1.28],[8,12.5,1.64],[9,11,5.74]],"id":44621159},{"bdatl":[[8,11.5,1.32],[9,12,2.02]],"id":44836671}]}]}
{"op":"mcm","clk":"AIwyANoZANcq","pt":1659347492533,"mc":[{"id":"1.201590187","rc":[{"atl":[[30,0.48]],"id":46969227}]}]}
{"op":"mcm","clk":"AJAyAN8ZAOAq","pt":1659347492584,"mc":[{"id":"1.201590187","rc":[{"bdatb":[[9,5,8.19]],"id":12989514},{"bdatl":[[1,32,2.2]],"id":46969227}]}]}
{"op":"mcm","clk":"AJoyAOAZAOIq","pt":1659347492634,"mc":[{"id":"1.201590187","rc":[{"atb":[[14,2.7]],"id":45323444}]}]}
{"op":"mcm","clk":"AJwyAOIZAOUq","pt":1659347492684,"mc":[{"id":"1.201590187","rc":[{"bdatb":[[1,14,2.7]],"id":45323444},{"bdatl":[[7,2.4,87.18],[8,2.44,155.42],[9,2.48,2.48]],"id":9570503}]}]}
{"op":"mcm","clk":"AMEyAPEZAIYr","pt":1659347492998,"mc":[{"id":"1.201590187","rc":[{"atb":[[23,1]],"id":46969227}]}]}
{"op":"mcm","clk":"AMwyAPQZAI0r","pt":1659347493068,"mc":[{"id":"1.201590187","rc":[{"bdatl":[[8,2.44,152.09],[9,2.46,3.97]],"id":9570503},{"bdatb":[[0,23,1]],"id":46969227}]}]}
{"op":"mcm","clk":"AM4yAPcZAI8r","pt":1659347493118,"mc":[{"id":"1.201590187","rc":[{"atb":[[1.02,1.63]],"id":46969227}]}]}
