{"op":"mcm","clk":"ANQyAPkZAJMr","pt":1659347493215,"mc":[{"id":"1.201590187","rc":[{"atb":[[11.5,5.54]],"id":45323444},{"atb":[[24,0.49]],"id":44621159}]}]}
{"op":"mcm","clk":"ANoyAP0ZAJcr","pt":1659347493265,"mc":[{"id":"1.201590187","rc":[{"bdatb":[[3,11.5,5.54]],"id":45323444},{"bdatl":[[7,2.4,74.97],[8,2.42,4.91],[9,2.44,159.23]],"id":9570503},{"bdatb":[[0,23,1.49],[1,21,5],[2,20,1.8],[3,19.5,4.19],[4,18.5,1.37],[5,15.5,5.13],[6,14.5,1.28],[7,12.5,1.64],[8,11,5.74],[9,10.5,2.53]],"id":44621159},{"bdatl":[[8,11.5,1.1],[9,12,2.23]],"id":44836671}]}]}
{"op":"mcm","clk":"ANwyAP4ZAJsr","pt":1659347493315,"mc":[{"id":"1.201590187","rc":[{"atb":[[1.05,1.5]],"id":45323444}]}]}
{"op":"mcm","clk":"AOgyAIMaAKAr","pt":1659347493425,"mc":[{"id":"1.201590187","rc":[{"atb":[[14.5,4.96]],"id":45323444}]}]}
{"op":"mcm","clk":"AO4yAIMaAKMr","pt":1659347493475,"mc":[{"id":"1.201590187","rc":[{"bdatb":[[0,14.5,4.96]],"id":45323444},{"bdatl":[[6,2.38,39.99],[7,2.4,76.38],[8,2.42,11.24],[9,2.44,156.13]],"id":9570503}]}]}
{"op":"mcm","clk":"APoyAIgaAKor","pt":1659347493621,"mc":[{"id":"1.201590187","rc":[{"atb":[[22,2.59]],"id":44621159}]}]}
{"op":"mcm","clk":"AP8yAIwaAKwr","pt":1659347493671,"mc":[{"id":"1.201590187","rc":[{"bdatl":[[8,2.42,15.32],[9,2.44,152.11]],"id":9570503},{"bdatb":[[1,22,2.59],[2,21,5],[3,20,1.8],[4,19.5,4.19],[5,18.5,1.37],[6,15.5,5.13],[7,14.5,1.28],[8,12.5,1.64],[9,11,5.74]],"id":44621159}]}]}
{"op":"mcm","clk":"AMIzAKUaAOwr","pt":1659347494415,"mc":[{"id":"1.201590187","rc":[{"atb":[[14.5,1]],"id":45323444},{"atb":[[22,0]],"id":44621159}]}]}
{"op":"mcm","clk":"AMQzAKUaAO0r","pt":1659347494465,"mc":[{"id":"1.201590187","rc":[{"bdatb":[[0,14.5,1]],"id":45323444},{"bdatl":[[6,2.38,36.42],[7,2.4,74.97],[8,2.42,4.91],[9,2.44,159.23]],"id":9570503},{"bdatb":[[1,21,5],[2,20,1.8],[3,19.5,4.19],[4,18.5,1.37],[5,15.5,5.13],[6,14.5,1.28],[7,12.5,1.64],[8,11,5.74],[9,10.5,2.53]],"id":44621159}]}]}
{"op":"mcm","clk":"AMozAKcaAPAr","pt":1659347494520,"mc":[{"id":"1.201590187","rc":[{"atb":[[23,0]],"atl":[[32,0.72]],"id":46969227}]}]}
{"op":"mcm","clk":"AM0zAKcaAPIr","pt":1659347494570,"mc":[{"id":"1.201590187","rc":[{"bdatl":[[6,2.38,35.31],[7,2.4,72.52],[8,2.42,8.42]],"id":9570503},{"bdatl":[[8,12,2.68],[9,13,42.48]],"id":44836671},{"bdatl":[[8,14.5,1],[9,15,12.51]],"id":43885158},{"bdatb":[[0,22,4.4],[1,21,8.6],[2,20,5.51],[3,19.5,7],[4,19,5],[5,16,1.43],[6,15.5,1.03],[7,13,1.39],[8,11.5,1.78],[9,10,6.38]],"bdatl":[[1,32,1.2]],"id":46969227}]}]}
{"op":"mcm","clk":"ANQzAKkaAPkr","pt":1659347494620,"mc":[{"id":"1.201590187","rc":[{"atb":[[13,4.42]],"id":45323444}]}]}
{"op":"mcm","clk":"ANUzAKkaAPkr","pt":1659347494670,"mc":[{"id":"1.201590187","rc":[{"bdatb":[[2,13,4.42],[3,12.5,1.14],[4,11.5,5.54],[5,11,1.23],[6,10.5,7.94],[7,10,11.88],[8,9.8,9],[9,9.6,21.04]],"id":45323444}]}]}
{"op":"mcm","clk":"ANszAKsaAP0r","pt":1659347494720,"mc":[{"id":"1.201590187","rc":[{"atb":[[21,1.6],[18.5,4]],"bdatb":[[1,21,1.6],[5,18.5,4],[6,16,1.43],[7,15.5,1.03],[8,13,1.39],[9,11.5,1.78]],"id":46969227}]}]}
{"op":"mcm","clk":"AOMzALAaAIMs","pt":1659347494834,"mc":[{"id":"1.201590187","rc":[{"atb":[[23,3.47]],"id":44621159}]}]}
{"op":"mcm","clk":"AOYzALQaAIos","pt":1659347494884,"mc":[{"id":"1.201590187","rc":[{"bdatl":[[8,2.42,15.62],[9,2.44,156.1]],"id":9570503},{"bdatb":[[0,23,3.96]],"id":44621159}]}]}
{"op":"mcm","clk":"AOwzALYaAI0s","pt":1659347494935,"mc":[{"id":"1.201590187","rc":[{"atl":[[7.8,11.52]],"id":12989514},{"atl":[[38,0]],"id":44621159}]}]}
{"op":"mcm","clk":"APEzALYaAI0s","pt":1659347494985,"mc":[{"id":"1.201590187","rc":[{"bdatb":[[9,1.88,9.57]],"id":9570503},{"bdatb":[[7,5.2,4.14]],"bdatl":[[1,7.8,11.52]],"id":12989514},{"bdatl":[[1,40,3.27],[2,95,2.64],[3,120,7.2],[4,170,2],[5,990,2.07],[6,0,0]],"id":44621159},{"bdatb":[[9,6.2,10.06]],"id":43885158}]}]}
{"op":"mcm","clk":"APczALkaAJcs","pt":1659347495115,"mc":[{"id":"1.201590187","rc":[{"atl":[[38,0.59],[34,0]],"id":44621159}]}]}
{"op":"mcm","clk":"AP8zAL0aAKAs","pt":1659347495166,"mc":[{"id":"1.201590187","rc":[{"bdatb":[[6,10.5,7.9],[7,10,10.03],[8,9.8,10.91],[9,9.6,21]],"id":45323444},{"bdatb":[[5,1.96,2.62],[6,1.95,9.49],[7,1.91,108.32],[8,1.9,10.2],[9,1.89,1.55]],"id":9570503},{"bdatb":[[3,6,2.67],[7,5.2,4.13]],"id":12989514},{"bdatl":[[0,36,1],[1,40,3.86]],"id":44621159},{"bdatb":[[5,5.8,30.83],[6,5.7,46.64]],"id":44836671},{"bdatb":[[8,6.4,2.29],[9,6.2,13.12]],"id":43885158},{"bdatb":[[7,15,1.07],[9,11,1.87]],"id":46969227}]}]}
{"op":"mcm","clk":"AI40AMUaALEs","pt":1659347495423,"mc":[{"id":"1.201590187","rc":[{"atl":[[7.4,0.35]],"id":44836671},{"atl":[[30,0.07]],"id":46969227}]}]}
{"op":"mcm","clk":"AJU0AMcaALUs","pt":1659347495473,"mc":[{"id":"1.201590187","rc":[{"bdatb":[[6,10.5,4.72],[7,10,13.34],[8,9.8,10.95]],"id":45323444},{"bdatb":[[2,1.99,24.61],[4,1.97,8.07],[6,1.94,6.14],[7,1.93,3.41],[8,1.91,108.15],[9,1.9,10.37]],"id":9570503},{"bdatb":[[4,5.7,2.09],[5,5.6,1.18],[6,5.4,3.81],[9,5,5.72]],"id":12989514},{"bdatb":[[5,15.5,5.18],[6,13.5,1.34],[7,12.5,1.65]],"id":44621159},{"bdatl":[[0,7.6,158.35],[1,7.8,8],[2,8,7.32],[3,8.2,5.31],[4,8.4,3],[5,9.2,8],[6,9.8,33.55],[7,12,2.68],[8,13,42.48],[9,13.5,1.55]],"id":44836671},{"bdatb":[[4,7.2,4.07],[5,7,6.92],[6,6.6,50.28],[7,6.4,2.23],[8,6.2,13.18],[9,6,14.49]],"id":43885158},{"bdatb":[[7,14.5,1.09],[8,12.5,1.48]],"bdatl":[[1,34,6.39],[2,38,2.51],[3,40,5.01],[4,80,1.66],[5,310,1],[6,990,2.15],[7,0,0]],"id":46969227}]}]}
{"op":"mcm","clk":"AJc0AMgaALgs","pt":1659347495525,"mc":[{"id":"1.201590187","rc":[{"atb":[[13,0]],"id":45323444},{"atb":[[23,1]],"id":44621159}]}]}
{"op":"mcm","clk":"AJo0AMoaALgs","pt":1659347495575,"mc":[{"id":"1.201590187","rc":[{"bdatb":[[2,12.5,1.14],[3,11.5,5.54],[4,11,1.23],[5,10.5,4.72],[6,10,13.34],[7,9.8,10.95],[8,9.6,21],[9,9.4,45.54]],"id":45323444},{"bdatl":[[8,2.42,8.42],[9,2.44,159.23]],"id":9570503},{"bdatb":[[0,23,1.49]],"id":44621159}]}]}
{"op":"mcm","clk":"AKg0AM0aAMUs","pt":1659347495692,"mc":[{"id":"1.201590187","rc":[{"atb":[[14.5,4.96]],"id":45323444}]}]}
{"op":"mcm","clk":"AKs0AM8aAM0s","pt":1659347495742,"mc":[{"id":"1.201590187","rc":[{"bdatb":[[0,14.5,4.96]],"id":45323444},{"bdatl":[[7,2.4,81.01],[8,2.42,11.24],[9,2.44,156.13]],"id":9570503},{"bdatl":[[7,12,3.28],[8,13,41.9]],"id":44836671}]}]}
{"op":"mcm","clk":"ALk0ANQaAN0s","pt":1659347495895,"mc":[{"id":"1.201590187","rc":[{"atb":[[3.7,65.72]],"id":12989514},{"atb":[[24,2.91]],"id":44621159}]}]}
{"op":"mcm","clk":"ALs0ANUaAN4s","pt":1659347495945,"mc":[{"id":"1.201590187","rc":[{"bdatl":[[6,2.38,56.41],[7,2.4,74.65],[8,2.44,153],[9,2.46,1.48]],"id":9570503},{"bdatb":[[0,24,2.91],[1,23,1],[2,21,5],[3,20,1.8],[4,19.5,4.19],[5,18.5,1.37],[6,15.5,5.18],[7,13.5,1.34],[8,12.5,1.65],[9,11,5.74]],"id":44621159}]}]}
{"op":"mcm","clk":"AMY0ANgaAOws","pt":1659347496105,"mc":[{"id":"1.201590187","rc":[{"atb":[[1.77,85.26]],"id":9570503},{"atb":[[6,81.85]],"id":44836671},{"atb":[[6.6,64.72]],"id":43885158}]}]}
{"op":"mcm","clk":"AMk0ANsaAO0s","pt":1659347496155,"mc":[{"id":"1.201590187","rc":[{"bdatb":[[3,6,84.51]],"id":44836671},{"bdatb":[[6,6.6,67.52]],"id":43885158}]}]}
{"op":"mcm","clk":"AOY0AOQaAIgt","pt":1659347496617,"mc":[{"id":"1.201590187","rc":[{"atb":[[14.5,1]],"id":45323444},{"atb":[[24,0.49]],"id":44621159}]}]}
{"op":"mcm","clk":"AOk0AOYaAIwt","pt":1659347496668,"mc":[{"id":"1.201590187","rc":[{"bdatb":[[0,14.5,1]],"id":45323444},{"bdatl":[[6,2.38,35.31],[7,2.4,72.52],[8,2.42,8.42],[9,2.44,159.23]],"id":9570503},{"bdatb":[[0,23,1.49],[1,21,5],[2,20,1.8],[3,19.5,4.19],[4,18.5,1.37],[5,15.5,5.18],[6,13.5,1.34],[7,12.5,1.65],[8,11,5.74],[9,10.5,2.53]],"id":44621159},{"bdatl":[[7,12,2.68],[8,13,42.48]],"id":44836671}]}]}
{"op":"mcm","clk":"AO00AOkaAJIt","pt":1659347496728,"mc":[{"id":"1.201590187","rc":[{"atb":[[13,4.42]],"id":45323444}]}]}
{"op":"mcm","clk":"AO80AOkaAJIt","pt":1659347496778,"mc":[{"id":"1.201590187","rc":[{"bdatb":[[2,13,4.42],[3,12.5,1.14],[4,11.5,5.54],[5,11,1.23],[6,10.5,4.72],[7,10,13.34],[8,9.8,10.95],[9,9.6,21]],"id":45323444}]}]}
{"op":"mcm","clk":"APY0APAaAJst","pt":1659347496890,"mc":[{"id":"1.201590187","rc":[{"atb":[[22,2.59]],"id":44621159}]}]}
{"op":"mcm","clk":"APg0APIaAJ4t","pt":1659347496940,"mc":[{"id":"1.201590187","rc":[{"bdatl":[[8,2.42,15.62],[9,2.44,152.09]],"id":9570503},{"bdatb":[[1,22,2.59],[2,21,5],[3,20,1.8],[4,19.5,4.19],[5,18.5,1.37],[6,15.5,5.18],[7,13.5,1.34],[8,12.5,1.65],[9,11,5.74]],"id":44621159}]}]}
{"op":"mcm","clk":"AJs1AIcbAMst","pt":1659347497627,"mc":[{"id":"1.201590187","rc":[{"atb":[[13,0]],"id":45323444},{"atb":[[22,0]],"id":44621159}]}]}
{"op":"mcm","clk":"AJw1AIcbAMwt","pt":1659347497677,"mc":[{"id":"1.201590187","rc":[{"bdatb":[[2,12.5,1.14],[3,11.5,5.54],[4,11,1.23],[5,10.5,4.72],[6,10,13.34],[7,9.8,10.95],[8,9.6,21],[9,9.4,45.54]],"id":45323444},{"bdatl":[[8,2.42,8.42],[9,2.44,159.23]],"id":9570503},{"bdatb":[[1,21,5],[2,20,1.8],[3,19.5,4.19],[4,18.5,1.37],[5,15.5,5.18],[6,13.5,1.34],[7,12.5,1.65],[8,11,5.74],[9,10.5,2.53]],"id":44621159}]}]}
{"op":"mcm","clk":"AKI1AIkbANMt","pt":1659347497727,"mc":[{"id":"1.201590187","rc":[{"atb":[[14.5,4.96]],"id":45323444}]}]}
{"op":"mcm","clk":"AKc1AIkbANMt","pt":1659347497777,"mc":[{"id":"1.201590187","rc":[{"bdatb":[[0,14.5,4.96]],"id":45323444},{"bdatl":[[7,2.4,81.01],[8,2.42,11.24],[9,2.44,156.13]],"id":9570503},{"bdatl":[[7,12,3.28],[8,13,41.9]],"id":44836671}]}]}
{"op":"mcm","clk":"AKw1AIsbANgt","pt":1659347497827,"mc":[{"id":"1.201590187","rc":[{"atb":[[23,3.47]],"id":44621159}]}]}
{"op":"mcm","clk":"AK01AIsbANgt","pt":1659347497878,"mc":[{"id":"1.201590187","rc":[{"bdatl":[[7,2.4,92.35],[8,2.42,4.08],[9,2.44,152.11]],"id":9570503},{"bdatb":[[0,23,3.96]],"id":44621159}]}]}
{"op":"mcm","clk":"AL81AJUbAPAt","pt":1659347498205,"mc":[{"id":"1.201590187","rc":[{"atl":[[1000,2]],"id":44621159}]}]}
{"op":"mcm","clk":"AMI1AJYbAPQt","pt":1659347498256,"mc":[{"id":"1.201590187","rc":[{"bdatl":[[6,1000,2]],"id":44621159}]}]}
{"op":"mcm","clk":"ANI1AJ4bAP8t","pt":1659347498514,"mc":[{"id":"1.201590187","rc":[{"atb":[[14.5,1]],"id":45323444},{"atb":[[23,1]],"id":44621159}]}]}
{"op":"mcm","clk":"ANM1AJ8bAIIu","pt":1659347498564,"mc":[{"id":"1.201590187","rc":[{"bdatb":[[0,14.5,1]],"id":45323444},{"bdatl":[[7,2.4,72.52],[8,2.42,8.42],[9,2.44,159.23]],"id":9570503},{"bdatb":[[0,23,1.49]],"id":44621159},{"bdatl":[[7,12,2.68],[8,13,42.48]],"id":44836671}]}]}
{"op":"mcm","clk":"ANs1AKcbAIgu","pt":1659347498729,"mc":[{"id":"1.201590187","rc":[{"atb":[[13,4.42]],"id":45323444}]}]}
{"op":"mcm","clk":"AN41AKgbAIsu","pt":1659347498779,"mc":[{"id":"1.201590187","rc":[{"bdatb":[[2,13,4.42],[3,12.5,1.14],[4,11.5,5.54],[5,11,1.23],[6,10.5,4.72],[7,10,13.34],[8,9.8,10.95],[9,9.6,21]],"id":45323444}]}]}
{"op":"mcm","clk":"AOY1AKsbAJEu","pt":1659347498925,"mc":[{"id":"1.201590187","rc":[{"atb":[[24,2.91]],"id":44621159}]}]}
{"op":"mcm","clk":"AOw1AKwbAJYu","pt":1659347498975,"mc":[{"id":"1.201590187","rc":[{"bdatl":[[6,2.38,36.42],[7,2.4,87.18],[8,2.44,156.1],[9,2.46,4.01]],"id":9570503},{"bdatb":[[0,24,2.91],[1,23,1],[2,21,5],[3,20,1.8],[4,19.5,4.19],[5,18.5,1.37],[6,15.5,5.18],[7,13.5,1.34],[8,12.5,1.65],[9,11,5.74]],"id":44621159},{"bdatl":[[7,12,3.28],[8,13,41.9]],"id":44836671}]}]}
{"op":"mcm","clk":"AIE2ALIbAKUu","pt":1659347499197,"mc":[{"id":"1.201590187","rc":[{"atb":[[5.7,65.83]],"id":44836671}]}]}
{"op":"mcm","clk":"AII2ALUbAKku","pt":1659347499247,"mc":[{"id":"1.201590187","rc":[{"bdatb":[[6,5.7,67.92]],"id":44836671}]}]}
{"op":"mcm","clk":"AIU2ALUbAK0u","pt":1659347499297,"mc":[{"id":"1.201590187","rc":[{"atb":[[5.8,10]],"id":44836671}]}]}
{"op":"mcm","clk":"AIc2ALYbAK0u","pt":1659347499347,"mc":[{"id":"1.201590187","rc":[{"bdatb":[[5,5.8,10]],"id":44836671}]}]}
{"op":"mcm","clk":"AJQ2ALkbALku","pt":1659347499609,"mc":[{"id":"1.201590187","rc":[{"atb":[[13,0]],"id":45323444},{"atb":[[24,0.49]],"id":44621159}]}]}
{"op":"mcm","clk":"AJU2ALobALwu","pt":1659347499660,"mc":[{"id":"1.201590187","rc":[{"bdatb":[[2,12.5,1.14],[3,11.5,5.54],[4,11,1.23],[5,10.5,4.72],[6,10,13.34],[7,9.8,10.95],[8,9.6,21],[9,9.4,45.54]],"id":45323444},{"bdatl":[[6,2.38,35.31],[7,2.4,72.52],[8,2.42,8.42],[9,2.44,159.23]],"id":9570503},{"bdatb":[[0,23,1.49],[1,21,5],[2,20,1.8],[3,19.5,4.19],[4,18.5,1.37],[5,15.5,5.18],[6,13.5,1.34],[7,12.5,1.65],[8,11,5.74],[9,10.5,2.53]],"id":44621159},{"bdatl":[[7,12,2.68],[8,13,42.48]],"id":44836671}]}]}
{"op":"mcm","clk":"AJ02ALwbAMEu","pt":1659347499809,"mc":[{"id":"1.201590187","rc":[{"atb":[[14.5,4.96]],"id":45323444}]}]}
{"op":"mcm","clk":"AJ42ALwbAMMu","pt":1659347499859,"mc":[{"id":"1.201590187","rc":[{"bdatb":[[0,14.5,4.96]],"id":45323444},{"bdatl":[[7,2.4,81.01],[8,2.42,11.24],[9,2.44,156.13]],"id":9570503},{"bdatl":[[7,12,3.28],[8,13,41.9]],"id":44836671}]}]}
{"op":"mcm","clk":"AKg2AL8bAMwu","pt":1659347500023,"mc":[{"id":"1.201590187","rc":[{"atb":[[22,2.59]],"id":44621159}]}]}
{"op":"mcm","clk":"AK02AMEbANEu","pt":1659347500073,"mc":[{"id":"1.201590187","rc":[{"bdatl":[[8,2.42,15.32],[9,2.44,152.11]],"id":9570503},{"bdatb":[[1,22,2.59],[2,21,5],[3,20,1.8],[4,19.5,4.19],[5,18.5,1.37],[6,15.5,5.18],[7,13.5,1.34],[8,12.5,1.65],[9,11,5.74]],"id":44621159}]}]}
{"op":"mcm","clk":"ANQ2AM0bAO8u","pt":1659347500602,"mc":[{"id":"1.201590187","rc":[{"atl":[[38,1.74]],"id":44621159}]}]}
{"op":"mcm","clk":"ANU2AM4bAPAu","pt":1659347500652,"mc":[{"id":"1.201590187","rc":[{"bdatl":[[1,38,1.74],[2,40,3.27],[3,95,2.64],[4,120,7.2],[5,170,2],[6,990,2.07],[7,1000,2]],"id":44621159}]}]}
{"op":"mcm","clk":"ANw2ANEbAPYu","pt":1659347500796,"mc":[{"id":"1.201590187","rc":[{"atb":[[14.5,1]],"id":45323444},{"atb":[[22,0]],"id":44621159}]}]}
{"op":"mcm","clk":"AOA2ANEbAPcu","pt":1659347500847,"mc":[{"id":"1.201590187","rc":[{"bdatb":[[0,14.5,1]],"id":45323444},{"bdatl":[[7,2.4,72.52],[8,2.42,8.42],[9,2.44,159.23]],"id":9570503},{"bdatb":[[1,21,5],[2,20,1.8],[3,19.5,4.19],[4,18.5,1.37],[5,15.5,5.18],[6,13.5,1.34],[7,12.5,1.65],[8,11,5.74],[9,10.5,2.53]],"id":44621159},{"bdatl":[[7,12,2.68],[8,13,42.48]],"id":44836671}]}]}
{"op":"mcm","clk":"AOc2ANMbAPwu","pt":1659347500921,"mc":[{"id":"1.201590187","rc":[{"atl":[[28,0.64],[32,0.09]],"id":46969227}]}]}
{"op":"mcm","clk":"AOk2ANYbAP4u","pt":1659347500971,"mc":[{"id":"1.201590187","rc":[{"bdatb":[[3,1.98,48.82],[4,1.97,1.26]],"id":9570503},{"bdatb":[[3,6,2.66],[9,5,9.3]],"id":12989514},{"bdatb":[[5,15.5,5.15],[9,10.5,2.58]],"id":44621159},{"bdatl":[[0,29,5.64],[1,34,5.76]],"id":46969227}]}]}
{"op":"mcm","clk":"AOs2ANcbAIIv","pt":1659347501022,"mc":[{"id":"1.201590187","rc":[{"atb":[[13,4.42]],"id":45323444}]}]}
{"op":"mcm","clk":"APA2ANgbAIUv","pt":1659347501072,"mc":[{"id":"1.201590187","rc":[{"bdatb":[[2,13,4.42],[3,12.5,1.14],[4,11.5,5.54],[5,11,1.23],[6,10.5,4.72],[7,10,13.34],[8,9.8,10.95],[9,9.6,21]],"id":45323444}]}]}
{"op":"mcm","clk":"API2ANgbAIgv","pt":1659347501122,"mc":[{"id":"1.201590187","rc":[{"atb":[[9.4,54.1]],"id":45323444},{"atb":[[9.4,53.15]],"id":44621159},{"atl":[[28,0.73]],"id":46969227}]}]}
{"op":"mcm","clk":"APU2ANkbAIgv","pt":1659347501172,"mc":[{"id":"1.201590187","rc":[{"bdatb":[[9,5,9.8]],"id":12989514},{"bdatl":[[0,29,5.73]],"id":46969227}]}]}
{"op":"mcm","clk":"APg2ANwbAIsv","pt":1659347501225,"mc":[{"id":"1.201590187","rc":[{"atb":[[23,3.47]],"id":44621159},{"atb":[[9.4,43.1]],"id":46969227}]}]}
{"op":"mcm","clk":"APg2ANwbAI8v","pt":1659347501275,"mc":[{"id":"1.201590187","rc":[{"bdatl":[[8,2.42,15.62],[9,2.44,156.1]],"id":9570503},{"bdatb":[[0,23,3.96]],"id":44621159}]}]}
{"op":"mcm","clk":"AJM3AOYbAJov","pt":1659347501597,"mc":[{"id":"1.201590187","rc":[{"atl":[[1000,0]],"id":44621159}]}]}
{"op":"mcm","clk":"AJU3AOgbAJ8v","pt":1659347501648,"mc":[{"id":"1.201590187","rc":[{"bdatl":[[7,0,0]],"id":44621159}]}]}
{"op":"mcm","clk":"AKg3APQbALMv","pt":1659347502013,"mc":[{"id":"1.201590187","rc":[{"atb":[[13,0]],"id":45323444},{"atb":[[23,1]],"id":44621159}]}]}
{"op":"mcm","clk":"AKo3APYbALcv","pt":1659347502063,"mc":[{"id":"1.201590187","rc":[{"bdatb":[[2,12.5,1.14],[3,11.5,5.54],[4,11,1.23],[5,10.5,4.72],[6,10,13.34],[7,9.8,10.95],[8,9.6,21],[9,9.4,54.16]],"id":45323444},{"bdatl":[[8,2.42,8.42],[9,2.44,159.23]],"id":9570503},{"bdatb":[[0,23,1.49]],"id":44621159}]}]}
{"op":"mcm","clk":"AK03APcbALkv","pt":1659347502113,"mc":[{"id":"1.201590187","rc":[{"atb":[[6.6,4.88]],"id":12989514}]}]}
{"op":"mcm","clk":"AK43APkbALsv","pt":1659347502164,"mc":[{"id":"1.201590187","rc":[{"bdatb":[[2,6.6,4.88]],"id":12989514}]}]}
{"op":"mcm","clk":"ALM3APsbAL4v","pt":1659347502218,"mc":[{"id":"1.201590187","rc":[{"atb":[[14.5,4.96]],"id":45323444}]}]}
{"op":"mcm","clk":"ALU3APwbAMEv","pt":1659347502268,"mc":[{"id":"1.201590187","rc":[{"bdatb":[[0,14.5,4.96]],"id":45323444},{"bdatl":[[7,2.4,81.01],[8,2.42,11.24],[9,2.44,156.13]],"id":9570503},{"bdatl":[[7,12,3.28],[8,13,41.9]],"id":44836671}]}]}
{"op":"mcm","clk":"AL43AP8bAMYv","pt":1659347502415,"mc":[{"id":"1.201590187","rc":[{"atb":[[24,2.91]],"id":44621159},{"atb":[[6.8,5.07]],"id":44836671}]}]}
{"op":"mcm","clk":"AMM3AIAcAMYv","pt":1659347502466,"mc":[{"id":"1.201590187","rc":[{"bdatl":[[4,2.32,3.31],[5,2.36,78.03],[6,2.38,45.15],[7,2.4,74.65],[8,2.44,153],[9,2.46,1.48]],"id":9570503},{"bdatb":[[0,24,2.91],[1,23,1],[2,21,5],[3,20,1.8],[4,19.5,4.19],[5,18.5,1.37],[6,15.5,5.15],[7,13.5,1.34],[8,12.5,1.65],[9,11,5.74]],"id":44621159},{"bdatb":[[0,6.8,5.07],[1,6.6,35.96],[2,6.4,9.67],[3,6.2,9.3],[4,6,84.51],[5,5.9,9],[6,5.8,10],[7,5.7,67.92],[8,5.6,13.18],[9,5.5,23]],"id":44836671},{"bdatl":[[7,14,1.55],[9,15,12]],"id":43885158}]}]}
{"op":"mcm","clk":"AMc3AIIcAMkv","pt":1659347502531,"mc":[{"id":"1.201590187","rc":[{"atb":[[6.6,1.15]],"id":12989514},{"atb":[[6.8,5.43]],"id":44836671}]}]}
{"op":"mcm","clk":"AMs3AIMcAM0v","pt":1659347502582,"mc":[{"id":"1.201590187","rc":[{"bdatl":[[5,2.36,79.07],[6,2.38,44.12]],"id":9570503},{"bdatb":[[2,6.6,1.15]],"id":12989514},{"bdatb":[[0,6.8,5.43]],"id":44836671}]}]}
{"op":"mcm","clk":"AN43AIkcAOMv","pt":1659347502903,"mc":[{"id":"1.201590187","rc":[{"atb":[[6.8,4.77]],"id":12989514}]}]}
{"op":"mcm","clk":"AN83AIscAOUv","pt":1659347502953,"mc":[{"id":"1.201590187","rc":[{"bdatl":[[6,2.38,34.89],[7,2.4,71.43],[8,2.42,3.13],[9,2.44,152.09]],"id":9570503},{"bdatb":[[1,6.8,4.77]],"id":12989514}]}]}
{"op":"mcm","clk":"AOQ3AIscAOgv","pt":1659347503003,"mc":[{"id":"1.201590187","rc":[{"atb":[[4.9,5.22]],"id":12989514}]}]}
{"op":"mcm","clk":"AOk3AI4cAOov","pt":1659347503104,"mc":[{"id":"1.201590187","rc":[{"atb":[[14.5,1]],"id":45323444},{"atb":[[24,0.49]],"id":44621159}]}]}
{"op":"mcm","clk":"AOo3AJAcAO8v","pt":1659347503154,"mc":[{"id":"1.201590187","rc":[{"bdatb":[[0,14.5,1]],"id":45323444},{"bdatl":[[5,2.36,68.46],[6,2.38,43.21],[8,2.44,154.24],[9,2.46,3.08]],"id":9570503},{"bdatb":[[0,23,1.49],[1,21,5],[2,20,1.8],[3,19.5,4.19],[4,18.5,1.37],[5,15.5,5.15],[6,13.5,1.34],[7,12.5,1.65],[8,11,5.74],[9,10.5,2.58]],"id":44621159},{"bdatl":[[7,12,2.68],[8,13,42.48]],"id":44836671}]}]}
{"op":"mcm","clk":"APE3AJccAPQv","pt":1659347503309,"mc":[{"id":"1.201590187","rc":[{"atb":[[13,4.42]],"id":45323444}]}]}
{"op":"mcm","clk":"APU3AJgcAPYv","pt":1659347503359,"mc":[{"id":"1.201590187","rc":[{"bdatb":[[2,13,4.42],[3,12.5,1.14],[4,11.5,5.54],[5,11,1.23],[6,10.5,4.72],[7,10,13.34],[8,9.8,10.95],[9,9.6,21]],"id":45323444}]}]}
{"op":"mcm","clk":"APc3AJgcAPkv","pt":1659347503414,"mc":[{"id":"1.201590187","rc":[{"atb":[[22,2.59]],"id":44621159},{"atb":[[6.2,6.15]],"id":44836671}]}]}
{"op":"mcm","clk":"APk3AJwcAPkv","pt":1659347503464,"mc":[{"id":"1.201590187","rc":[{"bdatl":[[7,2.4,72.28],[8,2.42,1.32],[9,2.44,152.09]],"id":9570503},{"bdatb":[[1,22,2.59],[2,21,5],[3,20,1.8],[4,19.5,4.19],[5,18.5,1.37],[6,15.5,5.15],[7,13.5,1.34],[8,12.5,1.65],[9,11,5.74]],"id":44621159},{"bdatb":[[3,6.2,6.15]],"id":44836671}]}]}
{"op":"mcm","clk":"AKA4ALEcAKEw","pt":1659347504098,"mc":[{"id":"1.201590187","rc":[{"atb":[[13,0]],"id":45323444},{"atb":[[22,0]],"id":44621159}]}]}
{"op":"mcm","clk":"AKA4ALMcAKQw","pt":1659347504149,"mc":[{"id":"1.201590187","rc":[{"bdatb":[[2,12.5,1.14],[3,11.5,5.54],[4,11,1.23],[5,10.5,4.72],[6,10,13.34],[7,9.8,10.95],[8,9.6,21],[9,9.4,54.16]],"id":45323444},{"bdatl":[[7,2.4,71.43],[8,2.44,154.24],[9,2.46,3.08]],"id":9570503},{"bdatb":[[1,21,5],[2,20,1.8],[3,19.5,4.19],[4,18.5,1.37],[5,15.5,5.15],[6,13.5,1.34],[7,12.5,1.65],[8,11,5.74],[9,10.5,2.58]],"id":44621159}]}]}
{"op":"mcm","clk":"AK04ALkcAKww","pt":1659347504308,"mc":[{"id":"1.201590187","rc":[{"atb":[[14.5,4.96]],"id":45323444}]}]}
{"op":"mcm","clk":"AK84ALscAK8w","pt":1659347504358,"mc":[{"id":"1.201590187","rc":[{"bdatb":[[0,14.5,4.96]],"id":45323444},{"bdatl":[[7,2.4,72.28],[8,2.42,1.32],[9,2.44,155.2]],"id":9570503},{"bdatl":[[7,12,3.28],[8,13,41.9]],"id":44836671}]}]}
{"op":"mcm","clk":"ALQ4AL0cALQw","pt":1659347504508,"mc":[{"id":"1.201590187","rc":[{"atb":[[23,3.47]],"id":44621159}]}]}
{"op":"mcm","clk":"ALY4AL4cALcw","pt":1659347504558,"mc":[{"id":"1.201590187","rc":[{"bdatl":[[6,2.38,44.07],[7,2.4,72.76],[8,2.42,3.13],[9,2.44,152.09]],"id":9570503},{"bdatb":[[0,23,3.96]],"id":44621159}]}]}
{"op":"mcm","clk":"AOU4ANUcANww","pt":1659347505302,"mc":[{"id":"1.201590187","rc":[{"atb":[[14.5,1]],"id":45323444},{"atb":[[4.8,5.44]],"id":12989514},{"atb":[[23,1]],"id":44621159}]}]}
{"op":"mcm","clk":"AOc4ANccAN8w","pt":1659347505353,"mc":[{"id":"1.201590187","rc":[{"bdatb":[[0,14.5,1]],"id":45323444},{"bdatl":[[6,2.38,43.21],[7,2.4,71.43],[8,2.44,154.24],[9,2.46,3.08]],"id":9570503},{"bdatb":[[0,23,1.49]],"id":44621159},{"bdatl":[[7,12,2.68],[8,13,42.48]],"id":44836671}]}]}
{"op":"mcm","clk":"AOg4ANccAOEw","pt":1659347505403,"mc":[{"id":"1.201590187","rc":[{"atb":[[4.5,233.02]],"id":12989514}]}]}
{"op":"mcm","clk":"APc4ANocAOsw","pt":1659347505516,"mc":[{"id":"1.201590187","rc":[{"atb":[[13,4.42]],"id":45323444}]}]}
{"op":"mcm","clk":"APo4ANwcAO0w","pt":1659347505566,"mc":[{"id":"1.201590187","rc":[{"bdatb":[[2,13,4.42],[3,12.5,1.14],[4,11.5,5.54],[5,11,1.23],[6,10.5,4.72],[7,10,13.34],[8,9.8,10.95],[9,9.6,21]],"id":45323444}]}]}
{"op":"mcm","clk":"AP04AN0cAO8w","pt":1659347505616,"mc":[{"id":"1.201590187","rc":[{"atl":[[29,10]],"bdatl":[[0,29,10.73]],"id":46969227},{"bdatb":[[9,5,10.32]],"id":12989514}]}]}
{"op":"mcm","clk":"AIs5AOIcAPMw","pt":1659347505721,"mc":[{"id":"1.201590187","rc":[{"atb":[[4,8]],"id":12989514},{"atb":[[24,2.91]],"id":44621159}]}]}
{"op":"mcm","clk":"AI85AOMcAPcw","pt":1659347505771,"mc":[{"id":"1.201590187","rc":[{"bdatl":[[5,2.36,69.57],[6,2.38,42.96],[7,2.4,72.76],[8,2.42,3.13],[9,2.44,152.09]],"id":9570503},{"bdatb":[[0,24,2.91],[1,23,1],[2,21,5],[3,20,1.8],[4,19.5,4.19],[5,18.5,1.37],[6,15.5,5.15],[7,13.5,1.34],[8,12.5,1.65],[9,11,5.74]],"id":44621159},{"bdatl":[[7,12,3.28],[8,13,41.9]],"id":44836671}]}]}
{"op":"mcm","clk":"AJI5AOUcAPcw","pt":1659347505821,"mc":[{"id":"1.201590187","rc":[{"atb":[[14.5,0]],"atl":[[18.5,0]],"id":45323444},{"atb":[[4.7,7.34]],"id":12989514},{"atb":[[23,0],[22,1]],"id":44621159}]}]}
{"op":"mcm","clk":"AJU5AOUcAP0w","pt":1659347505871,"mc":[{"id":"1.201590187","rc":[{"bdatb":[[0,14,2.7],[1,13,4.42],[2,12.5,1.14],[3,11.5,5.54],[4,11,1.23],[5,10.5,4.72],[6,10,13.34],[7,9.8,10.95],[8,9.6,21],[9,9.4,54.16]],"bdatl":[[1,21,1.15],[2,23,2.64],[3,25,5.61],[4,26,5.04],[5,27,3.85],[6,29,5.36],[7,32,3.23],[8,50,8],[9,55,9]],"id":45323444},{"bdatb":[[6,1.92,6.21],[7,1.91,111.59],[8,1.9,2.18],[9,1.89,8.24]],"bdatl":[[4,2.34,3.28],[5,2.36,66.68],[6,2.38,45.83],[7,2.4,71.8],[8,2.44,153.03],[9,2.46,3.08]],"id":9570503},{"bdatb":[[4,5.5,2.17],[5,5.4,2.26],[6,5.3,2.82],[7,5.1,8.79],[8,5,14.02],[9,4.9,5.22]],"id":12989514},{"bdatb":[[1,22,1],[7,12.5,1.9],[8,12,1.25],[9,11,4.08]],"id":44621159},{"bdatb":[[7,5.7,65.83],[8,5.6,12],[9,5.5,25.17]],"id":44836671},{"bdatb":[[6,6.6,64.72],[7,6.4,5.13],[8,6.2,13.08],[9,6,14.1]],"bdatl":[[7,14,1],[8,14.5,1.53]],"id":43885158},{"bdatb":[[8,11.5,1.74],[9,11,1.74]],"id":46969227}]}]}
{"op":"mcm","clk":"AJc5AOccAP4w","pt":1659347505922,"mc":[{"id":"1.201590187","rc":[{"atb":[[4.9,0]],"id":12989514}]}]}
{"op":"mcm","clk":"AJk5AOkcAIEx","pt":1659347505973,"mc":[{"id":"1.201590187","rc":[{"bdatb":[[9,4.8,7.34]],"id":12989514}]}]}
{"op":"mcm","clk":"AK85APAcAJcx","pt":1659347506339,"mc":[{"id":"1.201590187","rc":[{"atl":[[38,0.59]],"id":44621159}]}]}
{"op":"mcm","clk":"ALE5APQcAJox","pt":1659347506389,"mc":[{"id":"1.201590187","rc":[{"bdatl":[[1,40,3.86],[2,95,2.64],[3,120,7.2],[4,170,2],[5,990,2.07],[6,0,0]],"id":44621159}]}]}
{"op":"mcm","clk":"ALY5APUcAKAx","pt":1659347506449,"mc":[{"id":"1.201590187","rc":[{"atb":[[13,0]],"id":45323444},{"atb":[[24,0.49]],"id":44621159},{"atb":[[7.6,4.53]],"id":43885158}]}]}
{"op":"mcm","clk":"ALk5APccAKQx","pt":1659347506499,"mc":[{"id":"1.201590187","rc":[{"bdatb":[[1,12.5,1.14],[2,11.5,5.54],[3,11,1.23],[4,10.5,4.72],[5,10,13.34],[6,9.8,10.95],[7,9.6,21],[8,9.4,54.16],[9,9.2,12.29]],"id":45323444},{"bdatl":[[6,2.38,35.31],[7,2.4,80.6],[8,2.42,1.25],[9,2.44,152.45]],"id":9570503},{"bdatb":[[0,22,1.49],[1,21,5],[2,20,1.8],[3,19.5,4.19],[4,18.5,1.37],[5,15.5,5.15],[6,12.5,1.9],[7,12,1.25],[8,11,4.08],[9,10.5,4.34]],"id":44621159},{"bdatl":[[7,12,2.47],[8,13,42.69]],"id":44836671},{"bdatb":[[2,7.6,4.53]],"id":43885158}]}]}
{"op":"mcm","clk":"AL45APgcAKUx","pt":1659347506549,"mc":[{"id":"1.201590187","rc":[{"atb":[[14.5,3.96]],"bdatb":[[0,14.5,3.96],[1,14,2.7],[2,12.5,1.14],[3,11.5,5.54],[4,11,1.23],[5,10.5,4.72],[6,10,13.34],[7,9.8,10.95],[8,9.6,21],[9,9.4,54.16]],"id":45323444},{"bdatl":[[4,2.32,3.31],[5,2.36,68.46],[6,2.38,42.79],[7,2.4,72.69],[8,2.42,1.32],[9,2.44,155.2]],"id":9570503},{"bdatl":[[7,14,1.55],[8,14.5,1]],"id":43885158}]}]}
{"op":"mcm","clk":"AMQ5APkcAKsx","pt":1659347506603,"mc":[{"id":"1.201590187","rc":[{"atb":[[22,3.59]],"id":44621159}]}]}
{"op":"mcm","clk":"AMU5APscAK0x","pt":1659347506653,"mc":[{"id":"1.201590187","rc":[{"bdatl":[[6,2.38,44.07],[7,2.4,71.43]],"id":9570503},{"bdatb":[[0,22,4.08]],"id":44621159}]}]}
{"op":"mcm","clk":"AMc5AP0cALAx","pt":1659347506705,"mc":[{"id":"1.201590187","rc":[{"atl":[[34,2]],"id":44621159}]}]}
{"op":"mcm","clk":"AMg5AP4cALIx","pt":1659347506755,"mc":[{"id":"1.201590187","rc":[{"bdatb":[[4,11,1.46],[5,10.5,6.89],[6,10,12.72],[7,9.8,9.06],[9,9.4,55.4]],"id":45323444},{"bdatb":[[1,2,2.54],[2,1.99,23.31],[6,1.93,2.27],[7,1.92,3.93],[8,1.91,121.91],[9,1.89,6.5]],"id":9570503},{"bdatb":[[4,5.5,4.37],[5,5.4,2.77],[6,5.2,8.62],[7,5,14.01],[8,4.8,7.34],[9,4.7,7.34]],"id":12989514},{"bdatl":[[0,34,2],[1,36,1],[2,40,3.86],[3,95,2.64],[4,120,7.2],[5,170,2],[6,990,2.07]],"id":44621159},{"bdatb":[[8,5.6,12.78],[9,5.5,26.59]],"id":44836671},{"bdatb":[[3,7.4,2.67],[4,7.2,5.57],[5,7,5],[7,6.4,8.11],[8,6.2,10.1],[9,6,16.05]],"id":43885158},{"bdatb":[[8,11.5,3.35],[9,10,6.48]],"id":46969227}]}]}
{"op":"mcm","clk":"ANQ5AIEdALox","pt":1659347506916,"mc":[{"id":"1.201590187","rc":[{"atb":[[15,1]],"id":45323444}]}]}
{"op":"mcm","clk":"ANY5AIMdAL0x","pt":1659347506966,"mc":[{"id":"1.201590187","rc":[{"bdatb":[[0,15,1],[1,14.5,3.96],[2,14,2.7],[3,12.5,1.14],[4,11.5,5.54],[5,11,1.46],[6,10.5,6.89],[7,10,12.72],[8,9.8,9.06],[9,9.6,21]],"id":45323444},{"bdatl":[[3,2.3,5.06],[4,2.36,68.46],[5,2.38,44.07],[6,2.4,71.43],[7,2.42,1.32],[8,2.44,155.2],[9,2.5,21]],"id":9570503},{"bdatl":[[7,11.5,1.1],[8,12,1.68],[9,13,42.44]],"id":44836671},{"bdatl":[[6,13.5,8.57],[7,14,1]],"id":43885158}]}]}
{"op":"mcm","clk":"ANo5AIMdAMMx","pt":1659347507019,"mc":[{"id":"1.201590187","rc":[{"atl":[[20,1]],"id":45323444}]}]}
{"op":"mcm","clk":"AN05AIUdAMcx","pt":1659347507069,"mc":[{"id":"1.201590187","rc":[{"bdatl":[[1,20,1],[2,21,1.15],[3,23,2.64],[4,25,5.61],[5,26,5.04],[6,27,3.85],[7,29,5.36],[8,32,3.23],[9,50,8]],"id":45323444},{"bdatb":[[6,1.94,2.26],[7,1.93,3.91],[8,1.92,4.21],[9,1.91,117.68]],"id":9570503},{"bdatb":[[4,5.6,2.12],[5,5.5,4.94],[6,5.3,2.43],[7,5.2,6.92],[8,5.1,3.13],[9,5,10.02]],"id":12989514},{"bdatb":[[6,13,1.52],[7,12.5,1.53],[8,11,5.87],[9,10.5,2.44]],"id":44621159},{"bdatb":[[7,5.7,66.59],[8,5.6,13.35],[9,5.5,27.94]],"id":44836671},{"bdatb":[[6,6.6,67.75],[7,6.4,4.98],[9,6,17.74]],"id":43885158},{"bdatb":[[8,12,1.62],[9,11.5,1.66]],"id":46969227}]}]}
{"op":"mcm","clk":"AO05AI8dANgx","pt":1659347507340,"mc":[{"id":"1.201590187","rc":[{"atb":[[14.5,0]],"id":45323444},{"atb":[[22,1]],"id":44621159}]}]}
{"op":"mcm","clk":"AO85AJEdAN0x","pt":1659347507390,"mc":[{"id":"1.201590187","rc":[{"bdatb":[[1,14,2.7],[2,12.5,1.14],[3,11.5,5.54],[4,11,1.46],[5,10.5,6.89],[6,10,12.72],[7,9.8,9.06],[8,9.6,21],[9,9.4,55.4]],"id":45323444},{"bdatl":[[5,2.38,34.86],[6,2.4,79.29],[7,2.42,1.25],[8,2.44,153.4],[9,2.46,3.08]],"id":9570503},{"bdatb":[[0,22,1.49]],"id":44621159}]}]}
{"op":"mcm","clk":"APY5AJIdAN8x","pt":1659347507440,"mc":[{"id":"1.201590187","rc":[{"atl":[[2.38,0]],"id":9570503},{"atl":[[1000,0.41]],"id":44621159}]}]}
{"op":"mcm","clk":"APc5AJMdAOEx","pt":1659347507491,"mc":[{"id":"1.201590187","rc":[{"bdatl":[[5,2.38,1.31]],"id":9570503},{"bdatl":[[7,1000,0.41]],"id":44621159}]}]}
{"op":"mcm","clk":"AP05AJQdAOUx","pt":1659347507543,"mc":[{"id":"1.201590187","rc":[{"atb":[[13,4.42]],"atl":[[1000,0.89]],"id":45323444},{"atb":[[1.98,38.19]],"id":9570503}]}]}
{"op":"mcm","clk":"AP85AJUdAOYx","pt":1659347507593,"mc":[{"id":"1.201590187","rc":[{"bdatb":[[2,13,4.42],[3,12.5,1.14],[4,11.5,5.54],[5,11,1.46],[6,10.5,6.89],[7,10,12.72],[8,9.8,9.06],[9,9.6,21]],"id":45323444},{"bdatb":[[3,1.98,44.97]],"id":9570503}]}]}
{"op":"mcm","clk":"AIM6AJYdAOox","pt":1659347507643,"mc":[{"id":"1.201590187","rc":[{"atb":[[23,2.47]],"atl":[[1000,0]],"id":44621159}]}]}
{"op":"mcm","clk":"AIQ6AJgdAOox","pt":1659347507694,"mc":[{"id":"1.201590187","rc":[{"bdatl":[[4,2.36,69.79],[5,2.38,9.21],[6,2.4,71.43],[7,2.42,1.32],[8,2.44,155.2],[9,2.5,21]],"id":9570503},{"bdatb":[[0,23,2.96],[1,22,1],[2,21,5],[3,20,1.8],[4,19.5,4.19],[5,18.5,1.37],[6,15.5,5.15],[7,13,1.52],[8,12.5,1.53],[9,11,5.87]],"bdatl":[[7,0,0]],"id":44621159}]}]}
{"op":"mcm","clk":"AIc6AJodAO4x","pt":1659347507745,"mc":[{"id":"1.201590187","rc":[{"atl":[[1000,0.48]],"id":45323444},{"atl":[[32,0.41]],"id":44621159}]}]}
{"op":"mcm","clk":"AIg6AJsdAPAx","pt":1659347507795,"mc":[{"id":"1.201590187","rc":[{"bdatb":[[2,1.99,28.61],[3,1.98,39.63]],"id":9570503},{"bdatb":[[3,6.2,2.12],[4,5.7,1.25],[5,5.6,1.35],[6,5.5,4.94],[7,5.3,4.34],[8,5.2,7.51],[9,5,10.58]],"id":12989514},{"bdatl":[[0,34,2.41]],"id":44621159},{"bdatb":[[3,6.2,8.27],[4,6,82.32]],"id":44836671},{"bdatb":[[9,6,18.24]],"id":43885158},{"bdatb":[[6,16,1.59],[7,12.5,1.85],[8,11.5,2.33],[9,10.5,2.19]],"id":46969227}]}]}
{"op":"mcm","clk":"AI06AJwdAPQx","pt":1659347507856,"mc":[{"id":"1.201590187","rc":[{"atl":[[19.5,0.41]],"id":45323444},{"atb":[[6.8,0.36]],"id":12989514}]}]}
{"op":"mcm","clk":"AJM6AJ4dAPgx","pt":1659347507906,"mc":[{"id":"1.201590187","rc":[{"bdatl":[[1,20,1.41]],"id":45323444},{"bdatb":[[6,1.94,4.13],[7,1.93,2.02],[8,1.92,8.38],[9,1.91,113.48]],"bdatl":[[4,2.36,67.72],[5,2.38,2.05],[7,2.42,1.12],[8,2.44,152.09]],"id":9570503},{"bdatb":[[1,6.6,1.51],[2,6.2,2.12],[3,5.7,1.89],[4,5.5,5.64],[5,5.3,4.92],[6,5.2,6.92],[7,5.1,2.13],[8,5,8.42],[9,4.8,7.34]],"id":12989514},{"bdatb":[[7,13,2.13],[8,11.5,2.02],[9,11,5.44]],"id":44621159},{"bdatb":[[7,5.7,67.23],[8,5.6,12.7]],"bdatl":[[7,12,2.5],[8,13,42.35],[9,13.5,1.55]],"id":44836671},{"bdatb":[[6,6.6,68.96],[7,6.4,3.73],[9,6,19.07]],"id":43885158},{"bdatb":[[8,12,1.34],[9,11,1.02]],"id":46969227}]}]}
{"op":"mcm","clk":"AJc6AKEdAPwx","pt":1659347507957,"mc":[{"id":"1.201590187","rc":[{"atl":[[7.8,11]],"bdatl":[[1,7.8,11]],"id":44836671},{"atl":[[36,2.64]],"bdatl":[[2,36,2.64],[3,38,2.51],[4,40,5.01],[5,80,1.66],[6,310,1],[7,990,2.15]],"id":46969227}]}]}
{"op":"mcm","clk":"AJ46AKgdAIUy","pt":1659347508124,"mc":[{"id":"1.201590187","rc":[{"atb":[[4.6,0]],"id":12989514}]}]}
{"op":"mcm","clk":"AKM6AKodAIwy","pt":1659347508228,"mc":[{"id":"1.201590187","rc":[{"atb":[[4.9,1.55],[4.1,0]],"id":12989514}]}]}
{"op":"mcm","clk":"AKQ6AKwdAI4y","pt":1659347508278,"mc":[{"id":"1.201590187","rc":[{"bdatb":[[9,4.9,1.55]],"id":12989514}]}]}
{"op":"mcm","clk":"AKg6ALAdAJUy","pt":1659347508338,"mc":[{"id":"1.201590187","rc":[{"atb":[[7.2,0],[4.8,6.91]],"trd":[[7.2,3.25]],"tv":53.97,"id":12989514}],"tv":1184.44}]}
{"op":"mcm","clk":"AKk6ALEdAJUy","pt":1659347508388,"mc":[{"id":"1.201590187","rc":[{"bdatl":[[3,2.3,1.72],[5,2.38,3.19],[7,2.44,152.09],[8,2.5,21],[9,2.72,1.83]],"id":9570503},{"bdatb":[[0,6.6,1.51],[1,6.2,2.12],[2,5.7,1.89],[3,5.5,5.64],[4,5.3,4.92],[5,5.2,6.92],[6,5.1,2.13],[7,5,8.42],[8,4.9,1.55],[9,4.8,8.81]],"id":12989514},{"bdatl":[[7,12,2.26],[8,13,41.9]],"id":44836671},{"bdatl":[[6,13.5,8]],"id":43885158}]}]}
{"op":"mcm","clk":"AK86ALMdAJoy","pt":1659347508443,"mc":[{"id":"1.201590187","rc":[{"atb":[[13,0]],"id":45323444},{"atb":[[6.2,15.5]],"atl":[[1000,3.34]],"id":12989514},{"atb":[[23,0]],"id":44621159}]}]}
{"op":"mcm","clk":"ALE6ALQdAJ4y","pt":1659347508493,"mc":[{"id":"1.201590187","rc":[{"bdatb":[[2,12.5,1.14],[3,11.5,5.54],[4,11,1.46],[5,10.5,6.89],[6,10,12.72],[7,9.8,9.06],[8,9.6,21],[9,9.4,56.8]],"id":45323444},{"bdatl":[[7,2.44,152.85],[8,2.46,1.27],[9,2.48,7.61]],"id":9570503},{"bdatb":[[1,6.2,17.62]],"id":12989514},{"bdatb":[[0,22,1.49],[1,21,5],[2,20,1.8],[3,19.5,4.19],[4,18.5,1.37],[5,15.5,5.15],[6,13,2.13],[7,11.5,2.02],[8,11,5.44],[9,10.5,1.68]],"id":44621159},{"bdatl":[[9,13.5,1.69]],"id":44836671}]}]}
{"op":"mcm","clk":"AL06ALwdAKgy","pt":1659347508655,"mc":[{"id":"1.201590187","rc":[{"atb":[[14.5,3.96]],"id":45323444},{"atb":[[6.8,0]],"atl":[[7.4,4],[8.2,0.31],[8,0.32]],"id":12989514}]}]}
{"op":"mcm","clk":"AL46AL4dAKgy","pt":1659347508705,"mc":[{"id":"1.201590187","rc":[{"bdatb":[[1,14.5,3.96],[2,14,2.7],[3,12.5,1.14],[4,11.5,5.76],[5,11,2.84],[6,10.5,5.35],[7,10,12.55],[8,9.8,11.66],[9,9.6,21.43]],"id":45323444},{"bdatb":[[1,2.02,1.28],[2,2,7.95],[3,1.99,23.31],[4,1.98,38.19],[5,1.97,1.26],[6,1.96,2.62],[7,1.95,4.11],[8,1.94,2.88],[9,1.92,7.51]],"bdatl":[[4,2.36,66.68],[7,2.44,153.85],[8,2.46,8.94],[9,2.48,1.22]],"id":9570503},{"bdatb":[[0,6.6,1.15]],"bdatl":[[0,7.4,4],[1,7.6,7.33],[2,7.8,11.52],[3,8.4,2.69],[4,9,2.17],[5,9.2,4.82],[6,9.6,11.09],[7,10,17.36],[8,10.5,12.47],[9,11,33.84]],"id":12989514},{"bdatb":[[4,18.5,1.51],[5,15.5,4.96],[6,13,2.07],[7,12,1.98],[8,11.5,1.49],[9,11,3.88]],"id":44621159},{"bdatb":[[3,6.2,8.73],[4,6,81.85],[6,5.8,11.38],[7,5.7,66.81],[8,5.6,12],[9,5.5,27.64]],"bdatl":[[7,12,2.05],[9,13.5,1.87]],"id":44836671},{"bdatb":[[2,7.6,4.87],[3,7.4,4.13],[4,7.2,3.71],[6,6.8,1.18],[7,6.6,67.75],[8,6.4,3.73],[9,6.2,14.2]],"id":43885158},{"bdatb":[[6,16,2.24],[7,13,1.1],[8,12,1.33],[9,11,3.33]],"id":46969227}]}]}
{"op":"mcm","clk":"AMs6AMMdALIy","pt":1659347508848,"mc":[{"id":"1.201590187","rc":[{"atl":[[8.4,1.76],[7.4,4.35]],"id":12989514},{"atb":[[22,3.59]],"id":44621159}]}]}
{"op":"mcm","clk":"AMw6AMYdALQy","pt":1659347508898,"mc":[{"id":"1.201590187","rc":[{"bdatb":[[6,10.5,5.6],[7,10,12.29],[9,9.6,21.7]],"id":45323444},{"bdatb":[[8,1.94,4.21],[9,1.92,6.16]],"bdatl":[[8,2.46,10.18],[9,2.5,31.07]],"id":9570503},{"bdatl":[[0,7.4,4.35],[3,8.4,2.39]],"id":12989514},{"bdatb":[[0,22,4.08],[6,13.5,1.16],[7,12.5,1.8],[8,12,1.09],[9,11.5,1.56]],"id":44621159},{"bdatb":[[7,5.7,67.26],[9,5.5,27.17]],"id":44836671}]}]}
{"op":"mcm","clk":"AM86AMcdALwy","pt":1659347508949,"mc":[{"id":"1.201590187","rc":[{"atb":[[6.4,11]],"atl":[[1000,0.47]],"id":12989514},{"atl":[[34,0]],"id":44621159}]}]}
{"op":"mcm","clk":"ANA6AMgdAMMy","pt":1659347508999,"mc":[{"id":"1.201590187","rc":[{"bdatb":[[5,11,2.19],[6,10.5,6.29],[7,10,11.7],[8,9.8,9.61],[9,9.6,21]],"id":45323444},{"bdatb":[[2,2,6.52],[3,1.99,24.74],[7,1.95,2.25],[8,1.94,3.89],[9,1.93,2.21]],"bdatl":[[6,2.4,73.22],[7,2.42,1.29],[8,2.44,161.07],[9,2.46,10.23]],"id":9570503},{"bdatb":[[1,6.4,11],[2,6.2,17.62],[3,5.6,2.61],[4,5.5,2.93],[5,5.4,2.05],[6,5.3,2.46],[7,5.2,3.46],[8,5.1,8.21],[9,5,8.42]],"id":12989514},{"bdatl":[[0,36,1.41],[1,40,3.86],[2,95,2.64],[3,120,7.2],[4,170,2],[5,990,2.07],[6,0,0]],"id":44621159},{"bdatb":[[6,5.8,10.76],[7,5.7,67.15],[8,5.6,12.76],[9,5.5,25.15]],"bdatl":[[8,13,42.23],[9,13.5,1.79]],"id":44836671},{"bdatb":[[3,7.4,3.75],[4,7.2,4.1],[6,6.6,67.14],[7,6.4,4.65],[8,6.2,13.06],[9,6,17.29]],"id":43885158},{"bdatb":[[7,12.5,1.46],[8,11.5,1.44],[9,10.5,3.5]],"id":46969227}]}]}
{"op":"mcm","clk":"ANw6AM0dANEy","pt":1659347509130,"mc":[{"id":"1.201590187","rc":[{"atl":[[7.8,4.52],[7.2,7]],"id":12989514},{"atl":[[34,2]],"id":44621159}]}]}
{"op":"mcm","clk":"AN06AM8dANky","pt":1659347509181,"mc":[{"id":"1.201590187","rc":[{"bdatb":[[4,11.5,7.3],[5,11,3.96],[6,10.5,4.92],[7,10,12.75],[8,9.8,9],[9,9.6,24.6]],"id":45323444},{"bdatb":[[1,2.04,1.27],[2,2.02,5.23],[3,2,2.67],[4,1.99,23.31],[5,1.98,38.19],[6,1.97,3.48],[7,1.96,6.46],[8,1.95,8.25],[9,1.94,3.29]],"id":9570503},{"bdatb":[[3,5.7,1.89],[4,5.5,5.64],[5,5.3,4.92],[6,5.2,6.92],[7,5.1,2.13],[8,5,8.42],[9,4.9,1.55]],"bdatl":[[0,7.2,7],[1,7.4,4.35],[2,7.6,7.33],[3,7.8,4.52],[4,8.4,2.39],[5,9,2.17],[6,9.2,4.82],[7,9.6,11.09],[8,10,17.36],[9,10.5,12.47]],"id":12989514},{"bdatb":[[2,20,1.93],[4,18.5,2.1],[5,15.5,4.48],[6,14,1.66],[7,12.5,1.87],[8,12,1.2],[9,11,5.05]],"bdatl":[[0,34,2.41],[1,36,1],[2,40,3.86],[3,95,2.64],[4,120,7.2],[5,170,2],[6,990,2.07]],"id":44621159},{"bdatb":[[2,6.4,12.17],[3,6.2,6.15],[4,6,82.58],[5,5.9,10.28],[6,5.8,12.78],[7,5.7,66.95],[8,5.6,12.84],[9,5.5,23]],"id":44836671},{"bdatb":[[0,8,8.08],[2,7.6,6.3],[3,7.4,2.32],[4,7.2,3.71],[5,7,6.14],[6,6.8,3.88],[7,6.6,65.43],[8,6.4,4.04],[9,6.2,12.33]],"id":43885158},{"bdatb":[[6,16,2.36],[7,13,2.59],[8,11.5,1.52],[9,11,1.31]],"id":46969227}]}]}
{"op":"mcm","clk":"AOE6ANAdANwy","pt":1659347509231,"mc":[{"id":"1.201590187","rc":[{"atl":[[8.2,0]],"id":12989514}]}]}
{"op":"mcm","clk":"AOM6ANIdAN0y","pt":1659347509281,"mc":[{"id":"1.201590187","rc":[{"bdatl":[[4,8.4,2.08]],"id":12989514}]}]}
{"op":"mcm","clk":"AOY6ANUdAOAy","pt":1659347509346,"mc":[{"id":"1.201590187","rc":[{"atb":[[6.6,1.52]],"atl":[[7.2,7.36]],"bdatb":[[0,6.6,1.52]],"bdatl":[[0,7.2,7.36]],"id":12989514},{"bdatb":[[5,11,4.19],[6,10.5,4.68],[7,10,13.01],[9,9.6,24.33]],"id":45323444},{"bdatb":[[9,1.94,4.63]],"bdatl":[[5,2.38,4.21],[6,2.4,72.2]],"id":9570503},{"bdatb":[[8,12,1.42],[9,11,5.06]],"id":44621159},{"bdatb":[[7,5.7,67.4],[8,5.6,12.38]],"bdatl":[[7,12,2.25],[8,13,42.04]],"id":44836671},{"bdatb":[[6,6.8,4.26],[7,6.6,65.03],[9,6.2,12.75]],"id":43885158},{"bdatb":[[7,13,2.79],[8,11.5,1.31],[9,11,1.55]],"id":46969227}]}]}
{"op":"mcm","clk":"AOw6AN0dAOcy","pt":1659347509445,"mc":[{"id":"1.201590187","rc":[{"atb":[[2.04,4.55],[2.02,7.75]],"id":9570503},{"atb":[[6.6,1.51]],"trd":[[6.6,0.01]],"ltp":6.6,"tv":53.98,"id":12989514},{"atb":[[7.6,8.8]],"id":43885158}],"tv":1184.45}]}
{"op":"mcm","clk":"AO46AOEdAOsy","pt":1659347509495,"mc":[{"id":"1.201590187","rc":[{"bdatb":[[1,2.04,5.82],[2,2.02,12.98]],"bdatl":[[5,2.38,4.19],[6,2.4,72.22]],"id":9570503},{"bdatb":[[0,6.6,1.51]],"id":12989514},{"bdatb":[[2,7.6,10.57]],"id":43885158}]}]}
{"op":"mcm","clk":"API6AOUdAO4y","pt":1659347509557,"mc":[{"id":"1.201590187","rc":[{"atb":[[14.5,0]],"id":45323444},{"atb":[[1.99,21.03]],"id":9570503},{"atb":[[6.2,0]],"id":12989514},{"atl":[[29,0]],"id":46969227}]}]}
{"op":"mcm","clk":"APU6AOcdAPQy","pt":1659347509607,"mc":[{"id":"1.201590187","rc":[{"bdatb":[[1,14,2.7],[2,12.5,1.14],[3,11.5,7.3],[4,11,1.68],[5,10.5,7.11],[6,10,10.21],[7,9.8,9],[8,9.6,23.71],[9,9.4,54.52]],"id":45323444},{"bdatb":[[4,1.99,21.03],[7,1.96,3.69],[8,1.95,1.48],[9,1.94,1.32]],"bdatl":[[8,2.44,152.09],[9,2.46,8.91]],"id":9570503},{"bdatb":[[2,6.2,2.12],[3,5.7,1.25],[4,5.5,1.36],[5,5.4,2.98],[6,5.3,2.09],[7,5.2,2.51],[8,5.1,3.53],[9,5,8.37]],"id":12989514},{"bdatb":[[6,13,2.47],[7,11.5,1.31],[8,11,1.64],[9,10.5,3.99]],"id":44621159},{"bdatb":[[5,5.9,9.36],[6,5.8,10.5],[7,5.7,66.27],[8,5.6,14.87],[9,5.5,24.63]],"id":44836671},{"bdatb":[[5,7,5.63],[6,6.6,69.64],[7,6.4,2.33],[8,6.2,12.1],[9,6,16.84]],"id":43885158},{"bdatl":[[0,34,6.49],[1,36,2.64],[2,38,2.51],[3,40,5.01],[4,80,1.66],[5,310,1],[6,990,2.15],[7,0,0]],"id":46969227}]}]}
{"op":"mcm","clk":"APw6AOgdAPYy","pt":1659347509657,"mc":[{"id":"1.201590187","rc":[{"atb":[[1.99,18.57]],"atl":[[3.15,33.55]],"id":9570503}]}]}
{"op":"mcm","clk":"AP46AOodAPsy","pt":1659347509707,"mc":[{"id":"1.201590187","rc":[{"bdatb":[[4,1.99,18.57]],"id":9570503}]}]}
{"op":"mcm","clk":"AIQ7AO0dAIAz","pt":1659347509757,"mc":[{"id":"1.201590187","rc":[{"atb":[[13,4.42]],"id":45323444}]}]}
{"op":"mcm","clk":"AIg7AO0dAIAz","pt":1659347509807,"mc":[{"id":"1.201590187","rc":[{"bdatb":[[2,13,4.42],[3,12.5,1.14],[4,11.5,7.3],[5,11,1.68],[6,10.5,7.11],[7,10,10.21],[8,9.8,9],[9,9.6,23.71]],"id":45323444}]}]}
{"op":"mcm","clk":"AIs7AO4dAIYz","pt":1659347509857,"mc":[{"id":"1.201590187","rc":[{"atb":[[2.04,6.95]],"bdatb":[[1,2.04,8.22]],"id":9570503}]}]}
{"op":"mcm","clk":"AJU7APgdAJMz","pt":1659347510022,"mc":[{"id":"1.201590187","rc":[{"atb":[[23,2]],"atl":[[32,2.09]],"id":46969227}]}]}
{"op":"mcm","clk":"AJY7APkdAJYz","pt":1659347510072,"mc":[{"id":"1.201590187","rc":[{"bdatb":[[5,11,1.91],[6,10.5,6.86],[8,9.8,11.66],[9,9.6,21.42]],"id":45323444},{"bdatb":[[8,1.95,2.79],[9,1.94,8.3]],"bdatl":[[4,2.36,70.9],[5,2.4,72.22],[6,2.42,1.29],[7,2.44,161.07],[8,2.46,3.69],[9,2.48,2.74]],"id":9570503},{"bdatb":[[5,5.4,5.03],[6,5.2,5.01],[7,5.1,1.61],[8,5,7.73],[9,4.9,10.14]],"id":12989514},{"bdatb":[[6,13.5,1.72],[7,12,1.95],[8,11.5,1.48],[9,10.5,4.06]],"id":44621159},{"bdatb":[[6,5.8,10.94],[7,5.7,68.65],[8,5.6,13.6],[9,5.5,23.38]],"bdatl":[[8,13,42.29],[9,13.5,1.55]],"id":44836671},{"bdatb":[[8,6.2,14.2],[9,6,14.83]],"id":43885158},{"bdatb":[[0,23,2],[1,22,4.4],[2,21,1.6],[3,20,5.51],[4,19.5,7],[5,19,5],[6,18.5,4],[7,16,2.36],[8,13,2.79],[9,11.5,1.31]],"bdatl":[[0,32,2.89],[1,34,5.6],[2,36,2.64],[3,38,2.51],[4,40,5.01],[5,80,1.66],[6,310,1],[7,990,2.15]],"id":46969227}]}]}
{"op":"mcm","clk":"AJk7APodAJoz","pt":1659347510128,"mc":[{"id":"1.201590187","rc":[{"atb":[[6.6,20.96]],"id":44836671},{"atb":[[21,5.6],[18.5,0]],"id":46969227}]}]}
{"op":"mcm","clk":"AJo7AP0dAJ0z","pt":1659347510178,"mc":[{"id":"1.201590187","rc":[{"bdatb":[[1,6.6,20.96]],"id":44836671},{"bdatb":[[2,21,5.6],[6,16,2.36],[7,13,2.79],[8,11.5,1.31],[9,11,1.55]],"id":46969227}]}]}
{"op":"mcm","clk":"AJw7AP4dAJ8z","pt":1659347510228,"mc":[{"id":"1.201590187","rc":[{"atb":[[6.8,20.43]],"id":44836671}]}]}
{"op":"mcm","clk":"AJ87AIAeAKMz","pt":1659347510278,"mc":[{"id":"1.201590187","rc":[{"bdatl":[[7,2.44,164.79],[8,2.46,2.76],[9,2.48,3.74]],"id":9570503},{"bdatb":[[0,6.8,20.43]],"id":44836671}]}]}
{"op":"mcm","clk":"AKo7AIkeAK0z","pt":1659347510438,"mc":[{"id":"1.201590187","rc":[{"atb":[[13,0]],"id":45323444},{"atb":[[6.2,2.98]],"id":12989514},{"atb":[[22,1]],"id":44621159},{"atl":[[28,5.73]],"id":46969227}]}]}
{"op":"mcm","clk":"AKs7AIkeALAz","pt":1659347510488,"mc":[{"id":"1.201590187","rc":[{"bdatb":[[2,12.5,1.14],[3,11.5,7.96],[4,11,3.51],[5,10.5,4.68],[6,10,13.01],[7,9.8,12.26],[8,9.6,23.33],[9,9.4,54.24]],"id":45323444},{"bdatb":[[6,1.97,5.33],[7,1.96,4.61],[8,1.95,12.86],[9,1.93,7.85]],"bdatl":[[7,2.44,159.83],[8,2.46,7.69],[9,2.5,21]],"id":9570503},{"bdatb":[[2,6.2,5.1],[3,5.7,2.57],[4,5.6,2.87],[5,5.5,2.02],[6,5.4,2.42],[7,5.3,3.39],[8,5.2,8.05],[9,5.1,2.26]],"id":12989514},{"bdatb":[[0,22,1.49],[5,15.5,4.71],[6,14.5,1.37],[7,12.5,1.84],[8,12,1.42],[9,11.5,3.72]],"id":44621159},{"bdatb":[[4,6,83.18],[5,5.9,9.66],[6,5.8,12.78],[7,5.7,67.4],[8,5.6,12.38],[9,5.5,25.37]],"id":44836671},{"bdatb":[[5,7,9],[6,6.8,1.32],[7,6.6,65.03],[8,6.4,6.07],[9,6.2,10.8]],"id":43885158},{"bdatl":[[0,28,5.73],[1,32,2.16],[2,34,5.6],[3,36,2.64],[4,38,2.51],[5,40,5.01],[6,80,1.66],[7,310,1],[8,990,2.15]],"id":46969227}]}]}
{"op":"mcm","clk":"AK87AIoeALIz","pt":1659347510545,"mc":[{"id":"1.201590187","rc":[{"atb":[[14.5,3.96]],"id":45323444}]}]}
{"op":"mcm","clk":"ALI7AIseALQz","pt":1659347510595,"mc":[{"id":"1.201590187","rc":[{"bdatb":[[1,14.5,3.96],[2,14,2.7],[3,12.5,1.14],[4,11.5,7.96],[5,11,3.51],[6,10.5,4.68],[7,10,13.01],[8,9.8,12.26],[9,9.6,23.33]],"id":45323444},{"bdatl":[[6,2.42,9.09],[7,2.44,157.06],[8,2.46,6.53],[9,2.48,3.98]],"id":9570503},{"bdatl":[[9,13.5,2.05]],"id":44836671}]}]}
{"op":"mcm","clk":"AL07AJMeALwz","pt":1659347510754,"mc":[{"id":"1.201590187","rc":[{"atb":[[23,2.47]],"id":44621159}]}]}
{"op":"mcm","clk":"AL47AJMeAMAz","pt":1659347510804,"mc":[{"id":"1.201590187","rc":[{"bdatl":[[5,2.4,73.53],[6,2.42,19.45],[7,2.44,154.81],[8,2.46,1.32],[9,2.5,24.37]],"id":9570503},{"bdatb":[[0,23,2.96],[1,22,1],[2,21,5],[3,20,1.93],[4,19.5,4.19],[5,18.5,2.1],[6,15.5,4.71],[7,14.5,1.37],[8,12.5,1.84],[9,12,1.42]],"id":44621159},{"bdatl":[[8,13,42.8],[9,13.5,1.55]],"id":44836671}]}]}
{"op":"mcm","clk":"AOw7AKYeAOYz","pt":1659347511443,"mc":[{"id":"1.201590187","rc":[{"atb":[[14.5,0]],"id":45323444},{"atb":[[23,0]],"id":44621159}]}]}
{"op":"mcm","clk":"AO87AKceAOkz","pt":1659347511493,"mc":[{"id":"1.201590187","rc":[{"bdatb":[[1,14,2.7],[2,12.5,1.14],[3,11.5,7.96],[4,11,3.51],[5,10.5,4.68],[6,10,13.01],[7,9.8,12.26],[8,9.6,23.33],[9,9.4,54.24]],"id":45323444},{"bdatl":[[5,2.4,72.22],[6,2.42,1.29],[7,2.44,159.83],[8,2.46,7.69],[9,2.5,21]],"id":9570503},{"bdatb":[[0,22,1.49],[1,21,5],[2,20,1.93],[3,19.5,4.19],[4,18.5,2.1],[5,15.5,4.71],[6,14.5,1.37],[7,12.5,1.84],[8,12,1.42],[9,11.5,3.72]],"id":44621159},{"bdatl":[[8,13,42.29]],"id":44836671}]}]}
{"op":"mcm","clk":"APQ7AKkeAOsz","pt":1659347511548,"mc":[{"id":"1.201590187","rc":[{"atb":[[6.2,0]],"id":12989514}]}]}
{"op":"mcm","clk":"APY7AKkeAO0z","pt":1659347511599,"mc":[{"id":"1.201590187","rc":[{"bdatb":[[2,6.2,2.12]],"id":12989514}]}]}
{"op":"mcm","clk":"AP07AKseAPAz","pt":1659347511650,"mc":[{"id":"1.201590187","rc":[{"atb":[[13,4.42]],"id":45323444}]}]}
{"op":"mcm","clk":"AIE8AKseAPEz","pt":1659347511700,"mc":[{"id":"1.201590187","rc":[{"bdatb":[[2,13,4.42],[3,12.5,1.14],[4,11.5,7.96],[5,11,3.51],[6,10.5,4.68],[7,10,13.01],[8,9.8,12.26],[9,9.6,23.33]],"id":45323444},{"bdatl":[[9,2.5,24.71]],"id":9570503}]}]}
{"op":"mcm","clk":"AIc8ALAeAPUz","pt":1659347511750,"mc":[{"id":"1.201590187","rc":[{"atb":[[22,3.59]],"id":44621159}]}]}
{"op":"mcm","clk":"AIo8ALAeAPYz","pt":1659347511800,"mc":[{"id":"1.201590187","rc":[{"bdatl":[[7,2.44,164.79],[8,2.46,2.76],[9,2.48,3.74]],"id":9570503},{"bdatb":[[0,22,4.08]],"id":44621159}]}]}
{"op":"mcm","clk":"AKI8ALceAII0","pt":1659347512048,"mc":[{"id":"1.201590187","rc":[{"atl":[[34,3.15]],"id":44621159}]}]}
{"op":"mcm","clk":"AKQ8ALoeAIQ0","pt":1659347512099,"mc":[{"id":"1.201590187","rc":[{"bdatb":[[8,9.8,14.68],[9,9.6,21]],"id":45323444},{"bdatb":[[7,5.3,9.83],[8,5.2,1.49],[9,5.1,6.35]],"id":12989514},{"bdatl":[[0,34,3.56]],"id":44621159},{"bdatb":[[8,6.4,6.7],[9,6.2,15.65]],"id":43885158},{"bdatb":[[9,11,1.64]],"id":46969227}]}]}
{"op":"mcm","clk":"AMI8AMYeAKQ0","pt":1659347512521,"mc":[{"id":"1.201590187","rc":[{"atb":[[13,0]],"id":45323444},{"atb":[[6.2,2.98]],"id":12989514},{"atb":[[22,1]],"id":44621159}]}]}
{"op":"mcm","clk":"AMM8AMceAKY0","pt":1659347512571,"mc":[{"id":"1.201590187","rc":[{"bdatb":[[2,12.5,1.14],[3,11.5,7.96],[4,11,3.51],[5,10.5,4.68],[6,10,13.01],[7,9.8,14.68],[8,9.6,21],[9,9.4,55.73]],"id":45323444},{"bdatl":[[7,2.44,159.83],[8,2.46,7.69],[9,2.5,21]],"id":9570503},{"bdatb":[[2,6.2,5.1]],"id":12989514},{"bdatb":[[0,22,1.49]],"id":44621159}]}]}
{"op":"mcm","clk":"AMs8ANIeAKw0","pt":1659347512726,"mc":[{"id":"1.201590187","rc":[{"atb":[[14.5,3.96]],"id":45323444}]}]}
{"op":"mcm","clk":"AMw8ANQeAK40","pt":1659347512776,"mc":[{"id":"1.201590187","rc":[{"bdatb":[[1,14.5,3.96],[2,14,2.7],[3,12.5,1.14],[4,11.5,7.96],[5,11,3.51],[6,10.5,4.68],[7,10,13.01],[8,9.8,14.68],[9,9.6,21]],"id":45323444},{"bdatl":[[6,2.42,9.09],[7,2.44,157.06],[8,2.46,6.53],[9,2.48,3.98]],"id":9570503},{"bdatl":[[9,13.5,2.05]],"id":44836671}]}]}
{"op":"mcm","clk":"ANE8ANkeALE0","pt":1659347512928,"mc":[{"id":"1.201590187","rc":[{"atb":[[23,2.47]],"id":44621159}]}]}
{"op":"mcm","clk":"ANE8ANseALQ0","pt":1659347512978,"mc":[{"id":"1.201590187","rc":[{"bdatl":[[5,2.4,73.53],[6,2.42,19.45],[7,2.44,154.81],[8,2.46,1.32],[9,2.5,24.37]],"id":9570503},{"bdatb":[[0,23,2.96],[1,22,1],[2,21,5],[3,20,1.93],[4,19.5,4.19],[5,18.5,2.1],[6,15.5,4.71],[7,14.5,1.37],[8,12.5,1.84],[9,12,1.42]],"id":44621159},{"bdatl":[[8,13,42.8],[9,13.5,1.55]],"id":44836671}]}]}
{"op":"mcm","clk":"APk8APkeAM00","pt":1659347513558,"mc":[{"id":"1.201590187","rc":[{"atb":[[6.2,0]],"id":12989514}]}]}
{"op":"mcm","clk":"APo8APseANA0","pt":1659347513608,"mc":[{"id":"1.201590187","rc":[{"bdatb":[[2,6.2,2.12]],"id":12989514}]}]}
{"op":"mcm","clk":"AIg9AIIfANk0","pt":1659347513720,"mc":[{"id":"1.201590187","rc":[{"atb":[[14.5,0]],"id":45323444},{"atb":[[23,0]],"id":44621159}]}]}
{"op":"mcm","clk":"AIk9AIMfAN00","pt":1659347513776,"mc":[{"id":"1.201590187","rc":[{"bdatb":[[1,14,2.7],[2,12.5,1.14],[3,11.5,7.96],[4,11,3.51],[5,10.5,4.68],[6,10,13.01],[7,9.8,14.68],[8,9.6,21],[9,9.4,55.73]],"id":45323444},{"bdatl":[[5,2.4,72.22],[6,2.42,1.29],[7,2.44,159.83],[8,2.46,7.69],[9,2.5,21]],"id":9570503},{"bdatb":[[0,22,1.49],[1,21,5],[2,20,1.93],[3,19.5,4.19],[4,18.5,2.1],[5,15.5,4.71],[6,14.5,1.37],[7,12.5,1.84],[8,12,1.42],[9,11.5,3.72]],"id":44621159},{"bdatl":[[8,13,42.29]],"id":44836671}]}]}
{"op":"mcm","clk":"AJk9AIwfAOQ0","pt":1659347513955,"mc":[{"id":"1.201590187","rc":[{"atb":[[13,4.42]],"id":45323444}]}]}
{"op":"mcm","clk":"AJw9AI0fAOU0","pt":1659347514005,"mc":[{"id":"1.201590187","rc":[{"bdatb":[[2,13,4.42],[3,12.5,1.14],[4,11.5,7.96],[5,11,3.51],[6,10.5,4.68],[7,10,13.01],[8,9.8,14.68],[9,9.6,21]],"id":45323444},{"bdatl":[[9,2.5,24.71]],"id":9570503}]}]}
{"op":"mcm","clk":"AJ89AJUfAPI0","pt":1659347514265,"mc":[{"id":"1.201590187","rc":[{"bdatl":[[7,2.44,164.79],[8,2.46,2.76],[9,2.48,3.74]],"id":9570503},{"bdatb":[[0,22,4.08]],"id":44621159}]}]}
{"op":"mcm","clk":"AK49AJYfAPM0","pt":1659347514315,"mc":[{"id":"1.201590187","rc":[{"atb":[[22,3.59]],"id":44621159}]}]}
{"op":"mcm","clk":"AME9AJ0fAIQ1","pt":1659347514530,"mc":[{"id":"1.201590187","rc":[{"atb":[[6.2,2.98]],"id":12989514}]}]}
{"op":"mcm","clk":"AMM9AJ4fAIU1","pt":1659347514580,"mc":[{"id":"1.201590187","rc":[{"bdatb":[[2,6.2,5.1]],"id":12989514}]}]}
{"op":"mcm","clk":"ANg9AKIfAJE1","pt":1659347514855,"mc":[{"id":"1.201590187","rc":[{"atb":[[13,0]],"id":45323444},{"atb":[[22,1]],"id":44621159}]}]}
{"op":"mcm","clk":"ANk9AKIfAJc1","pt":1659347514905,"mc":[{"id":"1.201590187","rc":[{"bdatb":[[2,12.5,1.14],[3,11.5,7.96],[4,11,3.51],[5,10.5,4.68],[6,10,13.01],[7,9.8,14.68],[8,9.6,21],[9,9.4,55.73]],"id":45323444},{"bdatl":[[7,2.44,159.83],[8,2.46,7.69],[9,2.5,21]],"id":9570503},{"bdatb":[[0,22,1.49]],"id":44621159}]}]}
{"op":"mcm","clk":"AN89AKYfAJk1","pt":1659347514955,"mc":[{"id":"1.201590187","rc":[{"atb":[[14.5,3.96]],"id":45323444}]}]}
{"op":"mcm","clk":"AOA9AKcfAJ01","pt":1659347515005,"mc":[{"id":"1.201590187","rc":[{"bdatb":[[1,14.5,3.96],[2,14,2.7],[3,12.5,1.14],[4,11.5,7.96],[5,11,3.51],[6,10.5,4.68],[7,10,13.01],[8,9.8,14.68],[9,9.6,21]],"id":45323444},{"bdatl":[[6,2.42,9.09],[7,2.44,157.06],[8,2.46,6.53],[9,2.48,3.98]],"id":9570503},{"bdatl":[[9,13.5,2.05]],"id":44836671}]}]}
{"op":"mcm","clk":"AOY9AKsfAKQ1","pt":1659347515149,"mc":[{"id":"1.201590187","rc":[{"atb":[[23,2.47]],"id":44621159}]}]}
{"op":"mcm","clk":"AOo9AK0fAKQ1","pt":1659347515199,"mc":[{"id":"1.201590187","rc":[{"bdatl":[[5,2.4,73.53],[6,2.42,19.45],[7,2.44,154.81],[8,2.46,1.32],[9,2.5,24.37]],"id":9570503},{"bdatb":[[0,23,2.96],[1,22,1],[2,21,5],[3,20,1.93],[4,19.5,4.19],[5,18.5,2.1],[6,15.5,4.71],[7,14.5,1.37],[8,12.5,1.84],[9,12,1.42]],"id":44621159},{"bdatl":[[8,13,42.8],[9,13.5,1.55]],"id":44836671}]}]}
{"op":"mcm","clk":"AIQ+ALkfALg1","pt":1659347515528,"mc":[{"id":"1.201590187","rc":[{"atb":[[6.2,0]],"id":12989514},{"atb":[[6,30.13]],"id":44836671}]}]}
{"op":"mcm","clk":"AIY+ALsfALo1","pt":1659347515578,"mc":[{"id":"1.201590187","rc":[{"bdatb":[[2,6.2,2.12]],"id":12989514},{"bdatb":[[4,6,31.47]],"id":44836671}]}]}
{"op":"mcm","clk":"AIk+ALwfAL81","pt":1659347515635,"mc":[{"id":"1.201590187","rc":[{"atb":[[9.4,0]],"id":46969227}]}]}
{"op":"mcm","clk":"AJQ+AMMfAMs1","pt":1659347515843,"mc":[{"id":"1.201590187","rc":[{"atb":[[14.5,0]],"id":45323444},{"atb":[[23,0]],"id":44621159}]}]}
{"op":"mcm","clk":"AJU+AMMfANM1","pt":1659347515893,"mc":[{"id":"1.201590187","rc":[{"bdatb":[[1,14,2.7],[2,12.5,1.14],[3,11.5,7.96],[4,11,3.51],[5,10.5,4.68],[6,10,13.01],[7,9.8,14.68],[8,9.6,21],[9,9.4,55.73]],"id":45323444},{"bdatl":[[5,2.4,72.22],[6,2.42,1.29],[7,2.44,159.83],[8,2.46,7.69],[9,2.5,21]],"id":9570503},{"bdatb":[[0,22,1.49],[1,21,5],[2,20,1.93],[3,19.5,4.19],[4,18.5,2.1],[5,15.5,4.71],[6,14.5,1.37],[7,12.5,1.84],[8,12,1.42],[9,11.5,3.72]],"id":44621159},{"bdatl":[[8,13,42.29]],"id":44836671}]}]}
{"op":"mcm","clk":"AJs+AMgfANU1","pt":1659347515948,"mc":[{"id":"1.201590187","rc":[{"atb":[[13,4.42]],"id":45323444}]}]}
{"op":"mcm","clk":"AJw+AMgfANg1","pt":1659347515998,"mc":[{"id":"1.201590187","rc":[{"bdatb":[[2,13,4.42],[3,12.5,1.14],[4,11.5,7.96],[5,11,3.51],[6,10.5,4.68],[7,10,13.01],[8,9.8,14.68],[9,9.6,21]],"id":45323444},{"bdatl":[[9,2.5,24.71]],"id":9570503}]}]}
{"op":"mcm","clk":"AJ8+AMsfANs1","pt":1659347516049,"mc":[{"id":"1.201590187","rc":[{"atb":[[22,3.59]],"id":44621159}]}]}
{"op":"mcm","clk":"AKE+AMsfAN41","pt":1659347516099,"mc":[{"id":"1.201590187","rc":[{"bdatl":[[7,2.44,164.79],[8,2.46,2.76],[9,2.48,3.74]],"id":9570503},{"bdatb":[[0,22,4.08]],"id":44621159}]}]}
{"op":"mcm","clk":"AKU+AM4fAOA1","pt":1659347516154,"mc":[{"id":"1.201590187","rc":[{"atb":[[5.7,83.06]],"id":44836671}]}]}
{"op":"mcm","clk":"AKY+AM4fAOY1","pt":1659347516204,"mc":[{"id":"1.201590187","rc":[{"bdatb":[[7,5.7,84.64]],"id":44836671}]}]}
{"op":"mcm","clk":"ALE+ANUfAO41","pt":1659347516368,"mc":[{"id":"1.201590187","rc":[{"atb":[[8.8,17.24]],"id":46969227}]}]}
{"op":"mcm","clk":"ALY+ANcfAPY1","pt":1659347516462,"mc":[{"id":"1.201590187","rc":[{"atl":[[2.36,0]],"id":9570503},{"atl":[[7,7]],"id":12989514},{"atl":[[13.5,0],[12.5,18]],"id":43885158},{"atl":[[38,0],[36,5.5]],"id":46969227}]}]}
{"op":"mcm","clk":"ALc+ANofAPo1","pt":1659347516512,"mc":[{"id":"1.201590187","rc":[{"bdatb":[[3,12.5,1.35],[4,12,2.11],[5,11.5,7.37],[6,11,1.78],[7,10.5,8.94],[8,10,13.22],[9,9.8,11.25]],"id":45323444},{"bdatb":[[1,2.04,13.4],[2,2.02,9.16],[3,2,1.24],[5,1.98,44.21],[6,1.97,9.43],[7,1.96,5.16],[8,1.95,9.82],[9,1.94,9.27]],"bdatl":[[4,2.36,4.22]],"id":9570503},{"bdatl":[[0,7,7],[1,7.2,7.36],[2,7.4,4.35],[3,7.6,7.33],[4,7.8,4.52],[5,8.4,2.08],[6,9,2.17],[7,9.2,4.82],[8,9.6,11.09],[9,10,17.36]],"id":12989514},{"bdatb":[[1,21,5.12],[2,20,2.47],[4,18.5,1.37],[5,15.5,5.96],[6,13,3.16],[7,12.5,1.27],[8,12,2.17],[9,11,2.92]],"id":44621159},{"bdatb":[[1,6.6,23.38],[2,6.4,9.67],[4,6,34.8],[5,5.9,9.85],[6,5.8,10],[7,5.7,84.13],[8,5.6,14.33],[9,5.5,29.15]],"id":44836671},{"bdatb":[[0,8,9.4],[1,7.8,1.63],[2,7.6,8.8],[4,7.2,7.6],[5,7,5.71],[6,6.6,67.59],[7,6.4,7.29],[8,6.2,14.19],[9,6,18.7]],"bdatl":[[5,12.5,18],[6,14,1],[7,14.5,1],[8,15,12],[9,15.5,1]],"id":43885158},{"bdatb":[[4,19.5,7.13],[6,16,2.16],[7,14,1.97],[8,12,3.43],[9,11.5,1.38]],"bdatl":[[3,36,5.5],[4,40,5.01],[5,80,1.66],[6,310,1],[7,990,2.15],[8,0,0]],"id":46969227}]}]}
{"op":"mcm","clk":"ALo+ANsfAP01","pt":1659347516562,"mc":[{"id":"1.201590187","rc":[{"atb":[[6.2,2.98]],"id":12989514}]}]}
{"op":"mcm","clk":"ALs+ANwfAP01","pt":1659347516612,"mc":[{"id":"1.201590187","rc":[{"bdatb":[[2,6.2,5.1]],"id":12989514}]}]}
{"op":"mcm","clk":"AMA+AN4fAIM2","pt":1659347516665,"mc":[{"id":"1.201590187","rc":[{"atb":[[6.6,1.14]],"atl":[[7,7.36],[8,0]],"id":12989514}]}]}
{"op":"mcm","clk":"AME+AOAfAIg2","pt":1659347516715,"mc":[{"id":"1.201590187","rc":[{"bdatb":[[5,11.5,7.59],[6,11,1.55],[7,10.5,9.18],[9,9.8,10.99]],"id":45323444},{"bdatb":[[7,1.96,6.45],[8,1.95,8.53]],"bdatl":[[4,2.36,3.19],[5,2.4,73.24]],"id":9570503},{"bdatb":[[0,6.6,1.14]],"bdatl":[[0,7,7.36],[5,8.4,1.76]],"id":12989514},{"bdatb":[[6,13,3.15],[7,12.5,1.47],[8,12,1.96],[9,11,2.91]],"id":44621159},{"bdatb":[[5,5.9,10.27],[7,5.7,83.69],[9,5.5,29.61]],"bdatl":[[7,12,2.04],[8,13,42.49]],"id":44836671},{"bdatb":[[5,7,6.07],[6,6.6,67.22],[7,6.4,7.68],[8,6.2,13.79]],"id":43885158},{"bdatb":[[9,11.5,1.6]],"id":46969227}]}]}
{"op":"mcm","clk":"AM4+AOcfAJE2","pt":1659347516834,"mc":[{"id":"1.201590187","rc":[{"atb":[[13,0]],"id":45323444},{"atb":[[6.6,1.52]],"id":12989514},{"atb":[[22,1]],"id":44621159}]}]}
{"op":"mcm","clk":"AM8+AOofAJQ2","pt":1659347516884,"mc":[{"id":"1.201590187","rc":[{"bdatb":[[2,12.5,1.35],[3,12,2.11],[4,11.5,7.59],[5,11,1.55],[6,10.5,9.18],[7,10,13.22],[8,9.8,10.99],[9,9.6,21.43]],"id":45323444},{"bdatl":[[4,2.36,4.25],[5,2.4,72.2],[7,2.44,159.83],[8,2.46,7.69],[9,2.5,21]],"id":9570503},{"bdatb":[[0,6.6,1.52]],"id":12989514},{"bdatb":[[0,22,1.49]],"id":44621159},{"bdatl":[[7,12,2.25],[8,13,42.29]],"id":44836671}]}]}
{"op":"mcm","clk":"AN4+APIfAKE2","pt":1659347517044,"mc":[{"id":"1.201590187","rc":[{"atb":[[14.5,3.96]],"id":45323444}]}]}
{"op":"mcm","clk":"AN8+APQfAKM2","pt":1659347517094,"mc":[{"id":"1.201590187","rc":[{"bdatb":[[1,14.5,3.96],[2,14,2.7],[3,12.5,1.35],[4,12,2.11],[5,11.5,7.59],[6,11,1.55],[7,10.5,9.18],[8,10,13.22],[9,9.8,10.99]],"id":45323444},{"bdatl":[[6,2.42,9.09],[7,2.44,157.06],[8,2.46,6.53],[9,2.48,3.98]],"id":9570503},{"bdatl":[[9,13.5,2.05]],"id":44836671}]}]}
{"op":"mcm","clk":"AOY+APUfAKc2","pt":1659347517144,"mc":[{"id":"1.201590187","rc":[{"atb":[[23,2.47]],"id":44621159}]}]}
{"op":"mcm","clk":"AOc+APgfAKk2","pt":1659347517194,"mc":[{"id":"1.201590187","rc":[{"bdatl":[[5,2.4,73.5],[6,2.42,19.45],[7,2.44,154.81],[8,2.46,1.32],[9,2.5,24.4]],"id":9570503},{"bdatb":[[0,23,2.96],[1,22,1],[2,21,5.12],[3,20,2.47],[4,19.5,4.19],[5,18.5,1.37],[6,15.5,5.96],[7,13,3.15],[8,12.5,1.47],[9,12,1.96]],"id":44621159},{"bdatl":[[8,13,42.8],[9,13.5,1.55]],"id":44836671}]}]}
{"op":"mcm","clk":"AP8+AIUgALY2","pt":1659347517563,"mc":[{"id":"1.201590187","rc":[{"atb":[[6.2,0]],"id":12989514}]}]}
{"op":"mcm","clk":"AIA/AIYgALk2","pt":1659347517613,"mc":[{"id":"1.201590187","rc":[{"bdatb":[[2,6.2,2.12]],"id":12989514}]}]}
{"op":"mcm","clk":"AI0/AJIgAMo2","pt":1659347517870,"mc":[{"id":"1.201590187","rc":[{"atb":[[14.5,0]],"id":45323444},{"atb":[[23,0]],"id":44621159}]}]}
{"op":"mcm","clk":"AJM/AJUgAM82","pt":1659347517920,"mc":[{"id":"1.201590187","rc":[{"bdatb":[[1,14,2.7],[2,12.5,1.35],[3,12,2.11],[4,11.5,7.59],[5,11,1.55],[6,10.5,9.18],[7,10,13.22],[8,9.8,10.99],[9,9.6,21.43]],"id":45323444},{"bdatl":[[5,2.4,72.2],[6,2.42,1.29],[7,2.44,159.83],[8,2.46,7.69],[9,2.5,21]],"id":9570503},{"bdatb":[[0,22,1.49],[1,21,5.12],[2,20,2.47],[3,19.5,4.19],[4,18.5,1.37],[5,15.5,5.96],[6,13,3.15],[7,12.5,1.47],[8,12,1.96],[9,11,2.91]],"id":44621159},{"bdatl":[[8,13,42.29]],"id":44836671}]}]}
{"op":"mcm","clk":"AJo/AJogANk2","pt":1659347518035,"mc":[{"id":"1.201590187","rc":[{"atb":[[13,4.42]],"id":45323444},{"atb":[[7,7.64]],"id":44836671}]}]}
{"op":"mcm","clk":"AJs/AJsgAN02","pt":1659347518085,"mc":[{"id":"1.201590187","rc":[{"bdatb":[[2,13,4.42],[3,12.5,1.35],[4,12,2.11],[5,11.5,7.59],[6,11,1.55],[7,10.5,9.18],[8,10,13.22],[9,9.8,10.99]],"id":45323444},{"bdatl":[[4,2.34,4.29],[5,2.38,2.09],[6,2.4,71.43],[7,2.42,12.81],[8,2.44,154.88],[9,2.5,24.71]],"id":9570503},{"bdatb":[[0,7,7.64],[1,6.8,20.43],[2,6.6,23.38],[3,6.4,9.67],[4,6.2,6.15],[5,6,34.8],[6,5.9,10.27],[7,5.8,10],[8,5.7,83.69],[9,5.6,14.33]],"id":44836671},{"bdatl":[[8,15,12.67]],"id":43885158}]}]}
{"op":"mcm","clk":"AJw/AJwgAOA2","pt":1659347518138,"mc":[{"id":"1.201590187","rc":[{"bdatl":[[9,2.48,1.3]],"id":9570503},{"bdatb":[[0,7,8],[5,6,34.41]],"id":44836671}]}]}
{"op":"mcm","clk":"AJ4/AJ4gAOQ2","pt":1659347518188,"mc":[{"id":"1.201590187","rc":[{"atb":[[7,8],[6,29.74]],"id":44836671}]}]}
{"op":"mcm","clk":"AKI/AKAgAOc2","pt":1659347518239,"mc":[{"id":"1.201590187","rc":[{"atb":[[22,3.59]],"id":44621159}]}]}
{"op":"mcm","clk":"AKM/AKIgAOk2","pt":1659347518289,"mc":[{"id":"1.201590187","rc":[{"bdatl":[[7,2.42,15.62],[8,2.44,152.09],[9,2.46,1.31]],"id":9570503},{"bdatb":[[0,22,4.08]],"id":44621159}]}]}
{"op":"mcm","clk":"ALI/ALEgAPo2","pt":1659347518557,"mc":[{"id":"1.201590187","rc":[{"atb":[[6.2,2.98]],"id":12989514}]}]}
{"op":"mcm","clk":"ALM/ALEgAP02","pt":1659347518608,"mc":[{"id":"1.201590187","rc":[{"bdatb":[[2,6.2,5.1]],"id":12989514}]}]}
{"op":"mcm","clk":"ALc/ALYgAP82","pt":1659347518658,"mc":[{"id":"1.201590187","rc":[{"atb":[[6.4,6.37]],"id":44836671}]}]}
{"op":"mcm","clk":"ALg/ALYgAIM3","pt":1659347518708,"mc":[{"id":"1.201590187","rc":[{"bdatb":[[3,6.4,6.37]],"id":44836671}]}]}
{"op":"mcm","clk":"AMI/AL4gAIw3","pt":1659347518860,"mc":[{"id":"1.201590187","rc":[{"atb":[[1.99,1.25]],"id":9570503}]}]}
{"op":"mcm","clk":"AMQ/AL4gAI83","pt":1659347518910,"mc":[{"id":"1.201590187","rc":[{"bdatb":[[4,1.99,1.25]],"id":9570503}]}]}
{"op":"mcm","clk":"AMY/AMAgAJE3","pt":1659347518962,"mc":[{"id":"1.201590187","rc":[{"atb":[[2.06,27.86]],"id":9570503}]}]}
{"op":"mcm","clk":"AMc/AMEgAJQ3","pt":1659347519013,"mc":[{"id":"1.201590187","rc":[{"bdatb":[[0,2.06,27.86]],"id":9570503}]}]}
{"op":"mcm","clk":"AMs/AMcgAJg3","pt":1659347519076,"mc":[{"id":"1.201590187","rc":[{"atb":[[13,0]],"id":45323444},{"atb":[[1.97,0],[2.06,29.06],[1.98,36.93]],"id":9570503},{"atb":[[22,1]],"id":44621159}]}]}
{"op":"mcm","clk":"AM0/AMcgAJs3","pt":1659347519126,"mc":[{"id":"1.201590187","rc":[{"bdatb":[[2,12.5,1.35],[3,12,2.11],[4,11.5,7.59],[5,11,1.55],[6,10.5,9.18],[7,10,13.22],[8,9.8,10.99],[9,9.6,21.43]],"id":45323444},{"bdatb":[[0,2.06,29.06],[5,1.98,42.95],[6,1.97,8.17]],"bdatl":[[7,2.42,12.81],[8,2.44,154.88],[9,2.5,22.29]],"id":9570503},{"bdatb":[[0,22,1.49]],"id":44621159}]}]}
{"op":"mcm","clk":"ANU/ANAgAJ03","pt":1659347519268,"mc":[{"id":"1.201590187","rc":[{"atb":[[14.5,3.96]],"id":45323444}]}]}
{"op":"mcm","clk":"ANU/ANEgAKI3","pt":1659347519318,"mc":[{"id":"1.201590187","rc":[{"bdatb":[[1,14.5,3.96],[2,14,2.7],[3,12.5,1.35],[4,12,2.11],[5,11.5,7.59],[6,11,1.55],[7,10.5,9.18],[8,10,13.22],[9,9.8,10.99]],"id":45323444},{"bdatl":[[6,2.4,79.29],[7,2.42,9.15],[8,2.44,152.09],[9,2.46,2.46]],"id":9570503},{"bdatl":[[9,13.5,2.95]],"id":44836671}]}]}
{"op":"mcm","clk":"AN8/ANYgAKY3","pt":1659347519428,"mc":[{"id":"1.201590187","rc":[{"atb":[[23,2.47]],"id":44621159}]}]}
{"op":"mcm","clk":"AOM/ANcgAKk3","pt":1659347519478,"mc":[{"id":"1.201590187","rc":[{"bdatl":[[6,2.4,88.52],[7,2.42,2.5],[8,2.44,154.81],[9,2.46,1.32]],"id":9570503},{"bdatb":[[0,23,2.96],[1,22,1],[2,21,5.12],[3,20,2.47],[4,19.5,4.19],[5,18.5,1.37],[6,15.5,5.96],[7,13,3.15],[8,12.5,1.47],[9,12,1.96]],"id":44621159},{"bdatl":[[8,13,44.67],[9,13.5,2.58]],"id":44836671}]}]}
{"op":"mcm","clk":"AOs/ANogAK83","pt":1659347519544,"mc":[{"id":"1.201590187","rc":[{"atb":[[6.2,0]],"id":12989514},{"atl":[[28,7.73]],"id":46969227}]}]}
{"op":"mcm","clk":"AOw/ANsgAK83","pt":1659347519594,"mc":[{"id":"1.201590187","rc":[{"bdatb":[[2,6.2,2.12],[9,5.1,8.25]],"id":12989514},{"bdatl":[[0,28,7.73]],"id":46969227}]}]}
{"op":"mcm","clk":"API/AOIgALo3","pt":1659347519750,"mc":[{"id":"1.201590187","rc":[{"atb":[[6.4,0.37]],"id":44836671},{"atl":[[9.4,0.27]],"id":43885158},{"atl":[[36,2.86]],"id":46969227}]}]}
{"op":"mcm","clk":"APM/AOIgALw3","pt":1659347519800,"mc":[{"id":"1.201590187","rc":[{"bdatb":[[4,11.5,9.75],[5,11,1.55],[6,10.5,9.18],[7,10,13.22],[8,9.8,9.82],[9,9.6,21]],"id":45323444},{"bdatb":[[1,2.04,8.22],[2,2.02,14.39],[5,1.98,40.98],[6,1.97,10.15]],"id":9570503},{"bdatb":[[2,6,2.66],[3,5.6,5],[4,5.5,2.02],[5,5.4,2.42],[6,5.3,9.83],[7,5.2,1.49],[8,5.1,3.28],[9,4.9,8.47]],"id":12989514},{"bdatb":[[3,20,1.8],[5,18.5,2.08],[6,15.5,6]],"id":44621159},{"bdatb":[[2,6.6,21.34],[3,6.4,2.47]],"id":44836671},{"bdatl":[[0,9.6,15.08],[1,10.5,3.28],[2,11.5,2.89],[3,12,1.4],[4,12.5,18],[5,14,1],[6,14.5,1],[7,15,12.67],[8,15.5,1],[9,16.5,9.24]],"id":43885158},{"bdatb":[[6,16,2.2],[7,14,2]],"bdatl":[[3,36,2.86]],"id":46969227}]}]}
{"op":"mcm","clk":"APU/AOUgAL83","pt":1659347519850,"mc":[{"id":"1.201590187","rc":[{"atb":[[2.04,4.55]],"id":9570503},{"atl":[[10,2.34]],"id":43885158}]}]}
{"op":"mcm","clk":"APY/AOcgAMA3","pt":1659347519900,"mc":[{"id":"1.201590187","rc":[{"bdatb":[[1,2.04,5.82]],"id":9570503},{"bdatb":[[9,5,4.68]],"id":12989514},{"bdatl":[[1,10,2.34],[2,10.5,3.28],[3,11.5,2.89],[4,12,1.4],[5,12.5,18],[6,14,1],[7,14.5,1],[8,15,12.67],[9,15.5,1]],"id":43885158}]}]}
{"op":"mcm","clk":"APg/AOogAMY3","pt":1659347519960,"mc":[{"id":"1.201590187","rc":[{"atb":[[2.06,31.43]],"id":9570503}]}]}
{"op":"mcm","clk":"APw/AOwgAMk3","pt":1659347520012,"mc":[{"id":"1.201590187","rc":[{"bdatb":[[0,2.06,31.43]],"id":9570503},{"bdatl":[[9,13.5,2.74]],"id":44836671}]}]}
{"op":"mcm","clk":"AI5AAPsgANc3","pt":1659347520282,"mc":[{"id":"1.201590187","rc":[{"atb":[[14.5,0]],"id":45323444},{"atb":[[6.6,0],[6.4,9.43]],"trd":[[6.6,3.05],[6.4,19.92]],"ltp":6.4,"tv":60.16,"id":12989514},{"atb":[[23,0]],"id":44621159}],"tv":1190.63}]}
{"op":"mcm","clk":"AJFAAPwgANg3","pt":1659347520332,"mc":[{"id":"1.201590187","rc":[{"bdatb":[[1,14,2.7],[2,12.5,1.35],[3,11.5,9.75],[4,11,1.55],[5,10.5,9.18],[6,10,13.22],[7,9.8,9.82],[8,9.6,21],[9,9.4,55.32]],"id":45323444},{"bdatl":[[4,2.36,5.03],[5,2.38,1.31],[6,2.4,71.43],[7,2.42,12.81],[8,2.44,154.88],[9,2.5,22.29]],"id":9570503},{"bdatb":[[0,6.4,9.43],[1,6,2.66],[2,5.6,5],[3,5.5,2.02],[4,5.4,2.42],[5,5.3,9.83],[6,5.2,1.49],[7,5.1,3.28],[8,5,4.68],[9,4.9,3.69]],"id":12989514},{"bdatb":[[0,22,1.49],[1,21,5.12],[2,20,1.8],[3,19.5,4.19],[4,18.5,2.08],[5,15.5,6],[6,13,3.15],[7,12.5,1.47],[8,12,1.96],[9,11,1.49]],"id":44621159},{"bdatl":[[7,12,1.41],[8,13,43.09],[9,13.5,1.55]],"id":44836671},{"bdatl":[[8,15,12]],"id":43885158}]}]}
{"op":"mcm","clk":"AJVAAP4gANs3","pt":1659347520382,"mc":[{"id":"1.201590187","rc":[{"atb":[[15,2]],"atl":[[19.5,1.41]],"bdatb":[[0,15,2],[7,9.8,9],[8,9.6,21.61],[9,9.4,54.32]],"bdatl":[[1,19.5,1.41],[2,20,1],[3,21,1.15],[4,23,2.64],[5,25,5.61],[6,26,5.04],[7,27,3.85],[8,29,5.36],[9,32,3.23]],"id":45323444},{"atb":[[22,0]],"atl":[[55,0],[36,0]],"bdatb":[[0,21,5.61],[1,20,1.8],[2,19.5,4.19],[3,18.5,2.08],[4,15.5,6.48],[5,13,4.02],[6,12,2.68],[7,10.5,2.91],[8,10,103.11],[9,9.6,1.68]],"bdatl":[[1,40,3.86],[2,95,2],[3,120,7.2],[4,170,2],[5,990,2.07],[6,0,0]],"id":44621159},{"bdatb":[[5,1.98,50.83],[6,1.97,4.06],[7,1.96,2.62],[8,1.95,18.53],[9,1.94,8.69]],"bdatl":[[5,2.4,78.98],[6,2.42,6.61],[7,2.44,156.2],[8,2.46,1.76],[9,2.5,21]],"id":9570503},{"bdatb":[[2,5.6,6.98],[3,5.4,6.03],[4,5.3,6.15],[5,5.2,4.3],[6,4.9,6.74],[7,4.8,9.22],[8,4.7,7.34],[9,4.5,233.58]],"id":12989514},{"bdatb":[[5,6,35.66],[6,5.9,9],[7,5.8,10.62],[8,5.7,84.54],[9,5.6,16.31]],"bdatl":[[8,13,42.85],[9,13.5,2.9]],"id":44836671},{"bdatb":[[4,7.2,8.64],[5,7,5.51],[6,6.6,69.65],[7,6.4,4.81],[8,6.2,15.01],[9,6,15.8]],"id":43885158},{"bdatb":[[7,14,2.54],[8,12,4.37],[9,11,1.43]],"id":46969227}]}]}
{"op":"mcm","clk":"AJlAAP8gAOE3","pt":1659347520443,"mc":[{"id":"1.201590187","rc":[{"atb":[[13,4.42]],"id":45323444},{"atb":[[6.4,9.81]],"id":12989514},{"atl":[[44,0.64]],"id":44621159}]}]}
{"op":"mcm","clk":"AJtAAIAhAOI3","pt":1659347520494,"mc":[{"id":"1.201590187","rc":[{"bdatb":[[2,13,4.42],[3,12.5,1.35],[4,11.5,9.75],[5,11,1.55],[6,10.5,9.18],[7,10,13.22],[8,9.8,9],[9,9.6,21.61]],"id":45323444},{"bdatl":[[8,2.46,2.46],[9,2.5,21.29]],"id":9570503},{"bdatb":[[0,6.4,9.81]],"id":12989514},{"bdatl":[[2,95,2.64]],"id":44621159}]}]}
{"op":"mcm","clk":"AKFAAIQhAOU3","pt":1659347520549,"mc":[{"id":"1.201590187","rc":[{"atb":[[6,14.05],[6.2,2.98]],"id":12989514}]}]}
{"op":"mcm","clk":"AKJAAIQhAOU3","pt":1659347520599,"mc":[{"id":"1.201590187","rc":[{"bdatb":[[1,6.2,3.39],[2,6,16.28],[3,5.6,6.98],[4,5.4,6.03],[5,5.3,6.15],[6,5.2,4.3],[7,4.9,6.74],[8,4.8,9.22],[9,4.7,7.34]],"id":12989514}]}]}
{"op":"mcm","clk":"AKhAAIchAOs3","pt":1659347520676,"mc":[{"id":"1.201590187","rc":[{"atb":[[22,2.59]],"id":44621159}]}]}
{"op":"mcm","clk":"AKlAAIchAO43","pt":1659347520726,"mc":[{"id":"1.201590187","rc":[{"bdatl":[[5,2.38,7.62],[6,2.4,71.43],[7,2.42,10.75],[8,2.44,152.09],[9,2.46,2.46]],"id":9570503},{"bdatb":[[0,22,3.08],[1,21,5.12],[2,20,1.8],[3,19.5,4.19],[4,18.5,2.08],[5,15.5,6.48],[6,13,4.02],[7,12,2.68],[8,10.5,2.91],[9,10,103.11]],"id":44621159},{"bdatl":[[8,13,44.24],[9,13.5,1.55]],"id":44836671}]}]}
{"op":"mcm","clk":"ALdAAJAhAIE4","pt":1659347520966,"mc":[{"id":"1.201590187","rc":[{"atl":[[1000,3.34]],"id":12989514}]}]}
{"op":"mcm","clk":"AMJAAJohAI84","pt":1659347521186,"mc":[{"id":"1.201590187","rc":[{"atl":[[34,1.15]],"id":44621159}]}]}
{"op":"mcm","clk":"AMNAAJwhAJQ4","pt":1659347521236,"mc":[{"id":"1.201590187","rc":[{"bdatb":[[5,11,1.29],[6,10.5,4.75],[7,10,14.94],[8,9.8,12.28],[9,9.6,21]],"id":45323444},{"bdatb":[[8,1.94,6.18],[9,1.93,12.5]],"id":9570503},{"bdatb":[[3,5.6,6.47],[4,5.4,2.08],[5,5.3,4.55],[6,5.2,3.46],[7,5.1,7.66],[8,4.9,6.32],[9,4.8,9.22]],"id":12989514},{"bdatl":[[0,34,1.56]],"id":44621159},{"bdatb":[[7,5.8,10.12],[8,5.7,83.57],[9,5.6,13.5]],"id":44836671},{"bdatb":[[5,7,5.1],[6,6.6,66.41],[7,6.4,8.41],[8,6.2,10.18],[9,6,20.98]],"id":43885158},{"bdatb":[[8,11.5,3.08],[9,11,1.53]],"id":46969227}]}]}
{"op":"mcm","clk":"AM1AAJ4hAJ04","pt":1659347521375,"mc":[{"id":"1.201590187","rc":[{"atb":[[13,0]],"id":45323444},{"atl":[[1000,0.47]],"id":12989514},{"atb":[[23,1]],"atl":[[32,1.41]],"id":44621159},{"atb":[[7,0.36]],"id":44836671}]}]}
{"op":"mcm","clk":"AM5AAJ4hAJ44","pt":1659347521425,"mc":[{"id":"1.201590187","rc":[{"bdatb":[[2,12.5,1.35],[3,12,3.55],[4,11.5,6.09],[5,11,1.55],[6,10.5,7.25],[7,10,12.24],[8,9.8,12.07]],"id":45323444},{"bdatb":[[5,1.98,51.66],[6,1.97,3.23],[8,1.95,16.77],[9,1.93,10.51]],"bdatl":[[4,2.36,1.07],[5,2.4,82.88],[6,2.42,2.01],[7,2.44,156.65],[8,2.46,6.53],[9,2.5,23.3]],"id":9570503},{"bdatb":[[3,5.7,4.83],[4,5.6,2.07],[5,5.4,5.39],[6,5.2,4.29],[7,5.1,7.47]],"id":12989514},{"bdatb":[[0,23,1.49],[1,22,2.59],[2,21,5.12],[3,20,1.8],[4,19.5,4.19],[5,18.5,2.08],[6,15.5,6.48],[7,13,4.02],[8,12,2.68],[9,10.5,2.91]],"bdatl":[[0,32,1.41],[1,34,1.15],[2,40,3.86],[3,95,2.64],[4,120,7.2],[5,170,2],[6,990,2.07]],"id":44621159},{"bdatb":[[0,6.8,20.79],[1,6.6,21.34],[2,6.4,2.47],[3,6.2,6.15],[4,6,35.66],[5,5.9,9],[6,5.8,10.62],[7,5.7,84.54],[8,5.6,15.7],[9,5.5,23.62]],"bdatl":[[9,13.5,1.91]],"id":44836671},{"bdatb":[[0,8,9.76],[1,7.8,1.26],[5,7,5.51],[6,6.6,69.13],[7,6.4,5.17],[8,6.2,10.34],[9,6,20.82]],"id":43885158},{"bdatb":[[7,14.5,2.01],[8,12.5,1.41],[9,12,1.73]],"id":46969227}]}]}
{"op":"mcm","clk":"ANdAAKEhAK04","pt":1659347521545,"mc":[{"id":"1.201590187","rc":[{"atb":[[14.5,3.96]],"id":45323444},{"atb":[[6.2,0]],"id":12989514},{"atb":[[8.2,7.01]],"id":43885158}]}]}
{"op":"mcm","clk":"ANdAAKEhAK04","pt":1659347521596,"mc":[{"id":"1.201590187","rc":[{"bdatb":[[1,14.5,3.96],[2,14,2.7],[3,12.5,1.35],[4,12,3.55],[5,11.5,6.09],[6,11,1.55],[7,10.5,7.25],[8,10,12.24],[9,9.8,12.07]],"id":45323444},{"bdatl":[[5,2.38,11.55],[6,2.4,78.1],[7,2.42,4.75],[8,2.44,154.26],[9,2.5,30.88]],"id":9570503},{"bdatb":[[1,6,16.7],[2,5.7,4.83],[3,5.6,2.07],[4,5.4,5.39],[5,5.2,4.29],[6,5.1,7.47],[7,4.9,6.32],[8,4.8,9.22],[9,4.7,7.34]],"id":12989514},{"bdatl":[[7,12,2.4],[8,12.5,1.86],[9,13,42.73]],"id":44836671},{"bdatb":[[0,8.2,7.33],[1,8,9.44],[2,7.8,1.26],[3,7.6,8.8],[4,7.4,2.32],[5,7.2,8.64],[6,7,5.51],[7,6.6,69.13],[8,6.4,5.17],[9,6.2,10.34]],"id":43885158}]}]}
{"op":"mcm","clk":"ANtAAKUhALE4","pt":1659347521671,"mc":[{"id":"1.201590187","rc":[{"atb":[[1.71,140.85],[1.62,0]],"id":9570503},{"atl":[[7.6,0.33],[6.8,8]],"id":12989514},{"atb":[[8.2,7.31]],"id":43885158}]}]}
{"op":"mcm","clk":"AN1AAKkhALM4","pt":1659347521722,"mc":[{"id":"1.201590187","rc":[{"bdatb":[[3,12.5,4.74],[4,11.5,6.37],[5,11,3.87],[6,10.5,6.54],[7,10,13.88],[8,9.8,10.45],[9,9.6,21]],"id":45323444},{"bdatb":[[0,2.06,32.69],[1,2.04,11.13],[2,2.02,7.75],[3,2,15],[4,1.99,6.72],[5,1.98,36.93],[6,1.97,4.63],[7,1.96,13.18],[8,1.95,1.76],[9,1.94,9.27]],"bdatl":[[7,2.42,5.76],[8,2.44,153.25]],"id":9570503},{"bdatl":[[0,6.8,8],[1,7,7.36],[2,7.2,7.36],[3,7.4,4.35],[4,7.8,4.85]],"id":12989514},{"bdatb":[[0,23,1.6],[2,21,5.64],[5,18.5,1.37],[6,17,1.62],[7,15.5,4.9],[8,14,2.3],[9,13.5,1.33]],"id":44621159},{"bdatb":[[0,6.8,21.16],[1,6.6,23],[2,6.2,11.22],[3,6,31.4],[4,5.9,9],[5,5.8,11.45],[6,5.7,86.7],[7,5.6,15.82],[8,5.5,23.05],[9,5.4,14.13]],"id":44836671},{"bdatb":[[0,8.2,9.26],[1,8,7.76],[3,7.6,12.42],[4,7.4,3.79],[5,7.2,3.8],[6,7,5],[7,6.8,4.28],[8,6.6,67.96],[9,6.4,2.04]],"id":43885158},{"bdatb":[[2,21,5.72],[3,20,5.52],[4,19.5,7],[5,19,5.71],[6,16,1.43],[7,15.5,1.88],[8,13,1.32],[9,12.5,1.66]],"id":46969227}]}]}
{"op":"mcm","clk":"AOhAAK4hALs4","pt":1659347521874,"mc":[{"id":"1.201590187","rc":[{"atb":[[6.4,9.8]],"atl":[[7.8,4.19],[6.8,8.37]],"trd":[[6.4,19.94]],"tv":60.18,"id":12989514}],"tv":1190.65}]}
{"op":"mcm","clk":"AOtAAK8hAMA4","pt":1659347521925,"mc":[{"id":"1.201590187","rc":[{"bdatb":[[4,11.5,6.52],[5,11,3.71],[6,10.5,6.78],[7,10,13.63],[8,9.8,10.71]],"id":45323444},{"bdatb":[[4,1.99,7.99],[6,1.97,3.35]],"bdatl":[[8,2.44,153.23],[9,2.5,30.91]],"id":9570503},{"bdatb":[[0,6.4,9.8]],"bdatl":[[0,6.8,8.37],[4,7.8,4.52]],"id":12989514},{"bdatb":[[7,15.5,5.01],[8,14,2.17]],"id":44621159},{"bdatb":[[3,6,31.7],[5,5.8,11.14],[8,5.5,23.51],[9,5.4,14]],"id":44836671},{"bdatb":[[4,7.4,3.89],[5,7.2,3.71],[6,7,5.26],[7,6.8,4.02],[9,6.4,2.44]],"id":43885158},{"bdatb":[[8,13,1.3]],"id":46969227}]}]}
{"op":"mcm","clk":"APJAALEhAMI4","pt":1659347521975,"mc":[{"id":"1.201590187","rc":[{"atb":[[6.4,7.28]],"trd":[[6.4,24.98]],"tv":65.22,"id":12989514},{"atl":[[44,0]],"id":44621159}],"tv":1195.69}]}
{"op":"mcm","clk":"APZAALIhAMI4","pt":1659347522026,"mc":[{"id":"1.201590187","rc":[{"bdatl":[[7,2.44,152.33],[8,2.48,5.38],[9,2.5,32.02]],"id":9570503},{"bdatb":[[0,6.4,7.28]],"id":12989514},{"bdatl":[[3,95,2]],"id":44621159}]}]}
{"op":"mcm","clk":"APtAALUhAMo4","pt":1659347522077,"mc":[{"id":"1.201590187","rc":[{"atl":[[46,0.64]],"id":44621159}]}]}
{"op":"mcm","clk":"AP5AALchAMo4","pt":1659347522128,"mc":[{"id":"1.201590187","rc":[{"bdatl":[[3,95,2.64]],"id":44621159}]}]}
{"op":"mcm","clk":"AIRBALohAM84","pt":1659347522178,"mc":[{"id":"1.201590187","rc":[{"atb":[[6.4,6.9]],"id":12989514}]}]}
{"op":"mcm","clk":"AIdBALshANE4","pt":1659347522228,"mc":[{"id":"1.201590187","rc":[{"bdatl":[[6,2.4,77.33],[7,2.44,152.09],[8,2.48,6.36]],"id":9570503},{"bdatb":[[0,6.4,6.9]],"id":12989514},{"bdatl":[[9,13,42.59]],"id":44836671}]}]}
{"op":"mcm","clk":"AI9BAMIhANk4","pt":1659347522373,"mc":[{"id":"1.201590187","rc":[{"atb":[[14.5,0]],"id":45323444},{"atb":[[22,0]],"id":44621159}]}]}
{"op":"mcm","clk":"AJJBAMIhANs4","pt":1659347522423,"mc":[{"id":"1.201590187","rc":[{"bdatb":[[1,14,2.7],[2,12.5,4.74],[3,11.5,6.52],[4,11,3.71],[5,10.5,6.78],[6,10,13.63],[7,9.8,10.71],[8,9.6,21],[9,9.4,54.81]],"id":45323444},{"bdatl":[[6,2.4,71.43],[7,2.42,2.01],[8,2.44,155.9],[9,2.5,21.74]],"id":9570503},{"bdatb":[[1,21,5.64],[2,20,1.8],[3,19.5,4.19],[4,18.5,1.37],[5,17,1.62],[6,15.5,5.01],[7,14,2.17],[8,13.5,1.33],[9,12.5,3.12]],"id":44621159},{"bdatl":[[8,12.5,1.47],[9,13,42.25]],"id":44836671}]}]}
{"op":"mcm","clk":"AJdBAMYhAN44","pt":1659347522473,"mc":[{"id":"1.201590187","rc":[{"atb":[[4.7,0]],"id":12989514},{"atl":[[46,0]],"id":44621159}]}]}
{"op":"mcm","clk":"AJlBAMYhAOE4","pt":1659347522530,"mc":[{"id":"1.201590187","rc":[{"bdatb":[[9,4.5,233.58]],"id":12989514},{"bdatl":[[3,95,2]],"id":44621159}]}]}
{"op":"mcm","clk":"AJ1BAMwhAOQ4","pt":1659347522580,"mc":[{"id":"1.201590187","rc":[{"atb":[[15,4.85]],"atl":[[20,0]],"id":45323444},{"atb":[[6,0],[6.2,7.34]],"id":12989514},{"atl":[[48,0.64]],"id":44621159}]}]}
{"op":"mcm","clk":"AJ5BAMwhAOg4","pt":1659347522631,"mc":[{"id":"1.201590187","rc":[{"bdatb":[[0,15,4.85]],"bdatl":[[2,21,1.15],[3,23,2.64],[4,25,5.61],[5,26,5.04],[6,27,3.85],[7,29,5.36],[8,32,3.23],[9,50,8]],"id":45323444},{"bdatb":[[4,1.99,1.25],[5,1.98,43.7],[6,1.96,8.09],[7,1.95,8.5],[8,1.93,12.54],[9,1.91,117.34]],"bdatl":[[5,2.38,13.59],[6,2.4,75.3],[7,2.44,158.56],[8,2.46,5.21],[9,2.5,27.76]],"id":9570503},{"bdatb":[[1,6.2,7.76],[2,6,2.24],[3,5.7,4.83],[4,5.5,2.1],[5,5.4,2.32],[6,5.3,3.13],[7,5.2,4.3],[8,5.1,4.1],[9,5,3.44]],"id":12989514},{"bdatb":[[6,15.5,4.91],[7,13.5,2.22],[8,13,1.75],[9,12.5,1.52]],"bdatl":[[3,95,2.64]],"id":44621159},{"bdatb":[[2,6.2,10.96],[3,6,31.67],[4,5.9,9.31],[5,5.8,10],[6,5.7,87.86],[7,5.6,12.25],[8,5.5,27.15]],"bdatl":[[8,12.5,1.86],[9,13,42.59]],"id":44836671},{"bdatb":[[4,7.4,2.54],[5,7.2,5.09],[7,6.8,1.58],[8,6.6,67.44],[9,6.4,5.56]],"id":43885158},{"bdatb":[[7,15.5,1.78],[8,12.5,3.11],[9,11.5,2.1]],"id":46969227}]}]}
{"op":"mcm","clk":"AKJBANAhAOw4","pt":1659347522681,"mc":[{"id":"1.201590187","rc":[{"atl":[[16,0.84]],"trd":[[16,2.16]],"tv":12.5,"id":45323444},{"atl":[[2.12,24.77]],"trd":[[2.12,93.85]],"ltp":2.12,"tv":765.97,"id":9570503},{"atl":[[6.8,7.99]],"trd":[[6.8,0.38]],"ltp":6.8,"tv":65.6,"id":12989514},{"atb":[[23,3.47]],"atl":[[32,1.33]],"trd":[[32,0.08]],"ltp":32,"tv":2.08,"id":44621159},{"atl":[[7.4,0]],"trd":[[7.4,39.58]],"tv":187.45,"id":44836671},{"atb":[[8.2,6.62]],"trd":[[8.4,5.85],[8.2,3.22]],"ltp":8.2,"tv":124.15,"id":43885158},{"atl":[[28,7.64]],"trd":[[28,12.33]],"ltp":28,"tv":41.91,"id":46969227}],"tv":1199.66}]}
{"op":"mcm","clk":"AKVBANAhAO84","pt":1659347522731,"mc":[{"id":"1.201590187","rc":[{"bdatb":[[2,12.5,4.53],[3,11.5,6.53],[4,11,3.7],[5,10.5,6.79],[6,10,13.89],[7,9.8,10.44],[9,9.4,55.08]],"bdatl":[[0,19.5,2.25],[1,21,1.15],[2,23,2.64],[3,25,5.61],[4,26,5.04],[5,27,3.85],[6,29,5.36],[7,32,3.23],[8,50,8],[9,55,9]],"id":45323444},{"bdatb":[[0,2.06,31.43],[1,2.04,11.14],[5,1.98,43.69],[6,1.96,8.1],[7,1.95,8.44],[8,1.93,12.59],[9,1.91,117.35]],"bdatl":[[0,2.12,24.77],[5,2.38,17.5],[6,2.4,71.43],[7,2.42,4.19],[8,2.44,159.65],[9,2.48,6.82]],"id":9570503},{"bdatb":[[1,6.2,7.75],[2,6,1.82],[5,5.4,2.33],[6,5.3,3.1],[8,5.1,4.12],[9,5,3.96]],"bdatl":[[0,6.8,7.99]],"id":12989514},{"bdatb":[[0,23,3.96],[9,12.5,1.53]],"bdatl":[[0,32,1.33]],"id":44621159},{"bdatb":[[1,6.6,22.61],[6,5.7,87.84],[7,5.6,12.27],[8,5.5,27.14]],"bdatl":[[0,7.6,158],[8,12.5,2.6],[9,13,42.02]],"id":44836671},{"bdatb":[[0,8.2,8.26],[4,7.4,2.53],[5,7.2,5.1]],"id":43885158},{"bdatb":[[2,21,5.6],[3,20,5.64],[5,19,5.57],[8,12.5,3.1],[9,11.5,2.11]],"bdatl":[[0,28,7.64]],"id":46969227}]}]}
{"op":"mcm","clk":"AKlBANUhAPM4","pt":1659347522781,"mc":[{"id":"1.201590187","rc":[{"atl":[[16,0]],"trd":[[16,3.84]],"tv":14.18,"id":45323444},{"atl":[[2.12,11.41]],"trd":[[2.12,120.57]],"tv":792.69,"id":9570503}],"tv":1228.06}]}
{"op":"mcm","clk":"AKpBANYhAPU4","pt":1659347522831,"mc":[{"id":"1.201590187","rc":[{"bdatb":[[2,12.5,3.07],[3,12,1.52],[4,11.5,6.57],[5,11,3.7],[6,10.5,6.79],[7,10,13.89],[8,9.8,9.37],[9,9.6,21]],"bdatl":[[0,19.5,1.41]],"id":45323444},{"bdatb":[[1,2.04,4.55],[5,1.98,49.12],[6,1.97,1.36],[7,1.96,2.62],[8,1.95,13.95],[9,1.93,12.6]],"bdatl":[[0,2.12,11.41]],"id":9570503},{"bdatb":[[1,6.2,7.34],[2,5.7,4.24],[3,5.4,5.07],[4,5.3,5.64],[5,5.2,4.3],[6,5.1,1.49],[7,5,6.64],[8,4.9,2.29],[9,4.8,6.91]],"id":12989514},{"bdatb":[[1,21,5],[5,17,1.42],[6,15.5,4.41],[7,15,1.61],[8,13.5,1.32],[9,13,2.79]],"id":44621159},{"bdatb":[[0,6.8,20.79],[1,6.6,20.96],[2,6.2,10.42],[3,6,30.3],[4,5.9,13.09],[5,5.8,10.46],[6,5.7,85.75],[7,5.6,14.13],[8,5.5,27.42]],"id":44836671},{"bdatb":[[0,8.2,6.62],[3,7.6,11.99],[4,7.4,2.32],[5,7.2,4.17],[6,7,8.45],[7,6.6,69.23],[8,6.4,5.8],[9,6.2,10.91]],"id":43885158},{"bdatb":[[3,20,5.51],[5,19,5],[6,16,1.58],[7,15.5,1.4],[8,14,1.3],[9,12.5,2.11]],"id":46969227}]}]}
{"op":"mcm","clk":"ALBBANchAPw4","pt":1659347522886,"mc":[{"id":"1.201590187","rc":[{"atb":[[6.2,0]],"atl":[[7,0.36],[6.8,0.37],[7.4,0.35],[7.2,0.36]],"id":12989514},{"atl":[[7.6,158.34]],"id":44836671}]}]}
{"op":"mcm","clk":"ALJBANghAIY5","pt":1659347522936,"mc":[{"id":"1.201590187","rc":[{"bdatb":[[2,12.5,1.33],[3,11.5,5.97],[4,11,1.46],[5,10.5,4.71],[6,10,11.15],[7,9.8,10.87],[8,9.6,21.31],[9,9.4,54.1]],"id":45323444},{"bdatb":[[3,2,2.5],[4,1.99,1.26],[5,1.98,38.2],[6,1.97,1.32],[8,1.95,1.33],[9,1.94,1.29]],"bdatl":[[7,2.44,152.09],[8,2.5,21],[9,2.7,2.82]],"id":9570503},{"bdatb":[[1,5.7,4.24],[2,5.4,5.07],[3,5.3,5.64],[4,5.2,4.3],[5,5.1,1.49],[6,5,6.64],[7,4.9,2.29],[8,4.8,6.91],[9,4.5,233.57]],"bdatl":[[0,7.2,1.09],[1,7.8,4.87],[2,8.4,1.76],[3,9,2.17],[4,9.2,4.82],[5,9.6,11.09],[6,10,17.36],[7,10.5,12.71],[8,11,37.79],[9,12,1.72]],"id":12989514},{"bdatb":[[5,15.5,4.49],[6,12.5,1.48],[7,11.5,1.84],[8,10,103.45],[9,9.6,1.68]],"id":44621159},{"bdatb":[[2,6.2,6.93],[3,6,30.16],[4,5.9,9.44],[5,5.8,10.45],[6,5.7,83.5],[7,5.6,14.05],[8,5.5,23],[9,5.4,14.62]],"bdatl":[[0,7.6,158.34],[9,13,41.88]],"id":44836671},{"bdatb":[[3,7.6,9.13],[5,7.2,4.06],[6,7,5.37],[7,6.6,67.2],[8,6.4,2.52],[9,6.2,12.89]],"id":43885158},{"bdatb":[[7,12,1.72],[8,11,1.65],[9,10,2.28]],"id":46969227}]}]}
{"op":"mcm","clk":"ALhBANohAIg5","pt":1659347522986,"mc":[{"id":"1.201590187","rc":[{"atl":[[29,8.93],[32,0]],"bdatl":[[6,29,8.93],[7,50,8],[8,55,9],[9,60,10]],"id":45323444},{"atb":[[4.9,8.89]],"bdatb":[[7,4.9,9.62]],"id":12989514},{"bdatl":[[9,2.7,3.76]],"id":9570503}]}]}
{"op":"mcm","clk":"AL1BANwhAI85","pt":1659347523079,"mc":[{"id":"1.201590187","rc":[{"atl":[[6.8,0]],"trd":[[6.8,1.12]],"tv":66.34,"id":12989514}],"tv":1228.8}]}
{"op":"mcm","clk":"AMFBAN8hAI85","pt":1659347523129,"mc":[{"id":"1.201590187","rc":[{"bdatb":[[2,12.5,1.14],[6,10,11.4],[8,9.6,21.05]],"id":45323444},{"bdatb":[[3,2,1.24],[4,1.99,2.52],[5,1.98,36.94],[6,1.97,1.31]],"id":9570503},{"bdatl":[[0,7.4,1.07],[1,7.8,4.52]],"id":12989514},{"bdatb":[[5,15.5,4.34],[6,12.5,1.68],[7,11.5,1.62],[8,10,103.44]],"id":44621159},{"bdatb":[[3,6,29.74],[7,5.6,14.5]],"id":44836671},{"bdatb":[[3,7.6,8.8],[7,6.6,67.58],[9,6.2,12.48]],"id":43885158},{"bdatb":[[6,16,1.43],[7,12,1.91],[9,10,2.04]],"id":46969227}]}]}
{"op":"mcm","clk":"AMZBAOMhAJI5","pt":1659347523179,"mc":[{"id":"1.201590187","rc":[{"atl":[[7.8,11.34]],"id":44836671}]}]}
{"op":"mcm","clk":"AMdBAOQhAJI5","pt":1659347523229,"mc":[{"id":"1.201590187","rc":[{"bdatl":[[1,7.8,11.34]],"id":44836671}]}]}
{"op":"mcm","clk":"ANRBAOkhAJo5","pt":1659347523380,"mc":[{"id":"1.201590187","rc":[{"atl":[[16.5,3.92]],"id":45323444},{"atb":[[6.4,0.17]],"atl":[[7,0]],"trd":[[6.4,38.44]],"ltp":6.4,"tv":79.8,"id":12989514},{"atl":[[48,0]],"id":44621159},{"atb":[[7.4,5.83]],"id":44836671},{"atb":[[9.2,4.68]],"id":43885158}],"tv":1242.26}]}
{"op":"mcm","clk":"ANVBAOkhAJs5","pt":1659347523431,"mc":[{"id":"1.201590187","rc":[{"bdatb":[[3,11.5,5.76],[6,10,11.65],[7,9.8,10.65],[8,9.6,21]],"bdatl":[[0,16.5,3.92],[1,19.5,1.41],[2,21,1.15],[3,23,2.64],[4,25,5.61],[5,26,5.04],[6,27,3.85],[7,29,8.93],[8,50,8.03],[9,55,9]],"id":45323444},{"bdatb":[[3,2,2.54],[4,1.99,2.55],[5,1.98,36.93],[6,1.97,1.27],[7,1.96,19.3],[8,1.93,1.07],[9,1.92,6.62]],"bdatl":[[3,2.3,2.21],[4,2.4,71.43],[5,2.44,152.09],[6,2.5,25.31],[7,2.52,12.38],[8,2.72,1.08],[9,2.74,9.76]],"id":9570503},{"bdatb":[[0,6,4.2],[1,5.9,3.1],[2,5.8,3.83],[3,5.5,3.07],[4,5.4,1.97],[5,5.3,4.55],[6,5.2,3.46],[7,5.1,2.04],[8,4.9,9.61],[9,4.8,7.45]],"bdatl":[[0,7.6,1.04],[1,7.8,4.19],[3,8.6,5.01],[4,9,2.17],[5,9.2,4.82],[6,9.6,11.09],[7,10,17.36],[8,10.5,12.71],[9,11,33.87]],"id":12989514},{"bdatb":[[5,15.5,4.49],[6,14.5,1.31],[7,13.5,1.2],[8,12,1.23],[9,10,103.87]],"bdatl":[[3,95,2]],"id":44621159},{"bdatb":[[0,7.4,5.83],[1,6.8,20.79],[2,6.6,20.96],[3,6.2,6.93],[4,6,30.59],[5,5.9,11.8],[6,5.8,10],[7,5.7,85.91],[8,5.6,12],[9,5.5,23]],"bdatl":[[7,12,1.51],[8,13,41.9],[9,13.5,1.55]],"id":44836671},{"bdatb":[[0,9.2,4.68],[1,8.2,6.62],[2,8,7.76],[3,7.8,1.26],[4,7.6,9.14],[5,7.4,2.67],[6,7.2,4.06],[7,7,7.36],[8,6.8,2.38],[9,6.6,64.72]],"bdatl":[[7,14.5,1.08]],"id":43885158},{"bdatb":[[6,16,1.58],[7,13.5,1.57],[8,13,1.25],[9,11,1.34]],"bdatl":[[6,310,1.01]],"id":46969227}]}]}
{"op":"mcm","clk":"ANxBAOohAJ45","pt":1659347523481,"mc":[{"id":"1.201590187","rc":[{"atb":[[15,1]],"bdatb":[[0,15,1]],"bdatl":[[8,50,8]],"id":45323444},{"atb":[[6.4,0]],"trd":[[6.4,38.78]],"bdatb":[[0,6,4.03]],"bdatl":[[3,8.6,1.74],[4,9,4.38],[6,9.6,11.96],[8,10.5,12.47],[9,11,33.84]],"tv":80.14,"id":12989514},{"atb":[[23,1]],"atl":[[50,0.64]],"bdatb":[[0,23,1.49]],"bdatl":[[3,95,2.64]],"id":44621159},{"bdatl":[[3,2.3,1.72],[6,2.5,25.75],[7,2.52,1.24],[8,2.54,7.82],[9,2.58,3.18]],"id":9570503},{"bdatl":[[7,12,1.41]],"id":44836671},{"bdatl":[[7,14.5,1]],"id":43885158},{"bdatl":[[6,310,1]],"id":46969227}],"tv":1242.6}]}
{"op":"mcm","clk":"AORBAPMhAKU5","pt":1659347523574,"mc":[{"id":"1.201590187","rc":[{"atb":[[2.04,0],[2.06,29.06]],"id":9570503},{"atb":[[4.6,15.8],[4.5,222]],"id":12989514},{"atb":[[7.4,0],[6.2,5.77]],"trd":[[7.4,51.23]],"tv":199.1,"id":44836671},{"atb":[[9.2,0.24]],"atl":[[9.4,0],[9.6,14.54]],"trd":[[9.2,27.29]],"ltp":9.2,"tv":133.05,"id":43885158}],"tv":1263.15}]}
{"op":"mcm","clk":"AOhBAPMhAKY5","pt":1659347523625,"mc":[{"id":"1.201590187","rc":[{"bdatb":[[0,2.06,29.06],[1,2.02,7.75],[2,2,2.54],[3,1.99,2.55],[4,1.98,36.93],[5,1.97,1.27],[6,1.96,19.3],[7,1.93,1.07],[8,1.92,6.62],[9,1.91,107.36]],"bdatl":[[6,2.5,21],[7,2.68,5.64],[8,2.72,7.31],[9,2.76,3.15]],"id":9570503},{"bdatb":[[7,5.1,1.04],[8,5,1.75],[9,4.9,8.89]],"bdatl":[[3,9,2.41],[4,9.2,4.82],[5,9.6,11.09],[6,10,17.36],[7,10.5,12.5],[8,11,34.97],[9,11.5,1.73]],"id":12989514},{"bdatb":[[5,15.5,4.5]],"id":44621159},{"bdatb":[[0,6.8,20.79],[1,6.6,20.96],[2,6.2,6.56],[3,6,30.59],[4,5.9,11.8],[5,5.8,10],[6,5.7,85.91],[7,5.6,12],[8,5.5,23],[9,5.4,16.74]],"id":44836671},{"bdatb":[[0,8.2,6.86],[1,8,7.76],[2,7.8,1.26],[3,7.6,9.14],[4,7.4,2.67],[5,7.2,4.06],[6,7,7.36],[7,6.8,2.38],[8,6.6,64.72],[9,6.4,2.32]],"bdatl":[[0,9.6,14.54]],"id":43885158},{"bdatb":[[6,16,1.59]],"id":46969227}]}]}
{"op":"mcm","clk":"AO9BAPchAK05","pt":1659347523676,"mc":[{"id":"1.201590187","rc":[{"atb":[[13.5,4.25]],"id":45323444},{"atb":[[2.02,8.95]],"id":9570503},{"atb":[[4.9,9.39]],"id":12989514},{"atl":[[8.4,7],[7.6,150.34]],"id":44836671}]}]}
{"op":"mcm","clk":"APBBAPchAK45","pt":1659347523738,"mc":[{"id":"1.201590187","rc":[{"bdatb":[[2,13.5,4.25],[3,12.5,1.14],[4,11.5,5.76],[5,11,1.46],[6,10.5,4.71],[7,10,11.65],[8,9.8,10.65],[9,9.6,21]],"id":45323444},{"bdatb":[[1,2.02,8.95]],"bdatl":[[9,2.76,4.03]],"id":9570503},{"bdatb":[[9,4.9,9.39]],"id":12989514},{"bdatl":[[0,7.6,150.34],[4,8.4,7]],"id":44836671}]}]}
{"op":"mcm","clk":"APhBAPwhALI5","pt":1659347523789,"mc":[{"id":"1.201590187","rc":[{"atb":[[2.06,31.41]],"id":9570503}]}]}
{"op":"mcm","clk":"APxBAPwhALQ5","pt":1659347523840,"mc":[{"id":"1.201590187","rc":[{"bdatb":[[0,2.06,31.41]],"id":9570503}]}]}
{"op":"mcm","clk":"AIJCAIIiALo5","pt":1659347523890,"mc":[{"id":"1.201590187","rc":[{"atb":[[24,2.91]],"bdatb":[[0,24,2.91],[1,23,1],[2,21,5],[3,20,1.8],[4,19.5,4.19],[5,18.5,1.37],[6,15.5,4.5],[7,14.5,1.31],[8,13.5,1.2],[9,12,1.23]],"id":44621159},{"bdatl":[[8,2.72,11.4],[9,2.76,2.46]],"id":9570503},{"bdatl":[[9,11.5,3.29]],"id":12989514}]}]}
{"op":"mcm","clk":"AIlCAIYiAMQ5","pt":1659347523995,"mc":[{"id":"1.201590187","rc":[{"atb":[[4.8,5.44]],"id":12989514},{"atb":[[20,0]],"id":44621159}]}]}
{"op":"mcm","clk":"AI5CAIkiAMc5","pt":1659347524045,"mc":[{"id":"1.201590187","rc":[{"bdatb":[[3,19.5,4.19],[4,18.5,1.37],[5,15.5,4.5],[6,14.5,1.31],[7,13.5,1.2],[8,12,1.23],[9,10,103.87]],"id":44621159}]}]}
{"op":"mcm","clk":"AJRCAIsiAMw5","pt":1659347524095,"mc":[{"id":"1.201590187","rc":[{"atb":[[4.9,10.86]],"bdatb":[[9,4.9,10.86]],"id":12989514},{"atb":[[17,1.8]],"bdatb":[[5,17,1.95],[6,15.5,4.35],[7,14.5,1.31],[8,13.5,1.2],[9,12,1.23]],"id":44621159},{"bdatl":[[8,2.72,13.9],[9,2.78,1.32]],"id":9570503}]}]}
{"op":"mcm","clk":"AK5CAJsiAOQ5","pt":1659347524470,"mc":[{"id":"1.201590187","rc":[{"atl":[[1000,3.34]],"id":12989514},{"atl":[[50,0]],"id":44621159}]}]}
{"op":"mcm","clk":"ALFCAJsiAOg5","pt":1659347524520,"mc":[{"id":"1.201590187","rc":[{"bdatl":[[3,95,2]],"id":44621159}]}]}
{"op":"mcm","clk":"ALhCAJ0iAOs5","pt":1659347524570,"mc":[{"id":"1.201590187","rc":[{"atb":[[13.5,0]],"id":45323444},{"atb":[[2.02,15.26]],"id":9570503},{"atb":[[6,4.68],[6.2,2.32]],"id":12989514},{"atb":[[24,0.49]],"atl":[[55,0.64]],"id":44621159}]}]}
{"op":"mcm","clk":"ALpCAJ0iAO05","pt":1659347524620,"mc":[{"id":"1.201590187","rc":[{"bdatb":[[2,12.5,1.14],[3,11.5,5.76],[4,11,1.46],[5,10.5,4.71],[6,10,11.65],[7,9.8,10.65],[8,9.6,21],[9,9.4,54.1]],"id":45323444},{"bdatb":[[1,2.02,15.26]],"bdatl":[[3,2.3,2.67],[4,2.4,75.48],[5,2.42,1.04],[6,2.44,152.33],[7,2.48,8.01],[8,2.5,24.04],[9,2.76,3.74]],"id":9570503},{"bdatb":[[0,6.2,2.32],[1,6,8.71],[2,5.9,3.1],[3,5.8,3.83],[4,5.5,3.07],[5,5.4,1.97],[6,5.3,4.55],[7,5.2,3.46],[8,5.1,1.04],[9,5,1.75]],"bdatl":[[9,11.5,1.73]],"id":12989514},{"bdatb":[[0,23,1.49],[1,21,5],[2,19.5,4.19],[3,18.5,1.37],[4,17,1.95],[5,15.5,4.35],[6,14.5,1.31],[7,13.5,1.2],[8,12,1.23],[9,10,103.87]],"bdatl":[[3,95,2.64]],"id":44621159},{"bdatl":[[7,12,1.61],[8,13,42.84]],"id":44836671}]}]}
{"op":"mcm","clk":"AMBCAJ8iAPE5","pt":1659347524676,"mc":[{"id":"1.201590187","rc":[{"atl":[[7.2,0]],"id":12989514}]}]}
{"op":"mcm","clk":"AMJCAJ8iAPQ5","pt":1659347524726,"mc":[{"id":"1.201590187","rc":[{"bdatb":[[3,11.5,5.54],[6,10,11.91],[7,9.8,10.39]],"id":45323444},{"bdatb":[[2,2,1.24],[7,1.93,2.42],[8,1.92,5.27]],"id":9570503},{"bdatl":[[0,7.8,4.87],[1,8.4,1.76],[2,9,2.41],[3,9.2,4.82],[4,9.6,11.09],[5,10,17.36],[6,10.5,12.5],[7,11,34.97],[8,11.5,1.73],[9,12.5,1.56]],"id":12989514},{"bdatb":[[4,17,1.8],[6,14.5,1.49],[7,13.5,1.01],[9,11,1.1]],"id":44621159},{"bdatb":[[2,6.2,6.14],[4,5.9,12.24],[6,5.7,85.45]],"id":44836671},{"bdatb":[[3,7.6,8.8],[6,7,7.73],[7,6.8,2],[9,6.4,2.73]],"id":43885158},{"bdatb":[[6,16,1.43],[7,13.5,1.76],[8,13,1.05],[9,11,1.33]],"id":46969227}]}]}
{"op":"mcm","clk":"AMVCAKUiAPc5","pt":1659347524776,"mc":[{"id":"1.201590187","rc":[{"atb":[[9.4,36.86]],"id":45323444},{"atb":[[1.77,68.02]],"id":9570503},{"atb":[[3.7,48.48]],"atl":[[7.8,4.54],[7.6,0]],"id":12989514},{"atb":[[9.4,35.91],[22,2.59]],"id":44621159},{"atb":[[6.6,47.48]],"id":43885158},{"atb":[[23,1]],"atl":[[32,0.09]],"id":46969227}]}]}
{"op":"mcm","clk":"AMZCAKUiAPg5","pt":1659347524826,"mc":[{"id":"1.201590187","rc":[{"bdatb":[[5,10.5,4.47],[6,10,12.16],[7,9.8,10.41],[9,9.4,36.86]],"id":45323444},{"bdatb":[[5,1.96,20.7],[6,1.93,2.3],[7,1.92,5.39],[8,1.91,107.36],[9,1.89,6.27]],"id":9570503},{"bdatl":[[0,7.8,4.89],[8,12,1.82],[9,12.5,1.43]],"id":12989514},{"bdatb":[[1,22,2.59],[2,21,5],[3,19.5,4.19],[4,18.5,1.37],[5,17,1.8],[6,15.5,4.35],[7,14.5,1.49],[8,13.5,1.03],[9,12,1.23]],"id":44621159},{"bdatb":[[3,6,30.17],[4,5.9,12.66],[6,5.7,85.49]],"id":44836671},{"bdatb":[[5,7.2,3.71],[6,7,8.09],[7,6.8,2.03],[8,6.6,47.48],[9,6.4,2.69]],"id":43885158},{"bdatb":[[0,23,1],[7,13.5,1.77],[8,13,1.06]],"bdatl":[[1,34,5.76],[2,36,2.86],[3,40,5.01],[4,80,1.66],[5,310,1],[6,990,2.15],[7,0,0]],"id":46969227}]}]}
{"op":"mcm","clk":"AMpCAKkiAP45","pt":1659347524876,"mc":[{"id":"1.201590187","rc":[{"atl":[[9.4,3.67],[7.4,0]],"id":12989514},{"atb":[[23,0]],"id":46969227}]}]}
{"op":"mcm","clk":"AMxCAKkiAIQ6","pt":1659347524926,"mc":[{"id":"1.201590187","rc":[{"bdatb":[[4,11,1.23],[6,10,12.42],[7,9.8,10.15]],"id":45323444},{"bdatb":[[3,1.99,1.25],[6,1.93,3.64],[7,1.92,4.04],[9,1.89,7.64]],"bdatl":[[3,2.3,1.72],[4,2.4,72.51],[5,2.42,4.91],[6,2.44,152.09],[7,2.48,8.25]],"id":9570503},{"bdatl":[[0,7.8,4.54],[2,9,2.17],[3,9.2,5.06],[4,9.4,3.67],[5,9.6,11.09],[6,10,17.36],[7,10.5,12.5],[8,11,34.69],[9,12,2.05]],"id":12989514},{"bdatb":[[6,15.5,4.19],[7,14.5,1.67],[8,12,2.06],[9,11,1.31]],"id":44621159},{"bdatb":[[3,6,29.74],[4,5.9,13.1],[6,5.7,85.04]],"bdatl":[[7,12,1.6],[8,13,42.64],[9,13.5,1.74]],"id":44836671},{"bdatb":[[4,7.4,2.32],[6,7,8.46],[7,6.8,1.65],[9,6.4,3.1]],"id":43885158},{"bdatb":[[0,22,4.4],[1,21,5.6],[2,20,5.51],[3,19.5,7],[4,19,5],[5,16,1.43],[6,13.5,1.79],[7,11.5,1.48],[8,10,4.14],[9,9.2,1.82]],"id":46969227}]}]}
{"op":"mcm","clk":"ANJCAK4iAIY6","pt":1659347524986,"mc":[{"id":"1.201590187","rc":[{"atl":[[1000,0.47]],"id":12989514}]}]}
{"op":"mcm","clk":"ANpCALAiAI46","pt":1659347525089,"mc":[{"id":"1.201590187","rc":[{"atb":[[21,1.6],[18.5,8]],"id":46969227}]}]}
{"op":"mcm","clk":"ANtCALAiAJE6","pt":1659347525139,"mc":[{"id":"1.201590187","rc":[{"bdatb":[[1,21,1.6],[5,18.5,8],[6,16,1.43],[7,13.5,1.79],[8,11.5,1.48],[9,10,4.14]],"id":46969227}]}]}
{"op":"mcm","clk":"AOBCALIiAJo6","pt":1659347525189,"mc":[{"id":"1.201590187","rc":[{"atl":[[7.8,4.19]],"id":12989514}]}]}
{"op":"mcm","clk":"AOJCALQiAJ86","pt":1659347525239,"mc":[{"id":"1.201590187","rc":[{"bdatb":[[7,9.8,9.87]],"id":45323444},{"bdatb":[[5,1.96,19.3],[6,1.93,5.06],[7,1.92,2.62],[9,1.89,9.08]],"id":9570503},{"bdatl":[[0,7.8,4.19]],"id":12989514},{"bdatb":[[8,12,1.86],[9,11,1.56]],"id":44621159},{"bdatb":[[6,5.7,84.56]],"id":44836671},{"bdatb":[[7,6.8,1.25],[9,6.4,3.52]],"id":43885158},{"bdatb":[[8,11.5,1.51],[9,10,4.18]],"id":46969227}]}]}
{"op":"mcm","clk":"AO5CALsiAK06","pt":1659347525459,"mc":[{"id":"1.201590187","rc":[{"atl":[[19.5,1]],"id":45323444},{"atb":[[22,0],[1.15,1.68]],"id":44621159}]}]}
{"op":"mcm","clk":"APBCALsiAK86","pt":1659347525509,"mc":[{"id":"1.201590187","rc":[{"bdatl":[[1,19.5,1]],"id":45323444},{"bdatl":[[8,2.5,21],[9,2.52,3.02]],"id":9570503},{"bdatb":[[5,5.3,5.04],[6,5.2,3.46],[7,5.1,2.61],[8,5,1.75],[9,4.9,10.86]],"id":12989514},{"bdatb":[[1,21,5],[2,19.5,4.19],[3,18.5,1.37],[4,17,1.8],[5,15.5,4.19],[6,14.5,1.67],[7,12,1.86],[8,11,1.56],[9,10,102.24]],"id":44621159}]}]}
{"op":"mcm","clk":"APhCAL0iALQ6","pt":1659347525584,"mc":[{"id":"1.201590187","rc":[{"atb":[[6.2,2.31]],"trd":[[6.2,7.23]],"ltp":6.2,"tv":80.15,"id":12989514}],"tv":1263.16}]}
{"op":"mcm","clk":"APpCAL0iALs6","pt":1659347525638,"mc":[{"id":"1.201590187","rc":[{"bdatl":[[5,2.42,4.89],[7,2.48,8.27],[9,2.52,3]],"id":9570503},{"bdatb":[[0,6.2,2.31]],"id":12989514}]}]}
{"op":"mcm","clk":"AP9CAMEiAMA6","pt":1659347525688,"mc":[{"id":"1.201590187","rc":[{"atb":[[2.02,21.58]],"bdatb":[[1,2.02,21.58]],"bdatl":[[5,2.42,5.16],[7,2.46,5.57],[8,2.48,9.72],[9,2.5,21]],"id":9570503},{"atb":[[6.2,4.63]],"bdatb":[[0,6.2,4.63]],"bdatl":[[9,12,3.55]],"id":12989514},{"atb":[[23,3.47],[1.15,0.12]],"bdatb":[[0,23,3.96]],"id":44621159},{"bdatl":[[9,13.5,1.79]],"id":44836671}]}]}
{"op":"mcm","clk":"AIVDAMciAMY6","pt":1659347525768,"mc":[{"id":"1.201590187","rc":[{"atl":[[2.12,15.41]],"id":9570503}]}]}
{"op":"mcm","clk":"AIhDAMciAMk6","pt":1659347525818,"mc":[{"id":"1.201590187","rc":[{"bdatb":[[6,10,13.27],[7,9.8,9]],"id":45323444},{"bdatl":[[0,2.12,15.41]],"id":9570503},{"bdatb":[[1,6,10.12],[2,5.9,1.66],[8,5,3.44]],"id":12989514},{"bdatb":[[6,14.5,2.25],[7,12,1.23]],"id":44621159},{"bdatb":[[4,5.9,14.54],[6,5.7,83.07]],"id":44836671},{"bdatb":[[6,7,9.67],[7,6.6,47.49],[8,6.4,3.52],[9,6.2,10.81]],"id":43885158},{"bdatb":[[7,13.5,2.42],[8,11,1.31],[9,10,3.72]],"id":46969227}]}]}
{"op":"mcm","clk":"AJFDANAiANY6","pt":1659347525975,"mc":[{"id":"1.201590187","rc":[{"atb":[[1.15,0]],"id":44621159}]}]}
{"op":"mcm","clk":"AJpDANMiAN86","pt":1659347526078,"mc":[{"id":"1.201590187","rc":[{"atb":[[23,3.59]],"id":44621159}]}]}
{"op":"mcm","clk":"AJtDANMiAOA6","pt":1659347526128,"mc":[{"id":"1.201590187","rc":[{"bdatb":[[0,23,4.08]],"id":44621159}]}]}
{"op":"mcm","clk":"AKBDANkiAOU6","pt":1659347526182,"mc":[{"id":"1.201590187","rc":[{"atb":[[3.9,27.24]],"id":12989514},{"atb":[[5.7,100.3]],"id":44836671}]}]}
{"op":"mcm","clk":"AKJDANoiAOg6","pt":1659347526232,"mc":[{"id":"1.201590187","rc":[{"bdatb":[[6,5.7,100.31]],"id":44836671}]}]}
{"op":"mcm","clk":"AKpDAN4iAOk6","pt":1659347526294,"mc":[{"id":"1.201590187","rc":[{"atb":[[9.4,54.1]],"id":45323444},{"atb":[[1.79,17.24]],"id":9570503},{"atb":[[11,14.37]],"id":44621159},{"atb":[[6.6,64.72]],"id":43885158}]}]}
{"op":"mcm","clk":"AK1DAOAiAOs6","pt":1659347526344,"mc":[{"id":"1.201590187","rc":[{"bdatb":[[9,9.4,54.1]],"id":45323444},{"bdatb":[[8,11,15.93]],"id":44621159},{"bdatb":[[7,6.6,64.73]],"id":43885158}]}]}
{"op":"mcm","clk":"ALVDAOIiAPE6","pt":1659347526399,"mc":[{"id":"1.201590187","rc":[{"atb":[[4.9,3.52]],"id":12989514},{"atb":[[23,1.12]],"id":44621159},{"atb":[[8.8,34.48]],"id":46969227}]}]}
{"op":"mcm","clk":"ALlDAOMiAPM6","pt":1659347526449,"mc":[{"id":"1.201590187","rc":[{"bdatl":[[8,2.48,3.58]],"id":9570503},{"bdatb":[[9,4.9,3.52]],"bdatl":[[9,12,2.28]],"id":12989514},{"bdatb":[[0,23,1.61]],"id":44621159}]}]}
{"op":"mcm","clk":"ALxDAOYiAPU6","pt":1659347526499,"mc":[{"id":"1.201590187","rc":[{"atb":[[4.7,7.34]],"id":12989514}]}]}
{"op":"mcm","clk":"AMJDAOsiAPs6","pt":1659347526591,"mc":[{"id":"1.201590187","rc":[{"atb":[[2.02,27.89]],"id":9570503},{"atb":[[24,2.91]],"id":44621159}]}]}
{"op":"mcm","clk":"AMZDAOwiAIA7","pt":1659347526641,"mc":[{"id":"1.201590187","rc":[{"bdatb":[[1,2.02,27.89]],"bdatl":[[6,2.44,157.71],[7,2.48,9.72],[8,2.5,21],[9,2.52,1.45]],"id":9570503},{"bdatl":[[8,11,34.97],[9,11.5,3.29]],"id":12989514},{"bdatb":[[0,24,2.91],[1,23,1.12],[2,21,5],[3,19.5,4.19],[4,18.5,1.37],[5,17,1.8],[6,15.5,4.19],[7,14.5,2.25],[8,12,1.23],[9,11,15.93]],"id":44621159},{"bdatl":[[8,13,42.88],[9,13.5,1.55]],"id":44836671}]}]}
{"op":"mcm","clk":"AO1DAIIjAKo7","pt":1659347527270,"mc":[{"id":"1.201590187","rc":[{"atb":[[24,0.49]],"id":44621159}]}]}
{"op":"mcm","clk":"AO5DAIIjAKw7","pt":1659347527320,"mc":[{"id":"1.201590187","rc":[{"bdatl":[[6,2.44,152.09],[7,2.46,5.57],[8,2.48,3.58],[9,2.5,21]],"id":9570503},{"bdatl":[[8,11,34.69],[9,12,2.28]],"id":12989514},{"bdatb":[[0,23,1.61],[1,21,5],[2,19.5,4.19],[3,18.5,1.37],[4,17,1.8],[5,15.5,4.19],[6,14.5,2.25],[7,12,1.23],[8,11,15.93],[9,10,102.24]],"id":44621159},{"bdatl":[[8,13,42.64],[9,13.5,1.79]],"id":44836671}]}]}
{"op":"mcm","clk":"APNDAIQjALA7","pt":1659347527375,"mc":[{"id":"1.201590187","rc":[{"atb":[[22,2.59]],"id":44621159}]}]}
{"op":"mcm","clk":"APRDAIQjALI7","pt":1659347527425,"mc":[{"id":"1.201590187","rc":[{"bdatl":[[9,2.5,27.09]],"id":9570503},{"bdatb":[[1,22,2.59],[2,21,5],[3,19.5,4.19],[4,18.5,1.37],[5,17,1.8],[6,15.5,4.19],[7,14.5,2.25],[8,12,1.23],[9,11,15.93]],"id":44621159}]}]}
{"op":"mcm","clk":"AJtEAK0jANY7","pt":1659347528052,"mc":[{"id":"1.201590187","rc":[{"atb":[[22,0]],"id":44621159}]}]}
{"op":"mcm","clk":"AJxEAK0jANc7","pt":1659347528103,"mc":[{"id":"1.201590187","rc":[{"bdatl":[[9,2.5,21]],"id":9570503},{"bdatb":[[1,21,5],[2,19.5,4.19],[3,18.5,1.37],[4,17,1.8],[5,15.5,4.19],[6,14.5,2.25],[7,12,1.23],[8,11,15.93],[9,10,102.24]],"id":44621159}]}]}
{"op":"mcm","clk":"AKREALYjAOI7","pt":1659347528263,"mc":[{"id":"1.201590187","rc":[{"atb":[[23,3.59]],"id":44621159}]}]}
{"op":"mcm","clk":"AKZEALYjAOM7","pt":1659347528313,"mc":[{"id":"1.201590187","rc":[{"bdatl":[[8,2.48,9.72]],"id":9570503},{"bdatl":[[9,12,3.55]],"id":12989514},{"bdatb":[[0,23,4.08]],"id":44621159}]}]}
{"op":"mcm","clk":"ALBEAMAjAPI7","pt":1659347528476,"mc":[{"id":"1.201590187","rc":[{"atl":[[10.5,0],[10,5.79]],"id":43885158}]}]}
{"op":"mcm","clk":"ALREAMAjAPc7","pt":1659347528526,"mc":[{"id":"1.201590187","rc":[{"bdatl":[[1,10,5.79],[2,11.5,2.89],[3,12,1.4],[4,12.5,18],[5,14,1],[6,14.5,1],[7,15,12],[8,15.5,1],[9,16.5,8.94]],"id":43885158}]}]}
{"op":"mcm","clk":"AMlEAM4jAIo8","pt":1659347528883,"mc":[{"id":"1.201590187","rc":[{"atb":[[2.62,0],[7.2,0]],"atl":[[21,0],[75,13]],"id":45323444},{"atb":[[1.46,0]],"atl":[[3.55,0],[17,0],[34,0]],"id":9570503},{"atb":[[2.7,0]],"atl":[[18.5,0],[34,10]],"id":12989514},{"atb":[[9.4,27.34],[2.62,0]],"atl":[[120,0]],"id":44621159},{"atb":[[2.62,0],[4.6,0]],"atl":[[28,0]],"id":43885158},{"atb":[[4.2,0],[6.6,0],[2.62,0]],"id":46969227}]}]}
{"op":"mcm","clk":"AMtEANwjAJo8","pt":1659347528933,"mc":[{"id":"1.201590187","rc":[{"bdatl":[[2,23,2.64],[3,25,5.61],[4,26,5.04],[5,27,3.85],[6,29,8.93],[7,50,8],[8,55,9],[9,60,10]],"id":45323444},{"bdatb":[[5,5.2,4.29],[6,5.1,6.99],[7,4.9,7.02],[8,4.8,5.44],[9,4.7,7.89]],"id":12989514},{"bdatl":[[4,170,2],[5,990,2.07],[6,0,0]],"id":44621159}]}]}
{"op":"mcm","clk":"ANFEAOIjAJs8","pt":1659347528992,"mc":[{"id":"1.201590187","rc":[{"atb":[[23,1.12]],"id":44621159},{"atb":[[2.62,0],[4.8,0]],"atl":[[28,0]],"id":44836671}]}]}
{"op":"mcm","clk":"ANJEAOMjAJ48","pt":1659347529043,"mc":[{"id":"1.201590187","rc":[{"bdatl":[[8,2.48,3.58]],"id":9570503},{"bdatl":[[9,12,2.28]],"id":12989514},{"bdatb":[[0,23,1.61]],"id":44621159}]}]}
{"op":"mcm","clk":"ANNEAOYjAJ88","pt":1659347529093,"mc":[{"id":"1.201590187","rc":[{"atb":[[2.02,32.05]],"atl":[[2.3,5.32]],"bdatb":[[1,2.02,32.05],[5,1.97,10.64],[6,1.96,8.61],[7,1.93,5.06],[8,1.92,2.62],[9,1.91,107.36]],"bdatl":[[3,2.3,5.32],[6,2.44,157.71],[7,2.48,9.72],[8,2.5,21],[9,2.52,1.45]],"id":9570503},{"atb":[[6,7.2]],"atl":[[9,4.44]],"bdatb":[[1,6,12.64],[6,5.1,7.86],[7,5,2.56],[8,4.9,3.52],[9,4.8,5.98]],"bdatl":[[2,9,4.44],[8,11,34.97],[9,11.5,3.29]],"id":12989514},{"atb":[[24,2.91]],"bdatb":[[0,24,2.91],[1,23,1.12],[2,21,5],[3,19.5,4.19],[4,18.5,1.37],[5,17,1.8],[6,15.5,4.19],[7,15,1.4],[8,12,2.04],[9,11,15.93]],"id":44621159},{"atb":[[6.8,22.73]],"atl":[[7.6,152.61]],"bdatb":[[0,6.8,23.09],[3,6,33.24],[4,5.9,10.98]],"bdatl":[[0,7.6,152.61],[8,13,42.88],[9,13.5,1.55]],"id":44836671},{"atb":[[8,10.08]],"atl":[[9.4,2.23]],"bdatb":[[1,8,10.08]],"bdatl":[[0,9.4,2.23],[1,9.6,14.54],[2,10,5.79],[3,11.5,2.89],[4,12,1.4],[5,12.5,18],[6,14,1],[7,14.5,1],[8,15,12],[9,15.5,1]],"id":43885158},{"bdatb":[[5,10.5,6.47],[6,10,11.17]],"id":45323444},{"bdatb":[[7,14,1.5],[8,11.5,1.72],[9,10,4.18]],"id":46969227}]}]}
{"op":"mcm","clk":"ANlEAOsjAKM8","pt":1659347529187,"mc":[{"id":"1.201590187","rc":[{"atb":[[2.02,35.99]],"atl":[[2.3,8.99]],"id":9570503},{"atb":[[6,9.56]],"atl":[[9,6.73]],"id":12989514},{"atb":[[6.8,24.97]],"atl":[[7.6,154.81]],"id":44836671},{"atb":[[9.2,0],[8,12.41]],"atl":[[9.4,4.78]],"trd":[[9.2,27.76]],"tv":133.52,"id":43885158}],"tv":1263.63}]}
{"op":"mcm","clk":"AN1EAO0jAKQ8","pt":1659347529237,"mc":[{"id":"1.201590187","rc":[{"bdatb":[[5,10.5,7.59],[6,10,10]],"id":45323444},{"bdatb":[[1,2.02,35.99],[5,1.97,16.6],[6,1.96,2.62],[7,1.94,5.03],[8,1.93,1.29],[9,1.92,1.32]],"bdatl":[[3,2.3,8.99],[4,2.4,72.48],[9,2.54,5.62]],"id":9570503},{"bdatb":[[1,6,15.01],[2,5.9,2.08],[3,5.8,3.4]],"bdatl":[[2,9,6.73],[3,9.2,4.82],[7,10.5,12.71]],"id":12989514},{"bdatb":[[7,15,2.18],[8,12,1.19]],"id":44621159},{"bdatb":[[0,6.8,25.33],[3,6,35.19],[4,5.9,9],[5,5.8,10.01],[6,5.7,100.3],[8,5.5,25.23],[9,5.4,14.47]],"bdatl":[[0,7.6,154.81],[7,12,1.41],[8,13,43.05]],"id":44836671},{"bdatb":[[0,8.2,6.62],[1,8,12.41]],"bdatl":[[0,9.4,4.78]],"id":43885158},{"bdatb":[[7,14,2.33],[8,11.5,1.06],[9,10,3.95]],"id":46969227}]}]}
{"op":"mcm","clk":"AOREAPQjAKg8","pt":1659347529392,"mc":[{"id":"1.201590187","rc":[{"atl":[[34,6.19]],"id":46969227}]}]}
{"op":"mcm","clk":"AOpEAPkjAKo8","pt":1659347529442,"mc":[{"id":"1.201590187","rc":[{"bdatl":[[1,34,6.35]],"id":46969227}]}]}
{"op":"mcm","clk":"AINFAIckALg8","pt":1659347529766,"mc":[{"id":"1.201590187","rc":[{"atb":[[24,0.49]],"id":44621159}]}]}
{"op":"mcm","clk":"AIVFAIckALk8","pt":1659347529816,"mc":[{"id":"1.201590187","rc":[{"bdatl":[[6,2.44,152.09],[7,2.46,5.57],[8,2.48,3.58],[9,2.5,21]],"id":9570503},{"bdatl":[[8,11,34.69],[9,12,2.28]],"id":12989514},{"bdatb":[[0,23,1.61],[1,21,5],[2,19.5,4.19],[3,18.5,1.37],[4,17,1.8],[5,15.5,4.19],[6,15,2.18],[7,12,1.19],[8,11,15.93],[9,10,103.95]],"id":44621159},{"bdatl":[[8,13,42.81],[9,13.5,1.79]],"id":44836671}]}]}
{"op":"mcm","clk":"AIlFAIokALw8","pt":1659347529867,"mc":[{"id":"1.201590187","rc":[{"atb":[[8,6.41]],"atl":[[10,3.45]],"id":43885158},{"atb":[[22,0.1]],"id":46969227}]}]}
{"op":"mcm","clk":"AIxFAIwkAL08","pt":1659347529917,"mc":[{"id":"1.201590187","rc":[{"bdatl":[[5,2.42,3.87],[6,2.44,153.37],[8,2.5,23.84],[9,2.54,6.7]],"id":9570503},{"bdatl":[[7,10.5,12.68],[8,11,33.87],[9,11.5,1.09]],"id":12989514},{"bdatl":[[8,13,42.07],[9,13.5,2.27]],"id":44836671},{"bdatb":[[1,8,6.41]],"bdatl":[[2,10,3.45]],"id":43885158},{"bdatb":[[0,21,1.7],[1,20,5.51],[2,19.5,7],[3,19,5],[4,18.5,8],[5,16,1.43],[6,14,2.33],[7,11.5,1.06],[8,10,3.95],[9,9.4,1.8]],"id":46969227}]}]}
{"op":"mcm","clk":"AI9FAI8kAMA8","pt":1659347529972,"mc":[{"id":"1.201590187","rc":[{"atb":[[22,2.59]],"id":44621159},{"atb":[[22,0]],"id":46969227}]}]}
{"op":"mcm","clk":"AJFFAI8kAMI8","pt":1659347530022,"mc":[{"id":"1.201590187","rc":[{"bdatl":[[8,2.5,22.96],[9,2.52,7.62]],"id":9570503},{"bdatl":[[7,10.5,12.47],[8,11,34.07]],"id":12989514},{"bdatb":[[1,22,2.59],[2,21,5],[3,19.5,4.19],[4,18.5,1.37],[5,17,1.8],[6,15.5,4.19],[7,15,2.18],[8,12,1.19],[9,11,15.93]],"id":44621159},{"bdatl":[[8,13,41.9],[9,13.5,2.43]],"id":44836671},{"bdatb":[[0,21,1.6]],"id":46969227}]}]}
{"op":"mcm","clk":"AJRFAJMkAMQ8","pt":1659347530072,"mc":[{"id":"1.201590187","rc":[{"atb":[[8.2,8.82]],"atl":[[9.4,7.98]],"id":43885158},{"atb":[[21,4.69]],"atl":[[34,8.19]],"id":46969227}]}]}
{"op":"mcm","clk":"AJVFAJMkAMc8","pt":1659347530122,"mc":[{"id":"1.201590187","rc":[{"bdatb":[[8,1.93,2.6],[9,1.91,107.36]],"bdatl":[[8,2.5,24.55],[9,2.52,6.04]],"id":9570503},{"bdatb":[[2,5.9,5.42],[3,5.6,1.85],[4,5.5,1.18]],"id":12989514},{"bdatb":[[8,12.5,1.18]],"id":44621159},{"bdatb":[[8,5.5,25.69],[9,5.4,14]],"id":44836671},{"bdatb":[[0,8.2,8.82]],"bdatl":[[0,9.4,7.98]],"id":43885158},{"bdatb":[[0,21,4.69],[7,11.5,1.29],[8,10.5,1.64],[9,10,2]],"bdatl":[[1,34,8.35]],"id":46969227}]}]}
{"op":"mcm","clk":"AJhFAJUkAMk8","pt":1659347530177,"mc":[{"id":"1.201590187","rc":[{"atb":[[1.02,0]],"id":46969227}]}]}
{"op":"mcm","clk":"AJ9FAJwkAM48","pt":1659347530296,"mc":[{"id":"1.201590187","rc":[{"atb":[[21,6.32]],"id":46969227}]}]}
{"op":"mcm","clk":"AKRFAJwkANA8","pt":1659347530346,"mc":[{"id":"1.201590187","rc":[{"bdatb":[[0,21,6.32]],"id":46969227}]}]}
{"op":"mcm","clk":"AKlFAJ8kANM8","pt":1659347530397,"mc":[{"id":"1.201590187","rc":[{"atb":[[7.6,4.27]],"bdatb":[[3,7.6,4.27]],"id":43885158}]}]}
{"op":"mcm","clk":"ALRFAKYkANs8","pt":1659347530507,"mc":[{"id":"1.201590187","rc":[{"atb":[[8.2,13.35]],"id":43885158}]}]}
{"op":"mcm","clk":"ALRFAKkkAOE8","pt":1659347530557,"mc":[{"id":"1.201590187","rc":[{"bdatb":[[0,8.2,13.35]],"id":43885158}]}]}
{"op":"mcm","clk":"ALxFAKwkAOU8","pt":1659347530607,"mc":[{"id":"1.201590187","rc":[{"atb":[[2.02,53.12]],"id":9570503},{"atb":[[6,14.02]],"id":12989514}]}]}
{"op":"mcm","clk":"ALxFAK0kAOY8","pt":1659347530657,"mc":[{"id":"1.201590187","rc":[{"bdatb":[[1,2.02,53.12]],"id":9570503},{"bdatb":[[1,6,19.47]],"id":12989514}]}]}
{"op":"mcm","clk":"AMRFAK4kAOo8","pt":1659347530707,"mc":[{"id":"1.201590187","rc":[{"atb":[[22,0]],"id":44621159},{"atb":[[8.2,7.03]],"id":43885158}]}]}
{"op":"mcm","clk":"AMZFALAkAOo8","pt":1659347530757,"mc":[{"id":"1.201590187","rc":[{"bdatb":[[1,21,5],[2,19.5,4.19],[3,18.5,1.37],[4,17,1.8],[5,15.5,4.19],[6,15,2.18],[7,12.5,1.18],[8,11,15.93],[9,10,103.95]],"id":44621159},{"bdatb":[[0,8.2,7.03]],"id":43885158}]}]}
{"op":"mcm","clk":"AM1FALYkAPE8","pt":1659347530875,"mc":[{"id":"1.201590187","rc":[{"atb":[[23,3.59]],"id":44621159}]}]}
{"op":"mcm","clk":"AM5FALYkAPQ8","pt":1659347530926,"mc":[{"id":"1.201590187","rc":[{"bdatl":[[8,2.5,30.64],[9,2.56,1.9]],"id":9570503},{"bdatb":[[0,23,4.08]],"id":44621159}]}]}
{"op":"mcm","clk":"AOBFAMAkAII9","pt":1659347531172,"mc":[{"id":"1.201590187","rc":[{"atb":[[21,4.69]],"id":46969227}]}]}
{"op":"mcm","clk":"AOJFAMAkAIY9","pt":1659347531223,"mc":[{"id":"1.201590187","rc":[{"bdatb":[[0,21,4.69]],"id":46969227}]}]}
{"op":"mcm","clk":"AOlFAMMkAIo9","pt":1659347531276,"mc":[{"id":"1.201590187","rc":[{"atb":[[1.02,1.63]],"id":46969227}]}]}
{"op":"mcm","clk":"AIJGANAkAJw9","pt":1659347531589,"mc":[{"id":"1.201590187","rc":[{"atb":[[23,1.12]],"id":44621159}]}]}
{"op":"mcm","clk":"AIRGANAkAJ89","pt":1659347531640,"mc":[{"id":"1.201590187","rc":[{"bdatl":[[8,2.5,24.55],[9,2.52,6.04]],"id":9570503},{"bdatb":[[0,23,1.61]],"id":44621159}]}]}
{"op":"mcm","clk":"AI5GANQkAKA9","pt":1659347531704,"mc":[{"id":"1.201590187","rc":[{"atb":[[24,2.91]],"id":44621159}]}]}
{"op":"mcm","clk":"AJFGANYkAKY9","pt":1659347531764,"mc":[{"id":"1.201590187","rc":[{"bdatl":[[5,2.42,5.16],[6,2.44,152.09],[8,2.48,9.72],[9,2.5,21]],"id":9570503},{"bdatb":[[0,24,2.91],[1,23,1.12],[2,21,5],[3,19.5,4.19],[4,18.5,1.37],[5,17,1.8],[6,15.5,4.19],[7,15,2.18],[8,12.5,1.18],[9,11,15.93]],"id":44621159},{"bdatl":[[9,13.5,2.66]],"id":44836671}]}]}
{"op":"mcm","clk":"AKJGAN4kALU9","pt":1659347531957,"mc":[{"id":"1.201590187","rc":[{"atb":[[17,0]],"id":44621159}]}]}
{"op":"mcm","clk":"AKRGAN4kALY9","pt":1659347532007,"mc":[{"id":"1.201590187","rc":[{"bdatb":[[5,15.5,4.19],[6,15,2.18],[7,12.5,1.18],[8,11,15.93],[9,10,103.95]],"id":44621159}]}]}
{"op":"mcm","clk":"AKpGAN8kALk9","pt":1659347532060,"mc":[{"id":"1.201590187","rc":[{"atb":[[16.5,1.8]],"id":44621159},{"atb":[[7,0],[6.8,23.34]],"trd":[[7,20.78],[6.8,14.5]],"ltp":6.8,"tv":203.09,"id":44836671}],"tv":1267.62}]}
{"op":"mcm","clk":"AK9GAOAkALs9","pt":1659347532110,"mc":[{"id":"1.201590187","rc":[{"bdatl":[[4,2.4,71.43],[5,2.42,6.2]],"id":9570503},{"bdatl":[[8,11,33.84],[9,11.5,1.3]],"id":12989514},{"bdatb":[[5,16.5,1.8],[6,15.5,4.19],[7,15,2.18],[8,12.5,1.18],[9,11,15.93]],"id":44621159},{"bdatb":[[0,6.8,23.34]],"id":44836671}]}]}
{"op":"mcm","clk":"ALNGAOIkAL49","pt":1659347532164,"mc":[{"id":"1.201590187","rc":[{"atb":[[5.7,79.02],[5.8,30.83]],"id":44836671}]}]}
{"op":"mcm","clk":"ALVGAOIkAL89","pt":1659347532215,"mc":[{"id":"1.201590187","rc":[{"bdatb":[[5,5.8,30.84],[6,5.7,79.02]],"id":44836671}]}]}
{"op":"mcm","clk":"AL9GAOYkAMk9","pt":1659347532383,"mc":[{"id":"1.201590187","rc":[{"atb":[[24,0.49]],"id":44621159}]}]}
{"op":"mcm","clk":"AMJGAOYkAMw9","pt":1659347532433,"mc":[{"id":"1.201590187","rc":[{"bdatl":[[5,2.42,4.91],[6,2.44,153.37],[8,2.5,24.55],[9,2.52,6.04]],"id":9570503},{"bdatb":[[0,23,1.61],[1,21,5],[2,19.5,4.19],[3,18.5,1.37],[4,16.5,1.8],[5,15.5,4.19],[6,15,2.18],[7,12.5,1.18],[8,11,15.93],[9,10,103.95]],"id":44621159},{"bdatl":[[9,13.5,2.43]],"id":44836671}]}]}
{"op":"mcm","clk":"AMZGAOokANA9","pt":1659347532484,"mc":[{"id":"1.201590187","rc":[{"atl":[[1000,2.88]],"id":44836671}]}]}
{"op":"mcm","clk":"AMxGAO4kANY9","pt":1659347532587,"mc":[{"id":"1.201590187","rc":[{"atb":[[22,2.59]],"id":44621159},{"atl":[[8.4,3],[7.6,158.81]],"id":44836671}]}]}
{"op":"mcm","clk":"AM9GAO8kANg9","pt":1659347532637,"mc":[{"id":"1.201590187","rc":[{"bdatb":[[1,22,2.59],[2,21,5],[3,19.5,4.19],[4,18.5,1.37],[5,16.5,1.8],[6,15.5,4.19],[7,15,2.18],[8,12.5,1.18],[9,11,15.93]],"id":44621159},{"bdatl":[[0,7.6,158.81],[4,8.4,3]],"id":44836671}]}]}
{"op":"mcm","clk":"AOhGAPkkAOo9","pt":1659347532996,"mc":[{"id":"1.201590187","rc":[{"atl":[[1000,0.01]],"id":44836671}]}]}
{"op":"mcm","clk":"APlGAIQlAPw9","pt":1659347533268,"mc":[{"id":"1.201590187","rc":[{"atb":[[22,0]],"id":44621159},{"atb":[[18,7]],"id":46969227}]}]}
{"op":"mcm","clk":"AP1GAIQlAPw9","pt":1659347533318,"mc":[{"id":"1.201590187","rc":[{"bdatb":[[1,21,5],[2,19.5,4.19],[3,18.5,1.37],[4,16.5,1.8],[5,15.5,4.19],[6,15,2.18],[7,12.5,1.18],[8,11,15.93],[9,10,103.95]],"id":44621159},{"bdatb":[[5,18,7],[6,16,1.43],[7,14,2.33],[8,11.5,1.29],[9,10.5,1.64]],"id":46969227}]}]}
{"op":"mcm","clk":"AIJHAIglAP49","pt":1659347533420,"mc":[{"id":"1.201590187","rc":[{"atl":[[1000,0]],"id":44836671},{"atb":[[20,1.51]],"id":46969227}]}]}
{"op":"mcm","clk":"AINHAIolAIQ+","pt":1659347533470,"mc":[{"id":"1.201590187","rc":[{"bdatb":[[1,20,1.51]],"id":46969227}]}]}
{"op":"mcm","clk":"AIVHAIolAIg+","pt":1659347533520,"mc":[{"id":"1.201590187","rc":[{"atb":[[23,3.59]],"bdatb":[[0,23,4.08]],"id":44621159},{"bdatl":[[8,2.5,30.64],[9,2.56,1.9]],"id":9570503}]}]}
{"op":"mcm","clk":"AItHAI8lAIo+","pt":1659347533584,"mc":[{"id":"1.201590187","rc":[{"atb":[[6.8,23.33]],"trd":[[6.8,14.52]],"tv":203.11,"id":44836671},{"atb":[[8,9.32]],"id":43885158}],"tv":1267.64}]}
{"op":"mcm","clk":"AI5HAI8lAIw+","pt":1659347533635,"mc":[{"id":"1.201590187","rc":[{"bdatb":[[0,6.8,23.33]],"id":44836671},{"bdatb":[[1,8,9.32]],"id":43885158}]}]}
{"op":"mcm","clk":"AKtHAKUlAKM+","pt":1659347534094,"mc":[{"id":"1.201590187","rc":[{"atb":[[8.2,5.03]],"atl":[[9.2,3.48]],"trd":[[8.2,7.22]],"ltp":8.2,"tv":137.52,"id":43885158}],"tv":1271.64}]}
{"op":"mcm","clk":"AK5HAKglAKc+","pt":1659347534144,"mc":[{"id":"1.201590187","rc":[{"bdatb":[[4,1.98,53.1],[5,1.96,2.97],[6,1.94,5.03],[7,1.93,2.6],[8,1.91,107.36],[9,1.9,9.04]],"bdatl":[[8,2.5,26.03],[9,2.52,4.57]],"id":9570503},{"bdatb":[[0,6.2,9.79],[1,6,14.13],[3,5.6,3.01],[4,5.3,3.87],[5,5.1,8.19],[6,5,2.56],[7,4.9,3.52],[8,4.8,5.98],[9,4.7,7.34]],"id":12989514},{"bdatb":[[5,15.5,6.26],[6,12.5,1.22],[7,11,15.93],[8,10,103.95],[9,9.6,3.55]],"id":44621159},{"bdatb":[[0,8.2,5.03]],"bdatl":[[0,9.2,3.48],[1,9.4,7.98],[2,9.6,14.54],[3,10,3.45],[4,11.5,2.89],[5,12,1.4],[6,12.5,18],[7,14,1],[8,14.5,1],[9,15,12]],"id":43885158},{"bdatb":[[7,14.5,2.21],[8,11.5,1.34]],"id":46969227}]}]}
{"op":"mcm","clk":"ALRHAKolAKg+","pt":1659347534197,"mc":[{"id":"1.201590187","rc":[{"atb":[[8,6.41]],"atl":[[9.2,0]],"id":43885158}]}]}
{"op":"mcm","clk":"ALdHAK8lAKw+","pt":1659347534251,"mc":[{"id":"1.201590187","rc":[{"bdatb":[[4,1.98,36.93],[5,1.97,16.6],[6,1.96,2.62],[7,1.94,5.03],[8,1.93,2.6],[9,1.91,107.36]],"id":9570503},{"bdatb":[[0,6.2,4.63],[1,6,19.47],[3,5.6,1.85],[4,5.5,1.18],[5,5.2,4.29],[6,5.1,7.86],[7,5,2.56],[8,4.9,3.52],[9,4.8,5.98]],"id":12989514},{"bdatb":[[5,15.5,4.19],[6,15,2.18],[7,12.5,1.18],[8,11,15.93],[9,10,103.95]],"id":44621159},{"bdatb":[[1,8,6.41]],"bdatl":[[0,9.4,7.98],[1,9.6,14.54],[2,10,3.45],[3,11.5,2.89],[4,12,1.4],[5,12.5,18],[6,14,1],[7,14.5,1],[8,15,12],[9,15.5,1]],"id":43885158},{"bdatb":[[7,14,2.33],[8,11.5,1.29]],"id":46969227}]}]}
{"op":"mcm","clk":"ALtHALAlAK4+","pt":1659347534303,"mc":[{"id":"1.201590187","rc":[{"atb":[[23,1.12]],"id":44621159},{"atl":[[9.2,0.28]],"id":43885158}]}]}
{"op":"mcm","clk":"ALxHALMlALQ+","pt":1659347534353,"mc":[{"id":"1.201590187","rc":[{"bdatb":[[4,1.98,38.23],[5,1.97,15.29]],"bdatl":[[8,2.5,24.55],[9,2.52,1.47]],"id":9570503},{"bdatb":[[0,6.2,5.04],[1,6,19.04],[3,5.6,2.31],[4,5.4,1.21],[5,5.2,3.8]],"id":12989514},{"bdatb":[[0,23,1.61],[5,15.5,4.36],[6,15,2.01]],"id":44621159},{"bdatl":[[0,9.4,8.26]],"id":43885158}]}]}
{"op":"mcm","clk":"AMFHALMlALc+","pt":1659347534403,"mc":[{"id":"1.201590187","rc":[{"atb":[[8.2,0.5]],"atl":[[9.4,7.71]],"bdatb":[[0,8,6.91],[1,7.8,1.26],[2,7.6,4.27],[3,7.4,2.32],[4,7.2,3.71],[5,7,9.67],[6,6.6,64.73],[7,6.4,3.52],[8,6.2,10.81],[9,6,16.86]],"bdatl":[[0,9.4,7.99]],"id":43885158},{"bdatl":[[5,2.42,1.69],[6,2.44,155.28],[7,2.46,1.27],[8,2.48,5.52],[9,2.5,21]],"id":9570503},{"bdatb":[[3,5.6,1.86],[4,5.5,1.18],[5,5.2,4.29]],"bdatl":[[9,12,1.39]],"id":12989514},{"bdatl":[[9,13.5,1.86]],"id":44836671}]}]}
{"op":"mcm","clk":"AMVHALYlALo+","pt":1659347534465,"mc":[{"id":"1.201590187","rc":[{"atb":[[24,2.91]],"id":44621159},{"atb":[[7.8,5.8]],"id":43885158}]}]}
{"op":"mcm","clk":"AMhHALYlALw+","pt":1659347534516,"mc":[{"id":"1.201590187","rc":[{"bdatl":[[6,2.44,156.56],[7,2.48,5.52],[8,2.5,30.64],[9,2.58,5.53]],"id":9570503},{"bdatb":[[0,24,2.91],[1,23,1.12],[2,21,5],[3,19.5,4.19],[4,18.5,1.37],[5,16.5,1.8],[6,15.5,4.36],[7,15,2.01],[8,12.5,1.18],[9,11,15.93]],"id":44621159},{"bdatb":[[1,7.8,5.8]],"id":43885158}]}]}
{"op":"mcm","clk":"ANRHAL4lAMY+","pt":1659347534672,"mc":[{"id":"1.201590187","rc":[{"atb":[[8,4.08]],"id":43885158}]}]}
{"op":"mcm","clk":"ANdHAL4lAMk+","pt":1659347534723,"mc":[{"id":"1.201590187","rc":[{"bdatl":[[8,2.5,24.22],[9,2.52,6.37]],"id":9570503},{"bdatb":[[0,8,4.58]],"id":43885158}]}]}
{"op":"mcm","clk":"APZHANAlAOM+","pt":1659347535189,"mc":[{"id":"1.201590187","rc":[{"atb":[[24,0.49]],"id":44621159},{"atl":[[9.2,2.28]],"id":43885158}]}]}
{"op":"mcm","clk":"APhHANIlAOk+","pt":1659347535240,"mc":[{"id":"1.201590187","rc":[{"bdatb":[[4,1.98,47.53],[5,1.97,5.95]],"bdatl":[[6,2.44,155.28],[7,2.46,1.27],[8,2.48,5.52],[9,2.5,21]],"id":9570503},{"bdatb":[[0,6.2,8.01],[1,6,15.97],[3,5.6,3.01],[4,5.3,2.24],[5,5.2,2.01]],"id":12989514},{"bdatb":[[0,23,1.61],[1,21,5],[2,19.5,4.19],[3,18.5,1.37],[4,16.5,1.8],[5,15.5,5.55],[6,12.5,1.96],[7,11,15.93],[8,10,103.95],[9,9.6,2.65]],"id":44621159},{"bdatl":[[0,9.2,2.28],[1,9.4,7.71],[2,9.6,14.54],[3,10,3.45],[4,11.5,2.89],[5,12,1.4],[6,12.5,18],[7,14,1],[8,14.5,1],[9,15,12]],"id":43885158},{"bdatb":[[7,14.5,1.45],[8,11.5,2.13]],"id":46969227}]}]}
{"op":"mcm","clk":"AIBIANklAPM+","pt":1659347535397,"mc":[{"id":"1.201590187","rc":[{"atb":[[22,2.59]],"id":44621159}]}]}
{"op":"mcm","clk":"AIVIANklAPc+","pt":1659347535447,"mc":[{"id":"1.201590187","rc":[{"bdatb":[[1,22,2.59],[2,21,5],[3,19.5,4.19],[4,18.5,1.37],[5,16.5,1.8],[6,15.5,5.55],[7,12.5,1.96],[8,11,15.93],[9,10,103.95]],"id":44621159}]}]}
{"op":"mcm","clk":"AJRIAN4lAIg/","pt":1659347535706,"mc":[{"id":"1.201590187","rc":[{"atb":[[6.6,2.16]],"id":44836671}]}]}
{"op":"mcm","clk":"AJZIAOAlAI4/","pt":1659347535756,"mc":[{"id":"1.201590187","rc":[{"bdatb":[[1,6.6,2.16]],"id":44836671}]}]}
{"op":"mcm","clk":"AKtIAO0lAKY/","pt":1659347536090,"mc":[{"id":"1.201590187","rc":[{"atl":[[19.5,0]],"id":45323444}]}]}
{"op":"mcm","clk":"AKxIAO0lAKk/","pt":1659347536140,"mc":[{"id":"1.201590187","rc":[{"bdatl":[[1,23,2.64],[2,25,5.61],[3,26,5.04],[4,27,3.85],[5,29,8.93],[6,50,8],[7,55,9],[8,60,10],[9,65,11]],"id":45323444},{"bdatb":[[3,5.4,3.13],[4,5.2,4.3],[5,5.1,4.04],[6,5,6.46],[7,4.9,3.52],[8,4.8,5.98],[9,4.7,7.34]],"id":12989514},{"bdatb":[[9,10,102]],"id":44621159}]}]}
{"op":"mcm","clk":"ALBIAPAlAKw/","pt":1659347536190,"mc":[{"id":"1.201590187","rc":[{"atb":[[15,0]],"id":45323444},{"atb":[[22,0]],"id":44621159}]}]}
{"op":"mcm","clk":"ALFIAPAlAK4/","pt":1659347536241,"mc":[{"id":"1.201590187","rc":[{"bdatb":[[0,14,2.7],[1,12.5,1.14],[2,11.5,5.54],[3,11,1.23],[4,10.5,7.59],[5,10,10],[6,9.8,9],[7,9.6,21],[8,9.4,54.1],[9,9.2,12]],"id":45323444},{"bdatl":[[5,2.44,152.09],[6,2.46,1.67],[7,2.48,9.92],[8,2.5,21],[9,2.52,3.2]],"id":9570503},{"bdatl":[[9,12.5,1.09]],"id":12989514},{"bdatb":[[1,21,5],[2,19.5,4.19],[3,18.5,1.37],[4,16.5,1.8],[5,15.5,5.55],[6,12.5,1.96],[7,11,15.93],[8,10,102],[9,9.6,3.55]],"id":44621159},{"bdatl":[[9,13.5,1.55]],"id":44836671}]}]}
{"op":"mcm","clk":"ALxIAPMlALk/","pt":1659347536394,"mc":[{"id":"1.201590187","rc":[{"atb":[[23,4.59]],"atl":[[32,2.33]],"id":44621159}]}]}
{"op":"mcm","clk":"AL1IAPMlALs/","pt":1659347536446,"mc":[{"id":"1.201590187","rc":[{"bdatb":[[7,1.94,7.62],[8,1.91,116.35],[9,1.85,9.72]],"id":9570503},{"bdatb":[[3,5.4,3.33],[4,5.3,5.83],[5,5.2,2.11],[6,5.1,2.24],[7,5,4.18],[8,4.9,3.52],[9,4.8,5.98]],"id":12989514},{"bdatb":[[0,23,5.08]],"bdatl":[[0,32,2.33]],"id":44621159},{"bdatb":[[7,6.4,4.31],[8,6.2,10]],"id":43885158}]}]}
{"op":"mcm","clk":"AMFIAPQlAL8/","pt":1659347536496,"mc":[{"id":"1.201590187","rc":[{"atl":[[7.8,8.34]],"id":44836671},{"atb":[[8.2,0]],"atl":[[9.4,4.51]],"id":43885158},{"atb":[[21,1.6]],"id":46969227}]}]}
{"op":"mcm","clk":"AMJIAPQlAMM/","pt":1659347536546,"mc":[{"id":"1.201590187","rc":[{"bdatb":[[8,1.91,115.68],[9,1.84,10.45]],"bdatl":[[6,2.48,11.57],[7,2.5,21],[8,2.52,1.57],[9,2.56,2.01]],"id":9570503},{"bdatb":[[3,5.4,1.82],[4,5.3,7.37]],"bdatl":[[9,12.5,1.08]],"id":12989514},{"bdatb":[[9,9.6,1.68]],"id":44621159},{"bdatl":[[1,7.8,8.34]],"id":44836671},{"bdatb":[[0,8,4.08]],"bdatl":[[1,9.4,4.51]],"id":43885158},{"bdatb":[[0,21,1.6]],"id":46969227}]}]}
{"op":"mcm","clk":"AMpIAPYlAMU/","pt":1659347536598,"mc":[{"id":"1.201590187","rc":[{"atb":[[6.2,7.63],[6.4,1.15]],"id":12989514},{"atb":[[7,1.15],[6.6,10.86],[6.4,3.37]],"atl":[[7.4,3]],"id":44836671},{"atb":[[8,6.08]],"atl":[[9.2,4.69]],"id":43885158},{"atb":[[22,1.15],[20,3.81]],"atl":[[38,2.7],[36,0]],"id":46969227}]}]}
{"op":"mcm","clk":"AM1IAPglAMg/","pt":1659347536648,"mc":[{"id":"1.201590187","rc":[{"bdatb":[[3,11,3.24],[4,10.5,5.47],[9,9.2,13.13]],"id":45323444},{"bdatb":[[3,1.99,12.41],[4,1.98,42.24],[5,1.96,2.62],[6,1.94,7.62],[7,1.91,116.35],[8,1.85,9.72],[9,1.84,1.58]],"bdatl":[[4,2.4,74.49],[5,2.44,152.37],[6,2.46,1.56],[7,2.48,10.45],[8,2.5,21],[9,2.54,4.27]],"id":9570503},{"bdatb":[[0,6.4,1.15],[1,6.2,12.9],[2,6,15.77],[3,5.9,3.65],[4,5.4,3.33],[5,5.3,5.83],[6,5.2,2.11],[7,5.1,2.24],[8,5,4.18],[9,4.9,3.52]],"bdatl":[[9,12,1.15]],"id":12989514},{"bdatb":[[4,16.5,3.14],[5,15.5,4.87],[6,12.5,1.18],[9,9.6,3.55]],"id":44621159},{"bdatb":[[0,7,1.15],[1,6.8,23.33],[2,6.6,10.86],[3,6.4,3.37],[4,6.2,5.77],[5,6,35.19],[6,5.9,9.01],[7,5.8,30.83],[8,5.7,79.02],[9,5.6,13.86]],"bdatl":[[0,7.4,3],[1,7.6,158.81],[2,7.8,8.34],[3,8,7.32],[4,8.2,5.31],[5,8.4,3],[6,9.2,8],[7,9.8,33.55],[8,12,1.41],[9,13,41.9]],"id":44836671},{"bdatb":[[0,8,6.08],[4,7.2,6.79],[5,7,6.5]],"bdatl":[[0,9.2,4.69]],"id":43885158},{"bdatb":[[0,22,1.15],[1,21,1.6],[2,20,3.81],[3,19.5,7],[4,19,5],[5,18.5,8],[6,18,7],[7,16,1.43],[8,15.5,1.43],[9,12,1.59]],"bdatl":[[2,38,2.7]],"id":46969227}]}]}
{"op":"mcm","clk":"ANtIAPslAM8/","pt":1659347536799,"mc":[{"id":"1.201590187","rc":[{"atb":[[6.4,1.53]],"id":12989514},{"atb":[[7,1.51]],"atl":[[7.4,3.34]],"id":44836671},{"atb":[[7.8,8.04]],"id":43885158}]}]}
{"op":"mcm","clk":"AOBIAPslANI/","pt":1659347536850,"mc":[{"id":"1.201590187","rc":[{"bdatb":[[3,11,3.47],[4,10.5,5.23]],"id":45323444},{"bdatb":[[3,1.99,13.67],[4,1.98,40.97]],"bdatl":[[4,2.4,75.51],[5,2.44,152.41],[6,2.48,10.98],[7,2.5,21],[8,2.54,4.27],[9,2.56,1.33]],"id":9570503},{"bdatb":[[0,6.4,1.53]],"bdatl":[[9,12,1.16]],"id":12989514},{"bdatb":[[4,16.5,3.3],[5,15.5,4.71]],"id":44621159},{"bdatb":[[0,7,1.51]],"bdatl":[[0,7.4,3.34]],"id":44836671},{"bdatb":[[1,7.8,8.04],[4,7.2,7.14],[5,7,6.14]],"id":43885158},{"bdatb":[[8,15.5,1.59],[9,12,1.42]],"id":46969227}]}]}
{"op":"mcm","clk":"AOJIAP0lANM/","pt":1659347536902,"mc":[{"id":"1.201590187","rc":[{"atb":[[2.06,14.09]],"bdatb":[[0,2.06,14.09]],"bdatl":[[6,2.48,6.78],[7,2.5,25.17],[8,2.56,4.24],[9,2.58,1.32]],"id":9570503},{"atb":[[7.8,10.3]],"bdatb":[[1,7.8,10.3]],"id":43885158},{"atb":[[21,0.1]],"bdatb":[[1,20,3.91],[2,19.5,7],[3,19,5],[4,18.5,8],[5,18,7],[6,16,1.43],[7,15.5,1.59],[8,12,1.42],[9,10.5,2.02]],"id":46969227}]}]}
{"op":"mcm","clk":"AO1IAIAmANg/","pt":1659347537004,"mc":[{"id":"1.201590187","rc":[{"atb":[[2.04,17.32]],"id":9570503},{"atb":[[20,5.31]],"id":46969227}]}]}
{"op":"mcm","clk":"AO9IAIImANw/","pt":1659347537054,"mc":[{"id":"1.201590187","rc":[{"bdatb":[[1,2.04,17.32],[2,2.02,53.12],[3,2,1.24],[4,1.99,13.67],[5,1.98,40.97],[6,1.96,2.62],[7,1.94,7.62],[8,1.91,116.35],[9,1.85,9.72]],"id":9570503},{"bdatb":[[1,20,5.41]],"id":46969227}]}]}
{"op":"mcm","clk":"APpIAIUmAOU/","pt":1659347537209,"mc":[{"id":"1.201590187","rc":[{"atb":[[23,2.12]],"id":44621159},{"atb":[[1.02,0]],"id":46969227}]}]}
{"op":"mcm","clk":"AP5IAIcmAOk/","pt":1659347537259,"mc":[{"id":"1.201590187","rc":[{"bdatb":[[0,23,2.61]],"id":44621159}]}]}
{"op":"mcm","clk":"AIFJAIsmAO0/","pt":1659347537309,"mc":[{"id":"1.201590187","rc":[{"atb":[[6.2,25.79]],"bdatb":[[4,6.2,25.79]],"id":44836671},{"atb":[[20,6.94]],"bdatb":[[1,20,7.04]],"id":46969227}]}]}
{"op":"mcm","clk":"AIlJAI8mAPA/","pt":1659347537385,"mc":[{"id":"1.201590187","rc":[{"atb":[[24,2.91],[23,1.12]],"atl":[[32,1.33]],"id":44621159},{"atl":[[9.2,2.69]],"id":43885158}]}]}
{"op":"mcm","clk":"AIxJAI8mAPQ/","pt":1659347537436,"mc":[{"id":"1.201590187","rc":[{"bdatb":[[9,9.2,12]],"id":45323444},{"bdatb":[[5,1.98,36.95],[6,1.97,4.04],[7,1.96,2.62],[8,1.94,5.03],[9,1.93,2.6]],"bdatl":[[6,2.46,5.98],[7,2.48,5.05],[8,2.5,21],[9,2.54,4.27]],"id":9570503},{"bdatb":[[1,6.2,11.62],[2,6,15.34],[3,5.9,5.42],[4,5.3,3.17],[5,5.2,4.3],[6,5.1,4.04],[7,5,6.46],[8,4.9,3.52],[9,4.8,5.98]],"bdatl":[[9,12,2.27]],"id":12989514},{"bdatb":[[0,24,2.91],[1,23,1.12],[2,21,5],[3,19.5,4.19],[4,18.5,1.37],[5,16.5,3.3],[6,15.5,4.2],[7,12.5,1.71],[8,11,15.93],[9,10,102]],"bdatl":[[0,32,1.33]],"id":44621159},{"bdatb":[[6,5.9,9],[7,5.8,30.84],[9,5.6,12]],"id":44836671},{"bdatb":[[7,6.4,3.52],[8,6.2,10.81]],"bdatl":[[0,9.2,2.69]],"id":43885158},{"bdatb":[[8,11.5,1.86],[9,10.5,1.64]],"id":46969227}]}]}
{"op":"mcm","clk":"AJNJAJImAPc/","pt":1659347537486,"mc":[{"id":"1.201590187","rc":[{"atl":[[1000,0.41]],"id":46969227}]}]}
{"op":"mcm","clk":"AJdJAJImAPo/","pt":1659347537536,"mc":[{"id":"1.201590187","rc":[{"bdatl":[[7,1000,0.41]],"id":46969227}]}]}
{"op":"mcm","clk":"AJ5JAJUmAP0/","pt":1659347537587,"mc":[{"id":"1.201590187","rc":[{"atb":[[2.04,32.87]],"id":9570503}]}]}
{"op":"mcm","clk":"AJ9JAJYmAIBA","pt":1659347537637,"mc":[{"id":"1.201590187","rc":[{"bdatb":[[1,2.04,32.87]],"id":9570503}]}]}
{"op":"mcm","clk":"AKZJAJkmAINA","pt":1659347537716,"mc":[{"id":"1.201590187","rc":[{"atl":[[1000,0]],"id":46969227}]}]}
{"op":"mcm","clk":"AKdJAJkmAIVA","pt":1659347537766,"mc":[{"id":"1.201590187","rc":[{"bdatl":[[7,0,0]],"id":46969227}]}]}
{"op":"mcm","clk":"AK5JAJ0mAIhA","pt":1659347537816,"mc":[{"id":"1.201590187","rc":[{"atl":[[27,0.41]],"id":46969227}]}]}
{"op":"mcm","clk":"AK9JAJ4mAI5A","pt":1659347537866,"mc":[{"id":"1.201590187","rc":[{"bdatb":[[3,2,6.79],[4,1.99,8.09]],"id":9570503},{"bdatb":[[0,6.4,3.26],[1,6.2,9.83]],"id":12989514},{"bdatb":[[5,16.5,3.27]],"id":44621159},{"bdatl":[[0,28,8.05]],"id":46969227}]}]}
{"op":"mcm","clk":"ALZJAKEmAJFA","pt":1659347537916,"mc":[{"id":"1.201590187","rc":[{"atb":[[7.8,5.77]],"id":43885158}]}]}
{"op":"mcm","clk":"ALhJAKQmAJZA","pt":1659347537968,"mc":[{"id":"1.201590187","rc":[{"bdatb":[[1,7.8,5.77]],"id":43885158}]}]}
{"op":"mcm","clk":"ALtJAKYmAJlA","pt":1659347538018,"mc":[{"id":"1.201590187","rc":[{"atb":[[7.6,8.8]],"atl":[[8.2,2]],"id":43885158},{"atl":[[27,0.51]],"id":46969227}]}]}
{"op":"mcm","clk":"AL1JAKcmAJpA","pt":1659347538068,"mc":[{"id":"1.201590187","rc":[{"bdatb":[[1,13,1.26],[2,12.5,1.14],[3,11.5,5.54],[4,11,1.98],[5,10.5,5.23],[6,10,10],[7,9.8,9],[8,9.6,21],[9,9.4,54.1]],"id":45323444},{"bdatb":[[1,2.04,40.91],[3,2,1.24],[4,1.99,5.43],[5,1.98,40.97],[6,1.96,2.62],[7,1.94,5.03],[8,1.93,2.6],[9,1.91,107.36]],"id":9570503},{"bdatb":[[0,7,1.97],[1,6.4,1.91],[2,6.2,10.25],[3,6,15.44],[4,5.9,3.99],[5,5.4,3.13],[6,5.2,4.3],[7,5.1,4.04],[8,5,6.46],[9,4.9,3.52]],"id":12989514},{"bdatb":[[2,21,5.75],[5,16.5,2.3],[6,15.5,4.71],[7,12.5,1.18]],"id":44621159},{"bdatb":[[2,6.6,13.35],[5,6,32.45],[6,5.9,9.01],[7,5.8,30.83],[9,5.6,13.51]],"id":44836671},{"bdatb":[[2,7.6,8.8]],"bdatl":[[0,8.2,2],[1,9.2,2.69],[2,9.4,4.51],[3,9.6,14.54],[4,10,3.45],[5,11.5,2.89],[6,12,1.4],[7,12.5,18],[8,14,1],[9,14.5,1]],"id":43885158},{"bdatb":[[2,19.5,7.84],[7,14.5,1.09],[8,11.5,1.25]],"bdatl":[[0,28,8.15]],"id":46969227}]}]}
{"op":"mcm","clk":"AMVJAKkmAJxA","pt":1659347538118,"mc":[{"id":"1.201590187","rc":[{"atb":[[24,0.49]],"id":44621159}]}]}
{"op":"mcm","clk":"AMdJAKomAKBA","pt":1659347538169,"mc":[{"id":"1.201590187","rc":[{"bdatl":[[6,2.48,6.78],[7,2.5,25.08],[8,2.58,4.3],[9,2.6,1.31]],"id":9570503},{"bdatl":[[9,12,1.16]],"id":12989514},{"bdatb":[[0,23,1.61],[1,21,5.75],[2,19.5,4.19],[3,18.5,1.37],[4,16.5,2.3],[5,15.5,4.71],[6,12.5,1.18],[7,11,15.93],[8,10,102],[9,9.6,3.55]],"id":44621159}]}]}
{"op":"mcm","clk":"AMpJAKwmAKZA","pt":1659347538219,"mc":[{"id":"1.201590187","rc":[{"atb":[[2.06,12.09]],"atl":[[2.12,0]],"trd":[[2.12,151.39],[2.06,42.06]],"tv":827.51,"id":9570503},{"atb":[[6.2,13.09]],"id":12989514},{"atb":[[22,2.59]],"id":44621159},{"atl":[[11,0.01],[8.2,0]],"trd":[[8.2,11.22]],"tv":141.52,"id":43885158}],"tv":1310.46}]}
{"op":"mcm","clk":"AM9JAK4mAKdA","pt":1659347538269,"mc":[{"id":"1.201590187","rc":[{"bdatb":[[1,12.5,1.14],[2,11.5,5.54],[3,11,1.23],[4,10.5,6.83],[5,10,10.8],[6,9.8,9],[7,9.6,21],[8,9.4,54.1],[9,9.2,12]],"id":45323444},{"bdatb":[[0,2.06,12.09],[1,2.04,32.87],[3,2,8.14],[4,1.99,6.74],[5,1.98,36.95],[6,1.97,4.04],[7,1.96,2.62],[8,1.94,5.03],[9,1.93,2.6]],"bdatl":[[0,2.14,58],[1,2.18,1.18],[2,2.3,8.99],[3,2.4,75.51],[4,2.44,152.41],[5,2.48,6.78],[6,2.5,25.08],[7,2.56,4.33],[8,2.58,1.32],[9,2.64,14.73]],"id":9570503},{"bdatb":[[0,6.4,1.53],[1,6.2,15.31],[2,6,15.85],[3,5.9,6.76],[4,5.3,3.17],[5,5.2,4.3],[6,5.1,3.96],[7,4.9,3.6],[8,4.8,5.9],[9,4.7,7.34]],"id":12989514},{"bdatb":[[1,22,2.59],[2,21,5],[3,19.5,4.19],[4,18.5,1.37],[5,16.5,1.8],[6,15.5,5.79],[7,12.5,1.75],[8,11,15.93],[9,10,102]],"id":44621159},{"bdatb":[[2,6.6,10.86],[5,6,29.74],[6,5.9,13.19],[7,5.8,32.2],[9,5.6,12]],"id":44836671},{"bdatb":[[4,7.2,3.71],[5,7,8.53],[6,6.8,1.18],[7,6.6,64.72],[8,6.4,3.52],[9,6.2,10.81]],"bdatl":[[0,9.2,2.69],[1,9.4,4.51],[2,9.6,14.54],[3,10,3.45],[4,11.5,2.65],[5,12,1.4],[6,12.5,18],[7,14,1],[8,14.5,1],[9,15,12]],"id":43885158},{"bdatb":[[2,19.5,7],[7,14.5,1.7],[8,11.5,1.9]],"id":46969227}]}]}
{"op":"mcm","clk":"AONJALkmAMBA","pt":1659347538589,"mc":[{"id":"1.201590187","rc":[{"atb":[[2.04,17.32],[2.02,39.06]],"id":9570503},{"atb":[[6.6,2.16]],"id":44836671},{"atb":[[7.6,4.53]],"id":43885158}]}]}
{"op":"mcm","clk":"AOZJALkmAMNA","pt":1659347538640,"mc":[{"id":"1.201590187","rc":[{"bdatb":[[1,2.04,17.32],[2,2.02,39.06]],"id":9570503},{"bdatb":[[2,6.6,2.16]],"id":44836671},{"bdatb":[[2,7.6,4.53]],"id":43885158}]}]}
{"op":"mcm","clk":"APhJAL8mANJA","pt":1659347538917,"mc":[{"id":"1.201590187","rc":[{"atb":[[22,0]],"id":44621159}]}]}
{"op":"mcm","clk":"APpJAL8mANVA","pt":1659347538967,"mc":[{"id":"1.201590187","rc":[{"bdatl":[[7,2.58,4.3],[8,2.6,1.31]],"id":9570503},{"bdatb":[[1,21,5],[2,19.5,4.19],[3,18.5,1.37],[4,16.5,1.8],[5,15.5,5.79],[6,12.5,1.75],[7,11,15.93],[8,10,102],[9,9.6,1.94]],"id":44621159}]}]}
{"op":"mcm","clk":"AIFKAMEmANpA","pt":1659347539017,"mc":[{"id":"1.201590187","rc":[{"atb":[[23,3.59]],"bdatb":[[0,23,4.08]],"id":44621159},{"atb":[[7.8,3.53]],"bdatb":[[1,7.8,3.53]],"id":43885158},{"bdatl":[[6,2.5,25.17],[7,2.56,4.24],[8,2.58,1.32],[9,2.62,9.21]],"id":9570503}]}]}
{"op":"mcm","clk":"AI5KAMYmAORA","pt":1659347539207,"mc":[{"id":"1.201590187","rc":[{"atb":[[7.8,1.26]],"id":43885158}]}]}
{"op":"mcm","clk":"AJFKAMgmAOhA","pt":1659347539257,"mc":[{"id":"1.201590187","rc":[{"bdatl":[[9,2.62,2.47]],"id":9570503},{"bdatb":[[1,7.8,1.26]],"id":43885158}]}]}
{"op":"mcm","clk":"ALBKANcmAINB","pt":1659347539772,"mc":[{"id":"1.201590187","rc":[{"atb":[[23,1.12]],"id":44621159}]}]}
{"op":"mcm","clk":"ALJKANkmAIdB","pt":1659347539822,"mc":[{"id":"1.201590187","rc":[{"bdatl":[[6,2.5,25.08],[7,2.58,4.3],[8,2.6,1.31],[9,2.64,2.45]],"id":9570503},{"bdatb":[[0,23,1.61]],"id":44621159}]}]}
{"op":"mcm","clk":"ALZKANsmAIpB","pt":1659347539910,"mc":[{"id":"1.201590187","marketDefinition":{"bspMarket":true,"turnInPlayEnabled":true,"persistenceEnabled":true,"marketBaseRate":5,"eventId":"31628781","eventTypeId":"7","numberOfWinners":1,"bettingType":"ODDS","marketType":"WIN","marketTime":"2022-08-01T10:00:00.000Z","suspendTime":"2022-08-01T10:00:00.000Z","bspReconciled":false,"complete":true,"inPlay":false,"crossMatching":true,"runnersVoidable":false,"numberOfActiveRunners":7,"betDelay":0,"status":"OPEN","runners":[{"adjustmentFactor":3.355,"status":"ACTIVE","sortPriority":1,"id":44621159},{"adjustmentFactor":2.163,"status":"ACTIVE","sortPriority":2,"id":45323444},{"adjustmentFactor":63.661,"status":"ACTIVE","sortPriority":3,"id":9570503},{"adjustmentFactor":13.991,"status":"ACTIVE","sortPriority":4,"id":44836671},{"adjustmentFactor":7.118,"status":"ACTIVE","sortPriority":5,"id":43885158},{"adjustmentFactor":1.044,"status":"ACTIVE","sortPriority":6,"id":46969227},{"adjustmentFactor":8.669,"status":"ACTIVE","sortPriority":7,"id":12989514}],"regulators":["MR_INT"],"venue":"DAX","countryCode":"FR","discountAllowed":true,"timezone":"Europe/London","openDate":"2022-08-01T10:00:00.000Z","version":4679023832,"raceType":"Flat","priceLadderDefinition":{"type":"CLASSIC"}}}]}
{"op":"mcm","clk":"AL1KAOImAJBB","pt":1659347539989,"mc":[{"id":"1.201590187","rc":[{"atb":[[24,2.91]],"id":44621159}]}]}
{"op":"mcm","clk":"AL9KAOImAJVB","pt":1659347540040,"mc":[{"id":"1.201590187","rc":[{"bdatl":[[5,2.46,5.98],[6,2.48,5.05],[7,2.5,21],[8,2.54,4.27],[9,2.56,1.33]],"id":9570503},{"bdatl":[[9,12,2.24]],"id":12989514},{"bdatb":[[0,24,2.91],[1,23,1.12],[2,21,5],[3,19.5,4.19],[4,18.5,1.37],[5,16.5,1.8],[6,15.5,5.79],[7,12.5,1.75],[8,11,15.93],[9,10,102]],"id":44621159}]}]}
{"op":"mcm","clk":"ANJKAO8mAK5B","pt":1659347540399,"mc":[{"id":"1.201590187","rc":[{"atl":[[10,0]],"id":43885158}]}]}
{"op":"mcm","clk":"ANVKAO8mALdB","pt":1659347540454,"mc":[{"id":"1.201590187","rc":[{"bdatl":[[3,11.5,2.65],[4,12,1.4],[5,12.5,18],[6,14,1],[7,14.5,1],[8,15,12],[9,15.5,1]],"id":43885158}]}]}
{"op":"mcm","clk":"ANtKAPgmALlB","pt":1659347540509,"mc":[{"id":"1.201590187","rc":[{"atb":[[2.06,13.88]],"id":9570503},{"atb":[[23,1]],"id":44621159},{"atl":[[10.5,3.45]],"id":43885158}]}]}
{"op":"mcm","clk":"AN1KAPkmAL5B","pt":1659347540559,"mc":[{"id":"1.201590187","rc":[{"bdatb":[[0,2.06,13.88]],"id":9570503},{"bdatl":[[9,12,2.27]],"id":12989514},{"bdatb":[[1,23,1]],"id":44621159},{"bdatl":[[3,10.5,3.45],[4,11.5,2.65],[5,12,1.4],[6,12.5,18],[7,14,1],[8,14.5,1],[9,15,12]],"id":43885158}]}]}
{"op":"mcm","clk":"AO9KAIUnANBB","pt":1659347540809,"mc":[{"id":"1.201590187","rc":[{"bdatl":[[5,2.48,6.78],[6,2.5,24],[7,2.52,1.16],[8,2.58,4.21],[9,2.6,1.31]],"id":9570503},{"bdatl":[[9,12,1.16]],"id":12989514},{"bdatb":[[0,23,1.49],[1,21,5],[2,19.5,4.19],[3,18.5,1.37],[4,16.5,1.8],[5,15.5,5.79],[6,12.5,1.75],[7,11,15.93],[8,10,102],[9,9.6,1.94]],"id":44621159}]}]}
{"op":"mcm","clk":"APNKAIUnANZB","pt":1659347540859,"mc":[{"id":"1.201590187","rc":[{"atb":[[24,0.49]],"id":44621159}]}]}
{"op":"mcm","clk":"APVKAIcnANdB","pt":1659347540912,"mc":[{"id":"1.201590187","rc":[{"atb":[[6.8,24.97]],"id":44836671}]}]}
{"op":"mcm","clk":"APZKAIcnAN1B","pt":1659347540962,"mc":[{"id":"1.201590187","rc":[{"bdatb":[[1,6.8,24.97]],"id":44836671}]}]}
{"op":"mcm","clk":"AP5KAI0nAN5B","pt":1659347541012,"mc":[{"id":"1.201590187","rc":[{"atb":[[22,2.59]],"id":44621159}]}]}
{"op":"mcm","clk":"AP9KAI4nAONB","pt":1659347541067,"mc":[{"id":"1.201590187","rc":[{"bdatl":[[8,2.56,4.24],[9,2.58,1.32]],"id":9570503},{"bdatb":[[1,22,2.59],[2,21,5],[3,19.5,4.19],[4,18.5,1.37],[5,16.5,1.8],[6,15.5,5.79],[7,12.5,1.75],[8,11,15.93],[9,10,102]],"id":44621159}]}]}
{"op":"mcm","clk":"AJBLAJYnAO9B","pt":1659347541285,"mc":[{"id":"1.201590187","rc":[{"atb":[[7.6,6.9]],"id":43885158}]}]}
{"op":"mcm","clk":"AJFLAJgnAPFB","pt":1659347541336,"mc":[{"id":"1.201590187","rc":[{"bdatb":[[2,7.6,6.9]],"id":43885158}]}]}
{"op":"mcm","clk":"AJhLAJonAPZB","pt":1659347541401,"mc":[{"id":"1.201590187","rc":[{"atl":[[7.4,10.34],[8.2,0.31]],"id":44836671},{"atb":[[7.4,4.7]],"id":43885158}]}]}
{"op":"mcm","clk":"AJlLAJonAPpB","pt":1659347541451,"mc":[{"id":"1.201590187","rc":[{"bdatb":[[8,9.4,55.13],[9,9.2,12.55]],"id":45323444},{"bdatb":[[4,1.99,6.75],[5,1.98,40.95],[6,1.96,2.62],[7,1.95,5],[8,1.94,2.59],[9,1.91,116.35]],"id":9570503},{"bdatb":[[2,6,22.5],[3,5.4,2.18],[4,5.2,5.25],[5,5.1,3.96],[6,4.9,3.6],[7,4.8,5.9],[8,4.7,7.34],[9,4.6,15.8]],"id":12989514},{"bdatb":[[7,13,1.69],[8,11.5,1.49],[9,11,14.37]],"id":44621159},{"bdatl":[[0,7.4,10.34],[4,8.4,3.31],[5,9.2,8],[6,9.8,33.55],[7,12,1.41],[8,13,41.9],[9,13.5,2.28]],"id":44836671},{"bdatb":[[3,7.4,4.7],[5,7,9.67],[6,6.6,66.19],[7,6.4,2.79],[8,6.2,12.77],[9,6,14]],"id":43885158},{"bdatb":[[7,14.5,1.71],[8,12,1.8],[9,11,1.56]],"id":46969227}]}]}
{"op":"mcm","clk":"AKtLAKAnAINC","pt":1659347541604,"mc":[{"id":"1.201590187","rc":[{"atb":[[5.7,44.55]],"id":44836671}]}]}
{"op":"mcm","clk":"AMNLAK0nAJdC","pt":1659347541881,"mc":[{"id":"1.201590187","rc":[{"atb":[[23,3.47],[22,0]],"bdatb":[[1,21,5],[2,19.5,4.19],[3,18.5,1.37],[4,16.5,1.8],[5,15.5,5.79],[6,13,1.69],[7,11.5,1.49],[8,11,14.37],[9,10,102.25],[0,23,3.96]],"id":44621159},{"atl":[[34,7.09]],"bdatl":[[1,34,7.25]],"id":46969227},{"bdatl":[[6,2.5,25.17],[7,2.56,4.24],[8,2.58,1.32],[9,2.62,2.47]],"id":9570503},{"bdatb":[[8,5.7,44.55]],"id":44836671}],"con":true}]}
{"op":"mcm","clk":"AMdLALAnAJlC","pt":1659347541931,"mc":[{"id":"1.201590187","rc":[{"atl":[[36,1.1]],"bdatl":[[2,36,1.1],[3,38,2.7],[4,40,5.01],[5,80,1.66],[6,310,1],[7,990,2.15]],"id":46969227}]}]}
{"op":"mcm","clk":"AMpLALQnAJxC","pt":1659347542015,"mc":[{"id":"1.201590187","rc":[{"atb":[[6.8,19.91]],"id":44836671}]}]}
{"op":"mcm","clk":"AMtLALUnAKFC","pt":1659347542065,"mc":[{"id":"1.201590187","rc":[{"bdatb":[[1,6.8,19.91]],"id":44836671}]}]}
{"op":"mcm","clk":"ANBLALgnAKNC","pt":1659347542115,"mc":[{"id":"1.201590187","rc":[{"atb":[[4.7,0]],"bdatb":[[8,4.6,15.8],[9,4.5,222]],"id":12989514},{"atb":[[20,11.94],[18,0]],"bdatb":[[1,20,12.04],[5,16,1.43],[6,14.5,1.71],[7,12,1.8],[8,11,1.56],[9,10,2]],"id":46969227}]}]}
{"op":"mcm","clk":"ANdLALsnAKZC","pt":1659347542183,"mc":[{"id":"1.201590187","rc":[{"atb":[[6.4,8.87]],"id":12989514}]}]}
{"op":"mcm","clk":"ANlLALsnAKlC","pt":1659347542233,"mc":[{"id":"1.201590187","rc":[{"bdatl":[[3,2.4,75.83],[4,2.44,158.12],[5,2.46,5.09],[6,2.5,21],[7,2.52,4.31],[8,2.54,1.34],[9,2.58,1.82]],"id":9570503},{"bdatb":[[0,6.4,8.87]],"id":12989514},{"bdatl":[[9,13.5,2.43]],"id":44836671}]}]}
{"op":"mcm","clk":"AOxLAMInALJC","pt":1659347542495,"mc":[{"id":"1.201590187","rc":[{"atb":[[23,1]],"id":44621159}]}]}
{"op":"mcm","clk":"AO5LAMInALZC","pt":1659347542545,"mc":[{"id":"1.201590187","rc":[{"bdatl":[[5,2.46,3.9],[6,2.5,22.17],[7,2.54,4.27],[8,2.56,1.33],[9,2.62,1.79]],"id":9570503},{"bdatb":[[0,23,1.49]],"id":44621159}]}]}
{"op":"mcm","clk":"AP1LAMUnAMBC","pt":1659347542698,"mc":[{"id":"1.201590187","rc":[{"atb":[[24,2.91]],"id":44621159}]}]}
{"op":"mcm","clk":"AP5LAMYnAMNC","pt":1659347542748,"mc":[{"id":"1.201590187","rc":[{"bdatl":[[4,2.44,158.98],[5,2.46,4.23],[6,2.5,25.34],[7,2.54,1.34],[8,2.58,1.82],[9,2.64,13.66]],"id":9570503},{"bdatl":[[9,12,2.27]],"id":12989514},{"bdatb":[[0,24,2.91],[1,23,1],[2,21,5],[3,19.5,4.19],[4,18.5,1.37],[5,16.5,1.8],[6,15.5,5.79],[7,13,1.69],[8,11.5,1.49],[9,11,14.37]],"id":44621159},{"bdatl":[[9,13.5,3.43]],"id":44836671}]}]}
{"op":"mcm","clk":"AIVMAMgnAMRC","pt":1659347542802,"mc":[{"id":"1.201590187","rc":[{"atl":[[1000,3.34]],"id":12989514}]}]}
{"op":"mcm","clk":"AJtMANEnANNC","pt":1659347543112,"mc":[{"id":"1.201590187","rc":[{"atb":[[14,0]],"id":45323444},{"atb":[[6.2,10.09]],"id":12989514},{"atb":[[6.4,0.37]],"id":44836671},{"atb":[[8.2,1.15]],"atl":[[9.2,3.84]],"id":43885158}]}]}
{"op":"mcm","clk":"AJ9MANMnANRC","pt":1659347543163,"mc":[{"id":"1.201590187","rc":[{"bdatb":[[0,12.5,1.14],[1,11.5,5.54],[2,11,1.23],[3,10.5,7.59],[4,10,10],[5,9.8,9],[6,9.6,21.27],[7,9.4,54.86],[8,9.2,12.55],[9,9,13]],"id":45323444},{"bdatb":[[4,1.99,10.75],[5,1.98,36.93],[6,1.96,3.95],[7,1.95,3.66]],"bdatl":[[3,2.4,71.43],[4,2.44,155.95],[5,2.48,1.95],[6,2.5,21],[7,2.52,4.38],[8,2.56,12.3],[9,2.6,4.31]],"id":9570503},{"bdatb":[[1,6.2,12.31],[3,5.5,2.16]],"bdatl":[[9,13.5,1.24]],"id":12989514},{"bdatb":[[6,15.5,6.3],[7,13,1.13]],"id":44621159},{"bdatb":[[3,6.2,26.16],[4,6,29.74],[5,5.9,14.54],[6,5.8,30.83],[7,5.7,44.55],[8,5.6,12.47],[9,5.5,25.21]],"bdatl":[[9,13.5,1.55]],"id":44836671},{"bdatb":[[0,8.2,1.15],[1,8,6.08],[2,7.8,1.26],[3,7.6,6.9],[4,7.4,4.7],[5,7.2,3.71],[6,7,9.67],[7,6.6,66.19],[8,6.4,2.79],[9,6.2,12.77]],"bdatl":[[0,9.2,3.84]],"id":43885158},{"bdatb":[[6,14.5,2.26],[7,12,1.22]],"id":46969227}]}]}
{"op":"mcm","clk":"AKNMANYnANVC","pt":1659347543216,"mc":[{"id":"1.201590187","rc":[{"atb":[[12.5,3.2]],"id":45323444},{"atb":[[6.4,11.87]],"atl":[[1000,0.47]],"id":12989514}]}]}
{"op":"mcm","clk":"AKZMANcnANlC","pt":1659347543267,"mc":[{"id":"1.201590187","rc":[{"bdatb":[[0,12.5,3.2]],"id":45323444},{"bdatl":[[5,2.48,6.39],[6,2.5,26.89],[7,2.56,7.06],[8,2.58,3.82],[9,2.6,3.08]],"id":9570503},{"bdatb":[[0,6.4,11.87]],"bdatl":[[9,13.5,2.06]],"id":12989514}]}]}
{"op":"mcm","clk":"AKpMANgnANxC","pt":1659347543318,"mc":[{"id":"1.201590187","rc":[{"atb":[[7,0.36]],"bdatb":[[0,6.8,20.27],[1,6.6,2.16],[2,6.2,26.16],[3,6,29.74],[4,5.9,14.54],[5,5.8,30.83],[6,5.7,44.55],[7,5.6,12.47],[8,5.5,25.21],[9,5.4,14]],"id":44836671},{"atb":[[22,0]],"bdatb":[[0,20,12.04],[1,19.5,7],[2,19,5],[3,18.5,8],[4,16,1.43],[5,14.5,2.26],[6,12,1.22],[7,11,1.56],[8,10,2],[9,9.4,1.26]],"id":46969227},{"bdatl":[[4,2.44,152.09],[5,2.46,1.02],[6,2.5,35.99]],"id":9570503},{"bdatl":[[9,14.5,2.14]],"id":12989514}]}]}
{"op":"mcm","clk":"ALJMANonAOJC","pt":1659347543386,"mc":[{"id":"1.201590187","rc":[{"atb":[[24,0.49]],"id":44621159},{"atb":[[5.7,4]],"id":43885158}]}]}
{"op":"mcm","clk":"ALRMANonAOVC","pt":1659347543438,"mc":[{"id":"1.201590187","rc":[{"bdatl":[[6,2.5,24.74],[7,2.52,9.13],[8,2.54,2.02],[9,2.6,6.95]],"id":9570503},{"bdatb":[[0,23,1.49],[1,21,5],[2,19.5,4.19],[3,18.5,1.37],[4,16.5,1.8],[5,15.5,6.3],[6,13,1.13],[7,11.5,1.49],[8,11,14.37],[9,10,103.19]],"id":44621159}]}]}
{"op":"mcm","clk":"ALpMAN4nAOdC","pt":1659347543502,"mc":[{"id":"1.201590187","rc":[{"atl":[[1000,0.89]],"id":45323444},{"atb":[[1.16,1.68]],"id":44621159},{"atl":[[1000,2.88]],"id":44836671},{"atb":[[18,5]],"id":46969227}]}]}
{"op":"mcm","clk":"AL1MAN4nAOlC","pt":1659347543552,"mc":[{"id":"1.201590187","rc":[{"bdatb":[[4,18,5],[5,16,1.43],[6,14.5,2.26],[7,12,1.22],[8,11,1.56],[9,10,2]],"id":46969227}]}]}
{"op":"mcm","clk":"AMRMAOEnAOxC","pt":1659347543602,"mc":[{"id":"1.201590187","rc":[{"atb":[[6.2,15.76]],"id":12989514},{"atb":[[22,2.59]],"id":44621159},{"atb":[[5.2,25.81],[7.6,11.12]],"id":43885158},{"atb":[[20,6.94]],"id":46969227}]}]}
{"op":"mcm","clk":"AMVMAOMnAO9C","pt":1659347543652,"mc":[{"id":"1.201590187","rc":[{"bdatl":[[9,2.58,7.01]],"id":9570503},{"bdatb":[[1,6.2,17.98]],"id":12989514},{"bdatb":[[1,22,2.59],[2,21,5],[3,19.5,4.19],[4,18.5,1.37],[5,16.5,1.8],[6,15.5,6.3],[7,13,1.13],[8,11.5,1.49],[9,11,14.37]],"id":44621159},{"bdatb":[[3,7.6,11.12]],"id":43885158},{"bdatb":[[0,20,7.04]],"id":46969227}]}]}
{"op":"mcm","clk":"AM1MAOYnAPFC","pt":1659347543710,"mc":[{"id":"1.201590187","rc":[{"atl":[[1000,0.48]],"id":45323444},{"atb":[[6.4,11.86]],"trd":[[6.4,38.79]],"ltp":6.4,"tv":80.16,"id":12989514},{"atb":[[1.16,0.11]],"id":44621159}],"tv":1310.47}]}
{"op":"mcm","clk":"AM5MAOYnAPRC","pt":1659347543760,"mc":[{"id":"1.201590187","rc":[{"bdatb":[[0,6.4,11.86]],"id":12989514}]}]}
{"op":"mcm","clk":"ANVMAOknAPZC","pt":1659347543812,"mc":[{"id":"1.201590187","rc":[{"atl":[[16,0.41]],"id":45323444}]}]}
{"op":"mcm","clk":"ANVMAOonAPlC","pt":1659347543862,"mc":[{"id":"1.201590187","rc":[{"bdatl":[[0,16.5,4.33]],"id":45323444},{"bdatb":[[9,1.91,119.79]],"id":9570503},{"bdatb":[[2,6,23.6],[3,5.4,1.19],[4,5.2,5.02],[6,4.9,4.04],[7,4.8,5.44]],"id":12989514},{"bdatb":[[6,15.5,6.29],[8,11.5,2.06]],"id":44621159},{"bdatb":[[3,6,30.84],[4,5.9,13.43]],"id":44836671},{"bdatb":[[5,7.2,4.62],[6,7,8.73],[9,6.2,13.83]],"id":43885158},{"bdatb":[[8,11,2.16]],"id":46969227}]}]}
{"op":"mcm","clk":"ANlMAOsnAPpC","pt":1659347543913,"mc":[{"id":"1.201590187","rc":[{"atb":[[1.16,0]],"id":44621159},{"atl":[[1000,0.01]],"id":44836671}]}]}
{"op":"mcm","clk":"ANxMAO4nAIFD","pt":1659347544012,"mc":[{"id":"1.201590187","rc":[{"atb":[[25,0.11]],"id":44621159}]}]}
{"op":"mcm","clk":"AOJMAO4nAIRD","pt":1659347544062,"mc":[{"id":"1.201590187","rc":[{"bdatl":[[4,2.44,152.95],[5,2.5,26],[6,2.52,9.13],[7,2.58,7.96],[8,2.6,3.79],[9,2.62,3.04]],"id":9570503},{"bdatl":[[9,14.5,2.15]],"id":12989514},{"bdatb":[[0,23,1.6]],"id":44621159}]}]}
{"op":"mcm","clk":"APFMAPonAJhD","pt":1659347544395,"mc":[{"id":"1.201590187","rc":[{"atb":[[22,0]],"id":44621159},{"atl":[[1000,0]],"id":44836671}]}]}
{"op":"mcm","clk":"APNMAPonAJpD","pt":1659347544445,"mc":[{"id":"1.201590187","rc":[{"bdatl":[[7,2.6,7.9],[8,2.62,3.77],[9,2.64,3.02]],"id":9570503},{"bdatb":[[1,21,5],[2,19.5,4.19],[3,18.5,1.37],[4,16.5,1.8],[5,15.5,6.29],[6,13,1.13],[7,11.5,2.06],[8,11,14.37],[9,10,102.53]],"id":44621159}]}]}
{"op":"mcm","clk":"APdMAP4nAJxD","pt":1659347544499,"mc":[{"id":"1.201590187","rc":[{"atb":[[7,0.35]],"trd":[[7,20.8]],"ltp":7,"tv":203.13,"id":44836671}],"tv":1310.49}]}
{"op":"mcm","clk":"APhMAP4nAJ9D","pt":1659347544549,"mc":[{"id":"1.201590187","rc":[{"bdatb":[[0,6.8,20.26]],"id":44836671}]}]}
{"op":"mcm","clk":"APpMAIEoAKFD","pt":1659347544599,"mc":[{"id":"1.201590187","rc":[{"atb":[[23,3.47]],"id":44621159}]}]}
{"op":"mcm","clk":"AP9MAIQoAKZD","pt":1659347544649,"mc":[{"id":"1.201590187","rc":[{"bdatl":[[6,2.52,10.08],[7,2.56,7.06],[8,2.58,3.82],[9,2.6,3.06]],"id":9570503},{"bdatb":[[0,23,4.07]],"id":44621159}]}]}
{"op":"mcm","clk":"AJ9NAJ4oANVD","pt":1659347545323,"mc":[{"id":"1.201590187","rc":[{"atb":[[23,1]],"bdatb":[[0,23,1.6]],"id":44621159},{"bdatl":[[6,2.52,9.13],[7,2.6,7.9],[8,2.62,3.77],[9,2.64,3.02]],"id":9570503}]}]}
{"op":"mcm","clk":"AKZNAKAoAN1D","pt":1659347545391,"mc":[{"id":"1.201590187","rc":[{"atb":[[16.5,0]],"id":44621159}]}]}
{"op":"mcm","clk":"AKdNAKAoAN9D","pt":1659347545441,"mc":[{"id":"1.201590187","rc":[{"bdatb":[[4,15.5,6.29],[5,13,1.13],[6,11.5,2.06],[7,11,14.37],[8,10,102.53],[9,9.6,1.8]],"id":44621159}]}]}
{"op":"mcm","clk":"AK1NAKEoAOBD","pt":1659347545492,"mc":[{"id":"1.201590187","rc":[{"atb":[[24,2.91],[22,1.8]],"id":44621159}]}]}
{"op":"mcm","clk":"AK9NAKEoAOVD","pt":1659347545552,"mc":[{"id":"1.201590187","rc":[{"bdatl":[[5,2.5,36.16],[6,2.56,7.06],[7,2.58,3.82],[8,2.6,3.06],[9,2.64,7.43]],"id":9570503},{"bdatb":[[0,24,3.02],[1,23,1],[2,22,1.8],[3,21,5],[4,19.5,4.19],[5,18.5,1.37],[6,15.5,6.29],[7,13,1.13],[8,11.5,2.06],[9,11,14.37]],"id":44621159}]}]}
{"op":"mcm","clk":"AOFNALcoAJFE","pt":1659347546328,"mc":[{"id":"1.201590187","rc":[{"atb":[[24,0.49]],"id":44621159},{"atb":[[5.6,29.24]],"id":44836671}]}]}
{"op":"mcm","clk":"AOFNALooAJJE","pt":1659347546378,"mc":[{"id":"1.201590187","rc":[{"bdatl":[[5,2.5,26],[6,2.52,9.13],[7,2.58,7.96],[8,2.6,3.79],[9,2.62,3.04]],"id":9570503},{"bdatb":[[0,23,1.6],[1,22,1.8],[2,21,5],[3,19.5,4.19],[4,18.5,1.37],[5,15.5,6.29],[6,13,1.13],[7,11.5,2.06],[8,11,14.37],[9,10,102.53]],"id":44621159},{"bdatb":[[7,5.6,29.71]],"id":44836671}]}]}
{"op":"mcm","clk":"AOtNAL0oAJhE","pt":1659347546521,"mc":[{"id":"1.201590187","rc":[{"atb":[[22,4.38]],"id":44621159}]}]}
{"op":"mcm","clk":"AO5NAL4oAJtE","pt":1659347546571,"mc":[{"id":"1.201590187","rc":[{"bdatb":[[1,22,4.38]],"id":44621159}]}]}
{"op":"mcm","clk":"AJJOANkoAMZE","pt":1659347547311,"mc":[{"id":"1.201590187","rc":[{"atb":[[22,1.8]],"id":44621159}]}]}
{"op":"mcm","clk":"AJNOANkoAMpE","pt":1659347547361,"mc":[{"id":"1.201590187","rc":[{"bdatb":[[1,22,1.8]],"id":44621159}]}]}
{"op":"mcm","clk":"AJtOAN8oANJE","pt":1659347547514,"mc":[{"id":"1.201590187","rc":[{"atb":[[23,3.47]],"id":44621159}]}]}
{"op":"mcm","clk":"AJtOAN8oANNE","pt":1659347547564,"mc":[{"id":"1.201590187","rc":[{"bdatl":[[6,2.52,10.08],[7,2.56,7.06],[8,2.58,3.82],[9,2.6,3.06]],"id":9570503},{"bdatb":[[0,23,4.07]],"id":44621159}]}]}
{"op":"mcm","clk":"AL9OAPMoAPdE","pt":1659347548227,"mc":[{"id":"1.201590187","rc":[{"atb":[[23,1]],"id":44621159}]}]}
{"op":"mcm","clk":"AMBOAPUoAPlE","pt":1659347548277,"mc":[{"id":"1.201590187","rc":[{"bdatl":[[6,2.52,9.13],[7,2.58,7.96],[8,2.6,3.79],[9,2.62,3.04]],"id":9570503},{"bdatb":[[0,23,1.6]],"id":44621159}]}]}
{"op":"mcm","clk":"AMROAPcoAPpE","pt":1659347548328,"mc":[{"id":"1.201590187","rc":[{"atb":[[24,2.91]],"id":44621159}]}]}
{"op":"mcm","clk":"AMVOAPgoAP5E","pt":1659347548378,"mc":[{"id":"1.201590187","rc":[{"bdatl":[[5,2.5,36.16],[6,2.56,7.06],[7,2.58,3.82],[8,2.6,3.06],[9,2.64,7.43]],"id":9570503},{"bdatb":[[0,24,3.02],[1,23,1],[2,22,1.8],[3,21,5],[4,19.5,4.19],[5,18.5,1.37],[6,15.5,6.29],[7,13,1.13],[8,11.5,2.06],[9,11,14.37]],"id":44621159}]}]}
{"op":"mcm","clk":"AOJOAIopAJlF","pt":1659347548912,"mc":[{"id":"1.201590187","rc":[{"atb":[[2.04,0]],"id":9570503}]}]}
{"op":"mcm","clk":"AOROAIopAJ1F","pt":1659347548963,"mc":[{"id":"1.201590187","rc":[{"bdatb":[[1,2.02,39.06],[2,2,8.14],[3,1.99,10.75],[4,1.98,36.93],[5,1.96,3.95],[6,1.95,3.66],[7,1.94,2.59],[8,1.91,119.79],[9,1.86,2.84]],"id":9570503}]}]}
{"op":"mcm","clk":"AOxOAI0pAKBF","pt":1659347549022,"mc":[{"id":"1.201590187","rc":[{"atb":[[2.08,17.32]],"id":9570503}]}]}
{"op":"mcm","clk":"AOxOAI4pAKFF","pt":1659347549072,"mc":[{"id":"1.201590187","rc":[{"bdatb":[[0,2.08,17.32],[1,2.06,13.88],[2,2.02,39.06],[3,2,8.14],[4,1.99,10.75],[5,1.98,36.93],[6,1.96,3.95],[7,1.95,3.66],[8,1.94,2.59],[9,1.91,119.79]],"id":9570503},{"bdatl":[[9,13.5,2.84]],"id":12989514}]}]}
{"op":"mcm","clk":"APZOAJApAKJF","pt":1659347549123,"mc":[{"id":"1.201590187","rc":[{"atb":[[24,0.49]],"id":44621159}]}]}
{"op":"mcm","clk":"APZOAJMpAKlF","pt":1659347549173,"mc":[{"id":"1.201590187","rc":[{"bdatl":[[5,2.5,26],[6,2.52,9.13],[7,2.58,7.96],[8,2.6,3.79],[9,2.62,3.04]],"id":9570503},{"bdatl":[[9,13.5,1.25]],"id":12989514},{"bdatb":[[0,23,1.6],[1,22,1.8],[2,21,5],[3,19.5,4.19],[4,18.5,1.37],[5,15.5,6.29],[6,13,1.13],[7,11.5,2.06],[8,11,14.37],[9,10,102.53]],"id":44621159}]}]}
{"op":"mcm","clk":"AP9OAJMpAKlF","pt":1659347549223,"mc":[{"id":"1.201590187","rc":[{"atb":[[2.06,10.33]],"id":9570503}]}]}
{"op":"mcm","clk":"AINPAJwpALFF","pt":1659347549273,"mc":[{"id":"1.201590187","rc":[{"bdatb":[[1,2.06,10.33]],"id":9570503}]}]}
{"op":"mcm","clk":"AIpPAKApALVF","pt":1659347549340,"mc":[{"id":"1.201590187","rc":[{"atb":[[2.08,19.68]],"id":9570503},{"atb":[[22,4.38]],"id":44621159}]}]}
{"op":"mcm","clk":"AI9PAKkpAL1F","pt":1659347549392,"mc":[{"id":"1.201590187","rc":[{"bdatb":[[0,2.08,19.68]],"id":9570503},{"bdatb":[[1,22,4.38]],"id":44621159}]}]}
{"op":"mcm","clk":"AJhPALUpAMZF","pt":1659347549507,"mc":[{"id":"1.201590187","rc":[{"atl":[[16,0]],"id":45323444}]}]}
{"op":"mcm","clk":"AKpPAMEpANBF","pt":1659347549614,"mc":[{"id":"1.201590187","rc":[{"atl":[[7.4,7.34]],"id":44836671},{"atb":[[8,4.08]],"id":43885158},{"atl":[[34,5.09]],"id":46969227}]}]}
{"op":"mcm","clk":"AKpPANMpANFF","pt":1659347549664,"mc":[{"id":"1.201590187","rc":[{"bdatl":[[0,16.5,3.92]],"id":45323444},{"bdatb":[[9,1.91,116.35]],"id":9570503},{"bdatb":[[2,6,22.5],[3,5.5,2.16],[4,5.2,5.25],[6,4.9,3.6],[7,4.8,5.9]],"id":12989514},{"bdatb":[[5,15.5,6.3],[7,11.5,1.49],[9,10,103.19]],"id":44621159},{"bdatb":[[3,6,29.74],[4,5.9,14.54]],"id":44836671},{"bdatb":[[5,7.2,3.71],[6,7,9.67],[9,6.2,12.77]],"id":43885158},{"bdatb":[[8,11,1.56]],"id":46969227}]}]}
{"op":"mcm","clk":"ALtPANMpAN5F","pt":1659347549718,"mc":[{"id":"1.201590187","rc":[{"bdatb":[[9,1.91,110.93]],"bdatl":[[7,2.58,1.75],[9,2.62,9.15]],"id":9570503},{"bdatb":[[2,6,20.78],[3,5.9,1.75],[4,5.4,2.42],[5,5.2,5.02],[6,5.1,3.96],[7,4.9,3.6],[8,4.8,5.9],[9,4.6,15.8]],"id":12989514},{"bdatb":[[7,11,15.9],[8,10,102],[9,9.6,3.04]],"id":44621159},{"bdatl":[[0,7.4,7.34]],"id":44836671},{"bdatb":[[1,8,4.08],[9,6.2,11.1]],"id":43885158},{"bdatb":[[8,10.5,1.61]],"bdatl":[[1,34,5.25]],"id":46969227}]}]}
{"op":"mcm","clk":"AMxPAOIpAN9F","pt":1659347549768,"mc":[{"id":"1.201590187","rc":[{"atb":[[2.04,6.8]],"id":9570503},{"atb":[[6.6,5.83]],"id":44836671},{"atb":[[21,1.25]],"atl":[[32,2.09]],"id":46969227}]}]}
{"op":"mcm","clk":"AM9PAOopAO5F","pt":1659347549835,"mc":[{"id":"1.201590187","rc":[{"bdatb":[[2,2.04,6.8],[3,2.02,39.06],[4,2,8.14],[5,1.99,10.75],[6,1.98,36.93],[7,1.96,3.95],[8,1.95,3.66],[9,1.94,2.59]],"bdatl":[[4,2.44,153.09],[5,2.48,2.81],[6,2.5,27.72],[7,2.52,4.51],[8,2.58,1.75],[9,2.6,3.79]],"id":9570503},{"bdatl":[[9,13,1.29]],"id":12989514},{"bdatb":[[1,6.6,5.83]],"id":44836671},{"bdatb":[[0,21,1.25],[1,20,6.94],[2,19.5,7],[3,19,5],[4,18.5,8],[5,18,5],[6,16,1.43],[7,14.5,2.26],[8,12,1.22],[9,10.5,1.61]],"bdatl":[[1,32,2.16],[2,34,5.09],[3,36,1.1],[4,38,2.7],[5,40,5.01],[6,80,1.66],[7,310,1],[8,990,2.15]],"id":46969227}]}]}
{"op":"mcm","clk":"AN5PAPUpAPVF","pt":1659347549907,"mc":[{"id":"1.201590187","rc":[{"atb":[[8.2,0]],"atl":[[9.2,2.69]],"id":43885158}]}]}
{"op":"mcm","clk":"AOhPAP0pAING","pt":1659347550045,"mc":[{"id":"1.201590187","rc":[{"bdatb":[[3,10.5,6.83],[4,10,10.8],[6,9.6,21],[7,9.4,55.13]],"id":45323444},{"bdatb":[[5,1.99,6.75],[6,1.98,40.95],[7,1.96,2.62],[8,1.95,5]],"bdatl":[[4,2.44,152.09],[5,2.46,1],[6,2.5,30.51],[7,2.52,2.55],[8,2.54,1.95],[9,2.6,1.91]],"id":9570503},{"bdatb":[[4,5.3,3.17],[5,5.2,4.3]],"bdatl":[[9,13,1.26]],"id":12989514},{"bdatb":[[5,15.5,5.79],[6,13,1.69],[9,9.6,1.94]],"id":44621159},{"bdatb":[[4,5.9,13.19],[5,5.8,32.2],[7,5.6,29.24],[8,5.5,25.69]],"id":44836671},{"bdatb":[[0,8,4.08],[1,7.8,1.26],[2,7.6,11.12],[3,7.4,4.7],[4,7.2,3.71],[5,7,9.67],[6,6.6,66.19],[7,6.4,2.79],[8,6.2,11.1],[9,6,15.72]],"bdatl":[[0,9.2,2.69]],"id":43885158},{"bdatb":[[7,14.5,1.71],[8,12,1.8]],"id":46969227}]}]}
{"op":"mcm","clk":"APdPAP4pAIhG","pt":1659347550113,"mc":[{"id":"1.201590187","rc":[{"atb":[[22,1.8]],"id":44621159}]}]}
{"op":"mcm","clk":"AP1PAP4pAIlG","pt":1659347550163,"mc":[{"id":"1.201590187","rc":[{"bdatb":[[1,22,1.8]],"id":44621159}]}]}
{"op":"mcm","clk":"AP5PAIUqAJFG","pt":1659347550214,"mc":[{"id":"1.201590187","rc":[{"atb":[[23,3.47]],"id":44621159}]}]}
{"op":"mcm","clk":"AIZQAI0qAJNG","pt":1659347550265,"mc":[{"id":"1.201590187","rc":[{"bdatl":[[8,2.54,2.89],[9,2.6,13.82]],"id":9570503},{"bdatb":[[0,23,4.07]],"id":44621159}]}]}
{"op":"mcm","clk":"AKJQAKUqAKhG","pt":1659347550451,"mc":[{"id":"1.201590187","rc":[{"atb":[[2.02,35.11]],"atl":[[2.3,5.32]],"id":9570503},{"atb":[[6,11.66]],"atl":[[9,4.44]],"id":12989514},{"atb":[[6.8,17.67]],"atl":[[7.6,156.61]],"id":44836671},{"atb":[[7.4,2.32],[8,1.76]],"atl":[[9.4,2.23]],"id":43885158}]}]}
{"op":"mcm","clk":"AKlQAKwqALFG","pt":1659347550501,"mc":[{"id":"1.201590187","rc":[{"bdatb":[[8,9.2,12.35],[9,9,13.2]],"id":45323444},{"bdatb":[[3,2.02,35.11],[9,1.94,1.68]],"bdatl":[[2,2.3,5.32],[6,2.5,25.65],[7,2.52,3.92],[8,2.56,6.28],[9,2.6,13.81]],"id":9570503},{"bdatb":[[2,6,16.98],[3,5.9,1.46],[4,5.8,1.78],[5,5.3,3.18],[6,5.2,4.3],[7,5.1,3.96],[8,4.9,3.6],[9,4.8,5.9]],"bdatl":[[2,9,4.44],[9,13,1.22]],"id":12989514},{"bdatb":[[6,13,1.55],[7,11,16.04],[9,9.6,1.68]],"id":44621159},{"bdatb":[[0,6.8,18.02],[8,5.5,25.37],[9,5.4,14.33]],"bdatl":[[1,7.6,156.61]],"id":44836671},{"bdatb":[[0,8,1.76],[3,7.4,2.32]],"bdatl":[[1,9.4,2.23]],"id":43885158},{"bdatb":[[8,12,1.65],[9,10,3.83]],"id":46969227}]}]}
{"op":"mcm","clk":"AKtQAK0qALpG","pt":1659347550551,"mc":[{"id":"1.201590187","rc":[{"atb":[[2.02,30.96]],"atl":[[2.3,1.72]],"id":9570503},{"atb":[[6,9.14]],"atl":[[9,2.17]],"id":12989514},{"atb":[[6.8,15.36]],"atl":[[7.6,154.34]],"id":44836671},{"atb":[[7.6,8.75]],"atl":[[9.4,0]],"id":43885158}]}]}
{"op":"mcm","clk":"ALZQALAqAL5G","pt":1659347550601,"mc":[{"id":"1.201590187","rc":[{"bdatb":[[7,9.4,54.1],[8,9.2,13.06],[9,9,13.56]],"id":45323444},{"bdatb":[[3,2.02,30.96],[8,1.94,5.03],[9,1.93,2.6]],"bdatl":[[2,2.3,1.72]],"id":9570503},{"bdatb":[[2,6,13.92],[3,5.9,2.01]],"bdatl":[[2,9,2.17]],"id":12989514},{"bdatb":[[6,12.5,1.73],[7,11,15.9]],"id":44621159},{"bdatb":[[0,6.8,15.71],[5,5.8,30.83],[6,5.7,45.94],[8,5.5,23],[9,5.4,16.74]],"bdatl":[[1,7.6,154.34]],"id":44836671},{"bdatb":[[2,7.6,8.75]],"bdatl":[[1,9.6,14.54],[2,10.5,3.45],[3,11.5,2.65],[4,12,1.4],[5,12.5,18],[6,14,1],[7,14.5,1],[8,15,12],[9,15.5,1]],"id":43885158},{"bdatb":[[8,12,1.4],[9,10.5,1.09]],"id":46969227}]}]}
{"op":"mcm","clk":"ALdQALUqAMRG","pt":1659347550652,"mc":[{"id":"1.201590187","rc":[{"atb":[[2.06,15.38]],"id":9570503},{"atb":[[8,1.46]],"id":43885158}]}]}
{"op":"mcm","clk":"ALtQALcqAMdG","pt":1659347550702,"mc":[{"id":"1.201590187","rc":[{"bdatb":[[1,2.06,15.38]],"bdatl":[[6,2.5,24.69],[8,2.54,1.85],[9,2.56,5.38]],"id":9570503},{"bdatl":[[9,13,1.04]],"id":12989514},{"bdatb":[[0,8,1.46]],"id":43885158}]}]}
{"op":"mcm","clk":"AN5QANsqAOdG","pt":1659347551029,"mc":[{"id":"1.201590187","rc":[{"atb":[[23,1]],"id":44621159}]}]}
{"op":"mcm","clk":"AONQAN8qAPBG","pt":1659347551079,"mc":[{"id":"1.201590187","rc":[{"bdatl":[[9,2.56,4.44]],"id":9570503},{"bdatb":[[0,23,1.6]],"id":44621159}]}]}
{"op":"mcm","clk":"APJQAOsqAPZG","pt":1659347551233,"mc":[{"id":"1.201590187","rc":[{"atb":[[24,2.91]],"id":44621159}]}]}
{"op":"mcm","clk":"APVQAO0qAIBH","pt":1659347551283,"mc":[{"id":"1.201590187","rc":[{"bdatl":[[9,2.56,5.38]],"id":9570503},{"bdatb":[[0,24,3.02],[1,23,1],[2,22,1.8],[3,21,5],[4,19.5,4.19],[5,18.5,1.37],[6,15.5,5.79],[7,12.5,1.73],[8,11,15.9],[9,10,102]],"id":44621159}]}]}
{"op":"mcm","clk":"AJJRAIMrAJ5H","pt":1659347551614,"mc":[{"id":"1.201590187","rc":[{"atb":[[2.08,17.24]],"trd":[[2.08,33.1]],"ltp":2.08,"tv":832.41,"id":9570503},{"atb":[[7.6,4.53],[7.4,10.26]],"id":43885158}],"tv":1315.39}]}
{"op":"mcm","clk":"AJhRAIMrAKRH","pt":1659347551664,"mc":[{"id":"1.201590187","rc":[{"bdatb":[[0,2.08,17.24]],"id":9570503},{"bdatb":[[2,7.6,4.53],[3,7.4,10.26]],"id":43885158}]}]}
{"op":"mcm","clk":"AJ5RAIwrAKdH","pt":1659347551728,"mc":[{"id":"1.201590187","rc":[{"atb":[[2.08,18.43]],"id":9570503}]}]}
{"op":"mcm","clk":"AKFRAIwrAKxH","pt":1659347551779,"mc":[{"id":"1.201590187","rc":[{"bdatb":[[0,2.08,18.43]],"id":9570503}]}]}
{"op":"mcm","clk":"AKpRAJErALVH","pt":1659347551833,"mc":[{"id":"1.201590187","rc":[{"atb":[[2.08,21.94],[2.06,14.11],[1.99,0]],"id":9570503}]}]}
{"op":"mcm","clk":"AKpRAJErALdH","pt":1659347551883,"mc":[{"id":"1.201590187","rc":[{"bdatb":[[0,2.08,21.94],[1,2.06,14.11],[5,1.99,5.5]],"id":9570503}]}]}
{"op":"mcm","clk":"ALFRAJorALxH","pt":1659347551935,"mc":[{"id":"1.201590187","rc":[{"atb":[[23,0]],"atl":[[32,0.33]],"id":44621159}]}]}
{"op":"mcm","clk":"ALNRAJ0rALxH","pt":1659347551985,"mc":[{"id":"1.201590187","rc":[{"bdatb":[[3,10.5,5.79],[4,10,11.1],[5,9.8,9.81],[8,9.2,12],[9,9,14.64]],"id":45323444},{"bdatb":[[4,2,6.47],[5,1.99,7.18],[6,1.98,36.93],[7,1.97,4.04],[8,1.96,2.62],[9,1.93,7.66]],"id":9570503},{"bdatb":[[1,6.2,17.45],[2,6,11.52],[3,5.9,4.2],[4,5.7,2.63],[5,5.2,3.46],[6,5.1,8.13],[7,4.9,3.6],[8,4.8,5.9],[9,4.6,15.8]],"id":12989514},{"bdatb":[[1,22,1.8],[2,21,5],[3,19.5,4.19],[4,18.5,1.37],[5,15.5,5.79],[6,12.5,1.73],[7,11,15.9],[8,10,102],[9,9.6,1.68]],"bdatl":[[0,34,1.48],[1,40,3.86],[2,95,2.64],[3,170,2],[4,990,2.07],[5,0,0]],"id":44621159},{"bdatb":[[4,5.9,11.34],[5,5.8,32.72]],"id":44836671},{"bdatb":[[5,7,6.97],[6,6.8,2.78],[7,6.6,64.72],[8,6.4,4.31],[9,6.2,10.33]],"id":43885158},{"bdatb":[[7,14,1.74],[8,11.5,1.9],[9,10,3.71]],"id":46969227}]}]}
{"op":"mcm","clk":"ALZRAJ8rAMFH","pt":1659347552035,"mc":[{"id":"1.201590187","rc":[{"atb":[[24,0.49]],"id":44621159}]}]}
{"op":"mcm","clk":"ALlRAKMrAMJH","pt":1659347552085,"mc":[{"id":"1.201590187","rc":[{"bdatl":[[7,2.52,1.16],[8,2.54,2.73],[9,2.56,1.83]],"id":9570503},{"bdatb":[[0,22,2.4],[1,21,5],[2,19.5,4.19],[3,18.5,1.37],[4,15.5,5.79],[5,12.5,1.73],[6,11,15.9],[7,10,102],[8,9.6,1.68],[9,9.4,27.6]],"id":44621159}]}]}
{"op":"mcm","clk":"ALxRAKQrAMdH","pt":1659347552141,"mc":[{"id":"1.201590187","rc":[{"atb":[[7.8,7.93]],"id":43885158}]}]}
{"op":"mcm","clk":"AMRRAKkrAMlH","pt":1659347552191,"mc":[{"id":"1.201590187","rc":[{"bdatl":[[8,2.54,4.58],[9,2.56,5.38]],"id":9570503},{"bdatb":[[1,7.8,7.93]],"id":43885158}]}]}
{"op":"mcm","clk":"AM1RALMrANBH","pt":1659347552339,"mc":[{"id":"1.201590187","rc":[{"atb":[[22,4.38]],"id":44621159}]}]}
{"op":"mcm","clk":"ANFRALMrANVH","pt":1659347552389,"mc":[{"id":"1.201590187","rc":[{"bdatb":[[0,22,4.98]],"id":44621159}]}]}
{"op":"mcm","clk":"ANVRALkrANZH","pt":1659347552440,"mc":[{"id":"1.201590187","rc":[{"atl":[[10.5,0]],"bdatl":[[2,11.5,2.65],[3,12,1.4],[4,12.5,18],[5,14,1],[6,14.5,1],[7,15,12],[8,15.5,1],[9,16.5,8.94]],"id":43885158}]}]}
{"op":"mcm","clk":"AN1RAMArANtH","pt":1659347552513,"mc":[{"id":"1.201590187","rc":[{"atb":[[2.04,10.62]],"atl":[[2.3,5.17]],"id":9570503},{"atb":[[6.4,14.14]],"atl":[[9,4.36]],"id":12989514},{"atb":[[6.8,17.72]],"atl":[[7.6,156.73]],"id":44836671},{"atb":[[7.8,10.26]],"atl":[[9.4,2.35],[10,3.45]],"id":43885158}]}]}
{"op":"mcm","clk":"AOJRAMArAOBH","pt":1659347552564,"mc":[{"id":"1.201590187","rc":[{"bdatb":[[4,10,11.89],[5,9.8,9],[8,9.2,13.53],[9,9,13.07]],"id":45323444},{"bdatb":[[2,2.04,10.62],[6,1.98,40.95],[7,1.96,2.62],[8,1.94,7.28],[9,1.91,107.71]],"bdatl":[[2,2.3,5.17]],"id":9570503},{"bdatb":[[0,6.4,14.14],[2,6,15.2],[3,5.8,1.28],[4,5.7,1.81]],"bdatl":[[2,9,4.36]],"id":12989514},{"bdatb":[[5,13,1.64],[6,11,15.95],[9,9.4,29.26]],"id":44621159},{"bdatb":[[0,6.8,18.07],[5,5.8,34.09],[6,5.7,44.55],[8,5.5,25.57],[9,5.4,14.12]],"bdatl":[[1,7.6,156.73]],"id":44836671},{"bdatb":[[1,7.8,10.26]],"bdatl":[[1,9.4,2.35],[2,9.6,14.54],[3,10,3.45],[4,11.5,2.65],[5,12,1.4],[6,12.5,18],[7,14,1],[8,14.5,1],[9,15,12]],"id":43885158},{"bdatb":[[8,12,1.77],[9,10,3.77]],"id":46969227}]}]}
{"op":"mcm","clk":"AOVRAMQrAONH","pt":1659347552617,"mc":[{"id":"1.201590187","rc":[{"atb":[[2.04,14.73]],"atl":[[2.3,8.58]],"id":9570503},{"atb":[[6.4,16.47]],"atl":[[9,6.65]],"id":12989514},{"atb":[[6.8,20.15]],"atl":[[7.6,158.98]],"id":44836671},{"atb":[[7.8,12.45]],"atl":[[9.4,4.53]],"id":43885158}]}]}
{"op":"mcm","clk":"AOdRAMQrAOVH","pt":1659347552667,"mc":[{"id":"1.201590187","rc":[{"bdatb":[[8,9.2,13.61],[9,9,13]],"id":45323444},{"bdatb":[[2,2.04,14.73],[8,1.94,7.62],[9,1.91,108.43]],"bdatl":[[2,2.3,8.58]],"id":9570503},{"bdatb":[[0,6.4,16.47],[2,6,15.65],[3,5.8,2.59],[4,5.2,3.45],[5,5.1,8.13],[6,4.9,3.6],[7,4.8,5.9],[8,4.6,15.8],[9,4.5,222]],"bdatl":[[2,9,6.65]],"id":12989514},{"bdatb":[[5,13,1.69],[6,11,15.9],[8,9.6,1.95],[9,9.4,28.97]],"id":44621159},{"bdatb":[[0,6.8,20.5],[8,5.5,25.69],[9,5.4,14]],"bdatl":[[1,7.6,158.98]],"id":44836671},{"bdatb":[[1,7.8,12.45]],"bdatl":[[1,9.4,4.53]],"id":43885158},{"bdatb":[[8,12,1.82],[9,10,3.67]],"id":46969227}]}]}
{"op":"mcm","clk":"APtRANYrAPtH","pt":1659347552935,"mc":[{"id":"1.201590187","rc":[{"atb":[[23,1]],"atl":[[36,1]],"id":44621159}]}]}
{"op":"mcm","clk":"APtRANsrAP1H","pt":1659347552986,"mc":[{"id":"1.201590187","rc":[{"bdatb":[[9,1.91,110.93]],"bdatl":[[7,2.52,5.78],[8,2.54,4.48],[9,2.6,25.42]],"id":9570503},{"bdatb":[[4,5.3,3.39],[5,5.2,4.86],[6,5.1,3.18],[7,4.9,3.6],[8,4.8,5.9],[9,4.6,15.8]],"id":12989514},{"bdatb":[[0,23,1.6],[1,22,4.38],[2,21,5],[3,19.5,4.19],[4,18.5,1.37],[5,15.5,5.79],[6,13,1.69],[7,11,15.9],[8,10,102],[9,9.6,1.95]],"bdatl":[[1,36,1],[2,40,3.86],[3,95,2.64],[4,170,2],[5,990,2.07]],"id":44621159}]}]}
{"op":"mcm","clk":"AIdSAOQrAIVI","pt":1659347553144,"mc":[{"id":"1.201590187","rc":[{"atb":[[22,1.8]],"id":44621159}]}]}
{"op":"mcm","clk":"AIxSAOgrAItI","pt":1659347553195,"mc":[{"id":"1.201590187","rc":[{"bdatl":[[9,2.6,15.23]],"id":9570503},{"bdatb":[[1,22,1.8]],"id":44621159}]}]}
{"op":"mcm","clk":"AJNSAO0rAJNI","pt":1659347553340,"mc":[{"id":"1.201590187","rc":[{"atl":[[25,4.17]],"id":45323444},{"atb":[[23,3.47]],"id":44621159}]}]}
{"op":"mcm","clk":"AJVSAO4rAJVI","pt":1659347553390,"mc":[{"id":"1.201590187","rc":[{"bdatl":[[2,25,4.17]],"id":45323444},{"bdatl":[[8,2.54,5.42],[9,2.58,21.09]],"id":9570503},{"bdatb":[[0,23,4.07]],"id":44621159}]}]}
{"op":"mcm","clk":"AJlSAPIrAJlI","pt":1659347553441,"mc":[{"id":"1.201590187","rc":[{"atl":[[26,6.48]],"bdatl":[[3,26,6.48]],"id":45323444}]}]}
{"op":"mcm","clk":"ALhSAIwsALZI","pt":1659347553932,"mc":[{"id":"1.201590187","rc":[{"atb":[[10.5,1.6]],"id":45323444},{"atl":[[9.2,0],[9,11.3]],"id":12989514}]}]}
{"op":"mcm","clk":"ALlSAJAsALhI","pt":1659347553983,"mc":[{"id":"1.201590187","rc":[{"bdatb":[[3,10.5,2.92]],"id":45323444},{"bdatl":[[2,9,11.3],[3,9.4,3.67],[4,9.6,11.09],[5,10,17.36],[6,10.5,12.47],[7,11,33.84],[8,13,1.04],[9,14,1.05]],"id":12989514}]}]}
{"op":"mcm","clk":"AL1SAJEsALtI","pt":1659347554034,"mc":[{"id":"1.201590187","rc":[{"atb":[[12,2.87]],"id":45323444},{"atb":[[23,1]],"id":44621159},{"atb":[[7.8,5.79]],"id":43885158}]}]}
{"op":"mcm","clk":"AMFSAJQsALxI","pt":1659347554084,"mc":[{"id":"1.201590187","rc":[{"bdatb":[[1,12,2.87],[2,11.5,5.54],[3,11,1.23],[4,10.5,2.92],[5,10,11.89],[6,9.8,9],[7,9.6,21],[8,9.4,54.1],[9,9.2,13.61]],"id":45323444},{"bdatl":[[8,2.54,4.48],[9,2.58,7.45]],"id":9570503},{"bdatb":[[0,23,1.6]],"id":44621159},{"bdatb":[[1,7.8,5.79]],"id":43885158}]}]}
{"op":"mcm","clk":"AMxSAJcsAMdI","pt":1659347554243,"mc":[{"id":"1.201590187","rc":[{"atb":[[8,7.95]],"id":43885158}]}]}
{"op":"mcm","clk":"ANFSAJosAMpI","pt":1659347554293,"mc":[{"id":"1.201590187","rc":[{"bdatl":[[6,2.5,30.51],[7,2.52,4.51],[8,2.56,10.17],[9,2.58,4.21]],"id":9570503},{"bdatl":[[8,13,1.26],[9,14,1.84]],"id":12989514},{"bdatb":[[0,8,7.95]],"id":43885158}]}]}
{"op":"mcm","clk":"AN1SAJ0sANNI","pt":1659347554439,"mc":[{"id":"1.201590187","rc":[{"atb":[[24,2.91]],"id":44621159}]}]}
{"op":"mcm","clk":"AOBSAJ0sANlI","pt":1659347554489,"mc":[{"id":"1.201590187","rc":[{"bdatl":[[6,2.5,36.02],[7,2.54,9.3],[8,2.56,4.24],[9,2.58,8.15]],"id":9570503},{"bdatl":[[8,13,2.16],[9,13.5,1.02]],"id":12989514},{"bdatb":[[0,24,3.02],[1,23,1],[2,22,1.8],[3,21,5],[4,19.5,4.19],[5,18.5,1.37],[6,15.5,5.79],[7,13,1.69],[8,11,15.9],[9,10,102]],"id":44621159}]}]}
{"op":"mcm","clk":"AIpTALksAIlJ","pt":1659347555133,"mc":[{"id":"1.201590187","rc":[{"atb":[[24,0.49]],"id":44621159}]}]}
{"op":"mcm","clk":"AIxTAL0sAJNJ","pt":1659347555183,"mc":[{"id":"1.201590187","rc":[{"bdatl":[[6,2.5,30.51],[7,2.52,4.51],[8,2.56,10.17],[9,2.58,4.21]],"id":9570503},{"bdatl":[[8,13,1.26],[9,14,1.84]],"id":12989514},{"bdatb":[[0,23,1.6],[1,22,1.8],[2,21,5],[3,19.5,4.19],[4,18.5,1.37],[5,15.5,5.79],[6,13,1.69],[7,11,15.9],[8,10,102],[9,9.6,1.95]],"id":44621159}]}]}
{"op":"mcm","clk":"AJhTAMMsAJtJ","pt":1659347555338,"mc":[{"id":"1.201590187","rc":[{"atb":[[2.08,23.14]],"id":9570503},{"atb":[[22,4.38]],"id":44621159}]}]}
{"op":"mcm","clk":"AJtTAMcsAKFJ","pt":1659347555388,"mc":[{"id":"1.201590187","rc":[{"bdatb":[[0,2.08,23.14]],"id":9570503},{"bdatb":[[1,22,4.38]],"id":44621159}]}]}
{"op":"mcm","clk":"AJ5TAMgsAKFJ","pt":1659347555439,"mc":[{"id":"1.201590187","rc":[{"atb":[[22,2.59]],"id":44621159}]}]}
{"op":"mcm","clk":"AKBTAMosAKNJ","pt":1659347555489,"mc":[{"id":"1.201590187","rc":[{"bdatb":[[1,22,2.59]],"id":44621159}]}]}
{"op":"mcm","clk":"AKZTAM0sAKVJ","pt":1659347555542,"mc":[{"id":"1.201590187","rc":[{"atb":[[20,1.8]],"id":44621159}]}]}
{"op":"mcm","clk":"AKpTAM0sAKhJ","pt":1659347555592,"mc":[{"id":"1.201590187","rc":[{"bdatb":[[3,20,1.8],[4,19.5,4.19],[5,18.5,1.37],[6,15.5,5.79],[7,13,1.69],[8,11,15.9],[9,10,102]],"id":44621159}]}]}
{"op":"mcm","clk":"AMJTANwsALdJ","pt":1659347555825,"mc":[{"id":"1.201590187","rc":[{"atl":[[10,0]],"id":43885158}]}]}
{"op":"mcm","clk":"AMZTANwsALpJ","pt":1659347555875,"mc":[{"id":"1.201590187","rc":[{"bdatl":[[3,11.5,2.65],[4,12,1.4],[5,12.5,18],[6,14,1],[7,14.5,1],[8,15,12],[9,15.5,1]],"id":43885158}]}]}
{"op":"mcm","clk":"AMpTAN8sALxJ","pt":1659347555925,"mc":[{"id":"1.201590187","rc":[{"atl":[[10.5,3.45]],"id":43885158}]}]}
{"op":"mcm","clk":"AM5TAN8sAMBJ","pt":1659347555975,"mc":[{"id":"1.201590187","rc":[{"bdatl":[[3,10.5,3.45],[4,11.5,2.65],[5,12,1.4],[6,12.5,18],[7,14,1],[8,14.5,1],[9,15,12]],"id":43885158}]}]}
{"op":"mcm","clk":"ANtTAOUsAMdJ","pt":1659347556131,"mc":[{"id":"1.201590187","rc":[{"atb":[[22,0]],"id":44621159}]}]}
{"op":"mcm","clk":"ANtTAOUsAMxJ","pt":1659347556181,"mc":[{"id":"1.201590187","rc":[{"bdatl":[[9,2.6,4.18]],"id":9570503},{"bdatl":[[9,14,1.67]],"id":12989514},{"bdatb":[[1,21,5],[2,20,1.8],[3,19.5,4.19],[4,18.5,1.37],[5,15.5,5.79],[6,13,1.69],[7,11,15.9],[8,10,102],[9,9.6,1.95]],"id":44621159}]}]}
{"op":"mcm","clk":"AN5TAOUsAM1J","pt":1659347556233,"mc":[{"id":"1.201590187","rc":[{"atb":[[6.4,13.47]],"bdatb":[[0,6.4,13.47]],"id":12989514},{"atb":[[20,4.64]],"bdatb":[[1,20,4.64]],"id":46969227}]}]}
{"op":"mcm","clk":"AOpTAOcsANhJ","pt":1659347556337,"mc":[{"id":"1.201590187","rc":[{"atb":[[6.6,4]],"atl":[[7.8,6.59]],"id":12989514},{"atb":[[23,3.47]],"id":44621159},{"atb":[[5.6,46.48]],"atl":[[7.4,11.34]],"id":44836671},{"atb":[[8.2,1.15],[8,10.55]],"atl":[[9.2,3.84]],"id":43885158},{"atb":[[21,3.25]],"id":46969227}]}]}
{"op":"mcm","clk":"AOpTAOksAN1J","pt":1659347556387,"mc":[{"id":"1.201590187","rc":[{"bdatb":[[5,10,13.76]],"id":45323444},{"bdatb":[[5,1.99,12.49],[6,1.98,44.12],[7,1.96,3.58],[8,1.94,6.82],[9,1.91,107.36]],"bdatl":[[4,2.42,1.01],[5,2.44,154.95],[6,2.46,2.1],[7,2.48,4.76],[8,2.5,26.44],[9,2.52,11.2]],"id":9570503},{"bdatb":[[0,6.6,4],[1,6.4,13.47],[2,6.2,17.45],[3,6,15.65],[4,5.9,2.56],[5,5.4,3.33],[6,5.2,4.85],[7,5.1,3.18],[8,4.9,3.6],[9,4.8,5.9]],"bdatl":[[0,7.8,6.59],[8,13,1.29],[9,13.5,1.88]],"id":12989514},{"bdatb":[[0,23,4.07],[5,15.5,6.47],[6,14.5,1.11],[7,13,1.02],[8,11,14.37],[9,10,103.32]],"id":44621159},{"bdatb":[[5,5.8,36.99],[6,5.7,44.88],[7,5.6,46.48],[8,5.5,23],[9,5.4,16.45]],"bdatl":[[0,7.4,11.34],[8,13,42.11],[9,13.5,2.05]],"id":44836671},{"bdatb":[[0,8.2,1.15],[1,8,10.55],[2,7.8,5.79],[3,7.6,4.53],[4,7.4,10.26],[5,7.2,3.71],[6,7,6.97],[7,6.8,5.53],[8,6.6,64.72],[9,6.4,4.07]],"bdatl":[[0,9.2,3.84]],"id":43885158},{"bdatb":[[0,21,3.25],[7,14,2.5],[8,13.5,1.05],[9,11.5,1.3]],"id":46969227}]}]}
{"op":"mcm","clk":"AO1TAOksAN5J","pt":1659347556437,"mc":[{"id":"1.201590187","rc":[{"atl":[[38,0],[36,3.96]],"id":46969227}]}]}
{"op":"mcm","clk":"AO9TAOwsAORJ","pt":1659347556487,"mc":[{"id":"1.201590187","rc":[{"bdatl":[[3,36,3.96],[4,40,5.01],[5,80,1.66],[6,310,1],[7,990,2.15],[8,0,0]],"id":46969227}]}]}
{"op":"mcm","clk":"APRTAO0sAOZJ","pt":1659347556537,"mc":[{"id":"1.201590187","rc":[{"atb":[[6.6,4.37]],"id":12989514},{"atb":[[8,10.85]],"id":43885158},{"atb":[[8.8,48.84],[21,2.1]],"id":46969227}]}]}
{"op":"mcm","clk":"APhTAO8sAOxJ","pt":1659347556587,"mc":[{"id":"1.201590187","rc":[{"bdatl":[[7,2.48,5.74],[8,2.5,25.47],[9,2.52,1.62]],"id":9570503},{"bdatb":[[0,6.6,4.37]],"id":12989514},{"bdatb":[[1,8,10.85]],"id":43885158},{"bdatb":[[0,21,2.1]],"id":46969227}]}]}
{"op":"mcm","clk":"AIRUAPMsAPRJ","pt":1659347556741,"mc":[{"id":"1.201590187","rc":[{"atb":[[6,4.68]],"id":12989514}]}]}
{"op":"mcm","clk":"AIdUAPQsAPhJ","pt":1659347556791,"mc":[{"id":"1.201590187","rc":[{"bdatb":[[3,6,11.19]],"id":12989514}]}]}
{"op":"mcm","clk":"AJBUAPssAP9J","pt":1659347556948,"mc":[{"id":"1.201590187","rc":[{"atb":[[6.2,10.3],[6.4,20.09]],"id":12989514}]}]}
{"op":"mcm","clk":"AJZUAPssAIJK","pt":1659347556998,"mc":[{"id":"1.201590187","rc":[{"bdatb":[[1,6.4,20.09],[2,6.2,11.99]],"id":12989514}]}]}
{"op":"mcm","clk":"AJpUAP4sAIVK","pt":1659347557048,"mc":[{"id":"1.201590187","rc":[{"atl":[[8.4,6.4]],"bdatl":[[1,8.4,6.4]],"id":12989514},{"bdatb":[[9,9.2,14.88]],"id":45323444},{"bdatb":[[9,10.5,1.83]],"id":44621159}]}]}
{"op":"mcm","clk":"AKBUAIAtAIxK","pt":1659347557134,"mc":[{"id":"1.201590187","rc":[{"atb":[[23,1]],"id":44621159},{"atb":[[8,4.36]],"id":43885158}]}]}
{"op":"mcm","clk":"AKJUAIAtAI9K","pt":1659347557184,"mc":[{"id":"1.201590187","rc":[{"bdatl":[[8,2.5,24.5],[9,2.56,2.63]],"id":9570503},{"bdatl":[[9,13.5,1.7]],"id":12989514},{"bdatb":[[0,23,1.6]],"id":44621159},{"bdatb":[[1,8,4.36]],"id":43885158}]}]}
{"op":"mcm","clk":"AKlUAIUtAJhK","pt":1659347557336,"mc":[{"id":"1.201590187","rc":[{"atb":[[24,2.91]],"id":44621159}]}]}
{"op":"mcm","clk":"AKlUAIYtAJhK","pt":1659347557386,"mc":[{"id":"1.201590187","rc":[{"bdatl":[[6,2.46,7.89],[7,2.5,25.47],[8,2.52,1.62],[9,2.56,11.87]],"id":9570503},{"bdatl":[[8,13,3.24],[9,16,2.09]],"id":12989514},{"bdatb":[[0,24,3.02],[1,23,1],[2,21,5],[3,20,1.8],[4,19.5,4.19],[5,18.5,1.37],[6,15.5,6.47],[7,14.5,1.11],[8,13,1.02],[9,11,14.37]],"id":44621159}]}]}
{"op":"mcm","clk":"AM5UAJAtAMlK","pt":1659347558034,"mc":[{"id":"1.201590187","rc":[{"atb":[[24,0.49]],"atl":[[1000,2]],"id":44621159}]}]}
{"op":"mcm","clk":"AM9UAJAtAM1K","pt":1659347558084,"mc":[{"id":"1.201590187","rc":[{"bdatl":[[6,2.46,2.1],[7,2.48,5.74],[8,2.5,24.5],[9,2.56,2.63]],"id":9570503},{"bdatl":[[8,13,1.29],[9,13.5,1.7]],"id":12989514},{"bdatb":[[0,23,1.6],[1,21,5],[2,20,1.8],[3,19.5,4.19],[4,18.5,1.37],[5,15.5,6.47],[6,14.5,1.11],[7,13,1.02],[8,11,14.37],[9,10.5,1.83]],"bdatl":[[6,1000,2]],"id":44621159}]}]}
{"op":"mcm","clk":"ANBUAJItANFK","pt":1659347558134,"mc":[{"id":"1.201590187","rc":[{"atb":[[22,2.59]],"id":44621159}]}]}
{"op":"mcm","clk":"ANRUAJItANVK","pt":1659347558184,"mc":[{"id":"1.201590187","rc":[{"bdatl":[[9,2.54,2.56]],"id":9570503},{"bdatl":[[9,13.5,1.88]],"id":12989514},{"bdatb":[[1,22,2.59],[2,21,5],[3,20,1.8],[4,19.5,4.19],[5,18.5,1.37],[6,15.5,6.47],[7,14.5,1.11],[8,13,1.02],[9,11,14.37]],"id":44621159}]}]}
{"op":"mcm","clk":"AOdUAJstAPNK","pt":1659347558545,"mc":[{"id":"1.201590187","rc":[{"atl":[[27,0.1]],"id":46969227}]}]}
{"op":"mcm","clk":"AO1UAJwtAPtK","pt":1659347558595,"mc":[{"id":"1.201590187","rc":[{"bdatb":[[4,10.5,2.6],[5,10,14.1]],"id":45323444},{"bdatb":[[4,2,2.59],[5,1.99,16.39]],"id":9570503},{"bdatb":[[2,6.2,10.73],[3,6,12.49]],"id":12989514},{"bdatb":[[4,5.9,10.77],[5,5.8,37.57]],"id":44836671},{"bdatb":[[6,7,6.5],[7,6.8,6.02]],"id":43885158},{"bdatl":[[0,28,7.74]],"id":46969227}]}]}
{"op":"mcm","clk":"APZUAKMtAIdL","pt":1659347558648,"mc":[{"id":"1.201590187","rc":[{"atb":[[6.4,22.52]],"id":12989514}]}]}
{"op":"mcm","clk":"APlUAKMtAI1L","pt":1659347558698,"mc":[{"id":"1.201590187","rc":[{"bdatb":[[1,6.4,22.52]],"id":12989514}]}]}
{"op":"mcm","clk":"AIZVAKktAJtL","pt":1659347558863,"mc":[{"id":"1.201590187","rc":[{"atb":[[22,0]],"id":44621159}]}]}
{"op":"mcm","clk":"AIlVAKstAKRL","pt":1659347558913,"mc":[{"id":"1.201590187","rc":[{"bdatl":[[9,2.56,2.63]],"id":9570503},{"bdatl":[[9,13.5,1.7]],"id":12989514},{"bdatb":[[1,21,5],[2,20,1.8],[3,19.5,4.19],[4,18.5,1.37],[5,15.5,6.47],[6,14.5,1.11],[7,13,1.02],[8,11,14.37],[9,10.5,1.83]],"id":44621159}]}]}
{"op":"mcm","clk":"AJxVALotALBL","pt":1659347559037,"mc":[{"id":"1.201590187","rc":[{"atb":[[23,3.47]],"id":44621159}]}]}
{"op":"mcm","clk":"AJ9VALotALVL","pt":1659347559088,"mc":[{"id":"1.201590187","rc":[{"bdatl":[[8,2.5,25.47],[9,2.52,1.62]],"id":9570503},{"bdatl":[[9,13.5,1.88]],"id":12989514},{"bdatb":[[0,23,4.07]],"id":44621159}]}]}
{"op":"mcm","clk":"AKtVAMAtAMFL","pt":1659347559245,"mc":[{"id":"1.201590187","rc":[{"atb":[[7.8,3.45]],"id":43885158}]}]}
{"op":"mcm","clk":"AK1VAMQtAMhL","pt":1659347559295,"mc":[{"id":"1.201590187","rc":[{"bdatb":[[2,7.8,3.45]],"id":43885158}]}]}
{"op":"mcm","clk":"ALNVAMQtAMhL","pt":1659347559370,"mc":[{"id":"1.201590187","rc":[{"atb":[[7.8,1.26]],"id":43885158}]}]}
{"op":"mcm","clk":"ALVVAMYtANBL","pt":1659347559420,"mc":[{"id":"1.201590187","rc":[{"bdatb":[[2,7.8,1.26]],"id":43885158}]}]}
{"op":"mcm","clk":"AMBVAM4tANpL","pt":1659347559549,"mc":[{"id":"1.201590187","rc":[{"atl":[[1000,0]],"id":44621159}]}]}
{"op":"mcm","clk":"AMJVANAtAOBL","pt":1659347559606,"mc":[{"id":"1.201590187","rc":[{"bdatl":[[6,0,0]],"id":44621159}]}]}
{"op":"mcm","clk":"AMRVANEtAOJL","pt":1659347559656,"mc":[{"id":"1.201590187","rc":[{"atb":[[7.6,8.3]],"bdatb":[[3,7.6,8.3]],"id":43885158}]}]}
{"op":"mcm","clk":"AM1VANUtAOZL","pt":1659347559713,"mc":[{"id":"1.201590187","rc":[{"atb":[[23,1]],"id":44621159}]}]}
{"op":"mcm","clk":"ANBVANYtAOpL","pt":1659347559763,"mc":[{"id":"1.201590187","rc":[{"bdatl":[[8,2.5,24.5],[9,2.56,2.63]],"id":9570503},{"bdatl":[[9,13.5,1.7]],"id":12989514},{"bdatb":[[0,23,1.6]],"id":44621159}]}]}
{"op":"mcm","clk":"ANdVANktAPVL","pt":1659347559929,"mc":[{"id":"1.201590187","rc":[{"atb":[[24,2.91]],"id":44621159},{"atl":[[10.5,0]],"id":43885158}]}]}
{"op":"mcm","clk":"ANpVANotAPlL","pt":1659347559979,"mc":[{"id":"1.201590187","rc":[{"bdatl":[[6,2.46,7.89],[7,2.5,25.47],[8,2.52,1.62],[9,2.56,3.93]],"id":9570503},{"bdatl":[[8,13,3.24],[9,16.5,2.06]],"id":12989514},{"bdatb":[[0,24,3.02],[1,23,1],[2,21,5],[3,20,1.8],[4,19.5,4.19],[5,18.5,1.37],[6,15.5,6.47],[7,14.5,1.11],[8,13,1.02],[9,11,14.37]],"id":44621159},{"bdatl":[[3,11.5,2.65],[4,12,1.4],[5,12.5,18],[6,14,1],[7,14.5,1],[8,15,12],[9,15.5,1]],"id":43885158}]}]}
{"op":"mcm","clk":"AOJVAOQtAP1L","pt":1659347560042,"mc":[{"id":"1.201590187","rc":[{"atl":[[11,3.46]],"id":43885158}]}]}
{"op":"mcm","clk":"AONVAOQtAIBM","pt":1659347560092,"mc":[{"id":"1.201590187","rc":[{"bdatl":[[3,11,3.46],[4,11.5,2.64],[5,12,1.4],[6,12.5,18],[7,14,1],[8,14.5,1],[9,15,12]],"id":43885158}]}]}
{"op":"mcm","clk":"APdVAPgtAJBM","pt":1659347560352,"mc":[{"id":"1.201590187","rc":[{"atl":[[22,2.72]],"id":45323444},{"atb":[[20,5.71]],"id":44621159}]}]}
{"op":"mcm","clk":"APdVAPotAJVM","pt":1659347560402,"mc":[{"id":"1.201590187","rc":[{"bdatl":[[1,22,2.72],[2,23,1.82],[3,25,4.17],[4,26,6.48],[5,27,3.85],[6,29,8.93],[7,50,8],[8,55,9],[9,60,10]],"id":45323444},{"bdatb":[[5,5.4,3.57],[6,5.2,7.73],[7,4.9,4.05],[8,4.8,5.44],[9,4.6,15.8]],"id":12989514},{"bdatb":[[3,20,5.71]],"id":44621159}]}]}
{"op":"mcm","clk":"AP5VAP0tAJhM","pt":1659347560452,"mc":[{"id":"1.201590187","rc":[{"atl":[[23,0]],"id":45323444},{"atb":[[19.5,0]],"id":44621159}]}]}
{"op":"mcm","clk":"AP9VAP0tAJxM","pt":1659347560502,"mc":[{"id":"1.201590187","rc":[{"bdatl":[[2,25,4.17],[3,26,6.48],[4,27,3.85],[5,29,8.93],[6,50,8],[7,55,9],[8,60,10],[9,65,11]],"id":45323444},{"bdatb":[[7,4.9,3.59],[8,4.8,5.91]],"id":12989514},{"bdatb":[[4,18.5,1.37],[5,15.5,6.47],[6,14.5,1.11],[7,13,1.02],[8,11,14.37],[9,10.5,1.83]],"id":44621159}]}]}
{"op":"mcm","clk":"AIdWAIUuAJ9M","pt":1659347560552,"mc":[{"id":"1.201590187","rc":[{"atb":[[2.06,5.05],[2,10.84]],"id":9570503},{"atb":[[6,6.68],[4.8,2.86]],"id":12989514}]}]}
{"op":"mcm","clk":"AItWAIUuAKJM","pt":1659347560602,"mc":[{"id":"1.201590187","rc":[{"bdatb":[[1,2.06,5.05],[4,2,12.19]],"id":9570503},{"bdatb":[[3,6,14.49],[8,4.8,3.33]],"bdatl":[[9,16.5,1.22]],"id":12989514}]}]}
{"op":"mcm","clk":"AJFWAIcuAKRM","pt":1659347560655,"mc":[{"id":"1.201590187","rc":[{"atb":[[24,0.49]],"id":44621159}]}]}
{"op":"mcm","clk":"AJJWAIouAKZM","pt":1659347560705,"mc":[{"id":"1.201590187","rc":[{"bdatl":[[6,2.46,2.1],[7,2.48,5.74],[8,2.5,24.5],[9,2.56,2.63]],"id":9570503},{"bdatl":[[8,13,1.29],[9,13.5,1.7]],"id":12989514},{"bdatb":[[0,23,1.6],[1,21,5],[2,20,5.71],[3,18.5,1.37],[4,15.5,6.47],[5,14.5,1.11],[6,13,1.02],[7,11,14.37],[8,10.5,1.83],[9,10,104.13]],"id":44621159}]}]}
{"op":"mcm","clk":"AJ9WAJQuALFM","pt":1659347560835,"mc":[{"id":"1.201590187","rc":[{"atb":[[22,2.59]],"id":44621159}]}]}
{"op":"mcm","clk":"AKFWAJQuALZM","pt":1659347560886,"mc":[{"id":"1.201590187","rc":[{"bdatl":[[9,2.54,2.56]],"id":9570503},{"bdatl":[[9,13.5,1.88]],"id":12989514},{"bdatb":[[1,22,2.59],[2,21,5],[3,20,5.71],[4,18.5,1.37],[5,15.5,6.47],[6,14.5,1.11],[7,13,1.02],[8,11,14.37],[9,10.5,1.83]],"id":44621159}]}]}
{"op":"mcm","clk":"ANFWALkuAPJM","pt":1659347561456,"mc":[{"id":"1.201590187","rc":[{"atb":[[7.6,10.66]],"id":43885158}]}]}
{"op":"mcm","clk":"ANRWALsuAPZM","pt":1659347561507,"mc":[{"id":"1.201590187","rc":[{"bdatb":[[3,7.6,10.66]],"id":43885158}]}]}
{"op":"mcm","clk":"ANlWALwuAPdM","pt":1659347561561,"mc":[{"id":"1.201590187","rc":[{"atb":[[22,0]],"id":44621159},{"atb":[[7.6,12.89]],"id":43885158}]}]}
{"op":"mcm","clk":"AN5WAL0uAP1M","pt":1659347561611,"mc":[{"id":"1.201590187","rc":[{"bdatl":[[9,2.56,2.63]],"id":9570503},{"bdatl":[[9,13.5,1.7]],"id":12989514},{"bdatb":[[1,21,5],[2,20,5.71],[3,18.5,1.37],[4,15.5,6.47],[5,14.5,1.11],[6,13,1.02],[7,11,14.37],[8,10.5,1.83],[9,10,104.13]],"id":44621159},{"bdatb":[[3,7.6,12.89]],"id":43885158}]}]}
{"op":"mcm","clk":"AOxWAMEuAIVN","pt":1659347561731,"mc":[{"id":"1.201590187","rc":[{"atb":[[23,3.47]],"id":44621159}]}]}
{"op":"mcm","clk":"AO9WAMIuAIZN","pt":1659347561781,"mc":[{"id":"1.201590187","rc":[{"bdatl":[[8,2.5,25.47],[9,2.52,1.62]],"id":9570503},{"bdatl":[[9,13.5,1.88]],"id":12989514},{"bdatb":[[0,23,4.07]],"id":44621159}]}]}
{"op":"mcm","clk":"AJ9XAOQuALNN","pt":1659347562453,"mc":[{"id":"1.201590187","rc":[{"atb":[[23,1]],"bdatb":[[0,23,1.6]],"id":44621159},{"bdatl":[[8,2.5,24.5],[9,2.56,2.63]],"id":9570503},{"bdatl":[[9,13.5,1.7]],"id":12989514}]}]}
{"op":"mcm","clk":"AKVXAOcuALlN","pt":1659347562563,"mc":[{"id":"1.201590187","rc":[{"atb":[[24,2.91]],"id":44621159}]}]}
{"op":"mcm","clk":"AKhXAOkuAMBN","pt":1659347562613,"mc":[{"id":"1.201590187","rc":[{"bdatl":[[6,2.46,7.89],[7,2.5,25.47],[8,2.52,1.62],[9,2.56,3.93]],"id":9570503},{"bdatl":[[8,13,3.24],[9,16.5,1.22]],"id":12989514},{"bdatb":[[0,24,3.02],[1,23,1],[2,21,5],[3,20,5.71],[4,18.5,1.37],[5,15.5,6.47],[6,14.5,1.11],[7,13,1.02],[8,11,14.37],[9,10.5,1.83]],"id":44621159}]}]}
{"op":"mcm","clk":"ALZXAPMuAMxN","pt":1659347562733,"mc":[{"id":"1.201590187","rc":[{"atb":[[8,1.76]],"id":43885158}]}]}
{"op":"mcm","clk":"ALlXAPQuANJN","pt":1659347562786,"mc":[{"id":"1.201590187","rc":[{"bdatl":[[6,2.46,5.72],[7,2.48,2.16],[8,2.5,21],[9,2.52,1.79]],"id":9570503},{"bdatl":[[8,13,1.97],[9,14.5,1.19]],"id":12989514},{"bdatb":[[1,8,1.76]],"id":43885158}]}]}
{"op":"mcm","clk":"AMNXAPkuANRN","pt":1659347562845,"mc":[{"id":"1.201590187","rc":[{"atl":[[36,2.86]],"id":46969227}]}]}
{"op":"mcm","clk":"AMNXAPkuANdN","pt":1659347562895,"mc":[{"id":"1.201590187","rc":[{"bdatl":[[3,36,2.86]],"id":46969227}]}]}
{"op":"mcm","clk":"AMlXAP0uANlN","pt":1659347562957,"mc":[{"id":"1.201590187","rc":[{"atb":[[21,3.25]],"atl":[[30,1.17]],"id":46969227}]}]}
{"op":"mcm","clk":"AMlXAIAvAN5N","pt":1659347563007,"mc":[{"id":"1.201590187","rc":[{"bdatb":[[0,21,3.25]],"bdatl":[[1,30,1.17],[2,32,2.09],[3,34,5.09],[4,36,2.86],[5,40,5.01],[6,80,1.66],[7,310,1],[8,990,2.15]],"id":46969227}]}]}
{"op":"mcm","clk":"ANBXAIcvAOlN","pt":1659347563155,"mc":[{"id":"1.201590187","rc":[{"atb":[[8.2,0]],"atl":[[9.2,2.69]],"id":43885158}]}]}
{"op":"mcm","clk":"ANNXAIovAO5N","pt":1659347563205,"mc":[{"id":"1.201590187","rc":[{"bdatb":[[9,9.2,13.73]],"id":45323444},{"bdatb":[[5,1.99,11.08],[6,1.98,49.46]],"bdatl":[[4,2.44,153.09],[5,2.46,4.73],[6,2.48,3.98],[7,2.5,22.96],[8,2.54,4.4],[9,2.56,11.03]],"id":9570503},{"bdatl":[[8,13,1.22],[9,14.5,1.84]],"id":12989514},{"bdatb":[[5,15.5,5.79],[6,14.5,1.84]],"id":44621159},{"bdatl":[[8,13,41.9],[9,13.5,1.76]],"id":44836671},{"bdatb":[[0,8,1.76],[1,7.8,1.26],[2,7.6,12.89],[3,7.4,10.26],[4,7.2,3.71],[5,7,6.5],[6,6.8,6.02],[7,6.6,64.72],[8,6.4,4.07],[9,6.2,10]],"bdatl":[[0,9.2,2.69]],"id":43885158},{"bdatb":[[7,14,1.74],[8,13.5,1.84]],"id":46969227}]}]}
{"op":"mcm","clk":"ANlXAIovAPJN","pt":1659347563255,"mc":[{"id":"1.201590187","rc":[{"atl":[[16.5,0.72]],"trd":[[16.5,6.4]],"bdatl":[[0,22,3.44],[1,25,4.17],[2,26,6.48],[3,27,3.85],[4,29,8.93],[5,50,8],[6,55,9],[7,60,10],[8,65,11],[9,70,12]],"ltp":16.5,"tv":20.58,"id":45323444},{"atb":[[24,0.49]],"bdatb":[[0,23,1.6],[1,21,5],[2,20,5.71],[3,18.5,1.37],[4,15.5,4.96],[5,12.5,1.03],[6,12,2.22],[7,11,14.37],[8,10.5,1.93],[9,10,103.23]],"id":44621159},{"bdatb":[[5,1.99,4.6],[6,1.98,36.93],[7,1.96,2.62],[8,1.93,6.68],[9,1.92,12.91]],"bdatl":[[6,2.5,24.95],[7,2.52,1.95],[8,2.54,3.45],[9,2.6,11.79]],"id":9570503},{"bdatb":[[3,6,8.2],[4,5.6,2.3],[5,5.5,4.51],[6,5.4,4.09],[7,5.2,2.36],[8,5.1,4.71],[9,5,3.24]],"bdatl":[[9,14.5,1.65]],"id":12989514},{"bdatb":[[5,5.8,31.07],[6,5.7,44.55],[9,5.4,14]],"id":44836671},{"bdatb":[[6,6.6,64.92],[7,6.4,2],[8,6.2,16.38],[9,6,14]],"id":43885158},{"bdatb":[[7,11.5,1.94],[8,11,2.43],[9,10,3.59]],"id":46969227}],"tv":1321.79}]}
{"op":"mcm","clk":"AOFXAJQvAPxN","pt":1659347563451,"mc":[{"id":"1.201590187","rc":[{"atb":[[12.5,3.39]],"atl":[[21,2]],"id":45323444},{"atb":[[6.4,20.09]],"id":12989514},{"atb":[[22,2.59]],"id":44621159}]}]}
{"op":"mcm","clk":"AONXAJUvAIFO","pt":1659347563501,"mc":[{"id":"1.201590187","rc":[{"bdatb":[[0,12.5,3.39]],"bdatl":[[0,21,2.72],[1,22,2.72],[2,25,4.17],[3,26,6.48],[4,27,3.85],[5,29,8.93],[6,50,8],[7,55,9],[8,60,10],[9,65,11]],"id":45323444},{"bdatb":[[8,1.94,6.65],[9,1.93,12.85]],"bdatl":[[9,2.56,1.87]],"id":9570503},{"bdatb":[[1,6.4,20.09],[4,5.6,6.73],[5,5.4,6.35],[6,5.2,5.71],[7,5,2.1],[8,4.9,3.52],[9,4.8,3.4]],"id":12989514},{"bdatb":[[1,22,2.59],[2,21,5],[3,20,5.71],[4,18.5,1.37],[5,15.5,4.96],[6,12.5,3.17],[7,11,14.59],[8,10.5,2.86],[9,10,104.13]],"id":44621159},{"bdatb":[[9,5.4,16.39]],"id":44836671},{"bdatb":[[7,11.5,4.1],[8,10,3.76],[9,9.8,1.69]],"id":46969227}]}]}
{"op":"mcm","clk":"AO5XAJ0vAIlO","pt":1659347563662,"mc":[{"id":"1.201590187","rc":[{"atb":[[7.6,9.12]],"id":43885158}]}]}
{"op":"mcm","clk":"APFXAJ4vAIxO","pt":1659347563712,"mc":[{"id":"1.201590187","rc":[{"bdatb":[[2,7.6,9.12]],"id":43885158}]}]}
{"op":"mcm","clk":"APhXAKEvAI5O","pt":1659347563762,"mc":[{"id":"1.201590187","rc":[{"atb":[[2.06,0]],"id":9570503}]}]}
{"op":"mcm","clk":"APlXAKEvAJBO","pt":1659347563813,"mc":[{"id":"1.201590187","rc":[{"bdatb":[[1,2.04,14.73],[2,2.02,30.96],[3,2,12.19],[4,1.99,4.6],[5,1.98,36.93],[6,1.96,2.62],[7,1.94,6.65],[8,1.93,12.85],[9,1.91,108.34]],"id":9570503}]}]}
{"op":"mcm","clk":"APxXAKUvAJJO","pt":1659347563863,"mc":[{"id":"1.201590187","rc":[{"atb":[[1.8,2.88]],"id":45323444},{"atb":[[8,1.46]],"id":43885158}]}]}
{"op":"mcm","clk":"AP1XAKUvAJRO","pt":1659347563914,"mc":[{"id":"1.201590187","rc":[{"bdatl":[[5,2.46,3.75],[6,2.48,1.18],[7,2.5,23.78],[8,2.52,2.9],[9,2.54,3.45]],"id":9570503},{"bdatl":[[8,13,1.04],[9,14.5,1.83]],"id":12989514},{"bdatb":[[0,8,1.46]],"id":43885158}]}]}
{"op":"mcm","clk":"AIVYAKwvAJ1O","pt":1659347564038,"mc":[{"id":"1.201590187","rc":[{"atl":[[20,2]],"id":45323444}]}]}
{"op":"mcm","clk":"AIdYAKwvAJ9O","pt":1659347564088,"mc":[{"id":"1.201590187","rc":[{"bdatl":[[0,20,2.72],[1,21,2],[2,22,2.72],[3,25,4.17],[4,26,6.48],[5,27,3.85],[6,29,8.93],[7,50,8],[8,55,9],[9,60,10]],"id":45323444},{"bdatb":[[7,1.94,19.43],[8,1.91,108.34],[9,1.89,8.4]],"id":9570503},{"bdatb":[[4,5.7,2.26],[5,5.6,4.84],[6,5.5,2.81],[7,5.4,3.07],[8,5.3,1.87],[9,5.2,5.82]],"id":12989514},{"bdatb":[[6,12.5,3.12],[7,11,15.81],[8,10.5,2.53],[9,10,103.13]],"id":44621159},{"bdatb":[[8,5.5,25.34],[9,5.4,18.94]],"id":44836671},{"bdatb":[[7,6.4,8.18],[8,6.2,10],[9,6,14.07]],"id":43885158},{"bdatb":[[7,12,1.89],[8,11.5,2.32],[9,10,5.25]],"id":46969227}]}]}
{"op":"mcm","clk":"AIxYAK4vAJ9O","pt":1659347564143,"mc":[{"id":"1.201590187","rc":[{"atb":[[13,2]],"atl":[[20,4]],"id":45323444},{"atb":[[22,0]],"id":44621159}]}]}
{"op":"mcm","clk":"AI5YALAvAKVO","pt":1659347564193,"mc":[{"id":"1.201590187","rc":[{"bdatb":[[0,13,2],[1,12.5,3.39],[2,12,2.87],[3,11.5,5.54],[4,11,1.23],[5,10.5,2.6],[6,10,14.1],[7,9.8,9],[8,9.6,21],[9,9.4,54.1]],"bdatl":[[0,20,4.72]],"id":45323444},{"bdatb":[[9,1.9,8.36]],"bdatl":[[4,2.42,1.01],[5,2.44,155.87],[6,2.46,1.19],[7,2.48,2.8],[8,2.5,22.78],[9,2.52,1.13]],"id":9570503},{"bdatb":[[5,5.6,7.6],[6,5.5,3.02],[7,5.4,1.47],[8,5.3,6.09],[9,4.9,4.03]],"bdatl":[[8,12.5,1.07],[9,14,1.06]],"id":12989514},{"bdatb":[[1,21,5],[2,20,5.71],[3,18.5,1.37],[4,15.5,4.96],[5,12.5,3.12],[6,11.5,1.38],[7,11,15.87],[8,10.5,2.02],[9,10,102]],"id":44621159},{"bdatl":[[8,13,42.11],[9,13.5,2.22]],"id":44836671},{"bdatb":[[9,6,19.41]],"id":43885158},{"bdatb":[[9,10.5,1.51]],"id":46969227}]}]}
{"op":"mcm","clk":"AJNYALIvAKZO","pt":1659347564248,"mc":[{"id":"1.201590187","rc":[{"atb":[[1.8,0.01]],"id":45323444}]}]}
{"op":"mcm","clk":"AJdYALcvAKtO","pt":1659347564353,"mc":[{"id":"1.201590187","rc":[{"atb":[[13,6.42]],"id":45323444},{"atb":[[8,7.95]],"id":43885158}]}]}
{"op":"mcm","clk":"AJlYALgvAK5O","pt":1659347564403,"mc":[{"id":"1.201590187","rc":[{"bdatb":[[0,13,6.42]],"id":45323444},{"bdatl":[[5,2.44,157.07],[6,2.46,5.79],[7,2.48,3.53],[8,2.5,21],[9,2.52,10.32]],"id":9570503},{"bdatl":[[8,12.5,1.3],[9,13,1.77]],"id":12989514},{"bdatl":[[9,13.5,3.49]],"id":44836671},{"bdatb":[[0,8,7.95]],"id":43885158}]}]}
{"op":"mcm","clk":"AKJYAMAvALZO","pt":1659347564554,"mc":[{"id":"1.201590187","rc":[{"atb":[[13,6.61]],"id":45323444},{"atb":[[23,3.47]],"id":44621159}]}]}
{"op":"mcm","clk":"AKVYAMEvALpO","pt":1659347564604,"mc":[{"id":"1.201590187","rc":[{"bdatb":[[0,13,6.61]],"id":45323444},{"bdatl":[[7,2.48,14.02],[8,2.5,22.85],[9,2.52,2.08]],"id":9570503},{"bdatl":[[9,13,2.58]],"id":12989514},{"bdatb":[[0,23,4.07]],"id":44621159}]}]}
{"op":"mcm","clk":"AKlYAMQvALxO","pt":1659347564658,"mc":[{"id":"1.201590187","rc":[{"atb":[[1.8,0]],"id":45323444},{"atb":[[2.04,21.54]],"id":9570503}]}]}
{"op":"mcm","clk":"AKpYAMQvAL9O","pt":1659347564708,"mc":[{"id":"1.201590187","rc":[{"bdatb":[[1,2.04,21.54]],"id":9570503}]}]}
{"op":"mcm","clk":"ALBYAMwvAMFO","pt":1659347564761,"mc":[{"id":"1.201590187","rc":[{"atl":[[1000,0.89],[16.5,0.71]],"trd":[[16.5,6.41]],"tv":20.59,"id":45323444}],"tv":1321.8}]}
{"op":"mcm","clk":"ALRYAM0vAMdO","pt":1659347564815,"mc":[{"id":"1.201590187","rc":[{"bdatl":[[0,20,4.71]],"id":45323444},{"bdatb":[[4,1.99,4.55],[7,1.94,19.48]],"id":9570503},{"bdatb":[[3,6,8.19],[4,5.7,2.28],[7,5.4,1.45],[8,5.3,6.11]],"id":12989514},{"bdatb":[[4,15.5,4.95],[5,13,1],[6,12.5,2.13],[7,11.5,1.38],[8,11,15.87],[9,10.5,2.02]],"id":44621159},{"bdatb":[[5,5.8,31.05],[8,5.5,25.36]],"id":44836671},{"bdatb":[[6,6.6,64.91],[7,6.4,8.2]],"id":43885158}]}]}
{"op":"mcm","clk":"ALpYANEvAMpO","pt":1659347564865,"mc":[{"id":"1.201590187","rc":[{"atb":[[2.08,0]],"atl":[[2.08,3.15]],"trd":[[2.08,79.39]],"tv":878.7,"id":9570503}],"tv":1368.09}]}
{"op":"mcm","clk":"AL1YANMvAM5O","pt":1659347564916,"mc":[{"id":"1.201590187","rc":[{"bdatb":[[1,12.5,3.61],[2,12,3.19],[5,10.5,1.97]],"id":45323444},{"bdatb":[[0,2.04,21.54],[1,2.02,30.96],[2,2,12.19],[3,1.99,4.55],[4,1.98,36.93],[5,1.96,2.62],[6,1.94,19.48],[7,1.91,108.34],[8,1.9,8.36],[9,1.89,8.78]],"bdatl":[[0,2.08,3.15],[1,2.14,58],[2,2.18,1.18],[3,2.3,8.58],[4,2.4,71.43],[5,2.42,1.01],[6,2.44,157.07],[7,2.46,5.79],[8,2.48,14.02],[9,2.5,22.85]],"id":9570503},{"bdatb":[[0,6.6,5.35],[2,6.2,10.3],[3,6,7.55],[8,5.3,7.34]],"bdatl":[[8,14,1.19],[9,14.5,2.02]],"id":12989514},{"bdatb":[[2,20,5.84],[3,18.5,1.57],[4,15.5,4.53]],"id":44621159},{"bdatb":[[2,6.4,1.39],[3,6.2,25.79],[4,6,29.74],[5,5.9,9.66],[6,5.8,31.05],[7,5.7,44.55],[8,5.6,46.48],[9,5.5,25.36]],"bdatl":[[8,13,41.9],[9,13.5,1.55]],"id":44836671},{"bdatb":[[1,7.8,1.61],[2,7.6,9.63],[5,7,5.56]],"id":43885158},{"bdatb":[[5,18,5.36],[7,12,1.44]],"id":46969227}]}]}
{"op":"mcm","clk":"AMNYANYvAM9O","pt":1659347564967,"mc":[{"id":"1.201590187","rc":[{"atl":[[1000,0.48]],"bdatb":[[1,12.5,3.39],[2,12,2.87],[5,10.5,2.6]],"id":45323444},{"atl":[[2.08,0]],"trd":[[2.08,85.69]],"bdatl":[[0,2.14,58],[1,2.18,1.18],[2,2.3,8.58],[3,2.4,71.43],[4,2.42,1.01],[5,2.44,157.07],[6,2.46,5.79],[7,2.48,14.02],[8,2.5,22.85],[9,2.52,2.08]],"tv":885,"id":9570503},{"bdatb":[[0,6.6,4.37],[2,6.2,10.73],[3,6,8.19],[8,5.3,6.11]],"id":12989514},{"bdatb":[[2,20,5.71],[3,18.5,1.37],[4,15.5,4.95]],"id":44621159},{"bdatb":[[2,6.2,26.16],[3,6,29.74],[4,5.9,10.77],[5,5.8,31.05],[6,5.7,44.55],[7,5.6,46.48],[8,5.5,25.36],[9,5.4,18.94]],"id":44836671},{"bdatb":[[1,7.8,1.26],[2,7.6,9.12],[5,7,6.5]],"id":43885158},{"bdatb":[[5,18,5],[7,12,1.89]],"id":46969227}],"tv":1374.39}]}
{"op":"mcm","clk":"AMpYANsvANRO","pt":1659347565051,"mc":[{"id":"1.201590187","rc":[{"atl":[[19.5,0.41]],"id":45323444},{"atb":[[2.08,2.68],[2.04,22.75],[1.97,2.53]],"atl":[[2.26,7]],"id":9570503}]}]}
{"op":"mcm","clk":"AMxYANsvANZO","pt":1659347565101,"mc":[{"id":"1.201590187","rc":[{"bdatl":[[0,19.5,1.12],[1,20,4],[2,21,2],[3,22,2.72],[4,25,4.17],[5,26,6.48],[6,27,3.85],[7,29,8.93],[8,50,8],[9,55,9]],"id":45323444},{"bdatb":[[0,2.08,2.68],[1,2.04,22.75],[2,2.02,30.96],[3,2,12.19],[4,1.99,4.55],[5,1.98,36.93],[6,1.97,2.53],[7,1.96,2.62],[8,1.95,4.11],[9,1.94,15.35]],"bdatl":[[2,2.26,7],[3,2.3,8.58],[4,2.4,71.43],[5,2.42,1.01],[6,2.44,157.07],[7,2.46,5.79],[8,2.48,14.02],[9,2.5,22.85]],"id":9570503},{"bdatb":[[7,5.4,2.94],[8,5.3,4.59]],"bdatl":[[8,14,1.22],[9,14.5,2.58]],"id":12989514},{"bdatb":[[5,12.5,3.1],[6,11.5,1.38],[7,11,15.87],[8,10.5,2.02],[9,10,102]],"id":44621159},{"bdatl":[[8,13,42.11],[9,13.5,1.76]],"id":44836671},{"bdatb":[[7,12.5,1.45],[8,11.5,2.73]],"id":46969227}]}]}
{"op":"mcm","clk":"ANFYAOEvANlO","pt":1659347565152,"mc":[{"id":"1.201590187","rc":[{"atb":[[2.08,0]],"id":9570503}]}]}
{"op":"mcm","clk":"ANJYAOEvAN1O","pt":1659347565202,"mc":[{"id":"1.201590187","rc":[{"bdatb":[[0,2.04,22.75],[1,2.02,30.96],[2,2,12.19],[3,1.99,4.55],[4,1.98,36.93],[5,1.97,2.53],[6,1.96,2.62],[7,1.95,4.11],[8,1.94,15.35],[9,1.91,108.34]],"id":9570503},{"bdatl":[[8,14,1.19],[9,14.5,2.19]],"id":12989514},{"bdatl":[[8,13,41.9],[9,13.5,1.55]],"id":44836671}]}]}
{"op":"mcm","clk":"ANdYAOQvAOJO","pt":1659347565253,"mc":[{"id":"1.201590187","rc":[{"atb":[[2.04,39.55]],"atl":[[2.26,0],[2.24,4]],"id":9570503},{"atb":[[23,1]],"id":44621159},{"atb":[[8,1.46]],"id":43885158}]}]}
{"op":"mcm","clk":"ANdYAOYvAONO","pt":1659347565303,"mc":[{"id":"1.201590187","rc":[{"bdatb":[[0,2.04,39.55]],"bdatl":[[2,2.24,4],[6,2.44,155.87],[7,2.46,1.19],[8,2.48,2.8],[9,2.5,23.92]],"id":9570503},{"bdatl":[[8,15,1.18],[9,16,1.45]],"id":12989514},{"bdatb":[[0,23,1.6]],"id":44621159},{"bdatb":[[0,8,1.46]],"id":43885158}]}]}
{"op":"mcm","clk":"ANxYAOwvAORO","pt":1659347565353,"mc":[{"id":"1.201590187","rc":[{"atb":[[2.04,32.74],[2.02,47.75]],"atl":[[2.22,4]],"id":9570503},{"atb":[[7.8,7.93]],"id":43885158}]}]}
{"op":"mcm","clk":"AN9YAO8vAOlO","pt":1659347565403,"mc":[{"id":"1.201590187","rc":[{"bdatb":[[0,2.04,32.74],[1,2.02,47.75]],"bdatl":[[2,2.22,4],[3,2.24,4],[4,2.3,8.58],[5,2.4,71.43],[6,2.42,1.01],[7,2.44,155.87],[8,2.46,1.19],[9,2.48,5.74]],"id":9570503},{"bdatl":[[9,15.5,1.48]],"id":12989514},{"bdatb":[[1,7.8,7.93]],"id":43885158}]}]}
{"op":"mcm","clk":"AORYAO8vAOpO","pt":1659347565453,"mc":[{"id":"1.201590187","rc":[{"atl":[[19.5,1.41]],"id":45323444},{"atb":[[2.04,15.94]],"atl":[[2.24,0]],"id":9570503},{"atb":[[24,1.49]],"atl":[[34,2.15]],"id":44621159}]}]}
{"op":"mcm","clk":"AOZYAPYvAO5O","pt":1659347565503,"mc":[{"id":"1.201590187","rc":[{"bdatl":[[0,19.5,2.12]],"id":45323444},{"bdatb":[[0,2.04,15.94],[7,1.95,6.66],[8,1.94,13.75],[9,1.91,107.36]],"bdatl":[[3,2.3,8.58],[4,2.4,71.43],[5,2.42,1.01],[6,2.44,155.87],[7,2.46,6.98],[8,2.5,34.1],[9,2.54,4.7]],"id":9570503},{"bdatb":[[4,5.7,4.83],[5,5.6,7.91],[6,5.4,6.62],[7,5.1,1.42],[8,4.9,3.52],[9,4.8,4.71]],"bdatl":[[8,15,2.37],[9,16.5,1.77]],"id":12989514},{"bdatb":[[0,24,1.6],[1,23,1],[2,21,5],[3,20,5.71],[4,18.5,1.37],[5,15.5,4.95],[6,13,2.08],[7,11.5,2.35],[8,11,15.87],[9,10.5,2.02]],"bdatl":[[0,34,2.48]],"id":44621159},{"bdatb":[[8,5.5,28],[9,5.4,16.25]],"id":44836671},{"bdatb":[[7,12.5,1.85],[8,12,1.21],[9,11.5,1.06]],"id":46969227}]}]}
{"op":"mcm","clk":"AO1YAPYvAO5O","pt":1659347565572,"mc":[{"id":"1.201590187","rc":[{"atb":[[13.5,1]],"atl":[[23,1.82],[22,0.82]],"id":45323444},{"atl":[[2.2,4]],"id":9570503},{"atb":[[24,3.91]],"id":44621159},{"atl":[[36,0],[34,8.12]],"id":46969227}]}]}
{"op":"mcm","clk":"APVYAPwvAPNO","pt":1659347565622,"mc":[{"id":"1.201590187","rc":[{"bdatb":[[0,13.5,1],[1,13,6.61],[2,12.5,3.39],[3,12,2.87],[4,11.5,5.54],[5,11,1.23],[6,10.5,2.6],[7,10,14.1],[8,9.8,9],[9,9.6,21]],"bdatl":[[3,23,2.64]],"id":45323444},{"bdatl":[[2,2.2,4],[3,2.22,4],[4,2.3,8.58],[5,2.4,72.45],[6,2.44,156.62],[7,2.46,6.24],[8,2.5,36.76],[9,2.52,2.1]],"id":9570503},{"bdatb":[[8,4.9,5.32]],"bdatl":[[8,13.5,1.01],[9,15,1.4]],"id":12989514},{"bdatb":[[0,24,4.02]],"id":44621159},{"bdatl":[[3,34,8.12],[4,40,5.01],[5,80,1.66],[6,310,1],[7,990,2.15],[8,0,0]],"id":46969227}]}]}
{"op":"mcm","clk":"APhYAP0vAPZO","pt":1659347565672,"mc":[{"id":"1.201590187","rc":[{"atl":[[21,0]],"bdatl":[[2,23,2.64],[3,25,4.17],[4,26,6.48],[5,27,3.85],[6,29,8.93],[7,50,8],[8,55,9],[9,60,10]],"id":45323444},{"atb":[[2.02,20.45]],"bdatb":[[1,2.02,20.45]],"id":9570503},{"bdatb":[[7,5,1.44],[9,4.8,4.2]],"id":12989514}]}]}
{"op":"mcm","clk":"AP9YAIIwAP1O","pt":1659347565756,"mc":[{"id":"1.201590187","rc":[{"atb":[[9.4,28.24],[13.5,1.18]],"id":45323444},{"atb":[[1.77,33.55]],"id":9570503},{"atb":[[3.7,14]],"id":12989514},{"atb":[[9.4,1.48]],"id":44621159},{"atb":[[6.6,30.24]],"id":43885158}]}]}
{"op":"mcm","clk":"AINZAIIwAP9O","pt":1659347565806,"mc":[{"id":"1.201590187","rc":[{"bdatb":[[0,13.5,1.18]],"id":45323444},{"bdatl":[[6,2.44,157.61],[7,2.46,5.25]],"id":9570503},{"bdatb":[[6,6.6,30.43]],"id":43885158}]}]}
{"op":"mcm","clk":"AIhZAIwwAIFP","pt":1659347565868,"mc":[{"id":"1.201590187","rc":[{"atl":[[2.14,61.89]],"id":9570503}]}]}
{"op":"mcm","clk":"AIpZAI0wAINP","pt":1659347565918,"mc":[{"id":"1.201590187","rc":[{"bdatl":[[0,2.14,61.89]],"id":9570503},{"bdatb":[[7,5.2,2.53],[8,4.9,4.49],[9,4.8,4.23]],"id":12989514}]}]}
{"op":"mcm","clk":"AJJZAJMwAIRP","pt":1659347565968,"mc":[{"id":"1.201590187","rc":[{"atl":[[2.14,65.55]],"bdatl":[[0,2.14,65.55]],"id":9570503},{"bdatb":[[7,5.2,4.04],[8,4.9,4.04],[9,4.8,4.7]],"id":12989514}]}]}
{"op":"mcm","clk":"AKNZAKkwAI9P","pt":1659347566242,"mc":[{"id":"1.201590187","rc":[{"atb":[[13,2.19]],"id":45323444},{"atb":[[24,1.49]],"id":44621159}]}]}
{"op":"mcm","clk":"AKRZAKkwAJNP","pt":1659347566292,"mc":[{"id":"1.201590187","rc":[{"bdatb":[[1,13,2.19]],"id":45323444},{"bdatl":[[8,2.5,27.22],[9,2.52,6.83]],"id":9570503},{"bdatb":[[0,24,1.6]],"id":44621159}]}]}
{"op":"mcm","clk":"AKpZAK4wAJVP","pt":1659347566344,"mc":[{"id":"1.201590187","rc":[{"atl":[[1000,1.7]],"id":9570503}]}]}
{"op":"mcm","clk":"ALFZALEwAJdP","pt":1659347566450,"mc":[{"id":"1.201590187","rc":[{"atb":[[13.5,5.43]],"id":45323444},{"atb":[[3.9,44.48]],"id":12989514},{"atb":[[11,31.6]],"id":44621159}]}]}
{"op":"mcm","clk":"ALFZALIwAJlP","pt":1659347566500,"mc":[{"id":"1.201590187","rc":[{"bdatb":[[0,13.5,5.43]],"id":45323444},{"bdatl":[[6,2.44,162.9],[7,2.48,13.21],[8,2.5,21],[9,2.52,2.63]],"id":9570503},{"bdatl":[[9,14.5,1.44]],"id":12989514},{"bdatb":[[8,11,33.11]],"id":44621159}]}]}
{"op":"mcm","clk":"ALZZALcwAKBP","pt":1659347566566,"mc":[{"id":"1.201590187","rc":[{"atb":[[1.79,34.48]],"id":9570503},{"atb":[[6.6,47.48]],"id":43885158}]}]}
{"op":"mcm","clk":"ALhZALkwAKNP","pt":1659347566616,"mc":[{"id":"1.201590187","rc":[{"bdatb":[[6,6.6,47.67]],"id":43885158}]}]}
{"op":"mcm","clk":"AL9ZALowAKZP","pt":1659347566666,"mc":[{"id":"1.201590187","rc":[{"atb":[[9.4,45.48]],"id":45323444},{"atb":[[2.02,25.16]],"atl":[[1000,0.85]],"bdatb":[[1,2.02,25.16]],"bdatl":[[6,2.42,3.81],[7,2.44,159.13],[8,2.46,12.74],[9,2.48,3.24]],"id":9570503},{"atb":[[25,2.41]],"bdatb":[[0,25,2.41],[1,24,1.49],[2,23,1],[3,21,5],[4,20,5.71],[5,18.5,1.37],[6,15.5,4.95],[7,13,2.08],[8,11.5,2.35],[9,11,33.11]],"id":44621159},{"atb":[[8.8,51.72]],"id":46969227},{"bdatl":[[9,14,1.49]],"id":12989514}]}]}
{"op":"mcm","clk":"ANRZAMwwALRP","pt":1659347566959,"mc":[{"id":"1.201590187","rc":[{"atl":[[1000,0]],"id":9570503},{"atb":[[20,3.91]],"id":44621159}]}]}
{"op":"mcm","clk":"ANZZAM4wALhP","pt":1659347567010,"mc":[{"id":"1.201590187","rc":[{"bdatb":[[4,20,3.91]],"id":44621159}]}]}
{"op":"mcm","clk":"ANpZANAwALtP","pt":1659347567064,"mc":[{"id":"1.201590187","rc":[{"atl":[[2.12,0.85]],"id":9570503},{"atb":[[22,1.8]],"id":44621159}]}]}
{"op":"mcm","clk":"AOBZANIwAL5P","pt":1659347567114,"mc":[{"id":"1.201590187","rc":[{"bdatb":[[5,11,1.39],[6,10.5,2.43]],"id":45323444},{"bdatl":[[0,2.14,66.4]],"id":9570503},{"bdatb":[[1,6.4,20.38],[2,6.2,10.44],[7,5.2,4.35],[8,4.9,4.07]],"id":12989514},{"bdatb":[[3,22,1.8],[4,21,5],[5,20,3.91],[6,18.5,1.37],[7,15.5,4.95],[8,13,2.08],[9,11.5,2.35]],"id":44621159},{"bdatb":[[3,6,30.04],[4,5.9,10.47]],"id":44836671},{"bdatb":[[4,7.2,3.96],[5,7,6.24]],"id":43885158}]}]}
{"op":"mcm","clk":"AOZZANgwAMNP","pt":1659347567225,"mc":[{"id":"1.201590187","rc":[{"atl":[[2.14,66.74]],"id":9570503}]}]}
{"op":"mcm","clk":"AOhZANkwAMRP","pt":1659347567275,"mc":[{"id":"1.201590187","rc":[{"bdatl":[[0,2.14,67.59]],"id":9570503},{"bdatb":[[8,4.9,4.57]],"id":12989514}]}]}
{"op":"mcm","clk":"APRZAOQwAMpP","pt":1659347567453,"mc":[{"id":"1.201590187","rc":[{"atb":[[13.5,1.18]],"id":45323444},{"atl":[[36,0]],"id":44621159}]}]}
{"op":"mcm","clk":"APVZAOQwAM5P","pt":1659347567504,"mc":[{"id":"1.201590187","rc":[{"bdatb":[[0,13.5,1.18]],"id":45323444},{"bdatl":[[7,2.44,153.83],[8,2.46,5.25],[9,2.48,6.27]],"id":9570503},{"bdatb":[[6,5.4,4.14],[7,5.3,2.52],[8,5.2,3.46],[9,5.1,1.44]],"bdatl":[[9,14.5,1.44]],"id":12989514},{"bdatl":[[1,40,3.86],[2,95,2.64],[3,170,2],[4,990,2.07],[5,0,0]],"id":44621159}]}]}
{"op":"mcm","clk":"APtZAOowANBP","pt":1659347567554,"mc":[{"id":"1.201590187","rc":[{"atb":[[23,0]],"atl":[[32,0]],"id":44621159}]}]}
{"op":"mcm","clk":"AP1ZAOowANFP","pt":1659347567604,"mc":[{"id":"1.201590187","rc":[{"bdatb":[[6,10.5,1.69],[7,10,14.87]],"id":45323444},{"bdatb":[[2,2,10.84],[3,1.99,5.91]],"id":9570503},{"bdatb":[[1,6.4,20.09],[2,6.2,10.59],[3,6,8.34],[5,5.6,6.04],[6,5.5,1.97],[7,5.4,2.14],[8,5.3,4.49],[9,5.2,3.46]],"id":12989514},{"bdatb":[[2,22,1.8],[3,21,5],[4,20,3.91],[5,18.5,1.37],[6,15.5,4.95],[7,13,2.08],[8,11.5,2.35],[9,11,33.11]],"bdatl":[[0,34,2.15]],"id":44621159},{"bdatb":[[4,5.9,9.15],[5,5.8,32.39]],"id":44836671},{"bdatb":[[5,7,5.13],[6,6.8,1.33],[7,6.6,47.48],[8,6.4,8.2],[9,6.2,10]],"id":43885158},{"bdatb":[[7,12.5,1.87]],"id":46969227}]}]}
{"op":"mcm","clk":"AINaAO8wANpP","pt":1659347567654,"mc":[{"id":"1.201590187","rc":[{"atb":[[13,6.61]],"id":45323444},{"atb":[[2.02,22.7]],"id":9570503}]}]}
{"op":"mcm","clk":"AIRaAPMwAN5P","pt":1659347567704,"mc":[{"id":"1.201590187","rc":[{"bdatb":[[1,13,6.61]],"id":45323444},{"bdatb":[[1,2.02,22.7]],"bdatl":[[9,2.48,12.64]],"id":9570503}]}]}
{"op":"mcm","clk":"AJRaAP8wAO1P","pt":1659347567966,"mc":[{"id":"1.201590187","rc":[{"atl":[[34,1]],"id":44621159}]}]}
