{"op":"mcm","clk":"AN60AQD/WQDinwE=","pt":1659347744517,"mc":[{"id":"1.201590187","rc":[{"bdatb":[[4,10,17.94],[6,9.6,21.47]],"bdatl":[[9,22,4.5]],"id":45323444},{"bdatb":[[3,2.04,9.33],[4,2.02,43.55],[7,1.98,79.09],[9,1.96,3.72]],"bdatl":[[2,2.18,14.25],[6,2.28,9.6],[7,2.3,2.76],[8,2.32,10.16],[9,2.34,1.03]],"id":9570503},{"bdatb":[[0,6.8,1.55],[1,6.6,4.92],[2,6.4,16.54],[3,6.2,6.62],[4,6,1.76],[5,5.9,1.76],[6,5.8,38.25],[7,5.7,223.76],[8,5.6,2.57],[9,5.5,1.87]],"bdatl":[[0,7.2,1.15],[1,7.4,17.23],[2,7.6,26.3],[3,7.8,12.92],[4,8,1.76],[5,8.2,1.76],[6,8.4,4],[7,8.6,1.77],[8,8.8,1.76],[9,9,8.69]],"id":12989514},{"bdatb":[[5,20,2.18],[8,18.5,2.79],[9,15,1.14]],"bdatl":[[5,900,1.21]],"id":44621159},{"bdatb":[[1,7,2.67],[2,6.8,18.54],[3,6.6,7.16],[4,6.4,3.06],[5,6.2,26.06],[6,6,218],[7,5.9,11.89],[8,5.8,10],[9,5.7,97.05]],"bdatl":[[1,7.8,9.55]],"id":44836671},{"bdatb":[[2,9,4.31],[3,8.8,2.94],[4,8.6,20.88],[5,8.4,2.75],[6,8.2,3.97],[7,8,1.46],[8,7.8,1.76],[9,7.6,1.76]],"bdatl":[[0,10.5,2.57],[9,15,12.7]],"id":43885158}]}]}
{"op":"mcm","clk":"AOe0AQCDWgDonwE=","pt":1659347744657,"mc":[{"id":"1.201590187","rc":[{"atl":[[7.4,17.85]],"id":12989514},{"atl":[[10.5,1.42]],"id":43885158},{"atl":[[23,0.22]],"id":46969227}]}]}
{"op":"mcm","clk":"AOm0AQCDWgDtnwE=","pt":1659347744707,"mc":[{"id":"1.201590187","rc":[{"bdatb":[[4,10,16.07],[5,9.8,9.68],[6,9.6,21],[7,9.4,56.34]],"id":45323444},{"bdatb":[[3,2.04,7.76],[4,2.02,45.14],[7,1.98,70.48],[8,1.97,5.05],[9,1.96,2.62]],"id":9570503},{"bdatb":[[3,6.2,5.84],[4,6,2.58],[6,5.8,35.31],[7,5.7,224.64],[8,5.6,4.3],[9,5.5,2.3]],"bdatl":[[1,7.4,17.85]],"id":12989514},{"bdatb":[[5,20,2.02],[6,19.5,1.93],[8,18.5,2.7],[9,14,1.44]],"id":44621159},{"bdatb":[[7,5.9,9],[8,5.8,10.86],[9,5.7,98.76]],"id":44836671},{"bdatb":[[6,8.2,3.76],[7,8,1.67]],"bdatl":[[0,10.5,1.42]],"id":43885158},{"bdatl":[[0,24,5.44],[1,25,1.48],[2,26,6.1],[3,27,1.86],[4,28,7.55],[5,29,1.76],[6,30,5.28],[7,32,1.76],[8,34,5],[9,36,1.76]],"id":46969227}]}]}
{"op":"mcm","clk":"AIa1AQCVWgCMoAE=","pt":1659347745276,"mc":[{"id":"1.201590187","rc":[{"atb":[[2.1,7.56]],"trd":[[2.1,120.85]],"tv":1111.17,"id":9570503}],"tv":1947.71}]}
{"op":"mcm","clk":"AIi1AQCWWgCOoAE=","pt":1659347745326,"mc":[{"id":"1.201590187","rc":[{"bdatb":[[0,2.1,7.56]],"id":9570503},{"bdatl":[[9,9,8.58]],"id":12989514}]}]}
{"op":"mcm","clk":"AMK1AQCyWgC2oAE=","pt":1659347746164,"mc":[{"id":"1.201590187","rc":[{"atb":[[25,2.33]],"atl":[[36,2]],"id":44621159}]}]}
{"op":"mcm","clk":"AMm1AQCzWgC5oAE=","pt":1659347746214,"mc":[{"id":"1.201590187","rc":[{"bdatb":[[7,9.4,59.84],[8,9.2,12],[9,9,13.28]],"id":45323444},{"bdatb":[[0,25,2.33]],"bdatl":[[0,36,2]],"id":44621159}]}]}
{"op":"mcm","clk":"ANa1AQC4WgC+oAE=","pt":1659347746387,"mc":[{"id":"1.201590187","rc":[{"atb":[[10,12.37]],"id":45323444},{"atl":[[55,0]],"id":44621159}]}]}
{"op":"mcm","clk":"ANa1AQC4WgC/oAE=","pt":1659347746437,"mc":[{"id":"1.201590187","rc":[{"bdatb":[[4,10,13.2]],"id":45323444},{"bdatl":[[3,80,2.32]],"id":44621159}]}]}
{"op":"mcm","clk":"ANe1AQC5WgDDoAE=","pt":1659347746487,"mc":[{"id":"1.201590187","rc":[{"atb":[[10.5,10.71]],"id":45323444},{"atb":[[2.04,9.26]],"atl":[[2.18,18.09]],"id":9570503},{"atb":[[6.4,18.95]],"atl":[[7.4,20.11]],"id":12989514},{"atl":[[50,0.64]],"id":44621159},{"atb":[[7,4.93]],"atl":[[7.8,11.82]],"id":44836671},{"atb":[[8.8,5.11]],"id":43885158}]}]}
{"op":"mcm","clk":"ANy1AQC5WgDKoAE=","pt":1659347746538,"mc":[{"id":"1.201590187","rc":[{"bdatb":[[3,10.5,10.71]],"id":45323444},{"bdatb":[[3,2.04,11.74]],"bdatl":[[2,2.18,18.09]],"id":9570503},{"bdatb":[[2,6.4,18.95]],"bdatl":[[1,7.4,20.11]],"id":12989514},{"bdatl":[[3,80,2.96]],"id":44621159},{"bdatb":[[1,7,4.93]],"bdatl":[[1,7.8,11.82]],"id":44836671},{"bdatb":[[3,8.8,5.11]],"id":43885158}]}]}
{"op":"mcm","clk":"AN+1AQC8WgDLoAE=","pt":1659347746588,"mc":[{"id":"1.201590187","rc":[{"atb":[[2.1,20.96]],"id":9570503},{"atb":[[8.2,5.8]],"id":43885158}]}]}
{"op":"mcm","clk":"AOO1AQDBWgDNoAE=","pt":1659347746638,"mc":[{"id":"1.201590187","rc":[{"bdatb":[[0,2.1,20.96]],"id":9570503},{"bdatl":[[9,9,8.69]],"id":12989514},{"bdatb":[[6,8.2,5.8]],"id":43885158}]}]}
{"op":"mcm","clk":"AOm1AQDCWgDPoAE=","pt":1659347746690,"mc":[{"id":"1.201590187","rc":[{"atb":[[2.1,13.4]],"id":9570503},{"atb":[[6.6,11.36]],"id":12989514},{"atb":[[8.2,3.8]],"id":43885158}]}]}
{"op":"mcm","clk":"AOu1AQDDWgDToAE=","pt":1659347746740,"mc":[{"id":"1.201590187","rc":[{"bdatb":[[0,2.1,13.4]],"id":9570503},{"bdatb":[[1,6.6,11.36]],"id":12989514},{"bdatb":[[6,8.2,3.8]],"id":43885158}]}]}
{"op":"mcm","clk":"AIO2AQDWWgDgoAE=","pt":1659347747156,"mc":[{"id":"1.201590187","rc":[{"atb":[[18,1.76]],"id":44621159}]}]}
{"op":"mcm","clk":"AIa2AQDWWgDioAE=","pt":1659347747206,"mc":[{"id":"1.201590187","rc":[{"bdatb":[[9,18,1.86]],"id":44621159}]}]}
{"op":"mcm","clk":"AN+2AQCAWwChoQE=","pt":1659347748563,"mc":[{"id":"1.201590187","rc":[{"atl":[[38,1.61]],"id":44621159}]}]}
{"op":"mcm","clk":"AOC2AQCAWwCjoQE=","pt":1659347748613,"mc":[{"id":"1.201590187","rc":[{"bdatl":[[1,38,1.61]],"id":44621159}]}]}
{"op":"mcm","clk":"AOW2AQCDWwCjoQE=","pt":1659347748669,"mc":[{"id":"1.201590187","rc":[{"atl":[[2.12,2.16]],"id":9570503}]}]}
{"op":"mcm","clk":"AOi2AQCDWwCooQE=","pt":1659347748719,"mc":[{"id":"1.201590187","rc":[{"bdatb":[[3,10.5,11.15],[4,10,12.74],[7,9.4,60.17],[8,9.2,12.16],[9,9,13]],"id":45323444},{"bdatl":[[0,2.12,2.16],[1,2.14,32.19],[2,2.16,1.18],[3,2.18,18.09],[4,2.22,4],[5,2.24,7],[6,2.26,7.02],[7,2.28,9.6],[8,2.3,2.76],[9,2.32,10.16]],"id":9570503},{"bdatb":[[2,6.4,19.67],[3,6.2,5.1]],"id":12989514},{"bdatb":[[3,22,1.97],[5,20,1.79]],"id":44621159},{"bdatb":[[3,6.6,7.85],[4,6.4,2.34]],"id":44836671},{"bdatb":[[3,8.8,5.63],[5,8.4,2.2]],"id":43885158},{"bdatb":[[8,16,1.71]],"id":46969227}]}]}
{"op":"mcm","clk":"APC2AQCFWwCsoQE=","pt":1659347748783,"mc":[{"id":"1.201590187","rc":[{"atl":[[2.12,0]],"trd":[[2.12,198.66]],"ltp":2.12,"tv":1115.5,"id":9570503}],"tv":1952.04}]}
{"op":"mcm","clk":"APG2AQCFWwCtoQE=","pt":1659347748833,"mc":[{"id":"1.201590187","rc":[{"bdatb":[[3,10.5,10.71],[4,10,13.2],[7,9.4,59.84],[8,9.2,12],[9,9,13.28]],"id":45323444},{"bdatl":[[0,2.14,32.19],[1,2.16,1.18],[2,2.18,18.09],[3,2.22,4],[4,2.24,7],[5,2.26,7.02],[6,2.28,9.6],[7,2.3,2.76],[8,2.32,10.16],[9,2.34,1.03]],"id":9570503},{"bdatb":[[2,6.4,18.95],[3,6.2,5.84]],"id":12989514},{"bdatb":[[3,22,1.76],[5,20,2.02]],"id":44621159},{"bdatb":[[3,6.6,7.16],[4,6.4,3.06]],"id":44836671},{"bdatb":[[3,8.8,5.11],[5,8.4,2.75]],"id":43885158},{"bdatb":[[8,16,1.43]],"id":46969227}]}]}
{"op":"mcm","clk":"AKS3AQCUWwDNoQE=","pt":1659347749539,"mc":[{"id":"1.201590187","rc":[{"atb":[[25,1.33]],"atl":[[36,1]],"id":44621159}]}]}
{"op":"mcm","clk":"AKu3AQCZWwDOoQE=","pt":1659347749589,"mc":[{"id":"1.201590187","rc":[{"bdatb":[[7,9.4,56.34],[8,9.2,15.57],[9,9,13]],"id":45323444},{"bdatb":[[0,25,1.33]],"bdatl":[[0,36,1]],"id":44621159}]}]}
{"op":"mcm","clk":"AOu3AQDDWwCIogE=","pt":1659347750692,"mc":[{"id":"1.201590187","rc":[{"atb":[[2.06,35.07]],"id":9570503},{"atb":[[11,17.24]],"id":44621159},{"atb":[[8.8,34.48]],"id":46969227}]}]}
{"op":"mcm","clk":"AO+3AQDEWwCOogE=","pt":1659347750743,"mc":[{"id":"1.201590187","rc":[{"bdatb":[[2,2.06,35.07]],"id":9570503}]}]}
{"op":"mcm","clk":"AIi4AQDTWwCpogE=","pt":1659347751068,"mc":[{"id":"1.201590187","rc":[{"atb":[[10,1.15]],"atl":[[10.5,2.57]],"id":43885158},{"atl":[[23,1.37]],"id":46969227}]}]}
{"op":"mcm","clk":"AIu4AQDTWwCvogE=","pt":1659347751118,"mc":[{"id":"1.201590187","rc":[{"bdatb":[[4,10,15.07],[5,9.8,9],[6,9.6,21.47],[7,9.4,54.58]],"bdatl":[[6,19.5,1.77],[8,21,2.26],[9,22,4.02]],"id":45323444},{"bdatb":[[3,2.04,13.32],[4,2.02,43.55],[7,1.98,79.09],[8,1.97,2.53],[9,1.96,3.72]],"bdatl":[[4,2.24,7.02],[5,2.26,11.64],[6,2.28,5.42],[7,2.3,2.34]],"id":9570503},{"bdatb":[[3,6.2,6.62],[4,6,1.76],[6,5.8,38.25],[7,5.7,223.76],[8,5.6,2.57],[9,5.5,1.87]],"bdatl":[[8,8.8,3.07],[9,9,7.42]],"id":12989514},{"bdatb":[[5,20,2.18],[6,19.5,1.76],[8,18.5,2.79],[9,18,1.76]],"bdatl":[[4,170,2.08],[5,900,1.15]],"id":44621159},{"bdatb":[[7,5.9,11.89],[8,5.8,10],[9,5.7,97.05]],"bdatl":[[9,9.4,2.88]],"id":44836671},{"bdatb":[[0,10,1.15],[1,9.8,8.8],[2,9.2,4.76],[3,9,4.31],[4,8.8,5.11],[5,8.6,20.88],[6,8.4,2.75],[7,8.2,4.01],[8,8,1.46],[9,7.8,1.76]],"bdatl":[[0,10.5,2.57]],"id":43885158},{"bdatl":[[0,23,1.37],[1,24,5.22],[2,25,1.48],[3,26,6.1],[4,27,1.86],[5,28,7.55],[6,29,1.76],[7,30,5.28],[8,32,1.76],[9,34,5]],"id":46969227}]}]}
{"op":"mcm","clk":"AJK4AQDUWwCyogE=","pt":1659347751178,"mc":[{"id":"1.201590187","rc":[{"atb":[[6.8,0.4]],"atl":[[7.2,0]],"id":12989514},{"atb":[[9.8,9.25]],"atl":[[10.5,1.42]],"id":43885158}]}]}
{"op":"mcm","clk":"AJO4AQDUWwC2ogE=","pt":1659347751228,"mc":[{"id":"1.201590187","rc":[{"bdatb":[[4,10,13.86],[6,9.6,22.73]],"bdatl":[[8,21,1.89]],"id":45323444},{"bdatb":[[3,2.04,9.26],[4,2.02,47.65],[7,1.98,72.99],[9,1.96,9.88]],"bdatl":[[5,2.26,8.18],[6,2.28,8.85]],"id":9570503},{"bdatb":[[0,6.6,11.76],[1,6.4,18.95],[2,6.2,6.62],[3,6,1.76],[4,5.9,1.76],[5,5.8,36.17],[6,5.7,223.76],[7,5.6,4.73],[8,5.5,1.87],[9,5.4,8.58]],"bdatl":[[0,7.4,20.11],[1,7.6,26.3],[2,7.8,12.92],[3,8,1.76],[4,8.2,1.76],[5,8.4,4],[6,8.6,1.77],[7,8.8,3.07],[8,9,7.42],[9,9.2,2.99]],"id":12989514},{"bdatb":[[5,20,1.76],[8,18.5,3.23]],"bdatl":[[4,170,2.02],[5,900,1.18]],"id":44621159},{"bdatb":[[4,6.4,1.76],[5,6.2,27.39],[7,5.9,9.84],[9,5.7,99.17]],"bdatl":[[9,9.4,2.05]],"id":44836671},{"bdatb":[[1,9.8,9.25],[6,8.4,1.76],[7,8.2,5.01]],"bdatl":[[0,10.5,1.42],[9,15,12.18]],"id":43885158}]}]}
{"op":"mcm","clk":"AK64AQDjWwDKogE=","pt":1659347751594,"mc":[{"id":"1.201590187","rc":[{"atl":[[13,1.76],[12.5,13.48]],"id":43885158},{"atl":[[30,1.83]],"id":46969227}]}]}
{"op":"mcm","clk":"ALS4AQDkWwDLogE=","pt":1659347751644,"mc":[{"id":"1.201590187","rc":[{"bdatl":[[4,12.5,13.48],[5,13,1.76]],"id":43885158},{"bdatl":[[7,30,1.83]],"id":46969227}]}]}
{"op":"mcm","clk":"ALW4AQDlWwDPogE=","pt":1659347751694,"mc":[{"id":"1.201590187","rc":[{"atl":[[29,5.33]],"id":46969227}]}]}
{"op":"mcm","clk":"ALe4AQDlWwDTogE=","pt":1659347751744,"mc":[{"id":"1.201590187","rc":[{"bdatl":[[6,29,5.33]],"id":46969227}]}]}
{"op":"mcm","clk":"ANy4AQD6WwDuogE=","pt":1659347752165,"mc":[{"id":"1.201590187","rc":[{"atb":[[9.4,11],[7.8,0],[8.2,11.39]],"id":45323444}]}]}
{"op":"mcm","clk":"AN24AQD6WwDyogE=","pt":1659347752215,"mc":[{"id":"1.201590187","rc":[{"bdatb":[[7,9.4,11.48]],"id":45323444}]}]}
{"op":"mcm","clk":"AOW4AQD8WwD1ogE=","pt":1659347752268,"mc":[{"id":"1.201590187","rc":[{"atb":[[1.75,0]],"id":9570503}]}]}
{"op":"mcm","clk":"AOy4AQD+WwD7ogE=","pt":1659347752366,"mc":[{"id":"1.201590187","rc":[{"atl":[[38,0.46]],"id":44621159}]}]}
{"op":"mcm","clk":"AO64AQD+WwCDowE=","pt":1659347752416,"mc":[{"id":"1.201590187","rc":[{"bdatb":[[9,5.4,5.95]],"id":12989514},{"bdatl":[[1,40,3.73],[2,80,2.96],[3,170,2.02],[4,900,1.18],[5,990,1.83],[6,1000,2],[7,0,0]],"id":44621159}]}]}
{"op":"mcm","clk":"APS4AQCAXACGowE=","pt":1659347752472,"mc":[{"id":"1.201590187","rc":[{"atb":[[6.6,4.92]],"id":12989514}]}]}
{"op":"mcm","clk":"APW4AQCBXACJowE=","pt":1659347752522,"mc":[{"id":"1.201590187","rc":[{"bdatl":[[8,2.32,7.89],[9,2.34,2.25]],"id":9570503},{"bdatb":[[0,6.6,5.32]],"id":12989514}]}]}
{"op":"mcm","clk":"AI65AQCNXAChowE=","pt":1659347752900,"mc":[{"id":"1.201590187","rc":[{"atb":[[8.8,31.24]],"id":45323444},{"atb":[[11.5,14.37]],"atl":[[50,0]],"id":44621159}]}]}
{"op":"mcm","clk":"AJO5AQCPXACjowE=","pt":1659347752950,"mc":[{"id":"1.201590187","rc":[{"bdatl":[[2,80,2.32]],"id":44621159}]}]}
{"op":"mcm","clk":"AJq5AQCQXAClowE=","pt":1659347753000,"mc":[{"id":"1.201590187","rc":[{"atb":[[1.74,17.24]],"id":9570503},{"atl":[[55,0.64]],"id":44621159}]}]}
{"op":"mcm","clk":"AKG5AQCSXACpowE=","pt":1659347753051,"mc":[{"id":"1.201590187","rc":[{"bdatl":[[2,80,2.96]],"id":44621159}]}]}
{"op":"mcm","clk":"ALC5AQCaXAC3owE=","pt":1659347753253,"mc":[{"id":"1.201590187","rc":[{"atb":[[8.8,45.97]],"id":46969227}]}]}
{"op":"mcm","clk":"ALm5AQCeXAC9owE=","pt":1659347753354,"mc":[{"id":"1.201590187","rc":[{"atb":[[2,1.68]],"id":12989514}]}]}
{"op":"mcm","clk":"AOK5AQCuXADrowE=","pt":1659347754079,"mc":[{"id":"1.201590187","rc":[{"atb":[[9.2,1.76]],"id":43885158}]}]}
{"op":"mcm","clk":"AOO5AQCuXADtowE=","pt":1659347754129,"mc":[{"id":"1.201590187","rc":[{"bdatb":[[2,9.2,1.76]],"id":43885158}]}]}
{"op":"mcm","clk":"APW5AQC4XAD7owE=","pt":1659347754401,"mc":[{"id":"1.201590187","rc":[{"atl":[[2.12,5]],"id":9570503}]}]}
{"op":"mcm","clk":"AP65AQDHXACTpAE=","pt":1659347754451,"mc":[{"id":"1.201590187","rc":[{"bdatb":[[3,10.5,11.72],[4,10,12.8],[8,9.2,16.73]],"id":45323444},{"bdatl":[[0,2.12,5],[1,2.14,32.19],[2,2.16,1.18],[3,2.18,18.09],[4,2.22,4],[5,2.24,7.02],[6,2.26,8.18],[7,2.28,8.85],[8,2.3,2.34],[9,2.32,7.89]],"id":9570503},{"bdatb":[[1,6.4,20.5],[2,6.2,5.02],[4,5.9,1.88],[5,5.8,36.05]],"id":12989514},{"bdatb":[[5,20,2.26],[8,18.5,2.7]],"id":44621159},{"bdatb":[[4,6.4,3.32],[5,6.2,25.79],[6,6,218.11],[7,5.9,9.73]],"id":44836671},{"bdatb":[[5,8.6,22.04],[7,8.2,3.8],[9,7.8,1.85]],"id":43885158},{"bdatb":[[9,15.5,2.4]],"id":46969227}]}]}
{"op":"mcm","clk":"AI+6AQDMXACYpAE=","pt":1659347754553,"mc":[{"id":"1.201590187","rc":[{"atl":[[2.12,0]],"trd":[[2.12,208.66]],"tv":1125.5,"id":9570503}],"tv":1962.04}]}
{"op":"mcm","clk":"AJK6AQDMXACapAE=","pt":1659347754603,"mc":[{"id":"1.201590187","rc":[{"bdatb":[[3,10.5,10.71],[4,10,13.86],[8,9.2,15.57]],"id":45323444},{"bdatl":[[0,2.14,32.19],[1,2.16,1.18],[2,2.18,18.09],[3,2.22,4],[4,2.24,7.02],[5,2.26,8.18],[6,2.28,8.85],[7,2.3,2.34],[8,2.32,7.89],[9,2.34,2.25]],"id":9570503},{"bdatb":[[1,6.4,18.95],[2,6.2,6.62],[4,5.9,1.76],[5,5.8,36.17]],"id":12989514},{"bdatb":[[5,20,1.76],[8,18.5,3.23]],"id":44621159},{"bdatb":[[4,6.4,1.76],[5,6.2,27.39],[6,6,218],[7,5.9,9.84]],"id":44836671},{"bdatb":[[5,8.6,20.88],[7,8.2,5.01],[9,7.8,1.76]],"id":43885158},{"bdatb":[[9,15.5,1.76]],"id":46969227}]}]}
{"op":"mcm","clk":"AJ66AQDTXACkpAE=","pt":1659347754762,"mc":[{"id":"1.201590187","rc":[{"atb":[[10,0]],"trd":[[10,6.3]],"ltp":10,"tv":199.39,"id":43885158}],"tv":1964.34}]}
{"op":"mcm","clk":"AJ+6AQDUXACopAE=","pt":1659347754812,"mc":[{"id":"1.201590187","rc":[{"bdatl":[[6,19.5,1.76],[8,21,1.77],[9,22,4.14]],"id":45323444},{"bdatl":[[4,2.24,7],[5,2.26,7.02],[6,2.28,6.17],[7,2.3,6.16]],"id":9570503},{"bdatl":[[7,8.8,1.76],[8,9,8.69]],"id":12989514},{"bdatl":[[3,170,2],[4,900,1.17]],"id":44621159},{"bdatl":[[9,9.4,1.76]],"id":44836671},{"bdatb":[[0,9.8,9.25],[1,9.2,1.76],[2,9,4.31],[3,8.8,5.11],[4,8.6,20.88],[5,8.4,1.76],[6,8.2,5.01],[7,8,1.46],[8,7.8,1.76],[9,7.6,1.76]],"id":43885158}]}]}
{"op":"mcm","clk":"AMW6AQDiXADIpAE=","pt":1659347755385,"mc":[{"id":"1.201590187","rc":[{"atl":[[22,2.58]],"id":45323444},{"atb":[[2.1,6.79]],"trd":[[2.1,134.06]],"ltp":2.1,"tv":1138.71,"id":9570503},{"atl":[[7.6,46.12]],"trd":[[7.6,211.34]],"ltp":7.6,"tv":455.97,"id":44836671},{"atb":[[1.8,2.88]],"id":43885158}],"tv":2046.5}]}
{"op":"mcm","clk":"AMe6AQDiXADMpAE=","pt":1659347755435,"mc":[{"id":"1.201590187","rc":[{"bdatl":[[9,22,2.7]],"id":45323444},{"bdatb":[[0,2.1,6.79]],"id":9570503},{"bdatl":[[8,9,8.4],[9,9.2,1.76]],"id":12989514},{"bdatl":[[0,7.6,46.12]],"id":44836671}]}]}
{"op":"mcm","clk":"AM+6AQDkXADNpAE=","pt":1659347755488,"mc":[{"id":"1.201590187","rc":[{"atl":[[21,3.2]],"id":45323444}]}]}
{"op":"mcm","clk":"AM+6AQDkXADQpAE=","pt":1659347755538,"mc":[{"id":"1.201590187","rc":[{"bdatl":[[8,21,3.2]],"id":45323444}]}]}
{"op":"mcm","clk":"ANS6AQDpXADRpAE=","pt":1659347755588,"mc":[{"id":"1.201590187","rc":[{"atb":[[9.8,8.8]],"id":43885158}]}]}
{"op":"mcm","clk":"ANW6AQDrXADVpAE=","pt":1659347755638,"mc":[{"id":"1.201590187","rc":[{"bdatb":[[0,9.8,8.8]],"id":43885158}]}]}
{"op":"mcm","clk":"AOG6AQDxXADbpAE=","pt":1659347755788,"mc":[{"id":"1.201590187","rc":[{"atb":[[1.8,0.01]],"id":43885158}]}]}
{"op":"mcm","clk":"AOq6AQD1XADkpAE=","pt":1659347755889,"mc":[{"id":"1.201590187","rc":[{"atl":[[21,1.76]],"id":45323444}]}]}
{"op":"mcm","clk":"AOq6AQD4XADlpAE=","pt":1659347755939,"mc":[{"id":"1.201590187","rc":[{"bdatl":[[8,21,1.77]],"id":45323444}]}]}
{"op":"mcm","clk":"APC6AQD9XADopAE=","pt":1659347755997,"mc":[{"id":"1.201590187","rc":[{"atl":[[22,4.02]],"id":45323444}]}]}
{"op":"mcm","clk":"APG6AQD/XADqpAE=","pt":1659347756047,"mc":[{"id":"1.201590187","rc":[{"bdatl":[[9,22,4.14]],"id":45323444}]}]}
{"op":"mcm","clk":"APm6AQCAXQDxpAE=","pt":1659347756097,"mc":[{"id":"1.201590187","rc":[{"atb":[[1.8,2.88]],"id":44836671}]}]}
{"op":"mcm","clk":"AP66AQCCXQD0pAE=","pt":1659347756203,"mc":[{"id":"1.201590187","rc":[{"atb":[[1.8,0]],"id":43885158}]}]}
{"op":"mcm","clk":"AIa7AQCFXQD7pAE=","pt":1659347756267,"mc":[{"id":"1.201590187","rc":[{"atl":[[10.5,1.41]],"trd":[[10.5,0.84]],"ltp":10.5,"tv":199.41,"id":43885158}],"tv":2046.52}]}
{"op":"mcm","clk":"AIi7AQCFXQD/pAE=","pt":1659347756317,"mc":[{"id":"1.201590187","rc":[{"bdatb":[[4,10,13.85],[6,9.6,22.74]],"id":45323444},{"bdatb":[[7,1.98,72.94],[9,1.96,9.93]],"id":9570503},{"bdatb":[[5,5.8,36.15],[7,5.6,4.75]],"id":12989514},{"bdatb":[[7,5.9,9.83],[9,5.7,99.19]],"id":44836671},{"bdatl":[[0,10.5,1.41]],"id":43885158}]}]}
{"op":"mcm","clk":"AKS7AQCXXQCdpQE=","pt":1659347756487,"mc":[{"id":"1.201590187","rc":[{"atb":[[1.8,0.01]],"id":44836671}]}]}
{"op":"mcm","clk":"AK+7AQCbXQCnpQE=","pt":1659347756687,"mc":[{"id":"1.201590187","rc":[{"atb":[[2.1,0],[2.12,12.16]],"id":9570503},{"atb":[[8.4,3.76],[8.2,1.76]],"id":43885158}]}]}
{"op":"mcm","clk":"ALC7AQCbXQCspQE=","pt":1659347756737,"mc":[{"id":"1.201590187","rc":[{"bdatl":[[4,18.5,1.77],[7,20,1.9],[8,21,1.76],[9,22,5.07]],"id":45323444},{"bdatb":[[0,2.12,12.16]],"id":9570503},{"bdatl":[[6,8.6,3.72],[7,8.8,2.78],[8,9,6.82]],"id":12989514},{"bdatl":[[3,170,2.03],[4,670,1],[5,990,2.07]],"id":44621159},{"bdatl":[[8,9.2,8.3]],"id":44836671},{"bdatb":[[5,8.4,3.76],[6,8.2,2.97]],"bdatl":[[6,13.5,9.77],[7,14,13.39],[9,15,12.94]],"id":43885158}]}]}
{"op":"mcm","clk":"ALu7AQCiXQC0pQE=","pt":1659347756885,"mc":[{"id":"1.201590187","rc":[{"atb":[[2.02,41.53]],"atl":[[2.26,0],[2.28,0],[2.22,0],[2.24,0]],"id":9570503},{"atl":[[7.8,20.92]],"id":12989514},{"atb":[[1.8,0]],"id":44836671}]}]}
{"op":"mcm","clk":"AL27AQCiXQC3pQE=","pt":1659347756935,"mc":[{"id":"1.201590187","rc":[{"bdatb":[[4,2.02,46.45]],"bdatl":[[3,2.28,1.19],[4,2.3,6.16],[5,2.32,7.89],[6,2.34,2.25],[7,2.36,1.02],[8,2.38,5.67],[9,2.42,12.34]],"id":9570503},{"bdatl":[[2,7.8,20.92]],"id":12989514}]}]}
{"op":"mcm","clk":"AMS7AQClXQC6pQE=","pt":1659347756996,"mc":[{"id":"1.201590187","rc":[{"atl":[[7.6,46.11]],"trd":[[7.6,211.36]],"tv":455.99,"id":44836671}],"tv":2046.54}]}
{"op":"mcm","clk":"AMa7AQClXQC7pQE=","pt":1659347757047,"mc":[{"id":"1.201590187","rc":[{"bdatl":[[0,7.6,46.11]],"id":44836671}]}]}
{"op":"mcm","clk":"AM27AQCnXQDApQE=","pt":1659347757097,"mc":[{"id":"1.201590187","rc":[{"atb":[[20,0],[19.5,0]],"trd":[[20,7.17],[19.5,2.78]],"ltp":19.5,"tv":55.72,"id":46969227}],"tv":2056.35}]}
{"op":"mcm","clk":"AM67AQCpXQDCpQE=","pt":1659347757147,"mc":[{"id":"1.201590187","rc":[{"bdatl":[[4,18.5,1.76],[6,19.5,1.77],[7,20,1.76],[8,21,1.89],[9,22,4.02]],"id":45323444},{"bdatl":[[5,2.32,7.02],[6,2.36,3.09],[7,2.38,1.01],[8,2.4,5.62]],"id":9570503},{"bdatl":[[6,8.6,1.77],[7,8.8,3.68],[8,9,7.81]],"id":12989514},{"bdatl":[[3,170,2.02],[4,900,1.18],[5,990,1.83]],"id":44621159},{"bdatl":[[8,9.2,8],[9,9.4,2.05]],"id":44836671},{"bdatl":[[6,13.5,9.76],[7,14,13.2],[8,14.5,14.06],[9,15,12]],"id":43885158},{"bdatb":[[0,19,7.2],[1,18.5,8],[2,18,5],[3,17.5,7.76],[4,17,1.76],[5,16.5,1.76],[6,16,1.43],[7,15.5,1.76],[8,15,1.76],[9,14.5,2.45]],"id":46969227}]}]}
{"op":"mcm","clk":"ANm7AQCvXQDIpQE=","pt":1659347757288,"mc":[{"id":"1.201590187","rc":[{"atb":[[19,2.46],[18.5,0],[16.5,5.76]],"id":46969227}]}]}
{"op":"mcm","clk":"ANy7AQCvXQDKpQE=","pt":1659347757338,"mc":[{"id":"1.201590187","rc":[{"bdatl":[[8,2.4,1.57],[9,2.42,4.01]],"id":9570503},{"bdatb":[[0,19,2.46],[1,18,5],[2,17.5,7.76],[3,17,1.76],[4,16.5,5.76],[5,16,1.43],[6,15.5,1.76],[7,15,1.76],[8,14.5,2.45],[9,11.5,9.72]],"id":46969227}]}]}
{"op":"mcm","clk":"AOi7AQC1XQDVpQE=","pt":1659347757464,"mc":[{"id":"1.201590187","rc":[{"atb":[[2.08,17.18]],"id":9570503},{"atb":[[19,2.2]],"id":46969227}]}]}
{"op":"mcm","clk":"AOm7AQC2XQDVpQE=","pt":1659347757514,"mc":[{"id":"1.201590187","rc":[{"bdatb":[[1,2.08,17.18]],"bdatl":[[7,2.4,1.01],[8,2.42,5.58],[9,2.44,12.24]],"id":9570503},{"bdatb":[[0,19,2.2]],"id":46969227}]}]}
{"op":"mcm","clk":"AO67AQC4XQDYpQE=","pt":1659347757564,"mc":[{"id":"1.201590187","rc":[{"atb":[[6.8,1.55],[2,1.7]],"atl":[[7.2,1.15]],"id":12989514},{"atl":[[10.5,2.56]],"id":43885158}]}]}
{"op":"mcm","clk":"AO+7AQC4XQDYpQE=","pt":1659347757614,"mc":[{"id":"1.201590187","rc":[{"bdatb":[[4,10,15.06],[6,9.6,21.48]],"bdatl":[[8,21,2.26]],"id":45323444},{"bdatb":[[3,2.04,13.32],[4,2.02,42.35],[7,1.98,79.03],[9,1.96,3.77]],"bdatl":[[3,2.28,4.62],[4,2.3,2.76],[6,2.34,3.11],[7,2.38,1.02]],"id":9570503},{"bdatb":[[0,6.8,1.55],[1,6.6,4.92],[2,6.4,18.95],[3,6.2,6.62],[4,6,1.76],[5,5.9,1.76],[6,5.8,38.23],[7,5.7,223.76],[8,5.6,2.59],[9,5.5,1.87]],"bdatl":[[0,7.2,1.15],[1,7.4,20.11],[2,7.6,26.3],[3,7.8,20.92],[4,8,1.76],[5,8.2,1.76],[6,8.4,4],[7,8.6,1.77],[8,8.8,3.68],[9,9,7.81]],"id":12989514},{"bdatb":[[5,20,2.18],[8,18.5,2.79]],"bdatl":[[3,170,2.07],[4,900,1.16]],"id":44621159},{"bdatb":[[4,6.4,3.06],[5,6.2,26.06],[7,5.9,11.87],[9,5.7,97.07]],"bdatl":[[9,9.4,2.88]],"id":44836671},{"bdatb":[[5,8.4,4.75],[6,8.2,1.97]],"bdatl":[[0,10.5,2.56],[8,14.5,14.6]],"id":43885158},{"bdatb":[[7,15,2.32],[8,14.5,1.88],[9,12,1.41]],"id":46969227}]}]}
{"op":"mcm","clk":"APW7AQC6XQDapQE=","pt":1659347757666,"mc":[{"id":"1.201590187","rc":[{"atl":[[38,2.22]],"id":44621159},{"atl":[[10.5,1.41]],"id":43885158},{"atb":[[14,1.76]],"atl":[[23,0.22]],"id":46969227}]}]}
{"op":"mcm","clk":"APa7AQC6XQDepQE=","pt":1659347757716,"mc":[{"id":"1.201590187","rc":[{"bdatb":[[4,10,13.2],[5,9.8,9.67],[6,9.6,21],[7,9.4,13.26]],"id":45323444},{"bdatb":[[3,2.04,11.74],[4,2.02,43.94],[7,1.98,70.48],[8,1.97,5],[9,1.96,2.62]],"id":9570503},{"bdatb":[[3,6.2,5.84],[4,6,2.58],[6,5.8,35.31],[7,5.7,224.62],[8,5.6,4.32],[9,5.5,2.3]],"id":12989514},{"bdatb":[[5,20,2.02],[6,19.5,1.93],[8,18.5,2.7],[9,18,1.86]],"bdatl":[[1,38,2.22],[2,40,3.27],[3,80,2.96],[4,170,2.07],[5,900,1.16],[6,990,1.83],[7,1000,2]],"id":44621159},{"bdatb":[[7,5.9,9],[8,5.8,10.84],[9,5.7,98.78]],"id":44836671},{"bdatb":[[6,8.2,1.76],[7,8,1.67]],"bdatl":[[0,10.5,1.41]],"id":43885158},{"bdatb":[[9,14,1.76]],"bdatl":[[0,24,5.44],[1,25,1.48],[2,26,6.1],[3,27,1.86],[4,28,7.55],[5,29,5.33],[6,30,1.83],[7,32,1.76],[8,34,5],[9,36,1.76]],"id":46969227}]}]}
{"op":"mcm","clk":"AIK8AQDAXQDmpQE=","pt":1659347757866,"mc":[{"id":"1.201590187","rc":[{"atb":[[8.8,39.86]],"id":45323444}]}]}
{"op":"mcm","clk":"AIa8AQDEXQDopQE=","pt":1659347757967,"mc":[{"id":"1.201590187","rc":[{"atb":[[1.74,34.48]],"id":9570503}]}]}
{"op":"mcm","clk":"AJG8AQDIXQDvpQE=","pt":1659347758072,"mc":[{"id":"1.201590187","rc":[{"atl":[[23,1.37]],"id":46969227}]}]}
{"op":"mcm","clk":"AJG8AQDIXQDxpQE=","pt":1659347758122,"mc":[{"id":"1.201590187","rc":[{"bdatb":[[4,10,13.85],[5,9.8,9],[6,9.6,22.74],[7,9.4,11.48]],"id":45323444},{"bdatb":[[3,2.04,13.32],[4,2.02,42.35],[7,1.98,72.94],[8,1.97,2.53],[9,1.96,9.93]],"id":9570503},{"bdatb":[[3,6.2,6.62],[4,6,1.76],[6,5.8,36.15],[7,5.7,223.76],[8,5.6,4.75],[9,5.5,1.87]],"id":12989514},{"bdatb":[[5,20,2.18],[6,19.5,1.76],[8,18.5,2.79],[9,18,1.76]],"id":44621159},{"bdatb":[[7,5.9,9.83],[8,5.8,10],[9,5.7,99.19]],"id":44836671},{"bdatb":[[6,8.2,1.97],[7,8,1.46]],"id":43885158},{"bdatl":[[0,23,1.37],[1,24,5.22],[2,25,1.48],[3,26,6.1],[4,27,1.86],[5,28,7.55],[6,29,5.33],[7,30,1.83],[8,32,1.76],[9,34,5]],"id":46969227}]}]}
{"op":"mcm","clk":"AJW8AQDMXQDypQE=","pt":1659347758182,"mc":[{"id":"1.201590187","rc":[{"atl":[[7.6,32.3]],"id":12989514},{"atb":[[17,6.76]],"atl":[[29,1.76],[28,11.25]],"id":46969227}]}]}
{"op":"mcm","clk":"AJi8AQDMXQD4pQE=","pt":1659347758232,"mc":[{"id":"1.201590187","rc":[{"bdatl":[[2,7.6,32.3]],"id":12989514},{"bdatb":[[3,17,6.76]],"bdatl":[[5,28,11.25],[6,29,1.76]],"id":46969227}]}]}
{"op":"mcm","clk":"AKC8AQDTXQCApgE=","pt":1659347758376,"mc":[{"id":"1.201590187","rc":[{"atb":[[9.4,4]],"id":43885158}]}]}
{"op":"mcm","clk":"AKK8AQDUXQCGpgE=","pt":1659347758426,"mc":[{"id":"1.201590187","rc":[{"bdatb":[[1,9.4,4],[2,9.2,1.76],[3,9,4.31],[4,8.8,5.11],[5,8.6,20.88],[6,8.4,4.75],[7,8.2,1.97],[8,8,1.46],[9,7.8,1.76]],"id":43885158}]}]}
{"op":"mcm","clk":"AOy8AQCGXgDMpgE=","pt":1659347759773,"mc":[{"id":"1.201590187","rc":[{"atb":[[9.4,6.26]],"id":43885158}]}]}
{"op":"mcm","clk":"AO68AQCGXgDRpgE=","pt":1659347759824,"mc":[{"id":"1.201590187","rc":[{"bdatb":[[1,9.4,6.26]],"id":43885158}]}]}
{"op":"mcm","clk":"APW8AQCHXgDTpgE=","pt":1659347759884,"mc":[{"id":"1.201590187","rc":[{"atb":[[19,0]],"id":46969227}]}]}
{"op":"mcm","clk":"APW8AQCHXgDXpgE=","pt":1659347759935,"mc":[{"id":"1.201590187","rc":[{"bdatl":[[6,19.5,1.76],[8,21,1.77]],"id":45323444},{"bdatl":[[3,2.3,4.58],[4,2.32,2.74],[5,2.34,6.96],[6,2.36,3.08],[7,2.38,1.01]],"id":9570503},{"bdatl":[[7,8.6,1.76],[8,8.8,1.77],[9,9,8.69]],"id":12989514},{"bdatl":[[4,170,2],[5,900,1.19]],"id":44621159},{"bdatl":[[9,9.4,1.76]],"id":44836671},{"bdatl":[[8,14.5,13.88],[9,15,12.7]],"id":43885158},{"bdatb":[[0,18,5],[1,17.5,7.76],[2,17,6.76],[3,16.5,5.76],[4,16,1.43],[5,15.5,1.76],[6,15,2.32],[7,14.5,1.88],[8,14,1.76],[9,11.5,9.72]],"id":46969227}]}]}
{"op":"mcm","clk":"APu8AQCJXgDYpgE=","pt":1659347759996,"mc":[{"id":"1.201590187","rc":[{"atb":[[2,0.03]],"id":12989514},{"atb":[[9.4,8.44]],"id":43885158},{"atb":[[18,7.2]],"id":46969227}]}]}
{"op":"mcm","clk":"APu8AQCJXgDZpgE=","pt":1659347760046,"mc":[{"id":"1.201590187","rc":[{"bdatb":[[1,9.4,8.44]],"id":43885158},{"bdatb":[[0,18,7.2]],"id":46969227}]}]}
{"op":"mcm","clk":"AIS9AQCOXgDdpgE=","pt":1659347760194,"mc":[{"id":"1.201590187","rc":[{"atb":[[2.12,7.66]],"trd":[[2.12,217.66]],"ltp":2.12,"tv":1147.71,"id":9570503}],"tv":2065.35}]}
{"op":"mcm","clk":"AIS9AQCSXgDfpgE=","pt":1659347760245,"mc":[{"id":"1.201590187","rc":[{"bdatb":[[0,2.12,7.66]],"id":9570503},{"bdatl":[[9,9,8.62]],"id":12989514}]}]}
{"op":"mcm","clk":"AIW9AQCTXgDhpgE=","pt":1659347760295,"mc":[{"id":"1.201590187","rc":[{"atb":[[2.12,0]],"trd":[[2.12,232.98]],"bdatb":[[0,2.08,17.18],[1,2.06,35.07],[2,2.04,13.32],[3,2.02,42.35],[4,2,93.09],[5,1.99,1.76],[6,1.98,72.94],[7,1.97,2.53],[8,1.96,9.93],[9,1.95,3.29]],"tv":1163.03,"id":9570503},{"bdatl":[[8,21,1.76]],"id":45323444},{"bdatl":[[8,8.8,1.76],[9,9,6.82]],"id":12989514},{"bdatl":[[5,900,1.14]],"id":44621159},{"bdatl":[[8,14.5,13.87],[9,15,12]],"id":43885158}],"tv":2080.67}]}
{"op":"mcm","clk":"AI+9AQCXXgDnpgE=","pt":1659347760501,"mc":[{"id":"1.201590187","rc":[{"atb":[[2.08,21.19],[2.06,42.74]],"atl":[[2.3,6]],"id":9570503},{"atl":[[7.4,25.11],[9,2.17]],"id":12989514},{"atb":[[15.5,6.76],[18,2.2],[17.5,1.76]],"id":46969227}]}]}
{"op":"mcm","clk":"AJK9AQCaXgDspgE=","pt":1659347760551,"mc":[{"id":"1.201590187","rc":[{"bdatb":[[0,2.08,21.19],[1,2.06,42.74]],"bdatl":[[3,2.3,10.58],[8,2.44,5.53],[9,2.46,12.14]],"id":9570503},{"bdatl":[[1,7.4,25.11],[9,9,2.17]],"id":12989514},{"bdatb":[[0,18,2.2],[1,17.5,1.76],[5,15.5,6.76]],"id":46969227}]}]}
{"op":"mcm","clk":"AJW9AQCcXgDupgE=","pt":1659347760601,"mc":[{"id":"1.201590187","rc":[{"atb":[[13.5,1.76]],"bdatb":[[9,13.5,1.76]],"id":46969227}]}]}
{"op":"mcm","clk":"AJ+9AQCgXgD0pgE=","pt":1659347760669,"mc":[{"id":"1.201590187","rc":[{"atb":[[2.08,14.39]],"id":9570503}]}]}
{"op":"mcm","clk":"AKC9AQCiXgD2pgE=","pt":1659347760720,"mc":[{"id":"1.201590187","rc":[{"bdatb":[[0,2.08,14.39]],"id":9570503}]}]}
{"op":"mcm","clk":"AKO9AQCkXgD6pgE=","pt":1659347760772,"mc":[{"id":"1.201590187","rc":[{"atb":[[2.06,35.07]],"id":9570503},{"atb":[[25,2.33]],"atl":[[36,2]],"id":44621159}]}]}
{"op":"mcm","clk":"AKa9AQCmXgCApwE=","pt":1659347760822,"mc":[{"id":"1.201590187","rc":[{"bdatb":[[7,9.4,14.98],[8,9.2,12],[9,9,13.28]],"id":45323444},{"bdatb":[[1,2.06,35.07]],"bdatl":[[5,2.34,9.67],[6,2.38,1.41],[7,2.42,5.58],[8,2.46,12.15],[9,2.5,35.99]],"id":9570503},{"bdatb":[[0,25,2.33]],"bdatl":[[0,36,2]],"id":44621159}]}]}
{"op":"mcm","clk":"AKq9AQCoXgCApwE=","pt":1659347760879,"mc":[{"id":"1.201590187","rc":[{"atl":[[25,0.1],[23,2.16]],"id":46969227}]}]}
{"op":"mcm","clk":"AK29AQCoXgCGpwE=","pt":1659347760929,"mc":[{"id":"1.201590187","rc":[{"bdatb":[[6,9.6,24.64],[7,9.4,13.04]],"id":45323444},{"bdatb":[[9,1.95,12.33]],"id":9570503},{"bdatb":[[8,5.6,4.85],[9,5.5,4.97]],"id":12989514},{"bdatb":[[9,5.7,99.3]],"id":44836671},{"bdatl":[[0,23,2.16],[2,26,6.2],[3,27,1.86],[4,28,11.25],[5,29,1.76],[6,30,1.83],[7,32,1.76],[8,34,5],[9,36,1.76]],"id":46969227}]}]}
{"op":"mcm","clk":"AK+9AQCpXgCHpwE=","pt":1659347760980,"mc":[{"id":"1.201590187","rc":[{"atb":[[25,4.63]],"id":44621159}]}]}
{"op":"mcm","clk":"ALS9AQCpXgCLpwE=","pt":1659347761030,"mc":[{"id":"1.201590187","rc":[{"bdatl":[[8,2.44,5.75],[9,2.46,6.44]],"id":9570503},{"bdatb":[[0,25,4.63]],"id":44621159}]}]}
{"op":"mcm","clk":"ANC9AQC5XgC4pwE=","pt":1659347761596,"mc":[{"id":"1.201590187","rc":[{"atl":[[7.2,9.15]],"id":12989514}]}]}
{"op":"mcm","clk":"ANS9AQC7XgC+pwE=","pt":1659347761646,"mc":[{"id":"1.201590187","rc":[{"bdatb":[[5,9.8,14.21],[6,9.6,21],[7,9.4,11.32]],"id":45323444},{"bdatb":[[2,2.04,14.13],[3,2.02,41.53],[5,1.99,4.21],[6,1.98,77.72],[7,1.97,4.04],[8,1.96,11.61],[9,1.95,10.04]],"id":9570503},{"bdatl":[[0,7.2,9.15]],"id":12989514},{"bdatb":[[5,20,2.26],[8,18.5,2.7]],"id":44621159},{"bdatb":[[4,6.4,3.32],[5,6.2,25.79],[6,6,218.81],[7,5.9,11.43],[8,5.8,10.51],[9,5.7,100.23]],"id":44836671},{"bdatb":[[6,8.4,4.95],[7,8.2,1.76]],"id":43885158},{"bdatb":[[6,15,2.43],[7,14.5,1.76]],"id":46969227}]}]}
{"op":"mcm","clk":"ANq9AQC9XgDBpwE=","pt":1659347761696,"mc":[{"id":"1.201590187","rc":[{"atb":[[2.12,2]],"bdatb":[[0,2.12,2],[1,2.08,14.39],[2,2.06,35.07],[3,2.04,14.13],[4,2.02,41.53],[5,2,93.09],[6,1.99,4.21],[7,1.98,77.72],[8,1.97,4.04],[9,1.96,11.61]],"id":9570503},{"bdatl":[[8,21,1.77]],"id":45323444},{"bdatl":[[8,8.8,1.77],[9,9,2.64]],"id":12989514},{"bdatl":[[5,900,1.16]],"id":44621159},{"bdatl":[[8,14.5,13.88],[9,15,12.28]],"id":43885158}]}]}
{"op":"mcm","clk":"AOG9AQC/XgDKpwE=","pt":1659347761768,"mc":[{"id":"1.201590187","rc":[{"atl":[[13.5,0]],"trd":[[13.5,19.16]],"tv":43.28,"id":45323444},{"atb":[[2.12,0]],"trd":[[2.12,236.98]],"tv":1167.03,"id":9570503},{"atb":[[25,1.33]],"atl":[[36,1]],"id":44621159},{"atb":[[16,9.43]],"id":46969227}],"tv":2086.14}]}
{"op":"mcm","clk":"AOK9AQDBXgDKpwE=","pt":1659347761818,"mc":[{"id":"1.201590187","rc":[{"bdatb":[[5,9.8,12.56],[6,9.6,22.68],[7,9.4,11],[8,9.2,12.33],[9,9,13]],"bdatl":[[0,16,1.2],[8,21,1.76]],"id":45323444},{"bdatb":[[0,2.08,14.39],[1,2.06,35.07],[2,2.04,9.26],[3,2.02,41.53],[4,2,93.09],[5,1.99,9.2],[6,1.98,72.7],[7,1.97,4.04],[8,1.96,14.15],[9,1.95,4.31]],"bdatl":[[5,2.34,6.96],[6,2.36,3.08],[7,2.38,1.01],[8,2.44,5.53],[9,2.46,12.14]],"id":9570503},{"bdatb":[[3,6.2,5.02],[6,5.8,37.86],[8,5.6,3.08],[9,5.5,5.87]],"bdatl":[[8,8.8,1.76],[9,9,2.17]],"id":12989514},{"bdatb":[[0,25,1.33],[5,20,1.76]],"bdatl":[[0,36,1],[5,900,1.14]],"id":44621159},{"bdatb":[[4,6.4,1.76],[6,6,220.47],[7,5.9,9.75]],"id":44836671},{"bdatb":[[6,8.4,3.76]],"bdatl":[[8,14.5,13.87],[9,15,12]],"id":43885158},{"bdatb":[[4,16,9.43],[6,15,1.76]],"id":46969227}]}]}
{"op":"mcm","clk":"AOm9AQDFXgDOpwE=","pt":1659347761872,"mc":[{"id":"1.201590187","rc":[{"atl":[[2.26,6],[2.3,0]],"id":9570503}]}]}
{"op":"mcm","clk":"AOy9AQDGXgDSpwE=","pt":1659347761922,"mc":[{"id":"1.201590187","rc":[{"bdatl":[[3,2.26,6],[4,2.3,4.58],[5,2.32,2.74],[6,2.34,6.96],[7,2.36,3.08],[8,2.38,1.01],[9,2.44,5.53]],"id":9570503}]}]}
{"op":"mcm","clk":"APC9AQDKXgDTpwE=","pt":1659347761976,"mc":[{"id":"1.201590187","rc":[{"atb":[[26,2.18]],"id":44621159}]}]}
{"op":"mcm","clk":"APC9AQDKXgDWpwE=","pt":1659347762026,"mc":[{"id":"1.201590187","rc":[{"bdatl":[[6,2.34,10.07],[7,2.36,1.02],[8,2.42,5.58],[9,2.44,5.75]],"id":9570503},{"bdatb":[[0,26,2.18],[1,25,1.33],[2,24,4.84],[3,23,3.56],[4,22,1.76],[5,21,5],[6,20,1.76],[7,19.5,1.76],[8,19,1.76],[9,18.5,2.7]],"id":44621159}]}]}
{"op":"mcm","clk":"APG9AQDLXgDWpwE=","pt":1659347762076,"mc":[{"id":"1.201590187","rc":[{"atl":[[7.4,20.66]],"bdatl":[[1,7.4,20.66]],"id":12989514}]}]}
{"op":"mcm","clk":"AIq+AQDUXgDopwE=","pt":1659347762396,"mc":[{"id":"1.201590187","rc":[{"atl":[[7.4,17.46]],"id":12989514}]}]}
{"op":"mcm","clk":"AJS+AQDUXgDupwE=","pt":1659347762446,"mc":[{"id":"1.201590187","rc":[{"bdatl":[[1,7.4,17.46]],"id":12989514}]}]}
{"op":"mcm","clk":"AKO+AQDjXgD4pwE=","pt":1659347762497,"mc":[{"id":"1.201590187","rc":[{"atl":[[7.2,13.01]],"id":12989514}]}]}
{"op":"mcm","clk":"AKa+AQDkXgD6pwE=","pt":1659347762547,"mc":[{"id":"1.201590187","rc":[{"bdatb":[[6,9.6,23],[8,9.2,12.28]],"id":45323444},{"bdatl":[[0,7.2,13.01]],"id":12989514}]}]}
{"op":"mcm","clk":"AK2+AQDnXgD+pwE=","pt":1659347762602,"mc":[{"id":"1.201590187","rc":[{"atb":[[2.08,1.59],[2.06,48.75]],"id":9570503},{"atb":[[6.6,11.36]],"atl":[[7.8,12.74]],"id":12989514}]}]}
{"op":"mcm","clk":"AK++AQDoXgCCqAE=","pt":1659347762652,"mc":[{"id":"1.201590187","rc":[{"bdatb":[[0,2.08,1.59],[1,2.06,48.75]],"bdatl":[[8,2.38,5.67],[9,2.42,12.04]],"id":9570503},{"bdatb":[[1,6.6,11.36]],"bdatl":[[3,7.8,12.74]],"id":12989514}]}]}
{"op":"mcm","clk":"AMW+AQDzXgCTqAE=","pt":1659347762879,"mc":[{"id":"1.201590187","rc":[{"atb":[[18,0]],"id":46969227}]}]}
{"op":"mcm","clk":"AMW+AQDzXgCaqAE=","pt":1659347762929,"mc":[{"id":"1.201590187","rc":[{"bdatl":[[6,2.34,5.98],[7,2.36,4.06],[8,2.38,1.01],[9,2.4,5.62]],"id":9570503},{"bdatb":[[0,17.5,1.76],[1,17,6.76],[2,16.5,5.76],[3,16,9.43],[4,15.5,6.76],[5,15,1.76],[6,14.5,1.76],[7,14,1.76],[8,13.5,1.76],[9,13,1.14]],"id":46969227}]}]}
{"op":"mcm","clk":"AMe+AQD2XgCbqAE=","pt":1659347762979,"mc":[{"id":"1.201590187","rc":[{"atl":[[16.5,1.18]],"bdatl":[[1,16.5,1.18],[2,17,1.33],[3,17.5,1.76],[4,18,1.76],[5,18.5,1.76],[6,19,1.76],[7,19.5,1.76],[8,20,1.76],[9,21,1.76]],"id":45323444},{"atb":[[11.5,17.24]],"id":44621159},{"atb":[[17,8.96]],"bdatb":[[1,17,8.96]],"id":46969227},{"bdatb":[[7,1.97,11.06],[8,1.96,9.62],[9,1.95,7.68]],"id":9570503},{"bdatb":[[8,5.6,5.55],[9,5.5,4.26]],"id":12989514},{"bdatb":[[8,5.8,12.9],[9,5.7,98.67]],"id":44836671}]}]}
{"op":"mcm","clk":"ANC+AQD9XgCjqAE=","pt":1659347763089,"mc":[{"id":"1.201590187","rc":[{"atb":[[12.5,3.35]],"atl":[[16.5,2.18]],"id":45323444}]}]}
{"op":"mcm","clk":"ANG+AQD9XgCoqAE=","pt":1659347763139,"mc":[{"id":"1.201590187","rc":[{"bdatb":[[0,12.5,3.35]],"bdatl":[[1,16.5,2.18]],"id":45323444},{"bdatb":[[8,1.96,12.4],[9,1.95,13.35]],"bdatl":[[5,2.32,8.77],[6,2.34,4.71],[7,2.36,9.99]],"id":9570503},{"bdatb":[[9,5.5,5.25]],"id":12989514},{"bdatb":[[9,5.7,99.62]],"id":44836671}]}]}
{"op":"mcm","clk":"AOS+AQCLXwC9qAE=","pt":1659347763400,"mc":[{"id":"1.201590187","rc":[{"atb":[[1.71,67.1],[1.78,0]],"atl":[[2.24,7]],"id":9570503},{"atb":[[15,5.76],[17,3.96]],"id":46969227}]}]}
{"op":"mcm","clk":"AOW+AQCMXwDAqAE=","pt":1659347763450,"mc":[{"id":"1.201590187","rc":[{"bdatl":[[3,2.24,7],[4,2.26,6],[5,2.3,4.58],[6,2.32,8.77],[7,2.34,4.71],[8,2.36,9.99],[9,2.38,1.01]],"id":9570503},{"bdatb":[[1,17,3.96],[5,15,5.76]],"id":46969227}]}]}
{"op":"mcm","clk":"AOm+AQCPXwDAqAE=","pt":1659347763500,"mc":[{"id":"1.201590187","rc":[{"atl":[[2.26,0],[2.52,0]],"id":9570503},{"atb":[[25,5.5],[24,0.49]],"id":44621159},{"atl":[[11.5,12.2]],"id":44836671},{"atl":[[12,10.85]],"id":43885158}]}]}
{"op":"mcm","clk":"AOq+AQCPXwDEqAE=","pt":1659347763550,"mc":[{"id":"1.201590187","rc":[{"bdatl":[[4,2.3,4.58],[5,2.32,8.77],[6,2.34,4.71],[7,2.36,9.99],[8,2.38,1.01],[9,2.4,5.62]],"id":9570503},{"bdatb":[[1,25,5.5],[2,23,4.05],[3,22,1.76],[4,21,5],[5,20,1.76],[6,19.5,1.76],[7,19,1.76],[8,18.5,2.7],[9,18,1.76]],"id":44621159},{"bdatl":[[3,12,10.85]],"id":43885158}]}]}
{"op":"mcm","clk":"AO6+AQCTXwDEqAE=","pt":1659347763600,"mc":[{"id":"1.201590187","rc":[{"atl":[[2.44,24.09]],"id":9570503},{"atl":[[11.5,2.88]],"id":43885158},{"atb":[[17.5,0]],"id":46969227}]}]}
{"op":"mcm","clk":"AO++AQCXXwDJqAE=","pt":1659347763650,"mc":[{"id":"1.201590187","rc":[{"bdatl":[[4,2.32,4.54],[5,2.34,13.4],[6,2.36,9.99],[7,2.4,1.01],[8,2.42,5.58],[9,2.44,25.79]],"id":9570503},{"bdatl":[[2,11.5,2.88]],"id":43885158},{"bdatb":[[0,17,3.96],[1,16.5,5.76],[2,16,9.43],[3,15.5,6.76],[4,15,5.76],[5,14.5,1.76],[6,14,1.76],[7,13.5,1.76],[8,13,1.14],[9,12,1.77]],"id":46969227}]}]}
{"op":"mcm","clk":"APO+AQCYXwDLqAE=","pt":1659347763707,"mc":[{"id":"1.201590187","rc":[{"atl":[[13,59.08]],"id":44836671},{"atb":[[1.02,0]],"id":46969227}]}]}
{"op":"mcm","clk":"APq+AQCfXwDRqAE=","pt":1659347763798,"mc":[{"id":"1.201590187","rc":[{"atb":[[12.5,7.95]],"atl":[[17,0.18]],"id":45323444},{"atb":[[17,5.59]],"id":46969227}]}]}
{"op":"mcm","clk":"APq+AQChXwDUqAE=","pt":1659347763848,"mc":[{"id":"1.201590187","rc":[{"bdatb":[[0,12.5,7.95]],"bdatl":[[2,17.5,1.94],[3,18,1.76],[4,18.5,1.76],[5,19,1.76],[6,19.5,1.76],[7,20,1.76],[8,21,1.76],[9,22,4.02]],"id":45323444},{"bdatb":[[9,1.95,3.33]],"bdatl":[[5,2.34,32.04],[6,2.4,5.77],[7,2.42,9.74],[8,2.44,24.41],[9,2.5,27.07]],"id":9570503},{"bdatb":[[0,17,5.59]],"id":46969227}]}]}
{"op":"mcm","clk":"AIC/AQCjXwDZqAE=","pt":1659347763898,"mc":[{"id":"1.201590187","rc":[{"atl":[[7.4,12.8]],"bdatl":[[1,7.4,12.8]],"id":12989514}]}]}
{"op":"mcm","clk":"AIy/AQCuXwDnqAE=","pt":1659347764072,"mc":[{"id":"1.201590187","rc":[{"atb":[[26,3.33]],"id":44621159},{"atl":[[10.5,2.56]],"id":43885158},{"atb":[[17.5,1.15]],"atl":[[23,3.31]],"id":46969227}]}]}
{"op":"mcm","clk":"AIy/AQCwXwDsqAE=","pt":1659347764122,"mc":[{"id":"1.201590187","rc":[{"bdatb":[[4,10,15.06],[5,9.8,13.29],[6,9.6,21],[7,9.4,11.27],[8,9.2,12],[9,9,13.53]],"id":45323444},{"bdatb":[[5,1.99,15.26],[6,1.98,70.48],[7,1.97,7.17],[8,1.96,13.96],[9,1.95,10.96]],"bdatl":[[4,2.3,4.58],[5,2.32,4.13],[6,2.34,27.95],[7,2.4,5.77],[8,2.42,9.74],[9,2.44,24.41]],"id":9570503},{"bdatb":[[6,5.8,38.62],[7,5.7,225.11],[8,5.6,3.4],[9,5.5,5.81]],"id":12989514},{"bdatb":[[0,26,3.33]],"id":44621159},{"bdatb":[[6,6,221.2],[7,5.9,10.3],[8,5.8,11.58],[9,5.7,100.16]],"id":44836671},{"bdatl":[[0,10.5,2.56]],"id":43885158},{"bdatb":[[0,17.5,1.15],[1,17,5.59],[2,16.5,5.76],[3,16,9.43],[4,15.5,6.76],[5,15,5.76],[6,14.5,1.76],[7,14,1.76],[8,13.5,1.76],[9,13,1.48]],"bdatl":[[0,23,3.31]],"id":46969227}]}]}
{"op":"mcm","clk":"AJK/AQCzXwDuqAE=","pt":1659347764177,"mc":[{"id":"1.201590187","rc":[{"atb":[[6.8,0.4]],"atl":[[7.2,11.86]],"id":12989514},{"atl":[[10.5,1.41]],"id":43885158}]}]}
{"op":"mcm","clk":"AJK/AQC3XwDwqAE=","pt":1659347764227,"mc":[{"id":"1.201590187","rc":[{"bdatb":[[4,10,13.85],[5,9.8,14.52]],"id":45323444},{"bdatb":[[5,1.99,9.2],[6,1.98,72.7],[7,1.97,11.06]],"bdatl":[[4,2.3,1.18],[5,2.32,7.5],[6,2.34,24.61],[7,2.36,3.61],[8,2.4,5.47],[9,2.42,9.74]],"id":9570503},{"bdatb":[[0,6.6,11.76],[1,6.4,18.95],[2,6.2,5.02],[3,6,1.76],[4,5.9,1.76],[5,5.8,37.86],[6,5.7,223.76],[7,5.6,5.55],[8,5.5,5.81],[9,5.4,3.74]],"bdatl":[[0,7.2,11.86]],"id":12989514},{"bdatb":[[6,6,220.47],[7,5.9,9.75],[8,5.8,12.9]],"id":44836671},{"bdatl":[[0,10.5,1.41]],"id":43885158},{"bdatb":[[9,13,1.14]],"id":46969227}]}]}
{"op":"mcm","clk":"AJa/AQDAXwDxqAE=","pt":1659347764298,"mc":[{"id":"1.201590187","rc":[{"atb":[[17,3.82]],"id":46969227}]}]}
{"op":"mcm","clk":"AJi/AQDAXwD5qAE=","pt":1659347764348,"mc":[{"id":"1.201590187","rc":[{"bdatb":[[1,17,3.82]],"id":46969227}]}]}
{"op":"mcm","clk":"ALe/AQDPXwCJqQE=","pt":1659347764488,"mc":[{"id":"1.201590187","rc":[{"atb":[[12.5,3.35]],"id":45323444},{"atb":[[2.04,18.86]],"id":9570503}]}]}
{"op":"mcm","clk":"ALe/AQDRXwCPqQE=","pt":1659347764538,"mc":[{"id":"1.201590187","rc":[{"bdatb":[[0,12.5,3.35]],"id":45323444},{"bdatb":[[2,2.04,18.86]],"bdatl":[[6,2.34,9.3],[7,2.36,9.99],[8,2.38,1.01],[9,2.4,4.09]],"id":9570503}]}]}
{"op":"mcm","clk":"AOe/AQDnXwCvqQE=","pt":1659347765167,"mc":[{"id":"1.201590187","rc":[{"atb":[[26,1.15]],"id":44621159}]}]}
{"op":"mcm","clk":"AOe/AQDpXwCyqQE=","pt":1659347765217,"mc":[{"id":"1.201590187","rc":[{"bdatb":[[0,26,1.15]],"id":44621159}]}]}
{"op":"mcm","clk":"APK/AQDvXwC7qQE=","pt":1659347765372,"mc":[{"id":"1.201590187","rc":[{"atl":[[16,2.53]],"id":45323444},{"atb":[[27,3.45]],"atl":[[36,2.33]],"id":44621159},{"atl":[[22,1.33]],"id":46969227}]}]}
{"op":"mcm","clk":"APK/AQDxXwC8qQE=","pt":1659347765425,"mc":[{"id":"1.201590187","rc":[{"bdatb":[[3,10.5,12.12],[4,10,13.81],[5,9.8,13.05],[8,9.2,13.34],[9,9,13.07]],"bdatl":[[0,16,2.53]],"id":45323444},{"bdatb":[[4,2,100.49],[5,1.99,1.76],[6,1.98,83.43],[7,1.97,20.79],[8,1.96,4.18],[9,1.95,4.31]],"bdatl":[[5,2.32,16.88],[6,2.34,10.07],[7,2.36,1.02],[8,2.38,4.13],[9,2.42,1.51]],"id":9570503},{"bdatb":[[6,5.7,226.29],[7,5.6,8.85],[8,5.5,1.76],[9,5.4,2.24]],"id":12989514},{"bdatb":[[0,27,3.45],[1,26,1.15],[2,25,5.5],[3,23,4.05],[4,22,1.76],[5,21,5],[6,20,1.76],[7,19.5,1.76],[8,19,1.76],[9,18.5,2.7]],"bdatl":[[0,36,2.33]],"id":44621159},{"bdatb":[[7,5.9,13.35],[8,5.8,14.9],[9,5.7,96.71]],"id":44836671},{"bdatb":[[9,7.8,5.51]],"id":43885158},{"bdatl":[[0,22,1.33],[1,23,3.31],[2,24,5.22],[3,26,6.2],[4,27,1.86],[5,28,11.25],[6,29,1.76],[7,30,1.83],[8,32,1.76],[9,34,5]],"id":46969227}]}]}
{"op":"mcm","clk":"APq/AQD3XwDAqQE=","pt":1659347765494,"mc":[{"id":"1.201590187","rc":[{"atl":[[27,1.76],[22,1.57]],"id":46969227}]}]}
{"op":"mcm","clk":"APq/AQD3XwDJqQE=","pt":1659347765544,"mc":[{"id":"1.201590187","rc":[{"bdatb":[[4,10,14.34],[5,9.8,12.51]],"id":45323444},{"bdatb":[[6,5.7,227.22],[7,5.6,7.91]],"id":12989514},{"bdatb":[[9,7.8,6.18]],"id":43885158},{"bdatl":[[0,22,1.57],[4,27,1.76]],"id":46969227}]}]}
{"op":"mcm","clk":"AJLAAQCDYADeqQE=","pt":1659347765896,"mc":[{"id":"1.201590187","rc":[{"atb":[[17,0]],"id":46969227}]}]}
{"op":"mcm","clk":"AJPAAQCDYADmqQE=","pt":1659347765946,"mc":[{"id":"1.201590187","rc":[{"bdatl":[[5,2.32,7.5],[6,2.34,9.3],[7,2.36,9.99],[8,2.38,1.01],[9,2.4,4.09]],"id":9570503},{"bdatb":[[1,16.5,5.76],[2,16,9.43],[3,15.5,6.76],[4,15,5.76],[5,14.5,1.76],[6,14,1.76],[7,13.5,1.76],[8,13,1.14],[9,12,4.51]],"id":46969227}]}]}
{"op":"mcm","clk":"AJTAAQCIYADmqQE=","pt":1659347765996,"mc":[{"id":"1.201590187","rc":[{"atb":[[1.02,1.63],[16.5,7.96]],"id":46969227}]}]}
{"op":"mcm","clk":"AJnAAQCJYADuqQE=","pt":1659347766047,"mc":[{"id":"1.201590187","rc":[{"bdatb":[[1,16.5,7.96]],"id":46969227}]}]}
{"op":"mcm","clk":"AKDAAQCJYADwqQE=","pt":1659347766106,"mc":[{"id":"1.201590187","rc":[{"atb":[[2.08,15.62],[2.06,35.07]],"atl":[[2.26,7],[2.24,0]],"id":9570503},{"atb":[[6.6,4.92]],"id":12989514},{"atb":[[27,1.33]],"id":44621159},{"atl":[[23,5.31]],"id":46969227}]}]}
{"op":"mcm","clk":"AKDAAQCMYAD3qQE=","pt":1659347766156,"mc":[{"id":"1.201590187","rc":[{"bdatb":[[0,2.08,15.62],[1,2.06,35.07]],"bdatl":[[3,2.26,7],[6,2.34,6.44],[7,2.36,2.84],[8,2.38,9.9],[9,2.42,1]],"id":9570503},{"bdatb":[[0,6.6,5.32]],"id":12989514},{"bdatb":[[0,27,1.33]],"id":44621159},{"bdatl":[[1,23,5.31]],"id":46969227}]}]}
{"op":"mcm","clk":"AK7AAQCOYAD9qQE=","pt":1659347766310,"mc":[{"id":"1.201590187","rc":[{"atb":[[2.08,1.59],[2.06,60.59]],"id":9570503},{"atb":[[28,2.07]],"id":44621159},{"atb":[[16,8]],"id":46969227}]}]}
{"op":"mcm","clk":"AK/AAQCOYACAqgE=","pt":1659347766360,"mc":[{"id":"1.201590187","rc":[{"bdatb":[[0,2.08,1.59],[1,2.06,60.59]],"bdatl":[[3,2.26,7.02],[4,2.28,1.17],[5,2.32,13.99],[6,2.36,2.84],[7,2.38,9.9],[8,2.4,1.01],[9,2.42,5.58]],"id":9570503},{"bdatb":[[0,28,2.07],[1,27,1.33],[2,26,1.15],[3,25,5.5],[4,23,4.05],[5,22,1.76],[6,21,5],[7,20,1.76],[8,19.5,1.76],[9,19,1.76]],"id":44621159},{"bdatb":[[2,16,8]],"id":46969227}]}]}
{"op":"mcm","clk":"ALXAAQCQYACDqgE=","pt":1659347766410,"mc":[{"id":"1.201590187","rc":[{"atb":[[1.05,1.43]],"id":46969227}]}]}
{"op":"mcm","clk":"ALvAAQCSYACJqgE=","pt":1659347766486,"mc":[{"id":"1.201590187","rc":[{"atb":[[2.04,44.38],[2.06,35.07]],"id":9570503},{"atl":[[11,3.53]],"id":43885158},{"atl":[[22,2.57]],"id":46969227}]}]}
{"op":"mcm","clk":"AL3AAQCSYACNqgE=","pt":1659347766536,"mc":[{"id":"1.201590187","rc":[{"bdatb":[[4,10,16.26],[5,9.8,9],[6,9.6,22.59],[7,9.4,11],[8,9.2,12.28],[9,9,13]],"id":45323444},{"bdatb":[[1,2.06,35.07],[2,2.04,44.38],[6,1.98,90.1],[7,1.97,2.53],[8,1.96,4.07],[9,1.95,13.55]],"id":9570503},{"bdatb":[[6,5.7,228.26],[7,5.6,4.12],[8,5.5,2.28],[9,5.4,4.06]],"id":12989514},{"bdatb":[[7,5.9,15.58],[8,5.8,10],[9,5.7,98.94]],"id":44836671},{"bdatb":[[9,7.8,6.95]],"bdatl":[[1,11,3.53]],"id":43885158},{"bdatb":[[9,12,3.24]],"bdatl":[[0,22,2.57]],"id":46969227}]}]}
{"op":"mcm","clk":"AMPAAQCXYACOqgE=","pt":1659347766588,"mc":[{"id":"1.201590187","rc":[{"atl":[[1000,2.41]],"id":44621159},{"atb":[[13,1.76],[17,2]],"atl":[[25,1.86],[22,3.57]],"id":46969227}]}]}
{"op":"mcm","clk":"AMPAAQCXYACWqgE=","pt":1659347766638,"mc":[{"id":"1.201590187","rc":[{"bdatb":[[7,9.4,11.27],[8,9.2,12],[9,9,13.78]],"id":45323444},{"bdatb":[[8,1.96,14.23],[9,1.95,3.33]],"bdatl":[[6,2.34,2.86],[7,2.36,5.18],[8,2.38,4.76],[9,2.4,1.01]],"id":9570503},{"bdatb":[[8,5.5,4.54],[9,5.4,2.24]],"id":12989514},{"bdatl":[[7,1000,2.41]],"id":44621159},{"bdatb":[[1,17,2],[2,16.5,7.96],[3,16,8],[4,15.5,6.76],[5,15,5.76],[6,14.5,1.76],[7,14,1.76],[8,13.5,1.76],[9,13,2.9]],"bdatl":[[0,22,3.57],[3,25,1.86],[4,26,6.1],[5,27,1.76],[6,28,11.25],[7,29,1.76],[8,30,1.83],[9,32,1.76]],"id":46969227}]}]}
{"op":"mcm","clk":"AMnAAQCZYACXqgE=","pt":1659347766693,"mc":[{"id":"1.201590187","rc":[{"atb":[[2.04,14.8],[2.06,48.89]],"atl":[[2.18,14.56]],"id":9570503},{"atb":[[6.4,16.52]],"atl":[[7.4,10.43]],"id":12989514},{"atl":[[1000,2]],"id":44621159},{"atb":[[7,2.61]],"atl":[[7.8,9.6]],"id":44836671},{"atb":[[9.4,6.26],[8.8,2.81]],"id":43885158},{"atb":[[17,4]],"atl":[[1000,0.41]],"id":46969227}]}]}
{"op":"mcm","clk":"AMzAAQCZYACeqgE=","pt":1659347766743,"mc":[{"id":"1.201590187","rc":[{"bdatb":[[1,2.06,48.89],[2,2.04,14.8]],"bdatl":[[2,2.18,14.56],[7,2.36,6.8],[8,2.38,3.16]],"id":9570503},{"bdatb":[[1,6.4,16.52]],"bdatl":[[1,7.4,10.43]],"id":12989514},{"bdatl":[[7,1000,2]],"id":44621159},{"bdatb":[[1,7,2.61]],"bdatl":[[1,7.8,9.6]],"id":44836671},{"bdatb":[[1,9.4,6.26],[4,8.8,2.81]],"id":43885158},{"bdatb":[[1,17,4]],"id":46969227}]}]}
{"op":"mcm","clk":"ANDAAQCcYACfqgE=","pt":1659347766793,"mc":[{"id":"1.201590187","rc":[{"atl":[[34,0.41]],"id":44621159}]}]}
{"op":"mcm","clk":"ANHAAQCdYAClqgE=","pt":1659347766843,"mc":[{"id":"1.201590187","rc":[{"bdatb":[[4,5.9,4.13],[5,5.8,35.45]],"id":12989514},{"bdatl":[[0,36,2.74]],"id":44621159},{"bdatb":[[5,6.2,28.04],[6,6,218.14]],"id":44836671},{"bdatb":[[8,8,3.21],[9,7.8,5.16]],"id":43885158}]}]}
{"op":"mcm","clk":"ANXAAQCgYACnqgE=","pt":1659347766898,"mc":[{"id":"1.201590187","rc":[{"atl":[[2.24,5]],"id":9570503},{"atl":[[1000,0]],"id":46969227}]}]}
{"op":"mcm","clk":"ANXAAQCgYACrqgE=","pt":1659347766948,"mc":[{"id":"1.201590187","rc":[{"bdatl":[[3,2.24,5],[4,2.26,7.02],[5,2.28,1.17],[6,2.32,13.99],[7,2.34,2.86],[8,2.36,6.8],[9,2.38,3.16]],"id":9570503}]}]}
{"op":"mcm","clk":"ANzAAQCjYACsqgE=","pt":1659347767010,"mc":[{"id":"1.201590187","rc":[{"atb":[[24,3.89]],"id":44621159},{"atl":[[22,3.98]],"id":46969227}]}]}
{"op":"mcm","clk":"ANzAAQCjYACwqgE=","pt":1659347767060,"mc":[{"id":"1.201590187","rc":[{"bdatb":[[9,9,14.55]],"id":45323444},{"bdatb":[[9,1.95,6.37]],"id":9570503},{"bdatb":[[4,24,3.89],[5,23,3.56],[6,22,1.76],[7,21,5],[8,20,1.76],[9,19.5,1.76]],"id":44621159},{"bdatl":[[0,22,3.98]],"id":46969227}]}]}
{"op":"mcm","clk":"AODAAQCmYACxqgE=","pt":1659347767110,"mc":[{"id":"1.201590187","rc":[{"atb":[[6.6,4.86],[6.8,0]],"trd":[[6.6,3.18],[6.8,31.59]],"ltp":6.6,"tv":159.8,"id":12989514},{"atb":[[25,1.33]],"id":44621159}],"tv":2087.07}]}
{"op":"mcm","clk":"AOHAAQCoYAC1qgE=","pt":1659347767161,"mc":[{"id":"1.201590187","rc":[{"bdatl":[[4,2.26,7],[5,2.32,13.83],[6,2.34,4.19],[7,2.36,6.8],[8,2.38,3.16],[9,2.4,1.01]],"id":9570503},{"bdatb":[[0,6.6,4.86]],"id":12989514},{"bdatb":[[3,25,1.33]],"id":44621159}]}]}
{"op":"mcm","clk":"APLAAQCvYAC/qgE=","pt":1659347767413,"mc":[{"id":"1.201590187","rc":[{"atb":[[23,1.76]],"id":44621159}]}]}
{"op":"mcm","clk":"APPAAQCwYADBqgE=","pt":1659347767463,"mc":[{"id":"1.201590187","rc":[{"bdatb":[[5,23,1.76]],"id":44621159}]}]}
{"op":"mcm","clk":"APrAAQCyYADEqgE=","pt":1659347767513,"mc":[{"id":"1.201590187","rc":[{"atb":[[22,3.56]],"id":44621159}]}]}
{"op":"mcm","clk":"AP3AAQCzYADFqgE=","pt":1659347767563,"mc":[{"id":"1.201590187","rc":[{"bdatb":[[6,22,3.56]],"id":44621159}]}]}
{"op":"mcm","clk":"AKbBAQDHYADmqgE=","pt":1659347768096,"mc":[{"id":"1.201590187","rc":[{"atl":[[2.22,5]],"id":9570503},{"atl":[[7.8,4.74],[7,4]],"id":12989514},{"atl":[[28,7.55],[26,10.1]],"id":46969227}]}]}
{"op":"mcm","clk":"AKfBAQDIYADvqgE=","pt":1659347768146,"mc":[{"id":"1.201590187","rc":[{"bdatb":[[2,11,2.78],[3,10.5,11.97],[4,10,14.94],[9,9,14.7]],"id":45323444},{"bdatb":[[3,2.02,48.85],[4,2,99.69],[6,1.98,83.43],[9,1.95,7.05]],"bdatl":[[3,2.22,5],[4,2.24,5],[5,2.26,7],[6,2.32,13.83],[7,2.34,4.19],[8,2.36,6.8],[9,2.38,3.16]],"id":9570503},{"bdatl":[[0,7,4],[1,7.2,11.86],[2,7.4,10.43],[3,7.6,32.3],[4,7.8,4.74],[5,8,1.76],[6,8.2,1.76],[7,8.4,4],[8,8.6,1.76],[9,8.8,1.76]],"id":12989514},{"bdatb":[[5,6.2,28.17],[6,6,220.2],[7,5.9,13.35]],"id":44836671},{"bdatb":[[7,8.2,3.47],[9,7.8,3.36]],"id":43885158},{"bdatb":[[7,14,2.76],[8,13.5,1.83],[9,13,1.76]],"bdatl":[[4,26,10.1],[6,28,7.55]],"id":46969227}]}]}
{"op":"mcm","clk":"AK3BAQDKYADvqgE=","pt":1659347768204,"mc":[{"id":"1.201590187","rc":[{"atl":[[7.2,12.57]],"id":12989514},{"atb":[[28,0]],"id":44621159}]}]}
{"op":"mcm","clk":"ALDBAQDMYAD3qgE=","pt":1659347768255,"mc":[{"id":"1.201590187","rc":[{"bdatl":[[7,2.36,4.16],[8,2.38,9.9],[9,2.4,1.01]],"id":9570503},{"bdatl":[[1,7.2,12.57]],"id":12989514},{"bdatb":[[0,27,1.33],[1,26,1.15],[2,25,1.33],[3,24,3.89],[4,23,1.76],[5,22,3.56],[6,21,5],[7,20,1.76],[8,19.5,1.76],[9,19,1.76]],"id":44621159}]}]}
{"op":"mcm","clk":"ALvBAQDQYAD/qgE=","pt":1659347768415,"mc":[{"id":"1.201590187","rc":[{"atb":[[7.2,0.35]],"id":44836671}]}]}
{"op":"mcm","clk":"AL7BAQDSYACGqwE=","pt":1659347768465,"mc":[{"id":"1.201590187","rc":[{"bdatl":[[6,2.32,1.11],[7,2.34,7.8],[8,2.38,4.73],[9,2.4,4.09]],"id":9570503},{"bdatb":[[0,7,2.97],[1,6.8,18.54],[2,6.6,7.16],[3,6.4,1.76],[4,6.2,28.17],[5,6,220.2],[6,5.9,13.35],[7,5.8,10],[8,5.7,98.94],[9,5.6,12.46]],"id":44836671}]}]}
{"op":"mcm","clk":"AMXBAQDUYACHqwE=","pt":1659347768520,"mc":[{"id":"1.201590187","rc":[{"atb":[[10,10]],"id":45323444}]}]}
{"op":"mcm","clk":"AMnBAQDcYACUqwE=","pt":1659347768776,"mc":[{"id":"1.201590187","rc":[{"bdatb":[[9,9,14.79],[4,10,12.56]],"id":45323444},{"bdatb":[[9,1.95,7.46]],"id":9570503},{"bdatb":[[4,6.2,8.16]],"id":44836671},{"bdatl":[[2,11.5,12.4],[3,12,1.76]],"id":43885158}]}]}
{"op":"mcm","clk":"ANvBAQDfYACcqwE=","pt":1659347768827,"mc":[{"id":"1.201590187","rc":[{"atb":[[2,0]],"atl":[[7,3.97]],"trd":[[7,45.4]],"bdatl":[[0,7,3.97]],"ltp":7,"tv":159.86,"id":12989514},{"atb":[[6.2,5.77]],"bdatb":[[5,6,220.17],[6,5.9,13.38]],"id":44836671},{"atl":[[12,1.76],[11.5,12.4]],"bdatb":[[8,8,3.19],[9,7.8,3.39]],"id":43885158},{"bdatb":[[3,10.5,11.95],[4,10,12.58]],"id":45323444},{"bdatb":[[4,2,99.59],[6,1.98,83.53]],"id":9570503}],"con":true,"tv":2087.13}]}
{"op":"mcm","clk":"AODBAQDhYACdqwE=","pt":1659347768877,"mc":[{"id":"1.201590187","rc":[{"atb":[[28,2.07],[22,1.76]],"id":44621159},{"atb":[[7,0.35]],"id":44836671}]}]}
{"op":"mcm","clk":"AOLBAQDhYAChqwE=","pt":1659347768927,"mc":[{"id":"1.201590187","rc":[{"bdatl":[[7,2.34,1.05],[8,2.36,11.47],[9,2.4,10.77]],"id":9570503},{"bdatb":[[0,28,2.07],[1,27,1.33],[2,26,1.15],[3,25,1.33],[4,24,3.89],[5,23,1.76],[6,22,1.76],[7,21,5],[8,20,1.76],[9,19.5,1.76]],"id":44621159},{"bdatb":[[0,6.8,19.25],[1,6.6,7.16],[2,6.4,1.76],[3,6.2,8.16],[4,6,220.17],[5,5.9,13.38],[6,5.8,10],[7,5.7,98.94],[8,5.6,12.46],[9,5.5,13.9]],"id":44836671}]}]}
{"op":"mcm","clk":"AOfBAQDjYAChqwE=","pt":1659347768977,"mc":[{"id":"1.201590187","rc":[{"atb":[[2.04,14.92]],"atl":[[2.18,14.53]],"id":9570503},{"atl":[[7.4,8.17],[7.2,14.88]],"id":12989514},{"atb":[[20,3.56]],"id":44621159},{"atb":[[6.8,20.95]],"atl":[[7.8,7.34],[7.6,48.45]],"id":44836671},{"atb":[[9.4,6.3],[8.8,0.64]],"id":43885158}]}]}
{"op":"mcm","clk":"AOnBAQDlYACqqwE=","pt":1659347769027,"mc":[{"id":"1.201590187","rc":[{"bdatb":[[2,2.04,14.92]],"bdatl":[[2,2.18,14.53]],"id":9570503},{"bdatl":[[1,7.2,14.88],[2,7.4,8.17]],"id":12989514},{"bdatb":[[8,20,3.56]],"id":44621159},{"bdatb":[[0,6.8,21.66]],"bdatl":[[0,7.6,48.45],[1,7.8,7.34]],"id":44836671},{"bdatb":[[1,9.4,6.3],[4,8.6,21.52],[5,8.4,3.76],[6,8.2,3.47],[7,8,3.19],[8,7.8,3.39],[9,7.6,5.51]],"id":43885158}]}]}
{"op":"mcm","clk":"AO/BAQDmYACrqwE=","pt":1659347769089,"mc":[{"id":"1.201590187","rc":[{"atb":[[7.2,0]],"id":44836671}]}]}
{"op":"mcm","clk":"APDBAQDmYACxqwE=","pt":1659347769139,"mc":[{"id":"1.201590187","rc":[{"bdatl":[[6,2.34,1.07],[7,2.36,12.53],[8,2.4,10.77],[9,2.42,3.11]],"id":9570503},{"bdatb":[[0,6.8,21.31]],"id":44836671}]}]}
{"op":"mcm","clk":"AIHCAQDvYAC/qwE=","pt":1659347769392,"mc":[{"id":"1.201590187","rc":[{"atl":[[1000,2]],"id":45323444},{"atl":[[1000,4]],"id":44621159},{"atl":[[1000,2]],"id":46969227}]}]}
{"op":"mcm","clk":"AIPCAQDvYADCqwE=","pt":1659347769443,"mc":[{"id":"1.201590187","rc":[{"bdatl":[[7,1000,4]],"id":44621159}]}]}
{"op":"mcm","clk":"AIvCAQDzYADDqwE=","pt":1659347769507,"mc":[{"id":"1.201590187","rc":[{"atl":[[2.18,10.05]],"id":9570503},{"atb":[[9,0]],"id":43885158}]}]}
{"op":"mcm","clk":"AIvCAQDzYADKqwE=","pt":1659347769557,"mc":[{"id":"1.201590187","rc":[{"bdatl":[[2,2.18,10.05]],"id":9570503},{"bdatb":[[3,8.6,21.52],[4,8.4,3.76],[5,8.2,3.47],[6,8,3.19],[7,7.8,3.39],[8,7.6,5.51],[9,7.4,2.67]],"id":43885158}]}]}
{"op":"mcm","clk":"AI/CAQDzYADLqwE=","pt":1659347769608,"mc":[{"id":"1.201590187","rc":[{"atl":[[1000,0.01]],"id":45323444},{"atl":[[1000,2.01],[38,0.46],[36,3.48]],"id":44621159},{"atb":[[9.6,4.31]],"id":43885158},{"atl":[[1000,0.01]],"id":46969227}]}]}
{"op":"mcm","clk":"AJLCAQDzYADPqwE=","pt":1659347769659,"mc":[{"id":"1.201590187","rc":[{"bdatl":[[0,36,3.89],[1,40,3.73],[2,80,2.96],[3,170,2],[4,900,1.14],[5,990,1.83],[6,1000,2.01],[7,0,0]],"id":44621159},{"bdatb":[[1,9.6,4.31],[2,9.4,6.3],[3,9.2,1.76],[4,8.6,21.52],[5,8.4,3.76],[6,8.2,3.47],[7,8,3.19],[8,7.8,3.39],[9,7.6,5.51]],"id":43885158}]}]}
{"op":"mcm","clk":"AJ3CAQD4YADVqwE=","pt":1659347769812,"mc":[{"id":"1.201590187","rc":[{"atl":[[1000,0]],"id":45323444},{"atl":[[1000,2]],"id":44621159},{"atl":[[1000,0],[23,4.16]],"id":46969227}]}]}
{"op":"mcm","clk":"AKPCAQD5YADbqwE=","pt":1659347769862,"mc":[{"id":"1.201590187","rc":[{"bdatl":[[6,1000,2]],"id":44621159},{"bdatl":[[1,23,4.16]],"id":46969227}]}]}
{"op":"mcm","clk":"AKXCAQD5YADcqwE=","pt":1659347769912,"mc":[{"id":"1.201590187","rc":[{"atl":[[900,0.23]],"id":45323444},{"atl":[[900,0.23]],"id":44621159},{"atl":[[900,0.23]],"id":46969227}]}]}
{"op":"mcm","clk":"AKjCAQD6YADgqwE=","pt":1659347769962,"mc":[{"id":"1.201590187","rc":[{"bdatl":[[4,900,1.15]],"id":44621159}]}]}
{"op":"mcm","clk":"AKnCAQD6YADhqwE=","pt":1659347770013,"mc":[{"id":"1.201590187","rc":[{"atb":[[8.8,2.4]],"id":43885158}]}]}
{"op":"mcm","clk":"AKvCAQD9YADlqwE=","pt":1659347770063,"mc":[{"id":"1.201590187","rc":[{"bdatb":[[4,8.8,2.4],[5,8.6,20.88],[6,8.4,3.76],[7,8.2,3.47],[8,8,3.19],[9,7.8,3.39]],"id":43885158}]}]}
{"op":"mcm","clk":"AMnCAQCNYQCArAE=","pt":1659347770500,"mc":[{"id":"1.201590187","rc":[{"atl":[[7.2,11.02]],"id":12989514},{"atl":[[8,13.03]],"id":44836671},{"atb":[[9.4,2.3]],"id":43885158},{"atb":[[17,2]],"id":46969227}]}]}
{"op":"mcm","clk":"AMnCAQCNYQCFrAE=","pt":1659347770550,"mc":[{"id":"1.201590187","rc":[{"bdatl":[[8,2.4,9.18],[9,2.42,4.69]],"id":9570503},{"bdatl":[[1,7.2,11.02]],"id":12989514},{"bdatl":[[2,8,13.03]],"id":44836671},{"bdatb":[[2,9.4,2.3]],"id":43885158},{"bdatb":[[1,17,2]],"id":46969227}]}]}
{"op":"mcm","clk":"AM7CAQCQYQCGrAE=","pt":1659347770600,"mc":[{"id":"1.201590187","rc":[{"atb":[[7,1.5],[6.8,24.95]],"atl":[[7.8,10.34]],"id":44836671},{"atl":[[10.5,2.56]],"id":43885158}]}]}
{"op":"mcm","clk":"AM7CAQCQYQCKrAE=","pt":1659347770650,"mc":[{"id":"1.201590187","rc":[{"bdatb":[[2,11,3.88],[3,10.5,10.8],[4,10,13.79],[6,9.6,21.33]],"id":45323444},{"bdatb":[[3,2.02,54.83],[4,2,93.55],[6,1.98,89.63],[8,1.96,8.08]],"bdatl":[[6,2.34,4.5],[7,2.36,9.13]],"id":9570503},{"bdatb":[[5,5.8,37.53],[6,5.7,226.15],[7,5.6,6.28],[8,5.5,2.34]],"id":12989514},{"bdatb":[[0,7,1.51],[1,6.8,24.95],[2,6.6,7.16],[3,6.4,1.76],[4,6.2,10.1],[5,6,218.15],[6,5.9,15.43],[7,5.8,10],[8,5.7,96.82],[9,5.6,12.46]],"bdatl":[[1,7.8,10.34]],"id":44836671},{"bdatl":[[0,10.5,2.56]],"id":43885158},{"bdatb":[[8,13.5,2.72]],"id":46969227}]}]}
{"op":"mcm","clk":"ANHCAQCWYQCLrAE=","pt":1659347770702,"mc":[{"id":"1.201590187","rc":[{"atb":[[26,0]],"id":44621159},{"atb":[[9.6,4.81]],"atl":[[10.5,1.41]],"id":43885158},{"atb":[[17.5,0]],"atl":[[23,3.01]],"id":46969227}]}]}
{"op":"mcm","clk":"ANLCAQCXYQCSrAE=","pt":1659347770752,"mc":[{"id":"1.201590187","rc":[{"bdatb":[[2,11,2.78],[3,10.5,11.95],[4,10,12.58],[6,9.6,22.59]],"id":45323444},{"bdatb":[[3,2.02,48.85],[4,2,99.59],[6,1.98,83.53],[8,1.96,14.23]],"bdatl":[[8,2.4,4.09],[9,2.42,9.74]],"id":9570503},{"bdatb":[[5,5.8,35.45],[6,5.7,228.26],[7,5.6,4.12],[8,5.5,4.54]],"id":12989514},{"bdatb":[[2,25,1.33],[3,24,3.89],[4,23,1.76],[5,22,1.76],[6,21,5],[7,20,3.56],[8,19.5,1.76],[9,19,1.76]],"id":44621159},{"bdatb":[[4,6.2,8.16],[5,6,220.17],[6,5.9,13.38],[8,5.7,98.94]],"id":44836671},{"bdatb":[[1,9.6,4.81]],"bdatl":[[0,10.5,1.41]],"id":43885158},{"bdatb":[[0,17,2],[1,16.5,7.96],[2,16,8],[3,15.5,6.76],[4,15,5.76],[5,14.5,1.76],[6,14,2.76],[7,13.5,1.83],[8,13,1.76],[9,12.5,1.04]],"bdatl":[[1,23,3.01]],"id":46969227}]}]}
{"op":"mcm","clk":"ANXCAQCcYQCTrAE=","pt":1659347770802,"mc":[{"id":"1.201590187","rc":[{"atb":[[28,0]],"id":44621159}]}]}
{"op":"mcm","clk":"ANfCAQCcYQCZrAE=","pt":1659347770852,"mc":[{"id":"1.201590187","rc":[{"bdatl":[[7,2.38,9.05],[8,2.4,1.57],[9,2.42,2.5]],"id":9570503},{"bdatb":[[0,27,1.33],[1,25,1.33],[2,24,3.89],[3,23,1.76],[4,22,1.76],[5,21,5],[6,20,3.56],[7,19.5,1.76],[8,19,1.76],[9,18.5,2.7]],"id":44621159}]}]}
{"op":"mcm","clk":"AOfCAQCkYQCtrAE=","pt":1659347771124,"mc":[{"id":"1.201590187","rc":[{"atb":[[2.04,18.7]],"atl":[[2.18,13.66]],"id":9570503},{"atb":[[6.4,18.8]],"atl":[[7.2,13.46]],"id":12989514},{"atb":[[6.8,27.21]],"atl":[[7.6,50.65]],"id":44836671},{"atb":[[9.6,6.98]],"id":43885158}]}]}
{"op":"mcm","clk":"AOzCAQClYQCyrAE=","pt":1659347771175,"mc":[{"id":"1.201590187","rc":[{"bdatb":[[2,2.04,18.7]],"bdatl":[[2,2.18,13.66]],"id":9570503},{"bdatb":[[1,6.4,18.8]],"bdatl":[[1,7.2,13.46]],"id":12989514},{"bdatb":[[1,6.8,27.21]],"bdatl":[[0,7.6,50.65]],"id":44836671},{"bdatb":[[1,9.6,6.98]],"id":43885158}]}]}
{"op":"mcm","clk":"AITDAQCsYQDBrAE=","pt":1659347771480,"mc":[{"id":"1.201590187","rc":[{"atb":[[25,3.63]],"id":44621159}]}]}
{"op":"mcm","clk":"AIXDAQCvYQDDrAE=","pt":1659347771530,"mc":[{"id":"1.201590187","rc":[{"bdatb":[[1,25,3.63]],"id":44621159}]}]}
{"op":"mcm","clk":"AJTDAQC2YQDSrAE=","pt":1659347771700,"mc":[{"id":"1.201590187","rc":[{"atb":[[3.9,44.48],[6.4,16.07]],"id":12989514},{"atb":[[5.7,79.02]],"id":44836671},{"atb":[[6.6,30.24]],"id":43885158},{"atb":[[8.8,31.6]],"id":46969227}]}]}
{"op":"mcm","clk":"AJXDAQC2YQDVrAE=","pt":1659347771750,"mc":[{"id":"1.201590187","rc":[{"bdatb":[[1,6.4,16.07]],"id":12989514},{"bdatb":[[8,5.7,81.7]],"id":44836671}]}]}
{"op":"mcm","clk":"ALrDAQDMYQD2rAE=","pt":1659347772300,"mc":[{"id":"1.201590187","rc":[{"atb":[[25,1.33]],"id":44621159}]}]}
{"op":"mcm","clk":"AMLDAQDRYQD3rAE=","pt":1659347772350,"mc":[{"id":"1.201590187","rc":[{"bdatb":[[1,25,1.33]],"id":44621159}]}]}
{"op":"mcm","clk":"AMfDAQDSYQD+rAE=","pt":1659347772424,"mc":[{"id":"1.201590187","rc":[{"atl":[[900,0.22]],"id":45323444},{"atl":[[900,0.22]],"id":44621159},{"atl":[[900,0.22]],"id":46969227}]}]}
{"op":"mcm","clk":"AMfDAQDSYQCBrQE=","pt":1659347772474,"mc":[{"id":"1.201590187","rc":[{"bdatl":[[4,900,1.14]],"id":44621159}]}]}
{"op":"mcm","clk":"AMrDAQDXYQCCrQE=","pt":1659347772525,"mc":[{"id":"1.201590187","rc":[{"atl":[[15.5,0.01]],"id":45323444},{"atb":[[26,2.18]],"atl":[[32,0.01]],"id":44621159},{"atl":[[21,0.01]],"id":46969227}]}]}
{"op":"mcm","clk":"ANDDAQDbYQCFrQE=","pt":1659347772575,"mc":[{"id":"1.201590187","rc":[{"bdatb":[[9,9,14.81]],"bdatl":[[0,16,2.54]],"id":45323444},{"bdatb":[[2,2.04,18.81],[3,2.02,48.75],[8,1.96,14.31],[9,1.95,7.49]],"id":9570503},{"bdatb":[[3,6,1.8],[4,5.9,4.15],[5,5.8,35.4],[6,5.7,228.29],[7,5.6,4.09]],"id":12989514},{"bdatb":[[1,26,2.18],[2,25,1.33],[3,24,3.89],[4,23,1.76],[5,22,1.76],[6,21,5],[7,20,3.56],[8,19.5,1.77],[9,19,1.76]],"bdatl":[[0,36,3.9]],"id":44621159},{"bdatb":[[2,6.6,7.18],[3,6.4,1.79],[4,6.2,8.1]],"id":44836671},{"bdatb":[[5,8.6,20.9],[6,8.4,3.77],[7,8.2,3.48],[8,8,3.15],[9,7.8,3.41]],"id":43885158},{"bdatb":[[5,14.5,1.77],[6,14,2.77],[7,13.5,1.8]],"bdatl":[[0,22,3.99]],"id":46969227}]}]}
{"op":"mcm","clk":"ANPDAQDbYQCNrQE=","pt":1659347772625,"mc":[{"id":"1.201590187","rc":[{"atl":[[22,3.57]],"bdatl":[[0,22,3.58]],"id":46969227},{"bdatb":[[9,9,13.81]],"id":45323444},{"bdatb":[[9,1.95,3.33]],"id":9570503}]}]}
{"op":"mcm","clk":"ANTDAQDeYQCPrQE=","pt":1659347772675,"mc":[{"id":"1.201590187","rc":[{"atl":[[26,10]],"id":46969227}]}]}
{"op":"mcm","clk":"ANXDAQDfYQCPrQE=","pt":1659347772725,"mc":[{"id":"1.201590187","rc":[{"bdatl":[[4,26,10]],"id":46969227}]}]}
{"op":"mcm","clk":"AOTDAQDnYQCXrQE=","pt":1659347772893,"mc":[{"id":"1.201590187","rc":[{"atb":[[9.6,2.67]],"id":43885158}]}]}
{"op":"mcm","clk":"AOTDAQDnYQCarQE=","pt":1659347772943,"mc":[{"id":"1.201590187","rc":[{"bdatb":[[1,9.6,2.67]],"id":43885158}]}]}
{"op":"mcm","clk":"AOXDAQDpYQCbrQE=","pt":1659347772993,"mc":[{"id":"1.201590187","rc":[{"atl":[[2.2,7]],"bdatl":[[3,2.2,7],[4,2.22,5],[5,2.24,5],[6,2.26,7],[7,2.34,4.5],[8,2.38,9.05],[9,2.4,1.57]],"id":9570503},{"atb":[[4.2,17.24]],"id":12989514},{"atb":[[5.7,96.26]],"bdatb":[[8,5.7,98.94]],"id":44836671},{"atb":[[9.4,6.61]],"bdatb":[[2,9.4,6.61]],"id":43885158}]}]}
{"op":"mcm","clk":"APHDAQDvYQChrQE=","pt":1659347773099,"mc":[{"id":"1.201590187","rc":[{"atb":[[6.6,47.48]],"id":43885158}]}]}
{"op":"mcm","clk":"AP3DAQD1YQCrrQE=","pt":1659347773310,"mc":[{"id":"1.201590187","rc":[{"atb":[[26,0]],"id":44621159}]}]}
{"op":"mcm","clk":"AIHEAQD1YQCurQE=","pt":1659347773360,"mc":[{"id":"1.201590187","rc":[{"bdatb":[[1,25,1.33],[2,24,3.89],[3,23,1.76],[4,22,1.76],[5,21,5],[6,20,3.56],[7,19.5,1.77],[8,19,1.76],[9,18.5,2.7]],"id":44621159}]}]}
{"op":"mcm","clk":"AIbEAQD4YQCurQE=","pt":1659347773414,"mc":[{"id":"1.201590187","rc":[{"atb":[[8.8,40.22]],"id":46969227}]}]}
{"op":"mcm","clk":"AInEAQD4YQC1rQE=","pt":1659347773502,"mc":[{"id":"1.201590187","rc":[{"atb":[[27,3.45]],"id":44621159}]}]}
{"op":"mcm","clk":"AI3EAQD6YQC5rQE=","pt":1659347773552,"mc":[{"id":"1.201590187","rc":[{"bdatl":[[9,2.4,4.09]],"id":9570503},{"bdatb":[[0,27,3.45]],"id":44621159}]}]}
{"op":"mcm","clk":"AKHEAQCFYgDKrQE=","pt":1659347773880,"mc":[{"id":"1.201590187","rc":[{"atl":[[23,2.22]],"id":46969227}]}]}
{"op":"mcm","clk":"AKnEAQCJYgDPrQE=","pt":1659347773985,"mc":[{"id":"1.201590187","rc":[{"atl":[[22,4.36]],"id":46969227}]}]}
{"op":"mcm","clk":"AKvEAQCJYgDXrQE=","pt":1659347774071,"mc":[{"id":"1.201590187","rc":[{"bdatl":[[1,23,2.22]],"id":46969227}]}]}
{"op":"mcm","clk":"ALXEAQCPYgDerQE=","pt":1659347774197,"mc":[{"id":"1.201590187","rc":[{"atb":[[27,1.33]],"id":44621159}]}]}
{"op":"mcm","clk":"ALvEAQCRYgDprQE=","pt":1659347774355,"mc":[{"id":"1.201590187","rc":[{"bdatb":[[9,9,15.74]],"id":45323444},{"bdatb":[[9,1.95,11.8]],"id":9570503},{"bdatl":[[0,22,4.37]],"id":46969227}]}]}
{"op":"mcm","clk":"AMDEAQCSYgDurQE=","pt":1659347774425,"mc":[{"id":"1.201590187","rc":[{"bdatl":[[9,2.4,1.57]],"id":9570503},{"bdatb":[[0,27,1.33]],"id":44621159}]}]}
{"op":"mcm","clk":"AMvEAQCUYgD1rQE=","pt":1659347774608,"mc":[{"id":"1.201590187","rc":[{"atb":[[17,4]],"id":46969227}]}]}
{"op":"mcm","clk":"AMzEAQCVYgD3rQE=","pt":1659347774659,"mc":[{"id":"1.201590187","rc":[{"bdatb":[[0,17,4]],"id":46969227}]}]}
{"op":"mcm","clk":"APXEAQCuYgCkrgE=","pt":1659347775387,"mc":[{"id":"1.201590187","rc":[{"atb":[[25,3.63]],"id":44621159},{"atl":[[7.6,25.37]],"trd":[[7.6,261.92]],"tv":506.55,"id":44836671}],"tv":2137.69}]}
{"op":"mcm","clk":"APbEAQCvYgCorgE=","pt":1659347775438,"mc":[{"id":"1.201590187","rc":[{"bdatb":[[1,25,3.63]],"id":44621159},{"bdatl":[[0,7.6,25.37]],"id":44836671}]}]}
{"op":"mcm","clk":"APvEAQCwYgCorgE=","pt":1659347775489,"mc":[{"id":"1.201590187","rc":[{"atl":[[36,2.48]],"id":44621159}]}]}
{"op":"mcm","clk":"AP3EAQCyYgCvrgE=","pt":1659347775539,"mc":[{"id":"1.201590187","rc":[{"bdatl":[[0,36,2.9]],"id":44621159}]}]}
{"op":"mcm","clk":"AIbFAQC1YgC0rgE=","pt":1659347775695,"mc":[{"id":"1.201590187","rc":[{"atb":[[1.01,48]],"id":43885158}]}]}
{"op":"mcm","clk":"AIzFAQC2YgC6rgE=","pt":1659347775799,"mc":[{"id":"1.201590187","rc":[{"atb":[[25,2.63]],"id":44621159},{"atb":[[8.6,20]],"id":43885158}]}]}
{"op":"mcm","clk":"AI7FAQC2YgDBrgE=","pt":1659347775849,"mc":[{"id":"1.201590187","rc":[{"bdatb":[[1,25,2.63]],"id":44621159},{"bdatb":[[5,8.6,20.02]],"id":43885158}]}]}
{"op":"mcm","clk":"AJbFAQC6YgDJrgE=","pt":1659347776007,"mc":[{"id":"1.201590187","rc":[{"atb":[[1.01,46.31]],"id":43885158}]}]}
{"op":"mcm","clk":"AJ7FAQC/YgDTrgE=","pt":1659347776118,"mc":[{"id":"1.201590187","rc":[{"atb":[[25,0.33]],"id":44621159}]}]}
{"op":"mcm","clk":"AKDFAQC/YgDWrgE=","pt":1659347776168,"mc":[{"id":"1.201590187","rc":[{"bdatb":[[1,24,4.22],[2,23,1.76],[3,22,1.76],[4,21,5],[5,20,3.56],[6,19.5,1.77],[7,19,1.76],[8,18.5,2.7],[9,18,2.57]],"id":44621159}]}]}
{"op":"mcm","clk":"AKTFAQDAYgDWrgE=","pt":1659347776218,"mc":[{"id":"1.201590187","rc":[{"atb":[[26,2.18]],"id":44621159}]}]}
{"op":"mcm","clk":"AKbFAQDBYgDcrgE=","pt":1659347776268,"mc":[{"id":"1.201590187","rc":[{"bdatl":[[9,2.4,4.09]],"id":9570503},{"bdatb":[[1,26,2.18],[2,24,4.22],[3,23,1.76],[4,22,1.76],[5,21,5],[6,20,3.56],[7,19.5,1.77],[8,19,1.76],[9,18.5,2.7]],"id":44621159}]}]}
{"op":"mcm","clk":"AKzFAQDEYgDhrgE=","pt":1659347776425,"mc":[{"id":"1.201590187","rc":[{"atb":[[1.01,45.55]],"id":43885158}]}]}
{"op":"mcm","clk":"ALHFAQDIYgDnrgE=","pt":1659347776483,"mc":[{"id":"1.201590187","rc":[{"atb":[[7.4,0]],"id":44836671},{"atb":[[9.8,0],[10,0.76]],"id":43885158}]}]}
{"op":"mcm","clk":"ALLFAQDIYgDorgE=","pt":1659347776534,"mc":[{"id":"1.201590187","rc":[{"bdatl":[[7,2.34,3.25],[8,2.36,1.22],[9,2.38,9.07]],"id":9570503},{"bdatb":[[0,7,1.5]],"id":44836671},{"bdatb":[[0,9.6,3.43],[1,9.4,6.61],[2,9.2,1.76],[3,8.8,2.4],[4,8.6,20.02],[5,8.4,3.77],[6,8.2,3.48],[7,8,3.15],[8,7.8,3.41],[9,7.6,5.49]],"id":43885158}]}]}
{"op":"mcm","clk":"AM7FAQDWYgCIrwE=","pt":1659347777006,"mc":[{"id":"1.201590187","rc":[{"atb":[[26,0]],"id":44621159}]}]}
{"op":"mcm","clk":"ANDFAQDWYgCOrwE=","pt":1659347777056,"mc":[{"id":"1.201590187","rc":[{"bdatb":[[1,24,4.22],[2,23,1.76],[3,22,1.76],[4,21,5],[5,20,3.56],[6,19.5,1.77],[7,19,1.76],[8,18.5,2.7],[9,18,2.57]],"id":44621159}]}]}
{"op":"mcm","clk":"ANfFAQDYYgCQrwE=","pt":1659347777111,"mc":[{"id":"1.201590187","rc":[{"atb":[[27,3.45]],"id":44621159},{"atl":[[10.5,2.56]],"id":43885158},{"atb":[[17.5,1.15]],"id":46969227}]}]}
{"op":"mcm","clk":"ANrFAQDYYgCUrwE=","pt":1659347777161,"mc":[{"id":"1.201590187","rc":[{"bdatb":[[2,11,3.88],[3,10.5,10.8],[4,10,13.79],[6,9.6,21.33]],"id":45323444},{"bdatb":[[3,2.02,54.72],[4,2,93.55],[6,1.98,89.63],[8,1.96,8.16]],"bdatl":[[7,2.32,3.28]],"id":9570503},{"bdatb":[[5,5.8,37.48],[6,5.7,226.17],[7,5.6,6.25],[8,5.5,2.34]],"id":12989514},{"bdatb":[[0,27,3.45],[9,18,3.24]],"id":44621159},{"bdatb":[[4,6.2,10.05],[5,6,218.15],[6,5.9,15.43],[8,5.7,96.82]],"id":44836671},{"bdatl":[[0,10.5,2.56]],"id":43885158},{"bdatb":[[0,17.5,1.15],[1,17,4],[2,16.5,7.96],[3,16,8],[4,15.5,6.76],[5,15,5.76],[6,14.5,1.77],[7,14,2.77],[8,13.5,2.7],[9,13,1.76]],"id":46969227}]}]}
{"op":"mcm","clk":"AN7FAQDcYgCWrwE=","pt":1659347777223,"mc":[{"id":"1.201590187","rc":[{"atb":[[7,0.35]],"id":44836671},{"atl":[[10.5,1.41]],"id":43885158}]}]}
{"op":"mcm","clk":"AODFAQDfYgCbrwE=","pt":1659347777273,"mc":[{"id":"1.201590187","rc":[{"bdatb":[[2,11,2.78],[3,10.5,11.95],[4,10,12.58],[6,9.6,22.59]],"id":45323444},{"bdatb":[[3,2.02,48.75],[4,2,99.59],[6,1.98,83.53],[8,1.96,14.31]],"bdatl":[[7,2.32,1.06],[8,2.36,2.18],[9,2.38,10.28]],"id":9570503},{"bdatb":[[5,5.8,35.4],[6,5.7,228.29],[7,5.6,4.09],[8,5.5,4.54]],"id":12989514},{"bdatb":[[9,18,2.57]],"id":44621159},{"bdatb":[[0,6.8,27.56],[1,6.6,7.18],[2,6.4,1.79],[3,6.2,8.1],[4,6,220.17],[5,5.9,13.38],[6,5.8,10],[7,5.7,98.94],[8,5.6,12.46],[9,5.5,13.93]],"id":44836671},{"bdatl":[[0,10.5,1.41]],"id":43885158},{"bdatb":[[8,13.5,1.8]],"id":46969227}]}]}
{"op":"mcm","clk":"AOzFAQDjYgCgrwE=","pt":1659347777416,"mc":[{"id":"1.201590187","rc":[{"atl":[[8.4,3],[7.6,33.37],[8.2,2.07]],"id":44836671}]}]}
{"op":"mcm","clk":"AOzFAQDmYgCjrwE=","pt":1659347777466,"mc":[{"id":"1.201590187","rc":[{"bdatl":[[0,7.6,33.37],[3,8.2,2.07],[4,8.4,3]],"id":44836671}]}]}
{"op":"mcm","clk":"AP/FAQDxYgC+rwE=","pt":1659347777793,"mc":[{"id":"1.201590187","rc":[{"atb":[[12.5,1.35]],"atl":[[16.5,0.18]],"id":45323444},{"atb":[[27,1.33]],"id":44621159},{"atb":[[9.6,0.5]],"id":43885158}]}]}
{"op":"mcm","clk":"AIDGAQDzYgDFrwE=","pt":1659347777844,"mc":[{"id":"1.201590187","rc":[{"bdatb":[[0,12.5,1.35]],"bdatl":[[1,17.5,2.12],[2,18,1.76],[3,18.5,1.76],[4,19,1.76],[5,19.5,1.76],[6,20,1.76],[7,21,1.76],[8,22,4.02],[9,23,1.76]],"id":45323444},{"bdatb":[[6,1.98,78.45],[7,1.97,4.08],[8,1.96,6.2],[9,1.95,14]],"bdatl":[[9,2.38,3.9]],"id":9570503},{"bdatb":[[7,5.6,2.84],[8,5.5,3.04],[9,5.4,4.59]],"id":12989514},{"bdatb":[[0,27,1.33]],"id":44621159},{"bdatb":[[5,5.9,11.67],[6,5.8,10.53],[7,5.7,97.49],[8,5.6,14.72],[9,5.5,13.46]],"id":44836671},{"bdatb":[[0,9.6,1.26],[9,7.6,2.56]],"id":43885158}]}]}
{"op":"mcm","clk":"AITGAQD2YgDGrwE=","pt":1659347777897,"mc":[{"id":"1.201590187","rc":[{"atl":[[7.6,17.44]],"trd":[[7.6,293.79]],"tv":538.42,"id":44836671},{"atb":[[9.4,4.31]],"id":43885158}],"tv":2169.56}]}
{"op":"mcm","clk":"AIbGAQD2YgDHrwE=","pt":1659347777948,"mc":[{"id":"1.201590187","rc":[{"bdatl":[[0,7.6,17.44]],"id":44836671},{"bdatb":[[1,9.4,4.31]],"id":43885158}]}]}
{"op":"mcm","clk":"AIrGAQD6YgDNrwE=","pt":1659347778001,"mc":[{"id":"1.201590187","rc":[{"atb":[[8.8,45.6]],"id":45323444}]}]}
{"op":"mcm","clk":"AJzGAQCEYwDjrwE=","pt":1659347778317,"mc":[{"id":"1.201590187","rc":[{"atb":[[20,1.76]],"id":44621159}]}]}
{"op":"mcm","clk":"AJzGAQCEYwDprwE=","pt":1659347778367,"mc":[{"id":"1.201590187","rc":[{"bdatb":[[5,20,1.76]],"id":44621159}]}]}
{"op":"mcm","clk":"AKHGAQCHYwDprwE=","pt":1659347778422,"mc":[{"id":"1.201590187","rc":[{"atb":[[18.5,4.49]],"id":44621159}]}]}
{"op":"mcm","clk":"AKHGAQCLYwDurwE=","pt":1659347778472,"mc":[{"id":"1.201590187","rc":[{"bdatb":[[8,18.5,4.5]],"id":44621159}]}]}
{"op":"mcm","clk":"AKfGAQCLYwDvrwE=","pt":1659347778534,"mc":[{"id":"1.201590187","rc":[{"atb":[[12.5,5.95]],"id":45323444},{"atb":[[2.08,29.17]],"id":9570503},{"atb":[[7,7.99]],"id":44836671},{"atb":[[8.8,43.1]],"id":46969227}]}]}
{"op":"mcm","clk":"AKrGAQCNYwDyrwE=","pt":1659347778584,"mc":[{"id":"1.201590187","rc":[{"bdatb":[[0,12.5,5.95]],"id":45323444},{"bdatb":[[0,2.08,29.17]],"bdatl":[[7,2.32,3.28],[8,2.36,5.3],[9,2.38,5.03]],"id":9570503},{"bdatb":[[0,7,7.99],[1,6.8,27.21],[2,6.6,7.18],[3,6.4,1.79],[4,6.2,8.1],[5,6,220.17],[6,5.9,11.67],[7,5.8,10.53],[8,5.7,97.49],[9,5.6,14.72]],"id":44836671}]}]}
{"op":"mcm","clk":"AK3GAQCOYwDzrwE=","pt":1659347778635,"mc":[{"id":"1.201590187","rc":[{"atb":[[11,7.02]],"id":45323444},{"atb":[[9,2.87]],"id":43885158},{"atb":[[17,2]],"id":46969227}]}]}
{"op":"mcm","clk":"AK/GAQCRYwD4rwE=","pt":1659347778685,"mc":[{"id":"1.201590187","rc":[{"atb":[[25,2.63]],"id":44621159},{"atl":[[11,6.54]],"bdatb":[[3,9,2.87],[4,8.8,2.4],[5,8.6,20.02],[6,8.4,3.77],[7,8.2,3.48],[8,8,3.15],[9,7.8,3.41]],"id":43885158},{"bdatb":[[2,11,8.58]],"id":45323444},{"bdatb":[[1,17,2]],"id":46969227}]}]}
{"op":"mcm","clk":"ALPGAQCRYwD6rwE=","pt":1659347778736,"mc":[{"id":"1.201590187","rc":[{"bdatb":[[4,10,14.11],[6,9.6,21.27],[7,9.4,11],[8,9.2,13.66],[9,9,14.04]],"id":45323444},{"bdatb":[[8,1.96,23.09],[9,1.95,1.76]],"id":9570503},{"bdatb":[[8,5.5,5.81],[9,5.4,2.24]],"id":12989514},{"bdatb":[[1,25,2.63],[2,24,3.89],[3,23,1.76],[4,22,1.76],[5,21,5],[6,20,1.76],[7,19.5,1.77],[8,19,1.76],[9,18.5,4.5]],"id":44621159},{"bdatb":[[8,5.7,100.17],[9,5.6,12.46]],"id":44836671},{"bdatl":[[1,11,6.54]],"id":43885158}]}]}
{"op":"mcm","clk":"ALXGAQCUYwD/rwE=","pt":1659347778795,"mc":[{"id":"1.201590187","rc":[{"atb":[[10.5,7.84]],"id":45323444}]}]}
{"op":"mcm","clk":"ALbGAQCWYwCAsAE=","pt":1659347778845,"mc":[{"id":"1.201590187","rc":[{"bdatb":[[3,10.5,9.07]],"id":45323444}]}]}
{"op":"mcm","clk":"ALnGAQCZYwCCsAE=","pt":1659347778895,"mc":[{"id":"1.201590187","rc":[{"atb":[[10,14.14]],"atl":[[22,2.58]],"id":45323444},{"atb":[[9.4,0]],"id":43885158}]}]}
{"op":"mcm","clk":"ALrGAQCZYwCHsAE=","pt":1659347778945,"mc":[{"id":"1.201590187","rc":[{"bdatb":[[4,10,18.25]],"bdatl":[[8,22,2.58]],"id":45323444},{"bdatl":[[8,2.36,2.03],[9,2.38,6.82]],"id":9570503},{"bdatb":[[1,9.2,1.76],[2,9,2.87],[3,8.8,2.4],[4,8.6,20.02],[5,8.4,3.77],[6,8.2,3.48],[7,8,3.15],[8,7.8,3.41],[9,7.6,2.56]],"id":43885158}]}]}
{"op":"mcm","clk":"AL/GAQCcYwCHsAE=","pt":1659347778997,"mc":[{"id":"1.201590187","rc":[{"atl":[[23,3.2]],"id":45323444},{"atb":[[8.8,6.71]],"id":43885158}]}]}
{"op":"mcm","clk":"AMHGAQCcYwCKsAE=","pt":1659347779047,"mc":[{"id":"1.201590187","rc":[{"bdatl":[[9,23,3.2]],"id":45323444},{"bdatb":[[3,8.8,6.71]],"id":43885158}]}]}
{"op":"mcm","clk":"AMbGAQChYwCKsAE=","pt":1659347779100,"mc":[{"id":"1.201590187","rc":[{"atb":[[26,0.93]],"id":44621159}]}]}
{"op":"mcm","clk":"AMrGAQChYwCOsAE=","pt":1659347779151,"mc":[{"id":"1.201590187","rc":[{"bdatb":[[1,25,3.56]],"id":44621159}]}]}
{"op":"mcm","clk":"AM/GAQClYwCOsAE=","pt":1659347779202,"mc":[{"id":"1.201590187","rc":[{"atb":[[13,1.87]],"id":45323444}]}]}
{"op":"mcm","clk":"AM/GAQClYwCTsAE=","pt":1659347779252,"mc":[{"id":"1.201590187","rc":[{"bdatb":[[0,13,1.87],[1,12.5,5.95],[2,12,1.96],[3,11,8.58],[4,10.5,9.07],[5,10,18.25],[6,9.8,9],[7,9.6,21.27],[8,9.4,11],[9,9.2,13.66]],"id":45323444},{"bdatl":[[8,2.34,2.05],[9,2.36,5.05]],"id":9570503}]}]}
{"op":"mcm","clk":"ANTGAQCqYwCWsAE=","pt":1659347779311,"mc":[{"id":"1.201590187","rc":[{"atb":[[2.1,11.57]],"id":9570503},{"atb":[[7.2,3.37]],"id":44836671}]}]}
{"op":"mcm","clk":"ANbGAQCsYwCasAE=","pt":1659347779361,"mc":[{"id":"1.201590187","rc":[{"bdatb":[[0,2.1,11.57],[1,2.08,29.17],[2,2.06,48.89],[3,2.04,18.81],[4,2.02,48.75],[5,2,99.59],[6,1.99,1.76],[7,1.98,78.45],[8,1.97,4.08],[9,1.96,23.09]],"bdatl":[[7,2.3,3.31],[8,2.32,2.07],[9,2.34,5.07]],"id":9570503},{"bdatl":[[9,8.8,2.63]],"id":12989514},{"bdatb":[[0,7.2,3.37],[1,7,7.99],[2,6.8,27.21],[3,6.6,7.18],[4,6.4,1.79],[5,6.2,8.1],[6,6,220.17],[7,5.9,11.67],[8,5.8,10.53],[9,5.7,100.17]],"id":44836671}]}]}
{"op":"mcm","clk":"ANvGAQCvYwCdsAE=","pt":1659347779411,"mc":[{"id":"1.201590187","rc":[{"atb":[[9.6,3.03]],"id":43885158}]}]}
{"op":"mcm","clk":"ANvGAQCvYwCisAE=","pt":1659347779462,"mc":[{"id":"1.201590187","rc":[{"bdatl":[[8,2.32,7.18],[9,2.36,3.31]],"id":9570503},{"bdatb":[[0,9.6,3.79]],"id":43885158}]}]}
{"op":"mcm","clk":"AN/GAQCwYwCisAE=","pt":1659347779512,"mc":[{"id":"1.201590187","rc":[{"atb":[[12.5,1.35]],"id":45323444},{"atl":[[2.14,8.99],[2.2,0],[2.26,0],[2.22,0],[2.24,0]],"trd":[[2.14,141.1]],"ltp":2.14,"tv":1213.42,"id":9570503},{"atb":[[25,0.33]],"id":44621159},{"atl":[[8.2,7.07]],"id":44836671},{"atb":[[17.5,2.54]],"id":46969227}],"tv":2215.95}]}
{"op":"mcm","clk":"AODGAQCwYwCpsAE=","pt":1659347779562,"mc":[{"id":"1.201590187","rc":[{"bdatb":[[1,12.5,1.35],[4,10.5,8.26],[5,10,14.39],[7,9.6,21.63],[9,9.2,14.58]],"id":45323444},{"bdatl":[[0,2.14,8.99],[3,2.3,3.31],[4,2.32,7.18],[5,2.36,3.31],[6,2.38,1.95],[7,2.42,3.2],[8,2.44,27.56],[9,2.46,4.8]],"id":9570503},{"bdatb":[[6,5.7,224.54],[7,5.6,1.76],[8,5.5,2.23],[9,5.4,5.8]],"id":12989514},{"bdatb":[[1,25,1.26]],"id":44621159},{"bdatb":[[6,6,218.74],[7,5.9,9.43],[8,5.8,11.03],[9,5.7,96.26]],"bdatl":[[3,8.2,7.07]],"id":44836671},{"bdatb":[[7,8,2.08],[8,7.8,2.09],[9,7.6,2.55]],"id":43885158},{"bdatb":[[0,17.5,2.54]],"id":46969227}]}]}
{"op":"mcm","clk":"AObGAQCzYwCpsAE=","pt":1659347779617,"mc":[{"id":"1.201590187","rc":[{"atl":[[2.14,1.4]],"trd":[[2.14,156.28]],"tv":1228.6,"id":9570503},{"atb":[[6.8,3.57]],"id":12989514}],"tv":2231.13}]}
{"op":"mcm","clk":"AOfGAQC0YwCwsAE=","pt":1659347779668,"mc":[{"id":"1.201590187","rc":[{"bdatb":[[3,11,7.5],[4,10.5,8.08],[5,10,15.06],[7,9.6,22.35],[9,9.2,12.82]],"bdatl":[[9,23,3.53]],"id":45323444},{"bdatl":[[0,2.14,1.4],[3,2.26,3.36],[4,2.28,7.31],[5,2.36,5.28],[6,2.38,1.88],[7,2.4,1.37],[8,2.42,4.91],[9,2.44,24.09]],"id":9570503},{"bdatb":[[0,6.8,3.57],[1,6.6,4.86],[2,6.4,16.07],[3,6.2,5.02],[4,6,1.8],[5,5.9,2.24],[6,5.8,35.31],[7,5.7,224.21],[8,5.6,3.33],[9,5.5,1.86]],"id":12989514},{"bdatl":[[4,900,1.17]],"id":44621159},{"bdatb":[[5,6.2,6.2],[6,6,219.88],[7,5.9,9.09],[8,5.8,12.24]],"id":44836671},{"bdatb":[[6,8.2,2.1],[7,8,1.46],[9,7.6,4.69]],"bdatl":[[9,15,13.62]],"id":43885158},{"bdatb":[[7,14,1.97],[8,13.5,1.76],[9,13,1.96]],"id":46969227}]}]}
{"op":"mcm","clk":"AOzGAQC0YwCwsAE=","pt":1659347779719,"mc":[{"id":"1.201590187","rc":[{"atb":[[11.5,5.21]],"id":45323444},{"atl":[[2.16,0]],"id":9570503},{"atl":[[7,0]],"trd":[[7,53.34]],"tv":167.8,"id":12989514}],"tv":2239.07}]}
{"op":"mcm","clk":"AO7GAQC0YwC4sAE=","pt":1659347779769,"mc":[{"id":"1.201590187","rc":[{"bdatb":[[3,11.5,5.21],[4,11,7.05],[5,10.5,8.09],[6,10,14.14],[7,9.8,10.15],[8,9.6,21.05],[9,9.4,11]],"id":45323444},{"bdatb":[[3,2.04,18.7],[4,2.02,41.63],[5,2,100.38],[7,1.98,85.01]],"bdatl":[[1,2.18,13.66],[2,2.26,3.36],[3,2.28,7.31],[4,2.36,5.28],[5,2.38,1.88],[6,2.4,1.37],[7,2.42,4.91],[8,2.44,24.09],[9,2.46,3.41]],"id":9570503},{"bdatb":[[7,5.7,223.76],[8,5.6,3.78]],"bdatl":[[0,7.2,13.46],[1,7.4,8.17],[2,7.6,32.3],[3,7.8,4.74],[4,8,1.76],[5,8.2,1.76],[6,8.4,4],[7,8.6,1.76],[8,8.8,2.63],[9,9,2.17]],"id":12989514},{"bdatb":[[7,19.5,1.76],[9,18.5,4.49]],"id":44621159},{"bdatb":[[3,6.6,7.16],[5,6.2,6.23],[6,6,218],[7,5.9,9],[8,5.8,12.03]],"id":44836671},{"bdatb":[[4,8.6,20],[5,8.4,3.78],[6,8.2,1.77],[7,8,1.81],[8,7.8,1.76],[9,7.6,1.76]],"id":43885158},{"bdatb":[[6,14.5,1.76],[7,14,1.78],[8,13.5,1.78],[9,13,1.97]],"id":46969227}]}]}
{"op":"mcm","clk":"APPGAQC3YwC6sAE=","pt":1659347779830,"mc":[{"id":"1.201590187","rc":[{"atb":[[1.02,0]],"id":45323444},{"atl":[[2.14,0]],"trd":[[2.14,159.08]],"tv":1231.4,"id":9570503},{"atb":[[26,3.11]],"id":44621159}],"tv":2241.87}]}
{"op":"mcm","clk":"APbGAQC4YwDBsAE=","pt":1659347779880,"mc":[{"id":"1.201590187","rc":[{"bdatb":[[4,11,7.02],[5,10.5,7.84],[6,10,14.17],[7,9.8,10.43]],"id":45323444},{"bdatl":[[0,2.18,13.66],[1,2.26,3.36],[2,2.28,7.31],[3,2.36,5.28],[4,2.38,1.88],[5,2.4,1.37],[6,2.42,4.91],[7,2.44,24.09],[8,2.46,3.41],[9,2.48,5.64]],"id":9570503},{"bdatb":[[4,6,1.76],[5,5.9,1.76],[6,5.8,35.34],[7,5.7,223.79],[8,5.6,4.26]],"id":12989514},{"bdatb":[[1,26,3.11],[2,24,4.22]],"id":44621159},{"bdatb":[[4,6.4,1.76],[5,6.2,5.77],[6,6,218.04],[7,5.9,9.02],[8,5.8,12.5]],"id":44836671},{"bdatb":[[5,8.4,3.76],[6,8.2,1.76],[7,8,1.46],[8,7.8,1.78],[9,7.6,1.77]],"id":43885158},{"bdatb":[[7,14,1.76],[8,13.5,1.76],[9,13,1.76]],"id":46969227}]}]}
{"op":"mcm","clk":"APjGAQC5YwDFsAE=","pt":1659347779930,"mc":[{"id":"1.201590187","rc":[{"atb":[[11.5,6.81]],"id":45323444},{"atb":[[6.6,9.82]],"atl":[[7.8,9.74],[7.6,26.3],[7.4,3.17],[7.2,5.46]],"id":12989514}]}]}
{"op":"mcm","clk":"APrGAQC7YwDHsAE=","pt":1659347779980,"mc":[{"id":"1.201590187","rc":[{"bdatb":[[3,11.5,6.81]],"id":45323444},{"bdatb":[[7,1.98,82.85],[8,1.97,3.19],[9,1.96,4.13]],"bdatl":[[6,2.42,8.38],[7,2.44,29.71],[8,2.5,25.26],[9,2.52,11]],"id":9570503},{"bdatb":[[1,6.6,9.82]],"bdatl":[[0,7.2,5.46],[1,7.4,3.17],[2,7.6,26.3],[3,7.8,9.74]],"id":12989514}]}]}
{"op":"mcm","clk":"AP3GAQC8YwDKsAE=","pt":1659347780030,"mc":[{"id":"1.201590187","rc":[{"atb":[[11.5,8.58]],"bdatb":[[3,11.5,8.58]],"bdatl":[[7,21,2.02],[9,23,3.3]],"id":45323444},{"atb":[[2.1,13.5],[2.12,2.54]],"atl":[[2.2,1.74]],"bdatb":[[0,2.12,2.54],[1,2.1,13.5],[2,2.08,29.17],[3,2.06,48.89],[4,2.04,18.7],[5,2.02,41.63],[6,2,100.38],[7,1.99,1.76],[8,1.98,82.85],[9,1.97,3.19]],"bdatl":[[1,2.2,1.74],[2,2.26,3.36],[3,2.28,7.31],[4,2.36,5.28],[5,2.38,1.88],[6,2.4,1.37],[7,2.42,8.38],[8,2.44,29.71],[9,2.48,4.29]],"id":9570503},{"atb":[[9,5.17]],"bdatb":[[2,9,5.17]],"bdatl":[[8,14.5,14.24],[9,15,13.26]],"id":43885158},{"bdatl":[[7,8.6,2.39],[8,8.8,2.02]],"id":12989514},{"bdatl":[[3,170,2.04],[4,900,1.15]],"id":44621159},{"bdatl":[[8,9.2,8.58]],"id":44836671}]}]}
{"op":"mcm","clk":"AIDHAQDBYwDPsAE=","pt":1659347780127,"mc":[{"id":"1.201590187","rc":[{"atl":[[2.18,6.25]],"id":9570503},{"atb":[[6.8,4.31]],"id":12989514},{"atb":[[8.8,9.08]],"id":43885158}]}]}
{"op":"mcm","clk":"AILHAQDCYwDVsAE=","pt":1659347780177,"mc":[{"id":"1.201590187","rc":[{"bdatb":[[7,9.8,10.36],[8,9.6,21],[9,9.4,11.07]],"id":45323444},{"bdatl":[[0,2.18,6.25],[4,2.32,2.18],[5,2.36,3.13],[6,2.38,1.88],[7,2.4,1.37],[8,2.42,8.38],[9,2.44,29.71]],"id":9570503},{"bdatb":[[0,6.8,4.31],[8,5.6,4.14],[9,5.5,1.88]],"id":12989514},{"bdatb":[[8,5.8,12.3],[9,5.7,96.38]],"id":44836671},{"bdatb":[[3,8.8,9.08]],"id":43885158}]}]}
{"op":"mcm","clk":"AIjHAQDEYwDWsAE=","pt":1659347780228,"mc":[{"id":"1.201590187","rc":[{"atb":[[6.4,35.31]],"bdatb":[[4,6.4,35.31]],"id":44836671}]}]}
{"op":"mcm","clk":"AJHHAQDHYwDbsAE=","pt":1659347780301,"mc":[{"id":"1.201590187","rc":[{"atl":[[2.18,4.04]],"id":9570503}]}]}
{"op":"mcm","clk":"AJLHAQDHYwDksAE=","pt":1659347780351,"mc":[{"id":"1.201590187","rc":[{"bdatb":[[7,9.8,9.87],[9,9.4,11.41]],"id":45323444},{"bdatl":[[0,2.18,4.04]],"id":9570503},{"bdatb":[[8,5.6,3.28],[9,5.5,2.46]],"id":12989514},{"bdatb":[[8,5.8,11.46],[9,5.7,96.93]],"id":44836671}]}]}
{"op":"mcm","clk":"AJfHAQDKYwDlsAE=","pt":1659347780401,"mc":[{"id":"1.201590187","rc":[{"atl":[[23,1.76]],"id":45323444},{"atl":[[2.42,14.24]],"id":9570503}]}]}
{"op":"mcm","clk":"AJjHAQDLYwDssAE=","pt":1659347780451,"mc":[{"id":"1.201590187","rc":[{"bdatl":[[9,23,1.86]],"id":45323444},{"bdatl":[[8,2.42,22.63]],"id":9570503}]}]}
{"op":"mcm","clk":"AJ3HAQDPYwDusAE=","pt":1659347780504,"mc":[{"id":"1.201590187","rc":[{"atb":[[11.5,3.58]],"atl":[[26,6.48]],"id":45323444},{"atb":[[2.08,1.59]],"id":9570503},{"atb":[[26,0.93]],"id":44621159},{"atb":[[7,0.35]],"id":44836671}]}]}
{"op":"mcm","clk":"AJ3HAQDQYwDxsAE=","pt":1659347780554,"mc":[{"id":"1.201590187","rc":[{"bdatb":[[3,11.5,3.58]],"id":45323444},{"bdatb":[[2,2.08,1.59]],"bdatl":[[4,2.32,1.06],[5,2.34,1.11],[6,2.38,3.11],[7,2.4,1.86],[8,2.42,15.6],[9,2.44,27.56]],"id":9570503},{"bdatb":[[1,25,1.26],[2,24,3.89]],"id":44621159},{"bdatb":[[1,6.8,27.56],[2,6.6,7.16],[3,6.4,35.31],[4,6.2,5.77],[5,6,218.04],[6,5.9,9.02],[7,5.8,11.46],[8,5.7,96.93],[9,5.6,12]],"id":44836671}]}]}
{"op":"mcm","clk":"AKLHAQDSYwDysAE=","pt":1659347780611,"mc":[{"id":"1.201590187","rc":[{"atb":[[2.04,9.1]],"id":9570503},{"atl":[[7.6,21.81],[7.4,0.62]],"id":12989514},{"atb":[[9,2.31]],"id":43885158}]}]}
{"op":"mcm","clk":"AKPHAQDSYwD5sAE=","pt":1659347780661,"mc":[{"id":"1.201590187","rc":[{"bdatb":[[4,2.04,9.1]],"id":9570503},{"bdatl":[[1,7.6,22.43],[2,7.8,9.74],[3,8,1.76],[4,8.2,1.76],[5,8.4,4],[6,8.6,2.39],[7,8.8,2.02],[8,9,2.17],[9,9.2,3.58]],"id":12989514},{"bdatb":[[2,9,2.31]],"id":43885158}]}]}
{"op":"mcm","clk":"ALTHAQDdYwCCsQE=","pt":1659347780926,"mc":[{"id":"1.201590187","rc":[{"atb":[[18.5,2.7],[17.5,3.34]],"id":44621159}]}]}
{"op":"mcm","clk":"ALXHAQDdYwCKsQE=","pt":1659347780977,"mc":[{"id":"1.201590187","rc":[{"bdatb":[[9,18.5,2.7]],"id":44621159}]}]}
{"op":"mcm","clk":"AMzHAQDpYwCZsQE=","pt":1659347781323,"mc":[{"id":"1.201590187","rc":[{"atl":[[38,1.37]],"id":44621159}]}]}
{"op":"mcm","clk":"ANDHAQDqYwCbsQE=","pt":1659347781373,"mc":[{"id":"1.201590187","rc":[{"bdatl":[[1,38,1.37],[2,40,3.27],[3,80,2.96],[4,170,2.04],[5,900,1.15],[6,990,1.83],[7,1000,2]],"id":44621159}]}]}
{"op":"mcm","clk":"ANXHAQDqYwCgsQE=","pt":1659347781477,"mc":[{"id":"1.201590187","rc":[{"atl":[[55,0]],"id":44621159},{"atb":[[17,0]],"atl":[[22,3.36]],"id":46969227}]}]}
{"op":"mcm","clk":"ANjHAQDuYwCisQE=","pt":1659347781527,"mc":[{"id":"1.201590187","rc":[{"bdatl":[[3,80,2.32]],"id":44621159},{"bdatb":[[1,16.5,7.96],[2,16,8],[3,15.5,6.76],[4,15,5.76],[5,14.5,1.76],[6,14,1.76],[7,13.5,1.76],[8,13,1.76],[9,11.5,8.57]],"bdatl":[[0,22,3.37]],"id":46969227}]}]}
{"op":"mcm","clk":"AOLHAQDvYwClsQE=","pt":1659347781600,"mc":[{"id":"1.201590187","rc":[{"atb":[[5.6,0]],"id":45323444},{"atb":[[1.42,0]],"id":9570503},{"atb":[[2.94,0]],"id":12989514},{"atb":[[5,0]],"id":44621159},{"atb":[[2.06,0]],"id":44836671},{"atb":[[3.6,0]],"id":43885158},{"atb":[[5.6,0]],"id":46969227}]}]}
{"op":"mcm","clk":"AOnHAQDyYwCqsQE=","pt":1659347781708,"mc":[{"id":"1.201590187","rc":[{"atb":[[5,6.6]],"atl":[[16,1.2]],"id":45323444},{"atb":[[1.74,70.15]],"id":9570503},{"atb":[[3.8,21.42]],"id":12989514},{"atb":[[27,0],[6,15.38]],"atl":[[36,1.15]],"id":44621159},{"atb":[[3.6,57.07]],"id":44836671},{"atb":[[4.6,7.33]],"id":43885158},{"atb":[[6.2,5.07]],"atl":[[22,2.03]],"id":46969227}]}]}
{"op":"mcm","clk":"AOrHAQDyYwCusQE=","pt":1659347781758,"mc":[{"id":"1.201590187","rc":[{"bdatl":[[0,16,1.21],[7,21,1.76],[8,22,2.83],[9,23,1.76]],"id":45323444},{"bdatb":[[8,1.98,74.28],[9,1.97,4.08]],"bdatl":[[2,2.28,3.34],[3,2.3,7.25],[4,2.34,1.05],[5,2.36,1.1],[6,2.4,3.08],[7,2.42,16.09],[8,2.44,25.43],[9,2.46,3.44]],"id":9570503},{"bdatl":[[7,8.8,1.76],[8,9,2.42],[9,9.2,1.76]],"id":12989514},{"bdatb":[[0,25,1.26],[1,24,3.89],[2,23,1.76],[3,22,1.76],[4,21,5],[5,20,1.76],[6,19.5,1.76],[7,19,1.76],[8,18.5,2.7],[9,18,1.76]],"bdatl":[[0,36,1.57]],"id":44621159},{"bdatl":[[9,15,12]],"id":43885158},{"bdatl":[[0,22,2.04]],"id":46969227}]}]}
{"op":"mcm","clk":"AO7HAQD0YwCvsQE=","pt":1659347781810,"mc":[{"id":"1.201590187","rc":[{"atb":[[7,2.45]],"id":12989514}]}]}
{"op":"mcm","clk":"AO/HAQD0YwCysQE=","pt":1659347781860,"mc":[{"id":"1.201590187","rc":[{"bdatl":[[6,20,2.03],[8,22,2.68]],"id":45323444},{"bdatl":[[2,2.26,3.36],[3,2.28,4.19],[4,2.3,3.1],[5,2.34,1.05],[6,2.36,2.4],[7,2.38,1.82],[8,2.4,1.86],[9,2.42,15.6]],"id":9570503},{"bdatb":[[0,7,2.45],[1,6.8,4.31],[2,6.6,9.82],[3,6.4,16.07],[4,6.2,5.02],[5,6,1.76],[6,5.9,1.76],[7,5.8,35.34],[8,5.7,223.79],[9,5.6,3.28]],"id":12989514},{"bdatl":[[4,170,2.08],[5,900,1.18]],"id":44621159},{"bdatl":[[7,9,2.36],[8,9.2,8],[9,9.4,2]],"id":44836671},{"bdatl":[[7,14,13.58],[8,14.5,14.69]],"id":43885158}]}]}
{"op":"mcm","clk":"APHHAQD3YwC0sQE=","pt":1659347781910,"mc":[{"id":"1.201590187","rc":[{"atl":[[990,1.42]],"id":46969227}]}]}
{"op":"mcm","clk":"APvHAQD8YwC9sQE=","pt":1659347782026,"mc":[{"id":"1.201590187","rc":[{"atl":[[23,2.69]],"id":46969227}]}]}
{"op":"mcm","clk":"APvHAQD+YwC+sQE=","pt":1659347782076,"mc":[{"id":"1.201590187","rc":[{"bdatl":[[1,23,2.69]],"id":46969227}]}]}
{"op":"mcm","clk":"AIDIAQCEZADDsQE=","pt":1659347782212,"mc":[{"id":"1.201590187","rc":[{"atl":[[7.2,3.02]],"id":12989514},{"atb":[[9,0]],"id":43885158}]}]}
{"op":"mcm","clk":"AIbIAQCFZADGsQE=","pt":1659347782262,"mc":[{"id":"1.201590187","rc":[{"bdatb":[[8,1.98,74.01],[9,1.97,2.53]],"id":9570503},{"bdatl":[[0,7.2,3.02]],"id":12989514},{"bdatb":[[2,8.8,9.08],[3,8.6,20],[4,8.4,3.76],[5,8.2,1.76],[6,8,1.46],[7,7.8,1.78],[8,7.6,1.77],[9,7.4,3.48]],"id":43885158}]}]}
{"op":"mcm","clk":"AI3IAQCGZADJsQE=","pt":1659347782324,"mc":[{"id":"1.201590187","rc":[{"atl":[[2.3,3.63]],"id":9570503},{"atl":[[7.2,0]],"id":12989514},{"atl":[[22,1.03]],"id":46969227}]}]}
{"op":"mcm","clk":"AJDIAQCHZADNsQE=","pt":1659347782375,"mc":[{"id":"1.201590187","rc":[{"bdatb":[[6,10,14.14],[7,9.8,9.02],[8,9.6,21.01],[9,9.4,11.45]],"id":45323444},{"bdatb":[[5,2.02,41.61],[6,2,93.17],[7,1.99,3.91],[8,1.98,75.38],[9,1.97,2.79]],"bdatl":[[4,2.3,6.73]],"id":9570503},{"bdatl":[[0,7.6,22.43],[1,7.8,9.74],[2,8,1.76],[3,8.2,1.76],[4,8.4,4],[5,8.6,2.39],[6,8.8,1.76],[7,9,2.42],[8,9.2,1.76],[9,9.4,3.54]],"id":12989514},{"bdatb":[[5,6,218],[6,5.9,9.03],[7,5.8,10.03],[8,5.7,97.01],[9,5.6,12.75]],"id":44836671},{"bdatb":[[7,7.8,1.76],[8,7.6,1.78],[9,7.4,2.33]],"id":43885158},{"bdatb":[[9,11.5,7.84]],"bdatl":[[0,22,1.04]],"id":46969227}]}]}
{"op":"mcm","clk":"AJLIAQCIZADPsQE=","pt":1659347782425,"mc":[{"id":"1.201590187","rc":[{"atb":[[13,2.87]],"atl":[[26,5.04],[17,1.18]],"id":45323444},{"atl":[[2.3,7.04]],"id":9570503},{"atb":[[25,1.33]],"atl":[[36,2.15]],"id":44621159}]}]}
{"op":"mcm","clk":"AJfIAQCKZADRsQE=","pt":1659347782475,"mc":[{"id":"1.201590187","rc":[{"bdatb":[[0,13,2.87]],"bdatl":[[1,17,1.36],[2,17.5,1.76],[3,18,1.76],[4,18.5,1.76],[5,19,1.76],[6,19.5,1.76],[7,20,2.03],[8,21,1.76],[9,22,2.68]],"id":45323444},{"bdatl":[[4,2.3,10.14],[5,2.32,1.06],[6,2.34,4.27],[7,2.4,3.23],[8,2.42,15.07],[9,2.44,26.74]],"id":9570503},{"bdatb":[[0,25,2.26]],"bdatl":[[0,36,2.57]],"id":44621159}]}]}
{"op":"mcm","clk":"AJzIAQCMZADRsQE=","pt":1659347782534,"mc":[{"id":"1.201590187","rc":[{"atl":[[27,1.44]],"id":45323444}]}]}
{"op":"mcm","clk":"AJ3IAQCOZADSsQE=","pt":1659347782627,"mc":[{"id":"1.201590187","rc":[{"atl":[[7.8,30.38]],"id":12989514}]}]}
{"op":"mcm","clk":"AKHIAQCQZADWsQE=","pt":1659347782677,"mc":[{"id":"1.201590187","rc":[{"bdatl":[[1,7.8,30.38]],"id":12989514}]}]}
{"op":"mcm","clk":"AKLIAQCSZADZsQE=","pt":1659347782729,"mc":[{"id":"1.201590187","rc":[{"atl":[[2.18,1.18]],"id":9570503},{"atb":[[6.8,23.21]],"atl":[[7.6,13.35]],"trd":[[7.6,301.97]],"tv":546.6,"id":44836671}],"tv":2250.05}]}
{"op":"mcm","clk":"AKnIAQCVZADgsQE=","pt":1659347782779,"mc":[{"id":"1.201590187","rc":[{"bdatb":[[9,9.4,11.24]],"id":45323444},{"bdatl":[[0,2.18,1.18]],"id":9570503},{"bdatb":[[9,5.6,2.17]],"id":12989514},{"bdatb":[[1,6.8,23.56],[8,5.7,96.66],[9,5.6,12.36]],"bdatl":[[0,7.6,13.35]],"id":44836671}]}]}
{"op":"mcm","clk":"AKzIAQCYZADgsQE=","pt":1659347782841,"mc":[{"id":"1.201590187","rc":[{"atl":[[7.4,4.62]],"id":12989514},{"atb":[[9.2,7.06]],"id":43885158},{"atb":[[17.5,4.54]],"id":46969227}]}]}
{"op":"mcm","clk":"AK3IAQCbZADlsQE=","pt":1659347782891,"mc":[{"id":"1.201590187","rc":[{"bdatb":[[7,1.99,9.04],[8,1.98,70.48],[9,1.97,4.84]],"bdatl":[[7,2.4,4.07],[8,2.42,17.43],[9,2.44,33.75]],"id":9570503},{"bdatl":[[0,7.4,4.62],[1,7.6,21.81],[2,7.8,30.38],[3,8,1.76],[4,8.2,1.76],[5,8.4,4],[6,8.6,2.39],[7,8.8,1.76],[8,9,2.42],[9,9.2,1.76]],"id":12989514},{"bdatb":[[9,5.6,12.68]],"id":44836671},{"bdatb":[[1,9.2,7.06]],"id":43885158},{"bdatb":[[0,17.5,4.54]],"id":46969227}]}]}
{"op":"mcm","clk":"ALXIAQCgZADvsQE=","pt":1659347783013,"mc":[{"id":"1.201590187","rc":[{"atb":[[8.8,48.48]],"id":45323444},{"atb":[[2.08,3.73],[2.06,35.07]],"id":9570503},{"atb":[[6.6,4.86],[6.8,9.05]],"id":12989514}]}]}
{"op":"mcm","clk":"ALbIAQChZADysQE=","pt":1659347783063,"mc":[{"id":"1.201590187","rc":[{"bdatb":[[2,2.08,3.73],[3,2.06,35.07]],"bdatl":[[7,2.4,8.61],[8,2.42,22.67],[9,2.44,24.48]],"id":9570503},{"bdatb":[[1,6.8,9.05],[2,6.6,4.86]],"id":12989514}]}]}
{"op":"mcm","clk":"AMPIAQCnZAD+sQE=","pt":1659347783316,"mc":[{"id":"1.201590187","rc":[{"atb":[[6.6,64.72]],"id":43885158}]}]}
{"op":"mcm","clk":"AN3IAQCxZACVsgE=","pt":1659347783630,"mc":[{"id":"1.201590187","rc":[{"atl":[[17,2.33]],"id":45323444},{"atl":[[2.26,3.35]],"id":9570503},{"atl":[[10.5,2.56]],"id":43885158}]}]}
{"op":"mcm","clk":"AN/IAQCxZACbsgE=","pt":1659347783680,"mc":[{"id":"1.201590187","rc":[{"bdatl":[[1,17,2.51]],"id":45323444},{"bdatb":[[7,1.99,11.33],[8,1.98,71.98],[9,1.97,2.84]],"bdatl":[[2,2.26,6.72]],"id":9570503},{"bdatl":[[0,10.5,2.56]],"id":43885158}]}]}
{"op":"mcm","clk":"AO3IAQC2ZACisgE=","pt":1659347783871,"mc":[{"id":"1.201590187","rc":[{"atl":[[10.5,1.41]],"id":43885158},{"atb":[[17.5,3.39]],"id":46969227}]}]}
{"op":"mcm","clk":"AO3IAQC2ZACnsgE=","pt":1659347783921,"mc":[{"id":"1.201590187","rc":[{"bdatb":[[7,1.99,9.04],[8,1.98,70.48],[9,1.97,4.84]],"bdatl":[[8,2.42,15.06],[9,2.44,31.63]],"id":9570503},{"bdatl":[[0,10.5,1.41]],"id":43885158},{"bdatb":[[0,17.5,3.39]],"id":46969227}]}]}
{"op":"mcm","clk":"AITJAQDDZAC4sgE=","pt":1659347784239,"mc":[{"id":"1.201590187","rc":[{"atb":[[2.1,0],[2.12,0]],"atl":[[2.1,3.96]],"trd":[[2.1,161.07],[2.12,242.05]],"ltp":2.1,"tv":1263.48,"id":9570503}],"tv":2282.13}]}
{"op":"mcm","clk":"AIXJAQDFZAC+sgE=","pt":1659347784290,"mc":[{"id":"1.201590187","rc":[{"bdatb":[[2,12,1.98],[3,11.5,3.59],[4,11,7.75],[7,9.8,9],[8,9.6,21],[9,9.4,11.27]],"bdatl":[[7,20,1.76],[9,22,2.58]],"id":45323444},{"bdatb":[[0,2.08,3.73],[1,2.06,35.07],[2,2.04,9.1],[3,2.02,41.61],[4,2,93.17],[5,1.99,9.04],[6,1.98,70.48],[7,1.97,4.84],[8,1.96,4.13],[9,1.95,7.85]],"bdatl":[[0,2.1,3.96],[1,2.18,1.18],[2,2.2,1.74],[3,2.26,6.72],[4,2.28,4.19],[5,2.3,10.14],[6,2.32,1.06],[7,2.34,4.27],[8,2.4,8.61],[9,2.42,15.06]],"id":9570503},{"bdatb":[[3,6.4,16.1],[4,6.2,6.33],[7,5.8,35.31],[8,5.7,223.76],[9,5.6,2.22]],"bdatl":[[6,8.6,1.76],[8,9,2.17]],"id":12989514},{"bdatb":[[5,20,1.77],[7,19,1.77],[8,18.5,3.13]],"bdatl":[[4,170,2],[5,900,1.17]],"id":44621159},{"bdatb":[[2,6.6,7.18],[3,6.4,36.59],[6,5.9,9],[7,5.8,10],[8,5.7,96.71],[9,5.6,12.61]],"bdatl":[[7,9,1.76],[9,9.4,1.76]],"id":44836671},{"bdatb":[[3,8.6,20.02],[4,8.4,3.78],[5,8.2,2.74],[8,7.6,1.76],[9,7.4,2.32]],"bdatl":[[7,14,13.2],[8,14.5,13.87]],"id":43885158},{"bdatb":[[4,15,5.77],[5,14.5,1.78],[6,14,2.34],[9,11.5,7.81]],"id":46969227}]}]}
{"op":"mcm","clk":"AIvJAQDHZAC+sgE=","pt":1659347784343,"mc":[{"id":"1.201590187","rc":[{"atl":[[2.1,0]],"trd":[[2.1,168.99]],"tv":1271.4,"id":9570503}],"tv":2290.05}]}
{"op":"mcm","clk":"AI/JAQDIZADCsgE=","pt":1659347784393,"mc":[{"id":"1.201590187","rc":[{"bdatb":[[2,12,1.96],[3,11.5,3.58],[4,11,7.02],[7,9.8,9.02],[8,9.6,21.01],[9,9.4,11.24]],"id":45323444},{"bdatl":[[0,2.18,1.18],[1,2.2,1.74],[2,2.26,6.72],[3,2.28,4.19],[4,2.3,10.14],[5,2.32,1.06],[6,2.34,4.27],[7,2.4,8.61],[8,2.42,15.06],[9,2.44,31.63]],"id":9570503},{"bdatb":[[3,6.4,16.07],[4,6.2,5.02],[7,5.8,35.34],[8,5.7,223.79],[9,5.6,2.17]],"id":12989514},{"bdatb":[[5,20,1.76],[7,19,1.76],[8,18.5,2.7]],"id":44621159},{"bdatb":[[2,6.6,7.16],[3,6.4,35.31],[6,5.9,9.03],[7,5.8,10.03],[8,5.7,96.66],[9,5.6,12.68]],"id":44836671},{"bdatb":[[3,8.6,20],[4,8.4,3.76],[5,8.2,1.76],[8,7.6,1.78],[9,7.4,2.33]],"id":43885158},{"bdatb":[[4,15,5.76],[5,14.5,1.76],[6,14,1.76],[9,11.5,7.84]],"id":46969227}]}]}
{"op":"mcm","clk":"AJTJAQDMZADHsgE=","pt":1659347784443,"mc":[{"id":"1.201590187","rc":[{"atl":[[2.28,8]],"id":9570503},{"atl":[[7.8,25.38]],"id":12989514}]}]}
{"op":"mcm","clk":"AJfJAQDPZADIsgE=","pt":1659347784493,"mc":[{"id":"1.201590187","rc":[{"bdatl":[[3,2.28,12.19]],"id":9570503},{"bdatl":[[2,7.8,25.38]],"id":12989514}]}]}
{"op":"mcm","clk":"AJzJAQDRZADLsgE=","pt":1659347784543,"mc":[{"id":"1.201590187","rc":[{"atb":[[1.02,2]],"id":9570503},{"atl":[[7.6,24.17]],"bdatl":[[1,7.6,24.17]],"id":12989514},{"atb":[[9.2,9.39]],"bdatb":[[1,9.2,9.39]],"id":43885158}]}]}
{"op":"mcm","clk":"AKPJAQDUZADPsgE=","pt":1659347784616,"mc":[{"id":"1.201590187","rc":[{"atb":[[2.06,37.72]],"atl":[[2.28,11.6]],"id":9570503},{"atl":[[7.6,5.27]],"id":12989514}]}]}
{"op":"mcm","clk":"AKTJAQDUZADSsgE=","pt":1659347784666,"mc":[{"id":"1.201590187","rc":[{"bdatb":[[1,2.06,37.72]],"bdatl":[[3,2.28,15.78]],"id":9570503},{"bdatl":[[1,7.6,5.27]],"id":12989514}]}]}
{"op":"mcm","clk":"AKrJAQDWZADTsgE=","pt":1659347784728,"mc":[{"id":"1.201590187","rc":[{"atb":[[1.02,1.82]],"id":9570503}]}]}
{"op":"mcm","clk":"ALjJAQDbZADbsgE=","pt":1659347784924,"mc":[{"id":"1.201590187","rc":[{"atb":[[1.02,0],[2.06,35.07]],"id":9570503}]}]}
{"op":"mcm","clk":"ALnJAQDdZADksgE=","pt":1659347784974,"mc":[{"id":"1.201590187","rc":[{"bdatb":[[1,2.06,35.07]],"id":9570503}]}]}
{"op":"mcm","clk":"AL/JAQDhZADlsgE=","pt":1659347785036,"mc":[{"id":"1.201590187","rc":[{"atb":[[2.1,1.82]],"id":9570503}]}]}
{"op":"mcm","clk":"AL/JAQDiZADpsgE=","pt":1659347785086,"mc":[{"id":"1.201590187","rc":[{"bdatl":[[9,22,2.76]],"id":45323444},{"bdatb":[[0,2.1,1.82],[1,2.08,3.73],[2,2.06,35.07],[3,2.04,9.1],[4,2.02,41.61],[5,2,93.17],[6,1.99,9.04],[7,1.98,70.48],[8,1.97,4.84],[9,1.96,4.13]],"id":9570503},{"bdatl":[[8,9,2.6]],"id":12989514},{"bdatl":[[4,170,2.03],[5,900,1.15]],"id":44621159},{"bdatl":[[9,9.4,2.17]],"id":44836671},{"bdatl":[[8,14.5,14.14]],"id":43885158}]}]}
{"op":"mcm","clk":"AMnJAQDlZADwsgE=","pt":1659347785234,"mc":[{"id":"1.201590187","rc":[{"atl":[[1000,1.77]],"id":9570503}]}]}
{"op":"mcm","clk":"AM3JAQDoZADzsgE=","pt":1659347785339,"mc":[{"id":"1.201590187","rc":[{"atl":[[2.28,3.6]],"id":9570503}]}]}
{"op":"mcm","clk":"AM/JAQDoZAD3sgE=","pt":1659347785389,"mc":[{"id":"1.201590187","rc":[{"bdatl":[[3,2.28,7.78]],"id":9570503}]}]}
{"op":"mcm","clk":"ANXJAQDsZAD4sgE=","pt":1659347785449,"mc":[{"id":"1.201590187","rc":[{"atl":[[1000,0]],"id":9570503},{"atb":[[15.5,1.76],[15,1.76],[17,6]],"id":46969227}]}]}
{"op":"mcm","clk":"ANnJAQDvZAD7sgE=","pt":1659347785499,"mc":[{"id":"1.201590187","rc":[{"bdatl":[[8,2.42,22.67],[9,2.44,24.09]],"id":9570503},{"bdatb":[[1,17,6],[2,16.5,7.96],[3,16,8],[4,15.5,1.76],[5,15,1.76],[6,14.5,1.76],[7,14,1.76],[8,13.5,1.76],[9,13,1.76]],"id":46969227}]}]}
{"op":"mcm","clk":"ANvJAQDvZAD/sgE=","pt":1659347785549,"mc":[{"id":"1.201590187","rc":[{"atl":[[2.16,1.77]],"bdatl":[[0,2.16,1.77],[1,2.18,1.18],[2,2.2,1.74],[3,2.26,6.72],[4,2.28,7.78],[5,2.3,10.14],[6,2.32,1.06],[7,2.34,4.27],[8,2.4,8.61],[9,2.42,22.67]],"id":9570503},{"atl":[[11.5,2.88]],"bdatb":[[7,7.8,1.78],[8,7.6,1.79],[9,7.4,2.8]],"bdatl":[[2,11.5,2.88]],"id":43885158},{"bdatb":[[6,10,14.17],[7,9.8,9.36],[8,9.6,21],[9,9.4,11.27]],"id":45323444},{"bdatb":[[6,5.9,1.8],[7,5.8,35.33],[8,5.7,224.38],[9,5.6,2.22]],"id":12989514},{"bdatb":[[5,6,218.04],[6,5.9,9.61],[7,5.8,10],[8,5.7,96.71]],"id":44836671}]}]}
{"op":"mcm","clk":"AODJAQDwZACDswE=","pt":1659347785636,"mc":[{"id":"1.201590187","rc":[{"atl":[[12,10.85]],"id":43885158}]}]}
{"op":"mcm","clk":"AODJAQDyZACGswE=","pt":1659347785686,"mc":[{"id":"1.201590187","rc":[{"bdatl":[[3,12,10.85]],"id":43885158}]}]}
{"op":"mcm","clk":"AOXJAQD0ZACGswE=","pt":1659347785743,"mc":[{"id":"1.201590187","rc":[{"atl":[[2.2,3.51],[2.18,0]],"id":9570503}]}]}
{"op":"mcm","clk":"AOjJAQD1ZACKswE=","pt":1659347785793,"mc":[{"id":"1.201590187","rc":[{"bdatb":[[9,9.4,11]],"id":45323444},{"bdatl":[[1,2.2,3.51],[2,2.26,6.72],[3,2.28,7.78],[4,2.3,10.14],[5,2.32,1.06],[6,2.34,4.27],[7,2.4,8.61],[8,2.42,22.67],[9,2.44,24.09]],"id":9570503},{"bdatb":[[9,5.6,1.76]],"id":12989514},{"bdatb":[[8,5.7,96.26],[9,5.6,13.38]],"id":44836671}]}]}
{"op":"mcm","clk":"AP/JAQD+ZACgswE=","pt":1659347786312,"mc":[{"id":"1.201590187","rc":[{"atb":[[17.5,7.39]],"id":46969227}]}]}
{"op":"mcm","clk":"AP/JAQCAZQClswE=","pt":1659347786362,"mc":[{"id":"1.201590187","rc":[{"bdatl":[[9,2.44,24.48]],"id":9570503},{"bdatb":[[0,17.5,7.39]],"id":46969227}]}]}
{"op":"mcm","clk":"AIzKAQCKZQCxswE=","pt":1659347786627,"mc":[{"id":"1.201590187","rc":[{"atl":[[2.28,0]],"id":9570503},{"atl":[[7.6,9.71]],"id":12989514}]}]}
{"op":"mcm","clk":"AJHKAQCNZQC2swE=","pt":1659347786677,"mc":[{"id":"1.201590187","rc":[{"bdatl":[[3,2.28,4.19]],"id":9570503},{"bdatl":[[1,7.6,9.71]],"id":12989514}]}]}
{"op":"mcm","clk":"AJfKAQCSZQC3swE=","pt":1659347786742,"mc":[{"id":"1.201590187","rc":[{"atl":[[7.4,0.62]],"id":12989514},{"atb":[[17.5,5.39]],"id":46969227}]}]}
{"op":"mcm","clk":"AJfKAQCTZQC7swE=","pt":1659347786792,"mc":[{"id":"1.201590187","rc":[{"bdatb":[[6,1.99,3.91],[7,1.98,75.38],[8,1.97,2.79],[9,1.96,4.94]],"id":9570503},{"bdatl":[[0,7.6,10.33],[1,7.8,25.38],[2,8,1.76],[3,8.2,1.76],[4,8.4,4],[5,8.6,1.76],[6,8.8,1.76],[7,9,2.6],[8,9.2,1.76],[9,9.4,2.17]],"id":12989514},{"bdatb":[[9,5.6,12.14]],"id":44836671},{"bdatb":[[0,17.5,5.39]],"id":46969227}]}]}
{"op":"mcm","clk":"AJ3KAQCXZQC9swE=","pt":1659347786849,"mc":[{"id":"1.201590187","rc":[{"atb":[[2.08,13.43]],"id":9570503},{"atl":[[7.6,13.5]],"id":12989514},{"atb":[[18,2]],"id":46969227}]}]}
{"op":"mcm","clk":"AJ3KAQCbZQDBswE=","pt":1659347786910,"mc":[{"id":"1.201590187","rc":[{"bdatl":[[8,21,1.95],[9,22,2.58]],"id":45323444},{"bdatb":[[1,2.08,13.43]],"bdatl":[[2,2.24,3.4],[3,2.26,7.58],[4,2.28,3.09],[5,2.3,7.08],[6,2.32,1.06],[7,2.34,4.27],[8,2.4,8.61],[9,2.42,22.67]],"id":9570503},{"bdatl":[[0,7.6,14.12],[6,8.8,2.2],[7,9,2.17],[8,9.2,2.18],[9,9.4,1.76]],"id":12989514},{"bdatl":[[5,900,1.16]],"id":44621159},{"bdatl":[[8,9.2,8.42],[9,9.4,1.76]],"id":44836671},{"bdatb":[[0,18,2],[1,17.5,5.39],[2,17,6],[3,16.5,7.96],[4,16,8],[5,15.5,1.76],[6,15,1.76],[7,14.5,1.76],[8,14,1.76],[9,13.5,1.76]],"id":46969227}]}]}
{"op":"mcm","clk":"AKXKAQCcZQDFswE=","pt":1659347786961,"mc":[{"id":"1.201590187","rc":[{"atb":[[7,3.16]],"id":12989514}]}]}
{"op":"mcm","clk":"AKvKAQCgZQDFswE=","pt":1659347787011,"mc":[{"id":"1.201590187","rc":[{"bdatl":[[3,2.26,9.78],[4,2.3,7.99],[5,2.32,1.06],[6,2.34,4.27],[7,2.4,8.61],[8,2.42,22.67],[9,2.44,26.51]],"id":9570503},{"bdatb":[[0,7,3.16]],"id":12989514}]}]}
{"op":"mcm","clk":"AMnKAQC7ZQDoswE=","pt":1659347787635,"mc":[{"id":"1.201590187","rc":[{"atl":[[2.4,33.55],[2.24,2.9]],"id":9570503},{"atl":[[7.6,17.93]],"id":12989514}]}]}
{"op":"mcm","clk":"AMnKAQC7ZQDsswE=","pt":1659347787685,"mc":[{"id":"1.201590187","rc":[{"bdatl":[[2,2.24,6.3],[7,2.4,42.16]],"id":9570503},{"bdatl":[[0,7.6,18.55]],"id":12989514}]}]}
{"op":"mcm","clk":"ANTKAQDGZQD2swE=","pt":1659347787840,"mc":[{"id":"1.201590187","rc":[{"atb":[[2.08,30.01]],"id":9570503}]}]}
{"op":"mcm","clk":"ANTKAQDGZQD8swE=","pt":1659347787890,"mc":[{"id":"1.201590187","rc":[{"bdatb":[[1,2.08,30.01]],"id":9570503}]}]}
{"op":"mcm","clk":"AK3LAQD+ZQC9tAE=","pt":1659347789339,"mc":[{"id":"1.201590187","rc":[{"atb":[[1.21,2.9]],"id":45323444},{"atb":[[1.04,2.99]],"id":9570503},{"atb":[[1.12,2.91]],"id":12989514},{"atb":[[1.27,2.89]],"id":44621159},{"atb":[[1.12,2.91]],"id":44836671},{"atb":[[1.27,2.89]],"id":46969227}]}]}
{"op":"mcm","clk":"ALTLAQCAZgC/tAE=","pt":1659347789438,"mc":[{"id":"1.201590187","rc":[{"atb":[[1.17,2.9]],"id":43885158}]}]}
{"op":"mcm","clk":"AMfLAQCQZgDMtAE=","pt":1659347789747,"mc":[{"id":"1.201590187","rc":[{"atb":[[1.04,0.12]],"id":9570503},{"atb":[[1.12,0.04]],"id":12989514},{"atb":[[1.27,0.02]],"id":44621159},{"atb":[[1.12,0.04]],"id":44836671},{"atb":[[1.27,0.02]],"id":46969227}]}]}
{"op":"mcm","clk":"AM3LAQCXZgDRtAE=","pt":1659347789852,"mc":[{"id":"1.201590187","rc":[{"atb":[[1.21,0.02]],"id":45323444},{"atb":[[6.6,0.32]],"id":12989514}]}]}
{"op":"mcm","clk":"ANHLAQCYZgDatAE=","pt":1659347789903,"mc":[{"id":"1.201590187","rc":[{"bdatb":[[2,6.4,16.39],[3,6.2,5.02],[4,6,1.76],[5,5.9,1.8],[6,5.8,35.33],[7,5.7,224.38],[8,5.6,1.76],[9,5.5,3.17]],"id":12989514}]}]}
{"op":"mcm","clk":"ANbLAQCaZgDdtAE=","pt":1659347789953,"mc":[{"id":"1.201590187","rc":[{"atb":[[7,7.7]],"bdatb":[[0,7,7.7]],"id":12989514},{"bdatl":[[3,2.26,10.7],[4,2.3,8.14],[5,2.32,4.31],[6,2.36,7.28],[7,2.4,35],[9,2.44,39.54]],"id":9570503}]}]}
{"op":"mcm","clk":"ANnLAQCdZgDgtAE=","pt":1659347790016,"mc":[{"id":"1.201590187","rc":[{"atb":[[1.17,0.03]],"id":43885158}]}]}
{"op":"mcm","clk":"AObLAQCjZgDntAE=","pt":1659347790214,"mc":[{"id":"1.201590187","rc":[{"atb":[[1.04,0]],"id":9570503},{"atb":[[1.12,0]],"id":12989514},{"atb":[[1.27,0]],"id":44621159},{"atb":[[1.12,0]],"id":44836671},{"atl":[[10.5,2.56]],"id":43885158},{"atb":[[1.27,0],[18,3.15]],"id":46969227}]}]}
{"op":"mcm","clk":"AObLAQCoZgDstAE=","pt":1659347790264,"mc":[{"id":"1.201590187","rc":[{"bdatb":[[8,1.97,5.1],[9,1.96,4.44]],"id":9570503},{"bdatl":[[0,10.5,2.56]],"id":43885158},{"bdatb":[[0,18,3.15]],"id":46969227}]}]}
{"op":"mcm","clk":"APPLAQCpZgDwtAE=","pt":1659347790330,"mc":[{"id":"1.201590187","rc":[{"atb":[[1.21,0]],"id":45323444},{"atb":[[1.96,2.74]],"id":9570503},{"atb":[[6,1.8]],"id":12989514},{"atb":[[12.5,0.02]],"id":44621159},{"atb":[[6.2,5.81]],"id":44836671},{"atb":[[15,1.78]],"id":46969227}]}]}
{"op":"mcm","clk":"APPLAQCqZgDztAE=","pt":1659347790380,"mc":[{"id":"1.201590187","rc":[{"bdatb":[[9,1.96,4.56]],"id":9570503},{"bdatb":[[4,6,1.8]],"id":12989514},{"bdatb":[[4,6.2,5.81]],"id":44836671},{"bdatb":[[6,15,1.78]],"id":46969227}]}]}
{"op":"mcm","clk":"APTLAQCrZgDztAE=","pt":1659347790430,"mc":[{"id":"1.201590187","rc":[{"atb":[[9.4,11.02]],"atl":[[17,1.18]],"id":45323444},{"atl":[[10.5,1.41]],"id":43885158}]}]}
{"op":"mcm","clk":"APjLAQCrZgD2tAE=","pt":1659347790480,"mc":[{"id":"1.201590187","rc":[{"bdatb":[[9,9.4,11.02]],"bdatl":[[1,17,1.36]],"id":45323444},{"bdatb":[[8,1.97,2.79],[9,1.96,5.06]],"id":9570503},{"bdatl":[[0,10.5,1.41]],"id":43885158}]}]}
{"op":"mcm","clk":"AIHMAQCyZgD6tAE=","pt":1659347790637,"mc":[{"id":"1.201590187","rc":[{"atb":[[1.17,0]],"id":43885158}]}]}
{"op":"mcm","clk":"AIzMAQC2ZgD+tAE=","pt":1659347790753,"mc":[{"id":"1.201590187","rc":[{"atb":[[8.2,1.79]],"id":43885158}]}]}
{"op":"mcm","clk":"AI7MAQC4ZgCCtQE=","pt":1659347790803,"mc":[{"id":"1.201590187","rc":[{"bdatb":[[5,8.2,1.79]],"id":43885158}]}]}
{"op":"mcm","clk":"AI/MAQC7ZgCFtQE=","pt":1659347790853,"mc":[{"id":"1.201590187","rc":[{"atb":[[2.08,20.31]],"id":9570503},{"atl":[[11,3.53]],"id":43885158}]}]}
{"op":"mcm","clk":"AJTMAQC9ZgCHtQE=","pt":1659347790903,"mc":[{"id":"1.201590187","rc":[{"bdatb":[[1,2.08,20.31]],"id":9570503},{"bdatl":[[1,11,3.53]],"id":43885158}]}]}
{"op":"mcm","clk":"AJfMAQC9ZgCItQE=","pt":1659347790954,"mc":[{"id":"1.201590187","rc":[{"atb":[[2.1,13.92]],"bdatb":[[0,2.1,13.92]],"id":9570503},{"atb":[[6.6,4.32]],"bdatb":[[2,6.6,4.32],[3,6.4,16.07],[4,6.2,5.02],[5,6,1.8],[6,5.9,1.8],[7,5.8,35.33],[8,5.7,224.38],[9,5.6,1.76]],"bdatl":[[6,8.8,2.63],[8,9.2,3.57],[9,9.4,1.77]],"id":12989514},{"bdatl":[[8,21,2.13]],"id":45323444},{"bdatl":[[4,170,2.07],[5,890,1.01],[6,990,2.05]],"id":44621159},{"bdatl":[[8,9.2,8.83]],"id":44836671},{"bdatl":[[8,14.5,15.55]],"id":43885158}]}]}
{"op":"mcm","clk":"AKXMAQDGZgCYtQE=","pt":1659347791213,"mc":[{"id":"1.201590187","rc":[{"atb":[[2.04,4.99]],"atl":[[2.3,3.63]],"id":9570503},{"atb":[[6.4,13.66]],"atl":[[7.6,15.57]],"id":12989514},{"atb":[[6.8,20.8]],"atl":[[7.6,11.01]],"id":44836671},{"atb":[[8.8,6.71]],"id":43885158}]}]}
{"op":"mcm","clk":"AKvMAQDHZgCetQE=","pt":1659347791263,"mc":[{"id":"1.201590187","rc":[{"bdatb":[[3,2.04,4.99]],"bdatl":[[4,2.3,4.73]],"id":9570503},{"bdatb":[[3,6.4,13.66]],"bdatl":[[0,7.6,16.19]],"id":12989514},{"bdatb":[[1,6.8,21.15]],"bdatl":[[0,7.6,11.01]],"id":44836671},{"bdatb":[[2,8.8,6.71]],"id":43885158}]}]}
{"op":"mcm","clk":"ALDMAQDKZgCgtQE=","pt":1659347791332,"mc":[{"id":"1.201590187","rc":[{"atl":[[22,0.24]],"id":46969227}]}]}
{"op":"mcm","clk":"ALDMAQDKZgCjtQE=","pt":1659347791383,"mc":[{"id":"1.201590187","rc":[{"bdatb":[[7,1.98,70.94],[8,1.97,7],[9,1.96,2.99]],"id":9570503},{"bdatl":[[0,23,2.94],[1,24,5.22],[2,25,1.86],[3,26,10],[4,27,1.76],[5,28,7.55],[6,29,1.76],[7,30,1.83],[8,32,1.76],[9,34,5]],"id":46969227}]}]}
{"op":"mcm","clk":"ALPMAQDMZgCltQE=","pt":1659347791433,"mc":[{"id":"1.201590187","rc":[{"atl":[[23,3.49]],"id":46969227}]}]}
{"op":"mcm","clk":"ALfMAQDPZgCntQE=","pt":1659347791483,"mc":[{"id":"1.201590187","rc":[{"bdatl":[[0,23,3.74]],"id":46969227}]}]}
{"op":"mcm","clk":"AOLMAQDxZgDRtQE=","pt":1659347792157,"mc":[{"id":"1.201590187","rc":[{"atl":[[17,2.33]],"id":45323444}]}]}
{"op":"mcm","clk":"AOTMAQDxZgDUtQE=","pt":1659347792208,"mc":[{"id":"1.201590187","rc":[{"bdatl":[[1,17,2.51]],"id":45323444}]}]}
{"op":"mcm","clk":"AP3MAQCBZwDttQE=","pt":1659347792653,"mc":[{"id":"1.201590187","rc":[{"atb":[[11,14.37]],"id":44621159},{"atb":[[8.8,37.35]],"id":46969227}]}]}
{"op":"mcm","clk":"AIHNAQCGZwD0tQE=","pt":1659347792754,"mc":[{"id":"1.201590187","rc":[{"atb":[[11,0]],"id":44621159}]}]}
{"op":"mcm","clk":"AIbNAQCKZwD5tQE=","pt":1659347792857,"mc":[{"id":"1.201590187","rc":[{"atb":[[3.9,27.24]],"id":12989514},{"atb":[[20,3.98],[17.5,0]],"id":44621159},{"atb":[[5.7,79.02]],"id":44836671},{"atb":[[8.8,25.86]],"id":46969227}]}]}
{"op":"mcm","clk":"AI3NAQCLZwD/tQE=","pt":1659347792907,"mc":[{"id":"1.201590187","rc":[{"bdatb":[[5,20,3.98]],"id":44621159},{"bdatb":[[8,5.7,79.02]],"id":44836671}]}]}
{"op":"mcm","clk":"AJTNAQCTZwCItgE=","pt":1659347793026,"mc":[{"id":"1.201590187","rc":[{"atb":[[20,1.76]],"id":44621159}]}]}
{"op":"mcm","clk":"AJbNAQCTZwCOtgE=","pt":1659347793076,"mc":[{"id":"1.201590187","rc":[{"bdatb":[[5,20,1.76]],"id":44621159}]}]}
{"op":"mcm","clk":"AJ3NAQCUZwCPtgE=","pt":1659347793131,"mc":[{"id":"1.201590187","rc":[{"atb":[[4.2,34.48]],"id":12989514},{"atb":[[11.5,31.6],[19.5,3.98]],"id":44621159},{"atb":[[5.7,96.26]],"id":44836671}]}]}
{"op":"mcm","clk":"AJ3NAQCUZwCXtgE=","pt":1659347793181,"mc":[{"id":"1.201590187","rc":[{"bdatb":[[6,19.5,3.98]],"id":44621159},{"bdatb":[[8,5.7,96.26]],"id":44836671}]}]}
{"op":"mcm","clk":"AMPNAQC2ZwC8tgE=","pt":1659347793553,"mc":[{"id":"1.201590187","rc":[{"atb":[[2.08,24.34],[2.04,1.21]],"atl":[[2.26,6.85],[2.3,0]],"id":9570503},{"atb":[[6.6,6.77],[6.4,11.38]],"atl":[[7.6,15.62]],"id":12989514},{"atb":[[6.8,20.87]],"atl":[[7.6,11.03]],"id":44836671},{"atb":[[9.2,9.29]],"id":43885158}]}]}
{"op":"mcm","clk":"ANDNAQDMZwDAtgE=","pt":1659347793603,"mc":[{"id":"1.201590187","rc":[{"bdatb":[[1,2.08,24.34],[3,2.04,1.21]],"bdatl":[[3,2.26,14.2],[4,2.3,1.1]],"id":9570503},{"bdatb":[[2,6.6,6.77],[3,6.4,11.38]],"bdatl":[[0,7.6,16.24]],"id":12989514},{"bdatb":[[1,6.8,21.22]],"bdatl":[[0,7.6,11.03]],"id":44836671},{"bdatb":[[1,9.2,9.29]],"id":43885158}]}]}
{"op":"mcm","clk":"ANXNAQDQZwDPtgE=","pt":1659347793660,"mc":[{"id":"1.201590187","rc":[{"atb":[[8.8,43.1]],"id":46969227}]}]}
{"op":"mcm","clk":"AN7NAQDWZwDWtgE=","pt":1659347793855,"mc":[{"id":"1.201590187","rc":[{"atl":[[23,1.49]],"id":46969227}]}]}
{"op":"mcm","clk":"AOTNAQDaZwDctgE=","pt":1659347793906,"mc":[{"id":"1.201590187","rc":[{"bdatl":[[0,23,1.74]],"id":46969227}]}]}
{"op":"mcm","clk":"AOXNAQDbZwDdtgE=","pt":1659347793956,"mc":[{"id":"1.201590187","rc":[{"atl":[[27,0]],"id":45323444},{"atl":[[2.42,0]],"id":9570503}]}]}
{"op":"mcm","clk":"AObNAQDcZwDktgE=","pt":1659347794006,"mc":[{"id":"1.201590187","rc":[{"bdatl":[[8,2.42,8.42]],"id":9570503}]}]}
{"op":"mcm","clk":"AO7NAQDcZwDmtgE=","pt":1659347794056,"mc":[{"id":"1.201590187","rc":[{"atl":[[19.5,3.2]],"bdatl":[[6,19.5,3.2]],"id":45323444},{"atl":[[2.38,14.24]],"bdatl":[[7,2.38,14.37],[8,2.4,34.87],[9,2.42,8.42]],"id":9570503}]}]}
{"op":"mcm","clk":"AP3NAQDlZwD3tgE=","pt":1659347794328,"mc":[{"id":"1.201590187","rc":[{"atb":[[10,10]],"id":45323444}]}]}
{"op":"mcm","clk":"AP/NAQDlZwD7tgE=","pt":1659347794379,"mc":[{"id":"1.201590187","rc":[{"bdatb":[[6,10,10.03]],"id":45323444}]}]}
{"op":"mcm","clk":"AIPOAQDpZwD8tgE=","pt":1659347794441,"mc":[{"id":"1.201590187","rc":[{"atb":[[11,11.16]],"id":45323444}]}]}
{"op":"mcm","clk":"AIXOAQDpZwD/tgE=","pt":1659347794491,"mc":[{"id":"1.201590187","rc":[{"bdatb":[[4,11,11.16]],"id":45323444}]}]}
{"op":"mcm","clk":"AL/OAQCUaACitwE=","pt":1659347794644,"mc":[{"id":"1.201590187","rc":[{"atb":[[7,5.18]],"trd":[[7,58.37]],"tv":172.83,"id":12989514}],"tv":2295.08}]}
{"op":"mcm","clk":"AMDOAQCUaACktwE=","pt":1659347794694,"mc":[{"id":"1.201590187","rc":[{"bdatl":[[5,2.32,4.11],[6,2.38,21.79],[7,2.4,34.87],[8,2.42,8.42],[9,2.44,32.31]],"id":9570503},{"bdatb":[[0,7,5.18]],"id":12989514}]}]}
{"op":"mcm","clk":"AMjOAQCdaACqtwE=","pt":1659347794846,"mc":[{"id":"1.201590187","rc":[{"atl":[[7.8,7.34]],"id":44836671}]}]}
{"op":"mcm","clk":"AMnOAQCfaACwtwE=","pt":1659347794896,"mc":[{"id":"1.201590187","rc":[{"bdatl":[[1,7.8,7.34]],"id":44836671}]}]}
{"op":"mcm","clk":"AM7OAQCjaACytwE=","pt":1659347794957,"mc":[{"id":"1.201590187","rc":[{"atl":[[7.6,15.03]],"id":44836671}]}]}
{"op":"mcm","clk":"ANHOAQCkaAC5twE=","pt":1659347795007,"mc":[{"id":"1.201590187","rc":[{"bdatl":[[0,7.6,15.03]],"id":44836671}]}]}
{"op":"mcm","clk":"AO3OAQCyaADStwE=","pt":1659347795423,"mc":[{"id":"1.201590187","rc":[{"atb":[[2.1,7.03]],"trd":[[2.1,182.77]],"tv":1285.18,"id":9570503}],"tv":2308.86}]}
{"op":"mcm","clk":"AO7OAQCyaADXtwE=","pt":1659347795473,"mc":[{"id":"1.201590187","rc":[{"bdatb":[[0,2.1,7.03]],"id":9570503},{"bdatl":[[8,9.2,2.54],[9,9.4,1.76]],"id":12989514},{"bdatl":[[5,900,1.18],[6,990,1.83]],"id":44621159},{"bdatl":[[8,14.5,14.89]],"id":43885158}]}]}
{"op":"mcm","clk":"AP7OAQC9aADktwE=","pt":1659347795644,"mc":[{"id":"1.201590187","rc":[{"atb":[[2.08,28.38]],"atl":[[2.26,10.5]],"id":9570503},{"atb":[[6.8,11.51]],"atl":[[7.6,17.82]],"id":12989514},{"atb":[[6.8,23.28]],"atl":[[7.8,10.48],[7.6,17.45]],"id":44836671},{"atb":[[9.2,11.59]],"id":43885158}]}]}
{"op":"mcm","clk":"AP7OAQC9aADrtwE=","pt":1659347795694,"mc":[{"id":"1.201590187","rc":[{"bdatb":[[1,2.08,28.38]],"bdatl":[[3,2.26,17.84],[9,2.44,39.16]],"id":9570503},{"bdatb":[[1,6.8,11.51]],"bdatl":[[0,7.6,18.44]],"id":12989514},{"bdatb":[[1,6.8,23.63]],"bdatl":[[0,7.6,17.45],[1,7.8,10.48]],"id":44836671},{"bdatb":[[1,9.2,11.59]],"id":43885158}]}]}
{"op":"mcm","clk":"AKbPAQDXaACUuAE=","pt":1659347796355,"mc":[{"id":"1.201590187","rc":[{"atl":[[13.5,1.76],[12.5,10]],"id":43885158}]}]}
{"op":"mcm","clk":"AKvPAQDbaACduAE=","pt":1659347796406,"mc":[{"id":"1.201590187","rc":[{"bdatl":[[4,12.5,10],[6,13.5,1.76]],"id":43885158}]}]}
{"op":"mcm","clk":"AMLPAQDnaAC4uAE=","pt":1659347796883,"mc":[{"id":"1.201590187","rc":[{"atb":[[2.08,30.38]],"id":9570503},{"atb":[[6.6,9.4]],"id":12989514},{"atl":[[10.5,2.56]],"id":43885158},{"atl":[[23,2.64]],"id":46969227}]}]}
{"op":"mcm","clk":"AMXPAQDoaAC+uAE=","pt":1659347796933,"mc":[{"id":"1.201590187","rc":[{"atb":[[16.5,5.76]],"bdatl":[[0,23,2.89]],"id":46969227},{"bdatb":[[1,2.08,30.38],[9,1.96,6.84]],"id":9570503},{"bdatb":[[2,6.6,9.4]],"id":12989514},{"bdatl":[[0,10.5,2.56]],"id":43885158}]}]}
{"op":"mcm","clk":"AMrPAQDpaADCuAE=","pt":1659347796983,"mc":[{"id":"1.201590187","rc":[{"bdatb":[[3,16.5,5.76]],"id":46969227}]}]}
{"op":"mcm","clk":"AMzPAQDsaADCuAE=","pt":1659347797033,"mc":[{"id":"1.201590187","rc":[{"atl":[[10.5,1.41]],"id":43885158},{"atb":[[18,2],[17.5,7.59]],"id":46969227}]}]}
{"op":"mcm","clk":"ANLPAQDsaADHuAE=","pt":1659347797083,"mc":[{"id":"1.201590187","rc":[{"bdatb":[[9,1.96,2.99]],"bdatl":[[6,2.38,14.69],[7,2.4,41.91]],"id":9570503},{"bdatl":[[0,10.5,1.41]],"id":43885158},{"bdatb":[[0,18,2],[1,17.5,7.59]],"id":46969227}]}]}
{"op":"mcm","clk":"AOzPAQD9aADhuAE=","pt":1659347797463,"mc":[{"id":"1.201590187","rc":[{"atb":[[2.14,30]],"id":9570503},{"atl":[[7.2,20]],"id":12989514},{"atl":[[7.4,10]],"id":44836671}]}]}
{"op":"mcm","clk":"AO3PAQD+aADmuAE=","pt":1659347797513,"mc":[{"id":"1.201590187","rc":[{"bdatb":[[4,11,11.18],[5,10.5,8.18],[6,10,10],[7,9.8,9.17],[8,9.6,21.63]],"bdatl":[[3,18,2.19],[5,19,2.64],[7,20,1.77],[8,21,1.76],[9,22,2.69]],"id":45323444},{"bdatb":[[0,2.14,30],[1,2.1,7.03],[2,2.08,30.38],[3,2.06,35.07],[4,2.04,1.31],[5,2.02,44.14],[6,2,97.74],[7,1.99,4.05],[8,1.98,87.79],[9,1.97,2.53]],"id":9570503},{"bdatb":[[5,6,1.84],[6,5.9,2.38],[7,5.8,35.31],[8,5.7,223.76],[9,5.6,2.06]],"bdatl":[[0,7.2,20],[1,7.6,18.44],[2,7.8,25.38],[3,8,1.76],[4,8.2,2.69],[5,8.4,4],[6,8.6,3.7],[7,8.8,1.76],[8,9,2.44],[9,9.2,2.77]],"id":12989514},{"bdatl":[[3,80,2.7],[5,900,1.14]],"id":44621159},{"bdatb":[[4,6.2,5.84],[5,6,218.61],[6,5.9,9],[8,5.7,96.55],[9,5.6,13.08]],"bdatl":[[0,7.4,10],[1,7.6,17.45],[2,7.8,10.48],[3,8,13.03],[4,8.2,7.07],[5,8.4,3],[6,8.6,2.65],[7,8.8,3.65],[8,9,3.1],[9,9.2,8]],"id":44836671},{"bdatb":[[5,8.2,1.82],[6,8,1.47],[7,7.8,2.21],[8,7.6,1.76],[9,7.4,2.55]],"bdatl":[[4,12.5,11.94],[5,13,1.77],[6,13.5,1.95],[8,14.5,14.51],[9,15,12.02]],"id":43885158},{"bdatb":[[9,13.5,1.79]],"bdatl":[[6,29,2.03],[8,32,2.28]],"id":46969227}]}]}
{"op":"mcm","clk":"APfPAQCDaQDtuAE=","pt":1659347797658,"mc":[{"id":"1.201590187","rc":[{"atl":[[7.4,10.68]],"id":44836671},{"atb":[[10,0],[9.6,2.79]],"trd":[[10,7.82],[9.6,6.02]],"ltp":9.6,"tv":201.41,"id":43885158}],"tv":2310.86}]}
{"op":"mcm","clk":"APrPAQCDaQD1uAE=","pt":1659347797709,"mc":[{"id":"1.201590187","rc":[{"bdatl":[[3,18,1.76],[5,19,3.04]],"id":45323444},{"bdatl":[[2,2.24,2.9],[3,2.26,21.21],[5,2.34,3.97],[6,2.38,14.8]],"id":9570503},{"bdatl":[[4,8.2,1.76],[6,8.6,4.59],[9,9.2,1.77]],"id":12989514},{"bdatl":[[3,80,2.67],[4,170,2.02],[5,900,1.15]],"id":44621159},{"bdatl":[[0,7.4,10.68],[6,8.6,1.76],[7,8.8,4.51],[8,9,2.05]],"id":44836671},{"bdatb":[[0,9.6,2.79]],"id":43885158},{"bdatl":[[6,29,1.76],[8,32,2.52]],"id":46969227}]}]}
{"op":"mcm","clk":"AILQAQCGaQD1uAE=","pt":1659347797768,"mc":[{"id":"1.201590187","rc":[{"atb":[[13,1.87]],"atl":[[17,1.33]],"id":45323444},{"atl":[[2.16,0]],"trd":[[2.16,3.54]],"ltp":2.16,"tv":1288.72,"id":9570503},{"atb":[[25,0.33]],"atl":[[36,1.15]],"id":44621159}],"tv":2314.4}]}
{"op":"mcm","clk":"AIfQAQCGaQD+uAE=","pt":1659347797818,"mc":[{"id":"1.201590187","rc":[{"bdatb":[[0,13,1.87],[4,11,11.16],[5,10.5,7.84],[6,10,10.03],[7,9.8,9.53],[8,9.6,21.23]],"bdatl":[[1,17,1.51]],"id":45323444},{"bdatb":[[8,1.98,83.39],[9,1.97,6.95]],"bdatl":[[0,2.2,3.51],[1,2.24,2.9],[2,2.26,21.21],[3,2.32,1.09],[4,2.36,3.93],[5,2.38,14.35],[6,2.4,35.6],[7,2.42,9.74],[8,2.44,40.94],[9,2.46,3.51]],"id":9570503},{"bdatb":[[5,6,1.8],[6,5.9,1.76],[7,5.8,35.34],[8,5.7,223.77],[9,5.6,2.71]],"bdatl":[[8,9,2.18],[9,9.2,2.03]],"id":12989514},{"bdatb":[[0,25,1.26]],"bdatl":[[0,36,1.57],[5,900,1.14]],"id":44621159},{"bdatb":[[4,6.2,5.81],[5,6,218],[6,5.9,9.03],[7,5.8,10.03],[8,5.7,97.17],[9,5.6,12.4]],"bdatl":[[8,9,1.78],[9,9.2,8.27]],"id":44836671},{"bdatb":[[5,8.2,1.79],[6,8,1.46],[7,7.8,1.78],[8,7.6,1.77],[9,7.4,3.04]],"bdatl":[[6,13.5,1.77],[7,14,13.37],[8,14.5,13.87],[9,15,12.38]],"id":43885158},{"bdatb":[[9,13.5,1.76]],"id":46969227}]}]}
{"op":"mcm","clk":"AIzQAQCKaQCEuQE=","pt":1659347797868,"mc":[{"id":"1.201590187","rc":[{"atb":[[7,0]],"trd":[[7,60.67]],"bdatb":[[0,6.8,11.51],[1,6.6,9.4],[2,6.4,11.38],[3,6.2,5.02],[4,6,1.8],[5,5.9,1.76],[6,5.8,35.34],[7,5.7,223.77],[8,5.6,2.71],[9,5.5,2.17]],"bdatl":[[9,9.2,1.76]],"tv":175.13,"id":12989514},{"atb":[[9.6,2.53]],"bdatb":[[0,9.6,2.53]],"bdatl":[[4,12.5,10],[5,13,1.76],[6,13.5,3.56],[7,14,13.2],[8,14.5,13.88],[9,15,12.16]],"id":43885158},{"bdatl":[[5,19,1.76],[7,20,1.76],[8,21,2.92],[9,22,2.58]],"id":45323444},{"bdatl":[[2,2.26,10.5],[3,2.28,10.62],[4,2.36,1.07],[5,2.38,16.62],[6,2.4,37.22],[8,2.44,29.62],[9,2.46,11.23]],"id":9570503},{"bdatl":[[3,80,2.32],[4,170,2.24]],"id":44621159},{"bdatl":[[7,8.8,1.76],[8,9,1.76],[9,9.2,10.64]],"id":44836671},{"bdatl":[[8,32,1.76]],"id":46969227}],"tv":2316.7}]}
{"op":"mcm","clk":"AJLQAQCNaQCIuQE=","pt":1659347797937,"mc":[{"id":"1.201590187","rc":[{"atb":[[6.8,15.54]],"id":12989514}]}]}
{"op":"mcm","clk":"AJPQAQCOaQCMuQE=","pt":1659347797987,"mc":[{"id":"1.201590187","rc":[{"bdatl":[[8,2.44,40.85],[9,2.5,31.12]],"id":9570503},{"bdatb":[[0,6.8,15.54]],"id":12989514}]}]}
{"op":"mcm","clk":"AJnQAQCQaQCNuQE=","pt":1659347798039,"mc":[{"id":"1.201590187","rc":[{"atl":[[17,2.66]],"id":45323444},{"atl":[[2.26,7]],"id":9570503},{"atb":[[6.6,23.01],[6.8,10.8]],"atl":[[7.2,20.69]],"id":12989514},{"atl":[[36,2.48]],"id":44621159}]}]}
{"op":"mcm","clk":"AJzQAQCRaQCSuQE=","pt":1659347798090,"mc":[{"id":"1.201590187","rc":[{"bdatl":[[1,17,2.84]],"id":45323444},{"bdatb":[[8,1.98,87.79],[9,1.97,2.53]],"bdatl":[[2,2.26,7],[8,2.44,27.64],[9,2.46,13.2]],"id":9570503},{"bdatb":[[0,6.8,10.8],[1,6.6,23.01]],"bdatl":[[0,7.2,20.69]],"id":12989514},{"bdatl":[[0,36,2.9]],"id":44621159}]}]}
{"op":"mcm","clk":"AKHQAQCSaQCSuQE=","pt":1659347798142,"mc":[{"id":"1.201590187","rc":[{"atb":[[8.8,62.84]],"id":45323444}]}]}
{"op":"mcm","clk":"ALLQAQCcaQCauQE=","pt":1659347798348,"mc":[{"id":"1.201590187","rc":[{"atb":[[11.5,1.97]],"atl":[[19.5,1.76]],"id":45323444},{"atb":[[1.77,50.78]],"id":9570503},{"atb":[[7.2,0]],"atl":[[7.2,2.92]],"trd":[[7.2,27.85]],"ltp":7.2,"tv":553.35,"id":44836671}],"tv":2323.45}]}
{"op":"mcm","clk":"ALXQAQCdaQChuQE=","pt":1659347798398,"mc":[{"id":"1.201590187","rc":[{"bdatb":[[3,11.5,1.97],[5,10.5,7.86],[6,10,10.75],[7,9.8,9],[8,9.6,21]],"bdatl":[[6,19.5,1.76],[8,21,1.76]],"id":45323444},{"bdatb":[[3,2.06,35.14],[4,2.04,3.83],[5,2.02,46.14],[6,2,96.2],[7,1.99,1.76],[8,1.98,86.96]],"bdatl":[[3,2.3,1.07],[4,2.34,9.34],[5,2.38,17.63],[9,2.46,5.71]],"id":9570503},{"bdatb":[[5,5.9,1.79],[7,5.7,224.67],[8,5.6,2.16],[9,5.5,1.76]],"bdatl":[[6,8.6,1.76],[7,8.8,2.04],[8,9,2.17],[9,9.2,4.14]],"id":12989514},{"bdatl":[[4,170,2.01],[5,900,1.18]],"id":44621159},{"bdatb":[[0,6.8,23.63],[1,6.6,7.16],[2,6.4,35.31],[3,6.2,5.81],[4,6,218],[5,5.9,9.03],[6,5.8,10.03],[7,5.7,97.17],[8,5.6,12.4],[9,5.5,13]],"bdatl":[[0,7.2,2.92],[1,7.4,10.68],[2,7.6,17.45],[3,7.8,10.48],[4,8,13.03],[5,8.2,7.07],[6,8.4,3],[7,8.6,1.76],[8,8.8,1.76],[9,9,1.76]],"id":44836671},{"bdatb":[[6,8,1.48],[7,7.8,1.77],[8,7.6,2.46],[9,7.4,2.62]],"bdatl":[[6,13.5,1.76],[7,14,13.38],[8,14.5,13.87],[9,15,13.45]],"id":43885158}]}]}
{"op":"mcm","clk":"ALvQAQCeaQCiuQE=","pt":1659347798458,"mc":[{"id":"1.201590187","rc":[{"atb":[[1.02,1.6]],"atl":[[23,3.2]],"id":45323444},{"atl":[[7.2,0]],"trd":[[7.2,33.69]],"tv":559.19,"id":44836671}],"tv":2329.29}]}
{"op":"mcm","clk":"AL7QAQCgaQCmuQE=","pt":1659347798508,"mc":[{"id":"1.201590187","rc":[{"bdatb":[[5,10.5,7.84],[6,10,10.03],[7,9.8,9.53],[8,9.6,21.23]],"id":45323444},{"bdatb":[[3,2.06,35.07],[4,2.04,1.31],[5,2.02,44.14],[6,2,97.74],[7,1.99,4.05],[8,1.98,87.79]],"id":9570503},{"bdatb":[[5,5.9,1.76],[7,5.7,223.77],[8,5.6,2.71],[9,5.5,2.17]],"id":12989514},{"bdatl":[[0,7.4,10.68],[1,7.6,17.45],[2,7.8,10.48],[3,8,13.03],[4,8.2,7.07],[5,8.4,3],[6,8.6,1.76],[7,8.8,1.76],[8,9,1.76],[9,9.2,10.64]],"id":44836671},{"bdatb":[[6,8,1.46],[7,7.8,1.78],[8,7.6,1.77],[9,7.4,3.04]],"id":43885158}]}]}
{"op":"mcm","clk":"AMTQAQCiaQCpuQE=","pt":1659347798570,"mc":[{"id":"1.201590187","rc":[{"atb":[[7,0]],"atl":[[8.2,6.76],[7.2,0.69]],"id":44836671}]}]}
{"op":"mcm","clk":"AMTQAQCiaQCpuQE=","pt":1659347798621,"mc":[{"id":"1.201590187","rc":[{"bdatb":[[5,10.5,7.86],[6,10,10.48],[7,9.8,9.05]],"id":45323444},{"bdatb":[[3,2.06,35.14],[4,2.04,3.57],[5,2.02,41.79]],"bdatl":[[3,2.34,10.39],[4,2.38,17.63],[5,2.4,37.22],[6,2.42,9.74],[7,2.44,27.64],[8,2.46,5.71],[9,2.5,38.4]],"id":9570503},{"bdatb":[[5,5.9,1.79],[7,5.7,224.58],[8,5.6,1.86]],"bdatl":[[7,8.8,1.76],[9,9.2,4.41]],"id":12989514},{"bdatl":[[4,170,2],[5,900,1.19]],"id":44621159},{"bdatb":[[0,6.8,23.28]],"bdatl":[[0,7.4,11.37],[4,8.2,6.76]],"id":44836671},{"bdatb":[[6,8,1.48],[7,7.8,1.77],[8,7.6,2.39],[9,7.4,2.39]],"bdatl":[[7,14,13.2],[9,15,13.61]],"id":43885158}]}]}
{"op":"mcm","clk":"AMXQAQClaQCpuQE=","pt":1659347798685,"mc":[{"id":"1.201590187","rc":[{"atb":[[6.6,9.94]],"atl":[[7.4,18.28],[8.2,1.76]],"id":44836671}]}]}
{"op":"mcm","clk":"AMzQAQCmaQCuuQE=","pt":1659347798735,"mc":[{"id":"1.201590187","rc":[{"bdatb":[[1,6.6,9.94]],"bdatl":[[0,7.4,18.97],[4,8.2,1.76]],"id":44836671}]}]}
{"op":"mcm","clk":"ANTQAQCraQCzuQE=","pt":1659347798786,"mc":[{"id":"1.201590187","rc":[{"atl":[[2.2,18.51]],"bdatl":[[0,2.2,18.51]],"id":9570503},{"atl":[[8,8.08]],"bdatb":[[8,5.6,13.66]],"bdatl":[[3,8,8.08]],"id":44836671},{"atb":[[8.8,6.07]],"bdatb":[[2,8.8,6.07]],"id":43885158},{"bdatb":[[8,9.6,21.92],[9,9.4,11.08]],"id":45323444},{"bdatb":[[9,5.5,3.46]],"id":12989514}]}]}
{"op":"mcm","clk":"AN/QAQCwaQC8uQE=","pt":1659347798952,"mc":[{"id":"1.201590187","rc":[{"atb":[[6.6,19.01]],"id":12989514}]}]}
{"op":"mcm","clk":"AOPQAQCyaQDBuQE=","pt":1659347799002,"mc":[{"id":"1.201590187","rc":[{"bdatb":[[1,6.6,19.01]],"id":12989514}]}]}
{"op":"mcm","clk":"AOjQAQCyaQDBuQE=","pt":1659347799055,"mc":[{"id":"1.201590187","rc":[{"atb":[[6.6,15.94]],"id":44836671}]}]}
{"op":"mcm","clk":"AOnQAQC0aQDHuQE=","pt":1659347799106,"mc":[{"id":"1.201590187","rc":[{"bdatb":[[1,6.6,15.94]],"id":44836671}]}]}
{"op":"mcm","clk":"AIrRAQDOaQDkuQE=","pt":1659347799632,"mc":[{"id":"1.201590187","rc":[{"atb":[[2.1,9.39]],"atl":[[2.2,23.51]],"id":9570503}]}]}
{"op":"mcm","clk":"AIvRAQDPaQDuuQE=","pt":1659347799683,"mc":[{"id":"1.201590187","rc":[{"bdatb":[[1,2.1,9.39]],"bdatl":[[0,2.2,23.51]],"id":9570503}]}]}
{"op":"mcm","clk":"AJTRAQDWaQD2uQE=","pt":1659347799841,"mc":[{"id":"1.201590187","rc":[{"atb":[[11,7.02]],"id":45323444},{"atb":[[17.5,5.39]],"id":46969227}]}]}
{"op":"mcm","clk":"AJbRAQDYaQCAugE=","pt":1659347799891,"mc":[{"id":"1.201590187","rc":[{"bdatb":[[4,11,7.02]],"id":45323444},{"bdatl":[[9,2.5,38.16]],"id":9570503},{"bdatb":[[1,17.5,5.39]],"id":46969227}]}]}
{"op":"mcm","clk":"AJrRAQDbaQCBugE=","pt":1659347799953,"mc":[{"id":"1.201590187","rc":[{"atb":[[10,14.14]],"id":45323444},{"atb":[[17,8.2]],"id":46969227}]}]}
{"op":"mcm","clk":"AJ7RAQDeaQCHugE=","pt":1659347800003,"mc":[{"id":"1.201590187","rc":[{"bdatb":[[6,10,14.61]],"id":45323444},{"bdatb":[[2,17,8.2]],"id":46969227}]}]}
{"op":"mcm","clk":"AKLRAQDgaQCIugE=","pt":1659347800056,"mc":[{"id":"1.201590187","rc":[{"atb":[[2.14,20.39]],"trd":[[2.14,178.3]],"ltp":2.14,"tv":1307.94,"id":9570503}],"tv":2348.51}]}
{"op":"mcm","clk":"AKbRAQDkaQCPugE=","pt":1659347800107,"mc":[{"id":"1.201590187","rc":[{"bdatb":[[0,2.14,20.39]],"id":9570503}]}]}
{"op":"mcm","clk":"AK7RAQDmaQCUugE=","pt":1659347800171,"mc":[{"id":"1.201590187","rc":[{"atb":[[6.8,8.34]],"id":12989514}]}]}
{"op":"mcm","clk":"AK7RAQDpaQCXugE=","pt":1659347800222,"mc":[{"id":"1.201590187","rc":[{"bdatl":[[6,2.42,6.41],[7,2.44,27.39],[8,2.46,9.23]],"id":9570503},{"bdatb":[[0,6.8,8.34]],"id":12989514}]}]}
{"op":"mcm","clk":"ALHRAQDvaQCYugE=","pt":1659347800272,"mc":[{"id":"1.201590187","rc":[{"atl":[[2.24,6.69]],"bdatl":[[1,2.24,6.69]],"id":9570503}]}]}
{"op":"mcm","clk":"ALvRAQD1aQClugE=","pt":1659347800431,"mc":[{"id":"1.201590187","rc":[{"atb":[[6.8,8.2]],"id":12989514}]}]}
{"op":"mcm","clk":"AL7RAQD4aQCrugE=","pt":1659347800481,"mc":[{"id":"1.201590187","rc":[{"bdatl":[[6,2.42,6.01],[7,2.44,27.79]],"id":9570503},{"bdatb":[[0,6.8,8.2]],"id":12989514}]}]}
{"op":"mcm","clk":"APHRAQCZagDbugE=","pt":1659347801370,"mc":[{"id":"1.201590187","rc":[{"atl":[[11.5,5.87],[11,0.25]],"id":43885158}]}]}
{"op":"mcm","clk":"APrRAQCaagDcugE=","pt":1659347801420,"mc":[{"id":"1.201590187","rc":[{"bdatb":[[7,1.99,3.15],[8,1.98,70.48],[9,1.97,4.96]],"id":9570503},{"bdatl":[[1,11.5,6.12],[2,12,10.85],[3,12.5,10],[4,13,1.76],[5,13.5,1.76],[6,14,13.2],[7,14.5,13.87],[8,15,13.61],[9,15.5,20.01]],"id":43885158}]}]}
{"op":"mcm","clk":"AP7RAQCdagDgugE=","pt":1659347801512,"mc":[{"id":"1.201590187","rc":[{"atl":[[38,0.46]],"id":44621159}]}]}
{"op":"mcm","clk":"AILSAQCtagDiugE=","pt":1659347801562,"mc":[{"id":"1.201590187","rc":[{"bdatl":[[1,40,3.73],[2,80,2.32],[3,170,2],[4,900,1.19],[5,990,1.83],[6,1000,2],[7,0,0]],"id":44621159}]}]}
{"op":"mcm","clk":"AIbSAQCwagDmugE=","pt":1659347801621,"mc":[{"id":"1.201590187","rc":[{"atb":[[2.1,17.58]],"atl":[[2.24,9.08]],"id":9570503},{"atl":[[48,0.91]],"id":44621159}]}]}
{"op":"mcm","clk":"AIjSAQCxagDpugE=","pt":1659347801671,"mc":[{"id":"1.201590187","rc":[{"bdatb":[[1,2.1,17.58]],"bdatl":[[1,2.24,9.08]],"id":9570503},{"bdatl":[[2,48,1.03],[3,80,2.2],[4,170,2],[5,900,1.19],[6,990,1.83],[7,1000,2]],"id":44621159}]}]}
{"op":"mcm","clk":"ALDSAQC/agCXuwE=","pt":1659347802367,"mc":[{"id":"1.201590187","rc":[{"atb":[[6.6,21.41]],"id":12989514}]}]}
{"op":"mcm","clk":"ALDSAQC/agCbuwE=","pt":1659347802417,"mc":[{"id":"1.201590187","rc":[{"bdatb":[[1,6.6,21.41]],"id":12989514}]}]}
{"op":"mcm","clk":"ALXSAQDBagCcuwE=","pt":1659347802467,"mc":[{"id":"1.201590187","rc":[{"atb":[[8.2,20.39]],"id":45323444},{"atb":[[1.92,14]],"id":9570503},{"atb":[[4.9,72.02]],"id":12989514},{"atb":[[15,2]],"id":44621159},{"atb":[[4.9,14]],"id":44836671},{"atb":[[6.6,78.72]],"id":43885158},{"atb":[[10.5,9]],"id":46969227}]}]}
{"op":"mcm","clk":"AMLSAQDGagCruwE=","pt":1659347802718,"mc":[{"id":"1.201590187","rc":[{"atl":[[2.24,11.47]],"id":9570503},{"atl":[[7.6,28.46]],"id":12989514}]}]}
{"op":"mcm","clk":"AMXSAQDGagCtuwE=","pt":1659347802768,"mc":[{"id":"1.201590187","rc":[{"bdatl":[[1,2.24,11.47]],"id":9570503},{"bdatl":[[1,7.6,29.08]],"id":12989514}]}]}
{"op":"mcm","clk":"ANDSAQDPagC6uwE=","pt":1659347802943,"mc":[{"id":"1.201590187","rc":[{"atl":[[7.2,7.69],[8,2.08]],"id":44836671},{"atb":[[9.2,6.29]],"id":43885158}]}]}
{"op":"mcm","clk":"ANHSAQDSagC+uwE=","pt":1659347802993,"mc":[{"id":"1.201590187","rc":[{"bdatb":[[6,10,15.55],[8,9.6,21],[9,9.4,11.32]],"id":45323444},{"bdatb":[[4,2.04,3.83],[5,2.02,46.14],[6,2,94.46],[7,1.99,2.67],[8,1.98,71.98],[9,1.97,19.3]],"bdatl":[[8,2.46,7.09],[9,2.5,23.1]],"id":9570503},{"bdatb":[[7,5.7,224.67],[8,5.6,3.43],[9,5.5,1.76]],"id":12989514},{"bdatl":[[0,7.2,7.69],[1,7.4,18.28],[2,7.6,17.45],[3,7.8,10.48],[4,8,2.08],[5,8.2,1.76],[6,8.4,3],[7,8.6,1.76],[8,8.8,1.76],[9,9,1.76]],"id":44836671},{"bdatb":[[1,9.2,6.29],[8,7.6,2.46],[9,7.4,4.2]],"id":43885158}]}]}
{"op":"mcm","clk":"ANfSAQDUagDCuwE=","pt":1659347803043,"mc":[{"id":"1.201590187","rc":[{"atl":[[2.24,16.57]],"id":9570503},{"atb":[[9.4,5.4]],"atl":[[11,2.65]],"id":43885158}]}]}
{"op":"mcm","clk":"ANjSAQDUagDLuwE=","pt":1659347803093,"mc":[{"id":"1.201590187","rc":[{"bdatb":[[9,9.4,14.12]],"id":45323444},{"bdatb":[[6,2,96.85],[7,1.99,12.63],[8,1.98,70.48],[9,1.97,8.33]],"bdatl":[[1,2.24,16.57],[4,2.36,3.42],[5,2.38,17.95],[6,2.4,39.61],[8,2.46,9.23],[9,2.5,38.16]],"id":9570503},{"bdatb":[[1,9.4,5.4],[2,9.2,6.29],[3,8.8,6.07],[4,8.6,20],[5,8.4,3.76],[6,8.2,1.79],[7,8,1.48],[8,7.8,1.77],[9,7.6,2.46]],"bdatl":[[1,11,2.65],[2,11.5,5.87],[3,12,10.85],[4,12.5,10],[5,13,1.76],[6,13.5,1.76],[7,14,13.2],[8,14.5,13.87],[9,15,13.61]],"id":43885158}]}]}
{"op":"mcm","clk":"APHSAQDhagDjuwE=","pt":1659347803472,"mc":[{"id":"1.201590187","rc":[{"atl":[[16.5,1.33]],"id":45323444},{"atl":[[10.5,2.56]],"id":43885158},{"atb":[[18,3.15]],"atl":[[21,5.01]],"id":46969227}]}]}
{"op":"mcm","clk":"APHSAQDhagDmuwE=","pt":1659347803523,"mc":[{"id":"1.201590187","rc":[{"bdatb":[[5,10.5,7.87],[6,10,16.79],[7,9.8,11.54],[9,9.4,11.02]],"bdatl":[[1,16.5,1.33],[2,17,2.66],[3,17.5,1.76],[4,18,1.76],[5,18.5,1.76],[6,19,1.76],[7,19.5,1.76],[8,20,1.76],[9,21,1.76]],"id":45323444},{"bdatb":[[4,2.04,10.62],[5,2.02,45.25],[6,2,107.34],[7,1.99,2.09],[8,1.98,85.85],[9,1.97,11.16]],"bdatl":[[9,2.5,39.2]],"id":9570503},{"bdatb":[[6,5.8,37.75],[7,5.7,225.97],[8,5.6,1.76],[9,5.5,6.28]],"id":12989514},{"bdatb":[[6,5.8,12.44],[7,5.7,98.47],[8,5.6,12],[9,5.5,17.52]],"id":44836671},{"bdatb":[[8,7.8,3.58],[9,7.6,2.43]],"bdatl":[[0,10.5,2.56]],"id":43885158},{"bdatb":[[0,18,3.15]],"bdatl":[[0,21,5.01],[1,23,2.88],[2,24,5.22],[3,25,1.86],[4,26,10],[5,27,1.76],[6,28,7.55],[7,29,1.76],[8,30,1.83],[9,32,1.76]],"id":46969227}]}]}
{"op":"mcm","clk":"APnSAQDlagDsuwE=","pt":1659347803667,"mc":[{"id":"1.201590187","rc":[{"atl":[[2.24,18.96]],"id":9570503},{"atl":[[7.8,7.34]],"id":44836671},{"atl":[[10.5,1.41]],"id":43885158}]}]}
{"op":"mcm","clk":"APnSAQDlagDxuwE=","pt":1659347803717,"mc":[{"id":"1.201590187","rc":[{"bdatb":[[6,10,15.58],[7,9.8,11.97],[9,9.4,11.85]],"id":45323444},{"bdatb":[[4,2.04,8.39],[5,2.02,43.79],[6,2,105.39],[7,1.99,7.5],[8,1.98,86.18]],"bdatl":[[1,2.24,18.96]],"id":9570503},{"bdatb":[[7,5.7,223.85],[8,5.6,2.58],[9,5.5,6.24]],"id":12989514},{"bdatb":[[7,5.7,96.35],[8,5.6,12.81],[9,5.5,17.47]],"bdatl":[[3,7.8,7.34]],"id":44836671},{"bdatl":[[0,10.5,1.41]],"id":43885158}]}]}
{"op":"mcm","clk":"APrSAQDqagDxuwE=","pt":1659347803769,"mc":[{"id":"1.201590187","rc":[{"atb":[[2.16,5]],"id":9570503},{"atb":[[6.4,1.76]],"id":44836671},{"atl":[[21,5.26]],"id":46969227}]}]}
{"op":"mcm","clk":"AIbTAQDragD4uwE=","pt":1659347803819,"mc":[{"id":"1.201590187","rc":[{"atb":[[2.16,0],[2.14,5.39]],"trd":[[2.16,13.54],[2.14,208.3]],"bdatb":[[0,2.16,5],[1,2.14,20.39],[2,2.1,17.58],[3,2.08,30.38],[4,2.06,35.14],[5,2.04,8.39],[6,2.02,43.79],[7,2,105.39],[8,1.99,7.5],[9,1.98,86.18]],"tv":1347.94,"id":9570503},{"atb":[[6.2,39.36]],"bdatb":[[2,6.4,1.76]],"bdatl":[[8,8.8,2.99]],"id":44836671},{"bdatl":[[7,8.8,2.99],[9,9.2,3.23]],"id":12989514},{"bdatl":[[4,170,2.07],[5,900,1.17]],"id":44621159},{"bdatl":[[7,14,13.97],[9,15,12.89]],"id":43885158},{"bdatl":[[0,21,5.26]],"id":46969227}],"tv":2388.51}]}
{"op":"mcm","clk":"AInTAQDragD7uwE=","pt":1659347803869,"mc":[{"id":"1.201590187","rc":[{"bdatb":[[0,2.14,5.39],[1,2.1,17.58],[2,2.08,30.38],[3,2.06,35.14],[4,2.04,8.39],[5,2.02,43.79],[6,2,105.39],[7,1.99,7.5],[8,1.98,86.18],[9,1.97,11.16]],"id":9570503},{"bdatl":[[7,8.8,1.76],[9,9.2,3.02]],"id":12989514},{"bdatl":[[4,170,2],[5,900,1.16]],"id":44621159},{"bdatb":[[3,6.2,39.36]],"bdatl":[[8,8.8,1.76]],"id":44836671},{"bdatl":[[7,14,13.2],[9,15,12.77]],"id":43885158}]}]}
{"op":"mcm","clk":"AI7TAQDtagD+uwE=","pt":1659347803936,"mc":[{"id":"1.201590187","rc":[{"atb":[[2.14,7.04],[2.04,0]],"id":9570503},{"atl":[[23,2.16]],"id":46969227}]}]}
{"op":"mcm","clk":"AI/TAQDtagCFvAE=","pt":1659347803986,"mc":[{"id":"1.201590187","rc":[{"bdatb":[[0,2.14,7.04],[4,2.04,7.18]],"id":9570503},{"bdatl":[[9,9.2,3.4]],"id":12989514},{"bdatl":[[5,900,1.17]],"id":44621159},{"bdatl":[[9,15,13]],"id":43885158},{"bdatl":[[1,23,2.4]],"id":46969227}]}]}
{"op":"mcm","clk":"AJLTAQDvagCGvAE=","pt":1659347804038,"mc":[{"id":"1.201590187","rc":[{"atb":[[2.14,5.39]],"id":9570503},{"atl":[[1000,0.47]],"id":46969227}]}]}
{"op":"mcm","clk":"AJTTAQDvagCKvAE=","pt":1659347804088,"mc":[{"id":"1.201590187","rc":[{"bdatb":[[0,2.14,5.39]],"id":9570503},{"bdatl":[[9,9.2,3.02]],"id":12989514},{"bdatl":[[5,900,1.16]],"id":44621159},{"bdatl":[[9,15,12.77]],"id":43885158}]}]}
{"op":"mcm","clk":"ALHTAQD/agCtvAE=","pt":1659347804767,"mc":[{"id":"1.201590187","rc":[{"atl":[[2.24,13.67]],"id":9570503},{"atb":[[18,0],[17.5,0]],"atl":[[17.5,26.46]],"trd":[[18,6.3],[17.5,10.78]],"ltp":17.5,"tv":72.8,"id":46969227}],"tv":2405.59}]}
{"op":"mcm","clk":"ALTTAQD/agCxvAE=","pt":1659347804818,"mc":[{"id":"1.201590187","rc":[{"bdatb":[[3,11.5,3.22],[4,11,7.07],[5,10.5,10.61],[6,10,14.91],[7,9.8,9],[8,9.6,21.38],[9,9.4,11.02]],"id":45323444},{"bdatb":[[1,2.1,17.73],[2,2.08,37.34],[3,2.06,37.28],[4,2.04,12.05],[5,2.02,47.18],[6,2,121.16],[7,1.99,4.68],[8,1.98,86.46],[9,1.97,2.53]],"bdatl":[[1,2.24,13.67],[3,2.34,10.34],[4,2.38,17.68],[5,2.4,37.22],[6,2.42,6.01],[8,2.46,4.19],[9,2.48,5]],"id":9570503},{"bdatb":[[3,6.2,5.07],[4,6,4.22],[5,5.9,2.54],[6,5.8,39.55],[7,5.7,223.76],[8,5.6,3.15],[9,5.5,1.76]],"bdatl":[[9,9.2,1.76]],"id":12989514},{"bdatb":[[6,19.5,3.99],[8,18.5,3.49]],"bdatl":[[5,900,1.14]],"id":44621159},{"bdatb":[[3,6.2,39.41],[4,6,220.41],[5,5.9,9.77],[6,5.8,14.24],[7,5.7,96.26],[8,5.6,13.39],[9,5.5,13]],"id":44836671},{"bdatb":[[4,8.6,20.02],[5,8.4,5.45],[6,8.2,2.41],[7,8,5.51],[8,7.8,1.76],[9,7.6,1.76]],"bdatl":[[9,15,12]],"id":43885158},{"bdatb":[[0,17,8.2],[1,16.5,5.76],[2,16,8],[3,15.5,1.76],[4,15,1.78],[5,14.5,1.76],[6,14,1.76],[7,13.5,1.76],[8,13,1.78],[9,12,1.22]],"bdatl":[[0,17.5,26.46],[1,21,5.26],[2,23,2.4],[3,24,5.22],[4,25,1.86],[5,26,10],[6,27,1.76],[7,28,7.55],[8,29,1.76],[9,30,1.83]],"id":46969227}]}]}
{"op":"mcm","clk":"ALzTAQCCawC1vAE=","pt":1659347804963,"mc":[{"id":"1.201590187","rc":[{"atb":[[17,2.2],[16,0],[16.5,1.76]],"atl":[[25,1.76]],"id":46969227}]}]}
{"op":"mcm","clk":"ALzTAQCDawC8vAE=","pt":1659347805013,"mc":[{"id":"1.201590187","rc":[{"bdatl":[[7,2.44,24.09],[8,2.46,3.67],[9,2.5,25.13]],"id":9570503},{"bdatb":[[0,17,2.2],[1,16.5,1.76],[2,15.5,1.76],[3,15,1.78],[4,14.5,1.76],[5,14,1.76],[6,13.5,1.76],[7,13,1.78],[8,12,1.22],[9,11.5,8.21]],"bdatl":[[4,25,1.76]],"id":46969227}]}]}
{"op":"mcm","clk":"AMXTAQCGawC/vAE=","pt":1659347805133,"mc":[{"id":"1.201590187","rc":[{"atb":[[17,0]],"atl":[[17.5,0]],"trd":[[17,4.39]],"ltp":17,"tv":77.19,"id":46969227}],"tv":2409.98}]}
{"op":"mcm","clk":"AMbTAQCGawDCvAE=","pt":1659347805183,"mc":[{"id":"1.201590187","rc":[{"bdatb":[[3,11.5,1.97],[4,11,7.02],[5,10.5,7.87],[6,10,15.58],[7,9.8,11.97],[8,9.6,21],[9,9.4,11.85]],"id":45323444},{"bdatb":[[1,2.1,17.58],[2,2.08,30.38],[3,2.06,35.14],[4,2.04,7.18],[5,2.02,43.79],[6,2,105.39],[7,1.99,7.5],[8,1.98,86.18],[9,1.97,11.16]],"bdatl":[[3,2.36,10.3],[4,2.38,14.25],[5,2.4,35.54],[6,2.42,4.99],[7,2.44,30.05],[8,2.48,3.64],[9,2.5,21]],"id":9570503},{"bdatb":[[3,6.2,5.02],[4,6,1.8],[5,5.9,1.79],[6,5.8,37.75],[7,5.7,223.85],[8,5.6,2.58],[9,5.5,6.24]],"id":12989514},{"bdatb":[[6,19.5,3.98],[8,18.5,2.7]],"id":44621159},{"bdatb":[[3,6.2,39.36],[4,6,218],[5,5.9,9.03],[6,5.8,12.44],[7,5.7,96.35],[8,5.6,12.81],[9,5.5,17.47]],"id":44836671},{"bdatb":[[4,8.6,20],[5,8.4,3.76],[6,8.2,1.79],[7,8,1.48],[8,7.8,3.58],[9,7.6,2.43]],"id":43885158},{"bdatb":[[0,16.5,1.76],[1,15.5,1.76],[2,15,1.78],[3,14.5,1.76],[4,14,1.76],[5,13.5,1.76],[6,13,1.78],[7,12,1.22],[8,11.5,8.21],[9,11,2.24]],"bdatl":[[0,21,5.26],[1,23,2.4],[2,24,5.22],[3,25,1.76],[4,26,10],[5,27,1.76],[6,28,7.55],[7,29,1.76],[8,30,1.83],[9,32,1.76]],"id":46969227}]}]}
{"op":"mcm","clk":"ANbTAQCPawDKvAE=","pt":1659347805453,"mc":[{"id":"1.201590187","rc":[{"atl":[[7.2,17.82]],"trd":[[7.2,11.99]],"ltp":7.2,"tv":180.88,"id":12989514},{"atl":[[7.2,3.95]],"trd":[[7.2,41.16]],"tv":566.66,"id":44836671},{"atb":[[16.5,0]],"id":46969227}],"tv":2423.2}]}
{"op":"mcm","clk":"ANbTAQCSawDLvAE=","pt":1659347805503,"mc":[{"id":"1.201590187","rc":[{"bdatb":[[7,9.8,10.39],[9,9.4,12.67]],"id":45323444},{"bdatb":[[6,2,104.06],[7,1.99,3.1],[8,1.98,91.95]],"bdatl":[[3,2.38,24.46],[4,2.4,33.55],[5,2.42,1.25],[6,2.44,29.77],[7,2.46,5.23],[8,2.5,25.29],[9,2.52,4.09]],"id":9570503},{"bdatb":[[9,5.5,3.42]],"bdatl":[[0,7.2,17.82]],"id":12989514},{"bdatl":[[0,7.2,3.95]],"id":44836671},{"bdatb":[[0,15.5,1.76],[1,15,1.78],[2,14.5,1.76],[3,14,1.76],[4,13.5,1.76],[5,13,1.78],[6,12,1.22],[7,11.5,8.21],[8,10.5,11.31],[9,10,7.88]],"id":46969227}]}]}
{"op":"mcm","clk":"ANvTAQCTawDMvAE=","pt":1659347805554,"mc":[{"id":"1.201590187","rc":[{"atb":[[6.6,22.98]],"atl":[[7.8,0.34],[7.6,9.45],[7.4,12.28],[7.2,0]],"id":44836671}]}]}
{"op":"mcm","clk":"ANzTAQCTawDSvAE=","pt":1659347805604,"mc":[{"id":"1.201590187","rc":[{"bdatb":[[5,10.5,7.84],[6,10,15.57],[7,9.8,9.05],[9,9.4,14.12]],"id":45323444},{"bdatb":[[3,2.06,35.07],[4,2.02,48.86],[5,2,106.33],[6,1.99,3.1],[7,1.98,91.95],[8,1.97,4.78],[9,1.96,9.15]],"id":9570503},{"bdatb":[[5,5.9,1.76],[6,5.8,35.34],[7,5.7,223.79],[8,5.6,4.35],[9,5.5,2.59]],"id":12989514},{"bdatb":[[1,6.6,22.98]],"bdatl":[[0,7.4,12.28],[1,7.6,9.45],[2,8,2.42],[3,8.2,1.76],[4,8.4,3],[5,8.6,1.76],[6,8.8,1.76],[7,9,1.76],[8,9.2,8],[9,9.4,1.76]],"id":44836671},{"bdatb":[[7,8,1.46],[8,7.8,1.78],[9,7.6,1.79]],"id":43885158},{"bdatb":[[5,13,1.76],[6,11.5,9.1],[7,10.5,11.75],[8,10,7.88],[9,9.4,3.26]],"id":46969227}]}]}
{"op":"mcm","clk":"AOHTAQCVawDUvAE=","pt":1659347805661,"mc":[{"id":"1.201590187","rc":[{"atl":[[7.2,1.6]],"id":44836671},{"atb":[[12.5,1.76]],"atl":[[19.5,1.76]],"id":46969227}]}]}
{"op":"mcm","clk":"AOLTAQCVawDXvAE=","pt":1659347805711,"mc":[{"id":"1.201590187","rc":[{"bdatb":[[4,11,7.05],[5,10.5,8.9],[6,10,14.46],[7,9.8,11],[9,9.4,12.04]],"id":45323444},{"bdatb":[[2,2.08,30.45],[3,2.06,40.58],[4,2.04,1.61],[5,2.02,43.79],[6,2,104.06],[7,1.99,3.1],[8,1.98,91.95],[9,1.97,10.62]],"id":9570503},{"bdatb":[[4,6,1.86],[5,5.9,3.66],[6,5.8,35.79],[7,5.7,223.85],[8,5.6,2.58],[9,5.5,4.5]],"id":12989514},{"bdatb":[[4,6,218.05],[5,5.9,11.37],[6,5.8,10.09],[7,5.7,97.06],[8,5.6,14.69],[9,5.5,14.74]],"bdatl":[[0,7.2,1.6],[1,7.4,12.28],[2,7.6,9.45],[3,8,2.42],[4,8.2,1.76],[5,8.4,3],[6,8.6,1.76],[7,8.8,1.76],[8,9,1.76],[9,9.2,8]],"id":44836671},{"bdatb":[[6,8.2,1.81],[7,8,2.88],[8,7.8,1.76],[9,7.6,2.79]],"id":43885158},{"bdatb":[[5,13,1.78],[6,12.5,1.78],[7,11.5,9.02],[8,10.5,11.75],[9,10,7.88]],"bdatl":[[0,19.5,1.76],[1,21,5.26],[2,23,2.4],[3,24,5.22],[4,25,1.76],[5,26,10],[6,27,1.76],[7,28,7.55],[8,29,1.76],[9,30,1.83]],"id":46969227}]}]}
{"op":"mcm","clk":"AOPTAQCWawDYvAE=","pt":1659347805761,"mc":[{"id":"1.201590187","rc":[{"atb":[[11,9.28]],"bdatb":[[4,11,9.31]],"id":45323444}]}]}
{"op":"mcm","clk":"APDTAQCZawDfvAE=","pt":1659347805874,"mc":[{"id":"1.201590187","rc":[{"atl":[[7.4,10.68]],"id":44836671}]}]}
{"op":"mcm","clk":"APDTAQCbawDjvAE=","pt":1659347805925,"mc":[{"id":"1.201590187","rc":[{"bdatb":[[9,1.97,4.61]],"id":9570503},{"bdatl":[[1,7.4,10.68]],"id":44836671}]}]}
{"op":"mcm","clk":"APXTAQCdawDlvAE=","pt":1659347805975,"mc":[{"id":"1.201590187","rc":[{"atb":[[13,6.29]],"bdatb":[[0,13,6.29]],"id":45323444},{"atb":[[15.5,0]],"bdatb":[[0,15,1.78],[1,14.5,1.76],[2,14,1.76],[3,13.5,1.76],[4,13,1.78],[5,12.5,1.78],[6,11.5,9.02],[7,10.5,11.75],[8,10,7.88],[9,9.4,3.26]],"id":46969227},{"bdatl":[[3,2.38,14.24],[4,2.4,43.68],[5,2.42,3.33],[6,2.44,32.25],[7,2.46,1.4],[8,2.48,7.8],[9,2.5,23.7]],"id":9570503}]}]}
{"op":"mcm","clk":"APfTAQCdawDpvAE=","pt":1659347806025,"mc":[{"id":"1.201590187","rc":[{"atb":[[25,2.63]],"bdatb":[[0,25,3.56]],"id":44621159},{"atl":[[9,35.31]],"bdatl":[[8,9,35.31]],"id":44836671},{"bdatl":[[5,2.42,11.56],[6,2.44,25.5],[7,2.46,7.86],[8,2.5,23.7],[9,2.52,6.7]],"id":9570503}]}]}
{"op":"mcm","clk":"AIPUAQChawDuvAE=","pt":1659347806130,"mc":[{"id":"1.201590187","rc":[{"atb":[[15.5,2]],"atl":[[20,2]],"id":46969227}]}]}
{"op":"mcm","clk":"AIPUAQCjawDvvAE=","pt":1659347806180,"mc":[{"id":"1.201590187","rc":[{"bdatb":[[8,9.6,21.99],[9,9.4,11.02]],"id":45323444},{"bdatb":[[6,2,105.39],[7,1.99,17.07],[8,1.98,76.57]],"bdatl":[[3,2.38,24.46],[4,2.4,36.33],[5,2.42,10.22],[6,2.44,24.9],[7,2.46,9.8],[8,2.5,24.21],[9,2.52,3.52]],"id":9570503},{"bdatb":[[9,5.5,5.75]],"id":12989514},{"bdatb":[[8,5.6,15.92],[9,5.5,13.48]],"id":44836671},{"bdatb":[[0,15.5,2],[1,15,1.78],[2,14.5,1.76],[3,14,1.76],[4,13.5,1.76],[5,13,1.78],[6,12.5,1.78],[7,11.5,9.02],[8,10.5,11.75],[9,10,7.88]],"bdatl":[[1,20,2],[2,21,5.26],[3,23,2.4],[4,24,5.22],[5,25,1.76],[6,26,10],[7,27,1.76],[8,28,7.55],[9,29,1.76]],"id":46969227}]}]}
{"op":"mcm","clk":"AIfUAQCmawDyvAE=","pt":1659347806231,"mc":[{"id":"1.201590187","rc":[{"atl":[[24,5],[19.5,0]],"id":46969227}]}]}
{"op":"mcm","clk":"AIfUAQCmawDzvAE=","pt":1659347806281,"mc":[{"id":"1.201590187","rc":[{"bdatb":[[4,11,9.28],[5,10.5,8.93],[7,9.8,9],[8,9.6,23.63],[9,9.4,11.44]],"id":45323444},{"bdatb":[[2,2.08,30.38],[3,2.06,40.66],[4,2.04,1.36],[5,2.02,44.04],[6,2,104.06],[7,1.99,3.1],[8,1.98,91.95]],"id":9570503},{"bdatb":[[4,6,1.83],[5,5.9,3.69],[6,5.8,35.31],[7,5.7,224.34],[8,5.6,1.76],[9,5.5,6.35]],"id":12989514},{"bdatb":[[4,6,218.03],[5,5.9,11.4],[8,5.6,15.69],[9,5.5,13.72]],"id":44836671},{"bdatb":[[7,8,1.48],[8,7.8,3.2]],"id":43885158},{"bdatl":[[0,20,2],[1,21,5.26],[2,23,2.4],[3,24,5],[4,25,1.76],[5,26,10],[6,27,1.76],[7,28,7.55],[8,29,1.76],[9,30,1.83]],"id":46969227}]}]}
{"op":"mcm","clk":"AI3UAQCpawD3vAE=","pt":1659347806331,"mc":[{"id":"1.201590187","rc":[{"atl":[[20,2.26]],"id":46969227}]}]}
{"op":"mcm","clk":"AJXUAQCrawD6vAE=","pt":1659347806381,"mc":[{"id":"1.201590187","rc":[{"bdatb":[[8,9.6,24.04],[9,9.4,11.02]],"id":45323444},{"bdatb":[[6,2,105.39],[7,1.99,2.39],[8,1.98,91.31]],"id":9570503},{"bdatb":[[9,5.5,6.58]],"id":12989514},{"bdatb":[[8,5.6,15.92],[9,5.5,13.48]],"id":44836671},{"bdatl":[[0,20,2.26]],"id":46969227}]}]}
{"op":"mcm","clk":"AKvUAQC0awCLvQE=","pt":1659347806771,"mc":[{"id":"1.201590187","rc":[{"atl":[[7.6,30.55]],"id":12989514},{"atl":[[21,5.25]],"id":46969227}]}]}
{"op":"mcm","clk":"AKzUAQC0awCOvQE=","pt":1659347806821,"mc":[{"id":"1.201590187","rc":[{"bdatl":[[1,7.6,31.17]],"id":12989514},{"bdatl":[[1,21,5.25]],"id":46969227}]}]}
{"op":"mcm","clk":"ALLUAQC1awCTvQE=","pt":1659347806871,"mc":[{"id":"1.201590187","rc":[{"atb":[[13,1.87]],"id":45323444},{"atb":[[25,0.33]],"id":44621159},{"atl":[[19.5,0.01]],"id":46969227}]}]}
{"op":"mcm","clk":"ALLUAQC1awCVvQE=","pt":1659347806921,"mc":[{"id":"1.201590187","rc":[{"bdatb":[[0,13,1.87],[4,11,9.3],[5,10.5,8.91]],"id":45323444},{"bdatb":[[2,2.08,30.45],[3,2.06,40.58],[7,1.99,2.49],[8,1.98,91.21]],"bdatl":[[4,2.4,33.55],[5,2.42,2.76],[6,2.44,28.27],[7,2.46,5.91],[8,2.5,24.62],[9,2.52,4.09]],"id":9570503},{"bdatb":[[4,6,1.84],[5,5.9,3.68]],"id":12989514},{"bdatb":[[0,25,1.26]],"id":44621159},{"bdatb":[[5,5.9,11.39]],"id":44836671},{"bdatl":[[0,20,2.27]],"id":46969227}]}]}
{"op":"mcm","clk":"ALnUAQC4awCYvQE=","pt":1659347806971,"mc":[{"id":"1.201590187","rc":[{"atb":[[12,1.76]],"id":46969227}]}]}
{"op":"mcm","clk":"ALvUAQC6awCdvQE=","pt":1659347807021,"mc":[{"id":"1.201590187","rc":[{"bdatb":[[7,12,2.7],[8,11.5,8.09],[9,10.5,11.75]],"id":46969227}]}]}
{"op":"mcm","clk":"AMLUAQC7awCevQE=","pt":1659347807071,"mc":[{"id":"1.201590187","rc":[{"atb":[[12.5,5.95]],"id":45323444},{"atl":[[20,2]],"id":46969227}]}]}
{"op":"mcm","clk":"AMLUAQC7awCivQE=","pt":1659347807122,"mc":[{"id":"1.201590187","rc":[{"bdatb":[[1,12.5,5.95],[8,9.6,23.65],[9,9.4,11.42]],"id":45323444},{"bdatb":[[6,2,104.06],[7,1.99,3.1],[8,1.98,91.95]],"bdatl":[[6,2.44,34.23],[7,2.48,7.8],[8,2.5,24.29],[9,2.52,6.09]],"id":9570503},{"bdatb":[[9,5.5,6.38]],"id":12989514},{"bdatb":[[8,5.6,15.72],[9,5.5,13.68]],"id":44836671},{"bdatl":[[0,20,2.01]],"id":46969227}]}]}
{"op":"mcm","clk":"AMzUAQC+awCnvQE=","pt":1659347807178,"mc":[{"id":"1.201590187","rc":[{"atl":[[7.6,5.45]],"id":44836671}]}]}
{"op":"mcm","clk":"AMzUAQC+awCovQE=","pt":1659347807228,"mc":[{"id":"1.201590187","rc":[{"bdatl":[[2,7.6,5.45]],"id":44836671}]}]}
{"op":"mcm","clk":"ANPUAQC/awCrvQE=","pt":1659347807279,"mc":[{"id":"1.201590187","rc":[{"atb":[[26,3.11]],"id":44621159}]}]}
{"op":"mcm","clk":"ANrUAQDDawCtvQE=","pt":1659347807330,"mc":[{"id":"1.201590187","rc":[{"bdatl":[[5,2.42,12.99],[6,2.44,24.9],[7,2.46,7.05],[8,2.48,3.32],[9,2.5,23.34]],"id":9570503},{"bdatb":[[0,26,3.11],[1,24,4.22]],"id":44621159}]}]}
{"op":"mcm","clk":"AN3UAQDEawCxvQE=","pt":1659347807380,"mc":[{"id":"1.201590187","rc":[{"atl":[[12.5,13.48]],"bdatl":[[4,12.5,13.48]],"id":43885158}]}]}
{"op":"mcm","clk":"AOXUAQDFawC3vQE=","pt":1659347807432,"mc":[{"id":"1.201590187","rc":[{"atl":[[19.5,5.01]],"id":46969227}]}]}
{"op":"mcm","clk":"AObUAQDHawC8vQE=","pt":1659347807482,"mc":[{"id":"1.201590187","rc":[{"bdatb":[[4,11,9.31],[5,10.5,8.9],[7,9.8,11.97],[8,9.6,21],[9,9.4,11.85]],"id":45323444},{"bdatb":[[4,2.04,1.61],[5,2.02,43.79],[6,2,105.39],[7,1.99,23.12],[8,1.98,72.55],[9,1.97,6.16]],"id":9570503},{"bdatb":[[4,6,1.86],[5,5.9,3.66],[6,5.8,35.79],[7,5.7,223.85],[8,5.6,2.58],[9,5.5,6.24]],"id":12989514},{"bdatb":[[4,6,218.05],[5,5.9,11.37],[8,5.6,16.39],[9,5.5,14.41]],"id":44836671},{"bdatb":[[7,8,2.88],[8,7.8,1.76]],"id":43885158},{"bdatl":[[0,19.5,5.01],[1,20,2],[2,21,5.25],[3,23,2.4],[4,24,5],[5,25,1.76],[6,26,10],[7,27,1.76],[8,28,7.55],[9,29,1.76]],"id":46969227}]}]}
{"op":"mcm","clk":"AOrUAQDIawC9vQE=","pt":1659347807532,"mc":[{"id":"1.201590187","rc":[{"atb":[[24,0.49],[23,6.31]],"id":44621159}]}]}
{"op":"mcm","clk":"AO3UAQDMawDCvQE=","pt":1659347807583,"mc":[{"id":"1.201590187","rc":[{"bdatb":[[1,23,7.13],[2,22,1.76],[3,21,5],[4,20,1.76],[5,19.5,3.98],[6,19,1.76],[7,18.5,2.7],[8,18,1.76],[9,15,2.88]],"id":44621159}]}]}
{"op":"mcm","clk":"APHUAQDPawDDvQE=","pt":1659347807645,"mc":[{"id":"1.201590187","rc":[{"atl":[[7.6,11.93],[7.4,14.51]],"id":44836671}]}]}
{"op":"mcm","clk":"APTUAQDTawDGvQE=","pt":1659347807695,"mc":[{"id":"1.201590187","rc":[{"bdatb":[[8,1.98,79.07],[9,1.97,6.62]],"id":9570503},{"bdatl":[[1,7.4,14.51],[2,7.6,11.93]],"id":44836671}]}]}
{"op":"mcm","clk":"AIDVAQDZawDLvQE=","pt":1659347807854,"mc":[{"id":"1.201590187","rc":[{"atl":[[48,0]],"id":44621159}]}]}
{"op":"mcm","clk":"AIHVAQDZawDOvQE=","pt":1659347807904,"mc":[{"id":"1.201590187","rc":[{"bdatl":[[2,80,2.32],[3,170,2],[4,900,1.14],[5,990,1.83],[6,1000,2],[7,0,0]],"id":44621159}]}]}
{"op":"mcm","clk":"AIbVAQDfawDQvQE=","pt":1659347807955,"mc":[{"id":"1.201590187","rc":[{"atb":[[12.5,1.35]],"id":45323444},{"atb":[[26,0.93]],"atl":[[50,0.91]],"id":44621159}]}]}
{"op":"mcm","clk":"AInVAQDfawDTvQE=","pt":1659347808005,"mc":[{"id":"1.201590187","rc":[{"bdatb":[[1,12.5,1.35]],"id":45323444},{"bdatl":[[5,2.42,2.76],[6,2.44,28.27],[7,2.46,1.24],[8,2.48,4.63],[9,2.5,21.79]],"id":9570503},{"bdatb":[[0,25,1.26],[1,23,6.8]],"bdatl":[[2,50,1.03],[3,80,2.2],[4,170,2],[5,900,1.14],[6,990,1.83],[7,1000,2]],"id":44621159}]}]}
{"op":"mcm","clk":"AJnVAQDqawDlvQE=","pt":1659347808273,"mc":[{"id":"1.201590187","rc":[{"atb":[[11.5,34.48]],"id":44621159}]}]}
{"op":"mcm","clk":"AKDVAQDtawDrvQE=","pt":1659347808370,"mc":[{"id":"1.201590187","rc":[{"atb":[[19.5,1.76]],"id":44621159},{"atl":[[26,6],[24,9.35]],"id":46969227}]}]}
{"op":"mcm","clk":"AKDVAQDtawDwvQE=","pt":1659347808420,"mc":[{"id":"1.201590187","rc":[{"bdatb":[[5,19.5,1.76]],"id":44621159},{"bdatl":[[4,24,9.35],[6,26,6]],"id":46969227}]}]}
{"op":"mcm","clk":"AKPVAQDuawDxvQE=","pt":1659347808470,"mc":[{"id":"1.201590187","rc":[{"atb":[[19,5.19]],"id":44621159}]}]}
{"op":"mcm","clk":"AKXVAQDuawD1vQE=","pt":1659347808520,"mc":[{"id":"1.201590187","rc":[{"bdatb":[[6,19,5.19]],"id":44621159}]}]}
{"op":"mcm","clk":"ALHVAQD0awD6vQE=","pt":1659347808664,"mc":[{"id":"1.201590187","rc":[{"atb":[[13,6.29]],"id":45323444},{"atb":[[24,2.49]],"atl":[[34,2.41]],"id":44621159},{"atl":[[22,2]],"id":46969227}]}]}
{"op":"mcm","clk":"ALPVAQD0awD8vQE=","pt":1659347808714,"mc":[{"id":"1.201590187","rc":[{"bdatb":[[0,13,6.29],[6,10,17.38],[7,9.8,9],[8,9.6,21.81],[9,9.4,11.02]],"id":45323444},{"bdatb":[[5,2.02,54.64],[6,2,113.59],[7,1.99,3.85],[8,1.98,83.14],[9,1.97,2.53]],"bdatl":[[4,2.4,36.33],[5,2.42,10.22],[6,2.44,24.09],[7,2.46,7.86],[8,2.48,2.72],[9,2.5,21.59]],"id":9570503},{"bdatb":[[6,5.8,35.87],[7,5.7,223.76],[8,5.6,6.49],[9,5.5,2.25]],"id":12989514},{"bdatb":[[1,24,2.49],[2,23,6.31],[3,22,1.76],[4,21,5],[5,20,1.76],[6,19.5,1.76],[7,19,5.19],[8,18.5,2.7],[9,18,1.76]],"bdatl":[[0,34,2.42],[1,36,2.48],[2,40,3.73],[3,50,1.03],[4,80,2.2],[5,170,2],[6,900,1.14],[7,990,1.83],[8,1000,2]],"id":44621159},{"bdatb":[[5,5.9,11.45],[6,5.8,10],[7,5.7,100.91],[8,5.6,12.47]],"id":44836671},{"bdatb":[[9,7.6,5.68]],"id":43885158},{"bdatb":[[9,11,2.41]],"bdatl":[[3,22,2],[4,23,2.16],[5,24,9.35],[6,25,1.76],[7,26,6],[8,27,1.76],[9,28,7.55]],"id":46969227}]}]}
{"op":"mcm","clk":"AL7VAQD4awCDvgE=","pt":1659347808834,"mc":[{"id":"1.201590187","rc":[{"atl":[[2.38,0]],"id":9570503},{"atb":[[24,4.91]],"id":44621159}]}]}
{"op":"mcm","clk":"AMHVAQD4awCJvgE=","pt":1659347808885,"mc":[{"id":"1.201590187","rc":[{"bdatl":[[3,2.38,10.22]],"id":9570503},{"bdatb":[[1,24,4.91]],"id":44621159}]}]}
{"op":"mcm","clk":"AOLVAQCIbACvvgE=","pt":1659347809553,"mc":[{"id":"1.201590187","rc":[{"atb":[[13,1.87]],"id":45323444},{"atb":[[24,2.49]],"id":44621159}]}]}
{"op":"mcm","clk":"AOLVAQCIbAC0vgE=","pt":1659347809603,"mc":[{"id":"1.201590187","rc":[{"bdatb":[[0,13,1.87]],"id":45323444},{"bdatl":[[4,2.4,33.55],[5,2.42,2.76],[6,2.44,28.27],[7,2.46,5.91],[8,2.5,24.62],[9,2.52,4.09]],"id":9570503},{"bdatb":[[1,24,2.49]],"id":44621159}]}]}
{"op":"mcm","clk":"AOfVAQCKbAC9vgE=","pt":1659347809676,"mc":[{"id":"1.201590187","rc":[{"atb":[[12.5,5.95]],"id":45323444}]}]}
{"op":"mcm","clk":"AOrVAQCLbAC/vgE=","pt":1659347809726,"mc":[{"id":"1.201590187","rc":[{"bdatb":[[1,12.5,5.95]],"id":45323444},{"bdatl":[[6,2.44,34.23],[7,2.48,7.8],[8,2.5,24.29],[9,2.52,6.09]],"id":9570503}]}]}
{"op":"mcm","clk":"AO/VAQCPbADFvgE=","pt":1659347809863,"mc":[{"id":"1.201590187","rc":[{"atb":[[25,2.63]],"id":44621159}]}]}
{"op":"mcm","clk":"APPVAQCQbADIvgE=","pt":1659347809913,"mc":[{"id":"1.201590187","rc":[{"bdatl":[[7,2.48,11.11],[8,2.5,23.62],[9,2.52,3.5]],"id":9570503},{"bdatb":[[0,25,3.56]],"id":44621159}]}]}
{"op":"mcm","clk":"APjVAQCVbADSvgE=","pt":1659347810086,"mc":[{"id":"1.201590187","rc":[{"atb":[[26,2.08]],"id":44621159},{"atl":[[10.5,2.56]],"id":43885158}]}]}
{"op":"mcm","clk":"APzVAQCbbADVvgE=","pt":1659347810136,"mc":[{"id":"1.201590187","rc":[{"bdatb":[[6,10,18.16],[8,9.6,21]],"id":45323444},{"bdatb":[[4,2.04,7.52],[5,2.02,48.67],[8,1.98,86.07],[9,1.97,3.34]],"bdatl":[[5,2.42,12.3],[6,2.44,24.77],[8,2.5,27.14],[9,2.52,3.71]],"id":9570503},{"bdatb":[[6,5.8,36.66],[7,5.7,225.08],[8,5.6,4.34],[9,5.5,3.66]],"id":12989514},{"bdatb":[[0,26,2.08],[1,25,2.63],[2,24,2.49],[3,23,6.31],[4,22,1.76],[5,21,5],[6,20,1.76],[7,19.5,1.76],[8,19,5.19],[9,18.5,2.7]],"id":44621159},{"bdatb":[[5,5.9,12.23],[6,5.8,11.29],[7,5.7,98.79],[8,5.6,13.86],[9,5.5,13]],"id":44836671},{"bdatl":[[0,10.5,2.56]],"id":43885158},{"bdatb":[[8,11.5,9.14],[9,11,1.31]],"id":46969227}]}]}
{"op":"mcm","clk":"AP7VAQCcbADWvgE=","pt":1659347810186,"mc":[{"id":"1.201590187","rc":[{"atl":[[16.5,0.18]],"id":45323444},{"atl":[[10.5,1.41]],"id":43885158},{"atl":[[23,1.01]],"id":46969227}]}]}
{"op":"mcm","clk":"AP/VAQChbADfvgE=","pt":1659347810236,"mc":[{"id":"1.201590187","rc":[{"bdatb":[[6,10,17.38],[8,9.6,21.81]],"bdatl":[[1,17,2.84],[2,17.5,1.76],[3,18,1.76],[4,18.5,1.76],[5,19,1.76],[6,19.5,1.76],[7,20,1.76],[8,21,1.76],[9,22,2.58]],"id":45323444},{"bdatb":[[4,2.04,1.61],[5,2.02,45.26],[6,2,115.67],[7,1.99,9.2],[8,1.98,78.59],[9,1.97,9.21]],"id":9570503},{"bdatb":[[6,5.8,35.87],[7,5.7,223.76],[8,5.6,3.11],[9,5.5,5.7]],"id":12989514},{"bdatb":[[5,5.9,11.45],[6,5.8,10],[7,5.7,97.58],[8,5.6,15.86],[9,5.5,14.41]],"id":44836671},{"bdatb":[[9,7.6,3.19]],"bdatl":[[0,10.5,1.41]],"id":43885158},{"bdatb":[[8,11.5,8.09],[9,10.5,11.74]],"bdatl":[[4,23,1.01]],"id":46969227}]}]}
{"op":"mcm","clk":"AIfWAQCkbADmvgE=","pt":1659347810342,"mc":[{"id":"1.201590187","rc":[{"atl":[[11.5,2.88]],"id":43885158}]}]}
{"op":"mcm","clk":"AIjWAQClbADvvgE=","pt":1659347810393,"mc":[{"id":"1.201590187","rc":[{"bdatb":[[7,1.99,6.55],[8,1.98,73.14],[9,1.97,10.35]],"id":9570503},{"bdatl":[[2,11.5,2.88]],"id":43885158}]}]}
{"op":"mcm","clk":"AIrWAQCnbADwvgE=","pt":1659347810443,"mc":[{"id":"1.201590187","rc":[{"atl":[[11,5.65]],"id":43885158}]}]}
{"op":"mcm","clk":"AI7WAQCobAD1vgE=","pt":1659347810493,"mc":[{"id":"1.201590187","rc":[{"bdatb":[[6,10,18.16],[8,9.6,21]],"id":45323444},{"bdatb":[[6,2,120.4],[7,1.99,4.45],[8,1.98,78.59],[9,1.97,8.44]],"id":9570503},{"bdatb":[[9,5.5,7.11]],"id":12989514},{"bdatb":[[8,5.6,17.25],[9,5.5,13]],"id":44836671},{"bdatl":[[1,11,5.65]],"id":43885158},{"bdatb":[[9,10.5,12.48]],"id":46969227}]}]}
{"op":"mcm","clk":"AI/WAQCqbAD4vgE=","pt":1659347810552,"mc":[{"id":"1.201590187","rc":[{"atb":[[12.5,1.35]],"id":45323444},{"atb":[[25,0.33]],"id":44621159}]}]}
{"op":"mcm","clk":"AJbWAQCtbAD+vgE=","pt":1659347810602,"mc":[{"id":"1.201590187","rc":[{"bdatb":[[1,12.5,1.35]],"id":45323444},{"bdatl":[[5,2.42,6.98],[6,2.44,29.37],[7,2.48,1.47],[8,2.5,23.82],[9,2.52,4.09]],"id":9570503},{"bdatb":[[1,24,2.82],[2,23,6.31],[3,22,1.76],[4,21,5],[5,20,1.76],[6,19.5,1.76],[7,19,5.19],[8,18.5,2.7],[9,18,1.76]],"id":44621159}]}]}
{"op":"mcm","clk":"AJrWAQCubACAvwE=","pt":1659347810665,"mc":[{"id":"1.201590187","rc":[{"atb":[[13,6.29]],"id":45323444}]}]}
{"op":"mcm","clk":"AJvWAQCybACFvwE=","pt":1659347810715,"mc":[{"id":"1.201590187","rc":[{"bdatb":[[0,13,6.29]],"id":45323444},{"bdatl":[[4,2.4,45.95],[5,2.44,25.58],[6,2.46,7.05],[7,2.48,2.72],[8,2.5,21.59],[9,2.52,6.12]],"id":9570503}]}]}
{"op":"mcm","clk":"AJ3WAQC1bACHvwE=","pt":1659347810768,"mc":[{"id":"1.201590187","rc":[{"atl":[[10.5,2.88]],"id":43885158}]}]}
{"op":"mcm","clk":"AKLWAQC1bACMvwE=","pt":1659347810818,"mc":[{"id":"1.201590187","rc":[{"bdatb":[[4,2.04,5.3],[5,2.02,45.44],[6,2,124.16],[7,1.99,1.76],[8,1.98,73.5],[9,1.97,12.96]],"id":9570503},{"bdatb":[[6,5.8,36.66],[7,5.7,224.29],[8,5.6,3.18],[9,5.5,5.67]],"id":12989514},{"bdatb":[[5,5.9,12.23],[6,5.8,11.88],[7,5.7,96.26],[8,5.6,15.84]],"id":44836671},{"bdatl":[[0,10.5,2.88]],"id":43885158},{"bdatb":[[8,11.5,8.75],[9,10.5,11.77]],"id":46969227}]}]}
{"op":"mcm","clk":"AKTWAQC1bACNvwE=","pt":1659347810868,"mc":[{"id":"1.201590187","rc":[{"atb":[[26,4.26]],"id":44621159}]}]}
{"op":"mcm","clk":"AKfWAQC4bACPvwE=","pt":1659347810918,"mc":[{"id":"1.201590187","rc":[{"bdatl":[[4,2.4,46.64],[5,2.44,32.01],[6,2.46,2.75],[7,2.5,27.76],[8,2.52,4.82],[9,2.54,3.22]],"id":9570503},{"bdatb":[[0,26,4.26]],"id":44621159}]}]}
{"op":"mcm","clk":"ALfWAQDIbACfvwE=","pt":1659347811143,"mc":[{"id":"1.201590187","rc":[{"atl":[[10.5,1.41]],"id":43885158}]}]}
{"op":"mcm","clk":"ALnWAQDJbACkvwE=","pt":1659347811193,"mc":[{"id":"1.201590187","rc":[{"bdatb":[[4,2.04,1.61],[5,2.02,45.26],[6,2,120.4],[7,1.99,4.45],[8,1.98,78.59],[9,1.97,8.44]],"id":9570503},{"bdatb":[[6,5.8,35.87],[7,5.7,223.76],[8,5.6,3.11],[9,5.5,7.11]],"id":12989514},{"bdatb":[[5,5.9,11.45],[6,5.8,10],[7,5.7,97.58],[8,5.6,17.25]],"id":44836671},{"bdatl":[[0,10.5,1.41]],"id":43885158},{"bdatb":[[8,11.5,8.09],[9,10.5,12.48]],"id":46969227}]}]}
{"op":"mcm","clk":"AMLWAQDMbACpvwE=","pt":1659347811351,"mc":[{"id":"1.201590187","rc":[{"atl":[[15,1.7]],"id":45323444},{"atl":[[10.5,3.84]],"id":43885158},{"atl":[[23,0.22],[19,1.82]],"id":46969227}]}]}
{"op":"mcm","clk":"AMPWAQDPbACwvwE=","pt":1659347811401,"mc":[{"id":"1.201590187","rc":[{"bdatb":[[4,11,10.32],[5,10.5,10.02],[6,10,15.86]],"bdatl":[[0,15,1.7],[1,16,1.21],[2,17,2.84],[3,17.5,1.76],[4,18,1.76],[5,18.5,1.76],[6,19,1.76],[7,19.5,1.76],[8,20,1.76],[9,21,1.76]],"id":45323444},{"bdatb":[[2,2.08,35.91],[3,2.06,41.93],[4,2.04,7.18],[5,2.02,45.25],[6,2,120.41],[7,1.99,1.76],[8,1.98,78.79],[9,1.97,5.04]],"id":9570503},{"bdatb":[[3,6.2,5.07],[4,6,6],[5,5.9,1.79],[6,5.8,37.84],[9,5.5,2.47]],"id":12989514},{"bdatb":[[8,18.5,3.32]],"id":44621159},{"bdatb":[[3,6.2,39.41],[4,6,222.22],[5,5.9,11.48],[8,5.6,12.7]],"id":44836671},{"bdatb":[[5,8.4,5.14],[6,8.2,1.79],[7,8,3.23],[8,7.8,2.9],[9,7.6,3.52]],"bdatl":[[0,10.5,3.84]],"id":43885158},{"bdatb":[[5,13,2.65],[6,12.5,1.76],[7,12,2.94],[8,11.5,9.08],[9,10.5,10.05]],"bdatl":[[0,19,1.82],[1,19.5,5.01],[2,20,2],[3,21,5.25],[4,22,2],[5,24,9.57]],"id":46969227}]}]}
{"op":"mcm","clk":"AMjWAQDSbAC1vwE=","pt":1659347811545,"mc":[{"id":"1.201590187","rc":[{"atb":[[13,1.87]],"atl":[[15,1.88]],"id":45323444},{"atb":[[26,2.08]],"id":44621159},{"atl":[[13.5,9.76]],"id":43885158},{"atl":[[23,0],[19,2.09]],"id":46969227}]}]}
{"op":"mcm","clk":"AM3WAQDXbAC7vwE=","pt":1659347811595,"mc":[{"id":"1.201590187","rc":[{"bdatb":[[0,13,1.87],[5,10.5,10.51],[6,10,15.35]],"bdatl":[[0,15,1.88]],"id":45323444},{"bdatb":[[3,2.06,43.24],[4,2.04,5.86],[5,2.02,46.59],[6,2,119.06],[9,1.97,6.41]],"bdatl":[[4,2.4,33.55],[5,2.42,6.98],[6,2.44,29.37],[7,2.48,1.47],[8,2.5,23.82],[9,2.52,4.09]],"id":9570503},{"bdatb":[[4,6,6.45],[6,5.8,37.37],[8,5.6,3.59],[9,5.5,1.98]],"id":12989514},{"bdatb":[[0,26,2.08]],"id":44621159},{"bdatb":[[4,6,222.67],[5,5.9,11.03],[7,5.7,98.05],[8,5.6,12.21]],"id":44836671},{"bdatb":[[7,8,3.56],[8,7.8,3.21],[9,7.6,3.2]],"bdatl":[[6,13.5,9.76]],"id":43885158},{"bdatb":[[7,12,3.17],[8,11.5,8.85],[9,10.5,10.04]],"bdatl":[[0,19,2.09],[5,24,9.35]],"id":46969227}]}]}
{"op":"mcm","clk":"ANfWAQDbbADLvwE=","pt":1659347811769,"mc":[{"id":"1.201590187","rc":[{"atb":[[12.5,5.95]],"id":45323444},{"atb":[[9.6,0]],"atl":[[9.6,0.22]],"trd":[[9.6,11.08]],"tv":206.47,"id":43885158}],"tv":2428.26}]}
{"op":"mcm","clk":"ANjWAQDdbADPvwE=","pt":1659347811819,"mc":[{"id":"1.201590187","rc":[{"bdatb":[[1,12.5,5.97],[2,12,2.11],[4,11,10.13]],"id":45323444},{"bdatb":[[1,2.1,18.57],[2,2.08,34.91],[4,2.04,6.89],[5,2.02,45.55],[6,2,120.1],[8,1.98,77.73]],"bdatl":[[3,2.4,43.68],[4,2.42,10.93],[5,2.44,26.13],[6,2.48,2.63],[7,2.5,29.42],[8,2.52,6.09],[9,2.54,3.68]],"id":9570503},{"bdatb":[[2,6.4,11.71],[3,6.2,5.02],[4,6,6.16],[6,5.8,37.73],[8,5.6,3.21]],"id":12989514},{"bdatb":[[3,22,1.86],[8,18.5,3.21]],"id":44621159},{"bdatb":[[2,6.4,2.09],[3,6.2,39.36],[4,6,222.38],[5,5.9,11.38],[7,5.7,97.69]],"id":44836671},{"bdatb":[[0,9.4,5.4],[1,9.2,6.29],[2,8.8,6.07],[3,8.6,20],[4,8.4,5.14],[5,8.2,1.79],[6,8,3.56],[7,7.8,3.21],[8,7.6,3.2],[9,7.4,2.48]],"bdatl":[[0,10.5,4.06]],"id":43885158},{"bdatb":[[1,15,1.8],[2,14.5,1.89],[5,13,2.49],[8,11.5,9.03],[9,10.5,9.85]],"id":46969227}]}]}
{"op":"mcm","clk":"ANvWAQDgbADRvwE=","pt":1659347811870,"mc":[{"id":"1.201590187","rc":[{"atb":[[27,2.13]],"bdatb":[[0,27,2.13],[1,26,2.08],[2,24,2.82],[3,23,6.31],[4,22,1.86],[5,21,5],[6,20,1.76],[7,19.5,1.76],[8,19,5.19],[9,18.5,3.21]],"id":44621159},{"bdatl":[[3,2.38,10.22],[4,2.4,36.33],[5,2.42,10.22],[6,2.44,24.09],[7,2.48,11.11],[8,2.5,27.14],[9,2.52,3.97]],"id":9570503}]}]}
{"op":"mcm","clk":"AIvXAQD8bACAwAE=","pt":1659347812658,"mc":[{"id":"1.201590187","rc":[{"atb":[[12.5,1.35]],"id":45323444},{"atb":[[2.14,0.39]],"trd":[[2.14,218.3]],"tv":1357.94,"id":9570503},{"atb":[[9,1.76]],"id":43885158}],"tv":2438.26}]}
{"op":"mcm","clk":"AIvXAQD9bACFwAE=","pt":1659347812708,"mc":[{"id":"1.201590187","rc":[{"bdatb":[[1,12.5,1.38]],"id":45323444},{"bdatb":[[0,2.12,1.38],[1,2.1,17.58]],"bdatl":[[5,2.42,4.21],[6,2.44,30.05],[7,2.5,24.62],[8,2.52,7.36],[9,2.54,1.64]],"id":9570503},{"bdatb":[[2,9,1.76],[3,8.8,6.07],[4,8.6,20],[5,8.4,5.14],[6,8.2,1.79],[7,8,3.56],[8,7.8,3.21],[9,7.6,3.2]],"id":43885158}]}]}
{"op":"mcm","clk":"AJDXAQD/bACJwAE=","pt":1659347812773,"mc":[{"id":"1.201590187","rc":[{"atb":[[8.8,45.6]],"atl":[[15.5,0]],"id":45323444},{"atb":[[2.12,2.25],[1.74,52.91]],"id":9570503},{"atb":[[3.9,10]],"id":12989514},{"atb":[[11.5,20.11]],"id":44621159},{"atb":[[5.7,79.02]],"id":44836671},{"atb":[[6.6,61.48]],"id":43885158},{"atb":[[8.8,40.22]],"atl":[[19.5,5]],"id":46969227}]}]}
{"op":"mcm","clk":"AJHXAQD/bACMwAE=","pt":1659347812823,"mc":[{"id":"1.201590187","rc":[{"bdatl":[[1,16,1.2]],"id":45323444},{"bdatb":[[0,2.12,3.62],[3,2.06,43.16],[4,2.04,6.96],[5,2.02,45.47],[6,2,120.18],[9,1.97,6.33]],"id":9570503},{"bdatb":[[5,5.9,1.76],[6,5.8,37.76],[8,5.6,3.19],[9,5.5,2.01]],"id":12989514},{"bdatb":[[4,6,222.35],[5,5.9,11.41],[7,5.7,80.42],[8,5.6,12.24]],"id":44836671},{"bdatb":[[7,8,3.54],[8,7.8,3.23],[9,7.6,3.18]],"id":43885158},{"bdatb":[[7,12,3.15],[8,11.5,9.05]],"bdatl":[[1,19.5,5]],"id":46969227}]}]}
{"op":"mcm","clk":"AJfXAQCEbQCNwAE=","pt":1659347812875,"mc":[{"id":"1.201590187","rc":[{"atl":[[14.5,0.01]],"id":45323444},{"atl":[[55,0.63],[50,0]],"id":44621159},{"atl":[[9.6,0]],"trd":[[9.6,11.52]],"tv":206.91,"id":43885158},{"atl":[[18.5,0.01]],"id":46969227}],"tv":2438.7}]}
{"op":"mcm","clk":"AJrXAQCEbQCUwAE=","pt":1659347812926,"mc":[{"id":"1.201590187","rc":[{"bdatb":[[1,12.5,1.35],[2,12,1.96],[4,11,10.32],[5,10.5,10.53],[6,10,15.33]],"bdatl":[[0,15,1.89]],"id":45323444},{"bdatb":[[0,2.12,2.64],[1,2.1,17.67],[2,2.08,35.82],[3,2.06,43.23],[4,2.04,5.87],[5,2.02,46.58],[6,2,119.06],[8,1.98,78.79],[9,1.97,6.41]],"id":9570503},{"bdatb":[[2,6.4,11.38],[3,6.2,5.07],[4,6,6.48],[6,5.8,37.37],[8,5.6,3.59],[9,5.5,1.98]],"id":12989514},{"bdatb":[[4,22,1.76],[6,20,1.77],[8,19,5.2],[9,18.5,3.31]],"bdatl":[[3,80,2.95],[4,170,2],[5,900,1.14],[6,990,1.83],[7,1000,2],[8,0,0]],"id":44621159},{"bdatb":[[2,6.4,1.76],[3,6.2,39.41],[4,6,222.67],[5,5.9,11.03],[7,5.7,80.81],[8,5.6,12.22]],"id":44836671},{"bdatb":[[3,8.8,6.09],[5,8.4,5.11],[7,8,3.56],[9,7.6,3.17]],"bdatl":[[0,10.5,3.84]],"id":43885158},{"bdatb":[[1,15,1.78],[2,14.5,1.76],[4,13.5,1.77],[5,13,2.64],[7,12,3.17],[8,11.5,8.85],[9,10.5,10.04]],"bdatl":[[0,19,2.1]],"id":46969227}]}]}
{"op":"mcm","clk":"AKLXAQCHbQCbwAE=","pt":1659347813072,"mc":[{"id":"1.201590187","rc":[{"atl":[[22,1.76]],"id":46969227}]}]}
{"op":"mcm","clk":"AKbXAQCLbQCfwAE=","pt":1659347813122,"mc":[{"id":"1.201590187","rc":[{"bdatl":[[4,22,1.76]],"id":46969227}]}]}
{"op":"mcm","clk":"AKjXAQCNbQCgwAE=","pt":1659347813173,"mc":[{"id":"1.201590187","rc":[{"atl":[[40,5]],"id":46969227}]}]}
{"op":"mcm","clk":"AK3XAQCRbQCkwAE=","pt":1659347813241,"mc":[{"id":"1.201590187","rc":[{"atb":[[8.8,57.1]],"id":45323444}]}]}
{"op":"mcm","clk":"ALHXAQCRbQCpwAE=","pt":1659347813331,"mc":[{"id":"1.201590187","rc":[{"atb":[[1.77,68.02]],"id":9570503},{"atb":[[11.5,31.6]],"id":44621159},{"atl":[[7.4,16.02]],"id":44836671},{"atl":[[42,0]],"id":46969227}]}]}
{"op":"mcm","clk":"ALfXAQCXbQCqwAE=","pt":1659347813381,"mc":[{"id":"1.201590187","rc":[{"bdatb":[[8,1.98,83.53],[9,1.97,2.53]],"id":9570503},{"bdatl":[[1,7.4,16.02]],"id":44836671}]}]}
{"op":"mcm","clk":"AL7XAQCZbQCywAE=","pt":1659347813454,"mc":[{"id":"1.201590187","rc":[{"atb":[[2.12,0]],"id":9570503}]}]}
{"op":"mcm","clk":"AMLXAQCcbQC2wAE=","pt":1659347813504,"mc":[{"id":"1.201590187","rc":[{"bdatb":[[0,2.1,18.06],[1,2.08,35.82],[2,2.06,43.23],[3,2.04,5.87],[4,2.02,46.58],[5,2,119.06],[6,1.99,1.76],[7,1.98,83.53],[8,1.97,2.53],[9,1.96,3.63]],"id":9570503}]}]}
{"op":"mcm","clk":"ANfXAQCkbQC+wAE=","pt":1659347813765,"mc":[{"id":"1.201590187","rc":[{"atb":[[2.08,36.15],[2.1,7.03]],"atl":[[2.4,0],[2.24,8.89]],"id":9570503}]}]}
{"op":"mcm","clk":"ANnXAQCpbQDEwAE=","pt":1659347813815,"mc":[{"id":"1.201590187","rc":[{"bdatb":[[0,2.1,7.51],[1,2.08,41.6]],"bdatl":[[1,2.24,8.89],[4,2.4,2.79]],"id":9570503}]}]}
{"op":"mcm","clk":"ANzXAQCqbQDGwAE=","pt":1659347813865,"mc":[{"id":"1.201590187","rc":[{"atl":[[2.42,33.55]],"id":9570503}]}]}
{"op":"mcm","clk":"AN7XAQCubQDKwAE=","pt":1659347813915,"mc":[{"id":"1.201590187","rc":[{"bdatl":[[5,2.42,37.76]],"id":9570503}]}]}
{"op":"mcm","clk":"APvXAQC9bQDnwAE=","pt":1659347814546,"mc":[{"id":"1.201590187","rc":[{"atl":[[2.2,13.51]],"id":9570503}]}]}
{"op":"mcm","clk":"APzXAQC9bQDtwAE=","pt":1659347814596,"mc":[{"id":"1.201590187","rc":[{"bdatb":[[5,10.5,9.57],[6,10,14.14],[8,9.6,22.1]],"id":45323444},{"bdatl":[[0,2.2,13.51]],"id":9570503},{"bdatb":[[6,5.8,35.55],[8,5.6,1.76],[9,5.5,3.69]],"id":12989514},{"bdatb":[[5,5.9,9.23],[7,5.7,80.79],[8,5.6,12.09],[9,5.5,14.32]],"id":44836671},{"bdatb":[[8,7.8,1.94],[9,7.6,1.76]],"id":43885158},{"bdatb":[[8,11.5,7.93],[9,10.5,10.01]],"id":46969227}]}]}
{"op":"mcm","clk":"AP/XAQC/bQDvwAE=","pt":1659347814647,"mc":[{"id":"1.201590187","rc":[{"atl":[[17,1.51]],"id":45323444},{"atl":[[34,2]],"id":44621159}]}]}
{"op":"mcm","clk":"AIDYAQC/bQDxwAE=","pt":1659347814697,"mc":[{"id":"1.201590187","rc":[{"bdatl":[[2,17,1.69]],"id":45323444},{"bdatl":[[0,34,2.01]],"id":44621159}]}]}
{"op":"mcm","clk":"AIXYAQDBbQDzwAE=","pt":1659347814748,"mc":[{"id":"1.201590187","rc":[{"atl":[[17,0.18]],"id":45323444},{"atl":[[36,1.15]],"id":44621159}]}]}
{"op":"mcm","clk":"AIbYAQDBbQD4wAE=","pt":1659347814798,"mc":[{"id":"1.201590187","rc":[{"bdatl":[[2,17.5,2.12],[3,18,1.76],[4,18.5,1.76],[5,19,1.76],[6,19.5,1.76],[7,20,1.76],[8,21,1.76],[9,22,2.58]],"id":45323444},{"bdatb":[[5,2,110.06],[6,1.99,10.81],[7,1.98,74.13],[8,1.97,11.36],[9,1.96,3.35]],"id":9570503},{"bdatl":[[1,36,1.15]],"id":44621159}]}]}
{"op":"mcm","clk":"AJrYAQDRbQCUwQE=","pt":1659347815283,"mc":[{"id":"1.201590187","rc":[{"atl":[[2.24,3.79]],"id":9570503}]}]}
{"op":"mcm","clk":"AKDYAQDXbQCawQE=","pt":1659347815334,"mc":[{"id":"1.201590187","rc":[{"bdatb":[[8,9.6,21.88],[9,9.4,11.19]],"id":45323444},{"bdatl":[[1,2.24,3.79]],"id":9570503},{"bdatb":[[9,5.5,3.31]],"id":12989514},{"bdatb":[[7,5.7,80.51],[8,5.6,12],[9,5.5,13.38]],"id":44836671},{"bdatb":[[9,10.5,9.81]],"id":46969227}]}]}
{"op":"mcm","clk":"AKHYAQDYbQCbwQE=","pt":1659347815385,"mc":[{"id":"1.201590187","rc":[{"atl":[[2.22,5.44]],"id":9570503},{"atb":[[12,4.64]],"id":46969227}]}]}
{"op":"mcm","clk":"AKbYAQDabQCkwQE=","pt":1659347815436,"mc":[{"id":"1.201590187","rc":[{"bdatb":[[6,10,15.2],[8,9.6,21.15],[9,9.4,11.02]],"id":45323444},{"bdatl":[[1,2.22,5.44],[2,2.24,3.79],[3,2.26,7],[4,2.38,10.22],[5,2.4,2.79],[6,2.42,37.76],[7,2.44,30.05],[8,2.5,24.62],[9,2.52,7.36]],"id":9570503},{"bdatb":[[7,5.7,225.53],[8,5.6,1.85],[9,5.5,2.03]],"id":12989514},{"bdatb":[[6,5.8,11.83],[7,5.7,79.02],[8,5.6,12.27],[9,5.5,14.04]],"id":44836671},{"bdatb":[[9,7.6,3.09]],"id":43885158},{"bdatb":[[7,12,6.04],[9,10.5,10.1]],"id":46969227}]}]}
{"op":"mcm","clk":"AKjYAQDdbQClwQE=","pt":1659347815486,"mc":[{"id":"1.201590187","rc":[{"atb":[[2.1,3.83],[2.14,0]],"trd":[[2.14,219.09],[2.1,189.17]],"ltp":2.1,"tv":1365.13,"id":9570503}],"tv":2445.89}]}
{"op":"mcm","clk":"AKrYAQDebQCowQE=","pt":1659347815536,"mc":[{"id":"1.201590187","rc":[{"bdatb":[[0,2.1,3.92]],"id":9570503}]}]}
{"op":"mcm","clk":"ALvYAQDrbQDBwQE=","pt":1659347815856,"mc":[{"id":"1.201590187","rc":[{"atb":[[2.08,15.54]],"atl":[[2.24,0]],"id":9570503},{"atb":[[6.6,18.96]],"atl":[[7.6,28.14]],"id":12989514},{"atb":[[6.8,20.95]],"atl":[[7.6,9.71]],"id":44836671},{"atb":[[9.2,4.06]],"id":43885158}]}]}
{"op":"mcm","clk":"AL3YAQDrbQDKwQE=","pt":1659347815908,"mc":[{"id":"1.201590187","rc":[{"bdatb":[[1,2.08,20.99]],"bdatl":[[2,2.26,7],[3,2.38,10.22],[4,2.4,2.79],[5,2.42,37.76],[6,2.44,30.05],[7,2.5,24.62],[8,2.52,7.36],[9,2.54,1.64]],"id":9570503},{"bdatb":[[1,6.6,18.96]],"bdatl":[[1,7.6,28.76]],"id":12989514},{"bdatb":[[0,6.8,20.95],[9,5.5,13]],"bdatl":[[2,7.6,9.71]],"id":44836671},{"bdatb":[[1,9.2,4.06]],"id":43885158}]}]}
{"op":"mcm","clk":"AMHYAQDtbQDLwQE=","pt":1659347815961,"mc":[{"id":"1.201590187","rc":[{"atl":[[2.26,8.85]],"id":9570503}]}]}
{"op":"mcm","clk":"AMHYAQDwbQDRwQE=","pt":1659347816011,"mc":[{"id":"1.201590187","rc":[{"bdatl":[[2,2.26,8.85]],"id":9570503}]}]}
{"op":"mcm","clk":"ANHYAQD4bQDdwQE=","pt":1659347816270,"mc":[{"id":"1.201590187","rc":[{"atb":[[2.12,1.76]],"id":9570503}]}]}
{"op":"mcm","clk":"ANLYAQD6bQDjwQE=","pt":1659347816320,"mc":[{"id":"1.201590187","rc":[{"bdatb":[[0,2.12,1.76],[1,2.1,3.92],[2,2.08,20.99],[3,2.06,43.23],[4,2.04,5.87],[5,2.02,46.58],[6,2,110.06],[7,1.99,10.81],[8,1.98,74.13],[9,1.97,11.36]],"id":9570503}]}]}
{"op":"mcm","clk":"ANnYAQD/bQDqwQE=","pt":1659347816476,"mc":[{"id":"1.201590187","rc":[{"atb":[[2.1,5.71]],"id":9570503}]}]}
{"op":"mcm","clk":"AN/YAQCDbgDwwQE=","pt":1659347816526,"mc":[{"id":"1.201590187","rc":[{"bdatb":[[1,2.1,5.8]],"id":9570503}]}]}
{"op":"mcm","clk":"AOPYAQCDbgD0wQE=","pt":1659347816576,"mc":[{"id":"1.201590187","rc":[{"atl":[[10,1.15]],"id":43885158},{"atl":[[19,3.24]],"id":46969227}]}]}
{"op":"mcm","clk":"AOTYAQCGbgD2wQE=","pt":1659347816626,"mc":[{"id":"1.201590187","rc":[{"bdatb":[[2,12,1.98],[3,11.5,2.96],[4,11,9.28],[6,10,15.34],[8,9.6,21],[9,9.4,12.09]],"id":45323444},{"bdatb":[[0,2.12,1.92],[1,2.1,11.03],[2,2.08,15.56],[4,2.04,11.5],[5,2.02,42.41],[6,2,108.53],[7,1.99,16.59],[8,1.98,70.48],[9,1.97,9.2]],"id":9570503},{"bdatb":[[2,6.4,11.43],[3,6.2,6.82],[4,6,4.61],[7,5.7,225.88],[8,5.6,1.76],[9,5.5,1.76]],"id":12989514},{"bdatb":[[4,22,1.77],[6,20,2.33],[8,19,5.19],[9,18.5,2.7]],"id":44621159},{"bdatb":[[2,6.4,1.81],[3,6.2,41.16],[4,6,220.81],[6,5.8,12.08],[8,5.6,12],[9,5.5,14.58]],"id":44836671},{"bdatb":[[9,7.6,3.35]],"bdatl":[[0,10,1.15],[1,10.5,3.84],[2,11,5.65],[3,11.5,2.88],[4,12,10.85],[5,12.5,13.48],[6,13,1.76],[7,13.5,9.76],[8,14,13.2],[9,14.5,13.87]],"id":43885158},{"bdatb":[[2,14.5,1.77],[3,14,1.78],[4,13.5,2.59],[5,13,1.77],[9,11,1.1]],"bdatl":[[0,19,3.25]],"id":46969227}]}]}
{"op":"mcm","clk":"AOvYAQCKbgD9wQE=","pt":1659347816737,"mc":[{"id":"1.201590187","rc":[{"atb":[[26,0.93]],"id":44621159},{"atl":[[10.5,2.43]],"id":43885158}]}]}
{"op":"mcm","clk":"AOzYAQCNbgCAwgE=","pt":1659347816787,"mc":[{"id":"1.201590187","rc":[{"bdatb":[[6,10,14.87],[8,9.6,21.5],[9,9.4,11.02]],"id":45323444},{"bdatb":[[4,2.04,4.25],[5,2.02,49.73],[7,1.99,9.15],[8,1.98,75.8],[9,1.97,11.36]],"bdatl":[[8,2.52,6.68],[9,2.54,2.31]],"id":9570503},{"bdatb":[[7,5.7,225.04],[9,5.5,2.64]],"id":12989514},{"bdatb":[[1,25,1.26],[2,24,2.49]],"id":44621159},{"bdatb":[[6,5.8,11.26],[7,5.7,79.86],[9,5.5,13]],"id":44836671},{"bdatl":[[1,10.5,2.43]],"id":43885158},{"bdatb":[[9,10.5,10.12]],"id":46969227}]}]}
{"op":"mcm","clk":"AP3YAQCRbgCIwgE=","pt":1659347816962,"mc":[{"id":"1.201590187","rc":[{"atb":[[6.6,16.33],[6.4,14.11]],"id":12989514}]}]}
{"op":"mcm","clk":"AP3YAQCWbgCNwgE=","pt":1659347817012,"mc":[{"id":"1.201590187","rc":[{"bdatb":[[1,6.6,16.33],[2,6.4,14.16]],"id":12989514}]}]}
{"op":"mcm","clk":"AI7ZAQChbgCYwgE=","pt":1659347817271,"mc":[{"id":"1.201590187","rc":[{"atb":[[2.06,1.52]],"id":9570503}]}]}
{"op":"mcm","clk":"AJLZAQCibgCewgE=","pt":1659347817321,"mc":[{"id":"1.201590187","rc":[{"bdatb":[[3,2.06,9.69]],"id":9570503}]}]}
{"op":"mcm","clk":"AKnZAQCsbgCxwgE=","pt":1659347817777,"mc":[{"id":"1.201590187","rc":[{"atb":[[11.5,5.14]],"id":45323444},{"atb":[[14,8.65],[13.5,6]],"id":46969227}]}]}
{"op":"mcm","clk":"AKnZAQCtbgCzwgE=","pt":1659347817827,"mc":[{"id":"1.201590187","rc":[{"bdatb":[[3,11.5,6.12]],"id":45323444},{"bdatl":[[9,2.54,2.57]],"id":9570503},{"bdatb":[[3,14,8.66],[4,13.5,6.83]],"id":46969227}]}]}
{"op":"mcm","clk":"AKvZAQCubgC0wgE=","pt":1659347817877,"mc":[{"id":"1.201590187","rc":[{"atb":[[19,1.76]],"bdatb":[[8,19,1.76]],"id":44621159}]}]}
{"op":"mcm","clk":"ALXZAQCwbgC4wgE=","pt":1659347817947,"mc":[{"id":"1.201590187","rc":[{"atb":[[20,5.19]],"id":44621159}]}]}
{"op":"mcm","clk":"ALfZAQCzbgC9wgE=","pt":1659347817997,"mc":[{"id":"1.201590187","rc":[{"bdatb":[[6,20,5.76]],"id":44621159}]}]}
{"op":"mcm","clk":"AL3ZAQCzbgC/wgE=","pt":1659347818056,"mc":[{"id":"1.201590187","rc":[{"atb":[[28,5]],"id":44621159}]}]}
{"op":"mcm","clk":"AL/ZAQC3bgDEwgE=","pt":1659347818106,"mc":[{"id":"1.201590187","rc":[{"bdatl":[[4,2.4,7.03],[5,2.42,37.5],[6,2.44,26.13],[7,2.48,3.64],[8,2.5,28.41],[9,2.52,1.92]],"id":9570503},{"bdatb":[[0,28,5],[1,27,2.13],[2,25,1.26],[3,24,2.49],[4,23,6.31],[5,22,1.77],[6,21,5],[7,20,5.76],[8,19.5,1.76],[9,19,1.76]],"id":44621159}]}]}
{"op":"mcm","clk":"AMPZAQC4bgDFwgE=","pt":1659347818161,"mc":[{"id":"1.201590187","rc":[{"atb":[[2.08,15.18]],"atl":[[2.26,5.2],[2.22,9.21]],"id":9570503},{"atb":[[6.6,16.25]],"atl":[[7.6,25.94],[7.4,3.02]],"id":12989514},{"atb":[[6.6,25.28],[6.8,18.54]],"atl":[[7.6,9.52]],"id":44836671},{"atb":[[9.2,3.9]],"id":43885158}]}]}
{"op":"mcm","clk":"AMfZAQC+bgDIwgE=","pt":1659347818211,"mc":[{"id":"1.201590187","rc":[{"bdatb":[[8,9.6,22.37]],"id":45323444},{"bdatb":[[2,2.08,15.19]],"bdatl":[[1,2.22,9.21],[2,2.26,5.2],[9,2.52,1.34]],"id":9570503},{"bdatb":[[1,6.6,16.25],[9,5.5,4.16]],"bdatl":[[1,7.4,3.02],[2,7.6,25.94],[3,7.8,25.38],[4,8,1.76],[5,8.2,1.76],[6,8.4,4],[7,8.6,1.76],[8,8.8,1.76],[9,9,2.17]],"id":12989514},{"bdatb":[[0,6.8,18.54],[1,6.6,25.28],[7,5.7,80.87],[8,5.6,12.47]],"bdatl":[[2,7.6,9.52]],"id":44836671},{"bdatb":[[1,9.2,3.9],[9,7.6,4.11]],"id":43885158},{"bdatb":[[9,10.5,10.91]],"id":46969227}]}]}
{"op":"mcm","clk":"ANHZAQDDbgDNwgE=","pt":1659347818376,"mc":[{"id":"1.201590187","rc":[{"atb":[[4.2,51.72]],"id":12989514},{"atb":[[5.7,96.26]],"id":44836671}]}]}
{"op":"mcm","clk":"ANHZAQDDbgDPwgE=","pt":1659347818426,"mc":[{"id":"1.201590187","rc":[{"bdatb":[[7,5.7,98.11]],"id":44836671}]}]}
{"op":"mcm","clk":"ANbZAQDEbgDPwgE=","pt":1659347818478,"mc":[{"id":"1.201590187","rc":[{"atb":[[6.6,78.72]],"id":43885158}]}]}
{"op":"mcm","clk":"AOjZAQDKbgDcwgE=","pt":1659347818776,"mc":[{"id":"1.201590187","rc":[{"atl":[[7.8,4.74]],"id":12989514}]}]}
{"op":"mcm","clk":"APDZAQDMbgDhwgE=","pt":1659347818826,"mc":[{"id":"1.201590187","rc":[{"bdatl":[[3,7.8,4.74]],"id":12989514}]}]}
{"op":"mcm","clk":"APTZAQDMbgDiwgE=","pt":1659347818881,"mc":[{"id":"1.201590187","rc":[{"atb":[[1.95,35.31]],"id":9570503},{"atl":[[11,2.65]],"id":43885158},{"atb":[[8.8,45.97]],"id":46969227}]}]}
{"op":"mcm","clk":"APbZAQDPbgDlwgE=","pt":1659347818931,"mc":[{"id":"1.201590187","rc":[{"bdatb":[[6,2,99.38],[7,1.99,2.85],[8,1.98,86.09],[9,1.97,2.53]],"id":9570503},{"bdatl":[[2,11,2.65]],"id":43885158}]}]}
{"op":"mcm","clk":"APvZAQDRbgDnwgE=","pt":1659347818982,"mc":[{"id":"1.201590187","rc":[{"atb":[[25,2.09]],"bdatb":[[2,25,3.02]],"id":44621159},{"atl":[[10.5,5.43]],"bdatl":[[1,10.5,5.43]],"id":43885158},{"bdatb":[[6,10,16.18],[8,9.6,21],[9,9.4,12.24]],"id":45323444},{"bdatb":[[4,2.04,12.37],[5,2.02,48.92],[6,2,101.06],[7,1.99,8.4],[8,1.98,76.56],[9,1.97,11.36]],"id":9570503},{"bdatb":[[7,5.7,226.89],[8,5.6,2.23],[9,5.5,1.76]],"id":12989514},{"bdatb":[[6,5.8,13.07],[7,5.7,96.72],[8,5.6,12],[9,5.5,13.06]],"id":44836671},{"bdatb":[[9,11,1.86]],"id":46969227}]}]}
{"op":"mcm","clk":"AIPaAQDSbgDvwgE=","pt":1659347819050,"mc":[{"id":"1.201590187","rc":[{"atb":[[27,0]],"id":44621159}]}]}
{"op":"mcm","clk":"AIbaAQDVbgDxwgE=","pt":1659347819101,"mc":[{"id":"1.201590187","rc":[{"bdatb":[[1,25,3.02],[2,24,2.49],[3,23,6.31],[4,22,1.77],[5,21,5],[6,20,5.76],[7,19.5,1.76],[8,19,1.76],[9,18.5,2.7]],"id":44621159}]}]}
{"op":"mcm","clk":"AJXaAQDabgCCwwE=","pt":1659347819370,"mc":[{"id":"1.201590187","rc":[{"atb":[[2.04,16.9]],"id":9570503},{"atb":[[6.6,19.28]],"id":44836671},{"atb":[[9.4,0]],"atl":[[11,0.25]],"id":43885158}]}]}
{"op":"mcm","clk":"AJjaAQDabgCEwwE=","pt":1659347819420,"mc":[{"id":"1.201590187","rc":[{"bdatb":[[4,2.04,29.27],[6,2,94.46],[7,1.99,1.76],[8,1.98,87.18],[9,1.97,2.53]],"bdatl":[[3,2.4,12.92],[4,2.42,35.57],[5,2.44,26.26],[6,2.46,5.91],[7,2.5,21.79],[8,2.52,2.8],[9,2.54,7.3]],"id":9570503},{"bdatb":[[1,6.6,19.28]],"id":44836671},{"bdatb":[[0,9.2,3.9],[1,9,1.76],[2,8.8,6.09],[3,8.6,20],[4,8.4,5.11],[5,8.2,1.79],[6,8,3.56],[7,7.8,1.94],[8,7.6,4.11],[9,7.4,2.68]],"bdatl":[[2,11.5,3.13],[3,12,10.85],[4,12.5,13.48],[5,13,1.76],[6,13.5,9.76],[7,14,13.2],[8,14.5,13.87],[9,15,12]],"id":43885158}]}]}
{"op":"mcm","clk":"AJzaAQDbbgCFwwE=","pt":1659347819475,"mc":[{"id":"1.201590187","rc":[{"atb":[[6.8,24.74]],"id":44836671}]}]}
{"op":"mcm","clk":"AJ7aAQDdbgCKwwE=","pt":1659347819525,"mc":[{"id":"1.201590187","rc":[{"bdatb":[[0,6.8,24.74]],"id":44836671}]}]}
{"op":"mcm","clk":"ALPaAQDkbgCfwwE=","pt":1659347819877,"mc":[{"id":"1.201590187","rc":[{"atl":[[23,1.76]],"id":45323444},{"atb":[[2.2,86.49]],"atl":[[2.2,0]],"trd":[[2.2,27.02]],"ltp":2.2,"tv":1392.15,"id":9570503}],"tv":2472.91}]}
{"op":"mcm","clk":"ALraAQDmbgCjwwE=","pt":1659347819927,"mc":[{"id":"1.201590187","rc":[{"bdatb":[[2,12,1.96],[3,11.5,5.15],[4,11,10.31],[5,10.5,7.84],[6,10,15.03],[9,9.4,12.27]],"id":45323444},{"bdatb":[[0,2.2,86.49],[1,2.12,1.92],[2,2.1,11.03],[3,2.08,15.19],[4,2.06,9.69],[5,2.04,29.27],[6,2.02,48.92],[7,2,94.46],[8,1.99,1.76],[9,1.98,87.18]],"bdatl":[[0,2.22,9.21],[1,2.26,5.2],[2,2.4,12.92],[3,2.42,35.57],[4,2.44,26.26],[5,2.46,5.91],[6,2.5,21.79],[7,2.52,2.8],[8,2.54,7.3],[9,2.56,15.83]],"id":9570503},{"bdatb":[[2,6.4,14.11],[3,6.2,5.07],[4,6,3.67],[5,5.9,1.77],[6,5.8,36.85],[7,5.7,223.76],[8,5.6,3.17]],"bdatl":[[9,9,4.87]],"id":12989514},{"bdatb":[[4,22,1.76],[6,20,5.2],[7,19.5,1.77],[8,19,2.36]],"bdatl":[[5,900,1.17]],"id":44621159},{"bdatb":[[2,6.4,1.76],[3,6.2,39.41],[4,6,219.86],[5,5.9,10.52],[6,5.8,10],[7,5.7,97.65],[9,5.5,13.7]],"bdatl":[[8,9,38.01],[9,9.2,8.73]],"id":44836671},{"bdatb":[[2,8.8,6.07],[4,8.4,3.78],[5,8.2,1.81],[6,8,2.86],[7,7.8,2.91],[8,7.6,1.76],[9,7.4,3.39]],"bdatl":[[6,13.5,11.56],[8,14.5,14.34],[9,15,12.68]],"id":43885158},{"bdatb":[[2,14.5,1.76],[3,14,8.65],[4,13.5,6.02],[5,13,2.62],[7,12,4.64],[8,11.5,8.59],[9,10.5,9.75]],"id":46969227}]}]}
{"op":"mcm","clk":"AMHaAQDpbgCowwE=","pt":1659347820002,"mc":[{"id":"1.201590187","rc":[{"atl":[[22,4.02]],"id":45323444}]}]}
{"op":"mcm","clk":"AMPaAQDpbgCrwwE=","pt":1659347820052,"mc":[{"id":"1.201590187","rc":[{"bdatl":[[9,22,4.02]],"id":45323444}]}]}
{"op":"mcm","clk":"AMTaAQDsbgCtwwE=","pt":1659347820102,"mc":[{"id":"1.201590187","rc":[{"atl":[[2.28,1.75],[2.22,0]],"trd":[[2.22,18.42]],"ltp":2.22,"tv":1410.57,"id":9570503}],"tv":2491.33}]}
{"op":"mcm","clk":"AMjaAQDtbgCywwE=","pt":1659347820152,"mc":[{"id":"1.201590187","rc":[{"bdatb":[[3,11.5,5.14],[4,11,9.28],[5,10.5,7.85],[6,10,15.27],[9,9.4,11.05]],"id":45323444},{"bdatl":[[0,2.26,5.2],[1,2.28,1.75]],"id":9570503},{"bdatb":[[3,6.2,5.02],[4,6,1.84],[5,5.9,1.79],[6,5.8,37.24],[7,5.7,223.77],[8,5.6,1.81]],"id":12989514},{"bdatb":[[6,20,5.19],[7,19.5,1.76],[8,19,1.76]],"id":44621159},{"bdatb":[[3,6.2,39.36],[4,6,218.03],[5,5.9,9.02],[6,5.8,11.93],[7,5.7,96.31],[8,5.6,12.71],[9,5.5,13]],"id":44836671},{"bdatb":[[4,8.4,3.76],[5,8.2,1.79],[6,8,1.46],[7,7.8,1.79],[8,7.6,3.26],[9,7.4,2.36]],"id":43885158},{"bdatb":[[4,13.5,6],[5,13,1.76],[6,12.5,1.78],[7,12,4.65],[8,11.5,8.78],[9,10.5,9.02]],"id":46969227}]}]}
{"op":"mcm","clk":"AMvaAQDubgC1wwE=","pt":1659347820203,"mc":[{"id":"1.201590187","rc":[{"atb":[[2.2,85.49]],"trd":[[2.2,29.02]],"bdatb":[[0,2.2,85.49]],"ltp":2.2,"tv":1412.57,"id":9570503}],"tv":2493.33}]}
{"op":"mcm","clk":"AM/aAQDwbgC5wwE=","pt":1659347820292,"mc":[{"id":"1.201590187","rc":[{"atb":[[2.12,5.53]],"atl":[[2.4,3.31]],"id":9570503},{"atb":[[6.6,18.63]],"atl":[[7.4,5.27]],"id":12989514},{"atb":[[6.6,21.53]],"atl":[[7.6,11.91]],"id":44836671},{"atb":[[8.8,8.35],[9.2,2.14]],"id":43885158}]}]}
{"op":"mcm","clk":"ANLaAQD2bgC+wwE=","pt":1659347820342,"mc":[{"id":"1.201590187","rc":[{"bdatb":[[1,2.12,5.68]],"bdatl":[[2,2.4,13.44],[3,2.42,36.31],[4,2.44,28.27]],"id":9570503},{"bdatb":[[1,6.6,18.63]],"bdatl":[[1,7.4,5.27],[9,9,4.36]],"id":12989514},{"bdatl":[[5,900,1.16]],"id":44621159},{"bdatb":[[1,6.6,21.53]],"bdatl":[[2,7.6,11.91],[8,9,37.5],[9,9.2,8.5]],"id":44836671},{"bdatb":[[0,9.2,2.14],[2,8.8,8.35]],"id":43885158}]}]}
{"op":"mcm","clk":"ANXaAQD4bgDBwwE=","pt":1659347820393,"mc":[{"id":"1.201590187","rc":[{"atl":[[22,2.58]],"bdatl":[[9,22,2.58]],"id":45323444},{"atl":[[2.4,17.68]],"bdatl":[[2,2.4,27.81],[3,2.42,35.62],[4,2.44,24.78],[5,2.46,1.85],[6,2.48,2.28],[7,2.5,27.61],[8,2.52,2.8],[9,2.54,7.3]],"id":9570503},{"atb":[[6.8,4.31]],"bdatb":[[0,6.8,4.31]],"id":12989514},{"bdatl":[[8,14.5,14.22],[9,15,12]],"id":43885158}]}]}
{"op":"mcm","clk":"AN3aAQD8bgDJwwE=","pt":1659347820472,"mc":[{"id":"1.201590187","rc":[{"atl":[[24,1.44]],"id":45323444},{"atb":[[6.6,22.51]],"id":12989514},{"atb":[[9.2,0]],"id":43885158},{"atb":[[15.5,1]],"id":46969227}]}]}
{"op":"mcm","clk":"AN3aAQD8bgDMwwE=","pt":1659347820522,"mc":[{"id":"1.201590187","rc":[{"bdatl":[[2,2.4,24.14],[3,2.42,33.7],[4,2.44,29.6],[5,2.48,4.79],[6,2.5,21.41],[7,2.52,8.95],[8,2.54,1.2],[9,2.56,21.89]],"id":9570503},{"bdatb":[[1,6.6,22.51]],"bdatl":[[9,9,2.17]],"id":12989514},{"bdatl":[[5,900,1.14]],"id":44621159},{"bdatl":[[8,9,35.31],[9,9.2,9.68]],"id":44836671},{"bdatb":[[0,9,1.76],[1,8.8,8.35],[2,8.6,20],[3,8.4,3.76],[4,8.2,1.79],[5,8,1.46],[6,7.8,1.79],[7,7.6,3.26],[8,7.4,2.36],[9,7.2,11.88]],"bdatl":[[6,13.5,10.91],[7,14,13.83],[8,14.5,13.87],[9,15,12.33]],"id":43885158},{"bdatb":[[0,15.5,1]],"id":46969227}]}]}
{"op":"mcm","clk":"AOHaAQD+bgDOwwE=","pt":1659347820575,"mc":[{"id":"1.201590187","rc":[{"atl":[[1000,2.88]],"id":45323444},{"atl":[[1000,2.98]],"id":9570503},{"atl":[[1000,2.9],[7.6,5.42],[7.4,12.19]],"id":44836671},{"atl":[[1000,3.32]],"id":43885158}]}]}
{"op":"mcm","clk":"AOLaAQD/bgDTwwE=","pt":1659347820625,"mc":[{"id":"1.201590187","rc":[{"bdatb":[[9,1.98,85.85]],"id":9570503},{"bdatl":[[1,7.4,12.19],[2,7.6,5.42]],"id":44836671}]}]}
{"op":"mcm","clk":"AOXaAQCBbwDWwwE=","pt":1659347820675,"mc":[{"id":"1.201590187","rc":[{"atl":[[2.26,1.85]],"id":9570503}]}]}
{"op":"mcm","clk":"AObaAQCDbwDbwwE=","pt":1659347820725,"mc":[{"id":"1.201590187","rc":[{"bdatb":[[6,10,14.54],[7,9.8,9.41],[9,9.4,11.02]],"id":45323444},{"bdatl":[[0,2.26,1.85]],"id":9570503},{"bdatb":[[6,5.8,35.98],[7,5.7,224.46],[8,5.6,1.76]],"id":12989514},{"bdatb":[[6,5.8,10.67],[7,5.7,96.96],[8,5.6,12]],"id":44836671},{"bdatb":[[7,7.6,2.29],[8,7.4,2.86],[9,7.2,11.33]],"id":43885158},{"bdatb":[[8,11.5,8.15],[9,10.5,9.36]],"id":46969227}]}]}
{"op":"mcm","clk":"AOraAQCEbwDcwwE=","pt":1659347820781,"mc":[{"id":"1.201590187","rc":[{"atb":[[11.5,1.97]],"id":45323444},{"atb":[[2.08,9.4]],"id":9570503},{"atb":[[7.2,3.71]],"id":43885158},{"atb":[[14,1.76],[13.5,1.76]],"id":46969227}]}]}
{"op":"mcm","clk":"AO3aAQCJbwDlwwE=","pt":1659347820831,"mc":[{"id":"1.201590187","rc":[{"bdatb":[[3,11.5,1.97]],"id":45323444},{"bdatb":[[3,2.08,9.42]],"bdatl":[[9,2.56,7.68]],"id":9570503},{"bdatb":[[9,7.2,3.71]],"id":43885158},{"bdatb":[[3,14,1.76],[4,13.5,1.76]],"id":46969227}]}]}
{"op":"mcm","clk":"APLaAQCLbwDnwwE=","pt":1659347820891,"mc":[{"id":"1.201590187","rc":[{"atl":[[1000,3.36]],"id":46969227}]}]}
{"op":"mcm","clk":"APfaAQCLbwDswwE=","pt":1659347820975,"mc":[{"id":"1.201590187","rc":[{"atb":[[9,0]],"id":43885158},{"atb":[[15,0.02]],"id":46969227}]}]}
{"op":"mcm","clk":"APnaAQCPbwDxwwE=","pt":1659347821025,"mc":[{"id":"1.201590187","rc":[{"bdatl":[[2,2.4,17.68],[3,2.42,39.95],[4,2.44,27.7],[5,2.46,2.04],[6,2.5,25.75],[7,2.52,9.35],[8,2.56,3.39],[9,2.58,5.43]],"id":9570503},{"bdatl":[[9,9.2,8]],"id":44836671},{"bdatb":[[0,8.8,8.35],[1,8.6,20],[2,8.4,3.76],[3,8.2,1.79],[4,8,1.46],[5,7.8,1.79],[6,7.6,2.29],[7,7.4,2.86],[8,7.2,3.71],[9,7,130]],"bdatl":[[7,14,13.22],[8,14.5,14.46],[9,15,12]],"id":43885158},{"bdatb":[[1,14.5,1.78],[2,14,1.76],[3,13.5,1.76],[4,13,1.76],[5,12.5,1.78],[6,12,4.65],[7,11.5,8.15],[8,10.5,9.36],[9,10,7.1]],"id":46969227}]}]}
{"op":"mcm","clk":"AP/aAQCQbwD0wwE=","pt":1659347821085,"mc":[{"id":"1.201590187","rc":[{"atl":[[1000,0.01]],"id":45323444},{"atl":[[1000,0.1]],"id":9570503},{"atl":[[1000,0.03]],"id":44836671},{"atl":[[1000,0.45]],"id":43885158}]}]}
{"op":"mcm","clk":"AIXbAQCSbwD+wwE=","pt":1659347821147,"mc":[{"id":"1.201590187","rc":[{"atl":[[2.48,92.98],[2.44,87.8],[2.52,150.89],[2.4,43.89]],"id":9570503}]}]}
{"op":"mcm","clk":"AIfbAQCUbwCDxAE=","pt":1659347821197,"mc":[{"id":"1.201590187","rc":[{"bdatl":[[2,2.4,43.89],[4,2.44,91.41],[6,2.48,92.98],[7,2.5,25.75],[8,2.52,160.24],[9,2.56,3.39]],"id":9570503}]}]}
{"op":"mcm","clk":"AI/bAQCbbwCOxAE=","pt":1659347821361,"mc":[{"id":"1.201590187","rc":[{"atl":[[2.38,1.76]],"id":9570503},{"atb":[[11,1.76]],"atl":[[1000,0.49],[23,1.76]],"id":46969227}]}]}
{"op":"mcm","clk":"AJLbAQCcbwCSxAE=","pt":1659347821411,"mc":[{"id":"1.201590187","rc":[{"bdatl":[[2,2.38,1.76],[3,2.4,43.89],[4,2.42,39.95],[5,2.44,91.41],[6,2.46,2.04],[7,2.48,92.98],[8,2.5,25.75],[9,2.52,160.24]],"id":9570503},{"bdatb":[[8,11,2.13],[9,10.5,9]],"bdatl":[[5,23,1.76],[6,24,9.35],[7,25,1.76],[8,26,6],[9,27,1.76]],"id":46969227}]}]}
{"op":"mcm","clk":"AJbbAQCebwCTxAE=","pt":1659347821462,"mc":[{"id":"1.201590187","rc":[{"atl":[[55,0]],"id":44621159},{"atl":[[20,1]],"id":46969227}]}]}
{"op":"mcm","clk":"AJnbAQCebwCaxAE=","pt":1659347821512,"mc":[{"id":"1.201590187","rc":[{"bdatl":[[3,80,2.32]],"id":44621159},{"bdatl":[[2,20,1]],"id":46969227}]}]}
{"op":"mcm","clk":"AJ3bAQCfbwCcxAE=","pt":1659347821571,"mc":[{"id":"1.201590187","rc":[{"atl":[[1000,0]],"id":45323444},{"atl":[[1000,0]],"id":9570503},{"atl":[[60,0.63]],"id":44621159},{"atl":[[1000,0]],"id":44836671},{"atl":[[1000,0.43]],"id":43885158},{"atb":[[15.5,0]],"atl":[[20,0]],"id":46969227}]}]}
{"op":"mcm","clk":"AJ3bAQCibwCfxAE=","pt":1659347821621,"mc":[{"id":"1.201590187","rc":[{"bdatl":[[4,2.42,33.55],[5,2.44,97.76],[6,2.48,95.01],[7,2.5,25.75],[8,2.52,154.6],[9,2.54,5.6]],"id":9570503},{"bdatl":[[3,80,2.95]],"id":44621159},{"bdatl":[[6,13.5,9.76],[8,14.5,15.53]],"id":43885158},{"bdatb":[[0,14.5,1.78],[1,14,1.76],[2,13.5,1.76],[3,13,1.76],[4,12.5,1.78],[5,12,4.65],[6,11.5,8.15],[7,11,2.13],[8,10.5,9],[9,10,7.1]],"bdatl":[[2,21,5.25],[3,22,1.76],[4,23,1.76],[5,24,9.35],[6,25,1.76],[7,26,6],[8,27,1.76],[9,28,7.55]],"id":46969227}]}]}
{"op":"mcm","clk":"AKDbAQCjbwCgxAE=","pt":1659347821671,"mc":[{"id":"1.201590187","rc":[{"atl":[[30,0.01]],"id":45323444},{"atl":[[2.56,0.1]],"id":9570503},{"atl":[[8.6,1.79]],"id":44836671},{"atl":[[13.5,9.78]],"id":43885158},{"atb":[[14.5,0]],"id":46969227}]}]}
{"op":"mcm","clk":"AKHbAQClbwCixAE=","pt":1659347821721,"mc":[{"id":"1.201590187","rc":[{"bdatl":[[5,2.44,87.91],[6,2.46,9.78],[7,2.48,93.24],[8,2.5,22.75],[9,2.52,155.6]],"id":9570503},{"bdatl":[[6,8.6,1.79]],"id":44836671},{"bdatl":[[6,13.5,9.78],[8,14.5,13.87],[9,15,13.6]],"id":43885158},{"bdatb":[[0,14,1.78],[1,13.5,1.76],[2,13,1.76],[3,12.5,1.78],[4,12,4.65],[5,11.5,8.15],[6,11,2.13],[7,10.5,9],[8,10,7.1],[9,9,15.6]],"id":46969227}]}]}
{"op":"mcm","clk":"AKnbAQCpbwCmxAE=","pt":1659347821788,"mc":[{"id":"1.201590187","rc":[{"atl":[[2.42,67.28],[2.4,59.38]],"id":9570503},{"atl":[[1000,3.37]],"id":12989514}]}]}
{"op":"mcm","clk":"AKrbAQCpbwCoxAE=","pt":1659347821838,"mc":[{"id":"1.201590187","rc":[{"bdatl":[[3,2.4,59.38],[4,2.42,67.28]],"id":9570503}]}]}
{"op":"mcm","clk":"AK/bAQCqbwCpxAE=","pt":1659347821888,"mc":[{"id":"1.201590187","rc":[{"atl":[[1000,0.47]],"id":46969227}]}]}
{"op":"mcm","clk":"ALnbAQCtbwCvxAE=","pt":1659347821995,"mc":[{"id":"1.201590187","rc":[{"atl":[[2.38,35.31]],"id":9570503},{"atl":[[27,1.78]],"id":46969227}]}]}
{"op":"mcm","clk":"ALzbAQCtbwCwxAE=","pt":1659347822045,"mc":[{"id":"1.201590187","rc":[{"bdatl":[[2,2.38,35.31]],"id":9570503},{"bdatl":[[8,27,1.78]],"id":46969227}]}]}
{"op":"mcm","clk":"AMzbAQC2bwC7xAE=","pt":1659347822294,"mc":[{"id":"1.201590187","rc":[{"atb":[[1.02,0]],"id":46969227}]}]}
{"op":"mcm","clk":"ANXbAQC7bwC/xAE=","pt":1659347822348,"mc":[{"id":"1.201590187","rc":[{"atl":[[1000,2.91]],"id":45323444},{"atl":[[1000,0.5]],"id":12989514},{"atl":[[9.6,2.3]],"id":43885158},{"atb":[[12.5,3.39]],"id":46969227}]}]}
{"op":"mcm","clk":"ANXbAQDAbwDAxAE=","pt":1659347822398,"mc":[{"id":"1.201590187","rc":[{"bdatb":[[4,11,9.29],[5,10.5,8.22],[7,9.8,9]],"id":45323444},{"bdatb":[[1,2.12,10.97],[2,2.1,10.74],[3,2.08,12.42],[4,2.06,4.06],[5,2.04,26.7],[6,2.02,56.81],[7,2,96.16],[8,1.99,3.15],[9,1.98,74.7]],"id":9570503},{"bdatb":[[3,6.2,5.04],[4,6,2.48],[5,5.9,1.76],[6,5.8,36],[7,5.7,223.76]],"id":12989514},{"bdatb":[[8,19,1.77]],"id":44621159},{"bdatb":[[3,6.2,39.38],[4,6,218.67],[5,5.9,9],[6,5.8,10.69],[7,5.7,96.26]],"id":44836671},{"bdatl":[[0,9.6,2.3],[1,10,1.15],[2,10.5,5.43],[3,11.5,3.13],[4,12,10.85],[5,12.5,13.48],[6,13,1.76],[7,13.5,9.78],[8,14,13.22],[9,14.5,13.87]],"id":43885158},{"bdatb":[[2,13,1.78],[3,12.5,3.71],[4,12,4.64],[5,11.5,8.16],[6,11,1.76],[9,9.4,1.46]],"id":46969227}]}]}
{"op":"mcm","clk":"ANvbAQDAbwDIxAE=","pt":1659347822460,"mc":[{"id":"1.201590187","rc":[{"atl":[[1000,3.27]],"id":9570503},{"atl":[[1000,2.99]],"id":44836671},{"atl":[[1000,3.38]],"id":43885158},{"atb":[[14,0]],"id":46969227}]}]}
{"op":"mcm","clk":"ANvbAQDFbwDMxAE=","pt":1659347822510,"mc":[{"id":"1.201590187","rc":[{"bdatl":[[6,2.48,102.58],[7,2.5,21.1],[8,2.52,152.88],[9,2.54,4.67]],"id":9570503},{"bdatb":[[0,13.5,1.78],[1,13,1.78],[2,12.5,3.71],[3,12,4.64],[4,11.5,8.16],[5,11,1.76],[6,10.5,9],[7,10,7.1],[8,9.4,1.46],[9,9,15.95]],"id":46969227}]}]}
{"op":"mcm","clk":"AOLbAQDGbwDQxAE=","pt":1659347822573,"mc":[{"id":"1.201590187","rc":[{"atl":[[2.36,3.53]],"id":9570503},{"atb":[[8.8,10.66]],"id":43885158},{"atl":[[1000,3.38]],"id":46969227}]}]}
{"op":"mcm","clk":"AOfbAQDHbwDUxAE=","pt":1659347822623,"mc":[{"id":"1.201590187","rc":[{"bdatl":[[2,2.36,3.53],[3,2.38,35.31],[4,2.4,59.38],[5,2.42,67.28],[6,2.44,87.91],[7,2.48,102.58],[8,2.5,21.1],[9,2.52,152.88]],"id":9570503},{"bdatb":[[0,8.8,10.66]],"id":43885158},{"bdatb":[[7,10,7.43],[8,9.4,1.1]],"id":46969227}]}]}
{"op":"mcm","clk":"APXbAQDPbwDdxAE=","pt":1659347822778,"mc":[{"id":"1.201590187","rc":[{"atl":[[1000,0.03]],"id":45323444},{"atl":[[2.36,5.29]],"id":9570503},{"atb":[[13,9.21],[12.5,9.13]],"id":46969227}]}]}
{"op":"mcm","clk":"APbbAQDPbwDjxAE=","pt":1659347822828,"mc":[{"id":"1.201590187","rc":[{"bdatl":[[2,2.36,5.29]],"id":9570503},{"bdatb":[[1,13,9.22],[2,12.5,9.45],[8,9.4,1.08]],"id":46969227}]}]}
{"op":"mcm","clk":"AP3bAQDRbwDoxAE=","pt":1659347822892,"mc":[{"id":"1.201590187","rc":[{"atl":[[10.5,3]],"id":43885158},{"atb":[[13.5,2.76],[12,1.76]],"id":46969227}]}]}
{"op":"mcm","clk":"AP7bAQDRbwDrxAE=","pt":1659347822942,"mc":[{"id":"1.201590187","rc":[{"bdatb":[[6,2.02,47.22],[7,2,94.46],[8,1.99,2.02],[9,1.98,86.93]],"bdatl":[[7,2.48,102.68],[8,2.5,23.01],[9,2.52,154.16]],"id":9570503},{"bdatl":[[2,10.5,3]],"id":43885158},{"bdatb":[[0,13.5,2.78],[3,12,1.76]],"id":46969227}]}]}
{"op":"mcm","clk":"AIbcAQDSbwDvxAE=","pt":1659347822999,"mc":[{"id":"1.201590187","rc":[{"atl":[[1000,0.4]],"id":9570503},{"atl":[[1000,0.47]],"id":12989514},{"atl":[[1000,0.11]],"id":44836671},{"atl":[[1000,0.5]],"id":43885158},{"atb":[[12.5,7.5],[11,4.64]],"atl":[[18.5,1.01]],"id":46969227}]}]}
{"op":"mcm","clk":"AIbcAQDVbwDxxAE=","pt":1659347823049,"mc":[{"id":"1.201590187","rc":[{"bdatb":[[4,11,9.31],[5,10.5,8.2]],"id":45323444},{"bdatb":[[1,2.12,14.34],[2,2.1,7.33],[7,2,94.72],[8,1.99,7.71],[9,1.98,80.95]],"id":9570503},{"bdatb":[[5,5.9,2.44],[6,5.8,35.31]],"id":12989514},{"bdatb":[[5,5.9,9.68],[6,5.8,10]],"id":44836671},{"bdatb":[[5,7.8,1.81],[6,7.6,2.27]],"id":43885158},{"bdatb":[[2,12.5,7.82],[5,11,4.64]],"bdatl":[[0,18.5,1.01],[1,19,3.24],[2,19.5,5],[3,21,5.25],[4,22,1.76],[5,23,1.76],[6,24,9.35],[7,25,1.76],[8,26,6],[9,27,1.78]],"id":46969227}]}]}
{"op":"mcm","clk":"AIncAQDZbwD1xAE=","pt":1659347823099,"mc":[{"id":"1.201590187","rc":[{"atl":[[8.2,1.8]],"id":12989514},{"atl":[[9.4,2.68]],"id":43885158},{"atb":[[13.5,4.39]],"id":46969227}]}]}
{"op":"mcm","clk":"AJLcAQDbbwD2xAE=","pt":1659347823149,"mc":[{"id":"1.201590187","rc":[{"bdatb":[[4,11,9.66],[5,10.5,8.22],[6,10,14.14]],"id":45323444},{"bdatb":[[1,2.14,5.39],[2,2.12,11.98],[3,2.1,7.21],[4,2.08,18.5],[5,2.06,4.58],[6,2.04,19.44],[7,2.02,54.24],[8,2,96],[9,1.99,3.15]],"bdatl":[[9,2.52,155.6]],"id":9570503},{"bdatb":[[3,6.2,5.07],[4,6,3.11],[5,5.9,1.76],[9,5.5,2.37]],"bdatl":[[5,8.2,1.8]],"id":12989514},{"bdatb":[[7,19.5,1.77],[8,19,1.76],[9,18.5,2.91]],"id":44621159},{"bdatb":[[3,6.2,39.41],[4,6,219.31],[5,5.9,9],[9,5.5,14.91]],"id":44836671},{"bdatl":[[0,9.4,2.68],[1,9.6,2.3],[2,10,1.15],[3,10.5,3],[4,11.5,3.13],[5,12,10.85],[6,12.5,13.48],[7,13,1.76],[8,13.5,9.78],[9,14,13.22]],"id":43885158},{"bdatb":[[0,13.5,4.42],[2,12.5,7.81],[3,12,2.1],[4,11.5,7.81],[7,10,8.35],[8,9,18.16],[9,8.8,45.97]],"id":46969227}]}]}
{"op":"mcm","clk":"AJTcAQDcbwD4xAE=","pt":1659347823199,"mc":[{"id":"1.201590187","rc":[{"atb":[[8.8,8.9]],"atl":[[9.8,1.15]],"id":43885158},{"atb":[[13.5,2.63]],"atl":[[1000,0.51],[18.5,2.44]],"id":46969227}]}]}
{"op":"mcm","clk":"AJjcAQDhbwD7xAE=","pt":1659347823249,"mc":[{"id":"1.201590187","rc":[{"bdatb":[[2,2.12,13.47],[3,2.1,13.7],[4,2.08,10.57],[5,2.06,6.85],[6,2.04,22.53],[7,2.02,57.12],[8,2,93.18],[9,1.99,1.76]],"bdatl":[[9,2.52,153.43]],"id":9570503},{"bdatb":[[9,5.5,15.27]],"id":44836671},{"bdatb":[[0,8.8,8.9]],"bdatl":[[2,9.8,1.15],[3,10,1.15],[4,10.5,3],[5,11.5,3.13],[6,12,10.85],[7,12.5,13.48],[8,13,1.76],[9,13.5,9.78]],"id":43885158},{"bdatb":[[0,13.5,2.66],[9,8.8,46]],"bdatl":[[0,18.5,2.44]],"id":46969227}]}]}
{"op":"mcm","clk":"AJzcAQDnbwD8xAE=","pt":1659347823299,"mc":[{"id":"1.201590187","rc":[{"atl":[[1000,0]],"id":45323444},{"atl":[[1000,3.46]],"id":12989514},{"atl":[[11.5,2.64]],"bdatl":[[5,11.5,2.89]],"id":43885158}]}]}
{"op":"mcm","clk":"AKPcAQDqbwCDxQE=","pt":1659347823376,"mc":[{"id":"1.201590187","rc":[{"atl":[[32,0.03]],"id":45323444},{"atl":[[9.4,3.22],[11,0.01],[10.5,0]],"id":43885158},{"atl":[[19,6.18]],"id":46969227}]}]}
{"op":"mcm","clk":"AKbcAQDtbwCIxQE=","pt":1659347823426,"mc":[{"id":"1.201590187","rc":[{"bdatb":[[4,2.08,11.99],[5,2.06,7.88],[7,2.02,41.53],[8,2,93.14],[9,1.99,6.4]],"id":9570503},{"bdatl":[[0,9.4,3.22],[4,11.5,2.65],[5,12,10.85],[6,12.5,13.48],[7,13,1.76],[8,13.5,9.78],[9,14,13.22]],"id":43885158},{"bdatb":[[8,9.2,1.01],[9,9,17.17]],"bdatl":[[1,19,6.18]],"id":46969227}]}]}
{"op":"mcm","clk":"AKjcAQDxbwCJxQE=","pt":1659347823476,"mc":[{"id":"1.201590187","rc":[{"atb":[[2.1,1.88]],"atl":[[1000,0]],"bdatb":[[3,2.1,9.87]],"id":9570503},{"atl":[[7.6,22.15]],"bdatl":[[2,7.6,22.15]],"id":12989514},{"atb":[[6.8,18.54]],"atl":[[1000,0]],"bdatb":[[0,6.8,18.54]],"id":44836671},{"atl":[[1000,0.43],[11.5,5.63]],"bdatl":[[4,11.5,5.64]],"id":43885158}]}]}
{"op":"mcm","clk":"ALXcAQD0bwCLxQE=","pt":1659347823583,"mc":[{"id":"1.201590187","rc":[{"atb":[[2.14,10.57]],"atl":[[2.7,0.4]],"id":9570503},{"atl":[[7.4,9.94]],"id":12989514},{"atl":[[9.4,1.88]],"id":44836671},{"atl":[[15,12.07]],"id":43885158}]}]}
{"op":"mcm","clk":"ALXcAQD0bwCPxQE=","pt":1659347823633,"mc":[{"id":"1.201590187","rc":[{"bdatb":[[1,2.14,15.96]],"id":9570503},{"bdatl":[[1,7.4,9.94]],"id":12989514}]}]}
{"op":"mcm","clk":"ALrcAQD2bwCQxQE=","pt":1659347823685,"mc":[{"id":"1.201590187","rc":[{"atb":[[2.2,0]],"id":9570503},{"atl":[[1000,0.47]],"id":46969227}]}]}
{"op":"mcm","clk":"AL7cAQD4bwCSxQE=","pt":1659347823735,"mc":[{"id":"1.201590187","rc":[{"bdatb":[[0,2.14,15.96],[1,2.12,13.47],[2,2.1,9.87],[3,2.08,11.99],[4,2.06,7.88],[5,2.04,22.53],[6,2.02,41.53],[7,2,93.14],[8,1.99,6.4],[9,1.98,79.19]],"id":9570503},{"bdatl":[[9,14,13.2]],"id":43885158}]}]}
{"op":"mcm","clk":"AMTcAQD6bwCTxQE=","pt":1659347823786,"mc":[{"id":"1.201590187","rc":[{"atl":[[1000,2.92]],"id":45323444},{"atb":[[2.24,85.49]],"atl":[[2.42,33.55],[2.36,8.95]],"id":9570503},{"atl":[[1000,0.59]],"id":12989514},{"atb":[[14,7.45],[13,1.76]],"atl":[[1000,0.89],[30,1.87]],"id":46969227}]}]}
{"op":"mcm","clk":"AMjcAQD7bwCYxQE=","pt":1659347823836,"mc":[{"id":"1.201590187","rc":[{"bdatb":[[0,2.24,85.49],[1,2.14,15.96],[2,2.12,13.47],[3,2.1,9.87],[4,2.08,11.99],[5,2.06,7.88],[6,2.04,22.53],[7,2.02,41.53],[8,2,93.14],[9,1.99,6.4]],"bdatl":[[2,2.36,8.95],[5,2.42,33.55],[7,2.46,9.78],[8,2.48,95],[9,2.5,25.75]],"id":9570503},{"bdatl":[[9,9,2.2]],"id":12989514},{"bdatb":[[9,5.5,16.67]],"bdatl":[[8,9,35.34],[9,9.2,10.61]],"id":44836671},{"bdatl":[[6,12.5,13.5],[8,13.5,11.56],[9,14,13.56]],"id":43885158},{"bdatb":[[0,14,7.47],[1,13.5,2.64],[2,13,1.78],[3,12.5,7.81],[4,12,2.1],[5,11.5,7.81],[6,11,4.64],[7,10.5,9],[8,10,9.12],[9,9,17.38]],"id":46969227}]}]}
{"op":"mcm","clk":"ANHcAQCCcACcxQE=","pt":1659347823902,"mc":[{"id":"1.201590187","rc":[{"atb":[[2.12,7.27],[2.06,0]],"atl":[[1000,3.44]],"id":9570503}]}]}
{"op":"mcm","clk":"ANHcAQCCcACdxQE=","pt":1659347823953,"mc":[{"id":"1.201590187","rc":[{"bdatb":[[2,2.12,15.21],[5,2.06,6.36]],"id":9570503}]}]}
{"op":"mcm","clk":"ANfcAQCEcACexQE=","pt":1659347824004,"mc":[{"id":"1.201590187","rc":[{"atl":[[2.26,0],[2.28,1.6]],"trd":[[2.26,3.7],[2.28,0.3]],"ltp":2.28,"tv":1416.57,"id":9570503},{"atb":[[24,1.49]],"atl":[[34,0]],"id":44621159},{"atl":[[1000,0]],"id":46969227}],"tv":2497.33}]}
{"op":"mcm","clk":"ANrcAQCGcACkxQE=","pt":1659347824054,"mc":[{"id":"1.201590187","rc":[{"bdatb":[[4,11,9.28],[5,10.5,7.87],[6,10,14.47]],"id":45323444},{"bdatb":[[1,2.14,10.72],[2,2.12,20.49],[3,2.1,2.8],[4,2.08,17.71],[5,2.06,2.33],[6,2.04,22.42],[7,2.02,47.22],[8,2,93.09],[9,1.99,1.82]],"bdatl":[[0,2.28,1.6],[1,2.36,8.95],[2,2.38,35.31],[3,2.4,59.38],[4,2.42,33.55],[5,2.44,87.91],[6,2.46,9.78],[7,2.48,95],[8,2.5,25.75],[9,2.52,160.24]],"id":9570503},{"bdatb":[[3,6.2,5.02],[4,6,1.86],[5,5.9,2.33],[9,5.5,1.76]],"id":12989514},{"bdatb":[[2,24,1.49],[7,19.5,1.76],[9,18.5,2.7]],"bdatl":[[0,36,1.16],[1,40,3.73],[2,80,2.95],[3,170,2],[4,900,1.14],[5,990,1.83],[6,1000,2],[7,0,0]],"id":44621159},{"bdatb":[[3,6.2,39.36],[4,6,218.05],[5,5.9,9.56],[9,5.5,13]],"id":44836671},{"bdatb":[[5,7.8,1.76],[6,7.6,1.78],[7,7.4,2.8]],"id":43885158},{"bdatb":[[1,13.5,2.63],[2,13,1.76],[3,12.5,7.53],[4,12,2.04],[8,10,7.89],[9,9.8,1.35]],"id":46969227}]}]}
{"op":"mcm","clk":"ANzcAQCKcACmxQE=","pt":1659347824104,"mc":[{"id":"1.201590187","rc":[{"atb":[[24,0.49]],"bdatb":[[2,23,6.8],[3,22,1.76],[4,21,5],[5,20,5.19],[6,19.5,1.76],[7,19,1.76],[8,18.5,2.7],[9,18,1.96]],"id":44621159},{"atl":[[18,0.41],[18.5,2.91]],"bdatl":[[0,18.5,3.32]],"id":46969227},{"bdatb":[[4,11,9.31],[5,10.5,8.15],[6,10,14.14]],"id":45323444},{"bdatb":[[1,2.14,14.03],[2,2.12,17.15],[5,2.06,2.93],[6,2.04,21.82]],"id":9570503},{"bdatb":[[3,6.2,5.04],[4,6,2.39],[5,5.9,1.76],[9,5.5,2.45]],"id":12989514},{"bdatb":[[3,6.2,39.38],[4,6,218.58],[5,5.9,9],[9,5.5,13.68]],"id":44836671},{"bdatb":[[5,7.8,1.78],[6,7.6,1.79],[7,7.4,2.77]],"id":43885158}]}]}
{"op":"mcm","clk":"AOLcAQCPcACrxQE=","pt":1659347824200,"mc":[{"id":"1.201590187","rc":[{"atl":[[1000,0.05]],"id":45323444},{"atl":[[2.46,1.76],[2.28,3.25]],"id":9570503},{"atl":[[1000,3.03]],"id":44836671},{"atl":[[1000,3.41]],"id":43885158},{"atl":[[1000,2.92],[20,1.76]],"id":46969227}]}]}
{"op":"mcm","clk":"AOPcAQCQcACyxQE=","pt":1659347824250,"mc":[{"id":"1.201590187","rc":[{"bdatb":[[5,10.5,8.51]],"id":45323444},{"bdatl":[[0,2.28,3.25],[6,2.46,11.54]],"id":9570503},{"bdatb":[[4,6,3.01],[5,5.9,1.77],[9,5.5,1.76]],"id":12989514},{"bdatb":[[9,18,2.17]],"id":44621159},{"bdatb":[[4,6,219.21],[9,5.5,13]],"id":44836671},{"bdatb":[[7,7.4,3.28]],"id":43885158},{"bdatb":[[4,12,2.35],[8,10,7.51],[9,9.8,1.72]],"bdatl":[[3,20,1.76],[4,21,5.25],[5,22,1.76],[6,23,1.76],[7,24,9.35],[8,25,1.76],[9,26,6]],"id":46969227}]}]}
{"op":"mcm","clk":"AOzcAQCRcAC0xQE=","pt":1659347824300,"mc":[{"id":"1.201590187","rc":[{"atl":[[2.36,5.29]],"bdatb":[[1,2.14,15.95],[2,2.12,15.21],[6,2.04,23.24],[7,2.02,45.78]],"bdatl":[[1,2.36,5.29]],"id":9570503},{"atl":[[18,0.7]],"bdatb":[[9,9.4,1.76]],"bdatl":[[0,18.5,3.61]],"id":46969227},{"bdatb":[[4,6,3.02],[5,5.9,1.76],[9,5.5,2.51]],"id":12989514},{"bdatb":[[9,5.5,13.95]],"id":44836671}]}]}
{"op":"mcm","clk":"APTcAQCUcAC6xQE=","pt":1659347824369,"mc":[{"id":"1.201590187","rc":[{"atl":[[1000,0.57],[2.28,1.6]],"id":9570503},{"atl":[[1000,3.63]],"id":12989514},{"atl":[[21,5]],"id":46969227}]}]}
