{"op":"mcm","clk":"ANCJAQC7RwCTeg==","pt":1659347659285,"mc":[{"id":"1.201590187","rc":[{"bdatl":[[7,2.34,10.79],[8,2.36,2.73],[9,2.38,4.22]],"id":9570503},{"bdatb":[[0,25,3.4]],"id":44621159}]}]}
{"op":"mcm","clk":"ANWJAQC8RwCWeg==","pt":1659347659336,"mc":[{"id":"1.201590187","rc":[{"atb":[[7.6,1.76]],"id":43885158}]}]}
{"op":"mcm","clk":"ANeJAQC+RwCYeg==","pt":1659347659387,"mc":[{"id":"1.201590187","rc":[{"bdatb":[[7,7.6,1.76],[8,7.4,10.23],[9,7.2,4.56]],"id":43885158}]}]}
{"op":"mcm","clk":"ANuJAQDARwCdeg==","pt":1659347659437,"mc":[{"id":"1.201590187","rc":[{"atl":[[2.14,81.54]],"bdatl":[[0,2.14,81.54]],"id":9570503},{"atb":[[8.6,9.06]],"bdatb":[[2,8.6,9.06]],"id":43885158}]}]}
{"op":"mcm","clk":"AISKAQDXRwDLeg==","pt":1659347660130,"mc":[{"id":"1.201590187","rc":[{"atb":[[9.2,1.26]],"atl":[[11,2.55]],"id":43885158}]}]}
{"op":"mcm","clk":"AISKAQDXRwDNeg==","pt":1659347660192,"mc":[{"id":"1.201590187","rc":[{"bdatb":[[9,9.6,23.92]],"id":45323444},{"bdatb":[[6,1.96,16.92],[8,1.94,16.13],[9,1.93,4.46]],"bdatl":[[4,2.28,13.08],[5,2.3,2.77],[7,2.34,13.54],[8,2.36,1.75],[9,2.38,2.48]],"id":9570503},{"bdatb":[[9,5.4,5.19]],"id":12989514},{"bdatb":[[9,5.7,49.46]],"id":44836671},{"bdatb":[[0,9.2,1.26],[1,9,7.51],[2,8.8,5.17],[3,8.6,9.06],[4,8.4,1.76],[5,8.2,1.76],[6,8,6.23],[7,7.8,2.73],[8,7.6,1.76],[9,7.4,10.23]],"bdatl":[[0,11,2.8]],"id":43885158}]}]}
{"op":"mcm","clk":"AI6KAQDfRwDVeg==","pt":1659347660333,"mc":[{"id":"1.201590187","rc":[{"atb":[[13.5,0.18]],"id":45323444},{"atb":[[9.2,1.53]],"id":43885158}]}]}
{"op":"mcm","clk":"AI+KAQDiRwDZeg==","pt":1659347660384,"mc":[{"id":"1.201590187","rc":[{"bdatb":[[0,13,2.13],[1,12.5,4.01],[2,12,7.26],[3,11.5,5.54],[4,11,1.23],[5,10.5,1.76],[6,10,10.26],[7,9.8,9],[8,9.6,23.92],[9,9.4,62.72]],"id":45323444},{"bdatl":[[4,2.28,9.07],[5,2.3,5.06],[6,2.32,5.93],[7,2.34,20.17],[8,2.36,1.25],[9,2.38,1.54]],"id":9570503},{"bdatb":[[0,9.2,1.53]],"id":43885158}]}]}
{"op":"mcm","clk":"AJuKAQDoRwDgeg==","pt":1659347660538,"mc":[{"id":"1.201590187","rc":[{"atb":[[13.5,0]],"id":45323444},{"atb":[[25,1]],"id":44621159}]}]}
{"op":"mcm","clk":"AJ6KAQDqRwDieg==","pt":1659347660588,"mc":[{"id":"1.201590187","rc":[{"bdatb":[[0,13,1.95]],"id":45323444},{"bdatl":[[4,2.28,8],[5,2.3,6.12],[6,2.32,4.89],[7,2.34,18.3],[8,2.36,2.88],[9,2.4,74.19]],"id":9570503},{"bdatb":[[0,25,1.1]],"id":44621159}]}]}
{"op":"mcm","clk":"AKiKAQDwRwDmeg==","pt":1659347660704,"mc":[{"id":"1.201590187","rc":[{"atl":[[2.2,5],[2.28,0]],"id":9570503},{"atb":[[24,4.71]],"id":44621159}]}]}
{"op":"mcm","clk":"AKiKAQDxRwDneg==","pt":1659347660754,"mc":[{"id":"1.201590187","rc":[{"bdatl":[[3,2.2,5],[4,2.22,4]],"id":9570503},{"bdatb":[[1,24,4.71]],"id":44621159}]}]}
{"op":"mcm","clk":"AL6KAQCCSAD6eg==","pt":1659347661135,"mc":[{"id":"1.201590187","rc":[{"atb":[[12,2.66]],"id":45323444}]}]}
{"op":"mcm","clk":"AL6KAQCDSAD6eg==","pt":1659347661186,"mc":[{"id":"1.201590187","rc":[{"bdatb":[[2,12,2.66]],"id":45323444}]}]}
{"op":"mcm","clk":"ANCKAQCISACJew==","pt":1659347661429,"mc":[{"id":"1.201590187","rc":[{"atb":[[24,2.29]],"id":44621159},{"atb":[[9,1.76]],"id":43885158}]}]}
{"op":"mcm","clk":"ANSKAQCISACLew==","pt":1659347661479,"mc":[{"id":"1.201590187","rc":[{"bdatl":[[7,2.34,1.94],[8,2.36,19.11],[9,2.4,71.65]],"id":9570503},{"bdatb":[[1,24,2.29]],"id":44621159},{"bdatb":[[1,9,1.76]],"id":43885158}]}]}
{"op":"mcm","clk":"AOGKAQCNSACTew==","pt":1659347661642,"mc":[{"id":"1.201590187","rc":[{"atb":[[9.2,7.16]],"bdatb":[[0,9.2,7.16]],"id":43885158},{"bdatl":[[5,2.3,11.04],[6,2.32,17.45],[7,2.34,1.01],[8,2.36,2.88],[9,2.4,74.22]],"id":9570503}]}]}
{"op":"mcm","clk":"APGKAQCTSACjew==","pt":1659347661803,"mc":[{"id":"1.201590187","rc":[{"atb":[[25,3.3]],"id":44621159}]}]}
{"op":"mcm","clk":"APGKAQCTSACjew==","pt":1659347661853,"mc":[{"id":"1.201590187","rc":[{"bdatl":[[7,2.34,3.92],[8,2.38,2.83],[9,2.4,72.82]],"id":9570503},{"bdatb":[[0,25,3.4]],"id":44621159}]}]}
{"op":"mcm","clk":"AIWLAQCZSAC0ew==","pt":1659347662215,"mc":[{"id":"1.201590187","rc":[{"atb":[[12,0]],"id":45323444}]}]}
{"op":"mcm","clk":"AIqLAQCZSAC3ew==","pt":1659347662265,"mc":[{"id":"1.201590187","rc":[{"bdatb":[[2,11.5,5.54],[3,11,1.23],[4,10.5,1.76],[5,10,10.26],[6,9.8,9],[7,9.6,23.92],[8,9.4,62.72],[9,9.2,15.03]],"id":45323444},{"bdatl":[[8,2.4,74.23],[9,2.42,1.37]],"id":9570503}]}]}
{"op":"mcm","clk":"AJWLAQCgSADKew==","pt":1659347662530,"mc":[{"id":"1.201590187","rc":[{"atb":[[25,1]],"id":44621159},{"atb":[[9.2,1.53]],"id":43885158}]}]}
{"op":"mcm","clk":"AJiLAQChSADOew==","pt":1659347662580,"mc":[{"id":"1.201590187","rc":[{"bdatl":[[5,2.3,6.12],[6,2.32,4.89],[7,2.34,1.94],[8,2.36,19.11],[9,2.4,71.65]],"id":9570503},{"bdatb":[[0,25,1.1]],"id":44621159},{"bdatb":[[0,9.2,1.53]],"id":43885158}]}]}
{"op":"mcm","clk":"AJ6LAQClSADUew==","pt":1659347662736,"mc":[{"id":"1.201590187","rc":[{"atb":[[9.2,1.26],[9,7.78]],"id":43885158}]}]}
{"op":"mcm","clk":"AKWLAQCoSADWew==","pt":1659347662786,"mc":[{"id":"1.201590187","rc":[{"bdatl":[[5,2.3,5.04],[6,2.32,5.96],[7,2.34,18.3],[8,2.36,2.88]],"id":9570503},{"bdatb":[[0,9.2,1.26],[1,9,7.78]],"id":43885158}]}]}
{"op":"mcm","clk":"ALGLAQCvSADfew==","pt":1659347662947,"mc":[{"id":"1.201590187","rc":[{"atb":[[24,4.71]],"id":44621159},{"atb":[[9.2,1.53]],"id":43885158}]}]}
{"op":"mcm","clk":"ALKLAQCvSADgew==","pt":1659347662997,"mc":[{"id":"1.201590187","rc":[{"bdatl":[[5,2.3,6.12],[6,2.32,4.89]],"id":9570503},{"bdatb":[[1,24,4.71]],"id":44621159},{"bdatb":[[0,9.2,1.53]],"id":43885158}]}]}
{"op":"mcm","clk":"ALuLAQCySADpew==","pt":1659347663124,"mc":[{"id":"1.201590187","rc":[{"atb":[[2.02,28.38]],"id":9570503}]}]}
{"op":"mcm","clk":"AL2LAQCySADpew==","pt":1659347663174,"mc":[{"id":"1.201590187","rc":[{"bdatb":[[1,2.02,28.38]],"id":9570503}]}]}
{"op":"mcm","clk":"AOKLAQDASACAfA==","pt":1659347663736,"mc":[{"id":"1.201590187","rc":[{"atb":[[24,2.29]],"id":44621159},{"atb":[[9,2.03]],"id":43885158}]}]}
{"op":"mcm","clk":"AOaLAQDBSACCfA==","pt":1659347663786,"mc":[{"id":"1.201590187","rc":[{"bdatl":[[7,2.34,2.98],[8,2.36,18.08]],"id":9570503},{"bdatb":[[1,24,2.29]],"id":44621159},{"bdatb":[[1,9,2.03]],"id":43885158}]}]}
{"op":"mcm","clk":"AOqLAQDDSACEfA==","pt":1659347663847,"mc":[{"id":"1.201590187","rc":[{"atb":[[12.5,1.14]],"id":45323444}]}]}
{"op":"mcm","clk":"AOyLAQDFSACGfA==","pt":1659347663897,"mc":[{"id":"1.201590187","rc":[{"bdatb":[[1,12.5,1.14]],"id":45323444},{"bdatl":[[8,2.36,3.09],[9,2.4,86.17]],"id":9570503}]}]}
{"op":"mcm","clk":"APGLAQDGSACKfA==","pt":1659347663949,"mc":[{"id":"1.201590187","rc":[{"atb":[[12,2.87]],"id":45323444},{"atb":[[9.2,7.05]],"id":43885158}]}]}
{"op":"mcm","clk":"APOLAQDISACLfA==","pt":1659347663999,"mc":[{"id":"1.201590187","rc":[{"bdatb":[[2,12,2.87],[3,11.5,5.54],[4,11,1.23],[5,10.5,1.76],[6,10,10.26],[7,9.8,9],[8,9.6,23.92],[9,9.4,62.72]],"id":45323444},{"bdatl":[[5,2.3,11.04],[6,2.32,6.15],[7,2.34,10.77],[8,2.36,1.43],[9,2.38,2.48]],"id":9570503},{"bdatb":[[0,9.2,7.05]],"id":43885158}]}]}
{"op":"mcm","clk":"APeLAQDJSACOfA==","pt":1659347664049,"mc":[{"id":"1.201590187","rc":[{"atb":[[25,3.3]],"id":44621159}]}]}
{"op":"mcm","clk":"AP2LAQDLSACPfA==","pt":1659347664103,"mc":[{"id":"1.201590187","rc":[{"bdatl":[[7,2.34,12.21],[8,2.36,2.5],[9,2.4,75.2]],"id":9570503},{"bdatb":[[0,25,3.4]],"id":44621159}]}]}
{"op":"mcm","clk":"AKaMAQDhSAC7fA==","pt":1659347664744,"mc":[{"id":"1.201590187","rc":[{"atl":[[2.18,9.18]],"id":9570503},{"atb":[[25,1]],"id":44621159},{"atb":[[9.2,1.42]],"id":43885158},{"atl":[[28,7.64],[27,7.4]],"id":46969227}]}]}
{"op":"mcm","clk":"AKiMAQDhSAC/fA==","pt":1659347664794,"mc":[{"id":"1.201590187","rc":[{"bdatl":[[2,2.18,9.18],[5,2.3,5.68],[6,2.32,5.32],[7,2.34,2.55],[8,2.36,3.52],[9,2.38,14.49]],"id":9570503},{"bdatb":[[0,25,1.1]],"id":44621159},{"bdatb":[[0,9.2,1.42]],"id":43885158},{"bdatl":[[1,27,7.4],[2,28,7.64]],"id":46969227}]}]}
{"op":"mcm","clk":"AK6MAQDiSADDfA==","pt":1659347664844,"mc":[{"id":"1.201590187","rc":[{"atl":[[28,11.34],[27,3.55]],"id":46969227}]}]}
{"op":"mcm","clk":"ALCMAQDiSADIfA==","pt":1659347664895,"mc":[{"id":"1.201590187","rc":[{"bdatl":[[1,27,3.55],[2,28,11.34]],"id":46969227}]}]}
{"op":"mcm","clk":"ALaMAQDiSADMfA==","pt":1659347664945,"mc":[{"id":"1.201590187","rc":[{"atb":[[9.2,1.15],[9,7.78]],"id":43885158}]}]}
{"op":"mcm","clk":"ALaMAQDkSADPfA==","pt":1659347664995,"mc":[{"id":"1.201590187","rc":[{"bdatl":[[5,2.3,4.6],[6,2.32,6.39],[7,2.34,6.09],[8,2.36,12.11],[9,2.38,2.48]],"id":9570503},{"bdatb":[[0,9.2,1.15],[1,9,7.78]],"id":43885158}]}]}
{"op":"mcm","clk":"ALuMAQDlSADSfA==","pt":1659347665046,"mc":[{"id":"1.201590187","rc":[{"atb":[[24,4.71]],"id":44621159},{"atb":[[9.2,1.42]],"id":43885158}]}]}
{"op":"mcm","clk":"ALyMAQDnSADXfA==","pt":1659347665096,"mc":[{"id":"1.201590187","rc":[{"bdatl":[[5,2.3,5.68],[6,2.32,5.32]],"id":9570503},{"bdatb":[[1,24,4.71]],"id":44621159},{"bdatb":[[0,9.2,1.42]],"id":43885158}]}]}
{"op":"mcm","clk":"AMaMAQDtSADffA==","pt":1659347665244,"mc":[{"id":"1.201590187","rc":[{"atb":[[11.5,7.77]],"id":45323444}]}]}
{"op":"mcm","clk":"AMmMAQDtSADkfA==","pt":1659347665295,"mc":[{"id":"1.201590187","rc":[{"bdatb":[[3,11.5,7.77]],"id":45323444}]}]}
{"op":"mcm","clk":"AM+MAQDuSADlfA==","pt":1659347665348,"mc":[{"id":"1.201590187","rc":[{"atl":[[15.5,20]],"id":43885158}]}]}
{"op":"mcm","clk":"AM+MAQDxSADrfA==","pt":1659347665398,"mc":[{"id":"1.201590187","rc":[{"bdatl":[[9,15.5,20]],"id":43885158}]}]}
{"op":"mcm","clk":"AO+MAQCESQCQfQ==","pt":1659347665933,"mc":[{"id":"1.201590187","rc":[{"atb":[[24,2.29]],"id":44621159},{"atb":[[9,2.03]],"id":43885158}]}]}
{"op":"mcm","clk":"AO+MAQCESQCQfQ==","pt":1659347665984,"mc":[{"id":"1.201590187","rc":[{"bdatl":[[7,2.34,2.55],[8,2.36,3.52],[9,2.38,14.49]],"id":9570503},{"bdatb":[[1,24,2.29]],"id":44621159},{"bdatb":[[1,9,2.03]],"id":43885158}]}]}
{"op":"mcm","clk":"APyMAQCJSQCgfQ==","pt":1659347666144,"mc":[{"id":"1.201590187","rc":[{"atb":[[9.2,7.05]],"id":43885158}]}]}
{"op":"mcm","clk":"AP2MAQCJSQChfQ==","pt":1659347666194,"mc":[{"id":"1.201590187","rc":[{"bdatl":[[5,2.3,11.04],[6,2.32,6.15],[7,2.34,10.77],[8,2.36,1.43],[9,2.38,2.48]],"id":9570503},{"bdatb":[[0,9.2,7.05]],"id":43885158}]}]}
{"op":"mcm","clk":"AIGNAQCOSQCqfQ==","pt":1659347666338,"mc":[{"id":"1.201590187","rc":[{"atb":[[25,3.3]],"id":44621159}]}]}
{"op":"mcm","clk":"AIaNAQCQSQCtfQ==","pt":1659347666389,"mc":[{"id":"1.201590187","rc":[{"bdatl":[[7,2.34,12.21],[8,2.36,2.5],[9,2.4,75.2]],"id":9570503},{"bdatb":[[0,25,3.4]],"id":44621159}]}]}
{"op":"mcm","clk":"AJ6NAQCaSQDMfQ==","pt":1659347666751,"mc":[{"id":"1.201590187","rc":[{"atb":[[9.2,5.9]],"atl":[[11,1.4]],"id":43885158}]}]}
{"op":"mcm","clk":"AJ+NAQCbSQDMfQ==","pt":1659347666801,"mc":[{"id":"1.201590187","rc":[{"bdatb":[[8,9.6,22.6]],"id":45323444},{"bdatb":[[6,1.96,10.47],[8,1.94,18.81],[9,1.93,5.62]],"bdatl":[[8,2.36,1.85],[9,2.4,72.46]],"id":9570503},{"bdatb":[[9,5.4,2.85]],"id":12989514},{"bdatb":[[9,5.7,47.25]],"id":44836671},{"bdatb":[[0,9.2,5.9]],"bdatl":[[0,11,1.65]],"id":43885158}]}]}
{"op":"mcm","clk":"AKqNAQCeSQDWfQ==","pt":1659347666928,"mc":[{"id":"1.201590187","rc":[{"atb":[[2.02,25.87]],"id":9570503}]}]}
{"op":"mcm","clk":"AKqNAQCgSQDYfQ==","pt":1659347666978,"mc":[{"id":"1.201590187","rc":[{"bdatb":[[1,2.02,25.87]],"id":9570503}]}]}
{"op":"mcm","clk":"ALmNAQCiSQDkfQ==","pt":1659347667136,"mc":[{"id":"1.201590187","rc":[{"atb":[[25,1]],"id":44621159},{"atb":[[9.2,0.27]],"id":43885158}]}]}
{"op":"mcm","clk":"ALuNAQCiSQDkfQ==","pt":1659347667192,"mc":[{"id":"1.201590187","rc":[{"bdatl":[[5,2.3,1.14],[6,2.32,9.82],[7,2.36,6.05],[8,2.38,12.01],[9,2.4,73.89]],"id":9570503},{"bdatb":[[0,25,1.1]],"id":44621159},{"bdatb":[[0,9,2.3],[1,8.8,5.17],[2,8.6,9.06],[3,8.4,1.76],[4,8.2,1.76],[5,8,6.23],[6,7.8,2.73],[7,7.6,1.76],[8,7.4,10.23],[9,7.2,4.56]],"id":43885158}]}]}
{"op":"mcm","clk":"AM+NAQCrSQDtfQ==","pt":1659347667341,"mc":[{"id":"1.201590187","rc":[{"atb":[[9.2,0],[9,7.78]],"id":43885158}]}]}
{"op":"mcm","clk":"ANCNAQCrSQDyfQ==","pt":1659347667391,"mc":[{"id":"1.201590187","rc":[{"bdatl":[[7,2.34,6.09],[8,2.36,12.11],[9,2.38,2.48]],"id":9570503},{"bdatb":[[0,9,7.78]],"id":43885158}]}]}
{"op":"mcm","clk":"ANWNAQCrSQD0fQ==","pt":1659347667441,"mc":[{"id":"1.201590187","rc":[{"atb":[[8.8,51.72]],"id":46969227}]}]}
{"op":"mcm","clk":"ANmNAQCuSQD4fQ==","pt":1659347667539,"mc":[{"id":"1.201590187","rc":[{"atb":[[24,4.71]],"id":44621159}]}]}
{"op":"mcm","clk":"ANuNAQCvSQD6fQ==","pt":1659347667589,"mc":[{"id":"1.201590187","rc":[{"bdatb":[[1,24,4.71]],"id":44621159}]}]}
{"op":"mcm","clk":"AOSNAQCySQD/fQ==","pt":1659347667745,"mc":[{"id":"1.201590187","rc":[{"atb":[[9.4,54.1]],"id":45323444},{"atb":[[11,17.24]],"id":44621159},{"atb":[[8.8,34.48]],"id":46969227}]}]}
{"op":"mcm","clk":"AOaNAQCySQCFfg==","pt":1659347667795,"mc":[{"id":"1.201590187","rc":[{"bdatb":[[9,9.4,54.1]],"id":45323444}]}]}
{"op":"mcm","clk":"AIWOAQC/SQCefg==","pt":1659347668223,"mc":[{"id":"1.201590187","rc":[{"atb":[[24,2.29]],"id":44621159}]}]}
{"op":"mcm","clk":"AIWOAQC/SQCefg==","pt":1659347668283,"mc":[{"id":"1.201590187","rc":[{"bdatb":[[1,24,2.29]],"id":44621159}]}]}
{"op":"mcm","clk":"AIuOAQDASQCifg==","pt":1659347668333,"mc":[{"id":"1.201590187","rc":[{"atl":[[27,1.25]],"id":46969227}]}]}
{"op":"mcm","clk":"AI2OAQDASQCkfg==","pt":1659347668394,"mc":[{"id":"1.201590187","rc":[{"bdatl":[[1,27,1.25]],"id":46969227}]}]}
{"op":"mcm","clk":"AJSOAQDASQCnfg==","pt":1659347668444,"mc":[{"id":"1.201590187","rc":[{"atb":[[25,3.3]],"id":44621159},{"atb":[[9.2,4.04]],"id":43885158},{"atl":[[26,7.28]],"id":46969227}]}]}
{"op":"mcm","clk":"AJSOAQDBSQCqfg==","pt":1659347668494,"mc":[{"id":"1.201590187","rc":[{"bdatl":[[5,2.3,11.04],[6,2.32,5.07],[7,2.34,13.28],[8,2.36,2.5],[9,2.4,75.99]],"id":9570503},{"bdatb":[[0,25,3.4]],"id":44621159},{"bdatb":[[0,9.2,4.04],[1,9,7.78],[2,8.8,5.17],[3,8.6,9.06],[4,8.4,1.76],[5,8.2,1.76],[6,8,6.23],[7,7.8,2.73],[8,7.6,1.76],[9,7.4,10.23]],"id":43885158},{"bdatl":[[0,26,7.28]],"id":46969227}]}]}
{"op":"mcm","clk":"AKCOAQDCSQCxfg==","pt":1659347668546,"mc":[{"id":"1.201590187","rc":[{"atb":[[9.2,4.31]],"id":43885158},{"atl":[[32,0]],"id":46969227}]}]}
{"op":"mcm","clk":"AKOOAQDESQCzfg==","pt":1659347668618,"mc":[{"id":"1.201590187","rc":[{"bdatl":[[6,2.32,6.14],[7,2.34,12.21]],"id":9570503},{"bdatb":[[0,9.2,4.31]],"id":43885158},{"bdatl":[[5,34,5]],"id":46969227}]}]}
{"op":"mcm","clk":"ANqOAQDWSQDifg==","pt":1659347669233,"mc":[{"id":"1.201590187","rc":[{"atb":[[25,1]],"id":44621159},{"atb":[[9,2.03]],"id":43885158}]}]}
{"op":"mcm","clk":"AOGOAQDWSQDrfg==","pt":1659347669283,"mc":[{"id":"1.201590187","rc":[{"bdatl":[[7,2.36,7.75],[8,2.38,6.8],[9,2.4,71.81]],"id":9570503},{"bdatb":[[0,25,1.1]],"id":44621159},{"bdatb":[[1,9,2.03]],"id":43885158}]}]}
{"op":"mcm","clk":"APCOAQDeSQD4fg==","pt":1659347669443,"mc":[{"id":"1.201590187","rc":[{"atb":[[9.4,5.52]],"id":43885158}]}]}
{"op":"mcm","clk":"APCOAQDfSQD7fg==","pt":1659347669493,"mc":[{"id":"1.201590187","rc":[{"bdatl":[[5,2.28,11.14],[6,2.32,6.15],[7,2.34,12.21],[8,2.36,2.5],[9,2.4,74.98]],"id":9570503},{"bdatb":[[0,9.4,5.52],[1,9.2,4.31],[2,9,2.03],[3,8.8,5.17],[4,8.6,9.06],[5,8.4,1.76],[6,8.2,1.76],[7,8,6.23],[8,7.8,2.73],[9,7.6,1.76]],"id":43885158}]}]}
{"op":"mcm","clk":"AP6OAQDmSQCFfw==","pt":1659347669650,"mc":[{"id":"1.201590187","rc":[{"atb":[[24,4.71]],"id":44621159},{"atb":[[9.4,5.78]],"id":43885158}]}]}
{"op":"mcm","clk":"AP6OAQDqSQCJfw==","pt":1659347669700,"mc":[{"id":"1.201590187","rc":[{"bdatl":[[9,2.4,79.69]],"id":9570503},{"bdatb":[[1,24,4.71]],"id":44621159},{"bdatb":[[0,9.4,5.78]],"id":43885158}]}]}
{"op":"mcm","clk":"AI6PAQDzSQCbfw==","pt":1659347669956,"mc":[{"id":"1.201590187","rc":[{"atl":[[24,0.48]],"id":45323444},{"atb":[[8.6,4.53]],"id":43885158},{"atl":[[27,5.1]],"id":46969227}]}]}
{"op":"mcm","clk":"AI+PAQD2SQCdfw==","pt":1659347670006,"mc":[{"id":"1.201590187","rc":[{"bdatl":[[7,25,4.65],[8,26,5.04],[9,27,3.85]],"id":45323444},{"bdatb":[[4,8.6,4.53]],"id":43885158},{"bdatl":[[1,27,5.1]],"id":46969227}]}]}
{"op":"mcm","clk":"AJaPAQD2SQCffw==","pt":1659347670056,"mc":[{"id":"1.201590187","rc":[{"atl":[[23,3.2]],"bdatl":[[6,23,3.2]],"id":45323444},{"atb":[[9.2,8.84]],"bdatb":[[1,9.2,8.84]],"id":43885158},{"atl":[[28,7.64]],"bdatl":[[2,28,7.64]],"id":46969227},{"bdatl":[[9,2.4,93.34]],"id":9570503}]}]}
{"op":"mcm","clk":"AKuPAQCGSgC4fw==","pt":1659347670437,"mc":[{"id":"1.201590187","rc":[{"atb":[[24,2.29]],"id":44621159}]}]}
{"op":"mcm","clk":"AKuPAQCGSgC4fw==","pt":1659347670494,"mc":[{"id":"1.201590187","rc":[{"bdatl":[[9,2.4,74.98]],"id":9570503},{"bdatb":[[1,24,2.29]],"id":44621159}]}]}
{"op":"mcm","clk":"ALSPAQCLSgDFfw==","pt":1659347670641,"mc":[{"id":"1.201590187","rc":[{"atb":[[2.02,22.1]],"atl":[[2.14,77.77]],"id":9570503},{"atb":[[6.4,7.86]],"atl":[[7.4,10.55]],"id":12989514},{"atb":[[25,3.3]],"id":44621159},{"atb":[[7,15.98]],"atl":[[8,7.34]],"id":44836671},{"atb":[[8.6,2.18],[8,3.83]],"id":43885158}]}]}
{"op":"mcm","clk":"ALWPAQCNSgDLfw==","pt":1659347670710,"mc":[{"id":"1.201590187","rc":[{"bdatb":[[1,2.02,22.1]],"bdatl":[[0,2.14,77.77],[6,2.3,6.2],[7,2.32,6.31],[8,2.34,8.48],[9,2.4,92.78]],"id":9570503},{"bdatb":[[1,6.4,7.86]],"bdatl":[[2,7.4,10.55]],"id":12989514},{"bdatb":[[0,25,3.4]],"id":44621159},{"bdatb":[[1,7,15.98]],"bdatl":[[1,8,7.68]],"id":44836671},{"bdatb":[[4,8.6,2.18],[7,8,3.83]],"id":43885158}]}]}
{"op":"mcm","clk":"ALuPAQCPSgDQfw==","pt":1659347670760,"mc":[{"id":"1.201590187","rc":[{"atl":[[2.16,5.18]],"id":9570503}]}]}
{"op":"mcm","clk":"ALuPAQCPSgDVfw==","pt":1659347670810,"mc":[{"id":"1.201590187","rc":[{"bdatl":[[1,2.16,5.18]],"id":9570503}]}]}
{"op":"mcm","clk":"AMWPAQCQSgDefw==","pt":1659347670952,"mc":[{"id":"1.201590187","rc":[{"atb":[[6.6,0.37]],"id":12989514}]}]}
{"op":"mcm","clk":"AMePAQCQSgDkfw==","pt":1659347671002,"mc":[{"id":"1.201590187","rc":[{"bdatl":[[5,2.28,1.07],[6,2.32,9.9],[7,2.34,11.69],[8,2.38,6.5],[9,2.4,73.89]],"id":9570503},{"bdatb":[[0,6.4,8.23],[1,6.2,13.94],[2,6,2],[3,5.9,1.76],[4,5.8,1.76],[5,5.7,1.76],[6,5.6,1.76],[7,5.5,2.24],[8,5.4,2.85],[9,5.3,1.76]],"id":12989514}]}]}
{"op":"mcm","clk":"AM2PAQCRSgDnfw==","pt":1659347671060,"mc":[{"id":"1.201590187","rc":[{"atb":[[6.4,18.86]],"id":12989514},{"atl":[[16,1.76]],"id":43885158}]}]}
{"op":"mcm","clk":"ANCPAQCRSgDsfw==","pt":1659347671110,"mc":[{"id":"1.201590187","rc":[{"bdatl":[[7,2.34,12.35],[8,2.36,5.91],[9,2.38,2.48]],"id":9570503},{"bdatb":[[0,6.4,19.23]],"id":12989514}]}]}
{"op":"mcm","clk":"ANOPAQCTSgDwfw==","pt":1659347671160,"mc":[{"id":"1.201590187","rc":[{"atb":[[6.6,0]],"id":12989514}]}]}
{"op":"mcm","clk":"ANePAQCVSgDyfw==","pt":1659347671210,"mc":[{"id":"1.201590187","rc":[{"bdatl":[[5,2.3,1.14],[6,2.32,9.82]],"id":9570503},{"bdatb":[[0,6.4,18.86]],"id":12989514}]}]}
{"op":"mcm","clk":"ANqPAQCWSgD1fw==","pt":1659347671260,"mc":[{"id":"1.201590187","rc":[{"atl":[[7.6,0.34],[6.8,6]],"id":12989514},{"atb":[[26,1.1]],"atl":[[38,0.87]],"id":44621159}]}]}
{"op":"mcm","clk":"ANuPAQCWSgD2fw==","pt":1659347671310,"mc":[{"id":"1.201590187","rc":[{"bdatb":[[5,10.5,2.01],[6,10,11.54],[8,9.6,23.37]],"id":45323444},{"bdatb":[[3,1.99,3.08],[4,1.98,36.93],[5,1.97,10.34],[6,1.96,10.27],[7,1.95,5.76],[8,1.94,7.07],[9,1.93,1.76]],"bdatl":[[5,2.3,11.04],[6,2.32,1.39],[7,2.34,10.97]],"id":9570503},{"bdatl":[[0,6.8,6],[1,7,8.36],[2,7.2,6.35],[3,7.4,10.55],[4,7.8,4.86]],"id":12989514},{"bdatb":[[0,26,1.1],[1,25,3.3],[2,24,2.29],[3,23,4.55],[4,22,1.76],[5,21,5],[6,20,1.76],[7,19.5,1.76],[8,19,1.76],[9,18.5,1.37]],"bdatl":[[0,40,4.14],[1,80,2.96],[2,170,2],[3,900,1.14],[4,990,1.83],[5,1000,2],[6,0,0]],"id":44621159},{"bdatb":[[6,6,30.18],[7,5.9,11.61],[9,5.7,48.54]],"id":44836671},{"bdatb":[[9,7.6,7.13]],"id":43885158}]}]}
{"op":"mcm","clk":"AN+PAQCXSgD6fw==","pt":1659347671360,"mc":[{"id":"1.201590187","rc":[{"atl":[[2.16,10.18]],"id":9570503},{"atl":[[38,1.87]],"id":44621159}]}]}
{"op":"mcm","clk":"AOGPAQCYSgD+fw==","pt":1659347671411,"mc":[{"id":"1.201590187","rc":[{"bdatb":[[6,1.96,14.24],[7,1.95,1.76],[9,1.93,8.8]],"bdatl":[[1,2.16,10.18]],"id":9570503},{"bdatl":[[0,38,1.87],[1,40,3.27],[2,80,2.96],[3,170,2],[4,900,1.14],[5,990,1.83],[6,1000,2]],"id":44621159}]}]}
{"op":"mcm","clk":"AOmPAQCZSgCCgAE=","pt":1659347671461,"mc":[{"id":"1.201590187","rc":[{"atb":[[6.2,14.33]],"atl":[[7.8,4.19],[6.8,6.37]],"id":12989514},{"atb":[[25,2.3]],"id":44621159}]}]}
{"op":"mcm","clk":"AOyPAQCeSgCEgAE=","pt":1659347671524,"mc":[{"id":"1.201590187","rc":[{"bdatb":[[8,9.6,23.64]],"id":45323444},{"bdatb":[[6,1.96,15.52],[8,1.94,5.77]],"id":9570503},{"bdatb":[[1,6.2,14.33]],"bdatl":[[0,6.8,6.37],[4,7.8,4.53]],"id":12989514},{"bdatb":[[1,25,2.3]],"id":44621159},{"bdatb":[[9,5.7,48.98]],"id":44836671},{"bdatb":[[9,7.6,7.46]],"id":43885158}]}]}
{"op":"mcm","clk":"AIiQAQCtSgClgAE=","pt":1659347671941,"mc":[{"id":"1.201590187","rc":[{"atb":[[2.04,6.94]],"trd":[[2.04,75.98]],"ltp":2.04,"tv":928.69,"id":9570503}],"tv":1477.31}]}
{"op":"mcm","clk":"AIqQAQCtSgCngAE=","pt":1659347671991,"mc":[{"id":"1.201590187","rc":[{"bdatb":[[0,2.04,6.94]],"id":9570503}]}]}
{"op":"mcm","clk":"AI6QAQCvSgCpgAE=","pt":1659347672041,"mc":[{"id":"1.201590187","rc":[{"atb":[[25,0]],"id":44621159}]}]}
{"op":"mcm","clk":"AJOQAQCvSgCtgAE=","pt":1659347672091,"mc":[{"id":"1.201590187","rc":[{"bdatl":[[7,2.34,4.72],[8,2.36,6.2],[9,2.38,8.34]],"id":9570503},{"bdatb":[[1,24,2.29],[2,23,4.55],[3,22,1.76],[4,21,5],[5,20,1.76],[6,19.5,1.76],[7,19,1.76],[8,18.5,1.37],[9,15.5,5.35]],"id":44621159}]}]}
{"op":"mcm","clk":"AKSQAQC1SgC0gAE=","pt":1659347672253,"mc":[{"id":"1.201590187","rc":[{"atb":[[6.2,8.66]],"id":12989514},{"atb":[[26,3.28],[11,34.48]],"id":44621159}]}]}
{"op":"mcm","clk":"AKeQAQC4SgC4gAE=","pt":1659347672303,"mc":[{"id":"1.201590187","rc":[{"bdatl":[[6,2.32,6.15],[7,2.34,6.26],[8,2.36,8.41],[9,2.38,4.73]],"id":9570503},{"bdatb":[[1,6.2,8.66]],"id":12989514},{"bdatb":[[0,26,3.28]],"id":44621159}]}]}
{"op":"mcm","clk":"ALSQAQC8SgDAgAE=","pt":1659347672469,"mc":[{"id":"1.201590187","rc":[{"atb":[[5.7,223.76]],"id":12989514}]}]}
{"op":"mcm","clk":"ALeQAQC9SgDEgAE=","pt":1659347672519,"mc":[{"id":"1.201590187","rc":[{"bdatb":[[5,5.7,223.76]],"id":12989514}]}]}
{"op":"mcm","clk":"AL2QAQC9SgDHgAE=","pt":1659347672569,"mc":[{"id":"1.201590187","rc":[{"atb":[[8.8,48.84]],"id":46969227}]}]}
{"op":"mcm","clk":"ANiQAQDJSgDcgAE=","pt":1659347672932,"mc":[{"id":"1.201590187","rc":[{"atb":[[6.2,11.06],[6.4,16.38]],"atl":[[7.4,8.34],[7.2,8.68]],"id":12989514},{"atb":[[7,15.88]],"atl":[[8,7.43]],"id":44836671},{"atb":[[9,4.34],[8.6,0],[8,1.46]],"id":43885158}]}]}
{"op":"mcm","clk":"ANiQAQDJSgDhgAE=","pt":1659347672982,"mc":[{"id":"1.201590187","rc":[{"bdatb":[[0,6.4,16.38],[1,6.2,11.06]],"bdatl":[[2,7.2,8.68],[3,7.4,8.34]],"id":12989514},{"bdatb":[[1,7,15.88]],"bdatl":[[1,8,7.77]],"id":44836671},{"bdatb":[[2,9,4.34],[4,8.4,1.76],[5,8.2,1.76],[6,8,1.46],[7,7.8,2.73],[8,7.6,7.46],[9,7.4,5.21]],"id":43885158}]}]}
{"op":"mcm","clk":"AOCQAQDLSgDkgAE=","pt":1659347673033,"mc":[{"id":"1.201590187","rc":[{"atb":[[26,1.1]],"id":44621159}]}]}
{"op":"mcm","clk":"AOCQAQDLSgDkgAE=","pt":1659347673083,"mc":[{"id":"1.201590187","rc":[{"bdatl":[[6,2.32,1.39],[7,2.34,4.72],[8,2.36,6.2],[9,2.38,8.34]],"id":9570503},{"bdatb":[[0,26,1.1]],"id":44621159}]}]}
{"op":"mcm","clk":"AOiQAQDPSgDtgAE=","pt":1659347673142,"mc":[{"id":"1.201590187","rc":[{"atb":[[24,4.71]],"id":44621159},{"atb":[[9.6,1.15]],"atl":[[11,2.55]],"id":43885158}]}]}
{"op":"mcm","clk":"AOiQAQDPSgDygAE=","pt":1659347673192,"mc":[{"id":"1.201590187","rc":[{"bdatb":[[6,10,12.8],[8,9.6,22.32]],"id":45323444},{"bdatb":[[5,1.97,16.76],[6,1.96,9.07],[8,1.94,12.28],[9,1.93,2.25]],"bdatl":[[8,2.36,10.88],[9,2.38,3.7]],"id":9570503},{"bdatb":[[8,5.4,5.19]],"id":12989514},{"bdatb":[[1,24,4.71],[9,15.5,6.16]],"id":44621159},{"bdatb":[[7,5.9,13.75],[9,5.7,46.77]],"id":44836671},{"bdatb":[[0,9.6,1.15],[1,9.4,5.78],[2,9.2,8.84],[3,9,4.34],[4,8.8,5.17],[5,8.4,1.76],[6,8.2,1.76],[7,8,1.46],[8,7.8,2.73],[9,7.6,7.46]],"bdatl":[[0,11,2.8]],"id":43885158}]}]}
{"op":"mcm","clk":"APGQAQDSSgD1gAE=","pt":1659347673244,"mc":[{"id":"1.201590187","rc":[{"atb":[[9.6,1.41]],"id":43885158}]}]}
{"op":"mcm","clk":"APGQAQDSSgD2gAE=","pt":1659347673296,"mc":[{"id":"1.201590187","rc":[{"bdatl":[[8,2.36,11.93],[9,2.38,2.65]],"id":9570503},{"bdatb":[[0,9.6,1.41]],"id":43885158}]}]}
{"op":"mcm","clk":"AKCRAQDlSgCagQE=","pt":1659347673922,"mc":[{"id":"1.201590187","rc":[{"atb":[[24,2.29]],"id":44621159}]}]}
{"op":"mcm","clk":"AKCRAQDlSgCdgQE=","pt":1659347673989,"mc":[{"id":"1.201590187","rc":[{"bdatb":[[1,24,2.29]],"id":44621159}]}]}
{"op":"mcm","clk":"AKeRAQDmSgCjgQE=","pt":1659347674039,"mc":[{"id":"1.201590187","rc":[{"atb":[[25,2.3]],"id":44621159}]}]}
{"op":"mcm","clk":"AKeRAQDmSgClgQE=","pt":1659347674089,"mc":[{"id":"1.201590187","rc":[{"bdatl":[[7,2.34,16.76],[8,2.38,2.65],[9,2.4,84.22]],"id":9570503},{"bdatb":[[1,25,2.3],[2,24,2.29],[3,23,4.55],[4,22,1.76],[5,21,5],[6,20,1.76],[7,19.5,1.76],[8,19,1.76],[9,18.5,1.37]],"id":44621159}]}]}
{"op":"mcm","clk":"AMSRAQD1SgC+gQE=","pt":1659347674452,"mc":[{"id":"1.201590187","rc":[{"atb":[[8.6,1.76]],"id":43885158}]}]}
{"op":"mcm","clk":"AMSRAQD1SgDBgQE=","pt":1659347674502,"mc":[{"id":"1.201590187","rc":[{"bdatb":[[5,8.6,1.76],[6,8.4,1.76],[7,8.2,1.76],[8,8,1.46],[9,7.8,2.73]],"id":43885158}]}]}
{"op":"mcm","clk":"AOCRAQCGSwDQgQE=","pt":1659347674861,"mc":[{"id":"1.201590187","rc":[{"atl":[[2.14,82.77]],"id":9570503},{"atb":[[25,0]],"id":44621159}]}]}
{"op":"mcm","clk":"AOSRAQCISwDVgQE=","pt":1659347674911,"mc":[{"id":"1.201590187","rc":[{"bdatl":[[0,2.14,82.77],[7,2.34,4.72],[8,2.36,11.93],[9,2.38,2.65]],"id":9570503},{"bdatb":[[1,24,2.29],[2,23,4.55],[3,22,1.76],[4,21,5],[5,20,1.76],[6,19.5,1.76],[7,19,1.76],[8,18.5,1.37],[9,15.5,6.16]],"id":44621159}]}]}
{"op":"mcm","clk":"AOqRAQCMSwDXgQE=","pt":1659347674961,"mc":[{"id":"1.201590187","rc":[{"atb":[[6.4,11.38]],"id":12989514},{"atl":[[13,50.75],[11.5,16.03]],"id":44836671},{"atb":[[9.2,4.8]],"id":43885158}]}]}
{"op":"mcm","clk":"AO2RAQCNSwDbgQE=","pt":1659347675016,"mc":[{"id":"1.201590187","rc":[{"bdatl":[[9,2.38,2.1]],"id":9570503},{"bdatb":[[0,6.4,11.38]],"id":12989514},{"bdatb":[[2,9.2,4.8]],"id":43885158}]}]}
{"op":"mcm","clk":"APKRAQCQSwDdgQE=","pt":1659347675066,"mc":[{"id":"1.201590187","rc":[{"atb":[[2.02,26.17]],"atl":[[2.14,86.39]],"id":9570503},{"atb":[[6.2,16.33]],"atl":[[7.2,11.11]],"id":12989514},{"atb":[[24,4.71]],"atl":[[1000,0]],"id":44621159},{"atb":[[7,18.11]],"atl":[[8,9.69]],"id":44836671},{"atb":[[9,6.53]],"id":43885158}]}]}
{"op":"mcm","clk":"APORAQCSSwDggQE=","pt":1659347675116,"mc":[{"id":"1.201590187","rc":[{"bdatb":[[1,2.02,26.17]],"bdatl":[[0,2.14,86.39]],"id":9570503},{"bdatb":[[1,6.2,16.33]],"bdatl":[[2,7.2,11.11]],"id":12989514},{"bdatb":[[1,24,4.71]],"bdatl":[[6,0,0]],"id":44621159},{"bdatb":[[1,7,18.11]],"bdatl":[[1,8,10.03]],"id":44836671},{"bdatb":[[3,9,6.53]],"id":43885158}]}]}
{"op":"mcm","clk":"APeRAQCWSwDkgQE=","pt":1659347675166,"mc":[{"id":"1.201590187","rc":[{"atb":[[2.02,28.85]],"id":9570503},{"atb":[[6,4.34],[6.2,12.69]],"id":12989514},{"atb":[[24,7],[23,0]],"id":44621159}]}]}
{"op":"mcm","clk":"APqRAQCYSwDngQE=","pt":1659347675216,"mc":[{"id":"1.201590187","rc":[{"bdatb":[[1,2.02,28.85]],"id":9570503},{"bdatb":[[1,6.2,12.69],[2,6,4.34]],"id":12989514},{"bdatb":[[1,24,7],[2,22,1.76],[3,21,5],[4,20,1.76],[5,19.5,1.76],[6,19,1.76],[7,18.5,1.37],[8,15.5,6.16],[9,13.5,8.94]],"id":44621159}]}]}
{"op":"mcm","clk":"AICSAQCbSwDugQE=","pt":1659347675266,"mc":[{"id":"1.201590187","rc":[{"atb":[[6,229.74]],"id":44836671}]}]}
{"op":"mcm","clk":"AICSAQCeSwDugQE=","pt":1659347675316,"mc":[{"id":"1.201590187","rc":[{"bdatb":[[6,6,230.18]],"id":44836671}]}]}
{"op":"mcm","clk":"AIeSAQCfSwD2gQE=","pt":1659347675366,"mc":[{"id":"1.201590187","rc":[{"atb":[[4.9,0]],"id":44836671}]}]}
{"op":"mcm","clk":"AI6SAQCiSwD8gQE=","pt":1659347675447,"mc":[{"id":"1.201590187","rc":[{"atb":[[4.4,53.53]],"id":44836671}]}]}
{"op":"mcm","clk":"ALGSAQCvSwCYggE=","pt":1659347675945,"mc":[{"id":"1.201590187","rc":[{"atb":[[12,0]],"id":45323444},{"atb":[[24,5.2]],"id":44621159}]}]}
{"op":"mcm","clk":"ALOSAQCySwCbggE=","pt":1659347675995,"mc":[{"id":"1.201590187","rc":[{"bdatb":[[2,11.5,7.77],[3,11,1.23],[4,10.5,2.01],[5,10,12.8],[6,9.8,9],[7,9.6,22.32],[8,9.4,54.1],[9,9.2,14.22]],"id":45323444},{"bdatl":[[8,2.38,11.83],[9,2.4,73.52]],"id":9570503},{"bdatb":[[1,24,5.2]],"id":44621159}]}]}
{"op":"mcm","clk":"ALiSAQCySwCcggE=","pt":1659347676050,"mc":[{"id":"1.201590187","rc":[{"atb":[[10,12.87]],"id":45323444},{"atb":[[20,3.56]],"id":44621159}]}]}
{"op":"mcm","clk":"ALqSAQC0SwCeggE=","pt":1659347676100,"mc":[{"id":"1.201590187","rc":[{"bdatb":[[5,10,15.68]],"id":45323444},{"bdatb":[[4,20,3.56]],"id":44621159}]}]}
{"op":"mcm","clk":"AMeSAQC7SwCqggE=","pt":1659347676355,"mc":[{"id":"1.201590187","rc":[{"atb":[[24,2.78]],"id":44621159}]}]}
{"op":"mcm","clk":"AMqSAQC9SwCsggE=","pt":1659347676405,"mc":[{"id":"1.201590187","rc":[{"bdatb":[[1,24,2.78]],"id":44621159}]}]}
{"op":"mcm","clk":"AMySAQC9SwCxggE=","pt":1659347676461,"mc":[{"id":"1.201590187","rc":[{"atb":[[13,0.19]],"id":45323444},{"atb":[[25,2.3]],"id":44621159}]}]}
{"op":"mcm","clk":"AM+SAQDASwCyggE=","pt":1659347676512,"mc":[{"id":"1.201590187","rc":[{"bdatb":[[0,12.5,1.33],[1,11.5,7.77],[2,11,1.23],[3,10.5,2.01],[4,10,15.68],[5,9.8,9],[6,9.6,22.32],[7,9.4,54.1],[8,9.2,14.22],[9,9,13.81]],"id":45323444},{"bdatl":[[5,2.3,1.07],[6,2.32,6.15],[7,2.36,21.65],[8,2.4,73.52],[9,2.42,5.47]],"id":9570503},{"bdatb":[[1,25,2.3],[2,24,2.78],[3,22,1.76],[4,21,5],[5,20,3.56],[6,19.5,1.76],[7,19,1.76],[8,18.5,1.37],[9,15.5,6.16]],"id":44621159}]}]}
{"op":"mcm","clk":"ANSSAQDCSwC2ggE=","pt":1659347676566,"mc":[{"id":"1.201590187","rc":[{"atb":[[5.8,35.31]],"id":12989514},{"atb":[[9.4,0],[9.6,0]],"atl":[[9.4,7.81]],"trd":[[9.4,91.77],[9.6,5.54]],"ltp":9.4,"tv":167.89,"id":43885158}],"tv":1491.68}]}
{"op":"mcm","clk":"ANeSAQDFSwC5ggE=","pt":1659347676617,"mc":[{"id":"1.201590187","rc":[{"bdatb":[[1,12,3.61],[2,11.5,7.77],[3,11,3.96],[4,10.5,1.76],[5,10,13.14],[6,9.8,9],[7,9.6,23.69],[8,9.4,54.1],[9,9.2,12.24]],"id":45323444},{"bdatb":[[0,2.04,28.17],[1,2.02,39.42],[3,1.99,6.16],[5,1.97,2.53],[6,1.96,2.62],[7,1.95,3.11],[8,1.94,1.76],[9,1.93,12.78]],"bdatl":[[5,2.32,1.06],[6,2.34,6.09],[7,2.38,11.54],[8,2.4,83.36],[9,2.44,164.44]],"id":9570503},{"bdatb":[[3,5.9,12.72],[4,5.8,35.31],[6,5.6,3.33],[7,5.5,1.76],[8,5.3,2.26],[9,5.1,5.5]],"id":12989514},{"bdatb":[[5,20,5.73],[8,18.5,2.53],[9,15.5,4.72]],"id":44621159},{"bdatb":[[4,6.4,8.53],[5,6.2,29.23],[6,6,231.2],[7,5.9,9],[9,5.7,44.55]],"id":44836671},{"bdatb":[[0,9.2,4.8],[1,9,6.53],[2,8.8,5.17],[3,8.6,1.76],[4,8.4,1.76],[5,8.2,1.76],[6,8,1.46],[7,7.8,2.73],[8,7.6,7.46],[9,7.4,5.21]],"bdatl":[[0,9.4,7.81],[1,11,2.8],[2,11.5,2.88],[3,12,6.99],[4,12.5,13.48],[5,13,1.76],[6,13.5,9.76],[7,14,13.2],[8,14.5,13.87],[9,15,12]],"id":43885158},{"bdatb":[[9,16,4.13]],"id":46969227}]}]}
{"op":"mcm","clk":"AN+SAQDFSwC/ggE=","pt":1659347676669,"mc":[{"id":"1.201590187","rc":[{"atb":[[13,0]],"bdatb":[[0,12.5,1.14]],"id":45323444},{"bdatl":[[5,2.34,6.09],[6,2.38,12.58],[7,2.4,83.36],[8,2.44,164.44],[9,2.48,5.69]],"id":9570503}]}]}
{"op":"mcm","clk":"AOSSAQDISwDBggE=","pt":1659347676731,"mc":[{"id":"1.201590187","rc":[{"atb":[[12.5,1.33]],"id":45323444},{"atb":[[9.2,0]],"atl":[[9.4,0.01]],"trd":[[9.4,107.37],[9.2,49.36]],"tv":193.09,"id":43885158}],"tv":1516.88}]}
{"op":"mcm","clk":"AOSSAQDISwDFggE=","pt":1659347676781,"mc":[{"id":"1.201590187","rc":[{"bdatb":[[0,12.5,1.33],[1,11.5,7.78],[2,11,1.23],[3,10.5,2.01],[4,10,15.68],[5,9.8,9],[6,9.6,22.31],[7,9.4,54.1],[8,9.2,14.23],[9,9,13.8]],"id":45323444},{"bdatb":[[0,2.04,6.99],[1,2.02,28.85],[3,1.99,3.08],[5,1.97,16.76],[6,1.96,9.03],[7,1.95,1.76],[8,1.94,12.33],[9,1.93,2.2]],"bdatl":[[5,2.34,7.11],[6,2.38,5.04],[7,2.4,83.99],[8,2.42,5.81],[9,2.44,152.09]],"id":9570503},{"bdatb":[[3,5.9,1.78],[6,5.6,1.76],[7,5.5,2.24],[8,5.4,5.19],[9,5.3,1.76]],"id":12989514},{"bdatb":[[5,20,3.57],[8,18.5,1.37],[9,15.5,6.16]],"id":44621159},{"bdatb":[[4,6.4,1.78],[5,6.2,25.79],[6,6,230.18],[7,5.9,13.75],[9,5.7,46.75]],"id":44836671},{"bdatb":[[0,9,6.53],[1,8.8,5.17],[2,8.6,1.76],[3,8.4,1.76],[4,8.2,1.76],[5,8,1.46],[6,7.8,2.73],[7,7.6,7.46],[8,7.4,5.21],[9,7.2,3.71]],"bdatl":[[0,11,2.81],[1,11.5,2.88],[2,12,6.99],[3,12.5,13.48],[4,13,1.76],[5,13.5,9.76],[6,14,13.2],[7,14.5,13.87],[8,15,12],[9,15.5,20]],"id":43885158},{"bdatb":[[9,16,1.43]],"id":46969227}]}]}
{"op":"mcm","clk":"AOySAQDMSwDLggE=","pt":1659347676843,"mc":[{"id":"1.201590187","rc":[{"atb":[[12.5,1.14]],"id":45323444},{"atb":[[9,6.26]],"id":43885158}]}]}
{"op":"mcm","clk":"AOySAQDMSwDQggE=","pt":1659347676893,"mc":[{"id":"1.201590187","rc":[{"bdatb":[[0,12.5,1.14]],"id":45323444},{"bdatl":[[5,2.34,6.09],[6,2.38,6.03],[7,2.4,82.98],[8,2.42,6.82]],"id":9570503},{"bdatb":[[0,9,6.26]],"id":43885158}]}]}
{"op":"mcm","clk":"APKSAQDPSwDTggE=","pt":1659347676943,"mc":[{"id":"1.201590187","rc":[{"atb":[[8.8,4.9]],"id":43885158}]}]}
{"op":"mcm","clk":"APKSAQDRSwDWggE=","pt":1659347676993,"mc":[{"id":"1.201590187","rc":[{"bdatb":[[1,8.8,4.9]],"id":43885158}]}]}
{"op":"mcm","clk":"APySAQDUSwDZggE=","pt":1659347677045,"mc":[{"id":"1.201590187","rc":[{"atb":[[13,1.76]],"id":45323444},{"atb":[[2.06,1.76]],"id":9570503},{"atb":[[5.4,1.76]],"id":12989514},{"atb":[[23,1.76]],"id":44621159}]}]}
{"op":"mcm","clk":"APySAQDUSwDbggE=","pt":1659347677096,"mc":[{"id":"1.201590187","rc":[{"bdatb":[[0,13,1.76],[1,12.5,1.14],[2,11.5,7.78],[3,11,1.23],[4,10.5,2.01],[5,10,15.68],[6,9.8,9],[7,9.6,22.31],[8,9.4,54.1],[9,9.2,14.23]],"id":45323444},{"bdatb":[[0,2.06,1.76],[1,2.04,6.99],[2,2.02,28.85],[3,2,11.07],[4,1.99,3.08],[5,1.98,36.93],[6,1.97,16.76],[7,1.96,9.03],[8,1.95,1.76],[9,1.94,12.33]],"bdatl":[[5,2.34,12.23],[6,2.36,3.63],[7,2.4,79.41]],"id":9570503},{"bdatb":[[8,5.4,6.96]],"id":12989514},{"bdatb":[[3,23,1.76],[4,22,1.76],[5,21,5],[6,20,3.57],[7,19.5,1.76],[8,19,1.76],[9,18.5,1.37]],"id":44621159}]}]}
{"op":"mcm","clk":"AP+SAQDXSwDfggE=","pt":1659347677147,"mc":[{"id":"1.201590187","rc":[{"atb":[[10.5,4.98]],"id":45323444},{"atl":[[7,11.92]],"id":12989514},{"atl":[[7.8,3.17],[8,14.64]],"id":44836671},{"atb":[[9,4.5]],"id":43885158}]}]}
{"op":"mcm","clk":"AP+SAQDXSwDhggE=","pt":1659347677197,"mc":[{"id":"1.201590187","rc":[{"bdatb":[[4,10.5,5.23]],"id":45323444},{"bdatl":[[7,2.4,72.79],[8,2.42,13.38]],"id":9570503},{"bdatl":[[1,7,11.92]],"id":12989514},{"bdatl":[[1,7.8,3.17],[2,8,14.64],[3,8.2,2.07],[4,8.4,3],[5,8.6,1.76],[6,8.8,1.76],[7,9,1.76],[8,9.2,8],[9,9.4,1.76]],"id":44836671},{"bdatb":[[0,9,4.5]],"id":43885158}]}]}
{"op":"mcm","clk":"AISTAQDZSwDlggE=","pt":1659347677248,"mc":[{"id":"1.201590187","rc":[{"atb":[[11.5,5.54]],"id":45323444},{"atb":[[9,2.31]],"id":43885158}]}]}
{"op":"mcm","clk":"AIaTAQDcSwDpggE=","pt":1659347677298,"mc":[{"id":"1.201590187","rc":[{"bdatb":[[2,11.5,5.55]],"id":45323444},{"bdatl":[[5,2.34,9.8],[6,2.36,2.41],[7,2.38,3.6],[8,2.4,71.43],[9,2.42,12.83]],"id":9570503},{"bdatb":[[0,9,2.31]],"id":43885158}]}]}
{"op":"mcm","clk":"AI2TAQDdSwDsggE=","pt":1659347677351,"mc":[{"id":"1.201590187","rc":[{"atb":[[1.02,0]],"id":45323444},{"atb":[[9,0]],"id":43885158}]}]}
{"op":"mcm","clk":"AI2TAQDeSwDuggE=","pt":1659347677401,"mc":[{"id":"1.201590187","rc":[{"bdatl":[[9,2.42,8.7]],"id":9570503},{"bdatb":[[0,8.8,4.9],[1,8.6,1.76],[2,8.4,1.76],[3,8.2,1.76],[4,8,1.46],[5,7.8,2.73],[6,7.6,7.46],[7,7.4,5.21],[8,7.2,3.71],[9,7,138.87]],"id":43885158}]}]}
{"op":"mcm","clk":"AJKTAQDfSwDwggE=","pt":1659347677452,"mc":[{"id":"1.201590187","rc":[{"atb":[[12,1.6]],"atl":[[22,0.82],[21,3.89]],"id":45323444},{"atl":[[2.16,5.18],[2.24,6]],"id":9570503},{"atl":[[12,3.28],[11.5,9.87]],"id":43885158},{"atl":[[27,1.25],[32,3.23]],"id":46969227}]}]}
{"op":"mcm","clk":"AJOTAQDlSwDzggE=","pt":1659347677502,"mc":[{"id":"1.201590187","rc":[{"bdatb":[[2,12,1.61],[3,11.5,5.54],[4,11,1.23],[5,10.5,5.23],[6,10,15.68],[7,9.8,9],[8,9.6,22.31],[9,9.4,54.1]],"bdatl":[[4,21,3.89],[5,23,4.02],[6,25,4.65],[7,26,5.04],[8,27,3.85],[9,29,8.93]],"id":45323444},{"bdatb":[[9,1.94,12.77]],"bdatl":[[1,2.16,5.18],[5,2.24,6],[6,2.34,9.8],[7,2.36,2.41],[8,2.38,6.08],[9,2.4,76.98]],"id":9570503},{"bdatl":[[1,11.5,9.87],[2,12,3.28]],"id":43885158},{"bdatl":[[1,27,1.25],[5,32,3.23],[6,34,5],[7,36,1.76],[8,38,1.76],[9,40,5.01]],"id":46969227}]}]}
{"op":"mcm","clk":"AJ2TAQDoSwD/ggE=","pt":1659347677658,"mc":[{"id":"1.201590187","rc":[{"atb":[[25,0]],"id":44621159}]}]}
{"op":"mcm","clk":"AKCTAQDpSwCCgwE=","pt":1659347677708,"mc":[{"id":"1.201590187","rc":[{"bdatl":[[8,2.38,3.6],[9,2.4,73.89]],"id":9570503},{"bdatb":[[1,24,2.78],[2,23,1.76],[3,22,1.76],[4,21,5],[5,20,3.57],[6,19.5,1.76],[7,19,1.76],[8,18.5,1.37],[9,15.5,6.16]],"id":44621159}]}]}
{"op":"mcm","clk":"AKSTAQDqSwCEgwE=","pt":1659347677763,"mc":[{"id":"1.201590187","rc":[{"atb":[[13,0]],"id":45323444}]}]}
{"op":"mcm","clk":"AKaTAQDsSwCJgwE=","pt":1659347677813,"mc":[{"id":"1.201590187","rc":[{"bdatb":[[0,12.5,1.14],[1,12,1.61],[2,11.5,5.54],[3,11,1.23],[4,10.5,5.23],[5,10,15.68],[6,9.8,9],[7,9.6,22.31],[8,9.4,54.1],[9,9.2,21.07]],"id":45323444},{"bdatl":[[6,2.36,6.04],[7,2.38,6.03],[8,2.4,73.46],[9,2.42,3.97]],"id":9570503}]}]}
{"op":"mcm","clk":"AKyTAQDuSwCMgwE=","pt":1659347677878,"mc":[{"id":"1.201590187","rc":[{"atb":[[12,6.37]],"id":45323444}]}]}
{"op":"mcm","clk":"ALCTAQDvSwCTgwE=","pt":1659347677928,"mc":[{"id":"1.201590187","rc":[{"bdatb":[[1,12,6.38]],"id":45323444},{"bdatl":[[8,2.4,77.46],[9,2.42,6.27]],"id":9570503}]}]}
{"op":"mcm","clk":"ALOTAQDwSwCUgwE=","pt":1659347677978,"mc":[{"id":"1.201590187","rc":[{"atb":[[12.5,1.33]],"id":45323444},{"atl":[[1000,2]],"id":44621159}]}]}
{"op":"mcm","clk":"ALeTAQDwSwCXgwE=","pt":1659347678028,"mc":[{"id":"1.201590187","rc":[{"bdatb":[[0,12.5,1.33]],"id":45323444},{"bdatl":[[6,2.36,7.05],[7,2.38,5.04]],"id":9570503},{"bdatl":[[6,1000,2]],"id":44621159}]}]}
{"op":"mcm","clk":"ALqTAQDySwCagwE=","pt":1659347678078,"mc":[{"id":"1.201590187","rc":[{"atb":[[23,4.23]],"bdatb":[[2,23,4.23]],"id":44621159}]}]}
{"op":"mcm","clk":"ALyTAQDzSwCdgwE=","pt":1659347678136,"mc":[{"id":"1.201590187","rc":[{"atb":[[2.02,32.15]],"id":9570503}]}]}
{"op":"mcm","clk":"AL6TAQDzSwCegwE=","pt":1659347678186,"mc":[{"id":"1.201590187","rc":[{"bdatb":[[2,2.02,32.15]],"id":9570503}]}]}
{"op":"mcm","clk":"AMuTAQD2SwCmgwE=","pt":1659347678346,"mc":[{"id":"1.201590187","rc":[{"atb":[[13,1.76],[12,4.77]],"atl":[[22,2.58]],"id":45323444},{"atb":[[8.8,9.9]],"id":43885158}]}]}
{"op":"mcm","clk":"AMyTAQD4SwCrgwE=","pt":1659347678396,"mc":[{"id":"1.201590187","rc":[{"bdatb":[[0,13,1.76],[1,12.5,1.33],[2,12,4.78],[3,11.5,5.54],[4,11,1.23],[5,10.5,5.23],[6,10,15.68],[7,9.8,9],[8,9.6,22.31],[9,9.4,54.1]],"bdatl":[[5,22,2.58],[6,23,3.2],[7,25,4.65],[8,26,5.04],[9,27,3.85]],"id":45323444},{"bdatl":[[6,2.34,9.8],[7,2.36,2.41],[8,2.38,4.6],[9,2.4,83.38]],"id":9570503},{"bdatb":[[0,8.8,9.9]],"id":43885158}]}]}
{"op":"mcm","clk":"ANCTAQD7SwCugwE=","pt":1659347678450,"mc":[{"id":"1.201590187","rc":[{"atb":[[1.02,1.6]],"id":45323444}]}]}
{"op":"mcm","clk":"AOGTAQCFTADEgwE=","pt":1659347678753,"mc":[{"id":"1.201590187","rc":[{"atb":[[12,0]],"id":45323444},{"atb":[[23,1.76]],"id":44621159}]}]}
{"op":"mcm","clk":"AOGTAQCHTADFgwE=","pt":1659347678803,"mc":[{"id":"1.201590187","rc":[{"bdatb":[[2,11.5,5.55],[3,11,1.23],[4,10.5,5.23],[5,10,15.68],[6,9.8,9],[7,9.6,22.31],[8,9.4,54.1],[9,9.2,21.07]],"id":45323444},{"bdatl":[[9,2.4,71.43]],"id":9570503},{"bdatb":[[2,23,1.76]],"id":44621159}]}]}
{"op":"mcm","clk":"APSTAQCMTADPgwE=","pt":1659347678960,"mc":[{"id":"1.201590187","rc":[{"atb":[[12.5,5.93]],"id":45323444}]}]}
{"op":"mcm","clk":"APWTAQCOTADRgwE=","pt":1659347679010,"mc":[{"id":"1.201590187","rc":[{"bdatb":[[1,12.5,5.93]],"id":45323444},{"bdatl":[[8,2.38,16.65],[9,2.4,73.35]],"id":9570503}]}]}
{"op":"mcm","clk":"AICUAQCSTADegwE=","pt":1659347679164,"mc":[{"id":"1.201590187","rc":[{"atb":[[25,2.3]],"id":44621159}]}]}
{"op":"mcm","clk":"AIGUAQCUTADigwE=","pt":1659347679214,"mc":[{"id":"1.201590187","rc":[{"bdatl":[[8,2.38,18.58],[9,2.4,71.43]],"id":9570503},{"bdatb":[[1,25,2.3],[2,24,2.78],[3,23,1.76],[4,22,1.76],[5,21,5],[6,20,3.57],[7,19.5,1.76],[8,19,1.76],[9,18.5,1.37]],"id":44621159}]}]}
{"op":"mcm","clk":"AISUAQCUTADkgwE=","pt":1659347679264,"mc":[{"id":"1.201590187","rc":[{"atb":[[10.5,1.76]],"id":45323444},{"atl":[[9.4,0]],"id":43885158}]}]}
{"op":"mcm","clk":"AIaUAQCUTADogwE=","pt":1659347679314,"mc":[{"id":"1.201590187","rc":[{"bdatb":[[2,11.5,5.54],[4,10.5,2.01],[7,9.6,22.32]],"id":45323444},{"bdatb":[[1,2.04,6.94],[7,1.96,9.07]],"id":9570503},{"bdatb":[[3,5.9,1.76]],"id":12989514},{"bdatb":[[6,20,3.56]],"id":44621159},{"bdatb":[[4,6.4,1.76],[9,5.7,46.77]],"id":44836671},{"bdatl":[[0,11,2.8]],"id":43885158}]}]}
{"op":"mcm","clk":"AJGUAQCaTAD2gwE=","pt":1659347679450,"mc":[{"id":"1.201590187","rc":[{"atl":[[23,1.76]],"id":45323444}]}]}
{"op":"mcm","clk":"AJGUAQCaTAD4gwE=","pt":1659347679500,"mc":[{"id":"1.201590187","rc":[{"bdatl":[[6,23,1.76]],"id":45323444}]}]}
{"op":"mcm","clk":"AJeUAQCdTAD5gwE=","pt":1659347679557,"mc":[{"id":"1.201590187","rc":[{"atl":[[24,1.92]],"id":45323444},{"atb":[[8.8,12.09]],"atl":[[11,1.4]],"id":43885158}]}]}
{"op":"mcm","clk":"AJuUAQCdTACDhAE=","pt":1659347679609,"mc":[{"id":"1.201590187","rc":[{"bdatb":[[5,10,14.41],[7,9.6,23.64]],"bdatl":[[7,24,1.92],[8,25,4.17],[9,26,5.04]],"id":45323444},{"bdatb":[[6,1.97,10.34],[7,1.96,15.52]],"id":9570503},{"bdatb":[[8,5.4,4.61]],"id":12989514},{"bdatb":[[7,5.9,11.61],[9,5.7,48.98]],"id":44836671},{"bdatb":[[0,8.8,12.09]],"bdatl":[[0,11,1.65]],"id":43885158}]}]}
{"op":"mcm","clk":"AKGUAQCgTACHhAE=","pt":1659347679659,"mc":[{"id":"1.201590187","rc":[{"atb":[[8.8,14.32]],"id":43885158}]}]}
{"op":"mcm","clk":"AKGUAQCgTACHhAE=","pt":1659347679709,"mc":[{"id":"1.201590187","rc":[{"bdatb":[[0,8.8,14.32]],"id":43885158}]}]}
{"op":"mcm","clk":"AKiUAQCiTACNhAE=","pt":1659347679761,"mc":[{"id":"1.201590187","rc":[{"atb":[[8.8,9.32]],"id":43885158}]}]}
{"op":"mcm","clk":"AKuUAQCiTACShAE=","pt":1659347679811,"mc":[{"id":"1.201590187","rc":[{"bdatb":[[0,8.8,9.32]],"id":43885158}]}]}
{"op":"mcm","clk":"ALmUAQCpTACbhAE=","pt":1659347679958,"mc":[{"id":"1.201590187","rc":[{"atb":[[12.5,1.33]],"id":45323444},{"atb":[[25,0]],"id":44621159}]}]}
{"op":"mcm","clk":"ALyUAQCtTACfhAE=","pt":1659347680009,"mc":[{"id":"1.201590187","rc":[{"bdatb":[[1,12.5,1.33]],"id":45323444},{"bdatl":[[8,2.38,4.6]],"id":9570503},{"bdatb":[[1,24,2.78],[2,23,1.76],[3,22,1.76],[4,21,5],[5,20,3.56],[6,19.5,1.76],[7,19,1.76],[8,18.5,1.37],[9,15.5,5.35]],"id":44621159}]}]}
{"op":"mcm","clk":"AMWUAQCxTACohAE=","pt":1659347680169,"mc":[{"id":"1.201590187","rc":[{"atb":[[24,5.2]],"id":44621159}]}]}
{"op":"mcm","clk":"AMeUAQCzTACthAE=","pt":1659347680220,"mc":[{"id":"1.201590187","rc":[{"bdatb":[[1,24,5.2]],"id":44621159}]}]}
{"op":"mcm","clk":"APGUAQDHTADWhAE=","pt":1659347680855,"mc":[{"id":"1.201590187","rc":[{"atb":[[24,2.78]],"id":44621159}]}]}
{"op":"mcm","clk":"APGUAQDHTADahAE=","pt":1659347680905,"mc":[{"id":"1.201590187","rc":[{"bdatb":[[1,24,2.78]],"id":44621159}]}]}
{"op":"mcm","clk":"APeUAQDJTADfhAE=","pt":1659347680955,"mc":[{"id":"1.201590187","rc":[{"atb":[[25,2.3]],"id":44621159}]}]}
{"op":"mcm","clk":"APiUAQDKTADlhAE=","pt":1659347681006,"mc":[{"id":"1.201590187","rc":[{"bdatb":[[1,25,2.3],[2,24,2.78],[3,23,1.76],[4,22,1.76],[5,21,5],[6,20,3.56],[7,19.5,1.76],[8,19,1.76],[9,18.5,1.37]],"id":44621159}]}]}
{"op":"mcm","clk":"AP2UAQDMTADohAE=","pt":1659347681061,"mc":[{"id":"1.201590187","rc":[{"atb":[[2.04,13],[2.02,15.36]],"id":9570503}]}]}
{"op":"mcm","clk":"AP2UAQDMTADohAE=","pt":1659347681111,"mc":[{"id":"1.201590187","rc":[{"bdatb":[[1,2.04,13],[2,2.02,15.36]],"id":9570503}]}]}
{"op":"mcm","clk":"AIKVAQDOTADxhAE=","pt":1659347681165,"mc":[{"id":"1.201590187","rc":[{"atb":[[11.5,7.73]],"id":45323444}]}]}
{"op":"mcm","clk":"AIOVAQDPTADyhAE=","pt":1659347681215,"mc":[{"id":"1.201590187","rc":[{"bdatb":[[2,11.5,7.73]],"id":45323444}]}]}
{"op":"mcm","clk":"AJSVAQDXTACFhQE=","pt":1659347681480,"mc":[{"id":"1.201590187","rc":[{"atb":[[2.04,6.27]],"id":9570503},{"atl":[[26,5.1]],"id":46969227}]}]}
{"op":"mcm","clk":"AJSVAQDaTACIhQE=","pt":1659347681530,"mc":[{"id":"1.201590187","rc":[{"bdatb":[[1,2.04,6.27]],"id":9570503},{"bdatl":[[0,26,5.1]],"id":46969227}]}]}
{"op":"mcm","clk":"AJWVAQDgTACZhQE=","pt":1659347681743,"mc":[{"id":"1.201590187","rc":[{"atl":[[11,4.4]],"id":43885158}]}]}
{"op":"mcm","clk":"AKiVAQDhTACZhQE=","pt":1659347681794,"mc":[{"id":"1.201590187","rc":[{"atb":[[25,0]],"bdatb":[[1,24,2.78],[2,23,1.76],[3,22,1.76],[4,21,5],[5,20,3.56],[6,19.5,1.76],[7,19,1.76],[8,18.5,1.37],[9,15.5,6.98]],"id":44621159},{"bdatb":[[5,10,16.94],[7,9.6,21.8],[9,9.2,20.24]],"id":45323444},{"bdatb":[[6,1.97,23.19],[7,1.96,6.55],[9,1.94,8.8]],"id":9570503},{"bdatb":[[8,5.4,10.73]],"id":12989514},{"bdatb":[[7,5.9,15.9],[9,5.7,45.9]],"id":44836671},{"bdatl":[[0,11,4.65]],"id":43885158}]}]}
{"op":"mcm","clk":"ALGVAQDjTACchQE=","pt":1659347681849,"mc":[{"id":"1.201590187","rc":[{"atb":[[24,5.2]],"id":44621159},{"atb":[[8.8,7.12]],"id":43885158}]}]}
{"op":"mcm","clk":"ALGVAQDlTACdhQE=","pt":1659347681899,"mc":[{"id":"1.201590187","rc":[{"bdatb":[[1,24,5.2]],"id":44621159},{"bdatb":[[0,8.8,7.12]],"id":43885158}]}]}
{"op":"mcm","clk":"ALWVAQDmTACghQE=","pt":1659347681955,"mc":[{"id":"1.201590187","rc":[{"atb":[[8.8,4.9]],"id":43885158}]}]}
{"op":"mcm","clk":"ALWVAQDnTAClhQE=","pt":1659347682005,"mc":[{"id":"1.201590187","rc":[{"bdatb":[[0,8.8,4.9]],"id":43885158}]}]}
{"op":"mcm","clk":"ANCVAQDzTADChQE=","pt":1659347682365,"mc":[{"id":"1.201590187","rc":[{"atb":[[2.02,32.42]],"id":9570503}]}]}
{"op":"mcm","clk":"ANCVAQD0TADFhQE=","pt":1659347682415,"mc":[{"id":"1.201590187","rc":[{"bdatb":[[2,2.02,32.42]],"id":9570503}]}]}
{"op":"mcm","clk":"ANqVAQD6TADThQE=","pt":1659347682665,"mc":[{"id":"1.201590187","rc":[{"atb":[[24,2.78]],"id":44621159}]}]}
{"op":"mcm","clk":"AN6VAQD6TADWhQE=","pt":1659347682715,"mc":[{"id":"1.201590187","rc":[{"bdatb":[[1,24,2.78]],"id":44621159}]}]}
{"op":"mcm","clk":"AOeVAQCCTQDbhQE=","pt":1659347682834,"mc":[{"id":"1.201590187","rc":[{"atb":[[25,2.3]],"id":44621159}]}]}
{"op":"mcm","clk":"AOuVAQCFTQDchQE=","pt":1659347682885,"mc":[{"id":"1.201590187","rc":[{"bdatb":[[1,25,2.3],[2,24,2.78],[3,23,1.76],[4,22,1.76],[5,21,5],[6,20,3.56],[7,19.5,1.76],[8,19,1.76],[9,18.5,1.37]],"id":44621159}]}]}
{"op":"mcm","clk":"AP6VAQCNTQDuhQE=","pt":1659347683149,"mc":[{"id":"1.201590187","rc":[{"atb":[[1.03,323]],"id":43885158}]}]}
{"op":"mcm","clk":"AJOWAQCTTQD6hQE=","pt":1659347683369,"mc":[{"id":"1.201590187","rc":[{"atb":[[1.03,322.64]],"id":43885158}]}]}
{"op":"mcm","clk":"AJqWAQCXTQCDhgE=","pt":1659347683469,"mc":[{"id":"1.201590187","rc":[{"atb":[[1.03,322]],"id":43885158}]}]}
{"op":"mcm","clk":"AJuWAQCZTQCIhgE=","pt":1659347683564,"mc":[{"id":"1.201590187","rc":[{"atb":[[8.8,5.54]],"id":43885158}]}]}
{"op":"mcm","clk":"AKKWAQCbTQCJhgE=","pt":1659347683614,"mc":[{"id":"1.201590187","rc":[{"bdatb":[[0,8.8,5.54]],"id":43885158}]}]}
{"op":"mcm","clk":"AKaWAQCbTQCLhgE=","pt":1659347683668,"mc":[{"id":"1.201590187","rc":[{"atb":[[25,0]],"id":44621159}]}]}
{"op":"mcm","clk":"AKmWAQCdTQCNhgE=","pt":1659347683718,"mc":[{"id":"1.201590187","rc":[{"bdatb":[[1,24,2.78],[2,23,1.76],[3,22,1.76],[4,21,5],[5,20,3.56],[6,19.5,1.76],[7,19,1.76],[8,18.5,1.37],[9,15.5,6.98]],"id":44621159}]}]}
{"op":"mcm","clk":"AK+WAQCdTQCPhgE=","pt":1659347683782,"mc":[{"id":"1.201590187","rc":[{"atb":[[24,5.2]],"id":44621159}]}]}
{"op":"mcm","clk":"AK+WAQCeTQCUhgE=","pt":1659347683832,"mc":[{"id":"1.201590187","rc":[{"bdatb":[[1,24,5.2]],"id":44621159}]}]}
{"op":"mcm","clk":"ALaWAQCeTQCYhgE=","pt":1659347683891,"mc":[{"id":"1.201590187","rc":[{"atl":[[23,6.31]],"id":45323444}]}]}
{"op":"mcm","clk":"ALeWAQCeTQCchgE=","pt":1659347683941,"mc":[{"id":"1.201590187","rc":[{"bdatl":[[6,23,6.31]],"id":45323444}]}]}
{"op":"mcm","clk":"AL6WAQCfTQCdhgE=","pt":1659347683991,"mc":[{"id":"1.201590187","rc":[{"atb":[[2.04,5.93],[2.06,0]],"trd":[[2.04,76.66],[2.06,45.59]],"tv":932.9,"id":9570503}],"tv":1521.09}]}
{"op":"mcm","clk":"AL6WAQChTQCfhgE=","pt":1659347684041,"mc":[{"id":"1.201590187","rc":[{"bdatb":[[0,2.04,5.93],[1,2.02,32.42],[2,2,11.07],[3,1.99,3.08],[4,1.98,36.93],[5,1.97,23.19],[6,1.96,6.55],[7,1.95,1.76],[8,1.94,8.8],[9,1.93,1.76]],"id":9570503}]}]}
{"op":"mcm","clk":"AMaWAQCiTQCghgE=","pt":1659347684093,"mc":[{"id":"1.201590187","rc":[{"atb":[[8.6,6.42]],"id":43885158}]}]}
{"op":"mcm","clk":"AMiWAQCjTQCqhgE=","pt":1659347684143,"mc":[{"id":"1.201590187","rc":[{"bdatb":[[1,8.6,6.42]],"id":43885158}]}]}
{"op":"mcm","clk":"AMuWAQCjTQCshgE=","pt":1659347684193,"mc":[{"id":"1.201590187","rc":[{"atb":[[2.04,7.14]],"bdatb":[[0,2.04,7.14]],"id":9570503}]}]}
{"op":"mcm","clk":"ANKWAQCnTQC0hgE=","pt":1659347684253,"mc":[{"id":"1.201590187","rc":[{"atb":[[2.04,1.21],[2,19.19]],"id":9570503}]}]}
{"op":"mcm","clk":"ANKWAQCnTQC0hgE=","pt":1659347684303,"mc":[{"id":"1.201590187","rc":[{"bdatb":[[0,2.04,1.21],[2,2,19.19]],"id":9570503}]}]}
{"op":"mcm","clk":"ANmWAQCpTQC6hgE=","pt":1659347684368,"mc":[{"id":"1.201590187","rc":[{"atl":[[2.16,9.18],[2.24,0]],"id":9570503}]}]}
{"op":"mcm","clk":"ANmWAQCrTQC8hgE=","pt":1659347684418,"mc":[{"id":"1.201590187","rc":[{"bdatl":[[1,2.16,9.18],[5,2.34,9.8],[6,2.36,2.41],[7,2.38,4.6],[8,2.4,71.43],[9,2.42,3.78]],"id":9570503}]}]}
{"op":"mcm","clk":"AN2WAQCtTQDChgE=","pt":1659347684468,"mc":[{"id":"1.201590187","rc":[{"atb":[[24,2.78]],"bdatb":[[1,24,2.78]],"id":44621159}]}]}
{"op":"mcm","clk":"AOaWAQCwTQDJhgE=","pt":1659347684557,"mc":[{"id":"1.201590187","rc":[{"atl":[[29,3.57],[27,0],[25,0],[23,1.76],[22,4.48],[21,1.89]],"id":45323444}]}]}
{"op":"mcm","clk":"AOaWAQCxTQDMhgE=","pt":1659347684607,"mc":[{"id":"1.201590187","rc":[{"bdatl":[[4,21,1.89],[5,22,4.48],[6,23,1.76],[8,26,5.04],[9,29,3.57]],"id":45323444}]}]}
{"op":"mcm","clk":"AO+WAQC0TQDPhgE=","pt":1659347684661,"mc":[{"id":"1.201590187","rc":[{"atb":[[25,2.3]],"id":44621159}]}]}
{"op":"mcm","clk":"AO+WAQC0TQDQhgE=","pt":1659347684711,"mc":[{"id":"1.201590187","rc":[{"bdatl":[[9,2.42,11.85]],"id":9570503},{"bdatb":[[1,25,2.3],[2,24,2.78],[3,23,1.76],[4,22,1.76],[5,21,5],[6,20,3.56],[7,19.5,1.76],[8,19,1.76],[9,18.5,1.37]],"id":44621159}]}]}
{"op":"mcm","clk":"APuWAQC6TQDchgE=","pt":1659347684869,"mc":[{"id":"1.201590187","rc":[{"atl":[[12,0]],"id":43885158}]}]}
{"op":"mcm","clk":"APuWAQC6TQDghgE=","pt":1659347684919,"mc":[{"id":"1.201590187","rc":[{"bdatl":[[2,12.5,13.48],[3,13,1.76],[4,13.5,9.76],[5,14,13.2],[6,14.5,13.87],[7,15,12],[8,15.5,20],[9,16,1.76]],"id":43885158}]}]}
{"op":"mcm","clk":"AIGXAQC8TQDkhgE=","pt":1659347684974,"mc":[{"id":"1.201590187","rc":[{"atl":[[11,7.68]],"id":43885158}]}]}
{"op":"mcm","clk":"AIGXAQC8TQDnhgE=","pt":1659347685024,"mc":[{"id":"1.201590187","rc":[{"bdatb":[[7,9.6,25.56],[9,9.2,16.31]],"id":45323444},{"bdatb":[[6,1.96,13.51],[8,1.94,1.76],[9,1.93,13.39]],"id":9570503},{"bdatb":[[8,5.4,13.25]],"id":12989514},{"bdatb":[[9,5.7,48.29]],"id":44836671},{"bdatl":[[0,11,7.93]],"id":43885158}]}]}
{"op":"mcm","clk":"AIuXAQDBTQD1hgE=","pt":1659347685181,"mc":[{"id":"1.201590187","rc":[{"atb":[[2.02,26.44],[2,35.36]],"id":9570503}]}]}
{"op":"mcm","clk":"AI2XAQDCTQD6hgE=","pt":1659347685231,"mc":[{"id":"1.201590187","rc":[{"bdatb":[[1,2.02,26.44],[2,2,35.36]],"id":9570503}]}]}
{"op":"mcm","clk":"AJWXAQDETQCBhwE=","pt":1659347685373,"mc":[{"id":"1.201590187","rc":[{"atb":[[25,0],[20,1.76]],"id":44621159}]}]}
{"op":"mcm","clk":"AJmXAQDFTQCDhwE=","pt":1659347685423,"mc":[{"id":"1.201590187","rc":[{"bdatl":[[9,2.42,3.78]],"id":9570503},{"bdatb":[[1,24,2.78],[2,23,1.76],[3,22,1.76],[4,21,5],[5,20,1.76],[6,19.5,1.76],[7,19,1.76],[8,18.5,1.37],[9,15.5,6.98]],"id":44621159}]}]}
{"op":"mcm","clk":"AJ6XAQDFTQCLhwE=","pt":1659347685477,"mc":[{"id":"1.201590187","rc":[{"atb":[[24,5.2],[19.5,3.56]],"id":44621159},{"atl":[[10.5,2.25]],"id":43885158}]}]}
{"op":"mcm","clk":"AKGXAQDFTQCNhwE=","pt":1659347685528,"mc":[{"id":"1.201590187","rc":[{"bdatb":[[4,10.5,4.01],[5,10,14.84],[7,9.6,27.75],[9,9.2,14.03]],"id":45323444},{"bdatb":[[3,1.99,13.64],[5,1.97,12.53],[9,1.93,18.67]],"id":9570503},{"bdatb":[[7,5.5,6.06],[8,5.4,9.36]],"id":12989514},{"bdatb":[[1,24,5.2],[6,19.5,3.56],[9,16.5,1.43]],"id":44621159},{"bdatb":[[6,6,233.68],[7,5.9,12.34]],"id":44836671},{"bdatl":[[0,10.5,2.25],[1,11,7.68],[2,11.5,9.87],[3,12.5,13.48],[4,13,1.76],[5,13.5,9.76],[6,14,13.2],[7,14.5,13.87],[8,15,12],[9,15.5,20]],"id":43885158}]}]}
{"op":"mcm","clk":"AL+XAQDOTQCthwE=","pt":1659347685967,"mc":[{"id":"1.201590187","rc":[{"atl":[[10.5,3.4]],"id":43885158}]}]}
{"op":"mcm","clk":"AMCXAQDOTQCuhwE=","pt":1659347686017,"mc":[{"id":"1.201590187","rc":[{"bdatb":[[4,10.5,5.16],[5,10,13.64],[7,9.6,29.01],[9,9.2,12.72]],"id":45323444},{"bdatb":[[3,1.99,19.7],[5,1.97,6.4]],"id":9570503},{"bdatb":[[7,5.5,8.25],[8,5.4,7.13]],"id":12989514},{"bdatb":[[9,16.5,2.16]],"id":44621159},{"bdatb":[[6,6,235.69],[7,5.9,10.29]],"id":44836671},{"bdatl":[[0,10.5,3.4]],"id":43885158}]}]}
{"op":"mcm","clk":"AMSXAQDPTQCxhwE=","pt":1659347686081,"mc":[{"id":"1.201590187","rc":[{"atl":[[27,0.1]],"id":46969227}]}]}
{"op":"mcm","clk":"AMaXAQDQTQCzhwE=","pt":1659347686137,"mc":[{"id":"1.201590187","rc":[{"bdatl":[[1,28,7.74],[2,29,1.76],[3,30,1.83],[4,32,3.23],[5,34,5],[6,36,1.76],[7,38,1.76],[8,40,5.01],[9,80,1.66]],"id":46969227}]}]}
{"op":"mcm","clk":"AMqXAQDRTQC2hwE=","pt":1659347686187,"mc":[{"id":"1.201590187","rc":[{"atb":[[11,7.26]],"bdatb":[[3,11,7.26]],"id":45323444},{"atb":[[2.02,42.25],[2,27.24]],"bdatb":[[1,2.02,42.25],[2,2,27.24]],"id":9570503},{"atb":[[24,2.78]],"bdatb":[[1,24,2.78]],"id":44621159}]}]}
{"op":"mcm","clk":"AM+XAQDUTQC+hwE=","pt":1659347686285,"mc":[{"id":"1.201590187","rc":[{"atb":[[25,2.3]],"id":44621159},{"atl":[[12,1.76]],"id":43885158}]}]}
{"op":"mcm","clk":"AM+XAQDUTQDBhwE=","pt":1659347686356,"mc":[{"id":"1.201590187","rc":[{"bdatl":[[9,2.42,11.85]],"id":9570503},{"bdatb":[[1,25,2.3],[2,24,2.78],[3,23,1.76],[4,22,1.76],[5,21,5],[6,20,1.76],[7,19.5,3.56],[8,19,1.76],[9,18.5,1.37]],"id":44621159},{"bdatl":[[3,12,1.76],[4,12.5,13.48],[5,13,1.76],[6,13.5,9.76],[7,14,13.2],[8,14.5,13.87],[9,15,12]],"id":43885158}]}]}
{"op":"mcm","clk":"ANiXAQDYTQDMhwE=","pt":1659347686479,"mc":[{"id":"1.201590187","rc":[{"atb":[[26,0.1],[25,3.3]],"atl":[[38,2.87]],"id":44621159}]}]}
{"op":"mcm","clk":"ANmXAQDaTQDMhwE=","pt":1659347686530,"mc":[{"id":"1.201590187","rc":[{"bdatb":[[9,1.93,24.75]],"bdatl":[[5,2.34,1.12],[6,2.36,8.61],[7,2.38,6.99]],"id":9570503},{"bdatb":[[0,25,3.4],[1,24,2.78],[2,23,1.76],[3,22,1.76],[4,21,5],[5,20,1.76],[6,19.5,3.56],[7,19,1.76],[8,18.5,1.37],[9,16.5,2.16]],"bdatl":[[0,38,2.87]],"id":44621159}]}]}
{"op":"mcm","clk":"AN+XAQDdTQDVhwE=","pt":1659347686630,"mc":[{"id":"1.201590187","rc":[{"atl":[[38,1.87]],"id":44621159}]}]}
{"op":"mcm","clk":"AOSXAQDdTQDXhwE=","pt":1659347686681,"mc":[{"id":"1.201590187","rc":[{"bdatb":[[9,1.93,18.67]],"id":9570503},{"bdatl":[[0,38,1.87]],"id":44621159}]}]}
{"op":"mcm","clk":"APiXAQDkTQDjhwE=","pt":1659347686856,"mc":[{"id":"1.201590187","rc":[{"atb":[[7.6,6.07]],"id":43885158}]}]}
{"op":"mcm","clk":"APiXAQDlTQDjhwE=","pt":1659347686906,"mc":[{"id":"1.201590187","rc":[{"bdatb":[[6,7.6,11.77]],"id":43885158}]}]}
{"op":"mcm","clk":"AP2XAQDqTQDohwE=","pt":1659347686956,"mc":[{"id":"1.201590187","rc":[{"atb":[[2.04,29.37]],"id":9570503}]}]}
{"op":"mcm","clk":"AP+XAQDqTQDohwE=","pt":1659347687006,"mc":[{"id":"1.201590187","rc":[{"bdatb":[[0,2.04,29.37]],"id":9570503}]}]}
{"op":"mcm","clk":"AJ6YAQD5TQD5hwE=","pt":1659347687469,"mc":[{"id":"1.201590187","rc":[{"atb":[[13.5,1.76]],"id":45323444},{"atb":[[2.06,1.76]],"id":9570503}]}]}
{"op":"mcm","clk":"AKGYAQD5TQD6hwE=","pt":1659347687519,"mc":[{"id":"1.201590187","rc":[{"bdatb":[[0,13.5,1.76],[1,13,1.76],[2,12.5,1.33],[3,11.5,7.73],[4,11,7.26],[5,10.5,5.16],[6,10,13.64],[7,9.8,9],[8,9.6,29.01],[9,9.4,54.1]],"id":45323444},{"bdatb":[[0,2.06,1.76],[1,2.04,29.37],[2,2.02,42.25],[3,2,27.24],[4,1.99,19.7],[5,1.98,36.93],[6,1.97,6.4],[7,1.96,13.51],[8,1.95,1.76],[9,1.94,1.76]],"bdatl":[[5,2.32,1.13],[6,2.34,9.06],[7,2.36,9.72],[8,2.38,6.99],[9,2.4,71.43]],"id":9570503}]}]}
{"op":"mcm","clk":"AKiYAQD7TQD9hwE=","pt":1659347687580,"mc":[{"id":"1.201590187","rc":[{"atb":[[2.06,2.96]],"id":9570503}]}]}
{"op":"mcm","clk":"AKiYAQD7TQD+hwE=","pt":1659347687630,"mc":[{"id":"1.201590187","rc":[{"bdatb":[[0,2.06,2.96]],"id":9570503}]}]}
{"op":"mcm","clk":"ALSYAQCBTgCJiAE=","pt":1659347687785,"mc":[{"id":"1.201590187","rc":[{"atb":[[25,1]],"id":44621159}]}]}
{"op":"mcm","clk":"ALSYAQCBTgCLiAE=","pt":1659347687835,"mc":[{"id":"1.201590187","rc":[{"bdatl":[[8,2.4,78.37],[9,2.44,155.96]],"id":9570503},{"bdatb":[[0,25,1.1]],"id":44621159}]}]}
{"op":"mcm","clk":"ALmYAQCDTgCNiAE=","pt":1659347687885,"mc":[{"id":"1.201590187","rc":[{"atb":[[24,5.2]],"id":44621159}]}]}
{"op":"mcm","clk":"ALmYAQCDTgCPiAE=","pt":1659347687935,"mc":[{"id":"1.201590187","rc":[{"bdatb":[[1,24,5.2]],"id":44621159}]}]}
{"op":"mcm","clk":"AMaYAQCETgCciAE=","pt":1659347688093,"mc":[{"id":"1.201590187","rc":[{"atb":[[13.5,0]],"id":45323444},{"atl":[[11,4.68]],"id":43885158}]}]}
{"op":"mcm","clk":"AMqYAQCETgCfiAE=","pt":1659347688144,"mc":[{"id":"1.201590187","rc":[{"bdatb":[[0,13,1.76],[1,12.5,1.33],[2,11.5,7.73],[3,11,7.26],[4,10.5,5.16],[5,10,13.64],[6,9.8,9],[7,9.6,25.57],[8,9.4,54.1],[9,9.2,16.31]],"id":45323444},{"bdatl":[[5,2.34,1.12],[6,2.36,8.61],[7,2.38,6.99],[8,2.4,71.43],[9,2.42,3.78]],"id":9570503},{"bdatl":[[1,11,4.68]],"id":43885158}]}]}
{"op":"mcm","clk":"AMyYAQCETgCjiAE=","pt":1659347688194,"mc":[{"id":"1.201590187","rc":[{"atb":[[2.04,37.82]],"id":9570503},{"atl":[[10.5,6.1]],"id":43885158},{"atl":[[27,2.51]],"id":46969227}]}]}
{"op":"mcm","clk":"ANGYAQCETgCpiAE=","pt":1659347688244,"mc":[{"id":"1.201590187","rc":[{"bdatb":[[4,10.5,5.89],[5,10,14.95],[7,9.6,26.36],[9,9.2,13.22]],"id":45323444},{"bdatb":[[1,2.04,37.82],[4,1.99,23.53],[5,1.98,47.4],[6,1.97,2.53],[7,1.96,2.93]],"id":9570503},{"bdatb":[[7,5.5,13.41],[8,5.4,1.88]],"id":12989514},{"bdatb":[[9,16.5,2.63]],"id":44621159},{"bdatb":[[6,6,236.96],[7,5.9,12.51],[9,5.7,44.65]],"id":44836671},{"bdatl":[[0,10.5,6.1]],"id":43885158},{"bdatl":[[1,27,2.51],[2,28,7.64],[3,29,1.76],[4,30,1.83],[5,32,3.23],[6,34,5],[7,36,1.76],[8,38,1.76],[9,40,5.01]],"id":46969227}]}]}
{"op":"mcm","clk":"ANOYAQCGTgCsiAE=","pt":1659347688294,"mc":[{"id":"1.201590187","rc":[{"atb":[[11.5,11.4],[11,1.23]],"bdatb":[[2,11.5,11.4],[3,11,1.23]],"id":45323444},{"atb":[[2,11.07]],"bdatb":[[3,2,11.07]],"id":9570503}]}]}
{"op":"mcm","clk":"AOGYAQCHTgC7iAE=","pt":1659347688457,"mc":[{"id":"1.201590187","rc":[{"atb":[[12.5,1.14]],"id":45323444}]}]}
{"op":"mcm","clk":"AOGYAQCHTgC7iAE=","pt":1659347688507,"mc":[{"id":"1.201590187","rc":[{"bdatb":[[1,12.5,1.14]],"id":45323444},{"bdatl":[[7,2.38,5.99],[9,2.42,4.76]],"id":9570503}]}]}
{"op":"mcm","clk":"AOeYAQCITgDAiAE=","pt":1659347688559,"mc":[{"id":"1.201590187","rc":[{"atb":[[2.04,9.66]],"id":9570503},{"atb":[[24,2.78]],"id":44621159}]}]}
{"op":"mcm","clk":"AOeYAQCITgDAiAE=","pt":1659347688609,"mc":[{"id":"1.201590187","rc":[{"bdatb":[[1,2.04,9.66]],"id":9570503},{"bdatb":[[1,24,2.78]],"id":44621159}]}]}
{"op":"mcm","clk":"APKYAQCKTgDMiAE=","pt":1659347688764,"mc":[{"id":"1.201590187","rc":[{"atb":[[9.4,36.86]],"id":45323444},{"atb":[[1.75,17.24]],"id":9570503},{"atb":[[3.9,44.48]],"id":12989514},{"atb":[[25,3.3]],"id":44621159},{"atb":[[5.6,46.48]],"id":44836671},{"atb":[[6,31.24]],"id":43885158},{"atb":[[8.8,31.6]],"id":46969227}]}]}
{"op":"mcm","clk":"APKYAQCKTgDOiAE=","pt":1659347688814,"mc":[{"id":"1.201590187","rc":[{"bdatb":[[8,9.4,36.86]],"id":45323444},{"bdatl":[[9,2.42,12.83]],"id":9570503},{"bdatb":[[0,25,3.4]],"id":44621159}]}]}
{"op":"mcm","clk":"AIaZAQCOTgDdiAE=","pt":1659347689076,"mc":[{"id":"1.201590187","rc":[{"atb":[[13,0]],"id":45323444}]}]}
{"op":"mcm","clk":"AIaZAQCOTgDgiAE=","pt":1659347689126,"mc":[{"id":"1.201590187","rc":[{"bdatb":[[0,12.5,1.14],[1,11.5,11.4],[2,11,1.23],[3,10.5,5.89],[4,10,14.95],[5,9.8,9],[6,9.6,26.36],[7,9.4,36.86],[8,9.2,13.22],[9,9,13]],"id":45323444},{"bdatl":[[5,2.36,1.11],[6,2.38,4.89],[7,2.4,71.43],[8,2.42,22.3],[9,2.44,153.97]],"id":9570503}]}]}
{"op":"mcm","clk":"AI6ZAQCSTgDjiAE=","pt":1659347689176,"mc":[{"id":"1.201590187","rc":[{"atb":[[12.5,1.33],[11.5,7.73],[11,7.26]],"id":45323444}]}]}
{"op":"mcm","clk":"AI+ZAQCSTgDkiAE=","pt":1659347689226,"mc":[{"id":"1.201590187","rc":[{"bdatb":[[0,12.5,1.33],[1,11.5,7.73],[2,11,7.26]],"id":45323444},{"bdatl":[[6,2.38,5.89],[8,2.42,21.32]],"id":9570503}]}]}
{"op":"mcm","clk":"AJqZAQCZTgDqiAE=","pt":1659347689388,"mc":[{"id":"1.201590187","rc":[{"atb":[[12.5,1.14]],"id":45323444},{"atb":[[2.04,17.08],[2.02,26.44]],"atl":[[2.16,5.18],[2.24,7]],"id":9570503}]}]}
{"op":"mcm","clk":"AJqZAQCbTgDsiAE=","pt":1659347689438,"mc":[{"id":"1.201590187","rc":[{"bdatb":[[0,12.5,1.14]],"id":45323444},{"bdatb":[[1,2.04,17.08],[2,2.02,26.44]],"bdatl":[[1,2.16,5.18],[5,2.24,7],[6,2.36,1.11],[7,2.38,4.89],[8,2.4,71.43],[9,2.42,22.3]],"id":9570503}]}]}
{"op":"mcm","clk":"AKWZAQCfTgDziAE=","pt":1659347689602,"mc":[{"id":"1.201590187","rc":[{"atb":[[25,1]],"id":44621159}]}]}
{"op":"mcm","clk":"AKqZAQChTgD3iAE=","pt":1659347689652,"mc":[{"id":"1.201590187","rc":[{"bdatl":[[9,2.42,14.24]],"id":9570503},{"bdatb":[[0,25,1.1]],"id":44621159}]}]}
{"op":"mcm","clk":"AK2ZAQCiTgD4iAE=","pt":1659347689703,"mc":[{"id":"1.201590187","rc":[{"atl":[[2.14,76.39]],"trd":[[2.14,60.71]],"bdatb":[[4,1.99,23.39],[5,1.98,36.93],[6,1.97,2.67],[7,1.96,13.51]],"bdatl":[[0,2.14,76.39]],"ltp":2.14,"tv":952.9,"id":9570503},{"atb":[[24,5.2]],"bdatb":[[1,24,5.2],[9,16.5,2.61]],"id":44621159},{"atl":[[10.5,4.1]],"bdatl":[[0,10.5,4.1]],"id":43885158},{"bdatb":[[3,10.5,5.86],[4,10,12.9],[6,9.6,26.33],[8,9.2,15.51]],"id":45323444},{"bdatb":[[7,5.5,9.59],[8,5.4,5.77]],"id":12989514},{"bdatb":[[6,6,236.91],[7,5.9,9.05],[9,5.7,48.29]],"id":44836671}],"tv":1541.09}]}
{"op":"mcm","clk":"ALKZAQCnTgD6iAE=","pt":1659347689783,"mc":[{"id":"1.201590187","rc":[{"atb":[[13,1.76]],"id":45323444}]}]}
{"op":"mcm","clk":"ALWZAQCnTgD8iAE=","pt":1659347689833,"mc":[{"id":"1.201590187","rc":[{"bdatb":[[0,13,1.76],[1,12.5,1.14],[2,11.5,7.73],[3,11,7.26],[4,10.5,5.86],[5,10,12.9],[6,9.8,9],[7,9.6,26.33],[8,9.4,36.86],[9,9.2,15.51]],"id":45323444},{"bdatl":[[6,2.34,1.12],[7,2.36,8.61],[8,2.38,5.99],[9,2.4,71.43]],"id":9570503}]}]}
{"op":"mcm","clk":"ALmZAQCrTgD+iAE=","pt":1659347689883,"mc":[{"id":"1.201590187","rc":[{"atl":[[24,0.48],[16,1]],"bdatl":[[0,16,1],[1,16.5,3.92],[2,18.5,1.76],[3,19,1.76],[4,19.5,1.76],[5,21,1.89],[6,22,4.48],[7,23,1.76],[8,26,5.52]],"id":45323444},{"bdatb":[[3,2,19.07],[4,1.99,15.35],[7,1.96,16.75],[8,1.95,6.71]],"id":9570503},{"bdatb":[[8,5.4,6.94],[9,5.3,3.58]],"id":12989514},{"bdatb":[[9,16.5,2.58]],"id":44621159},{"bdatb":[[9,5.7,51.1]],"id":44836671},{"bdatb":[[5,7.8,4.78],[6,7.6,9.67],[7,7.4,7.37],[9,7,136.59]],"id":43885158}]}]}
{"op":"mcm","clk":"ALqZAQCsTgCDiQE=","pt":1659347689945,"mc":[{"id":"1.201590187","rc":[{"atb":[[12,2]],"atl":[[22,5.92],[21,1.76],[16,2.16]],"id":45323444}]}]}
{"op":"mcm","clk":"ALuZAQCtTgCFiQE=","pt":1659347689995,"mc":[{"id":"1.201590187","rc":[{"bdatb":[[2,12,2],[3,11.5,7.73],[4,11,7.26],[5,10.5,5.86],[6,10,12.9],[7,9.8,9],[8,9.6,26.33],[9,9.4,36.86]],"bdatl":[[0,16,2.16],[5,21,1.76],[6,22,5.92]],"id":45323444},{"bdatb":[[3,2,28.35],[4,1.99,6.03],[8,1.95,13.82],[9,1.94,4.18]],"bdatl":[[9,2.4,76.23]],"id":9570503},{"bdatb":[[9,5.3,6.2]],"id":12989514},{"bdatb":[[9,17,2.03]],"id":44621159},{"bdatb":[[9,5.7,53.53]],"id":44836671},{"bdatb":[[5,7.8,7.16],[6,7.6,7.23],[7,7.4,9.88],[9,7,133.94]],"id":43885158}]}]}
{"op":"mcm","clk":"AMeZAQCxTgCIiQE=","pt":1659347690068,"mc":[{"id":"1.201590187","rc":[{"atb":[[12.5,1.33]],"id":45323444}]}]}
{"op":"mcm","clk":"AMmZAQCzTgCMiQE=","pt":1659347690118,"mc":[{"id":"1.201590187","rc":[{"bdatb":[[1,12.5,1.33]],"id":45323444},{"bdatl":[[8,2.38,6.99],[9,2.4,75.24]],"id":9570503}]}]}
{"op":"mcm","clk":"AM6ZAQC3TgCQiQE=","pt":1659347690168,"mc":[{"id":"1.201590187","rc":[{"atb":[[13,0],[11.5,5.54],[11,1.23]],"id":45323444}]}]}
{"op":"mcm","clk":"AM6ZAQC3TgCSiQE=","pt":1659347690218,"mc":[{"id":"1.201590187","rc":[{"bdatb":[[0,12.5,1.33],[1,12,2],[2,11.5,5.54],[3,11,1.23],[4,10.5,5.86],[5,10,12.9],[6,9.8,9],[7,9.6,26.33],[8,9.4,36.86],[9,9.2,15.51]],"id":45323444},{"bdatl":[[6,2.36,1.11],[7,2.38,10.5],[8,2.4,76.85],[9,2.42,3.34]],"id":9570503}]}]}
{"op":"mcm","clk":"AN2ZAQC+TgCaiQE=","pt":1659347690376,"mc":[{"id":"1.201590187","rc":[{"atb":[[24,2.78]],"id":44621159}]}]}
{"op":"mcm","clk":"AOKZAQC+TgCfiQE=","pt":1659347690427,"mc":[{"id":"1.201590187","rc":[{"bdatb":[[1,24,2.78]],"id":44621159}]}]}
{"op":"mcm","clk":"AO2ZAQDHTgCpiQE=","pt":1659347690594,"mc":[{"id":"1.201590187","rc":[{"atb":[[12,6.77]],"id":45323444},{"atl":[[11,3.53]],"id":43885158}]}]}
{"op":"mcm","clk":"AO+ZAQDITgCsiQE=","pt":1659347690644,"mc":[{"id":"1.201590187","rc":[{"bdatb":[[1,12,6.77],[7,9.6,25.02],[9,9.2,16.88]],"id":45323444},{"bdatb":[[8,1.95,7.34],[9,1.94,10.7]],"bdatl":[[8,2.4,80.22],[9,2.42,9.97]],"id":9570503},{"bdatb":[[9,5.3,3.81]],"id":12989514},{"bdatb":[[9,5.7,51.31]],"id":44836671},{"bdatl":[[1,11,3.53]],"id":43885158}]}]}
{"op":"mcm","clk":"APiZAQDNTgCziQE=","pt":1659347690777,"mc":[{"id":"1.201590187","rc":[{"atb":[[1.98,70.48]],"id":9570503},{"atb":[[25,3.3]],"id":44621159}]}]}
{"op":"mcm","clk":"APiZAQDNTgC1iQE=","pt":1659347690827,"mc":[{"id":"1.201590187","rc":[{"bdatb":[[5,1.98,70.48]],"bdatl":[[7,2.38,19.37],[8,2.4,79.56],[9,2.42,1.9]],"id":9570503},{"bdatb":[[0,25,3.4]],"id":44621159}]}]}
{"op":"mcm","clk":"AIeaAQDRTgDBiQE=","pt":1659347690988,"mc":[{"id":"1.201590187","rc":[{"atb":[[13,1.76]],"atl":[[17.5,1.76]],"id":45323444}]}]}
{"op":"mcm","clk":"AIiaAQDUTgDCiQE=","pt":1659347691039,"mc":[{"id":"1.201590187","rc":[{"bdatb":[[0,13,1.76],[1,12.5,1.33],[2,12,6.77],[3,11.5,5.54],[4,11,1.23],[5,10.5,5.86],[6,10,12.9],[7,9.8,9],[8,9.6,25.02],[9,9.4,36.86]],"bdatl":[[2,17.5,1.76],[3,18.5,1.76],[4,19,1.76],[5,19.5,1.76],[6,21,1.76],[7,22,5.92],[8,23,1.76],[9,26,5.52]],"id":45323444},{"bdatl":[[6,2.34,1.12],[7,2.36,8.61],[8,2.38,10.83],[9,2.4,79.56]],"id":9570503},{"bdatb":[[8,7.2,7.54],[9,7,130.47]],"id":43885158}]}]}
{"op":"mcm","clk":"AJiaAQDZTgDZiQE=","pt":1659347691273,"mc":[{"id":"1.201590187","rc":[{"atb":[[6.6,2],[6,2.34]],"id":12989514}]}]}
{"op":"mcm","clk":"AJiaAQDcTgDbiQE=","pt":1659347691323,"mc":[{"id":"1.201590187","rc":[{"bdatl":[[6,2.32,5.69],[7,2.36,4.12]],"id":9570503},{"bdatb":[[0,6.6,2],[1,6.4,11.38],[2,6.2,12.69],[3,6,2.34],[4,5.9,1.76],[5,5.8,35.31],[6,5.7,223.76],[7,5.6,1.76],[8,5.5,9.59],[9,5.4,6.94]],"id":12989514}]}]}
{"op":"mcm","clk":"AJ6aAQDfTgDeiQE=","pt":1659347691373,"mc":[{"id":"1.201590187","rc":[{"atl":[[6.8,0]],"trd":[[6.8,26.53]],"tv":119.56,"id":12989514}],"tv":1553.83}]}
{"op":"mcm","clk":"AKKaAQDfTgDgiQE=","pt":1659347691423,"mc":[{"id":"1.201590187","rc":[{"bdatb":[[5,10.5,1.76],[6,10,17.18],[8,9.6,25.05]],"id":45323444},{"bdatb":[[3,2,11.07],[4,1.99,1.76],[5,1.98,92.22],[6,1.97,2.53],[7,1.96,16.89],[9,1.94,2.58]],"id":9570503},{"bdatl":[[0,7,11.92],[1,7.2,11.11],[2,7.4,8.34],[3,7.8,4.53],[4,8,1.76],[5,8.2,1.76],[6,8.4,4],[7,8.6,1.76],[8,8.8,1.76],[9,9,6.82]],"id":12989514},{"bdatb":[[9,16,2.16]],"id":44621159},{"bdatb":[[6,6,229.74],[7,5.9,16.3],[9,5.7,51.36]],"id":44836671},{"bdatb":[[5,7.8,2.73],[6,7.6,10.62],[7,7.4,8.93],[8,7.2,5.89],[9,7,134.41]],"id":43885158}]}]}
{"op":"mcm","clk":"AKWaAQDgTgDhiQE=","pt":1659347691473,"mc":[{"id":"1.201590187","rc":[{"atb":[[12,2]],"bdatb":[[2,12,2]],"id":45323444},{"atl":[[7.6,5.34]],"bdatl":[[3,7.6,5.34],[4,7.8,4.19],[5,8,1.76],[6,8.2,1.76],[7,8.4,4],[8,8.6,1.76],[9,8.8,1.76]],"id":12989514},{"atb":[[25,1]],"bdatb":[[0,25,1.1]],"id":44621159},{"bdatl":[[8,2.38,6.99],[9,2.4,75.24]],"id":9570503}]}]}
{"op":"mcm","clk":"AK+aAQDiTgDjiQE=","pt":1659347691572,"mc":[{"id":"1.201590187","rc":[{"atb":[[6,0]],"atl":[[7,0.36],[7.4,0.34],[7.2,5.11]],"id":12989514}]}]}
{"op":"mcm","clk":"ALGaAQDjTgDkiQE=","pt":1659347691622,"mc":[{"id":"1.201590187","rc":[{"bdatb":[[6,10,13.13],[8,9.6,24.84],[9,9.4,37.13]],"id":45323444},{"bdatb":[[5,1.98,71.75],[6,1.97,18.79],[7,1.96,5.05],[8,1.95,3.05],[9,1.94,1.76]],"id":9570503},{"bdatb":[[3,5.9,1.76],[4,5.8,35.31],[5,5.7,223.76],[6,5.6,1.76],[7,5.5,9.59],[8,5.4,6.94],[9,5.3,3.81]],"bdatl":[[0,7.2,5.47],[1,7.6,5.68],[2,7.8,4.19],[3,8,1.76],[4,8.2,1.76],[5,8.4,4],[6,8.6,1.76],[7,8.8,1.76],[8,9,6.82],[9,9.2,1.76]],"id":12989514},{"bdatb":[[9,15.5,4.35]],"id":44621159},{"bdatb":[[7,5.9,9.43],[8,5.8,15.52],[9,5.7,45.38]],"id":44836671},{"bdatb":[[6,7.6,6.41],[7,7.4,6.65],[8,7.2,4.37],[9,7,130.36]],"id":43885158}]}]}
{"op":"mcm","clk":"ALaaAQDkTgDniQE=","pt":1659347691672,"mc":[{"id":"1.201590187","rc":[{"atb":[[12.5,5.93]],"atl":[[16.5,0]],"id":45323444},{"atb":[[6.6,2.38]],"atl":[[7,0]],"trd":[[7,20.71]],"ltp":7,"tv":120.28,"id":12989514},{"atb":[[7.2,17.59]],"id":44836671},{"atb":[[8.8,0.64]],"id":43885158}],"tv":1554.55}]}
{"op":"mcm","clk":"ALeaAQDkTgDpiQE=","pt":1659347691723,"mc":[{"id":"1.201590187","rc":[{"bdatb":[[1,12.5,5.93],[6,10,12.87]],"bdatl":[[1,17.5,1.76],[2,18.5,1.76],[3,19,1.76],[4,19.5,1.76],[5,21,1.76],[6,22,5.92],[7,23,1.76],[8,26,5.52],[9,29,3.57]],"id":45323444},{"bdatb":[[5,1.98,70.48],[6,1.97,20.07],[7,1.96,2.62],[8,1.95,2.92]],"bdatl":[[6,2.32,2.43],[7,2.34,4.31],[8,2.36,3.06],[9,2.38,1.97]],"id":9570503},{"bdatb":[[0,6.6,2.38],[7,5.5,8.05],[8,5.4,3.33],[9,5.3,5.99]],"bdatl":[[0,7.2,5.11]],"id":12989514},{"bdatb":[[9,15.5,4.19]],"id":44621159},{"bdatb":[[0,7.2,17.59],[7,5.9,9],[8,5.8,15.96],[9,5.7,44.55]],"id":44836671},{"bdatb":[[0,8.6,7.06],[1,8.4,1.76],[2,8.2,1.76],[3,8,1.46],[4,7.8,2.73],[5,7.6,6.07],[6,7.4,6.99],[7,7.2,3.71],[8,7,130.32],[9,6.6,18.17]],"id":43885158}]}]}
{"op":"mcm","clk":"AL6aAQDmTgDriQE=","pt":1659347691781,"mc":[{"id":"1.201590187","rc":[{"atl":[[7.6,0.34]],"id":12989514},{"atl":[[12,9.96],[11.5,2.88]],"id":43885158}]}]}
{"op":"mcm","clk":"AL+aAQDmTgDtiQE=","pt":1659347691831,"mc":[{"id":"1.201590187","rc":[{"bdatl":[[1,7.8,4.87],[2,8,1.76],[3,8.2,1.76],[4,8.4,4],[5,8.6,1.76],[6,8.8,1.76],[7,9,6.82],[8,9.2,1.76],[9,9.6,11.09]],"id":12989514},{"bdatb":[[9,6.6,17.32]],"bdatl":[[2,11.5,2.88],[3,12,9.96]],"id":43885158}]}]}
{"op":"mcm","clk":"AMeaAQDnTgDuiQE=","pt":1659347691887,"mc":[{"id":"1.201590187","rc":[{"atl":[[21,3.76]],"id":45323444},{"atb":[[6.4,16.77]],"id":12989514},{"atb":[[24,5.2]],"id":44621159}]}]}
{"op":"mcm","clk":"AMiaAQDoTgDxiQE=","pt":1659347691937,"mc":[{"id":"1.201590187","rc":[{"bdatl":[[5,21,3.76]],"id":45323444},{"bdatb":[[1,6.4,16.77]],"id":12989514},{"bdatb":[[1,24,5.2]],"id":44621159}]}]}
{"op":"mcm","clk":"ANuaAQDsTgD6iQE=","pt":1659347692183,"mc":[{"id":"1.201590187","rc":[{"atl":[[20,1.76]],"id":45323444},{"atl":[[7.6,8.77],[7.2,10.26]],"id":12989514}]}]}
{"op":"mcm","clk":"AN6aAQDsTgD+iQE=","pt":1659347692233,"mc":[{"id":"1.201590187","rc":[{"bdatb":[[8,9.6,25.48],[9,9.4,36.86]],"bdatl":[[5,20,1.76],[6,21,3.76],[7,22,5.92],[8,23,1.76],[9,26,5.52]],"id":45323444},{"bdatb":[[8,1.95,6.11]],"id":9570503},{"bdatl":[[0,7.2,10.26],[1,7.6,9.11],[2,7.8,4.19],[3,8,1.76],[4,8.2,1.76],[5,8.4,4],[6,8.6,1.76],[7,8.8,1.76],[8,9,6.82],[9,9.2,1.76]],"id":12989514},{"bdatb":[[8,7,134.41],[9,6.8,1.24]],"id":43885158}]}]}
{"op":"mcm","clk":"AOaaAQDtTgCBigE=","pt":1659347692298,"mc":[{"id":"1.201590187","rc":[{"atb":[[2.06,36.51]],"id":9570503}]}]}
{"op":"mcm","clk":"AO6aAQDvTgCGigE=","pt":1659347692351,"mc":[{"id":"1.201590187","rc":[{"bdatb":[[0,2.06,36.51]],"id":9570503}]}]}
{"op":"mcm","clk":"APGaAQDyTgCJigE=","pt":1659347692401,"mc":[{"id":"1.201590187","rc":[{"atl":[[22,4.48]],"bdatl":[[7,22,4.48]],"id":45323444}]}]}
{"op":"mcm","clk":"APqaAQDzTgCMigE=","pt":1659347692451,"mc":[{"id":"1.201590187","rc":[{"atb":[[9.4,54.1],[13,2.91]],"atl":[[25,1.44]],"id":45323444},{"atb":[[1.75,34.48]],"id":9570503},{"atb":[[3.9,61.72],[6.6,3.53]],"atl":[[7,1.15]],"id":12989514},{"atb":[[5.7,61.78]],"id":44836671},{"atb":[[6.6,30.24]],"atl":[[10,1.15]],"id":43885158},{"atl":[[25,1.15]],"id":46969227}]}]}
{"op":"mcm","clk":"APqaAQD0TgCNigE=","pt":1659347692504,"mc":[{"id":"1.201590187","rc":[{"bdatb":[[0,13,2.91],[5,10.5,2.53],[6,10,13.22],[7,9.8,10.76],[8,9.6,23.69],[9,9.4,54.1]],"bdatl":[[9,25,1.92]],"id":45323444},{"bdatb":[[3,2,15.09],[4,1.99,3.5],[6,1.97,14.24],[8,1.95,12.01]],"bdatl":[[7,2.34,7.55],[8,2.36,1.83],[9,2.38,4.31]],"id":9570503},{"bdatb":[[0,6.6,3.53],[4,5.8,37.29],[6,5.6,4.84],[7,5.5,2.82],[8,5.4,5.46],[9,5.3,3.82]],"bdatl":[[0,7,1.15],[1,7.2,10.26],[2,7.6,9.11],[3,7.8,4.19],[4,8,1.76],[5,8.2,1.76],[6,8.4,4],[7,8.6,1.76],[8,8.8,1.76],[9,9,6.82]],"id":12989514},{"bdatb":[[9,15.5,5.98]],"id":44621159},{"bdatb":[[5,6.2,27.09],[6,6,230.32],[8,5.8,13.98],[9,5.7,61.78]],"id":44836671},{"bdatb":[[5,7.6,7.13],[6,7.4,5.91],[9,6.8,2.43]],"bdatl":[[0,10,1.15],[1,10.5,4.1],[2,11,3.53],[3,11.5,2.88],[4,12,9.96],[5,12.5,13.48],[6,13,1.76],[7,13.5,9.76],[8,14,13.2],[9,14.5,13.87]],"id":43885158},{"bdatl":[[0,25,1.15],[1,26,5.1],[2,27,2.51],[3,28,7.64],[4,29,1.76],[5,30,1.83],[6,32,3.23],[7,34,5],[8,36,1.76],[9,38,1.76]],"id":46969227}]}]}
{"op":"mcm","clk":"AICbAQD5TgCRigE=","pt":1659347692562,"mc":[{"id":"1.201590187","rc":[{"atb":[[13,3.1]],"atl":[[16,2]],"id":45323444},{"atl":[[10.5,3.85]],"id":43885158},{"atl":[[25,1.25]],"id":46969227}]}]}
{"op":"mcm","clk":"AICbAQD6TgCRigE=","pt":1659347692612,"mc":[{"id":"1.201590187","rc":[{"bdatb":[[0,13,3.1],[7,9.8,11.01],[8,9.6,23.15]],"bdatl":[[0,16,2]],"id":45323444},{"bdatb":[[6,1.97,12.94],[8,1.95,11.97]],"bdatl":[[9,2.38,5.35]],"id":9570503},{"bdatb":[[6,5.6,5.29],[7,5.5,1.9],[8,5.4,5.45],[9,5.3,3.83]],"id":12989514},{"bdatb":[[9,15.5,6.14]],"id":44621159},{"bdatb":[[8,5.8,13.54]],"id":44836671},{"bdatb":[[6,7.4,5.56],[9,6.8,2.8]],"bdatl":[[1,10.5,3.85]],"id":43885158},{"bdatl":[[0,25,1.25]],"id":46969227}]}]}
{"op":"mcm","clk":"AIebAQD9TgCTigE=","pt":1659347692662,"mc":[{"id":"1.201590187","rc":[{"atb":[[12.5,1.33]],"bdatb":[[1,12.5,1.33]],"id":45323444},{"atb":[[24,2.78]],"bdatb":[[1,24,2.78]],"id":44621159},{"atb":[[8.8,34.48]],"id":46969227}]}]}
{"op":"mcm","clk":"AI6bAQCBTwCYigE=","pt":1659347692771,"mc":[{"id":"1.201590187","rc":[{"atb":[[13,7.53]],"id":45323444}]}]}
{"op":"mcm","clk":"AI+bAQCBTwCaigE=","pt":1659347692821,"mc":[{"id":"1.201590187","rc":[{"bdatb":[[0,13,7.53]],"id":45323444},{"bdatl":[[9,2.38,13.96]],"id":9570503}]}]}
{"op":"mcm","clk":"AJWbAQCHTwCeigE=","pt":1659347692872,"mc":[{"id":"1.201590187","rc":[{"atl":[[7.2,7.83]],"id":12989514},{"atb":[[8.6,4.05]],"id":43885158}]}]}
{"op":"mcm","clk":"AJabAQCHTwCgigE=","pt":1659347692922,"mc":[{"id":"1.201590187","rc":[{"bdatl":[[9,2.38,5.38]],"id":9570503},{"bdatl":[[1,7.2,7.83]],"id":12989514},{"bdatb":[[0,8.6,4.69],[9,6.6,31.47]],"id":43885158}]}]}
{"op":"mcm","clk":"AJubAQCITwCligE=","pt":1659347692978,"mc":[{"id":"1.201590187","rc":[{"atb":[[25,3.3]],"id":44621159},{"atb":[[8.6,1.76]],"id":43885158}]}]}
{"op":"mcm","clk":"AJybAQCITwCmigE=","pt":1659347693029,"mc":[{"id":"1.201590187","rc":[{"bdatl":[[7,2.34,6.48],[8,2.36,1.06],[9,2.38,5.18]],"id":9570503},{"bdatb":[[0,25,3.4]],"id":44621159},{"bdatb":[[0,8.6,2.4]],"id":43885158}]}]}
{"op":"mcm","clk":"ALSbAQCOTwCyigE=","pt":1659347693287,"mc":[{"id":"1.201590187","rc":[{"atb":[[8.6,0]],"id":43885158}]}]}
{"op":"mcm","clk":"ALebAQCOTwCzigE=","pt":1659347693337,"mc":[{"id":"1.201590187","rc":[{"bdatl":[[7,2.36,6.28],[8,2.38,1.19],[9,2.4,76.27]],"id":9570503},{"bdatb":[[0,8.4,2.4],[1,8.2,1.76],[2,8,1.46],[3,7.8,2.73],[4,7.6,7.13],[5,7.4,5.56],[6,7.2,3.71],[7,7,134.41],[8,6.6,31.47],[9,6.4,11.78]],"id":43885158}]}]}
{"op":"mcm","clk":"AMebAQCRTwC7igE=","pt":1659347693499,"mc":[{"id":"1.201590187","rc":[{"atb":[[6,1.76]],"id":12989514},{"atb":[[15.5,1.76]],"id":46969227}]}]}
{"op":"mcm","clk":"AMubAQCVTwC8igE=","pt":1659347693549,"mc":[{"id":"1.201590187","rc":[{"bdatb":[[3,6,1.76],[4,5.9,1.76],[5,5.8,37.29],[6,5.7,223.76],[7,5.6,5.29],[8,5.5,1.9],[9,5.4,5.45]],"id":12989514}]}]}
{"op":"mcm","clk":"AOObAQCaTwDJigE=","pt":1659347693795,"mc":[{"id":"1.201590187","rc":[{"atb":[[13,3.1]],"id":45323444},{"atb":[[25,1]],"id":44621159},{"atb":[[8.4,0]],"id":43885158}]}]}
{"op":"mcm","clk":"AOWbAQCbTwDMigE=","pt":1659347693845,"mc":[{"id":"1.201590187","rc":[{"bdatb":[[0,13,3.1]],"id":45323444},{"bdatl":[[7,2.38,6.08],[8,2.4,72.76],[9,2.42,3.5]],"id":9570503},{"bdatb":[[0,25,1.1]],"id":44621159},{"bdatb":[[0,8.2,2.4],[1,8,1.46],[2,7.8,2.73],[3,7.6,7.13],[4,7.4,5.56],[5,7.2,3.71],[6,7,134.41],[7,6.6,31.47],[8,6.4,11.78],[9,6.2,14.82]],"id":43885158}]}]}
{"op":"mcm","clk":"APObAQCdTwDSigE=","pt":1659347694001,"mc":[{"id":"1.201590187","rc":[{"atb":[[24,5.2]],"id":44621159}]}]}
{"op":"mcm","clk":"APabAQCeTwDVigE=","pt":1659347694051,"mc":[{"id":"1.201590187","rc":[{"bdatb":[[1,24,5.2]],"id":44621159}]}]}
{"op":"mcm","clk":"APqbAQCfTwDYigE=","pt":1659347694101,"mc":[{"id":"1.201590187","rc":[{"atl":[[10,2.15]],"bdatl":[[0,10,2.15]],"id":43885158},{"bdatb":[[6,10,14.22],[7,9.8,9.99],[8,9.6,24.2]],"id":45323444},{"bdatb":[[4,1.99,8.52],[6,1.97,7.86],[8,1.95,17.1]],"id":9570503},{"bdatb":[[5,5.8,39.02],[7,5.6,3.5],[9,5.4,7.3]],"id":12989514},{"bdatb":[[9,16.5,1.28]],"id":44621159},{"bdatb":[[6,6,231.98],[8,5.8,11.81]],"id":44836671}]}]}
{"op":"mcm","clk":"AIScAQChTwDcigE=","pt":1659347694167,"mc":[{"id":"1.201590187","rc":[{"atb":[[1.02,7.55]],"atl":[[10,3.15]],"id":43885158}]}]}
{"op":"mcm","clk":"AIWcAQChTwDcigE=","pt":1659347694217,"mc":[{"id":"1.201590187","rc":[{"bdatb":[[6,10,15.22],[7,9.8,9],[8,9.6,24.43],[9,9.4,54.36]],"id":45323444},{"bdatb":[[4,1.99,13.55],[6,1.97,2.79],[8,1.95,17.6],[9,1.94,2.57]],"id":9570503},{"bdatb":[[5,5.8,40.69],[6,5.7,223.81],[7,5.6,1.76],[8,5.5,1.86],[9,5.4,7.48]],"id":12989514},{"bdatb":[[9,16.5,1.87]],"id":44621159},{"bdatb":[[6,6,233.65],[8,5.8,10.09]],"id":44836671},{"bdatl":[[0,10,3.15]],"id":43885158}]}]}
{"op":"mcm","clk":"AJacAQCkTwDkigE=","pt":1659347694388,"mc":[{"id":"1.201590187","rc":[{"atl":[[7.4,5]],"id":12989514},{"atb":[[1.02,3.55]],"atl":[[10.5,4.11]],"id":43885158}]}]}
{"op":"mcm","clk":"AJicAQCkTwDligE=","pt":1659347694439,"mc":[{"id":"1.201590187","rc":[{"bdatb":[[9,9.4,54.8]],"id":45323444},{"bdatl":[[2,7.4,5],[3,7.6,8.77],[4,7.8,4.19],[5,8,1.76],[6,8.2,1.76],[7,8.4,4],[8,8.6,1.76],[9,8.8,1.76]],"id":12989514},{"bdatb":[[7,6.6,36.07],[8,6.4,11.69],[9,6.2,10.06]],"bdatl":[[1,10.5,4.11]],"id":43885158}]}]}
{"op":"mcm","clk":"AKWcAQCmTwDsigE=","pt":1659347694571,"mc":[{"id":"1.201590187","rc":[{"atb":[[1.02,2.55]],"id":43885158}]}]}
{"op":"mcm","clk":"AK2cAQCnTwDwigE=","pt":1659347694688,"mc":[{"id":"1.201590187","rc":[{"atb":[[6.2,9.69]],"id":12989514},{"atb":[[24,2.78]],"id":44621159},{"atb":[[8.4,1],[6.8,1.76],[1.02,1.55]],"id":43885158},{"atl":[[27,0.1]],"id":46969227}]}]}
{"op":"mcm","clk":"AK2cAQCnTwDxigE=","pt":1659347694738,"mc":[{"id":"1.201590187","rc":[{"bdatl":[[7,2.36,3.56],[8,2.38,3.89],[9,2.4,73.6]],"id":9570503},{"bdatb":[[2,6.2,9.69]],"id":12989514},{"bdatb":[[1,24,2.78]],"id":44621159},{"bdatb":[[0,8.4,1.64],[1,8.2,1.76],[2,8,1.46],[3,7.8,2.73],[4,7.6,7.13],[5,7.4,5.56],[6,7.2,3.71],[7,7,134.41],[8,6.8,1.99],[9,6.6,35.84]],"id":43885158},{"bdatl":[[2,28,7.74],[3,29,1.76],[4,30,1.83],[5,32,3.23],[6,34,5],[7,36,1.76],[8,38,1.76],[9,40,5.01]],"id":46969227}]}]}
{"op":"mcm","clk":"ALOcAQCpTwDyigE=","pt":1659347694788,"mc":[{"id":"1.201590187","rc":[{"atb":[[8.4,2]],"bdatb":[[0,8.4,2.64]],"id":43885158},{"bdatl":[[7,2.36,7.12],[8,2.4,77.46],[9,2.42,1.42]],"id":9570503}]}]}
{"op":"mcm","clk":"ALmcAQCrTwD2igE=","pt":1659347694888,"mc":[{"id":"1.201590187","rc":[{"atb":[[25,3.3]],"id":44621159},{"atb":[[21,2.25]],"trd":[[21,8.92]],"ltp":21,"tv":43.91,"id":46969227}],"tv":1556.55}]}
{"op":"mcm","clk":"ALmcAQCrTwD4igE=","pt":1659347694938,"mc":[{"id":"1.201590187","rc":[{"bdatb":[[0,25,3.4]],"id":44621159},{"bdatb":[[0,21,2.25]],"id":46969227}]}]}
{"op":"mcm","clk":"AMOcAQCzTwD+igE=","pt":1659347695084,"mc":[{"id":"1.201590187","rc":[{"atb":[[2.02,22.33]],"atl":[[2.14,72.8]],"id":9570503},{"atb":[[6.2,7.29]],"atl":[[7.2,5.5]],"id":12989514},{"atb":[[7,15.76]],"atl":[[8,12.29]],"id":44836671}]}]}
{"op":"mcm","clk":"AMScAQC0TwCBiwE=","pt":1659347695135,"mc":[{"id":"1.201590187","rc":[{"bdatb":[[8,9.6,22.68],[9,9.4,56.58]],"id":45323444},{"bdatb":[[2,2.02,22.33],[8,1.95,9.78],[9,1.94,1.76]],"bdatl":[[0,2.14,72.8]],"id":9570503},{"bdatb":[[2,6.2,7.29]],"bdatl":[[1,7.2,5.5]],"id":12989514},{"bdatb":[[1,7,15.76]],"bdatl":[[2,8,12.29]],"id":44836671},{"bdatb":[[7,7,132.23],[8,6.8,4],[9,6.6,33.54]],"id":43885158}]}]}
{"op":"mcm","clk":"AMycAQC0TwCCiwE=","pt":1659347695189,"mc":[{"id":"1.201590187","rc":[{"atb":[[2.04,28.04]],"id":9570503},{"atl":[[7.4,9.33]],"id":12989514},{"atb":[[7.6,10.66]],"id":43885158}]}]}
{"op":"mcm","clk":"AM2cAQC1TwCFiwE=","pt":1659347695239,"mc":[{"id":"1.201590187","rc":[{"bdatb":[[1,2.04,28.04]],"id":9570503},{"bdatl":[[2,7.4,9.33]],"id":12989514},{"bdatb":[[4,7.6,11.72],[9,6.6,38.39]],"id":43885158}]}]}
{"op":"mcm","clk":"AO2cAQC7TwCPiwE=","pt":1659347695555,"mc":[{"id":"1.201590187","rc":[{"atb":[[25,1]],"id":44621159}]}]}
{"op":"mcm","clk":"AO2cAQC9TwCPiwE=","pt":1659347695605,"mc":[{"id":"1.201590187","rc":[{"bdatb":[[0,25,1.1]],"id":44621159}]}]}
{"op":"mcm","clk":"APucAQDETwCXiwE=","pt":1659347695763,"mc":[{"id":"1.201590187","rc":[{"atb":[[24,5.2]],"id":44621159}]}]}
{"op":"mcm","clk":"APucAQDFTwCXiwE=","pt":1659347695813,"mc":[{"id":"1.201590187","rc":[{"bdatb":[[1,24,5.2]],"id":44621159}]}]}
{"op":"mcm","clk":"AP2cAQDITwCZiwE=","pt":1659347695868,"mc":[{"id":"1.201590187","rc":[{"atb":[[7.6,6.35]],"id":43885158}]}]}
{"op":"mcm","clk":"AIKdAQDLTwCaiwE=","pt":1659347695921,"mc":[{"id":"1.201590187","rc":[{"bdatb":[[4,7.6,7.41]],"id":43885158}]}]}
{"op":"mcm","clk":"AIidAQDRTwCciwE=","pt":1659347695985,"mc":[{"id":"1.201590187","rc":[{"atb":[[7.2,8.02]],"id":43885158}]}]}
{"op":"mcm","clk":"AIqdAQDRTwCeiwE=","pt":1659347696035,"mc":[{"id":"1.201590187","rc":[{"bdatb":[[6,7.2,8.02]],"id":43885158}]}]}
{"op":"mcm","clk":"AI+dAQDSTwCiiwE=","pt":1659347696086,"mc":[{"id":"1.201590187","rc":[{"atl":[[25,0.25]],"trd":[[25,2]],"ltp":25,"tv":45.91,"id":46969227}],"tv":1558.55}]}
{"op":"mcm","clk":"AJOdAQDTTwCjiwE=","pt":1659347696136,"mc":[{"id":"1.201590187","rc":[{"bdatb":[[5,5.8,36.38],[6,5.7,228.2]],"id":12989514},{"bdatb":[[9,16,1.94]],"id":44621159},{"bdatb":[[5,6.2,26.79],[6,6,233.95]],"id":44836671},{"bdatl":[[0,26,5.35],[1,28,7.74],[2,29,1.76],[3,30,1.83],[4,32,3.23],[5,34,5],[6,36,1.76],[7,38,1.76],[8,40,5.01],[9,80,1.66]],"id":46969227}]}]}
{"op":"mcm","clk":"AJmdAQDTTwCmiwE=","pt":1659347696194,"mc":[{"id":"1.201590187","rc":[{"atl":[[2.14,67.8]],"trd":[[2.14,70.71]],"tv":962.9,"id":9570503}],"tv":1568.55}]}
{"op":"mcm","clk":"AJmdAQDTTwCoiwE=","pt":1659347696244,"mc":[{"id":"1.201590187","rc":[{"bdatl":[[0,2.14,67.8]],"id":9570503}]}]}
{"op":"mcm","clk":"AKmdAQDYTwCuiwE=","pt":1659347696404,"mc":[{"id":"1.201590187","rc":[{"atb":[[19.5,1.76]],"id":44621159}]}]}
{"op":"mcm","clk":"AKmdAQDZTwCwiwE=","pt":1659347696454,"mc":[{"id":"1.201590187","rc":[{"bdatb":[[6,19.5,1.76]],"id":44621159}]}]}
{"op":"mcm","clk":"ALCdAQDaTwCxiwE=","pt":1659347696505,"mc":[{"id":"1.201590187","rc":[{"atb":[[24,2.78],[20,3.56]],"id":44621159}]}]}
{"op":"mcm","clk":"ALedAQDcTwC2iwE=","pt":1659347696555,"mc":[{"id":"1.201590187","rc":[{"bdatb":[[1,24,2.78],[5,20,3.56]],"id":44621159}]}]}
{"op":"mcm","clk":"AL2dAQDhTwC7iwE=","pt":1659347696698,"mc":[{"id":"1.201590187","rc":[{"atb":[[25,3.3]],"id":44621159}]}]}
{"op":"mcm","clk":"AMCdAQDhTwC7iwE=","pt":1659347696748,"mc":[{"id":"1.201590187","rc":[{"bdatb":[[0,25,3.4]],"id":44621159}]}]}
{"op":"mcm","clk":"ANadAQDrTwDPiwE=","pt":1659347697068,"mc":[{"id":"1.201590187","rc":[{"atl":[[22,2.58],[21,1.76]],"id":45323444},{"atb":[[5.2,23.81],[4.9,58.02]],"id":12989514},{"atl":[[12.5,10],[12,1.76],[11.5,12.4]],"id":43885158},{"atl":[[30,5.28],[32,0]],"id":46969227}]}]}
{"op":"mcm","clk":"ANidAQDtTwDSiwE=","pt":1659347697118,"mc":[{"id":"1.201590187","rc":[{"bdatl":[[6,21,1.76],[7,22,2.58]],"id":45323444},{"bdatl":[[3,11.5,12.4],[4,12,1.76],[5,12.5,10]],"id":43885158},{"bdatl":[[3,30,5.28],[4,34,5],[5,36,1.76],[6,38,1.76],[7,40,5.01],[8,80,1.66],[9,310,1]],"id":46969227}]}]}
{"op":"mcm","clk":"AOSdAQDvTwDXiwE=","pt":1659347697269,"mc":[{"id":"1.201590187","rc":[{"atl":[[2.14,52.8]],"id":9570503}]}]}
{"op":"mcm","clk":"AOSdAQDvTwDYiwE=","pt":1659347697319,"mc":[{"id":"1.201590187","rc":[{"bdatl":[[0,2.14,52.8]],"id":9570503},{"bdatb":[[9,6.6,37.83]],"id":43885158}]}]}
{"op":"mcm","clk":"AOudAQDxTwDbiwE=","pt":1659347697388,"mc":[{"id":"1.201590187","rc":[{"atb":[[2.04,32.15],[2.02,18.27]],"atl":[[2.16,8.74],[2.14,49.19]],"id":9570503},{"atb":[[6.2,5.02],[6.4,19.2]],"id":12989514},{"atb":[[7,15.95]],"atl":[[7.8,5.53],[8,10.03]],"id":44836671},{"atb":[[7.6,4.01]],"id":43885158}]}]}
{"op":"mcm","clk":"AOydAQDxTwDbiwE=","pt":1659347697439,"mc":[{"id":"1.201590187","rc":[{"bdatb":[[1,2.04,32.15],[2,2.02,18.27]],"bdatl":[[0,2.14,49.19],[1,2.16,8.74]],"id":9570503},{"bdatb":[[1,6.4,19.2],[2,6.2,5.02]],"id":12989514},{"bdatb":[[1,7,15.95]],"bdatl":[[1,7.8,5.53],[2,8,10.03]],"id":44836671},{"bdatb":[[4,7.6,5.07],[9,6.6,36.66]],"id":43885158}]}]}
{"op":"mcm","clk":"APSdAQD1TwDeiwE=","pt":1659347697502,"mc":[{"id":"1.201590187","rc":[{"atb":[[1.75,51.72]],"id":9570503},{"atb":[[25,1]],"id":44621159}]}]}
{"op":"mcm","clk":"APedAQD1TwDfiwE=","pt":1659347697552,"mc":[{"id":"1.201590187","rc":[{"bdatb":[[0,25,1.1]],"id":44621159}]}]}
{"op":"mcm","clk":"AP6dAQD4TwDkiwE=","pt":1659347697602,"mc":[{"id":"1.201590187","rc":[{"atb":[[24,5.2]],"id":44621159},{"atb":[[6.6,47.48]],"id":43885158}]}]}
{"op":"mcm","clk":"AP6dAQD4TwDkiwE=","pt":1659347697652,"mc":[{"id":"1.201590187","rc":[{"bdatb":[[1,24,5.2]],"id":44621159},{"bdatb":[[9,6.6,53.9]],"id":43885158}]}]}
{"op":"mcm","clk":"AIieAQD6TwDoiwE=","pt":1659347697702,"mc":[{"id":"1.201590187","rc":[{"atb":[[8.8,45.97]],"id":46969227}]}]}
{"op":"mcm","clk":"AJWeAQCDUADyiwE=","pt":1659347697899,"mc":[{"id":"1.201590187","rc":[{"atl":[[24,0]],"id":45323444},{"atb":[[20,1.51]],"id":46969227}]}]}
{"op":"mcm","clk":"AJaeAQCFUAD0iwE=","pt":1659347697949,"mc":[{"id":"1.201590187","rc":[{"bdatl":[[9,25,1.44]],"id":45323444},{"bdatb":[[1,20,1.51]],"id":46969227}]}]}
{"op":"mcm","clk":"AJ2eAQCGUAD2iwE=","pt":1659347698006,"mc":[{"id":"1.201590187","rc":[{"atl":[[990,1.93]],"id":45323444},{"atb":[[19.5,8.5]],"id":46969227}]}]}
{"op":"mcm","clk":"AJ2eAQCHUAD6iwE=","pt":1659347698056,"mc":[{"id":"1.201590187","rc":[{"bdatb":[[2,19.5,8.5]],"id":46969227}]}]}
{"op":"mcm","clk":"AK6eAQCQUACGjAE=","pt":1659347698301,"mc":[{"id":"1.201590187","rc":[{"atb":[[24,2.78]],"id":44621159}]}]}
{"op":"mcm","clk":"ALCeAQCRUACHjAE=","pt":1659347698351,"mc":[{"id":"1.201590187","rc":[{"bdatb":[[1,24,2.78]],"id":44621159}]}]}
{"op":"mcm","clk":"ALqeAQCUUACQjAE=","pt":1659347698469,"mc":[{"id":"1.201590187","rc":[{"atb":[[25,3.3]],"id":44621159}]}]}
{"op":"mcm","clk":"ALqeAQCVUACQjAE=","pt":1659347698519,"mc":[{"id":"1.201590187","rc":[{"bdatb":[[0,25,3.4]],"id":44621159}]}]}
{"op":"mcm","clk":"ANSeAQCdUACijAE=","pt":1659347698869,"mc":[{"id":"1.201590187","rc":[{"atb":[[13,1.95]],"id":45323444},{"atb":[[6.6,2.38]],"atl":[[7,0]],"id":12989514},{"atb":[[21,1.1]],"atl":[[25,0.1]],"id":46969227}]}]}
{"op":"mcm","clk":"ANSeAQCfUACjjAE=","pt":1659347698919,"mc":[{"id":"1.201590187","rc":[{"bdatb":[[0,13,1.95],[5,10.5,1.76],[6,10,16.02],[8,9.6,21.84],[9,9.4,57.44]],"id":45323444},{"bdatb":[[3,2,11.07],[4,1.99,17.59],[8,1.95,5.66]],"bdatl":[[7,2.36,4.27],[8,2.38,2.83],[9,2.4,71.71]],"id":9570503},{"bdatb":[[0,6.6,2.38],[5,5.8,35.74],[6,5.7,228.85]],"bdatl":[[0,7.2,5.5],[1,7.4,9.33],[2,7.6,8.77],[3,7.8,4.19],[4,8,1.76],[5,8.2,1.76],[6,8.4,4],[7,8.6,1.76],[8,8.8,1.76],[9,9,6.82]],"id":12989514},{"bdatb":[[9,16,1.96]],"id":44621159},{"bdatb":[[5,6.2,25.79],[6,6,234.99]],"id":44836671},{"bdatb":[[4,7.6,4.01],[5,7.4,6.65],[7,7,131.08],[8,6.8,5.19]],"id":43885158},{"bdatb":[[0,21,1.1]],"bdatl":[[0,26,5.2]],"id":46969227}]}]}
{"op":"mcm","clk":"AO2eAQClUACvjAE=","pt":1659347699192,"mc":[{"id":"1.201590187","rc":[{"atb":[[11.5,8.18]],"id":45323444},{"atb":[[25,1]],"id":44621159},{"atb":[[8,4.03]],"id":43885158}]}]}
{"op":"mcm","clk":"AO6eAQClUACxjAE=","pt":1659347699243,"mc":[{"id":"1.201590187","rc":[{"bdatb":[[3,11.5,8.18]],"id":45323444},{"bdatb":[[0,25,1.1]],"id":44621159},{"bdatb":[[2,8,4.03]],"id":43885158}]}]}
{"op":"mcm","clk":"APOeAQCnUACzjAE=","pt":1659347699294,"mc":[{"id":"1.201590187","rc":[{"atb":[[24,5.2]],"id":44621159}]}]}
{"op":"mcm","clk":"APOeAQCpUAC0jAE=","pt":1659347699345,"mc":[{"id":"1.201590187","rc":[{"bdatb":[[1,24,5.2]],"id":44621159}]}]}
{"op":"mcm","clk":"APmeAQCpUAC3jAE=","pt":1659347699400,"mc":[{"id":"1.201590187","rc":[{"atb":[[20,1.76]],"id":44621159}]}]}
{"op":"mcm","clk":"APueAQCqUAC5jAE=","pt":1659347699450,"mc":[{"id":"1.201590187","rc":[{"bdatb":[[5,20,1.76]],"id":44621159}]}]}
{"op":"mcm","clk":"AIOfAQCsUAC7jAE=","pt":1659347699505,"mc":[{"id":"1.201590187","rc":[{"atb":[[2.04,36.18]],"atl":[[2.16,12.6]],"id":9570503},{"atb":[[6.4,21.63]],"atl":[[7.4,11.63]],"id":12989514},{"atb":[[19.5,3.56]],"id":44621159},{"atb":[[7,18.38]],"atl":[[7.8,7.89]],"id":44836671},{"atb":[[8,6.41]],"id":43885158}]}]}
{"op":"mcm","clk":"AISfAQCuUAC+jAE=","pt":1659347699555,"mc":[{"id":"1.201590187","rc":[{"bdatb":[[1,2.04,36.18]],"bdatl":[[1,2.16,12.6]],"id":9570503},{"bdatb":[[1,6.4,21.63]],"bdatl":[[1,7.4,11.63]],"id":12989514},{"bdatb":[[6,19.5,3.56]],"id":44621159},{"bdatb":[[1,7,18.38]],"bdatl":[[1,7.8,7.89]],"id":44836671},{"bdatb":[[2,8,6.41]],"id":43885158}]}]}
{"op":"mcm","clk":"AJufAQC5UADQjAE=","pt":1659347699969,"mc":[{"id":"1.201590187","rc":[{"atb":[[24,2.78]],"id":44621159}]}]}
{"op":"mcm","clk":"AJyfAQC8UADSjAE=","pt":1659347700020,"mc":[{"id":"1.201590187","rc":[{"bdatb":[[1,24,2.78]],"id":44621159}]}]}
{"op":"mcm","clk":"AKmfAQDEUADgjAE=","pt":1659347700186,"mc":[{"id":"1.201590187","rc":[{"atb":[[13,6.38]],"id":45323444},{"atb":[[26,0],[25,0.1]],"trd":[[26,0.2],[25,1.8]],"ltp":25,"tv":4.34,"id":44621159}],"tv":1570.55}]}
{"op":"mcm","clk":"AKqfAQDEUADhjAE=","pt":1659347700237,"mc":[{"id":"1.201590187","rc":[{"bdatb":[[0,13,6.38]],"id":45323444},{"bdatl":[[6,2.32,1.08],[7,2.34,1.34],[8,2.36,4.27],[9,2.4,74.51]],"id":9570503},{"bdatb":[[0,24,2.88],[1,23,1.76],[2,22,1.76],[3,21,5],[4,20,1.76],[5,19.5,3.56],[6,19,1.76],[7,18.5,1.37],[8,16,1.96],[9,15.5,4.19]],"id":44621159}]}]}
{"op":"mcm","clk":"ALefAQDJUADtjAE=","pt":1659347700390,"mc":[{"id":"1.201590187","rc":[{"atb":[[25,2.4]],"id":44621159}]}]}
{"op":"mcm","clk":"ALqfAQDKUADvjAE=","pt":1659347700440,"mc":[{"id":"1.201590187","rc":[{"bdatl":[[6,2.32,2.43],[7,2.36,4.27],[8,2.38,2.83],[9,2.4,71.71]],"id":9570503},{"bdatb":[[0,25,2.4],[1,24,2.78],[2,23,1.76],[3,22,1.76],[4,21,5],[5,20,1.76],[6,19.5,3.56],[7,19,1.76],[8,18.5,1.37],[9,16,1.96]],"id":44621159}]}]}
{"op":"mcm","clk":"AL+fAQDOUADyjAE=","pt":1659347700496,"mc":[{"id":"1.201590187","rc":[{"atl":[[2.14,54.19]],"id":9570503}]}]}
{"op":"mcm","clk":"AMCfAQDOUAD0jAE=","pt":1659347700546,"mc":[{"id":"1.201590187","rc":[{"bdatl":[[0,2.14,54.19]],"id":9570503},{"bdatb":[[9,6.6,55.52]],"id":43885158}]}]}
{"op":"mcm","clk":"ANefAQDdUACFjQE=","pt":1659347700908,"mc":[{"id":"1.201590187","rc":[{"atb":[[2.02,1.2]],"id":9570503}]}]}
{"op":"mcm","clk":"ANufAQDjUACKjQE=","pt":1659347700958,"mc":[{"id":"1.201590187","rc":[{"bdatb":[[2,2.02,1.2]],"id":9570503}]}]}
{"op":"mcm","clk":"AN6fAQDkUACLjQE=","pt":1659347701008,"mc":[{"id":"1.201590187","rc":[{"atl":[[1000,1.1]],"id":9570503}]}]}
{"op":"mcm","clk":"AOafAQDmUACOjQE=","pt":1659347701107,"mc":[{"id":"1.201590187","rc":[{"atl":[[38,2.87]],"bdatl":[[0,38,2.87]],"id":44621159},{"bdatb":[[9,9.4,57.82]],"id":45323444}]}]}
{"op":"mcm","clk":"AO+fAQDrUACUjQE=","pt":1659347701212,"mc":[{"id":"1.201590187","rc":[{"atb":[[13,1.95]],"id":45323444},{"atl":[[1000,0.1]],"id":9570503},{"atb":[[26,1]],"id":44621159},{"atl":[[7.6,148.33]],"trd":[[7.6,6.94]],"tv":227.44,"id":44836671},{"atl":[[27,3.1]],"id":46969227}],"tv":1574.55}]}
{"op":"mcm","clk":"APCfAQDsUACXjQE=","pt":1659347701262,"mc":[{"id":"1.201590187","rc":[{"bdatb":[[0,13,1.95]],"id":45323444},{"bdatl":[[7,2.34,4.31],[9,2.4,72.67]],"id":9570503},{"bdatb":[[0,26,1],[1,25,2.4],[2,24,2.78],[3,23,1.76],[4,22,1.76],[5,21,5],[6,20,1.76],[7,19.5,3.56],[8,19,1.76],[9,18.5,1.37]],"id":44621159},{"bdatl":[[0,7.6,148.33]],"id":44836671},{"bdatl":[[1,27,3.1],[2,28,7.64],[3,29,1.76],[4,30,5.28],[5,34,5],[6,36,1.76],[7,38,1.76],[8,40,5.01],[9,80,1.66]],"id":46969227}]}]}
{"op":"mcm","clk":"APifAQDsUACbjQE=","pt":1659347701312,"mc":[{"id":"1.201590187","rc":[{"atl":[[7.6,145.08]],"trd":[[7.6,13.44]],"bdatl":[[0,7.6,145.08]],"tv":233.94,"id":44836671}],"tv":1581.05}]}
{"op":"mcm","clk":"AIOgAQDtUACgjQE=","pt":1659347701382,"mc":[{"id":"1.201590187","rc":[{"atb":[[12.5,5.93]],"id":45323444},{"atb":[[2.02,15.66],[2,1.24]],"atl":[[1000,0]],"id":9570503},{"atb":[[6.6,0.38],[6.8,2.54]],"id":12989514},{"atb":[[6.8,5.36]],"id":44836671},{"atb":[[9,2]],"id":43885158}]}]}
{"op":"mcm","clk":"AIOgAQDtUACijQE=","pt":1659347701432,"mc":[{"id":"1.201590187","rc":[{"bdatb":[[1,12.5,5.93]],"id":45323444},{"bdatb":[[2,2.02,15.66],[3,2,1.24]],"bdatl":[[6,2.28,7.58],[7,2.32,1.09],[8,2.34,1.42],[9,2.4,72.65]],"id":9570503},{"bdatb":[[0,6.8,2.54],[1,6.4,22.01]],"id":12989514},{"bdatb":[[2,6.8,5.36]],"id":44836671},{"bdatb":[[0,9,2],[1,8.4,2.64],[2,8.2,1.76],[3,8,6.41],[4,7.8,2.73],[5,7.6,4.01],[6,7.4,6.65],[7,7.2,8.02],[8,7,131.08],[9,6.8,5.19]],"id":43885158}]}]}
{"op":"mcm","clk":"AImgAQDuUACmjQE=","pt":1659347701484,"mc":[{"id":"1.201590187","rc":[{"atb":[[2.06,36.41]],"trd":[[2.06,45.78]],"ltp":2.06,"tv":963.09,"id":9570503}],"tv":1581.24}]}
{"op":"mcm","clk":"AIygAQDuUACqjQE=","pt":1659347701534,"mc":[{"id":"1.201590187","rc":[{"bdatb":[[0,2.06,36.41]],"id":9570503}]}]}
{"op":"mcm","clk":"AJ6gAQD0UAC6jQE=","pt":1659347701798,"mc":[{"id":"1.201590187","rc":[{"atl":[[17,1.15]],"id":45323444},{"atl":[[38,4.02]],"id":44621159}]}]}
{"op":"mcm","clk":"AJ6gAQD0UAC7jQE=","pt":1659347701848,"mc":[{"id":"1.201590187","rc":[{"bdatl":[[1,17,1.15],[2,17.5,1.76],[3,18.5,1.76],[4,19,1.76],[5,19.5,1.76],[6,20,1.76],[7,21,1.76],[8,22,2.58],[9,23,1.76]],"id":45323444},{"bdatb":[[9,1.94,7.92]],"id":9570503},{"bdatb":[[9,5.4,9.66]],"id":12989514},{"bdatl":[[0,38,4.02]],"id":44621159},{"bdatb":[[9,5.7,63.12]],"id":44836671},{"bdatb":[[7,7.2,9.07],[8,7,131.71],[9,6.8,6.3]],"id":43885158}]}]}
{"op":"mcm","clk":"AKSgAQD1UAC/jQE=","pt":1659347701898,"mc":[{"id":"1.201590187","rc":[{"atl":[[7.4,13.89]],"id":12989514}]}]}
{"op":"mcm","clk":"AKWgAQD1UADBjQE=","pt":1659347701948,"mc":[{"id":"1.201590187","rc":[{"bdatl":[[1,7.4,13.89]],"id":12989514}]}]}
{"op":"mcm","clk":"AKegAQD2UADEjQE=","pt":1659347702146,"mc":[{"id":"1.201590187","rc":[{"atb":[[12.5,1.33]],"id":45323444},{"atl":[[7.2,0.35]],"id":12989514},{"atb":[[25,0.1]],"id":44621159}]}]}
{"op":"mcm","clk":"AKmgAQD6UADKjQE=","pt":1659347702196,"mc":[{"id":"1.201590187","rc":[{"bdatb":[[1,12.5,1.33],[6,10,13.13],[7,9.8,11.96],[8,9.6,21],[9,9.4,58.69]],"id":45323444},{"bdatb":[[4,1.99,3.03],[6,1.97,17.24],[8,1.95,2.02],[9,1.94,11.83]],"id":9570503},{"bdatl":[[0,7.4,14.24],[1,7.6,8.77],[2,7.8,4.19],[3,8,1.76],[4,8.2,1.76],[5,8.4,4],[6,8.6,1.76],[7,8.8,1.76],[8,9,6.82],[9,9.2,1.76]],"id":12989514},{"bdatb":[[1,24,2.88],[2,23,1.76],[3,22,1.76],[4,21,5],[5,20,1.76],[6,19.5,3.56],[7,19,1.76],[8,18.5,1.37],[9,15.5,4.34]],"id":44621159},{"bdatb":[[6,6,230.16],[8,5.8,15],[9,5.7,61.87]],"id":44836671},{"bdatb":[[6,7.4,2.66],[7,7.2,12.11],[8,7,132.79]],"id":43885158}]}]}
{"op":"mcm","clk":"ALagAQD/UADRjQE=","pt":1659347702247,"mc":[{"id":"1.201590187","rc":[{"atb":[[8.2,4.67]],"bdatb":[[2,8.2,4.67]],"id":43885158}]}]}
{"op":"mcm","clk":"AMOgAQCHUQDcjQE=","pt":1659347702407,"mc":[{"id":"1.201590187","rc":[{"atb":[[13,6.38]],"id":45323444},{"atb":[[25,0]],"atl":[[38,3.02]],"id":44621159},{"atl":[[32,1.76]],"id":46969227}]}]}
{"op":"mcm","clk":"AM2gAQCJUQDljQE=","pt":1659347702457,"mc":[{"id":"1.201590187","rc":[{"bdatb":[[0,13,6.38]],"id":45323444},{"bdatl":[[9,2.38,1.22]],"id":9570503},{"bdatb":[[1,24,2.78]],"bdatl":[[0,38,3.02]],"id":44621159},{"bdatl":[[5,32,1.76],[6,34,5],[7,36,1.76],[8,38,1.76],[9,40,5.01]],"id":46969227}]}]}
{"op":"mcm","clk":"ANOgAQCPUQDsjQE=","pt":1659347702568,"mc":[{"id":"1.201590187","rc":[{"atb":[[24,5.2]],"id":44621159}]}]}
{"op":"mcm","clk":"ANigAQCTUQDwjQE=","pt":1659347702618,"mc":[{"id":"1.201590187","rc":[{"bdatb":[[1,24,5.2]],"id":44621159}]}]}
{"op":"mcm","clk":"AP+gAQCqUQCpjgE=","pt":1659347703394,"mc":[{"id":"1.201590187","rc":[{"atb":[[13,1.95]],"id":45323444},{"atb":[[24,2.78]],"atl":[[30,0.75]],"id":44621159}]}]}
{"op":"mcm","clk":"AIWhAQCsUQCvjgE=","pt":1659347703444,"mc":[{"id":"1.201590187","rc":[{"bdatb":[[0,13,1.95],[4,11,1.46],[5,10.5,3.67],[6,10,12.87],[7,9.8,9.92]],"id":45323444},{"bdatb":[[2,2.02,16.9],[3,2,11.24],[4,1.99,1.76],[6,1.97,7.09]],"bdatl":[[9,2.4,72.65]],"id":9570503},{"bdatb":[[3,6,2.18],[4,5.9,5.15],[5,5.8,35.31],[6,5.7,225.34]],"id":12989514},{"bdatb":[[1,24,2.78]],"bdatl":[[0,38,3.77]],"id":44621159},{"bdatb":[[5,6.2,26.19],[6,6,233.07],[8,5.8,11.55]],"id":44836671},{"bdatb":[[4,7.8,3.05],[6,7.4,5.02],[7,7.2,9.34]],"id":43885158}]}]}
{"op":"mcm","clk":"AIehAQCuUQCyjgE=","pt":1659347703497,"mc":[{"id":"1.201590187","rc":[{"atb":[[13,0.45]],"trd":[[13,5.14]],"ltp":13,"tv":23.59,"id":45323444}],"tv":1584.24}]}
{"op":"mcm","clk":"AIuhAQCwUQC5jgE=","pt":1659347703547,"mc":[{"id":"1.201590187","rc":[{"bdatb":[[0,12.5,1.78],[1,12,2],[2,11.5,8.18],[3,11,1.46],[4,10.5,3.67],[5,10,12.87],[6,9.8,9.92],[7,9.6,21],[8,9.4,58.69],[9,9.2,12]],"id":45323444},{"bdatl":[[6,2.28,2.59],[7,2.3,4.94],[8,2.34,1.07],[9,2.36,1.17]],"id":9570503}]}]}
{"op":"mcm","clk":"AI2hAQCxUQC6jgE=","pt":1659347703601,"mc":[{"id":"1.201590187","rc":[{"atb":[[12.5,5.93]],"id":45323444}]}]}
{"op":"mcm","clk":"AJOhAQC1UQC/jgE=","pt":1659347703652,"mc":[{"id":"1.201590187","rc":[{"bdatb":[[0,12.5,6.38]],"id":45323444},{"bdatl":[[9,2.36,1.41]],"id":9570503}]}]}
{"op":"mcm","clk":"AJahAQC2UQDCjgE=","pt":1659347703711,"mc":[{"id":"1.201590187","rc":[{"atb":[[13,0.26]],"id":45323444}]}]}
{"op":"mcm","clk":"AJqhAQC5UQDIjgE=","pt":1659347703761,"mc":[{"id":"1.201590187","rc":[{"bdatb":[[0,12.5,6.19]],"id":45323444},{"bdatl":[[6,2.28,1.51],[7,2.3,6.02]],"id":9570503}]}]}
{"op":"mcm","clk":"AJ2hAQC5UQDMjgE=","pt":1659347703812,"mc":[{"id":"1.201590187","rc":[{"atl":[[9.4,1.76]],"id":12989514},{"atb":[[25,2.3]],"bdatb":[[1,25,2.3],[2,24,2.78],[3,23,1.76],[4,22,1.76],[5,21,5],[6,20,1.76],[7,19.5,3.56],[8,19,1.76],[9,18.5,1.37]],"id":44621159}]}]}
{"op":"mcm","clk":"AKOhAQC7UQDOjgE=","pt":1659347703864,"mc":[{"id":"1.201590187","rc":[{"atb":[[13,0.47]],"atl":[[25,0]],"id":45323444}]}]}
{"op":"mcm","clk":"AKWhAQC+UQDSjgE=","pt":1659347703914,"mc":[{"id":"1.201590187","rc":[{"bdatb":[[0,12.5,6.4]],"id":45323444},{"bdatl":[[6,2.28,2.7],[7,2.3,4.83]],"id":9570503}]}]}
{"op":"mcm","clk":"AK2hAQC/UQDZjgE=","pt":1659347703977,"mc":[{"id":"1.201590187","rc":[{"atl":[[1000,2.88],[23,3.2]],"id":45323444}]}]}
{"op":"mcm","clk":"ALKhAQDCUQDfjgE=","pt":1659347704027,"mc":[{"id":"1.201590187","rc":[{"bdatl":[[9,23,3.2]],"id":45323444}]}]}
{"op":"mcm","clk":"ALShAQDDUQDgjgE=","pt":1659347704082,"mc":[{"id":"1.201590187","rc":[{"atb":[[8.2,6.89]],"id":43885158}]}]}
{"op":"mcm","clk":"ALqhAQDEUQDojgE=","pt":1659347704132,"mc":[{"id":"1.201590187","rc":[{"bdatb":[[2,8.2,6.89]],"id":43885158}]}]}
{"op":"mcm","clk":"AMihAQDKUQD4jgE=","pt":1659347704394,"mc":[{"id":"1.201590187","rc":[{"atl":[[1000,0.01]],"id":45323444}]}]}
{"op":"mcm","clk":"ANChAQDOUQD/jgE=","pt":1659347704495,"mc":[{"id":"1.201590187","rc":[{"atb":[[12,1]],"atl":[[16,0]],"id":45323444}]}]}
{"op":"mcm","clk":"ANihAQDOUQCDjwE=","pt":1659347704545,"mc":[{"id":"1.201590187","rc":[{"bdatb":[[1,12,1]],"bdatl":[[0,17,1.15],[1,17.5,1.76],[2,18.5,1.76],[3,19,1.76],[4,19.5,1.76],[5,20,1.76],[6,21,1.76],[7,22,2.58],[8,23,3.2],[9,26,5.04]],"id":45323444},{"bdatb":[[2,2.02,15.66],[3,2,2.5],[5,1.98,80.57],[6,1.97,2.53],[8,1.95,6.38],[9,1.94,1.76]],"id":9570503},{"bdatb":[[3,6,1.76],[4,5.9,2.19],[5,5.8,38.76],[6,5.7,223.76],[8,5.5,3.4],[9,5.4,5.27]],"id":12989514},{"bdatb":[[5,6.2,25.79],[6,6,230.16],[7,5.9,12.39],[8,5.8,10],[9,5.7,61.78]],"id":44836671},{"bdatb":[[4,7.8,2.73],[5,7.6,4.34],[6,7.4,2.33],[7,7.2,10.79],[8,7,130],[9,6.8,5.87]],"id":43885158}]}]}
{"op":"mcm","clk":"ANmhAQDPUQCGjwE=","pt":1659347704603,"mc":[{"id":"1.201590187","rc":[{"atb":[[12.5,1.33],[12,0]],"id":45323444},{"atb":[[25,0]],"id":44621159}]}]}
{"op":"mcm","clk":"AOGhAQDSUQCMjwE=","pt":1659347704653,"mc":[{"id":"1.201590187","rc":[{"bdatb":[[0,12.5,1.8],[1,11.5,8.18],[2,11,1.46],[3,10.5,3.67],[4,10,12.87],[5,9.8,9.92],[6,9.6,21],[7,9.4,58.69],[8,9.2,12],[9,9,16.41]],"id":45323444},{"bdatl":[[9,2.36,1.28]],"id":9570503},{"bdatb":[[1,24,2.78],[2,23,1.76],[3,22,1.76],[4,21,5],[5,20,1.76],[6,19.5,3.56],[7,19,1.76],[8,18.5,1.37],[9,15.5,4.35]],"id":44621159}]}]}
{"op":"mcm","clk":"AOShAQDTUQCPjwE=","pt":1659347704703,"mc":[{"id":"1.201590187","rc":[{"atb":[[12,4.77]],"bdatb":[[1,12,4.77],[2,11.5,8.18],[3,11,1.46],[4,10.5,3.67],[5,10,12.87],[6,9.8,9.92],[7,9.6,21],[8,9.4,58.69],[9,9.2,12]],"id":45323444}]}]}
{"op":"mcm","clk":"AOuhAQDVUQCRjwE=","pt":1659347704762,"mc":[{"id":"1.201590187","rc":[{"atb":[[12.5,1.14],[11.5,8.39]],"atl":[[1000,0],[17,1.33]],"id":45323444}]}]}
{"op":"mcm","clk":"AO6hAQDWUQCXjwE=","pt":1659347704812,"mc":[{"id":"1.201590187","rc":[{"bdatb":[[0,12.5,1.61],[2,11.5,8.39]],"bdatl":[[0,17,1.33]],"id":45323444},{"bdatb":[[7,1.96,2.67],[8,1.95,6.33]],"bdatl":[[9,2.38,1.39]],"id":9570503},{"bdatb":[[7,5.6,1.78],[8,5.5,3.38],[9,5.4,5.83]],"id":12989514},{"bdatb":[[9,5.7,61.8]],"id":44836671},{"bdatb":[[8,7,130.01],[9,6.8,6.3]],"id":43885158}]}]}
{"op":"mcm","clk":"APOhAQDYUQCajwE=","pt":1659347704864,"mc":[{"id":"1.201590187","rc":[{"atb":[[12.5,1.35]],"trd":[[13,5.15]],"tv":23.6,"id":45323444},{"atb":[[24,5.2]],"id":44621159}],"tv":1584.25}]}
{"op":"mcm","clk":"APqhAQDYUQCcjwE=","pt":1659347704914,"mc":[{"id":"1.201590187","rc":[{"bdatb":[[0,12.5,1.82]],"id":45323444},{"bdatl":[[6,2.28,2.67],[7,2.3,4.86],[9,2.36,1.35]],"id":9570503},{"bdatb":[[1,24,5.2]],"id":44621159}]}]}
{"op":"mcm","clk":"AI6iAQDmUQCxjwE=","pt":1659347705278,"mc":[{"id":"1.201590187","rc":[{"atb":[[12.5,2.5]],"id":45323444},{"atb":[[6.8,3.69]],"atl":[[7.2,1.5]],"id":12989514},{"atb":[[8.6,1.15]],"id":43885158},{"atb":[[20,2.66]],"atl":[[25,1.25]],"id":46969227}]}]}
{"op":"mcm","clk":"AJWiAQDpUQC2jwE=","pt":1659347705328,"mc":[{"id":"1.201590187","rc":[{"bdatb":[[0,12.5,2.97],[3,11,2.21],[4,10.5,2.88],[5,10,13.75],[6,9.8,9.03]],"id":45323444},{"bdatb":[[3,2,6.64],[4,1.99,7.65],[5,1.98,70.48],[7,1.96,7.07],[8,1.95,1.9]],"bdatl":[[7,2.3,5.18],[8,2.32,2.43],[9,2.36,1.01]],"id":9570503},{"bdatb":[[0,6.8,3.69],[4,5.9,5.58],[5,5.8,35.31],[7,5.6,3.32],[8,5.5,1.81]],"bdatl":[[0,7.2,1.5],[1,7.4,13.89],[2,7.6,8.77],[3,7.8,4.19],[4,8,1.76],[5,8.2,1.76],[6,8.4,4],[7,8.6,1.76],[8,8.8,1.76],[9,9,6.82]],"id":12989514},{"bdatb":[[9,15.5,4.89]],"id":44621159},{"bdatb":[[6,6,233.49],[7,5.9,9],[9,5.7,63.32]],"id":44836671},{"bdatb":[[1,8.6,1.79],[2,8.4,2],[3,8.2,6.89],[4,8,6.41],[5,7.8,2.73],[6,7.6,5.43],[7,7.4,3.9],[8,7.2,8.02],[9,7,131.25]],"id":43885158},{"bdatb":[[1,20,2.66]],"bdatl":[[0,25,1.25],[1,26,5.1],[2,27,3.1],[3,28,7.64],[4,29,1.76],[5,30,5.28],[6,32,1.76],[7,34,5],[8,36,1.76],[9,38,1.76]],"id":46969227}]}]}
{"op":"mcm","clk":"AJaiAQDpUQC5jwE=","pt":1659347705378,"mc":[{"id":"1.201590187","rc":[{"atb":[[1.02,0]],"id":45323444},{"atb":[[2.04,27.73]],"id":9570503}]}]}
{"op":"mcm","clk":"AJqiAQDsUQC8jwE=","pt":1659347705428,"mc":[{"id":"1.201590187","rc":[{"bdatb":[[1,2.04,27.73]],"id":9570503}]}]}
{"op":"mcm","clk":"AJyiAQDuUQDAjwE=","pt":1659347705490,"mc":[{"id":"1.201590187","rc":[{"atb":[[12.5,8.2]],"atl":[[17,2.33]],"id":45323444},{"atb":[[2.06,43.31]],"atl":[[2.14,44.19],[2.44,0],[2.52,25.2],[2.4,0]],"id":9570503},{"atb":[[6.6,7.28]],"atl":[[7.6,12.03]],"id":12989514},{"atb":[[24,2.91],[23,6.31]],"id":44621159},{"atl":[[12.5,13.48]],"id":43885158}]}]}
{"op":"mcm","clk":"AKCiAQDwUQDDjwE=","pt":1659347705540,"mc":[{"id":"1.201590187","rc":[{"bdatb":[[0,12.5,8.67]],"bdatl":[[0,17,2.33]],"id":45323444},{"bdatb":[[0,2.06,43.31],[7,1.96,7.2],[8,1.95,1.76],[9,1.94,5.94]],"bdatl":[[0,2.14,44.19]],"id":9570503},{"bdatb":[[1,6.6,7.28],[2,6.4,21.63],[3,6.2,5.02],[4,6,1.76],[5,5.9,5.58],[6,5.8,35.31],[7,5.7,223.76],[8,5.6,3.37],[9,5.5,1.76]],"bdatl":[[2,7.6,12.03]],"id":12989514},{"bdatb":[[1,24,2.91],[2,23,6.31]],"id":44621159},{"bdatb":[[9,5.7,63.36]],"id":44836671},{"bdatb":[[9,7,132.44]],"bdatl":[[5,12.5,13.48]],"id":43885158}]}]}
{"op":"mcm","clk":"AKiiAQD1UQDWjwE=","pt":1659347705791,"mc":[{"id":"1.201590187","rc":[{"atb":[[24,0.49]],"id":44621159}]}]}
{"op":"mcm","clk":"ALGiAQD7UQDejwE=","pt":1659347705841,"mc":[{"id":"1.201590187","rc":[{"atl":[[7.4,13.39],[7.2,0]],"trd":[[7.4,13.39],[7.2,6.24]],"bdatl":[[0,7.4,13.39],[1,7.6,12.03],[2,7.8,4.19],[3,8,1.76],[4,8.2,1.76],[5,8.4,4],[6,8.6,1.76],[7,8.8,1.76],[8,9,6.82],[9,9.2,1.76]],"ltp":7.4,"tv":124.27,"id":12989514},{"bdatb":[[3,11,1.23],[4,10.5,3.91]],"id":45323444},{"bdatb":[[3,2,1.24],[4,1.99,13.07]],"id":9570503},{"bdatb":[[8,15.5,4.19],[9,14.5,2.17],[1,23,6.8],[2,22,1.76],[3,21,5],[4,20,1.76],[5,19.5,3.56],[6,19,1.76],[7,18.5,1.37]],"id":44621159},{"bdatb":[[6,7.6,4.01],[7,7.4,5.36]],"id":43885158}],"tv":1588.24}]}
{"op":"mcm","clk":"ALKiAQD7UQDkjwE=","pt":1659347705900,"mc":[{"id":"1.201590187","rc":[{"atl":[[23,1.76]],"id":45323444},{"atb":[[25,2.3]],"id":44621159}]}]}
{"op":"mcm","clk":"ALiiAQD/UQDnjwE=","pt":1659347705951,"mc":[{"id":"1.201590187","rc":[{"bdatl":[[8,23,1.76]],"id":45323444},{"bdatb":[[1,25,2.3],[2,23,6.8],[3,22,1.76],[4,21,5],[5,20,1.76],[6,19.5,3.56],[7,19,1.76],[8,18.5,1.37],[9,15.5,4.19]],"id":44621159}]}]}
{"op":"mcm","clk":"AL+iAQCDUgDrjwE=","pt":1659347706020,"mc":[{"id":"1.201590187","rc":[{"atl":[[24,1.44]],"id":45323444},{"atb":[[6.8,4.22]],"atl":[[7.6,11.69]],"id":12989514}]}]}
{"op":"mcm","clk":"AMCiAQCDUgDvjwE=","pt":1659347706071,"mc":[{"id":"1.201590187","rc":[{"bdatl":[[9,24,1.44]],"id":45323444},{"bdatl":[[9,2.34,2.16]],"id":9570503},{"bdatb":[[0,6.8,4.22]],"bdatl":[[1,7.6,11.69]],"id":12989514}]}]}
{"op":"mcm","clk":"AMuiAQCNUgD6jwE=","pt":1659347706229,"mc":[{"id":"1.201590187","rc":[{"atb":[[11.5,5.75]],"id":45323444},{"atl":[[7.6,15.4],[7.4,11.08]],"id":12989514},{"atb":[[9,0]],"trd":[[9,8]],"ltp":9,"tv":197.09,"id":43885158}],"tv":1592.24}]}
{"op":"mcm","clk":"AM6iAQCNUgD8jwE=","pt":1659347706286,"mc":[{"id":"1.201590187","rc":[{"bdatb":[[2,11.5,5.75]],"id":45323444},{"bdatl":[[6,2.3,2.45],[7,2.32,4.26],[8,2.34,3.24],[9,2.36,2.37]],"id":9570503},{"bdatl":[[0,7.4,11.08],[1,7.6,15.4]],"id":12989514},{"bdatb":[[0,8.6,1.79],[1,8.4,2],[2,8.2,6.89],[3,8,6.41],[4,7.8,2.73],[5,7.6,4.01],[6,7.4,5.36],[7,7.2,8.02],[8,7,132.44],[9,6.8,6.3]],"id":43885158}]}]}
{"op":"mcm","clk":"ANWiAQCOUgD+jwE=","pt":1659347706336,"mc":[{"id":"1.201590187","rc":[{"atb":[[12.5,6.6]],"id":45323444},{"atb":[[1.8,2.88]],"atl":[[7.4,8.83]],"id":12989514}]}]}
{"op":"mcm","clk":"ANWiAQCOUgCCkAE=","pt":1659347706387,"mc":[{"id":"1.201590187","rc":[{"bdatb":[[0,12.5,7.07],[8,9.4,57.69]],"id":45323444},{"bdatl":[[0,7.4,8.83]],"id":12989514},{"bdatb":[[9,6.8,5.55]],"id":43885158}]}]}
{"op":"mcm","clk":"AN6iAQCQUgCCkAE=","pt":1659347706437,"mc":[{"id":"1.201590187","rc":[{"atb":[[1.02,1.6]],"id":45323444}]}]}
{"op":"mcm","clk":"AOeiAQCQUgCIkAE=","pt":1659347706488,"mc":[{"id":"1.201590187","rc":[{"atl":[[1000,0.41]],"id":45323444}]}]}
{"op":"mcm","clk":"APCiAQCWUgCRkAE=","pt":1659347706691,"mc":[{"id":"1.201590187","rc":[{"bdatb":[[1,11.5,5.75],[2,11,1.23],[3,10.5,3.91],[4,10,13.75],[5,9.8,9.03],[6,9.6,21],[7,9.4,57.69],[8,9.2,12],[9,9,14.04]],"id":45323444},{"bdatl":[[9,2.36,1.23]],"id":9570503},{"bdatb":[[1,23,6.8],[2,22,1.76],[3,21,5],[4,20,1.76],[5,19.5,3.56],[6,19,1.76],[7,18.5,1.37],[8,15.5,4.19],[9,14.5,2.17]],"id":44621159}]}]}
{"op":"mcm","clk":"APKiAQCZUgCRkAE=","pt":1659347706741,"mc":[{"id":"1.201590187","rc":[{"atb":[[12,0]],"atl":[[1000,0]],"id":45323444},{"atb":[[1.8,0.01]],"id":12989514},{"atb":[[25,0]],"id":44621159}]}]}
{"op":"mcm","clk":"APmiAQCaUgCWkAE=","pt":1659347706791,"mc":[{"id":"1.201590187","rc":[{"atl":[[16.5,0.41]],"id":45323444}]}]}
{"op":"mcm","clk":"APmiAQCaUgCWkAE=","pt":1659347706841,"mc":[{"id":"1.201590187","rc":[{"bdatl":[[0,17,2.74]],"id":45323444},{"bdatb":[[3,2,4.63],[4,1.99,9.66],[9,1.94,9.44]],"id":9570503},{"bdatb":[[9,14.5,2.15]],"id":44621159},{"bdatb":[[8,7,133.41],[9,6.8,4.55]],"id":43885158}]}]}
{"op":"mcm","clk":"APqiAQCbUgCZkAE=","pt":1659347706892,"mc":[{"id":"1.201590187","rc":[{"atb":[[13,4.89]],"atl":[[16.5,0.59]],"id":45323444},{"atl":[[24,10]],"id":46969227}]}]}
{"op":"mcm","clk":"AP6iAQCbUgCckAE=","pt":1659347706942,"mc":[{"id":"1.201590187","rc":[{"bdatb":[[0,13,4.89],[1,12.5,6.6],[2,11.5,5.75],[3,11,1.23],[4,10.5,3.91],[5,10,13.77],[6,9.8,9],[7,9.6,24.52],[8,9.4,55.09],[9,9.2,12]],"bdatl":[[0,17,2.92]],"id":45323444},{"bdatb":[[3,2,12.49],[4,1.99,1.76],[6,1.97,7.09],[7,1.96,2.62],[8,1.95,10.92],[9,1.94,10]],"bdatl":[[7,2.32,7.53],[8,2.34,1.24],[9,2.36,1.14]],"id":9570503},{"bdatb":[[4,6,3.39],[5,5.9,3.93],[7,5.7,225.34],[8,5.6,1.76],[9,5.5,9.61]],"id":12989514},{"bdatb":[[8,15.5,4.82],[9,15,1.45]],"id":44621159},{"bdatb":[[8,5.8,11.55],[9,5.7,61.78]],"id":44836671},{"bdatb":[[5,7.6,5.29],[6,7.4,4.05],[8,7,136.12],[9,6.8,3.96]],"id":43885158},{"bdatl":[[0,24,10],[1,25,1.25],[2,26,5.1],[3,27,3.1],[4,28,7.64],[5,29,1.76],[6,30,5.28],[7,32,1.76],[8,34,5],[9,36,1.76]],"id":46969227}]}]}
{"op":"mcm","clk":"AIWjAQCdUgCgkAE=","pt":1659347707005,"mc":[{"id":"1.201590187","rc":[{"atl":[[24,10.22]],"id":46969227}]}]}
{"op":"mcm","clk":"AIajAQCdUgChkAE=","pt":1659347707055,"mc":[{"id":"1.201590187","rc":[{"bdatl":[[0,24,10.22]],"id":46969227}]}]}
{"op":"mcm","clk":"AIujAQCfUgCnkAE=","pt":1659347707105,"mc":[{"id":"1.201590187","rc":[{"atb":[[24,2.91]],"bdatb":[[1,24,2.91],[2,23,6.31],[3,22,1.76],[4,21,5],[5,20,1.76],[6,19.5,3.56],[7,19,1.76],[8,18.5,1.37],[9,15.5,4.82]],"id":44621159}]}]}
{"op":"mcm","clk":"AI+jAQCgUgCrkAE=","pt":1659347707202,"mc":[{"id":"1.201590187","rc":[{"atb":[[1.8,0]],"atl":[[7.6,19.1]],"id":12989514}]}]}
{"op":"mcm","clk":"AJKjAQCgUgCrkAE=","pt":1659347707252,"mc":[{"id":"1.201590187","rc":[{"bdatl":[[1,7.6,19.1]],"id":12989514}]}]}
{"op":"mcm","clk":"AJajAQChUgCvkAE=","pt":1659347707309,"mc":[{"id":"1.201590187","rc":[{"atl":[[7.4,8.82]],"trd":[[7.4,13.4]],"tv":124.28,"id":12989514},{"atb":[[8.2,3.99],[8,3.83]],"id":43885158}],"tv":1592.25}]}
{"op":"mcm","clk":"AJejAQChUgCwkAE=","pt":1659347707359,"mc":[{"id":"1.201590187","rc":[{"bdatb":[[9,1.94,9.97]],"id":9570503},{"bdatl":[[0,7.4,8.82]],"id":12989514},{"bdatb":[[2,8.2,3.99],[3,8,3.83],[8,7,136.11]],"id":43885158}]}]}
{"op":"mcm","clk":"AJyjAQCiUgC0kAE=","pt":1659347707414,"mc":[{"id":"1.201590187","rc":[{"atl":[[7.4,5.97]],"trd":[[7.4,19.1]],"tv":129.98,"id":12989514},{"atb":[[7.2,3.71]],"id":43885158}],"tv":1597.95}]}
{"op":"mcm","clk":"AJ2jAQCjUgC2kAE=","pt":1659347707464,"mc":[{"id":"1.201590187","rc":[{"bdatb":[[7,9.6,22.32],[8,9.4,57.34]],"id":45323444},{"bdatb":[[8,1.95,8.27],[9,1.94,4.43]],"id":9570503},{"bdatl":[[0,7.4,5.97]],"id":12989514},{"bdatb":[[7,7.2,3.71],[8,7,133.84],[9,6.8,6.3]],"id":43885158}]}]}
{"op":"mcm","clk":"AKKjAQCkUgC3kAE=","pt":1659347707514,"mc":[{"id":"1.201590187","rc":[{"atb":[[8,8.14]],"bdatb":[[3,8,8.14]],"id":43885158}]}]}
{"op":"mcm","clk":"ALKjAQCsUgDKkAE=","pt":1659347707821,"mc":[{"id":"1.201590187","rc":[{"atb":[[13.5,1.76]],"id":45323444}]}]}
{"op":"mcm","clk":"ALKjAQCuUgDKkAE=","pt":1659347707871,"mc":[{"id":"1.201590187","rc":[{"bdatb":[[0,13.5,1.76],[1,13,4.89],[2,12.5,6.6],[3,11.5,5.75],[4,11,1.23],[5,10.5,3.91],[6,10,13.77],[7,9.8,9],[8,9.6,22.32],[9,9.4,57.34]],"id":45323444},{"bdatl":[[6,2.28,2.47],[7,2.3,7.59]],"id":9570503}]}]}
{"op":"mcm","clk":"ALmjAQCvUgDNkAE=","pt":1659347707922,"mc":[{"id":"1.201590187","rc":[{"atl":[[7.4,4.33]],"id":12989514},{"atb":[[24,0.49]],"id":44621159}]}]}
{"op":"mcm","clk":"ALyjAQCwUgDRkAE=","pt":1659347707972,"mc":[{"id":"1.201590187","rc":[{"bdatb":[[8,9.6,21.06],[9,9.4,58.63]],"id":45323444},{"bdatb":[[8,1.95,2.04],[9,1.94,10.69]],"id":9570503},{"bdatl":[[0,7.4,4.33]],"id":12989514},{"bdatb":[[1,23,6.8],[2,22,1.76],[3,21,5],[4,20,1.76],[5,19.5,3.56],[6,19,1.76],[7,18.5,1.37],[8,15.5,4.82],[9,15,1.45]],"id":44621159}]}]}
{"op":"mcm","clk":"AMCjAQCxUgDSkAE=","pt":1659347708038,"mc":[{"id":"1.201590187","rc":[{"atb":[[13.5,1.97]],"id":45323444}]}]}
{"op":"mcm","clk":"AMKjAQCzUgDXkAE=","pt":1659347708088,"mc":[{"id":"1.201590187","rc":[{"bdatb":[[0,13.5,1.97]],"id":45323444},{"bdatl":[[8,2.32,1.25]],"id":9570503}]}]}
{"op":"mcm","clk":"AMajAQC1UgDckAE=","pt":1659347708138,"mc":[{"id":"1.201590187","rc":[{"atb":[[25,2.3]],"bdatb":[[1,25,2.3],[2,23,6.8],[3,22,1.76],[4,21,5],[5,20,1.76],[6,19.5,3.56],[7,19,1.76],[8,18.5,1.37],[9,15.5,4.82]],"id":44621159},{"bdatl":[[9,2.34,1.15]],"id":9570503}]}]}
{"op":"mcm","clk":"ANSjAQC5UgDrkAE=","pt":1659347708402,"mc":[{"id":"1.201590187","rc":[{"atl":[[7.4,6.68]],"id":12989514}]}]}
{"op":"mcm","clk":"ANmjAQC5UgDzkAE=","pt":1659347708452,"mc":[{"id":"1.201590187","rc":[{"bdatb":[[8,9.6,22.87],[9,9.4,56.78]],"id":45323444},{"bdatb":[[8,1.95,10.92],[9,1.94,1.79]],"id":9570503},{"bdatl":[[0,7.4,6.68]],"id":12989514}]}]}
{"op":"mcm","clk":"AN2jAQC6UgD0kAE=","pt":1659347708503,"mc":[{"id":"1.201590187","rc":[{"atb":[[13.5,0.21]],"id":45323444},{"atl":[[7.4,8.88]],"id":12989514}]}]}
{"op":"mcm","clk":"AN6jAQC6UgD5kAE=","pt":1659347708553,"mc":[{"id":"1.201590187","rc":[{"bdatb":[[0,13,5.1],[1,12.5,6.6],[2,11.5,5.75],[3,11,1.23],[4,10.5,3.91],[5,10,13.77],[6,9.8,9],[7,9.6,24.57],[8,9.4,55.04],[9,9.2,12]],"id":45323444},{"bdatb":[[9,1.94,10.2]],"bdatl":[[6,2.28,1.24],[7,2.3,1.22],[8,2.32,7.53],[9,2.34,2.39]],"id":9570503},{"bdatl":[[0,7.4,8.88]],"id":12989514},{"bdatb":[[8,7,136.17],[9,6.8,3.9]],"id":43885158}]}]}
{"op":"mcm","clk":"AOOjAQC7UgD9kAE=","pt":1659347708618,"mc":[{"id":"1.201590187","rc":[{"atb":[[8.2,1.76]],"id":43885158},{"atl":[[24,5.22]],"id":46969227}]}]}
{"op":"mcm","clk":"AOOjAQC7UgCBkQE=","pt":1659347708668,"mc":[{"id":"1.201590187","rc":[{"bdatb":[[2,8.2,1.76]],"id":43885158},{"bdatl":[[0,24,5.22]],"id":46969227}]}]}
{"op":"mcm","clk":"APGjAQDBUgCFkQE=","pt":1659347708829,"mc":[{"id":"1.201590187","rc":[{"atb":[[13,0.47]],"id":45323444},{"atb":[[25,0]],"id":44621159}]}]}
{"op":"mcm","clk":"APGjAQDBUgCMkQE=","pt":1659347708879,"mc":[{"id":"1.201590187","rc":[{"bdatb":[[0,12.5,7.28],[1,11.5,5.75],[2,11,1.23],[3,10.5,3.91],[4,10,13.77],[5,9.8,9],[6,9.6,24.57],[7,9.4,55.04],[8,9.2,12],[9,9,15.21]],"id":45323444},{"bdatl":[[8,2.32,4.26],[9,2.34,3.24]],"id":9570503},{"bdatb":[[1,23,6.8],[2,22,1.76],[3,21,5],[4,20,1.76],[5,19.5,3.56],[6,19,1.76],[7,18.5,1.37],[8,15.5,4.82],[9,15,1.45]],"id":44621159}]}]}
{"op":"mcm","clk":"APejAQDEUgCOkQE=","pt":1659347708933,"mc":[{"id":"1.201590187","rc":[{"atl":[[10,2.15]],"id":43885158}]}]}
{"op":"mcm","clk":"APijAQDEUgCQkQE=","pt":1659347708983,"mc":[{"id":"1.201590187","rc":[{"bdatb":[[3,10.5,3.81],[4,10,12.97],[6,9.6,25.39],[7,9.4,54.1],[8,9.2,12.12],[9,9,16.21]],"id":45323444},{"bdatb":[[3,2,11.99],[5,1.98,70.99],[6,1.97,2.53],[8,1.95,15.53],[9,1.94,9.65]],"id":9570503},{"bdatb":[[5,5.9,3.75],[6,5.8,35.48],[7,5.7,223.76],[9,5.5,9.43]],"id":12989514},{"bdatb":[[9,14,2.77]],"id":44621159},{"bdatb":[[6,6,233.32],[7,5.9,9.17],[8,5.8,10]],"id":44836671},{"bdatl":[[0,10,2.15]],"id":43885158}]}]}
{"op":"mcm","clk":"APqjAQDGUgCRkQE=","pt":1659347709034,"mc":[{"id":"1.201590187","rc":[{"atb":[[24,2.91]],"id":44621159}]}]}
{"op":"mcm","clk":"APyjAQDGUgCUkQE=","pt":1659347709084,"mc":[{"id":"1.201590187","rc":[{"bdatb":[[1,24,2.91],[2,23,6.31],[3,22,1.76],[4,21,5],[5,20,1.76],[6,19.5,3.56],[7,19,1.76],[8,18.5,1.37],[9,15.5,4.82]],"id":44621159}]}]}
{"op":"mcm","clk":"AIakAQDLUgCckQE=","pt":1659347709218,"mc":[{"id":"1.201590187","rc":[{"atb":[[11.5,9.14]],"id":45323444},{"atb":[[7.8,8.04]],"id":43885158}]}]}
{"op":"mcm","clk":"AImkAQDPUgChkQE=","pt":1659347709268,"mc":[{"id":"1.201590187","rc":[{"bdatb":[[1,11.5,9.14]],"id":45323444},{"bdatb":[[4,7.8,8.04]],"id":43885158}]}]}
{"op":"mcm","clk":"AI6kAQDTUgCnkQE=","pt":1659347709336,"mc":[{"id":"1.201590187","rc":[{"atb":[[13.5,1.97]],"id":45323444}]}]}
{"op":"mcm","clk":"AJOkAQDTUgCukQE=","pt":1659347709387,"mc":[{"id":"1.201590187","rc":[{"bdatb":[[0,13.5,1.97],[1,12.5,7.07],[2,11.5,9.14],[3,11,1.23],[4,10.5,3.81],[5,10,12.97],[6,9.8,9],[7,9.6,25.39],[8,9.4,54.1],[9,9.2,12.12]],"id":45323444},{"bdatl":[[6,2.28,2.47],[7,2.3,7.59],[8,2.32,1.25],[9,2.36,1.14]],"id":9570503}]}]}
{"op":"mcm","clk":"AJykAQDUUgCzkQE=","pt":1659347709489,"mc":[{"id":"1.201590187","rc":[{"atb":[[12.5,3.5]],"id":45323444},{"atl":[[2.16,8.6]],"id":9570503},{"atb":[[6.8,2.22]],"atl":[[7.6,15.84]],"trd":[[6.8,30.53]],"ltp":6.8,"tv":133.98,"id":12989514},{"atl":[[10.5,1.41]],"id":43885158},{"atl":[[27,0.1]],"id":46969227}],"tv":1601.95}]}
{"op":"mcm","clk":"AJykAQDWUgCzkQE=","pt":1659347709539,"mc":[{"id":"1.201590187","rc":[{"bdatb":[[1,12.5,3.97],[7,9.6,22.44],[9,9.2,15.2]],"id":45323444},{"bdatb":[[8,1.95,8.84],[9,1.94,1.76]],"bdatl":[[1,2.16,8.6],[7,2.3,4.11],[8,2.34,4.66],[9,2.38,2.66]],"id":9570503},{"bdatb":[[0,6.8,2.22],[9,5.5,4.27]],"bdatl":[[1,7.6,15.84]],"id":12989514},{"bdatl":[[1,10.5,1.41]],"id":43885158},{"bdatl":[[3,28,7.74],[4,29,1.76],[5,30,5.28],[6,32,1.76],[7,34,5],[8,36,1.76],[9,38,1.76]],"id":46969227}]}]}
{"op":"mcm","clk":"AKKkAQDWUgC5kQE=","pt":1659347709602,"mc":[{"id":"1.201590187","rc":[{"atl":[[2.18,11.88]],"id":9570503},{"atb":[[6.6,11.48]],"atl":[[7.4,11.88]],"id":12989514}]}]}
{"op":"mcm","clk":"AKKkAQDWUgC5kQE=","pt":1659347709652,"mc":[{"id":"1.201590187","rc":[{"bdatb":[[9,9.2,16.22]],"id":45323444},{"bdatl":[[2,2.18,11.88]],"id":9570503},{"bdatb":[[1,6.6,11.48]],"bdatl":[[0,7.4,11.88]],"id":12989514},{"bdatb":[[8,7,138.25],[9,6.8,2.9]],"id":43885158}]}]}
{"op":"mcm","clk":"AKykAQDZUgDDkQE=","pt":1659347709800,"mc":[{"id":"1.201590187","rc":[{"atb":[[9.4,45.48]],"id":45323444},{"atb":[[3.9,44.48]],"id":12989514},{"atb":[[24,0.49],[11,17.24]],"id":44621159},{"atb":[[5.6,29.24]],"id":44836671}]}]}
{"op":"mcm","clk":"AK2kAQDZUgDDkQE=","pt":1659347709851,"mc":[{"id":"1.201590187","rc":[{"bdatb":[[8,9.4,45.48]],"id":45323444},{"bdatb":[[1,23,6.8],[2,22,1.76],[3,21,5],[4,20,1.76],[5,19.5,3.56],[6,19,1.76],[7,18.5,1.37],[8,15.5,4.82],[9,14,1.84]],"id":44621159}]}]}
{"op":"mcm","clk":"ALKkAQDaUgDHkQE=","pt":1659347709905,"mc":[{"id":"1.201590187","rc":[{"atb":[[8,3.83]],"id":43885158}]}]}
{"op":"mcm","clk":"ALKkAQDaUgDHkQE=","pt":1659347709955,"mc":[{"id":"1.201590187","rc":[{"bdatb":[[3,8,3.83]],"id":43885158}]}]}
{"op":"mcm","clk":"ALakAQDbUgDMkQE=","pt":1659347710007,"mc":[{"id":"1.201590187","rc":[{"atb":[[13,4.89]],"id":45323444},{"atb":[[7.4,6.63]],"id":43885158}]}]}
{"op":"mcm","clk":"ALikAQDbUgDPkQE=","pt":1659347710057,"mc":[{"id":"1.201590187","rc":[{"bdatb":[[1,13,4.89],[2,12.5,3.5],[3,11.5,9.14],[4,11,1.23],[5,10.5,3.81],[6,10,12.97],[7,9.8,9],[8,9.6,22.44],[9,9.4,45.48]],"id":45323444},{"bdatb":[[6,7.4,8.35]],"id":43885158}]}]}
{"op":"mcm","clk":"ALqkAQDdUgDSkQE=","pt":1659347710107,"mc":[{"id":"1.201590187","rc":[{"atb":[[13.5,0.21]],"id":45323444}]}]}
{"op":"mcm","clk":"ALukAQDdUgDTkQE=","pt":1659347710157,"mc":[{"id":"1.201590187","rc":[{"bdatb":[[0,13,5.1],[1,12.5,3.5],[2,11.5,9.14],[3,11,1.23],[4,10.5,3.81],[5,10,12.97],[6,9.8,9],[7,9.6,22.44],[8,9.4,45.48],[9,9.2,16.22]],"id":45323444},{"bdatl":[[6,2.28,1.24],[7,2.3,1.22],[8,2.32,4.08],[9,2.34,3.42]],"id":9570503}]}]}
{"op":"mcm","clk":"AMGkAQDeUgDWkQE=","pt":1659347710211,"mc":[{"id":"1.201590187","rc":[{"atb":[[25,2.3]],"id":44621159},{"atb":[[8.4,0]],"atl":[[10,1.15]],"id":43885158}]}]}
{"op":"mcm","clk":"AMGkAQDgUgDXkQE=","pt":1659347710261,"mc":[{"id":"1.201590187","rc":[{"bdatb":[[4,10.5,2.86],[5,10,13.97],[7,9.6,21.39]],"id":45323444},{"bdatb":[[3,2,6.99],[5,1.98,76.04],[8,1.95,3.71]],"bdatl":[[9,2.36,3.39]],"id":9570503},{"bdatb":[[5,5.9,2.06],[6,5.8,37.21],[9,5.5,2.45]],"id":12989514},{"bdatb":[[1,25,2.3],[2,23,6.8],[3,22,1.76],[4,21,5],[5,20,1.76],[6,19.5,3.56],[7,19,1.76],[8,18.5,1.37],[9,15.5,4.82]],"id":44621159},{"bdatb":[[6,6,231.66],[7,5.9,10.87]],"id":44836671},{"bdatb":[[1,8.2,1.76],[2,8,3.83],[3,7.8,8.04],[4,7.6,5.29],[5,7.4,8.35],[6,7.2,3.71],[7,7,138.25],[8,6.8,2.9],[9,6.6,48.48]],"bdatl":[[0,10,1.15]],"id":43885158}]}]}
{"op":"mcm","clk":"AMWkAQDiUgDakQE=","pt":1659347710315,"mc":[{"id":"1.201590187","rc":[{"atb":[[7.8,2.73]],"id":43885158}]}]}
{"op":"mcm","clk":"AM6kAQDkUgDgkQE=","pt":1659347710542,"mc":[{"id":"1.201590187","rc":[{"atb":[[19,3.56],[19.5,1.76]],"bdatb":[[6,19.5,1.76]],"id":44621159},{"atl":[[10.5,1.15]],"bdatb":[[3,7.8,2.73]],"bdatl":[[1,10.5,1.15]],"id":43885158},{"bdatb":[[7,9.6,21.11]],"id":45323444},{"bdatb":[[8,1.95,2.31]],"id":9570503},{"bdatb":[[9,5.5,1.96]],"id":12989514}],"con":true}]}
{"op":"mcm","clk":"AM+kAQDkUgDhkQE=","pt":1659347710593,"mc":[{"id":"1.201590187","rc":[{"bdatb":[[7,19,3.56]],"id":44621159}]}]}
{"op":"mcm","clk":"ANikAQDpUgDpkQE=","pt":1659347710722,"mc":[{"id":"1.201590187","rc":[{"atb":[[8,1.46]],"id":43885158},{"atl":[[27,1.86]],"id":46969227}]}]}
{"op":"mcm","clk":"ANqkAQDrUgDrkQE=","pt":1659347710772,"mc":[{"id":"1.201590187","rc":[{"bdatb":[[2,8,1.46]],"id":43885158},{"bdatl":[[3,27,1.86],[4,28,7.64],[5,29,1.76],[6,30,5.28],[7,32,1.76],[8,34,5],[9,36,1.76]],"id":46969227}]}]}
{"op":"mcm","clk":"AOOkAQDuUgDxkQE=","pt":1659347710923,"mc":[{"id":"1.201590187","rc":[{"atl":[[55,0]],"id":44621159}]}]}
{"op":"mcm","clk":"AOWkAQDxUgD1kQE=","pt":1659347710974,"mc":[{"id":"1.201590187","rc":[{"bdatl":[[2,80,2.32]],"id":44621159}]}]}
{"op":"mcm","clk":"AOqkAQDzUgD5kQE=","pt":1659347711024,"mc":[{"id":"1.201590187","rc":[{"atb":[[25,0]],"atl":[[50,0.64]],"bdatb":[[1,23,6.8],[2,22,1.76],[3,21,5],[4,20,1.76],[5,19.5,1.76],[6,19,3.56],[7,18.5,1.37],[8,15.5,4.82],[9,13.5,7.54]],"bdatl":[[2,80,2.96]],"id":44621159}]}]}
{"op":"mcm","clk":"APGkAQD1UgD6kQE=","pt":1659347711096,"mc":[{"id":"1.201590187","rc":[{"atb":[[24,2.91]],"id":44621159}]}]}
{"op":"mcm","clk":"APKkAQD2UgD8kQE=","pt":1659347711146,"mc":[{"id":"1.201590187","rc":[{"bdatb":[[1,24,2.91],[2,23,6.31],[3,22,1.76],[4,21,5],[5,20,1.76],[6,19.5,1.76],[7,19,3.56],[8,18.5,1.37],[9,15.5,4.82]],"id":44621159}]}]}
{"op":"mcm","clk":"APekAQD2UgCAkgE=","pt":1659347711196,"mc":[{"id":"1.201590187","rc":[{"atb":[[1.02,4.55]],"atl":[[10,2.15]],"id":43885158}]}]}
{"op":"mcm","clk":"APmkAQD4UgCCkgE=","pt":1659347711246,"mc":[{"id":"1.201590187","rc":[{"bdatb":[[4,10.5,3.81],[5,10,12.97],[7,9.6,22.15]],"id":45323444},{"bdatb":[[3,2,11.99],[5,1.98,70.99],[8,1.95,7.44]],"id":9570503},{"bdatb":[[5,5.9,3.75],[6,5.8,35.48],[9,5.5,3.77]],"id":12989514},{"bdatb":[[6,6,233.32],[7,5.9,9.17]],"id":44836671},{"bdatl":[[0,10,2.15]],"id":43885158}]}]}
{"op":"mcm","clk":"AP+kAQD5UgCHkgE=","pt":1659347711301,"mc":[{"id":"1.201590187","rc":[{"atb":[[7.6,7.53]],"atl":[[11.5,14.64]],"id":43885158}]}]}
{"op":"mcm","clk":"AP+kAQD7UgCLkgE=","pt":1659347711351,"mc":[{"id":"1.201590187","rc":[{"bdatb":[[4,7.6,8.82]],"bdatl":[[3,11.5,14.64]],"id":43885158}]}]}
{"op":"mcm","clk":"AIWlAQCAUwCSkgE=","pt":1659347711408,"mc":[{"id":"1.201590187","rc":[{"atb":[[6.8,1.68],[6.4,24.36]],"id":12989514},{"atb":[[8.4,2],[1.02,2.55]],"id":43885158}]}]}
{"op":"mcm","clk":"AIalAQCAUwCSkgE=","pt":1659347711458,"mc":[{"id":"1.201590187","rc":[{"bdatl":[[8,2.32,2.49],[9,2.34,4.99]],"id":9570503},{"bdatb":[[0,6.8,1.68],[2,6.4,24.36]],"id":12989514},{"bdatb":[[1,8.4,2],[2,8.2,1.76],[3,8,1.46],[4,7.8,2.73],[5,7.6,8.82],[6,7.4,8.35],[7,7.2,3.71],[8,7,138.25],[9,6.8,2.9]],"id":43885158}]}]}
{"op":"mcm","clk":"AIulAQCBUwCWkgE=","pt":1659347711513,"mc":[{"id":"1.201590187","rc":[{"atl":[[7.6,16.38]],"id":12989514}]}]}
{"op":"mcm","clk":"AIulAQCEUwCYkgE=","pt":1659347711563,"mc":[{"id":"1.201590187","rc":[{"bdatl":[[1,7.6,16.38]],"id":12989514}]}]}
{"op":"mcm","clk":"AJGlAQCKUwCckgE=","pt":1659347711630,"mc":[{"id":"1.201590187","rc":[{"atb":[[1.02,1.55]],"id":43885158}]}]}
{"op":"mcm","clk":"AJOlAQCKUwCjkgE=","pt":1659347711710,"mc":[{"id":"1.201590187","rc":[{"atb":[[6.8,0.53]],"id":12989514},{"atb":[[8.4,3],[8.6,0]],"atl":[[10,1]],"id":43885158}]}]}
{"op":"mcm","clk":"AJilAQCPUwCmkgE=","pt":1659347711760,"mc":[{"id":"1.201590187","rc":[{"bdatb":[[4,10.5,2.72],[5,10,14.08],[6,9.8,9.04],[7,9.6,21],[9,9.2,16.17]],"id":45323444},{"bdatb":[[3,2,6.24],[5,1.98,76.57],[7,1.96,2.84],[8,1.95,1.76]],"bdatl":[[7,2.32,1.2],[8,2.34,7.46],[9,2.36,1.23]],"id":9570503},{"bdatb":[[0,6.6,12.01],[1,6.4,24.36],[2,6.2,5.02],[3,6,3.39],[4,5.9,1.81],[5,5.8,37.39],[6,5.7,223.76],[7,5.6,1.84],[8,5.5,1.76],[9,5.4,8.88]],"id":12989514},{"bdatb":[[6,6,231.41],[7,5.9,11.05],[9,5.7,61.86]],"id":44836671},{"bdatb":[[0,8.4,3.64],[1,8.2,1.76],[2,8,1.46],[3,7.8,2.73],[4,7.6,8.82],[5,7.4,8.35],[6,7.2,3.71],[7,7,138.25],[8,6.8,2.9],[9,6.6,48.48]],"bdatl":[[0,10,1]],"id":43885158}]}]}
{"op":"mcm","clk":"AJulAQCSUwCqkgE=","pt":1659347711828,"mc":[{"id":"1.201590187","rc":[{"atb":[[24,0.49]],"id":44621159}]}]}
{"op":"mcm","clk":"AJ2lAQCSUwCykgE=","pt":1659347711878,"mc":[{"id":"1.201590187","rc":[{"bdatb":[[1,23,6.8],[2,22,1.76],[3,21,5],[4,20,1.76],[5,19.5,1.76],[6,19,3.56],[7,18.5,1.37],[8,15.5,4.82],[9,13.5,7.44]],"id":44621159}]}]}
{"op":"mcm","clk":"AKSlAQCVUwC7kgE=","pt":1659347712021,"mc":[{"id":"1.201590187","rc":[{"atb":[[25,2.3]],"id":44621159}]}]}
{"op":"mcm","clk":"AKWlAQCXUwDCkgE=","pt":1659347712072,"mc":[{"id":"1.201590187","rc":[{"bdatb":[[1,25,2.3],[2,23,6.8],[3,22,1.76],[4,21,5],[5,20,1.76],[6,19.5,1.76],[7,19,3.56],[8,18.5,1.37],[9,15.5,4.82]],"id":44621159}]}]}
{"op":"mcm","clk":"AKulAQCaUwDFkgE=","pt":1659347712144,"mc":[{"id":"1.201590187","rc":[{"atb":[[13.5,1.97]],"id":45323444}]}]}
{"op":"mcm","clk":"ALClAQCaUwDLkgE=","pt":1659347712195,"mc":[{"id":"1.201590187","rc":[{"bdatb":[[0,13.5,1.97],[1,13,4.89],[2,12.5,3.5],[3,11.5,9.14],[4,11,1.23],[5,10.5,2.72],[6,10,14.08],[7,9.8,9.04],[8,9.6,21],[9,9.4,45.48]],"id":45323444},{"bdatl":[[6,2.28,1.58],[7,2.34,9.58],[8,2.38,8.12],[9,2.4,4.86]],"id":9570503}]}]}
{"op":"mcm","clk":"ALulAQCfUwDTkgE=","pt":1659347712393,"mc":[{"id":"1.201590187","rc":[{"atl":[[16.5,0.18]],"id":45323444}]}]}
{"op":"mcm","clk":"AMGlAQCkUwDXkgE=","pt":1659347712443,"mc":[{"id":"1.201590187","rc":[{"bdatl":[[0,17,2.51]],"id":45323444},{"bdatb":[[3,6,2.26],[4,5.9,2.96]],"id":12989514},{"bdatb":[[9,15.5,4.38]],"id":44621159},{"bdatb":[[4,7.6,7.92],[5,7.4,9.27],[7,7,137.28],[8,6.8,3.89]],"id":43885158}]}]}
{"op":"mcm","clk":"AMmlAQCoUwDikgE=","pt":1659347712606,"mc":[{"id":"1.201590187","rc":[{"atb":[[9.4,54.1]],"id":45323444},{"atb":[[3.9,61.72]],"id":12989514},{"atb":[[11,31.6]],"id":44621159},{"atb":[[5.7,79.02]],"id":44836671}]}]}
{"op":"mcm","clk":"AM6lAQCrUwDlkgE=","pt":1659347712656,"mc":[{"id":"1.201590187","rc":[{"bdatb":[[9,9.4,54.1]],"id":45323444},{"bdatb":[[9,5.7,79.1]],"id":44836671}]}]}
{"op":"mcm","clk":"ANSlAQCvUwDvkgE=","pt":1659347712812,"mc":[{"id":"1.201590187","rc":[{"atb":[[13.5,0.21]],"id":45323444},{"atb":[[25,0]],"id":44621159}]}]}
{"op":"mcm","clk":"ANqlAQCwUwDykgE=","pt":1659347712863,"mc":[{"id":"1.201590187","rc":[{"bdatb":[[0,13,5.1],[1,12.5,3.5],[2,11.5,9.14],[3,11,1.23],[4,10.5,2.72],[5,10,14.08],[6,9.8,9.04],[7,9.6,21],[8,9.4,54.1],[9,9.2,16.17]],"id":45323444},{"bdatl":[[6,2.28,1.24],[7,2.32,1.2],[8,2.34,7.46],[9,2.36,1.23]],"id":9570503},{"bdatb":[[1,23,6.8],[2,22,1.76],[3,21,5],[4,20,1.76],[5,19.5,1.76],[6,19,3.56],[7,18.5,1.37],[8,15.5,4.38],[9,14,1.33]],"id":44621159}]}]}
{"op":"mcm","clk":"AOGlAQC2UwD4kgE=","pt":1659347712935,"mc":[{"id":"1.201590187","rc":[{"atb":[[7.2,17.17]],"trd":[[7.2,21.1]],"ltp":7.2,"tv":234.78,"id":44836671},{"atb":[[7.8,5.06]],"atl":[[1000,0]],"id":43885158}],"tv":1602.79}]}
{"op":"mcm","clk":"AOGlAQC2UwD6kgE=","pt":1659347712985,"mc":[{"id":"1.201590187","rc":[{"bdatb":[[0,7.2,17.17]],"id":44836671},{"bdatb":[[3,7.8,5.06]],"id":43885158}]}]}
{"op":"mcm","clk":"AOWlAQC4UwD9kgE=","pt":1659347713035,"mc":[{"id":"1.201590187","rc":[{"atb":[[24,2.91]],"bdatb":[[1,24,2.91],[2,23,6.31],[3,22,1.76],[4,21,5],[5,20,1.76],[6,19.5,1.76],[7,19,3.56],[8,18.5,1.37],[9,15.5,4.38]],"id":44621159},{"atl":[[11,3.96],[10.5,2.3]],"bdatl":[[1,10.5,2.3],[2,11,3.96]],"id":43885158},{"bdatb":[[5,10,14.12],[6,9.8,9],[7,9.6,22.21],[9,9.2,16.74]],"id":45323444},{"bdatb":[[5,1.98,76.79],[7,1.96,2.62],[8,1.95,7.73]],"id":9570503},{"bdatb":[[5,5.8,37.47],[7,5.6,1.76],[8,5.5,3.88],[9,5.4,9.04]],"id":12989514},{"bdatb":[[7,5.9,11.12],[9,5.7,79.02]],"id":44836671}]}]}
{"op":"mcm","clk":"APKlAQC/UwCGkwE=","pt":1659347713244,"mc":[{"id":"1.201590187","rc":[{"atl":[[2.14,32.19]],"trd":[[2.14,94.71]],"ltp":2.14,"tv":987.09,"id":9570503},{"atb":[[6.8,0.4]],"trd":[[6.8,30.79]],"tv":134.24,"id":12989514}],"tv":1627.05}]}
{"op":"mcm","clk":"APKlAQC/UwCHkwE=","pt":1659347713294,"mc":[{"id":"1.201590187","rc":[{"bdatb":[[9,9.2,15.78]],"id":45323444},{"bdatl":[[0,2.14,32.19],[6,2.28,1.19],[7,2.32,1.26]],"id":9570503},{"bdatb":[[0,6.6,11.88],[9,5.4,8.2]],"id":12989514},{"bdatb":[[7,7,136.63],[8,6.8,2.43],[9,6.6,49.6]],"id":43885158}]}]}
{"op":"mcm","clk":"APulAQDBUwCMkwE=","pt":1659347713345,"mc":[{"id":"1.201590187","rc":[{"atb":[[8,4.65]],"id":43885158}]}]}
{"op":"mcm","clk":"AIGmAQDCUwCPkwE=","pt":1659347713395,"mc":[{"id":"1.201590187","rc":[{"atb":[[13.5,1.97]],"id":45323444},{"atb":[[7.4,2.32]],"bdatb":[[2,8,4.65]],"id":43885158},{"atb":[[15,1.76]],"id":46969227}]}]}
{"op":"mcm","clk":"AIGmAQDCUwCPkwE=","pt":1659347713445,"mc":[{"id":"1.201590187","rc":[{"bdatb":[[0,13.5,1.97],[1,13,4.89],[2,12.5,3.5],[3,11.5,9.14],[4,11,1.23],[5,10.5,2.72],[6,10,14.12],[7,9.8,9],[8,9.6,22.21],[9,9.4,54.1]],"id":45323444},{"bdatl":[[7,2.3,1.27],[8,2.34,8.7],[9,2.38,2.04]],"id":9570503},{"bdatb":[[5,7.4,4.96]],"id":43885158}]}]}
{"op":"mcm","clk":"AIWmAQDDUwCUkwE=","pt":1659347713495,"mc":[{"id":"1.201590187","rc":[{"atb":[[7.2,8.02]],"id":43885158},{"atb":[[21,0]],"id":46969227}]}]}
{"op":"mcm","clk":"AIemAQDFUwCWkwE=","pt":1659347713545,"mc":[{"id":"1.201590187","rc":[{"bdatl":[[6,2.3,1.18],[7,2.32,1.26]],"id":9570503},{"bdatb":[[6,7.2,8.02]],"id":43885158},{"bdatb":[[0,20,2.66],[1,19.5,8.5],[2,19,5],[3,18.5,8],[4,18,5],[5,17.5,1.76],[6,17,1.76],[7,16.5,1.76],[8,16,1.43],[9,15.5,1.76]],"id":46969227}]}]}
{"op":"mcm","clk":"AIymAQDGUwCZkwE=","pt":1659347713597,"mc":[{"id":"1.201590187","rc":[{"atb":[[13.5,5.57]],"id":45323444},{"atl":[[7.6,143.08]],"trd":[[7.6,17.44]],"ltp":7.6,"tv":238.78,"id":44836671},{"atb":[[19.5,1.5],[17.5,9.76]],"id":46969227}],"tv":1631.05}]}
{"op":"mcm","clk":"AI2mAQDJUwCdkwE=","pt":1659347713648,"mc":[{"id":"1.201590187","rc":[{"bdatb":[[0,13.5,5.57]],"id":45323444},{"bdatl":[[9,2.36,2.05]],"id":9570503},{"bdatl":[[0,7.6,143.08]],"id":44836671},{"bdatb":[[1,19.5,1.5],[5,17.5,9.76]],"id":46969227}]}]}
{"op":"mcm","clk":"AJSmAQDKUwCgkwE=","pt":1659347713708,"mc":[{"id":"1.201590187","rc":[{"atb":[[2,0.84]],"id":44621159},{"atb":[[19.5,1.74]],"id":46969227}]}]}
{"op":"mcm","clk":"AJSmAQDMUwCikwE=","pt":1659347713758,"mc":[{"id":"1.201590187","rc":[{"bdatb":[[1,19.5,1.74]],"id":46969227}]}]}
{"op":"mcm","clk":"AJmmAQDNUwCmkwE=","pt":1659347713808,"mc":[{"id":"1.201590187","rc":[{"atb":[[24,0.49]],"id":44621159}]}]}
{"op":"mcm","clk":"AJ2mAQDRUwCpkwE=","pt":1659347713859,"mc":[{"id":"1.201590187","rc":[{"bdatb":[[1,23,6.8],[2,22,1.76],[3,21,5],[4,20,1.76],[5,19.5,1.76],[6,19,3.56],[7,18.5,1.37],[8,15.5,4.38],[9,14,2.19]],"id":44621159}]}]}
{"op":"mcm","clk":"AKSmAQDTUwCtkwE=","pt":1659347713910,"mc":[{"id":"1.201590187","rc":[{"atl":[[24,0]],"id":45323444},{"atb":[[6.6,16.02],[6.4,18.97]],"id":12989514},{"atb":[[25,2.3]],"id":44621159}]}]}
{"op":"mcm","clk":"AKSmAQDTUwCukwE=","pt":1659347713960,"mc":[{"id":"1.201590187","rc":[{"bdatl":[[9,26,5.04]],"id":45323444},{"bdatb":[[0,6.6,16.42],[1,6.4,18.97]],"id":12989514},{"bdatb":[[1,25,2.3],[2,23,6.8],[3,22,1.76],[4,21,5],[5,20,1.76],[6,19.5,1.76],[7,19,3.56],[8,18.5,1.37],[9,15.5,4.38]],"id":44621159}]}]}
{"op":"mcm","clk":"AKmmAQDUUwCvkwE=","pt":1659347714010,"mc":[{"id":"1.201590187","rc":[{"atl":[[25,1.44]],"id":45323444}]}]}
{"op":"mcm","clk":"AKumAQDXUwCzkwE=","pt":1659347714060,"mc":[{"id":"1.201590187","rc":[{"bdatl":[[9,25,1.44]],"id":45323444}]}]}
{"op":"mcm","clk":"ALGmAQDbUwC5kwE=","pt":1659347714144,"mc":[{"id":"1.201590187","rc":[{"atb":[[1.8,2.88]],"id":44836671}]}]}
{"op":"mcm","clk":"AMCmAQDgUwDCkwE=","pt":1659347714323,"mc":[{"id":"1.201590187","rc":[{"atb":[[11.5,5.75]],"id":45323444},{"atl":[[7.6,20.09]],"id":12989514},{"atb":[[7.6,4.01],[8,1.46]],"id":43885158}]}]}
{"op":"mcm","clk":"AMCmAQDjUwDGkwE=","pt":1659347714374,"mc":[{"id":"1.201590187","rc":[{"bdatb":[[3,11.5,5.75]],"id":45323444},{"bdatl":[[1,7.6,20.09]],"id":12989514},{"bdatb":[[2,8,1.46],[4,7.6,4.4]],"id":43885158}]}]}
{"op":"mcm","clk":"AM6mAQDqUwDOkwE=","pt":1659347714539,"mc":[{"id":"1.201590187","rc":[{"atb":[[1.8,0.01]],"id":44836671}]}]}
{"op":"mcm","clk":"ANemAQDuUwDTkwE=","pt":1659347714646,"mc":[{"id":"1.201590187","rc":[{"atb":[[13,0.47]],"id":45323444},{"atb":[[25,0]],"id":44621159}]}]}
{"op":"mcm","clk":"ANumAQDuUwDUkwE=","pt":1659347714696,"mc":[{"id":"1.201590187","rc":[{"bdatb":[[1,12.5,3.97],[2,11.5,5.75],[3,11,1.23],[4,10.5,2.72],[5,10,14.12],[6,9.8,9],[7,9.6,22.21],[8,9.4,54.1],[9,9.2,15.78]],"id":45323444},{"bdatb":[[1,23,6.8],[2,22,1.76],[3,21,5],[4,20,1.76],[5,19.5,1.76],[6,19,3.56],[7,18.5,1.37],[8,15.5,4.38],[9,14,2.19]],"id":44621159}]}]}
{"op":"mcm","clk":"AN2mAQDwUwDYkwE=","pt":1659347714746,"mc":[{"id":"1.201590187","rc":[{"atb":[[12,1.76]],"id":45323444}]}]}
{"op":"mcm","clk":"AOOmAQDwUwDZkwE=","pt":1659347714796,"mc":[{"id":"1.201590187","rc":[{"bdatb":[[2,12,1.76],[3,11.5,5.75],[4,11,1.23],[5,10.5,2.72],[6,10,14.12],[7,9.8,9],[8,9.6,22.21],[9,9.4,54.1]],"id":45323444}]}]}
{"op":"mcm","clk":"AOWmAQDyUwDckwE=","pt":1659347714847,"mc":[{"id":"1.201590187","rc":[{"atb":[[24,2.91]],"bdatb":[[1,24,2.91],[2,23,6.31],[3,22,1.76],[4,21,5],[5,20,1.76],[6,19.5,1.76],[7,19,3.56],[8,18.5,1.37],[9,15.5,4.38]],"id":44621159}]}]}
{"op":"mcm","clk":"APCmAQD1UwDokwE=","pt":1659347714997,"mc":[{"id":"1.201590187","rc":[{"atb":[[1.8,0]],"id":44836671}]}]}
{"op":"mcm","clk":"APOmAQD1UwDtkwE=","pt":1659347715098,"mc":[{"id":"1.201590187","rc":[{"atl":[[7.6,143.07]],"trd":[[7.6,17.45]],"tv":238.79,"id":44836671}],"tv":1631.06}]}
{"op":"mcm","clk":"APWmAQD2UwDxkwE=","pt":1659347715149,"mc":[{"id":"1.201590187","rc":[{"bdatl":[[0,7.6,143.07]],"id":44836671}]}]}
{"op":"mcm","clk":"AP6mAQD7UwD8kwE=","pt":1659347715307,"mc":[{"id":"1.201590187","rc":[{"atb":[[2.06,21.77]],"trd":[[2.06,88.88]],"ltp":2.06,"tv":1030.19,"id":9570503},{"atl":[[7.6,108.59]],"trd":[[7.6,86.41]],"tv":307.75,"id":44836671}],"tv":1743.12}]}
{"op":"mcm","clk":"AP+mAQD9UwD9kwE=","pt":1659347715357,"mc":[{"id":"1.201590187","rc":[{"bdatb":[[0,2.06,21.77]],"id":9570503},{"bdatl":[[0,7.6,108.59]],"id":44836671}]}]}
{"op":"mcm","clk":"AIenAQCAVACAlAE=","pt":1659347715419,"mc":[{"id":"1.201590187","rc":[{"atl":[[7.4,13.69]],"id":12989514},{"atb":[[2,0.02]],"id":44621159}]}]}
{"op":"mcm","clk":"AIenAQCAVACDlAE=","pt":1659347715469,"mc":[{"id":"1.201590187","rc":[{"bdatl":[[0,7.4,13.69]],"id":12989514}]}]}
{"op":"mcm","clk":"AIynAQCCVACHlAE=","pt":1659347715519,"mc":[{"id":"1.201590187","rc":[{"atb":[[1.02,2]],"id":9570503}]}]}
{"op":"mcm","clk":"AJOnAQCGVACNlAE=","pt":1659347715629,"mc":[{"id":"1.201590187","rc":[{"atb":[[24,0.49],[1.02,2.45],[18.5,0.93],[2,0]],"id":44621159}]}]}
{"op":"mcm","clk":"AJSnAQCGVACNlAE=","pt":1659347715679,"mc":[{"id":"1.201590187","rc":[{"bdatb":[[1,23,6.8],[2,22,1.76],[3,21,5],[4,20,1.76],[5,19.5,1.76],[6,19,3.56],[7,15.5,5.31],[8,14,2.19],[9,13.5,6.56]],"id":44621159}]}]}
{"op":"mcm","clk":"AJunAQCJVACSlAE=","pt":1659347715729,"mc":[{"id":"1.201590187","rc":[{"atb":[[1.02,1.85]],"id":9570503},{"atb":[[25,2.3]],"atl":[[30,0.73]],"trd":[[30,0.04]],"ltp":30,"tv":4.38,"id":44621159}],"tv":1743.16}]}
{"op":"mcm","clk":"AJunAQCJVACSlAE=","pt":1659347715779,"mc":[{"id":"1.201590187","rc":[{"bdatb":[[6,10,14.06],[8,9.6,22.27]],"id":45323444},{"bdatb":[[5,1.98,76.49],[8,1.95,8.04]],"id":9570503},{"bdatb":[[5,5.8,37.36],[8,5.5,3.99]],"id":12989514},{"bdatb":[[1,25,2.3],[2,23,6.8],[3,22,1.76],[4,21,5],[5,20,1.76],[6,19.5,1.76],[7,19,3.56],[8,15.5,5.31],[9,14,2.19]],"bdatl":[[0,38,3.75]],"id":44621159},{"bdatb":[[7,5.9,11.02]],"id":44836671},{"bdatb":[[5,7.4,4.88],[7,7,136.71]],"id":43885158}]}]}
{"op":"mcm","clk":"AKKnAQCMVACUlAE=","pt":1659347715829,"mc":[{"id":"1.201590187","rc":[{"atb":[[1.02,0]],"id":9570503},{"atl":[[30,0],[38,2.02],[36,1]],"trd":[[30,1.5]],"tv":5.84,"id":44621159},{"atb":[[7.8,4.1]],"id":43885158}],"tv":1744.62}]}
{"op":"mcm","clk":"AKKnAQCMVACUlAE=","pt":1659347715879,"mc":[{"id":"1.201590187","rc":[{"bdatb":[[5,10.5,1.76],[6,10,13.87],[7,9.8,11.46],[8,9.6,21],[9,9.4,54.29]],"id":45323444},{"bdatb":[[3,2,1.24],[5,1.98,75.53],[7,1.96,14.93],[8,1.95,1.76],[9,1.94,2.73]],"id":9570503},{"bdatb":[[3,6,1.76],[4,5.9,1.76],[5,5.8,35.82],[6,5.7,225],[7,5.6,6.07],[8,5.5,1.76]],"id":12989514},{"bdatl":[[0,36,1],[1,38,2.02],[2,40,3.27],[3,80,2.96],[4,170,2],[5,900,1.14],[6,990,1.83],[7,1000,2]],"id":44621159},{"bdatb":[[6,6,229.74],[7,5.9,10.69],[9,5.7,83.26]],"id":44836671},{"bdatb":[[3,7.8,4.1],[4,7.6,4.01],[5,7.4,2.32],[6,7.2,13.02],[7,7,134.7]],"id":43885158}]}]}
{"op":"mcm","clk":"AKenAQCNVACWlAE=","pt":1659347715929,"mc":[{"id":"1.201590187","rc":[{"atb":[[2.08,1.85]],"id":9570503},{"atb":[[25,3.3]],"id":44621159},{"atb":[[1.01,48]],"id":43885158},{"atb":[[19,7.2],[19.5,0.24]],"id":46969227}]}]}
{"op":"mcm","clk":"AKmnAQCQVACWlAE=","pt":1659347715979,"mc":[{"id":"1.201590187","rc":[{"bdatb":[[0,2.08,1.85],[1,2.06,21.77],[2,2.04,27.73],[3,2.02,15.66],[4,2,1.24],[5,1.99,1.76],[6,1.98,75.53],[7,1.97,2.53],[8,1.96,14.93],[9,1.95,1.76]],"id":9570503},{"bdatb":[[1,25,3.3]],"id":44621159},{"bdatl":[[9,14.5,14.06]],"id":43885158},{"bdatb":[[1,19,7.44],[2,18.5,8],[3,18,5],[4,17.5,9.76],[5,17,1.76],[6,16.5,1.76],[7,16,1.43],[8,15.5,1.76],[9,15,1.76]],"id":46969227}]}]}
{"op":"mcm","clk":"ALCnAQCTVACclAE=","pt":1659347716128,"mc":[{"id":"1.201590187","rc":[{"atl":[[16,1]],"id":45323444},{"atb":[[2.06,23.29]],"atl":[[1000,1.82]],"id":9570503},{"atb":[[1.02,0.33]],"id":44621159},{"atl":[[26,6.1]],"id":46969227}]}]}
{"op":"mcm","clk":"ALKnAQCVVACglAE=","pt":1659347716178,"mc":[{"id":"1.201590187","rc":[{"bdatl":[[0,16,1],[1,17,2.51],[2,17.5,1.76],[3,18.5,1.76],[4,19,1.76],[5,19.5,1.76],[6,20,1.76],[7,21,1.76],[8,22,2.58],[9,23,1.76]],"id":45323444},{"bdatb":[[1,2.06,23.29],[5,1.99,6.79],[6,1.98,70.48],[7,1.97,5.58],[8,1.96,11.87]],"id":9570503},{"bdatb":[[4,5.9,3.46],[5,5.8,35.31],[6,5.7,224.82],[7,5.6,5]],"id":12989514},{"bdatb":[[8,16,1.56],[9,15.5,4.19]],"id":44621159},{"bdatb":[[6,6,231.41],[7,5.9,9],[8,5.8,11.55],[9,5.7,81.68]],"id":44836671},{"bdatb":[[5,7.4,4.48],[6,7.2,10.79],[8,6.8,4.5],[9,6.6,47.78]],"id":43885158},{"bdatl":[[2,26,6.1]],"id":46969227}]}]}
{"op":"mcm","clk":"ALenAQCVVACilAE=","pt":1659347716230,"mc":[{"id":"1.201590187","rc":[{"atb":[[1.01,46.43]],"id":43885158}]}]}
{"op":"mcm","clk":"ALqnAQCYVACnlAE=","pt":1659347716329,"mc":[{"id":"1.201590187","rc":[{"atl":[[16,1.2]],"id":45323444},{"atb":[[2.06,37.75]],"atl":[[1000,0],[2.26,4],[2.18,3.88]],"id":9570503},{"atl":[[7.6,23.8]],"id":12989514}]}]}
{"op":"mcm","clk":"ALynAQCbVACqlAE=","pt":1659347716379,"mc":[{"id":"1.201590187","rc":[{"bdatl":[[0,16,1.2]],"id":45323444},{"bdatb":[[1,2.06,37.75],[7,1.97,7.2],[8,1.96,10.24]],"bdatl":[[2,2.18,3.88],[6,2.26,4],[7,2.3,1.18],[8,2.32,1.26],[9,2.34,8.7]],"id":9570503},{"bdatb":[[6,5.7,225.38],[7,5.6,4.43]],"bdatl":[[1,7.6,23.8]],"id":12989514},{"bdatb":[[8,5.8,12.1],[9,5.7,81.12]],"id":44836671},{"bdatb":[[5,7.4,4.92],[6,7.2,10.35],[9,6.6,48.26]],"id":43885158}]}]}
{"op":"mcm","clk":"AL+nAQCbVACslAE=","pt":1659347716430,"mc":[{"id":"1.201590187","rc":[{"atb":[[2.04,20.31]],"atl":[[2.12,1.82]],"id":9570503},{"atb":[[6.6,9.12]],"id":12989514},{"atb":[[25,1],[1.02,0]],"id":44621159}]}]}
{"op":"mcm","clk":"AMKnAQCdVACulAE=","pt":1659347716480,"mc":[{"id":"1.201590187","rc":[{"bdatb":[[5,10.5,2.13],[6,10,13.49]],"id":45323444},{"bdatb":[[2,2.04,20.31]],"bdatl":[[0,2.12,1.82],[1,2.14,32.19],[2,2.16,8.6],[3,2.18,3.88],[4,2.2,5],[5,2.22,4],[6,2.24,7],[7,2.26,4],[8,2.3,1.18],[9,2.32,1.26]],"id":9570503},{"bdatb":[[0,6.6,9.52],[3,6,2.41],[4,5.9,2.81],[9,5.4,8.91]],"id":12989514},{"bdatb":[[1,25,1],[8,17,1.16],[9,15.5,4.57]],"id":44621159},{"bdatb":[[5,6.2,26.41],[6,6,230.76]],"id":44836671},{"bdatb":[[4,7.6,4.52],[5,7.4,4.4],[7,7,135.25],[9,6.6,47.68]],"id":43885158}]}]}
{"op":"mcm","clk":"AMinAQCdVACvlAE=","pt":1659347716535,"mc":[{"id":"1.201590187","rc":[{"atb":[[25,1.33]],"id":44621159}]}]}
{"op":"mcm","clk":"AMynAQCiVACxlAE=","pt":1659347716585,"mc":[{"id":"1.201590187","rc":[{"bdatb":[[1,25,1.33]],"id":44621159}]}]}
{"op":"mcm","clk":"ANOnAQCkVAC2lAE=","pt":1659347716636,"mc":[{"id":"1.201590187","rc":[{"atl":[[2.12,3.32]],"bdatl":[[0,2.12,3.32]],"id":9570503},{"atb":[[24,2.91]],"bdatb":[[2,24,2.91],[3,23,6.31],[4,22,1.76],[5,21,5],[6,20,1.76],[7,19.5,1.76],[8,19,3.56],[9,17,1.34]],"id":44621159},{"bdatb":[[5,10.5,2.43],[6,10,13.17]],"id":45323444},{"bdatb":[[3,6,2.94],[4,5.9,2.27],[9,5.4,9.5]],"id":12989514},{"bdatb":[[5,6.2,26.92],[6,6,230.23]],"id":44836671},{"bdatb":[[4,7.6,4.94],[5,7.4,3.97],[7,7,135.7],[8,6.8,4.22],[9,6.6,47.76]],"id":43885158}]}]}
{"op":"mcm","clk":"ANWnAQClVAC5lAE=","pt":1659347716701,"mc":[{"id":"1.201590187","rc":[{"atb":[[26,0]],"id":44621159}]}]}
{"op":"mcm","clk":"ANmnAQCqVAC7lAE=","pt":1659347716751,"mc":[{"id":"1.201590187","rc":[{"bdatb":[[0,25,1.33],[1,24,2.91],[2,23,6.31],[3,22,1.76],[4,21,5],[5,20,1.76],[6,19.5,1.76],[7,19,3.56],[8,17,1.34],[9,15.5,4.38]],"id":44621159}]}]}
{"op":"mcm","clk":"ANunAQCqVAC/lAE=","pt":1659347716803,"mc":[{"id":"1.201590187","rc":[{"atb":[[1.01,45.55]],"id":43885158}]}]}
{"op":"mcm","clk":"AOSnAQCsVADJlAE=","pt":1659347716925,"mc":[{"id":"1.201590187","rc":[{"atb":[[8.6,0.88]],"id":43885158},{"atl":[[25,2.63]],"id":46969227}]}]}
{"op":"mcm","clk":"AOSnAQCsVADJlAE=","pt":1659347716975,"mc":[{"id":"1.201590187","rc":[{"bdatb":[[0,8.6,1.52],[1,8.4,3],[2,8.2,1.76],[3,8,1.46],[4,7.8,4.1],[5,7.6,4.94],[6,7.4,3.97],[7,7.2,10.35],[8,7,135.7],[9,6.8,4.22]],"id":43885158},{"bdatl":[[1,25,2.63]],"id":46969227}]}]}
{"op":"mcm","clk":"AISoAQC1VADllAE=","pt":1659347717425,"mc":[{"id":"1.201590187","rc":[{"atb":[[2.04,16.2]],"atl":[[2.16,5.05]],"id":9570503},{"atb":[[6.4,16.54]],"atl":[[7.4,9.25]],"id":12989514},{"atb":[[24,0.49]],"id":44621159},{"atb":[[7,15.95]],"atl":[[7.8,5.53]],"id":44836671},{"atb":[[7.6,1.76]],"id":43885158}]}]}
{"op":"mcm","clk":"AIWoAQC2VADplAE=","pt":1659347717475,"mc":[{"id":"1.201590187","rc":[{"bdatb":[[2,2.04,16.2]],"bdatl":[[2,2.16,5.05]],"id":9570503},{"bdatb":[[1,6.4,16.54]],"bdatl":[[0,7.4,9.25]],"id":12989514},{"bdatb":[[1,23,6.8],[2,22,1.76],[3,21,5],[4,20,1.76],[5,19.5,1.76],[6,19,3.56],[7,17,1.34],[8,15.5,4.38],[9,14,1.66]],"id":44621159},{"bdatb":[[1,7,15.95]],"bdatl":[[1,7.8,5.53]],"id":44836671},{"bdatb":[[5,7.6,2.69],[8,7,134.63],[9,6.8,2.86]],"id":43885158}]}]}
{"op":"mcm","clk":"AIeoAQC2VADqlAE=","pt":1659347717525,"mc":[{"id":"1.201590187","rc":[{"atb":[[25,3.63]],"id":44621159}]}]}
{"op":"mcm","clk":"AImoAQC5VADulAE=","pt":1659347717575,"mc":[{"id":"1.201590187","rc":[{"bdatb":[[0,25,3.63]],"id":44621159}]}]}
{"op":"mcm","clk":"AI6oAQC6VADwlAE=","pt":1659347717639,"mc":[{"id":"1.201590187","rc":[{"atl":[[2.18,1.18],[2.12,21.47]],"id":9570503},{"atb":[[6.6,4.92]],"id":12989514},{"atb":[[11,34.48]],"id":44621159}]}]}
{"op":"mcm","clk":"AJOoAQC6VADylAE=","pt":1659347717689,"mc":[{"id":"1.201590187","rc":[{"bdatb":[[5,10.5,2.72],[6,10,15.29],[7,9.8,9.19],[8,9.6,21.99],[9,9.4,54.1]],"id":45323444},{"bdatl":[[0,2.12,21.47],[3,2.18,1.18]],"id":9570503},{"bdatb":[[0,6.6,5.32],[3,6,3.43],[4,5.9,1.76],[5,5.8,37.41],[6,5.7,225.86],[7,5.6,2.1],[8,5.5,3.49],[9,5.4,7.73]],"id":12989514},{"bdatb":[[7,17,1.52],[8,15.5,4.95],[9,14,1.61]],"id":44621159},{"bdatb":[[5,6.2,27.4],[6,6,231.27],[7,5.9,9.5],[8,5.8,12.06],[9,5.7,79.35]],"id":44836671},{"bdatb":[[5,7.6,4.68],[6,7.4,5.48],[7,7.2,8.02],[8,7,133.28],[9,6.8,5.32]],"id":43885158}]}]}
{"op":"mcm","clk":"AJaoAQC7VAD1lAE=","pt":1659347717740,"mc":[{"id":"1.201590187","rc":[{"atb":[[6.4,20.84]],"id":12989514},{"atb":[[20,5.63]],"id":46969227}]}]}
{"op":"mcm","clk":"AJaoAQC8VAD3lAE=","pt":1659347717790,"mc":[{"id":"1.201590187","rc":[{"bdatb":[[1,6.4,20.84]],"id":12989514},{"bdatb":[[0,20,5.63]],"id":46969227}]}]}
{"op":"mcm","clk":"AKCoAQC+VAD8lAE=","pt":1659347717932,"mc":[{"id":"1.201590187","rc":[{"atb":[[2,94.33]],"id":9570503},{"atl":[[11,3.53]],"id":43885158},{"atb":[[8.8,51.72]],"id":46969227}]}]}
{"op":"mcm","clk":"AKGoAQDAVAD+lAE=","pt":1659347717982,"mc":[{"id":"1.201590187","rc":[{"bdatb":[[4,2,94.33]],"id":9570503},{"bdatb":[[9,5.4,6.85]],"id":12989514},{"bdatl":[[2,11,3.53]],"id":43885158}]}]}
{"op":"mcm","clk":"AKeoAQDAVACDlQE=","pt":1659347718032,"mc":[{"id":"1.201590187","rc":[{"atl":[[1000,0.43]],"id":43885158}]}]}
{"op":"mcm","clk":"AK6oAQDEVACFlQE=","pt":1659347718104,"mc":[{"id":"1.201590187","rc":[{"atb":[[6.8,1.55]],"id":12989514},{"atl":[[10,2.15]],"id":43885158}]}]}
{"op":"mcm","clk":"AK6oAQDEVACFlQE=","pt":1659347718154,"mc":[{"id":"1.201590187","rc":[{"bdatb":[[5,10.5,3.81],[6,10,15.28],[7,9.8,9],[8,9.6,21.01]],"id":45323444},{"bdatb":[[5,1.99,11.41],[6,1.98,71.64],[7,1.97,2.53],[8,1.96,10.02],[9,1.95,6.7]],"bdatl":[[8,2.3,2.45],[9,2.32,2.11]],"id":9570503},{"bdatb":[[0,6.8,1.55],[1,6.6,4.92],[2,6.4,20.84],[3,6.2,5.02],[4,6,4.96],[5,5.9,2.15],[6,5.8,35.43],[7,5.7,227.86],[8,5.6,1.76],[9,5.5,1.78]],"id":12989514},{"bdatb":[[7,17,2.06],[8,15.5,4.38],[9,15,1.56]],"id":44621159},{"bdatb":[[5,6.2,28.89],[6,6,230.12],[7,5.9,9.11],[8,5.8,14.02],[9,5.7,79.02]],"id":44836671},{"bdatl":[[0,10,2.15],[9,14.5,14.14]],"id":43885158}]}]}
{"op":"mcm","clk":"ALeoAQDFVACJlQE=","pt":1659347718211,"mc":[{"id":"1.201590187","rc":[{"atb":[[25,1.33]],"id":44621159},{"atl":[[10.5,2.58]],"id":43885158}]}]}
{"op":"mcm","clk":"ALeoAQDHVACJlQE=","pt":1659347718261,"mc":[{"id":"1.201590187","rc":[{"bdatb":[[8,9.6,21.32]],"id":45323444},{"bdatb":[[9,1.95,8.21]],"id":9570503},{"bdatb":[[9,5.5,2.32]],"id":12989514},{"bdatb":[[0,25,1.33]],"id":44621159},{"bdatl":[[1,10.5,2.58]],"id":43885158}]}]}
{"op":"mcm","clk":"ALyoAQDJVACNlQE=","pt":1659347718316,"mc":[{"id":"1.201590187","rc":[{"atb":[[12.5,2.35]],"id":45323444},{"atl":[[10.5,1.43]],"id":43885158},{"atb":[[20,4.48]],"atl":[[25,1.48]],"id":46969227}]}]}
{"op":"mcm","clk":"ALyoAQDJVACNlQE=","pt":1659347718366,"mc":[{"id":"1.201590187","rc":[{"bdatb":[[1,12.5,2.82],[6,10,14.37],[8,9.6,21.94]],"id":45323444},{"bdatb":[[9,1.95,2.02]],"id":9570503},{"bdatb":[[7,5.7,226.28],[9,5.5,3.4]],"id":12989514},{"bdatb":[[9,14,1.6]],"id":44621159},{"bdatb":[[8,5.8,12.47]],"id":44836671},{"bdatl":[[1,10.5,1.43]],"id":43885158},{"bdatb":[[0,20,4.48]],"bdatl":[[1,25,1.48]],"id":46969227}]}]}
{"op":"mcm","clk":"AMOoAQDMVACPlQE=","pt":1659347718416,"mc":[{"id":"1.201590187","rc":[{"atb":[[26,2.18]],"id":44621159}]}]}
{"op":"mcm","clk":"AMOoAQDMVACQlQE=","pt":1659347718466,"mc":[{"id":"1.201590187","rc":[{"bdatl":[[8,2.3,4.58],[9,2.34,11.92]],"id":9570503},{"bdatb":[[0,26,2.18],[1,25,1.33],[2,23,6.8],[3,22,1.76],[4,21,5],[5,20,1.76],[6,19.5,1.76],[7,19,3.56],[8,17,2.06],[9,15.5,4.38]],"id":44621159}]}]}
{"op":"mcm","clk":"AOWoAQDZVACglQE=","pt":1659347719126,"mc":[{"id":"1.201590187","rc":[{"atl":[[8.2,9.07]],"id":44836671},{"atl":[[12.5,10]],"id":43885158}]}]}
{"op":"mcm","clk":"AOaoAQDZVACklQE=","pt":1659347719176,"mc":[{"id":"1.201590187","rc":[{"bdatl":[[3,8.2,9.07]],"id":44836671},{"bdatl":[[5,12.5,10]],"id":43885158}]}]}
{"op":"mcm","clk":"AOmoAQDZVACllQE=","pt":1659347719229,"mc":[{"id":"1.201590187","rc":[{"atb":[[6.6,12]],"id":12989514}]}]}
{"op":"mcm","clk":"AOuoAQDdVACplQE=","pt":1659347719279,"mc":[{"id":"1.201590187","rc":[{"bdatb":[[1,6.6,12]],"id":12989514}]}]}
{"op":"mcm","clk":"APGoAQDdVACslQE=","pt":1659347719333,"mc":[{"id":"1.201590187","rc":[{"atl":[[8,16.03]],"id":44836671}]}]}
{"op":"mcm","clk":"APKoAQDgVACulQE=","pt":1659347719383,"mc":[{"id":"1.201590187","rc":[{"bdatl":[[2,8,16.03]],"id":44836671}]}]}
{"op":"mcm","clk":"APaoAQDgVACylQE=","pt":1659347719438,"mc":[{"id":"1.201590187","rc":[{"atl":[[7.6,15.37]],"id":12989514}]}]}
{"op":"mcm","clk":"APioAQDkVAC3lQE=","pt":1659347719489,"mc":[{"id":"1.201590187","rc":[{"bdatl":[[1,7.6,15.37]],"id":12989514}]}]}
{"op":"mcm","clk":"AP+oAQDoVAC+lQE=","pt":1659347719592,"mc":[{"id":"1.201590187","rc":[{"atb":[[7.8,1.76]],"id":43885158}]}]}
{"op":"mcm","clk":"AIGpAQDrVADBlQE=","pt":1659347719643,"mc":[{"id":"1.201590187","rc":[{"bdatb":[[4,7.8,1.76]],"id":43885158}]}]}
{"op":"mcm","clk":"AIWpAQDuVADDlQE=","pt":1659347719700,"mc":[{"id":"1.201590187","rc":[{"atb":[[2.08,0],[2.04,12.17],[2.06,35.52],[2.02,19.6]],"atl":[[2.16,1.18],[2.2,8.8]],"trd":[[2.08,89.39],[2.06,93.34]],"tv":1038.35,"id":9570503},{"atb":[[6.6,14.25],[6.4,18.41]],"atl":[[7.4,9.3]],"id":12989514},{"atb":[[7,15.98]],"atl":[[7.8,5.49]],"id":44836671},{"atb":[[7.6,4.04]],"id":43885158}],"tv":1752.78}]}
{"op":"mcm","clk":"AIapAQDwVADHlQE=","pt":1659347719750,"mc":[{"id":"1.201590187","rc":[{"bdatb":[[0,2.06,35.52],[1,2.04,12.17],[2,2.02,19.6],[3,2,94.33],[4,1.99,11.41],[5,1.98,71.64],[6,1.97,2.53],[7,1.96,10.02],[8,1.95,2.02],[9,1.94,1.76]],"bdatl":[[2,2.16,1.18],[4,2.2,8.8]],"id":9570503},{"bdatb":[[1,6.6,14.25],[2,6.4,18.41]],"bdatl":[[0,7.4,9.3]],"id":12989514},{"bdatb":[[1,7,15.98]],"bdatl":[[1,7.8,5.49]],"id":44836671},{"bdatb":[[5,7.6,6.95],[8,7,133.33],[9,6.8,5.27]],"bdatl":[[9,14.5,13.87]],"id":43885158}]}]}
{"op":"mcm","clk":"AKWpAQD+VADzlQE=","pt":1659347720546,"mc":[{"id":"1.201590187","rc":[{"atl":[[25,0.1]],"id":46969227}]}]}
{"op":"mcm","clk":"AKWpAQD+VAD1lQE=","pt":1659347720596,"mc":[{"id":"1.201590187","rc":[{"bdatl":[[1,26,6.2],[2,27,1.86],[3,28,7.64],[4,29,1.76],[5,30,5.28],[6,32,1.76],[7,34,5],[8,36,1.76],[9,38,1.76]],"id":46969227}]}]}
{"op":"mcm","clk":"AM+pAQCMVQCmlgE=","pt":1659347721411,"mc":[{"id":"1.201590187","rc":[{"atl":[[17,1.33]],"id":45323444},{"atb":[[2.04,26.35],[2.02,5.14]],"id":9570503},{"atb":[[7,2.45],[6.4,15.68]],"id":12989514}]}]}
{"op":"mcm","clk":"ANSpAQCQVQCplgE=","pt":1659347721461,"mc":[{"id":"1.201590187","rc":[{"bdatl":[[1,17,1.51]],"id":45323444},{"bdatb":[[1,2.04,26.35],[2,2.02,5.14]],"bdatl":[[8,2.28,5.8],[9,2.3,1.71]],"id":9570503},{"bdatb":[[0,7,2.45],[1,6.8,1.55],[2,6.6,14.25],[3,6.4,15.68],[4,6.2,5.02],[5,6,4.96],[6,5.9,2.15],[7,5.8,35.43],[8,5.7,226.28],[9,5.6,1.76]],"id":12989514},{"bdatb":[[6,7.4,5.38],[7,7.2,8.12],[9,6.8,2.77]],"bdatl":[[9,14.5,15.06]],"id":43885158}]}]}
{"op":"mcm","clk":"ANapAQCQVQCqlgE=","pt":1659347721512,"mc":[{"id":"1.201590187","rc":[{"atb":[[12.5,1.35]],"id":45323444}]}]}
{"op":"mcm","clk":"ANupAQCVVQCrlgE=","pt":1659347721562,"mc":[{"id":"1.201590187","rc":[{"bdatb":[[1,12.5,1.82]],"id":45323444}]}]}
{"op":"mcm","clk":"AOGpAQCWVQCslgE=","pt":1659347721626,"mc":[{"id":"1.201590187","rc":[{"atb":[[2.04,47.61],[2.06,21.06]],"id":9570503},{"atb":[[6.6,7.17],[6.8,2.9]],"id":12989514}]}]}
{"op":"mcm","clk":"AOOpAQCWVQCvlgE=","pt":1659347721676,"mc":[{"id":"1.201590187","rc":[{"bdatb":[[0,2.06,21.06],[1,2.04,47.61]],"id":9570503},{"bdatb":[[1,6.8,2.9],[2,6.6,7.17]],"id":12989514}]}]}
{"op":"mcm","clk":"AOSpAQCXVQCylgE=","pt":1659347721726,"mc":[{"id":"1.201590187","rc":[{"atb":[[13.5,1.97]],"id":45323444},{"atb":[[2.06,14.16]],"id":9570503},{"atb":[[6.4,11.38]],"id":12989514}]}]}
{"op":"mcm","clk":"AOypAQCZVQCylgE=","pt":1659347721776,"mc":[{"id":"1.201590187","rc":[{"bdatb":[[0,13.5,1.97]],"id":45323444},{"bdatb":[[0,2.06,14.16]],"id":9570503},{"bdatb":[[3,6.4,11.38]],"id":12989514}]}]}
{"op":"mcm","clk":"APKpAQCcVQC1lgE=","pt":1659347721849,"mc":[{"id":"1.201590187","rc":[{"atb":[[19,1.76]],"id":44621159}]}]}
{"op":"mcm","clk":"APSpAQCcVQC5lgE=","pt":1659347721899,"mc":[{"id":"1.201590187","rc":[{"bdatb":[[7,19,1.76]],"id":44621159}]}]}
{"op":"mcm","clk":"APipAQCeVQC8lgE=","pt":1659347721949,"mc":[{"id":"1.201590187","rc":[{"atb":[[2.02,9.25]],"atl":[[2.2,12.64]],"bdatb":[[2,2.02,9.25]],"bdatl":[[4,2.2,12.64]],"id":9570503},{"atb":[[6.6,9.57]],"atl":[[7.4,9.51]],"bdatb":[[2,6.6,9.57]],"bdatl":[[0,7.4,9.51]],"id":12989514},{"atb":[[22,3.56]],"bdatb":[[3,22,3.56]],"id":44621159},{"atb":[[7,18.28]],"atl":[[7.8,7.75]],"bdatb":[[1,7,18.28]],"bdatl":[[1,7.8,7.75]],"id":44836671},{"atb":[[7.6,6.45]],"bdatb":[[5,7.6,9.37],[8,7,133.55],[9,6.8,2.54]],"id":43885158}]}]}
{"op":"mcm","clk":"AIKqAQCeVQDElgE=","pt":1659347722051,"mc":[{"id":"1.201590187","rc":[{"atl":[[2.26,0],[2.18,6.18]],"id":9570503}]}]}
{"op":"mcm","clk":"AIWqAQCeVQDFlgE=","pt":1659347722101,"mc":[{"id":"1.201590187","rc":[{"bdatl":[[3,2.18,6.18],[7,2.28,5.8],[8,2.3,1.71],[9,2.32,4.09]],"id":9570503}]}]}
{"op":"mcm","clk":"AJeqAQChVQDQlgE=","pt":1659347722312,"mc":[{"id":"1.201590187","rc":[{"atb":[[11.5,16.37]],"id":45323444}]}]}
{"op":"mcm","clk":"AJeqAQChVQDTlgE=","pt":1659347722363,"mc":[{"id":"1.201590187","rc":[{"bdatb":[[3,11.5,16.37]],"id":45323444}]}]}
{"op":"mcm","clk":"AJmqAQCiVQDUlgE=","pt":1659347722413,"mc":[{"id":"1.201590187","rc":[{"atb":[[2.04,36.65]],"id":9570503},{"atl":[[7.6,7.95]],"id":12989514},{"atl":[[50,0]],"id":44621159}]}]}
{"op":"mcm","clk":"AKGqAQCiVQDXlgE=","pt":1659347722463,"mc":[{"id":"1.201590187","rc":[{"bdatb":[[1,2.04,36.65]],"id":9570503},{"bdatl":[[1,7.6,7.95]],"id":12989514},{"bdatl":[[3,80,2.32]],"id":44621159}]}]}
{"op":"mcm","clk":"AKiqAQCjVQDalgE=","pt":1659347722526,"mc":[{"id":"1.201590187","rc":[{"atb":[[13.5,0.21],[13,4.89]],"id":45323444},{"atl":[[55,0.64]],"id":44621159}]}]}
{"op":"mcm","clk":"AKiqAQCkVQDblgE=","pt":1659347722576,"mc":[{"id":"1.201590187","rc":[{"bdatb":[[0,13,5.1],[1,12.5,1.35]],"id":45323444},{"bdatl":[[7,2.28,2.47],[8,2.3,3.3],[9,2.32,1.69]],"id":9570503},{"bdatl":[[3,80,2.96]],"id":44621159},{"bdatl":[[9,14.5,14.07]],"id":43885158}]}]}
{"op":"mcm","clk":"ANSqAQC2VQD4lgE=","pt":1659347723246,"mc":[{"id":"1.201590187","rc":[{"atb":[[13,0.47]],"id":45323444}]}]}
{"op":"mcm","clk":"ANSqAQC2VQD6lgE=","pt":1659347723296,"mc":[{"id":"1.201590187","rc":[{"bdatb":[[0,12.5,2.03],[1,12,1.76],[2,11.5,16.37],[3,11,1.23],[4,10.5,3.81],[5,10,14.37],[6,9.8,9],[7,9.6,21.94],[8,9.4,54.1],[9,9.2,14.7]],"id":45323444},{"bdatl":[[8,2.3,1.43],[9,2.32,1.85]],"id":9570503}]}]}
{"op":"mcm","clk":"AOCqAQC9VQCFlwE=","pt":1659347723458,"mc":[{"id":"1.201590187","rc":[{"atb":[[12.5,5.95]],"id":45323444},{"atl":[[7.4,7.7]],"id":12989514}]}]}
{"op":"mcm","clk":"AOKqAQC9VQCIlwE=","pt":1659347723508,"mc":[{"id":"1.201590187","rc":[{"bdatb":[[0,12.5,6.63],[9,9.2,13.25]],"id":45323444},{"bdatl":[[0,7.4,7.7]],"id":12989514},{"bdatb":[[8,7,131.64],[9,6.8,4.5]],"id":43885158}]}]}
{"op":"mcm","clk":"APmqAQC/VQCZlwE=","pt":1659347723906,"mc":[{"id":"1.201590187","rc":[{"atb":[[2.06,1.52]],"id":9570503}]}]}
{"op":"mcm","clk":"AP2qAQDBVQCglwE=","pt":1659347723956,"mc":[{"id":"1.201590187","rc":[{"bdatb":[[0,2.06,1.52]],"id":9570503}]}]}
{"op":"mcm","clk":"AIurAQDGVQCtlwE=","pt":1659347724133,"mc":[{"id":"1.201590187","rc":[{"atl":[[2.12,18.47]],"trd":[[2.12,157.39]],"ltp":2.12,"tv":1044.35,"id":9570503},{"atl":[[7.4,5.4]],"id":12989514}],"tv":1758.78}]}
{"op":"mcm","clk":"AI2rAQDGVQCtlwE=","pt":1659347724184,"mc":[{"id":"1.201590187","rc":[{"bdatb":[[7,9.6,21.28],[9,9.2,12.09]],"id":45323444},{"bdatl":[[0,2.12,18.47]],"id":9570503},{"bdatl":[[0,7.4,5.4]],"id":12989514},{"bdatb":[[6,7.4,4.62],[7,7.2,8.02],[8,7,130.8],[9,6.8,6.3]],"id":43885158}]}]}
{"op":"mcm","clk":"AI6rAQDHVQCzlwE=","pt":1659347724234,"mc":[{"id":"1.201590187","rc":[{"atb":[[12.5,1.35]],"id":45323444},{"atl":[[2.14,36.01]],"id":9570503},{"atl":[[7.4,3]],"id":12989514}]}]}
{"op":"mcm","clk":"AJarAQDIVQCzlwE=","pt":1659347724284,"mc":[{"id":"1.201590187","rc":[{"bdatb":[[0,12.5,2.03],[5,10,12.94],[6,9.8,10.46],[7,9.6,21],[8,9.4,54.38],[9,9.2,12]],"id":45323444},{"bdatb":[[7,1.96,2.98],[8,1.95,1.76],[9,1.94,9.13]],"bdatl":[[1,2.14,36.01]],"id":9570503},{"bdatl":[[0,7.4,3]],"id":12989514},{"bdatb":[[8,5.8,10.01],[9,5.7,81.53]],"id":44836671},{"bdatb":[[6,7.4,2.33],[7,7.2,10.37]],"id":43885158}]}]}
{"op":"mcm","clk":"AKWrAQDLVQC9lwE=","pt":1659347724450,"mc":[{"id":"1.201590187","rc":[{"atb":[[12,6.53],[11.5,5.75]],"id":45323444},{"atb":[[2.02,15.88]],"id":9570503}]}]}
{"op":"mcm","clk":"AKarAQDLVQC+lwE=","pt":1659347724500,"mc":[{"id":"1.201590187","rc":[{"bdatb":[[1,12,6.53],[2,11.5,5.75]],"id":45323444},{"bdatb":[[2,2.02,15.88]],"id":9570503}]}]}
{"op":"mcm","clk":"ALerAQDNVQDFlwE=","pt":1659347724736,"mc":[{"id":"1.201590187","rc":[{"atl":[[10,3.3]],"id":43885158},{"atb":[[21,1.15]],"atl":[[23,1.15]],"id":46969227}]}]}
{"op":"mcm","clk":"ALyrAQDOVQDKlwE=","pt":1659347724786,"mc":[{"id":"1.201590187","rc":[{"bdatb":[[3,11,3.24],[4,10.5,2.17],[5,10,13.53],[6,9.8,9.63],[8,9.4,55.04]],"id":45323444},{"bdatb":[[3,2,103.93],[4,1.99,3.26],[5,1.98,70.49],[6,1.97,4.68],[7,1.96,5.96],[9,1.94,7.84]],"bdatl":[[7,2.26,1.25],[8,2.28,2.67],[9,2.3,1.87]],"id":9570503},{"bdatb":[[5,6,6.17],[6,5.9,2.87],[7,5.8,35.31],[8,5.7,224.85]],"id":12989514},{"bdatb":[[8,17.5,2.03],[9,15.5,4.64]],"id":44621159},{"bdatb":[[6,6,230.95],[7,5.9,10.11],[8,5.8,10],[9,5.7,80.1]],"id":44836671},{"bdatb":[[4,7.8,4.23],[5,7.6,6.85],[6,7.4,2.89],[7,7.2,9.78]],"bdatl":[[0,10,3.3],[8,14,13.4],[9,14.5,13.89]],"id":43885158},{"bdatb":[[0,21,1.15],[1,20,4.48],[2,19,7.44],[3,18.5,8],[4,18,5],[5,17.5,9.76],[6,17,1.76],[7,16.5,1.76],[8,16,1.43],[9,15.5,1.76]],"bdatl":[[0,23,1.15],[1,24,5.22],[2,26,6.2],[3,27,1.86],[4,28,7.64],[5,29,1.76],[6,30,5.28],[7,32,1.76],[8,34,5],[9,36,1.76]],"id":46969227}]}]}
{"op":"mcm","clk":"AL2rAQDOVQDNlwE=","pt":1659347724841,"mc":[{"id":"1.201590187","rc":[{"atl":[[10.5,1.15]],"id":43885158},{"atl":[[28,7.55],[23,1.37]],"id":46969227}]}]}
{"op":"mcm","clk":"AMOrAQDPVQDOlwE=","pt":1659347724892,"mc":[{"id":"1.201590187","rc":[{"bdatb":[[4,10.5,2.65],[5,10,13.02],[8,9.4,54.72]],"id":45323444},{"bdatb":[[6,1.97,7.25],[7,1.96,3.38]],"id":9570503},{"bdatb":[[5,6,7.01],[6,5.9,2.02]],"id":12989514},{"bdatb":[[9,15.5,4.96]],"id":44621159},{"bdatb":[[6,6,231.79],[7,5.9,9.25]],"id":44836671},{"bdatb":[[6,7.4,3.58],[7,7.2,9.08]],"bdatl":[[1,10.5,1.15]],"id":43885158},{"bdatl":[[0,23,1.37],[4,28,7.55]],"id":46969227}]}]}
{"op":"mcm","clk":"AMerAQDQVQDTlwE=","pt":1659347724942,"mc":[{"id":"1.201590187","rc":[{"atb":[[6.8,1.75]],"bdatb":[[1,6.8,1.75],[5,6,5.35],[6,5.9,1.76],[7,5.8,37.03],[8,5.7,224.13],[9,5.6,2.2]],"id":12989514},{"atl":[[10,2.15]],"bdatl":[[0,10,2.15]],"id":43885158},{"atb":[[19.5,4.24],[17.5,1.76]],"bdatb":[[2,19.5,4.24],[3,19,7.2],[4,18.5,8],[5,18,5],[6,17.5,1.76],[7,17,1.76],[8,16.5,1.76],[9,16,1.43]],"id":46969227},{"bdatb":[[3,11,3.18],[4,10.5,1.83],[5,10,13.8],[6,9.8,9.21],[8,9.4,54.69]],"id":45323444},{"bdatb":[[4,1.99,2.92],[5,1.98,70.48],[6,1.97,2.87],[7,1.96,2.63],[8,1.95,6.53],[9,1.94,2.83]],"id":9570503},{"bdatb":[[9,15.5,4.37]],"id":44621159},{"bdatb":[[6,6,230.24],[7,5.9,9.01],[8,5.8,11.6],[9,5.7,79.39]],"id":44836671}]}]}
{"op":"mcm","clk":"AM6rAQDRVQDUlwE=","pt":1659347725003,"mc":[{"id":"1.201590187","rc":[{"atl":[[7.8,14.75]],"id":44836671}]}]}
{"op":"mcm","clk":"ANOrAQDTVQDVlwE=","pt":1659347725053,"mc":[{"id":"1.201590187","rc":[{"bdatl":[[1,7.8,14.75]],"id":44836671}]}]}
{"op":"mcm","clk":"ANyrAQDUVQDdlwE=","pt":1659347725213,"mc":[{"id":"1.201590187","rc":[{"atb":[[12,1.76]],"id":45323444}]}]}
{"op":"mcm","clk":"AOWrAQDUVQDflwE=","pt":1659347725263,"mc":[{"id":"1.201590187","rc":[{"bdatb":[[1,12,1.76]],"id":45323444}]}]}
{"op":"mcm","clk":"AOirAQDUVQDhlwE=","pt":1659347725313,"mc":[{"id":"1.201590187","rc":[{"atb":[[12.5,5.95]],"id":45323444}]}]}
{"op":"mcm","clk":"APGrAQDVVQDllwE=","pt":1659347725363,"mc":[{"id":"1.201590187","rc":[{"bdatb":[[0,12.5,6.63]],"id":45323444}]}]}
{"op":"mcm","clk":"APOrAQDVVQDmlwE=","pt":1659347725414,"mc":[{"id":"1.201590187","rc":[{"atb":[[2.02,18.34]],"id":9570503},{"atb":[[6.6,12.72]],"id":12989514}]}]}
{"op":"mcm","clk":"APqrAQDWVQDmlwE=","pt":1659347725464,"mc":[{"id":"1.201590187","rc":[{"bdatb":[[2,2.02,18.34]],"id":9570503},{"bdatb":[[2,6.6,12.72]],"id":12989514}]}]}
{"op":"mcm","clk":"APurAQDWVQDrlwE=","pt":1659347725518,"mc":[{"id":"1.201590187","rc":[{"atl":[[25,0]],"id":45323444},{"atb":[[2.02,11.72]],"id":9570503}]}]}
{"op":"mcm","clk":"AIOsAQDXVQDslwE=","pt":1659347725568,"mc":[{"id":"1.201590187","rc":[{"bdatb":[[2,2.02,11.72]],"id":9570503}]}]}
{"op":"mcm","clk":"AISsAQDXVQDulwE=","pt":1659347725618,"mc":[{"id":"1.201590187","rc":[{"atl":[[24,1.44]],"id":45323444}]}]}
{"op":"mcm","clk":"AJGsAQDZVQD3lwE=","pt":1659347725823,"mc":[{"id":"1.201590187","rc":[{"atl":[[7.4,0]],"id":12989514},{"atb":[[20,1.51]],"id":46969227}]}]}
{"op":"mcm","clk":"AJasAQDcVQD6lwE=","pt":1659347725873,"mc":[{"id":"1.201590187","rc":[{"bdatb":[[3,11,1.23],[4,10.5,3.81],[5,10,13.87]],"id":45323444},{"bdatb":[[3,2,94.33],[4,1.99,1.76],[5,1.98,81.33],[6,1.97,2.53],[7,1.96,2.96],[8,1.95,6.54]],"id":9570503},{"bdatl":[[0,7.6,7.95],[1,7.8,4.19],[2,8,1.76],[3,8.2,1.76],[4,8.4,4],[5,8.6,1.76],[6,8.8,1.76],[7,9,6.82],[8,9.2,1.76],[9,9.4,1.76]],"id":12989514},{"bdatb":[[8,16.5,2.09],[9,15.5,4.33]],"id":44621159},{"bdatb":[[5,6.2,25.79],[6,6,233.32],[7,5.9,9],[8,5.8,11.72]],"id":44836671},{"bdatb":[[4,7.8,1.76],[5,7.6,8.98],[6,7.4,3.98],[9,6.8,4.07]],"id":43885158},{"bdatb":[[1,20,1.51]],"id":46969227}]}]}
{"op":"mcm","clk":"AKCsAQDfVQD8lwE=","pt":1659347725945,"mc":[{"id":"1.201590187","rc":[{"atb":[[13,3.47]],"id":45323444},{"atl":[[7.6,113.59]],"id":44836671}]}]}
{"op":"mcm","clk":"AKCsAQDfVQCBmAE=","pt":1659347725996,"mc":[{"id":"1.201590187","rc":[{"bdatb":[[0,13,3.68],[1,12.5,5.95],[2,12,1.76],[3,11.5,5.75],[4,11,1.23],[5,10.5,3.81],[6,10,13.87],[7,9.8,9.21],[8,9.6,21],[9,9.4,54.69]],"id":45323444},{"bdatl":[[8,2.28,4.56],[9,2.3,1.71]],"id":9570503},{"bdatl":[[0,7.6,113.59]],"id":44836671}]}]}
{"op":"mcm","clk":"AKesAQDjVQCFmAE=","pt":1659347726052,"mc":[{"id":"1.201590187","rc":[{"atb":[[12.5,1.35]],"id":45323444}]}]}
{"op":"mcm","clk":"AKisAQDjVQCHmAE=","pt":1659347726102,"mc":[{"id":"1.201590187","rc":[{"bdatb":[[1,12.5,1.35]],"id":45323444}]}]}
{"op":"mcm","clk":"ALGsAQDnVQCNmAE=","pt":1659347726199,"mc":[{"id":"1.201590187","rc":[{"atb":[[12,6.53]],"id":45323444}]}]}
{"op":"mcm","clk":"ALWsAQDoVQCRmAE=","pt":1659347726252,"mc":[{"id":"1.201590187","rc":[{"bdatb":[[2,12,6.53]],"id":45323444}]}]}
{"op":"mcm","clk":"AL+sAQDuVQCYmAE=","pt":1659347726404,"mc":[{"id":"1.201590187","rc":[{"atb":[[2.02,17.23]],"atl":[[2.14,39.62]],"id":9570503},{"atl":[[7.8,12.37],[7.6,10.27]],"id":12989514}]}]}
{"op":"mcm","clk":"AMOsAQDuVQCbmAE=","pt":1659347726454,"mc":[{"id":"1.201590187","rc":[{"bdatb":[[2,2.02,17.23]],"bdatl":[[1,2.14,39.62]],"id":9570503},{"bdatl":[[0,7.6,10.27],[1,7.8,12.37]],"id":12989514},{"bdatb":[[9,6.8,6.3]],"id":43885158}]}]}
{"op":"mcm","clk":"AMqsAQDvVQCfmAE=","pt":1659347726517,"mc":[{"id":"1.201590187","rc":[{"atl":[[7.8,12.92],[7.6,12.57]],"id":12989514}]}]}
{"op":"mcm","clk":"AMqsAQDvVQChmAE=","pt":1659347726567,"mc":[{"id":"1.201590187","rc":[{"bdatl":[[0,7.6,12.57],[1,7.8,12.92]],"id":12989514}]}]}
{"op":"mcm","clk":"AN+sAQD5VQC8mAE=","pt":1659347727036,"mc":[{"id":"1.201590187","rc":[{"atb":[[12,1.76]],"id":45323444},{"atb":[[2.02,50.78]],"id":9570503}]}]}
{"op":"mcm","clk":"AOCsAQD5VQDAmAE=","pt":1659347727086,"mc":[{"id":"1.201590187","rc":[{"bdatb":[[2,12,1.76]],"id":45323444},{"bdatb":[[2,2.02,50.78]],"id":9570503}]}]}
{"op":"mcm","clk":"AOWsAQD6VQDCmAE=","pt":1659347727136,"mc":[{"id":"1.201590187","rc":[{"atb":[[8.4,2]],"id":43885158}]}]}
{"op":"mcm","clk":"AOesAQD9VQDImAE=","pt":1659347727186,"mc":[{"id":"1.201590187","rc":[{"bdatb":[[1,8.4,2]],"id":43885158}]}]}
{"op":"mcm","clk":"AOqsAQD+VQDKmAE=","pt":1659347727243,"mc":[{"id":"1.201590187","rc":[{"atl":[[10,1.15]],"id":43885158}]}]}
{"op":"mcm","clk":"AOusAQCAVgDLmAE=","pt":1659347727293,"mc":[{"id":"1.201590187","rc":[{"bdatb":[[5,10.5,2.86],[6,10,14.08],[7,9.8,9],[8,9.6,21.83],[9,9.4,54.91]],"id":45323444},{"bdatb":[[5,1.98,76.28],[7,1.96,8.06],[8,1.95,2.48],[9,1.94,1.76]],"id":9570503},{"bdatb":[[5,6,3.68],[6,5.9,3.07],[7,5.8,36.06],[8,5.7,223.76],[9,5.6,3.99]],"id":12989514},{"bdatb":[[8,16.5,1.63],[9,15.5,4.69]],"id":44621159},{"bdatb":[[6,6,231.66],[7,5.9,10.31],[8,5.8,10.75],[9,5.7,79.02]],"id":44836671},{"bdatl":[[0,10,1.15]],"id":43885158}]}]}
{"op":"mcm","clk":"APisAQCEVgDSmAE=","pt":1659347727451,"mc":[{"id":"1.201590187","rc":[{"atb":[[7.2,15.64]],"id":43885158}]}]}
{"op":"mcm","clk":"APmsAQCFVgDUmAE=","pt":1659347727501,"mc":[{"id":"1.201590187","rc":[{"bdatb":[[7,7.2,16.7]],"id":43885158}]}]}
{"op":"mcm","clk":"AKWtAQCgVgCAmQE=","pt":1659347728322,"mc":[{"id":"1.201590187","rc":[{"atb":[[7,5.1]],"id":44836671}]}]}
{"op":"mcm","clk":"AKatAQCnVgCDmQE=","pt":1659347728372,"mc":[{"id":"1.201590187","rc":[{"bdatb":[[1,7,5.1]],"id":44836671}]}]}
{"op":"mcm","clk":"AKmtAQCoVgCHmQE=","pt":1659347728429,"mc":[{"id":"1.201590187","rc":[{"atb":[[6.8,18.54]],"id":44836671}]}]}
{"op":"mcm","clk":"AK2tAQCqVgCOmQE=","pt":1659347728479,"mc":[{"id":"1.201590187","rc":[{"bdatb":[[2,6.8,18.54]],"id":44836671}]}]}
{"op":"mcm","clk":"ANmtAQDEVgDPmQE=","pt":1659347729726,"mc":[{"id":"1.201590187","rc":[{"atb":[[1.75,34.48]],"id":9570503},{"atb":[[5.6,12]],"id":44836671},{"atb":[[6,14]],"id":43885158}]}]}
{"op":"mcm","clk":"AN+tAQDGVgDVmQE=","pt":1659347729830,"mc":[{"id":"1.201590187","rc":[{"atb":[[9.4,36.86],[13,0.47]],"id":45323444},{"atb":[[3.9,44.48]],"id":12989514},{"atb":[[8.8,34.48]],"id":46969227}]}]}
{"op":"mcm","clk":"AOKtAQDJVgDXmQE=","pt":1659347729880,"mc":[{"id":"1.201590187","rc":[{"bdatb":[[0,12.5,2.03],[1,12,1.76],[2,11.5,5.75],[3,11,1.23],[4,10.5,2.86],[5,10,14.08],[6,9.8,9],[7,9.6,21.83],[8,9.4,37.67],[9,9.2,12]],"id":45323444},{"bdatl":[[8,2.28,2.67],[9,2.3,1.87]],"id":9570503}]}]}
{"op":"mcm","clk":"AOStAQDJVgDYmQE=","pt":1659347729932,"mc":[{"id":"1.201590187","rc":[{"atb":[[2.04,47.65]],"id":9570503}]}]}
{"op":"mcm","clk":"AOitAQDNVgDcmQE=","pt":1659347729982,"mc":[{"id":"1.201590187","rc":[{"bdatb":[[1,2.04,47.65]],"id":9570503}]}]}
{"op":"mcm","clk":"AIGuAQDoVgDymQE=","pt":1659347730460,"mc":[{"id":"1.201590187","rc":[{"atb":[[11,7.39],[10.5,4.19]],"id":45323444},{"atl":[[36,0]],"id":44621159}]}]}
{"op":"mcm","clk":"AIauAQDrVgD3mQE=","pt":1659347730511,"mc":[{"id":"1.201590187","rc":[{"atb":[[12.5,5.95]],"bdatb":[[3,11,7.39],[4,10.5,4.19],[5,10,14.02],[6,9.8,10.23],[7,9.6,21],[8,9.4,38.52]],"id":45323444},{"atb":[[25,0.33]],"bdatl":[[0,38,2.02],[1,40,3.27],[2,80,2.96],[3,170,2],[4,900,1.14],[5,990,1.83],[6,1000,2],[7,0,0]],"id":44621159},{"bdatb":[[7,1.96,6.55],[8,1.95,3.29],[9,1.94,2.48]],"id":9570503},{"bdatb":[[7,5.8,35.82],[8,5.7,224.01],[9,5.6,3.18]],"id":12989514},{"bdatb":[[8,5.8,10.51],[9,5.7,79.27]],"id":44836671},{"bdatb":[[5,7.6,6.45],[6,7.4,5.32],[7,7.2,18]],"id":43885158}]}]}
{"op":"mcm","clk":"AIquAQDuVgD6mQE=","pt":1659347730561,"mc":[{"id":"1.201590187","rc":[{"bdatb":[[0,12.5,6.63]],"id":45323444},{"bdatb":[[1,23,7.13],[2,22,3.56],[3,21,5],[4,20,1.76],[5,19.5,1.76],[6,19,1.76],[7,16.5,1.63],[8,15.5,4.69],[9,13.5,8.02]],"id":44621159}]}]}
{"op":"mcm","clk":"AK2uAQCCVwCXmgE=","pt":1659347731335,"mc":[{"id":"1.201590187","rc":[{"atb":[[12.5,1.35],[11.5,0.21]],"id":45323444},{"atb":[[7,3.6]],"atl":[[7.4,1.15]],"id":12989514},{"atb":[[15.5,0],[26,0],[25,1.48]],"id":44621159},{"atb":[[6,218]],"id":44836671},{"atl":[[10.5,2.3]],"id":43885158}]}]}
{"op":"mcm","clk":"ALOuAQCDVwCcmgE=","pt":1659347731385,"mc":[{"id":"1.201590187","rc":[{"bdatb":[[0,12.5,2.03],[2,11,7.6],[3,10.5,5],[4,10,13.17],[5,9.8,11.46],[6,9.6,21],[7,9.4,37.23],[8,9.2,12],[9,9,16.92]],"id":45323444},{"bdatb":[[4,1.99,6.04],[5,1.98,71.99],[9,1.94,8.7]],"bdatl":[[8,2.28,1.23],[9,2.3,1.43]],"id":9570503},{"bdatb":[[0,7,3.6],[8,5.7,226.12],[9,5.6,1.76]],"bdatl":[[0,7.4,1.15],[1,7.6,12.57],[2,7.8,12.92],[3,8,1.76],[4,8.2,1.76],[5,8.4,4],[6,8.6,1.76],[7,8.8,1.76],[8,9,6.82],[9,9.2,1.76]],"id":12989514},{"bdatb":[[0,25,1.48],[1,23,6.8],[7,17.5,1.42],[8,14.5,1.52],[9,13.5,7.12]],"id":44621159},{"bdatb":[[5,6.2,27.16],[6,6,218.5],[9,5.7,81.38]],"id":44836671},{"bdatb":[[5,7.6,7.57],[6,7.4,4.17]],"bdatl":[[1,10.5,2.3],[8,14,13.2],[9,14.5,14.07]],"id":43885158}]}]}
{"op":"mcm","clk":"ALauAQCDVwCemgE=","pt":1659347731440,"mc":[{"id":"1.201590187","rc":[{"atb":[[10.5,1.76]],"id":45323444}]}]}
{"op":"mcm","clk":"ALyuAQCFVwCjmgE=","pt":1659347731491,"mc":[{"id":"1.201590187","rc":[{"bdatb":[[3,10.5,2.57]],"id":45323444}]}]}
{"op":"mcm","clk":"AL2uAQCFVwClmgE=","pt":1659347731543,"mc":[{"id":"1.201590187","rc":[{"atb":[[12,6.53]],"id":45323444},{"atb":[[2.1,13.4],[2.04,33.47]],"id":9570503},{"atb":[[7,1.15],[6.4,14.11]],"id":12989514},{"atb":[[8.4,0],[8.2,3.76]],"atl":[[10,0]],"id":43885158},{"atb":[[21,0]],"atl":[[23,0.22]],"id":46969227}]}]}
{"op":"mcm","clk":"AMKuAQCIVwCqmgE=","pt":1659347731593,"mc":[{"id":"1.201590187","rc":[{"bdatb":[[1,12,6.53],[3,10.5,1.76],[4,10,13.72],[5,9.8,10.59],[7,9.4,38.46],[9,9,15.65]],"id":45323444},{"bdatb":[[0,2.1,13.4],[1,2.06,1.52],[2,2.04,33.47],[3,2.02,50.78],[4,2,94.33],[5,1.99,1.76],[6,1.98,70.48],[7,1.97,6.85],[8,1.96,2.62],[9,1.95,7.25]],"bdatl":[[7,2.28,1.24],[8,2.3,2.27],[9,2.34,2.21]],"id":9570503},{"bdatb":[[0,7,1.15],[3,6.4,14.11],[5,6,1.76],[6,5.9,2.62],[7,5.8,37.75],[8,5.7,224.63]],"id":12989514},{"bdatb":[[7,16.5,1.24],[8,14.5,1.13],[9,13.5,7.81]],"bdatl":[[4,900,1.15]],"id":44621159},{"bdatb":[[5,6.2,25.79],[6,6,218.84],[7,5.9,9.58],[8,5.8,11.84],[9,5.7,79.89]],"id":44836671},{"bdatb":[[1,8.2,3.76],[2,8,1.46],[3,7.8,1.76],[4,7.6,7.57],[5,7.4,3.77],[6,7.2,18.41],[7,7,130.8],[8,6.8,6.3],[9,6.6,51.78]],"bdatl":[[0,10.5,2.3],[1,11,3.53],[2,11.5,14.64],[3,12,1.76],[4,12.5,10],[5,13,1.98],[6,13.5,10.15],[7,14,13.2],[8,14.5,13.93],[9,15,12.73]],"id":43885158},{"bdatb":[[0,20,1.51],[1,19.5,4.24],[2,19,7.2],[3,18.5,8],[4,18,5],[5,17.5,1.76],[6,17,1.76],[7,16.5,1.76],[8,16,1.43],[9,15.5,1.76]],"bdatl":[[0,24,5.44],[1,26,6.2],[2,27,1.86],[3,28,7.55],[4,29,1.76],[5,30,5.28],[6,32,1.76],[7,34,5],[8,36,1.76],[9,38,1.76]],"id":46969227}]}]}
{"op":"mcm","clk":"AMSuAQCIVwCtmgE=","pt":1659347731646,"mc":[{"id":"1.201590187","rc":[{"atb":[[8.6,20.88]],"id":43885158}]}]}
{"op":"mcm","clk":"AMuuAQCJVwCxmgE=","pt":1659347731696,"mc":[{"id":"1.201590187","rc":[{"bdatl":[[9,2.34,5.09]],"id":9570503},{"bdatb":[[0,8.6,21.52]],"id":43885158}]}]}
{"op":"mcm","clk":"AM2uAQCJVwCymgE=","pt":1659347731753,"mc":[{"id":"1.201590187","rc":[{"atb":[[2.08,12.8],[2.04,12.21]],"id":9570503},{"atb":[[25,3.77]],"id":44621159},{"atl":[[10.5,2.57]],"id":43885158},{"atb":[[19.5,0.24],[17.5,7.76]],"id":46969227}]}]}
{"op":"mcm","clk":"ANSuAQCMVwC2mgE=","pt":1659347731804,"mc":[{"id":"1.201590187","rc":[{"atb":[[19,5]],"bdatb":[[1,19,7.44],[2,18.5,8],[3,18,5],[4,17.5,7.76],[5,17,1.76],[6,16.5,1.76],[7,16,1.43],[8,15.5,1.76],[9,15,1.76]],"id":46969227},{"bdatb":[[5,9.8,10.88],[7,9.4,38.15],[9,9,15.96]],"id":45323444},{"bdatb":[[1,2.08,12.8],[2,2.06,1.52],[3,2.04,12.21],[4,2.02,50.78],[5,2,94.33],[6,1.99,1.76],[7,1.98,70.48],[8,1.97,6.85],[9,1.96,2.62]],"id":9570503},{"bdatb":[[8,5.7,225.13]],"id":12989514},{"bdatb":[[0,25,3.77],[9,13.5,7.8]],"id":44621159},{"bdatb":[[9,5.7,80.39]],"id":44836671},{"bdatl":[[0,10.5,2.57]],"id":43885158}]}]}
{"op":"mcm","clk":"ANauAQCOVwC6mgE=","pt":1659347731854,"mc":[{"id":"1.201590187","rc":[{"bdatb":[[1,19,5.24]],"id":46969227}]}]}
{"op":"mcm","clk":"ANuuAQCOVwDBmgE=","pt":1659347731917,"mc":[{"id":"1.201590187","rc":[{"atl":[[2.2,7.64],[2.18,1.18],[2.28,5]],"id":9570503},{"atb":[[19.5,2.44]],"id":46969227}]}]}
{"op":"mcm","clk":"ANyuAQCTVwDDmgE=","pt":1659347731967,"mc":[{"id":"1.201590187","rc":[{"bdatl":[[3,2.18,1.18],[4,2.2,7.64],[7,2.28,6.24]],"id":9570503},{"bdatb":[[1,19.5,2.44],[2,19,5],[3,18.5,8],[4,18,5],[5,17.5,7.76],[6,17,1.76],[7,16.5,1.76],[8,16,1.43],[9,15.5,1.76]],"id":46969227}]}]}
{"op":"mcm","clk":"AIGvAQCXVwDemgE=","pt":1659347732427,"mc":[{"id":"1.201590187","rc":[{"atb":[[12,1.76],[11,1.23]],"id":45323444},{"atb":[[6.6,9.57],[6.4,19.83]],"id":12989514},{"atb":[[25,1.48]],"id":44621159},{"atl":[[11.5,12.4]],"id":43885158}]}]}
{"op":"mcm","clk":"AIavAQCZVwDlmgE=","pt":1659347732477,"mc":[{"id":"1.201590187","rc":[{"bdatb":[[1,12,1.76],[2,11,1.44]],"id":45323444},{"bdatb":[[2,6.6,9.57],[3,6.4,19.83]],"id":12989514},{"bdatb":[[0,25,1.48]],"id":44621159},{"bdatl":[[2,11.5,12.4]],"id":43885158}]}]}
{"op":"mcm","clk":"AI6vAQCbVwDxmgE=","pt":1659347732634,"mc":[{"id":"1.201590187","rc":[{"atl":[[2.26,7]],"id":9570503},{"atl":[[13,5.09]],"id":43885158}]}]}
{"op":"mcm","clk":"AJWvAQCdVwDzmgE=","pt":1659347732684,"mc":[{"id":"1.201590187","rc":[{"bdatl":[[7,2.26,7],[8,2.28,6.24],[9,2.3,2.27]],"id":9570503},{"bdatl":[[5,13,5.31]],"id":43885158}]}]}
{"op":"mcm","clk":"AJivAQCdVwD2mgE=","pt":1659347732741,"mc":[{"id":"1.201590187","rc":[{"atb":[[9.4,45.48]],"id":45323444}]}]}
{"op":"mcm","clk":"AJuvAQCfVwD7mgE=","pt":1659347732791,"mc":[{"id":"1.201590187","rc":[{"bdatb":[[7,9.4,46.77]],"id":45323444}]}]}
{"op":"mcm","clk":"AKKvAQCfVwD/mgE=","pt":1659347732950,"mc":[{"id":"1.201590187","rc":[{"atb":[[7.2,11.33]],"id":43885158}]}]}
{"op":"mcm","clk":"AKivAQCjVwCFmwE=","pt":1659347733000,"mc":[{"id":"1.201590187","rc":[{"bdatb":[[6,7.2,14.1]],"id":43885158}]}]}
{"op":"mcm","clk":"AKqvAQCjVwCImwE=","pt":1659347733051,"mc":[{"id":"1.201590187","rc":[{"atl":[[2.14,36.01]],"id":9570503},{"atb":[[7.8,6.07],[8.8,2.81]],"id":43885158},{"atb":[[8.8,45.97]],"id":46969227}]}]}
{"op":"mcm","clk":"AK6vAQCkVwCJmwE=","pt":1659347733101,"mc":[{"id":"1.201590187","rc":[{"bdatl":[[1,2.14,36.01]],"id":9570503},{"bdatl":[[4,900,1.16]],"id":44621159},{"bdatb":[[0,8.8,2.81],[1,8.6,20.88],[2,8.2,3.76],[3,8,1.46],[4,7.8,6.07],[5,7.6,7.57],[6,7.4,3.77],[7,7.2,14.1],[8,7,130.8],[9,6.8,6.3]],"id":43885158}]}]}
{"op":"mcm","clk":"ALKvAQCkVwCOmwE=","pt":1659347733155,"mc":[{"id":"1.201590187","rc":[{"atb":[[24,2.91]],"id":44621159}]}]}
{"op":"mcm","clk":"ALavAQCnVwCSmwE=","pt":1659347733205,"mc":[{"id":"1.201590187","rc":[{"bdatb":[[1,24,2.91],[2,23,6.31],[3,22,3.56],[4,21,5],[5,20,1.76],[6,19.5,1.76],[7,19,1.76],[8,16.5,1.24],[9,14.5,1.13]],"id":44621159}]}]}
{"op":"mcm","clk":"ALuvAQCoVwCTmwE=","pt":1659347733255,"mc":[{"id":"1.201590187","rc":[{"atl":[[2.14,32.19]],"bdatl":[[1,2.14,32.19]],"id":9570503},{"atb":[[8.8,4.98]],"bdatb":[[0,8.8,4.98]],"id":43885158}]}]}
{"op":"mcm","clk":"AL2vAQCuVwCVmwE=","pt":1659347733312,"mc":[{"id":"1.201590187","rc":[{"atb":[[13.5,0],[1.02,0]],"atl":[[13.5,9.37]],"trd":[[13.5,0.42]],"ltp":13.5,"tv":24.02,"id":45323444},{"atb":[[7,0]],"atl":[[7,11.16]],"trd":[[7,23.01]],"ltp":7,"tv":136.54,"id":12989514},{"atb":[[7.4,11.65]],"id":44836671},{"atb":[[9.8,8.8]],"id":43885158}],"tv":1761.5}]}
{"op":"mcm","clk":"AMCvAQCuVwCXmwE=","pt":1659347733362,"mc":[{"id":"1.201590187","rc":[{"bdatb":[[0,12.5,1.82],[2,11,3.89],[3,10.5,2.92],[4,10,15.54],[5,9.8,9],[6,9.6,22.13],[7,9.4,45.63],[9,9,13]],"bdatl":[[0,13.5,9.37],[1,16,1.2],[2,17,1.51],[3,17.5,1.76],[4,18.5,1.76],[5,19,1.76],[6,19.5,1.76],[7,20,1.76],[8,21,2.33],[9,22,2.58]],"id":45323444},{"bdatb":[[3,2.04,25.43],[4,2.02,70.01],[5,2,100.5],[9,1.96,22.92]],"bdatl":[[6,2.24,9.72],[7,2.26,9.57],[8,2.28,9.86],[9,2.3,9.2]],"id":9570503},{"bdatb":[[0,6.8,1.75],[1,6.6,9.57],[2,6.4,19.83],[3,6.2,9.37],[4,6,3.79],[5,5.9,6.28],[6,5.8,37.19],[7,5.7,229.26],[8,5.6,2.22],[9,5.5,1.76]],"bdatl":[[0,7,11.16],[1,7.4,1.15],[2,7.6,12.57],[3,7.8,12.92],[4,8,1.76],[5,8.2,1.76],[6,8.4,4.72],[7,8.6,3.73],[8,8.8,1.76],[9,9,7.4]],"id":12989514},{"bdatb":[[1,24,3.12],[2,23,7.27],[4,21,5.58],[7,19,3.17],[8,17.5,1.64],[9,14.5,2.02]],"bdatl":[[2,80,3.04],[3,170,2.05],[4,900,1.21]],"id":44621159},{"bdatb":[[0,7.4,11.65],[1,7.2,17.17],[2,7,5.1],[3,6.8,19.28],[4,6.6,10.48],[5,6.4,3.67],[6,6.2,31.84],[7,6,218.24],[8,5.9,9],[9,5.8,11.47]],"bdatl":[[9,9.4,2.41]],"id":44836671},{"bdatb":[[0,9.8,8.8],[1,8.8,9.42],[2,8.6,25.25],[3,8.2,3.93],[4,8,1.46],[5,7.8,7.16],[6,7.6,9.27],[7,7.4,2.67],[8,7.2,11.69],[9,7,131.9]],"bdatl":[[5,13,5.09],[6,13.5,10.22],[7,14,13.61],[8,14.5,13.87],[9,15,12.74]],"id":43885158},{"bdatb":[[6,17,3.35],[9,15.5,2.55]],"id":46969227}]}]}
{"op":"mcm","clk":"AMGvAQCvVwCamwE=","pt":1659347733412,"mc":[{"id":"1.201590187","rc":[{"atb":[[13,0.26],[10.5,9.53]],"id":45323444},{"atl":[[7.6,85.6]],"trd":[[7.6,142.39]],"tv":363.73,"id":44836671}],"tv":1817.48}]}
{"op":"mcm","clk":"AMWvAQCxVwCemwE=","pt":1659347733463,"mc":[{"id":"1.201590187","rc":[{"bdatb":[[0,12.5,1.61],[3,10.5,10.69]],"id":45323444},{"bdatl":[[6,2.24,8.5],[7,2.26,10.78],[8,2.28,8.66]],"id":9570503},{"bdatl":[[6,8.4,4.4],[9,9,7.7]],"id":12989514},{"bdatl":[[2,80,3],[3,170,2.08],[4,900,1.19]],"id":44621159},{"bdatl":[[0,7.6,85.6],[9,9.4,2.12]],"id":44836671},{"bdatl":[[6,13.5,10.01],[7,14,13.81],[9,15,12.56]],"id":43885158}]}]}
{"op":"mcm","clk":"AMivAQCxVwCgmwE=","pt":1659347733523,"mc":[{"id":"1.201590187","rc":[{"atl":[[2.12,0.02]],"trd":[[2.12,194.3]],"tv":1081.26,"id":9570503},{"atb":[[7.4,0.01]],"atl":[[8.4,7],[7.6,80.6]],"trd":[[7.4,78.52]],"ltp":7.4,"tv":387.02,"id":44836671}],"tv":1877.68}]}
{"op":"mcm","clk":"AMyvAQCyVwChmwE=","pt":1659347733573,"mc":[{"id":"1.201590187","rc":[{"bdatb":[[2,11,1.44],[3,10.5,12.09],[4,10,16.76],[6,9.6,21.32],[7,9.4,45.48],[8,9.2,12.28]],"bdatl":[[8,21,1.77],[9,22,3.12]],"id":45323444},{"bdatl":[[0,2.14,32.21],[1,2.16,1.18],[2,2.18,1.18],[3,2.2,7.64],[4,2.22,4],[5,2.24,7.02],[6,2.26,8.47],[7,2.28,8.74],[8,2.3,3.63],[9,2.32,9.12]],"id":9570503},{"bdatb":[[3,6.2,5.03],[4,6,6.25],[5,5.9,8.35],[6,5.8,35.85],[7,5.7,223.76],[9,5.5,2.23]],"bdatl":[[6,8.4,4],[7,8.6,1.76],[8,8.8,2.14],[9,9,8.7]],"id":12989514},{"bdatb":[[1,24,2.91],[2,23,6.31],[4,21,6.28],[7,19,3.81],[8,17.5,1.11],[9,13.5,7.16]],"bdatl":[[2,80,2.96],[3,170,2.03],[4,900,1.2]],"id":44621159},{"bdatb":[[0,7.2,17.18],[1,7,5.1],[2,6.8,18.55],[3,6.6,7.92],[4,6.4,5.19],[5,6.2,32.56],[6,6,218.42],[7,5.9,9.44],[8,5.8,10],[9,5.7,79.74]],"bdatl":[[0,7.6,80.6],[4,8.4,7]],"id":44836671},{"bdatb":[[1,8.8,4.98],[2,8.6,28.89],[3,8.2,4.07],[4,8,1.78],[5,7.8,6.07],[6,7.6,6.99],[7,7.4,2.32],[8,7.2,12.51],[9,7,130.6]],"bdatl":[[6,13.5,9.77],[7,14,13.2],[8,14.5,14.1],[9,15,12.57]],"id":43885158},{"bdatb":[[6,17,1.77],[9,15.5,3.5]],"id":46969227}]}]}
{"op":"mcm","clk":"AM2vAQCzVwCkmwE=","pt":1659347733623,"mc":[{"id":"1.201590187","rc":[{"atb":[[2.1,15.03],[2,93.09]],"atl":[[2.12,0]],"trd":[[2.12,194.33]],"tv":1081.29,"id":9570503},{"atb":[[25,2.48]],"atl":[[36,1]],"id":44621159},{"atl":[[7.8,11.92]],"id":44836671}],"tv":1877.71}]}
{"op":"mcm","clk":"ANGvAQC1VwClmwE=","pt":1659347733673,"mc":[{"id":"1.201590187","rc":[{"bdatb":[[3,10.5,12.1]],"id":45323444},{"bdatb":[[0,2.1,15.03],[2,2.06,3.98],[3,2.04,22.95],[5,2,99.26],[7,1.98,74.77],[8,1.97,2.53]],"bdatl":[[0,2.14,32.19]],"id":9570503},{"bdatb":[[3,6.2,5.84],[4,6,5.42],[6,5.8,35.84]],"id":12989514},{"bdatb":[[0,25,2.48],[9,13.5,7.17]],"bdatl":[[0,36,1],[1,38,2.02],[2,40,3.27],[3,80,2.96],[4,170,2.03],[5,900,1.2],[6,990,1.83],[7,1000,2]],"id":44621159},{"bdatb":[[2,6.8,18.54],[3,6.6,11.24],[4,6.4,3.18],[5,6.2,31.09],[9,5.7,79.75]],"bdatl":[[1,7.8,11.92]],"id":44836671},{"bdatb":[[1,8.8,5.56],[2,8.6,28.3],[6,7.6,7],[9,7,130.59]],"id":43885158},{"bdatb":[[6,17,1.76],[8,16,3.11],[9,15.5,1.76]],"id":46969227}]}]}
{"op":"mcm","clk":"ANevAQC2VwCpmwE=","pt":1659347733850,"mc":[{"id":"1.201590187","rc":[{"atb":[[13,0]],"trd":[[13,5.67]],"ltp":13,"tv":24.54,"id":45323444},{"atb":[[2.04,1.21]],"id":9570503},{"atb":[[24,0.49]],"id":44621159}],"tv":1878.23}]}
{"op":"mcm","clk":"ANmvAQC5VwCtmwE=","pt":1659347733901,"mc":[{"id":"1.201590187","rc":[{"bdatb":[[0,12.5,1.35]],"id":45323444},{"bdatb":[[3,2.04,11.95]],"bdatl":[[5,2.24,7],[6,2.26,7.02],[7,2.28,10.2],[8,2.3,2.17]],"id":9570503},{"bdatl":[[7,8.6,1.77],[8,8.8,1.76],[9,9,8.69]],"id":12989514},{"bdatb":[[1,23,6.8],[2,22,3.56],[3,21,6.28],[4,20,1.76],[5,19.5,1.76],[6,19,3.81],[7,17.5,1.11],[8,13.5,7.17],[9,11.5,1.75]],"bdatl":[[4,170,2],[5,890,1],[6,990,2.05]],"id":44621159},{"bdatl":[[9,9.4,1.76]],"id":44836671},{"bdatl":[[6,13.5,9.76],[8,14.5,13.87],[9,15,12.79]],"id":43885158}]}]}
{"op":"mcm","clk":"AN6vAQC8VwCymwE=","pt":1659347733951,"mc":[{"id":"1.201590187","rc":[{"atl":[[13.5,6.91]],"trd":[[13.5,5.34]],"ltp":13.5,"tv":29.46,"id":45323444},{"atl":[[2.18,4.04]],"id":9570503},{"atb":[[8.8,9.08]],"atl":[[11,6.33]],"id":43885158}],"tv":1883.15}]}
{"op":"mcm","clk":"AN+vAQC8VwCzmwE=","pt":1659347734001,"mc":[{"id":"1.201590187","rc":[{"bdatb":[[4,10,17.06],[6,9.6,21.27],[8,9.2,12.73]],"bdatl":[[0,13.5,6.91]],"id":45323444},{"bdatb":[[4,2.02,76.12],[5,2,93.09],[6,1.99,6.04],[7,1.98,73.81],[9,1.96,2.62]],"bdatl":[[2,2.18,4.04]],"id":9570503},{"bdatb":[[5,5.9,8.87],[6,5.8,35.31],[7,5.7,224.21],[8,5.6,3.34],[9,5.5,4.13]],"id":12989514},{"bdatb":[[6,19,3.97],[7,17.5,1.08],[8,13.5,7.59],[9,11,35.29]],"id":44621159},{"bdatb":[[5,6.2,31.5],[6,6,219.12],[7,5.9,9],[9,5.7,79.39]],"id":44836671},{"bdatb":[[1,8.8,9.66],[4,8,2.3],[6,7.6,6.45],[7,7.4,2.6],[8,7.2,12.22],[9,7,130.94]],"bdatl":[[1,11,6.33]],"id":43885158}]}]}
{"op":"mcm","clk":"AOKvAQC9VwC4mwE=","pt":1659347734052,"mc":[{"id":"1.201590187","rc":[{"atb":[[12,1.96]],"atl":[[13.5,3.84]],"trd":[[13.5,11.48]],"bdatb":[[1,12,1.96]],"bdatl":[[0,13.5,3.84]],"tv":35.6,"id":45323444},{"atb":[[22,1.76]],"bdatb":[[2,22,1.76],[6,19,3.07],[7,15.5,2.03],[8,13.5,6.93],[9,11,36.45]],"id":44621159},{"bdatb":[[4,2.02,63.08],[6,1.99,1.76],[7,1.98,80.18],[8,1.97,4.04],[9,1.96,4.74]],"bdatl":[[9,2.32,10.16]],"id":9570503},{"bdatb":[[5,5.9,5.98],[7,5.7,223.76],[8,5.6,1.76],[9,5.5,4.87]],"id":12989514},{"bdatb":[[5,6.2,28.34],[6,6,218],[7,5.9,11.89],[9,5.7,79.47]],"id":44836671},{"bdatb":[[2,8.6,26.32],[3,8.2,3.76],[4,8,1.46],[5,7.8,8.26],[7,7.4,2.67],[8,7.2,11.68],[9,7,130.59]],"id":43885158}],"tv":1889.29}]}
{"op":"mcm","clk":"AOSvAQC9VwC8mwE=","pt":1659347734137,"mc":[{"id":"1.201590187","rc":[{"atb":[[23,8.11]],"id":44621159}]}]}
{"op":"mcm","clk":"AOivAQDCVwDAmwE=","pt":1659347734187,"mc":[{"id":"1.201590187","rc":[{"bdatb":[[1,23,8.6]],"id":44621159}]}]}
{"op":"mcm","clk":"AP+vAQDNVwDLmwE=","pt":1659347734461,"mc":[{"id":"1.201590187","rc":[{"atb":[[10.5,1.76],[10,15.25]],"id":45323444},{"atl":[[2.18,10.73]],"id":9570503},{"atb":[[6.4,14.11]],"id":12989514},{"atb":[[19.5,0.24]],"id":46969227}]}]}
{"op":"mcm","clk":"AICwAQDNVwDOmwE=","pt":1659347734511,"mc":[{"id":"1.201590187","rc":[{"bdatb":[[3,10.5,4.33],[4,10,19.44]],"id":45323444},{"bdatl":[[2,2.18,10.73]],"id":9570503},{"bdatb":[[2,6.4,14.11]],"id":12989514},{"bdatb":[[9,12,1.03]],"id":44621159},{"bdatb":[[1,19,5.24],[2,18.5,8],[3,18,5],[4,17.5,7.76],[5,17,1.76],[6,16.5,1.76],[7,16,3.11],[8,15.5,1.76],[9,15,2.37]],"id":46969227}]}]}
{"op":"mcm","clk":"AIKwAQDOVwDQmwE=","pt":1659347734562,"mc":[{"id":"1.201590187","rc":[{"atb":[[1.02,1.6]],"id":45323444},{"atb":[[25,4.77]],"id":44621159},{"atb":[[9.2,1.76]],"id":43885158},{"atb":[[19,7.2]],"id":46969227}]}]}
{"op":"mcm","clk":"AIawAQDSVwDUmwE=","pt":1659347734612,"mc":[{"id":"1.201590187","rc":[{"bdatb":[[0,25,4.77]],"id":44621159},{"bdatb":[[1,9.2,1.76],[2,8.8,9.66],[3,8.6,26.32],[4,8.2,3.76],[5,8,1.46],[6,7.8,8.26],[7,7.6,6.45],[8,7.4,2.67],[9,7.2,11.68]],"id":43885158},{"bdatb":[[1,19,7.44]],"id":46969227}]}]}
{"op":"mcm","clk":"AKewAQDiVwD2mwE=","pt":1659347735227,"mc":[{"id":"1.201590187","rc":[{"atb":[[2.1,7.56]],"trd":[[2.1,105.91]],"ltp":2.1,"tv":1096.23,"id":9570503}],"tv":1904.23}]}
{"op":"mcm","clk":"AKqwAQDjVwD7mwE=","pt":1659347735277,"mc":[{"id":"1.201590187","rc":[{"bdatb":[[0,2.1,7.56]],"id":9570503},{"bdatl":[[9,9,8.58]],"id":12989514}]}]}
{"op":"mcm","clk":"AKywAQDjVwD/mwE=","pt":1659347735335,"mc":[{"id":"1.201590187","rc":[{"atl":[[17,0.18]],"id":45323444},{"atb":[[2.08,14.39]],"id":9570503},{"atb":[[6.6,7.17]],"id":12989514},{"atb":[[25,2.48]],"id":44621159},{"atl":[[10.5,1.42]],"id":43885158}]}]}
{"op":"mcm","clk":"ALOwAQDpVwCBnAE=","pt":1659347735385,"mc":[{"id":"1.201590187","rc":[{"bdatb":[[3,10.5,3.18],[4,10,20.64]],"bdatl":[[2,17.5,2.12],[3,18.5,1.76],[4,19,1.76],[5,19.5,1.76],[6,20,1.76],[7,21,1.77],[8,22,3.12],[9,23,1.76]],"id":45323444},{"bdatb":[[1,2.08,14.39],[3,2.04,6.03],[4,2.02,69.06]],"id":9570503},{"bdatb":[[1,6.6,7.17],[4,6,3.4],[5,5.9,8.02]],"id":12989514},{"bdatb":[[0,25,2.48],[3,21,5.71],[6,19,3.71],[9,11,35.56]],"id":44621159},{"bdatb":[[3,6.6,9.41],[4,6.4,5.06]],"id":44836671},{"bdatl":[[0,10.5,1.42]],"id":43885158},{"bdatb":[[7,16,2.36],[9,15,3.17]],"id":46969227}]}]}
{"op":"mcm","clk":"ALWwAQDpVwCEnAE=","pt":1659347735437,"mc":[{"id":"1.201590187","rc":[{"atb":[[6.6,4.92]],"atl":[[7,7.05]],"trd":[[7,31.24]],"tv":144.77,"id":12989514}],"tv":1912.46}]}
{"op":"mcm","clk":"ALuwAQDsVwCHnAE=","pt":1659347735487,"mc":[{"id":"1.201590187","rc":[{"bdatb":[[4,10,18.69],[6,9.6,21],[8,9.2,12.92],[9,9,14.23]],"id":45323444},{"bdatb":[[4,2.02,67.84],[6,1.99,3],[7,1.98,70.48],[8,1.97,2.53],[9,1.96,2.62]],"id":9570503},{"bdatb":[[1,6.6,4.92]],"bdatl":[[0,7,7.05]],"id":12989514},{"bdatb":[[6,19,3.58],[7,16.5,1.08],[8,13.5,6.99],[9,12.5,1.02]],"id":44621159},{"bdatb":[[5,6.2,27.94],[6,6,218.41],[7,5.9,9],[9,5.7,79.02]],"id":44836671},{"bdatb":[[3,8.6,26.03],[5,8,1.77],[6,7.8,6.07],[8,7.4,2.32],[9,7.2,12.17]],"id":43885158}]}]}
{"op":"mcm","clk":"AL2wAQDsVwCNnAE=","pt":1659347735545,"mc":[{"id":"1.201590187","rc":[{"atb":[[26,2.18]],"id":44621159}]}]}
{"op":"mcm","clk":"AMCwAQDuVwCQnAE=","pt":1659347735596,"mc":[{"id":"1.201590187","rc":[{"bdatl":[[6,20,1.77],[7,21,1.76]],"id":45323444},{"bdatl":[[5,2.24,7.02],[6,2.26,12.25],[7,2.28,7.19],[8,2.3,5.83],[9,2.32,4.38]],"id":9570503},{"bdatl":[[8,8.8,3.56],[9,9,6.82]],"id":12989514},{"bdatb":[[0,26,2.18],[1,25,2.48],[2,23,8.6],[3,22,1.76],[4,21,5.71],[5,20,1.76],[6,19.5,1.76],[7,19,3.58],[8,16.5,1.08],[9,13.5,6.99]],"id":44621159},{"bdatl":[[8,14.5,14.69],[9,15,12]],"id":43885158}]}]}
{"op":"mcm","clk":"AMKwAQDuVwCSnAE=","pt":1659347735649,"mc":[{"id":"1.201590187","rc":[{"atl":[[13.5,0.74]],"trd":[[13.5,17.69]],"tv":41.81,"id":45323444},{"atl":[[7,2.9]],"trd":[[7,39.54]],"tv":153.07,"id":12989514}],"tv":1926.97}]}
{"op":"mcm","clk":"AMewAQDwVwCUnAE=","pt":1659347735699,"mc":[{"id":"1.201590187","rc":[{"bdatb":[[4,10,15.79],[7,9.4,46.38],[8,9.2,12],[9,9,17.45]],"bdatl":[[0,16,1.94],[1,17.5,2.12],[2,18.5,1.76],[3,19,1.76],[4,19.5,1.76],[5,20,1.77],[6,21,1.76],[7,22,3.12],[8,23,1.76],[9,24,1.6]],"id":45323444},{"bdatb":[[3,2.04,3.6],[4,2.02,50.78],[5,2,95.58],[6,1.99,1.76],[7,1.98,73.21]],"id":9570503},{"bdatb":[[4,6,2.58],[5,5.9,1.76],[7,5.7,224.64],[8,5.6,4.3],[9,5.5,2.3]],"bdatl":[[0,7,2.9]],"id":12989514},{"bdatb":[[4,21,5.47],[7,19,1.76],[8,16.5,1.23],[9,13.5,7.52]],"id":44621159},{"bdatb":[[3,6.6,8.66],[4,6.4,1.76],[5,6.2,25.79],[6,6,218.83],[7,5.9,9.92],[9,5.7,80.51]],"id":44836671},{"bdatb":[[3,8.6,21.45],[5,8,1.46],[6,7.8,7.4],[8,7.4,3.47],[9,7.2,11.37]],"id":43885158},{"bdatb":[[7,16,2.05],[9,15,1.76]],"id":46969227}]}]}
{"op":"mcm","clk":"AMiwAQDwVwCVnAE=","pt":1659347735755,"mc":[{"id":"1.201590187","rc":[{"atb":[[6.8,0.4]],"atl":[[7,0],[11,23.84],[9.6,22.72]],"trd":[[7,45.34]],"tv":158.87,"id":12989514},{"atb":[[24,4.84],[23,3.56]],"id":44621159}],"tv":1932.77}]}
{"op":"mcm","clk":"AMqwAQDzVwCYnAE=","pt":1659347735805,"mc":[{"id":"1.201590187","rc":[{"bdatb":[[3,10.5,1.76],[4,10,15.75],[5,9.8,9.35],[7,9.4,46.16],[9,9,19]],"bdatl":[[7,22,2.7],[9,24,1.98]],"id":45323444},{"bdatb":[[2,2.06,1.52],[3,2.04,1.21],[4,2.02,54.99],[5,2,93.8],[7,1.98,70.48],[9,1.96,5.15]],"bdatl":[[6,2.26,8.18],[7,2.28,11.21],[9,2.32,2.11]],"id":9570503},{"bdatb":[[0,6.6,5.32],[1,6.4,14.11],[2,6.2,5.84],[3,6,2.58],[4,5.9,1.76],[5,5.8,35.31],[6,5.7,224.64],[7,5.6,4.3],[8,5.5,2.3],[9,5.4,8.05]],"bdatl":[[0,7.4,1.15],[1,7.6,12.57],[2,7.8,12.92],[3,8,1.76],[4,8.2,1.76],[5,8.4,4],[6,8.6,1.77],[7,8.8,3.56],[8,9,6.82],[9,9.2,1.87]],"id":12989514},{"bdatb":[[2,24,4.84],[3,23,3.56],[4,22,1.76],[5,21,5],[6,20,1.76],[7,19.5,1.76],[8,19,1.76],[9,18.5,1.21]],"bdatl":[[5,900,1.17],[6,990,1.83]],"id":44621159},{"bdatb":[[3,6.6,7.16],[5,6.2,27.16],[6,6,218.24],[7,5.9,9],[9,5.7,79.89]],"id":44836671},{"bdatb":[[2,8.8,9.08],[3,8.6,20.88],[4,8.2,4.38],[5,8,1.89],[6,7.8,6.26],[8,7.4,2.32],[9,7.2,14]],"bdatl":[[8,14.5,14.06]],"id":43885158},{"bdatb":[[7,16,1.43]],"id":46969227}]}]}
{"op":"mcm","clk":"AMywAQDzVwCanAE=","pt":1659347735855,"mc":[{"id":"1.201590187","rc":[{"atb":[[8.4,1.76]],"id":43885158}]}]}
{"op":"mcm","clk":"ANCwAQD2VwCenAE=","pt":1659347735905,"mc":[{"id":"1.201590187","rc":[{"bdatb":[[4,8.4,1.76],[5,8.2,4.38],[6,8,1.89],[7,7.8,6.26],[8,7.6,6.45],[9,7.4,2.32]],"id":43885158}]}]}
{"op":"mcm","clk":"AO2wAQCFWACwnAE=","pt":1659347736426,"mc":[{"id":"1.201590187","rc":[{"atb":[[10.5,7.84]],"id":45323444},{"atl":[[7.6,21.93]],"id":12989514}]}]}
{"op":"mcm","clk":"APCwAQCKWAC0nAE=","pt":1659347736478,"mc":[{"id":"1.201590187","rc":[{"bdatb":[[3,10.5,7.84]],"id":45323444},{"bdatl":[[1,7.6,21.93]],"id":12989514}]}]}
{"op":"mcm","clk":"APGwAQCKWAC0nAE=","pt":1659347736528,"mc":[{"id":"1.201590187","rc":[{"atb":[[2.1,15.03]],"id":9570503}]}]}
{"op":"mcm","clk":"APSwAQCNWAC5nAE=","pt":1659347736579,"mc":[{"id":"1.201590187","rc":[{"bdatl":[[9,24,2.59]],"id":45323444},{"bdatb":[[0,2.1,15.03]],"id":9570503},{"bdatl":[[7,8.8,3.68],[9,9.2,3.36]],"id":12989514}]}]}
{"op":"mcm","clk":"AICxAQCWWADFnAE=","pt":1659347736848,"mc":[{"id":"1.201590187","rc":[{"atb":[[26,0]],"id":44621159}]}]}
{"op":"mcm","clk":"AICxAQCXWADInAE=","pt":1659347736898,"mc":[{"id":"1.201590187","rc":[{"bdatl":[[5,20,1.76],[6,21,1.77],[9,24,1.44]],"id":45323444},{"bdatl":[[5,2.24,7],[6,2.26,7.02],[7,2.28,6.17],[8,2.3,6.16],[9,2.32,7.89]],"id":9570503},{"bdatl":[[7,8.8,1.76],[8,9,8.69],[9,9.2,3.22]],"id":12989514},{"bdatb":[[0,25,2.48],[1,24,4.84],[2,23,3.56],[3,22,1.76],[4,21,5],[5,20,1.76],[6,19.5,1.76],[7,19,1.76],[8,18.5,1.21],[9,13.5,7.19]],"id":44621159},{"bdatl":[[8,14.5,13.87],[9,15,12.18]],"id":43885158}]}]}
{"op":"mcm","clk":"AJGxAQCgWADdnAE=","pt":1659347737368,"mc":[{"id":"1.201590187","rc":[{"atb":[[1.02,0]],"id":45323444}]}]}
{"op":"mcm","clk":"AJWxAQCkWADknAE=","pt":1659347737467,"mc":[{"id":"1.201590187","rc":[{"atb":[[11,2.83]],"id":45323444},{"atl":[[7.8,22.28]],"id":12989514}]}]}
{"op":"mcm","clk":"AJexAQCkWADqnAE=","pt":1659347737518,"mc":[{"id":"1.201590187","rc":[{"bdatb":[[2,11,3.04]],"id":45323444},{"bdatl":[[2,7.8,22.28]],"id":12989514}]}]}
{"op":"mcm","clk":"AJmxAQCkWADrnAE=","pt":1659347737568,"mc":[{"id":"1.201590187","rc":[{"atb":[[6.4,16.52]],"id":12989514}]}]}
{"op":"mcm","clk":"AJyxAQCnWADunAE=","pt":1659347737618,"mc":[{"id":"1.201590187","rc":[{"bdatb":[[1,6.4,16.52]],"id":12989514}]}]}
{"op":"mcm","clk":"AJ2xAQCnWADwnAE=","pt":1659347737670,"mc":[{"id":"1.201590187","rc":[{"atb":[[6.4,18.9]],"id":12989514}]}]}
{"op":"mcm","clk":"AKKxAQCrWAD1nAE=","pt":1659347737720,"mc":[{"id":"1.201590187","rc":[{"bdatb":[[1,6.4,18.9]],"id":12989514}]}]}
{"op":"mcm","clk":"AKmxAQCtWAD2nAE=","pt":1659347737770,"mc":[{"id":"1.201590187","rc":[{"atb":[[9.4,54.1]],"bdatb":[[7,9.4,54.78]],"id":45323444},{"atb":[[3.9,61.72]],"id":12989514},{"atb":[[5.7,96.26]],"bdatb":[[9,5.7,97.13]],"id":44836671}]}]}
{"op":"mcm","clk":"ALGxAQCvWAD7nAE=","pt":1659347737844,"mc":[{"id":"1.201590187","rc":[{"atb":[[1.75,51.72]],"id":9570503},{"atb":[[6.6,64.72]],"id":43885158}]}]}
{"op":"mcm","clk":"ALWxAQCvWAD/nAE=","pt":1659347737933,"mc":[{"id":"1.201590187","rc":[{"atl":[[10.5,2.57]],"id":43885158},{"atb":[[20,3.51],[19.5,1.39]],"atl":[[23,1.37]],"id":46969227}]}]}
{"op":"mcm","clk":"ALixAQC0WACDnQE=","pt":1659347737983,"mc":[{"id":"1.201590187","rc":[{"bdatb":[[4,10,16.1],[5,9.8,9],[6,9.6,22.92],[7,9.4,54.1],[8,9.2,12.49],[9,9,17.15]],"id":45323444},{"bdatb":[[9,1.96,11.31]],"id":9570503},{"bdatb":[[2,6.2,6.62],[3,6,1.76],[5,5.8,38.25],[6,5.7,223.76],[7,5.6,2.57],[8,5.5,1.87]],"bdatl":[[9,9.2,3.36]],"id":12989514},{"bdatb":[[8,18.5,1.39],[9,14.5,1.26]],"id":44621159},{"bdatb":[[5,6.2,27.39],[6,6,218],[8,5.8,12.94],[9,5.7,96.26]],"id":44836671},{"bdatb":[[5,8.2,4.8],[6,8,1.64],[7,7.8,6.07]],"bdatl":[[0,10.5,2.57]],"id":43885158},{"bdatb":[[0,20,3.51],[1,19.5,1.39],[2,19,7.2],[3,18.5,8],[4,18,5],[5,17.5,7.76],[6,17,1.76],[7,16.5,1.76],[8,16,1.43],[9,15.5,1.76]],"bdatl":[[0,23,1.37],[1,24,5.22],[2,26,6.2],[3,27,1.86],[4,28,7.55],[5,29,1.76],[6,30,5.28],[7,32,1.76],[8,34,5],[9,36,1.76]],"id":46969227}]}]}
{"op":"mcm","clk":"AMCxAQC3WACFnQE=","pt":1659347738056,"mc":[{"id":"1.201590187","rc":[{"atl":[[7.4,0]],"id":12989514},{"atb":[[25,1.33]],"id":44621159},{"atl":[[10.5,1.42]],"id":43885158}]}]}
{"op":"mcm","clk":"AMCxAQC3WACHnQE=","pt":1659347738106,"mc":[{"id":"1.201590187","rc":[{"bdatb":[[4,10,15.25],[6,9.6,22.55],[8,9.2,13.8]],"id":45323444},{"bdatb":[[4,2.02,50.78],[5,2,98.05],[9,1.96,5.15]],"id":9570503},{"bdatb":[[5,5.8,36.17],[7,5.6,4.73]],"bdatl":[[0,7.6,21.93],[1,7.8,22.28],[2,8,1.76],[3,8.2,1.76],[4,8.4,4],[5,8.6,1.77],[6,8.8,1.76],[7,9,8.69],[8,9.2,3.36],[9,9.4,1.76]],"id":12989514},{"bdatb":[[0,25,1.33],[8,17.5,1.5],[9,13.5,7.95]],"id":44621159},{"bdatb":[[8,5.8,10.86]],"id":44836671},{"bdatb":[[5,8.2,3.76],[6,8,2.7]],"bdatl":[[0,10.5,1.42]],"id":43885158}]}]}
{"op":"mcm","clk":"ANixAQC9WACVnQE=","pt":1659347738451,"mc":[{"id":"1.201590187","rc":[{"atl":[[7.6,26.42]],"id":12989514}]}]}
{"op":"mcm","clk":"AN6xAQC/WACbnQE=","pt":1659347738502,"mc":[{"id":"1.201590187","rc":[{"bdatl":[[0,7.6,26.42]],"id":12989514}]}]}
{"op":"mcm","clk":"AJiyAQDTWADFnQE=","pt":1659347739347,"mc":[{"id":"1.201590187","rc":[{"atl":[[18,1.76]],"id":45323444},{"atb":[[18.5,2.7]],"id":44621159},{"atb":[[14.5,1.76]],"id":46969227}]}]}
{"op":"mcm","clk":"AJiyAQDTWADInQE=","pt":1659347739400,"mc":[{"id":"1.201590187","rc":[{"bdatl":[[2,18,1.76],[3,18.5,1.76],[4,19,1.76],[5,19.5,1.76],[6,20,1.76],[7,21,1.77],[8,22,2.7],[9,23,1.76]],"id":45323444},{"bdatb":[[8,18.5,2.7],[9,13.5,8.52]],"id":44621159}]}]}
{"op":"mcm","clk":"AJuyAQDUWADLnQE=","pt":1659347739450,"mc":[{"id":"1.201590187","rc":[{"atl":[[7.6,30.92]],"id":12989514}]}]}
{"op":"mcm","clk":"AJ2yAQDUWADOnQE=","pt":1659347739500,"mc":[{"id":"1.201590187","rc":[{"bdatl":[[0,7.6,30.92]],"id":12989514}]}]}
{"op":"mcm","clk":"APKyAQD7WACNngE=","pt":1659347740861,"mc":[{"id":"1.201590187","rc":[{"atl":[[24,0]],"id":45323444}]}]}
{"op":"mcm","clk":"APiyAQD8WACUngE=","pt":1659347740953,"mc":[{"id":"1.201590187","rc":[{"atl":[[22,4.02]],"id":45323444}]}]}
{"op":"mcm","clk":"AP6yAQD8WACWngE=","pt":1659347741003,"mc":[{"id":"1.201590187","rc":[{"bdatl":[[8,22,4.14]],"id":45323444}]}]}
{"op":"mcm","clk":"AIazAQCBWQCfngE=","pt":1659347741080,"mc":[{"id":"1.201590187","rc":[{"atl":[[17,1.33]],"id":45323444},{"atl":[[7.4,4.45]],"id":12989514}]}]}
{"op":"mcm","clk":"AIezAQCBWQChngE=","pt":1659347741131,"mc":[{"id":"1.201590187","rc":[{"bdatb":[[4,10,16.74],[6,9.6,22.73],[7,9.4,54.25],[8,9.2,12],[9,9,17]],"bdatl":[[1,17,1.51],[2,17.5,1.76],[3,18,1.76],[4,18.5,1.76],[5,19,1.76],[6,19.5,1.76],[7,20,1.76],[8,21,1.77],[9,22,4.14]],"id":45323444},{"bdatb":[[4,2.02,55.7],[5,2,93.09],[7,1.98,72.99],[9,1.96,9.88]],"id":9570503},{"bdatb":[[9,5.4,8.58]],"bdatl":[[0,7.4,4.45],[1,7.6,30.92],[2,7.8,22.28],[3,8,1.76],[4,8.2,1.76],[5,8.4,4],[6,8.6,1.77],[7,8.8,1.76],[8,9,8.69],[9,9.2,3.36]],"id":12989514},{"bdatb":[[8,18.5,3.23],[9,14,1.52]],"id":44621159},{"bdatb":[[7,5.9,9.84],[8,5.8,10],[9,5.7,99.17]],"id":44836671},{"bdatb":[[5,8.2,4.97],[6,8,1.46],[9,7.4,5.24]],"id":43885158}]}]}
{"op":"mcm","clk":"AJyzAQCLWQCzngE=","pt":1659347741472,"mc":[{"id":"1.201590187","rc":[{"atl":[[7.8,12.92],[7.4,7]],"id":12989514}]}]}
{"op":"mcm","clk":"AKKzAQCOWQC0ngE=","pt":1659347741522,"mc":[{"id":"1.201590187","rc":[{"bdatb":[[7,9.4,54.58],[8,9.2,13.72],[9,9,14.9]],"id":45323444},{"bdatl":[[0,7.4,7],[2,7.8,12.92]],"id":12989514}]}]}
{"op":"mcm","clk":"AL6zAQCfWQDMngE=","pt":1659347741968,"mc":[{"id":"1.201590187","rc":[{"atb":[[8.8,4.98]],"id":43885158}]}]}
{"op":"mcm","clk":"AMCzAQCfWQDOngE=","pt":1659347742019,"mc":[{"id":"1.201590187","rc":[{"bdatb":[[2,8.8,4.98]],"id":43885158}]}]}
{"op":"mcm","clk":"AMWzAQCjWQDQngE=","pt":1659347742069,"mc":[{"id":"1.201590187","rc":[{"atl":[[7.4,10.2]],"id":12989514},{"atb":[[9.2,4.76]],"id":43885158}]}]}
{"op":"mcm","clk":"AMezAQCjWQDSngE=","pt":1659347742119,"mc":[{"id":"1.201590187","rc":[{"bdatb":[[8,9.2,15.57],[9,9,13]],"id":45323444},{"bdatl":[[0,7.4,10.2]],"id":12989514},{"bdatb":[[1,9.2,4.76]],"id":43885158}]}]}
{"op":"mcm","clk":"AMuzAQClWQDVngE=","pt":1659347742169,"mc":[{"id":"1.201590187","rc":[{"atb":[[2.02,46.84]],"atl":[[2.2,3.84]],"id":9570503},{"atb":[[6.4,16.52]],"atl":[[7.6,28.62]],"id":12989514},{"atb":[[7,2.65]],"atl":[[7.8,9.6]],"id":44836671},{"atb":[[8.8,2.81],[7.6,4.18]],"id":43885158}]}]}
{"op":"mcm","clk":"AMyzAQClWQDZngE=","pt":1659347742219,"mc":[{"id":"1.201590187","rc":[{"bdatb":[[4,2.02,51.75]],"bdatl":[[3,2.2,3.84]],"id":9570503},{"bdatb":[[1,6.4,16.52]],"bdatl":[[1,7.6,28.62]],"id":12989514},{"bdatb":[[1,7,2.65]],"bdatl":[[1,7.8,9.6]],"id":44836671},{"bdatb":[[2,8.8,2.81],[8,7.6,4.18]],"id":43885158}]}]}
{"op":"mcm","clk":"ANWzAQCpWQDhngE=","pt":1659347742374,"mc":[{"id":"1.201590187","rc":[{"atl":[[7.4,14.86]],"id":12989514}]}]}
{"op":"mcm","clk":"ANezAQCqWQDkngE=","pt":1659347742424,"mc":[{"id":"1.201590187","rc":[{"bdatl":[[0,7.4,14.86]],"id":12989514}]}]}
{"op":"mcm","clk":"AIm0AQDKWQCSnwE=","pt":1659347743146,"mc":[{"id":"1.201590187","rc":[{"atb":[[8.8,48.84]],"id":46969227}]}]}
{"op":"mcm","clk":"AJ+0AQDUWQCcnwE=","pt":1659347743458,"mc":[{"id":"1.201590187","rc":[{"atb":[[11,1.23]],"id":45323444}]}]}
{"op":"mcm","clk":"AKK0AQDVWQCjnwE=","pt":1659347743508,"mc":[{"id":"1.201590187","rc":[{"bdatb":[[2,11,1.44]],"id":45323444}]}]}
{"op":"mcm","clk":"AKm0AQDbWQCnnwE=","pt":1659347743581,"mc":[{"id":"1.201590187","rc":[{"atb":[[1.02,1.6]],"id":45323444}]}]}
{"op":"mcm","clk":"AMC0AQDtWQC5nwE=","pt":1659347743887,"mc":[{"id":"1.201590187","rc":[{"atl":[[25,1.48]],"id":46969227}]}]}
{"op":"mcm","clk":"AMK0AQDxWQC9nwE=","pt":1659347743937,"mc":[{"id":"1.201590187","rc":[{"bdatl":[[2,25,1.48],[3,26,6.1],[4,27,1.86],[5,28,7.55],[6,29,1.76],[7,30,5.28],[8,32,1.76],[9,34,5]],"id":46969227}]}]}
{"op":"mcm","clk":"ANW0AQD7WQDYnwE=","pt":1659347744352,"mc":[{"id":"1.201590187","rc":[{"atb":[[2.02,42.73]],"atl":[[2.2,0]],"id":9570503},{"atb":[[6.4,14.11]],"atl":[[7.6,26.3]],"id":12989514},{"atb":[[7,0.35]],"atl":[[7.8,7.34]],"id":44836671},{"atb":[[7.8,1.76],[8.8,0.64],[7.6,1.76]],"id":43885158}]}]}
{"op":"mcm","clk":"ANW0AQD7WQDcnwE=","pt":1659347744402,"mc":[{"id":"1.201590187","rc":[{"bdatb":[[4,2.02,47.65]],"bdatl":[[3,2.22,4],[4,2.24,7],[5,2.26,7.02],[6,2.28,6.17],[7,2.3,6.16],[8,2.32,7.89],[9,2.34,2.25]],"id":9570503},{"bdatb":[[1,6.4,14.11]],"bdatl":[[1,7.6,26.3]],"id":12989514},{"bdatb":[[1,6.8,18.89],[2,6.6,7.16],[3,6.4,1.76],[4,6.2,27.39],[5,6,218],[6,5.9,9.84],[7,5.8,10],[8,5.7,99.17],[9,5.6,12.8]],"bdatl":[[1,7.8,7.34]],"id":44836671},{"bdatb":[[2,8.6,21.52],[3,8.4,1.76],[4,8.2,4.97],[5,8,1.46],[6,7.8,1.76],[7,7.6,1.76],[8,7.4,5.24],[9,7.2,11.96]],"id":43885158}]}]}
{"op":"mcm","clk":"ANy0AQD/WQDfnwE=","pt":1659347744467,"mc":[{"id":"1.201590187","rc":[{"atb":[[2.04,5.28]],"atl":[[2.18,14.25]],"id":9570503},{"atb":[[6.8,1.55],[6.4,16.54]],"atl":[[7.4,17.23],[7.2,1.15]],"id":12989514},{"atb":[[7,2.67]],"atl":[[7.8,9.55]],"id":44836671},{"atb":[[8.8,2.94],[9,4.31]],"atl":[[10.5,2.57]],"id":43885158}]}]}
